Workbook
Name 作業ステータス: [1]コード内訳!$A$125:$A$132
Name 発生場所: [1]コード内訳!$A$115:$A$120

Sheet 概算見積
A1: 概 算 御 見 積 書 | X1: 見積番号 | AF1: -
X2: 見積年月日 | AF2: 45770
A5: 出光興産株式会社 御中
X8: 株式会社システムエグゼ
X9: 東京都中央区日本橋室町三丁目4番4号
X10: OVOL日本橋ビル7階
A11: 見積金額 | F11: =AE45 -> 300000 | X11: 担当: 髙橋 裕輔
X12: MAIL: yusuke.takahashi@system-exe.jp
A16: 件名
B18: IFC生産委託ポータル 下請法対応
A21: 作業形態
B23: 請負契約
A26: 作業場所
B28: 弊社内（在宅勤務を含む）
A31: 作業期間
B33: （仮）2025年8月18日 ～ 2025年8月29日
A36: 見積金額内訳
B38: No | D38: 項目 | Y38: 数量 | AE38: 金額 | AM38: 単価
B39: 1 | D39: 設計 | Y39: 0.03 | AC39: 人月 | AE39: =AM39*Y39 -> 30000 | AM39: 1000000
B40: 2 | D40: 改修 | Y40: 0.05 | AC40: 人月 | AE40: =AM40*Y40 -> 50000 | AM40: 1000000
B41: 3 | D41: テスト | Y41: 0.08 | AC41: 人月 | AE41: =AM41*Y41 -> 80000 | AM41: 1000000
B42: 4 | D42: リリース | Y42: 0.05 | AC42: 人月 | AE42: =AM42*Y42 -> 50000 | AM42: 1000000
B43: 5 | D43: 初期流動 | Y43: 0.02 | AC43: 人月 | AE43: =AM43*Y43 -> 20000 | AM43: 1000000
B44: 6 | D44: プロジェクト管理 | Y44: =ROUNDUP(SUM(Y39:AB43)*0.2,2) -> 0.05 | AC44: 人月 | AE44: =AM44*Y44 -> 70000 | AM44: 1400000
D45: 合計 | Y45: =SUM(Y39:AB44) -> 0.28 | AC45: 人月 | AE45: =SUM(AE39:AJ44) -> 300000 | AM45: -
A48: 納品物
B50: ・ | C50: 設計書 | T50: ・ | U50: 結合テスト仕様書兼結果報告書
B51: ・ | C51: ソースコード | T51: ・ | U51: 本番作業手順書
A53: 作業内容
B55: No | D55: 工程 | I55: 作業内容 | U55: 成果物
B56: 1 | D56: 設計 | I56: ・ | J56: 基本設計作成（既存更新） | U56: ・ | V56: 基本設計書
I57: ・ | J57: 詳細設計作成（既存更新） | U57: ・ | V57: 詳細設計書
B58: 2 | D58: 開発・単体テスト | I58: 「改修対象」を参照 | U58: ・ | V58: プログラム一式
B60: 3 | D60: 結合テスト | I60: ・ | J60: 結合テスト実施 | U60: ・ | V60: 結合テスト仕様書
B62: 4 | D62: 受入テスト | I62: ・ | J62: 受入テスト対応
B64: 5 | D64: リリース | I64: ・ | J64: 作業手順書作成 | U64: ・ | V64: 本番作業手順書
I65: ・ | J65: リリース作業実施
B66: 6 | D66: プロジェクト管理 | I66: ・ | J66: スケジュール管理 | U66: ・ | V66: 進捗報告書
I67: ・ | J67: レビュー、進捗管理・報告 | U67: ・ | V67: 課題管理表
I68: ・ | J68: 打ち合わせ等
...

Sheet IFCポータル_概算見積（内部用）
A1: IFC生産委託ポータル 下請法対応概算見積② | AA1: 人日 | AG1: 人月 | AM1: 工程別作業工数合算
I2: 人日 | R2: 人月 | AA2: 開発 | AB2: 50000 | AC2: 管理 | AD2: 70000 | AG2: 開発 | AH2: 1000000 | AI2: 管理 | AJ2: 1400000 | AM2: 人日 | AU2: 人月
A3: No. | B3: 案件名 | C3: 完成希望日 | D3: 内容 | E3: 改修内容 | F3: 概算工数 開発工数内訳（人日） | G3: 概算工数 開発工数（人日） | H3: 管理工数込み（人日） | I3: 設計 | J3: PG | K3: IT | L3: ST | M3: UAT | N3: リリース | O3: 初期流動 | P3: 合計 | R3: 設計 | S3: PG | T3: IT | U3: ST | V3: UAT | W3: リリース | X3: 初期流動 | Y3: 合計 | Z3: 備考 | AA3: 人日 | AB3: 金額 | AC3: 人日 | AD3: 金額 | AE3: 合計金額 | AG3: 人月 | AH3: 金額 | AI3: 人月 | AJ3: 金額 | AK3: 合計金額 | AM3: 調査・設計 | AN3: PG | AO3: IT | AP3: ST | AQ3: UAT | AR3: リリース | AS3: 合計 | AU3: 調査・設計 | AV3: PG | AW3: IT | AX3: ST | AY3: UAT | AZ3: リリース | BA3: 合計
A4: 1 | B4: 下請法対応概算見積 | C4: 45900 | D4: 下請法対応機能を追加する。 （文言表示機能） | E4: 【試験結果確認画面】 ・下請法に関するメッセージを表示する 文言：検査を完了する期日（検収日：即日） 場所：一覧表の上部若しくは下部 条件：下請法対象の委託先の場合 【委託先マスタ】 ・下請法対象フラグを追加 ・初期データ登録 | F4: =P4 -> 4.4 | G4: =P4 -> 4.4 | H4: =AA4+AC4 -> 5.28 | I4: 0.5 | J4: 1 | K4: 0.5 | L4: 0 | M4: 1 | N4: 1 | O4: 0.4 | P4: =SUM(I4:O4) -> 4.4 | R4: =ROUNDUP(I4/20,3) -> 0.025 | S4: =ROUNDUP(J4/20,3) -> 0.05 | T4: =ROUNDUP(K4/20,3) -> 0.025 | U4: =ROUNDUP(L4/20,3) -> 0 | V4: =ROUNDUP(M4/20,3) -> 0.05 | W4: =ROUNDUP(N4/20,3) -> 0.05 | X4: =ROUNDUP(O4/20,3) -> 0.02 | Y4: =SUM(R4:W4) -> 0.2 | AA4: =P4 -> 4.4 | AB4: =AA4*$AB$2 -> 220000 | AC4: =ROUNDUP(AA4*0.2,2) -> 0.88 | AD4: =ROUNDUP(AC4*$AD$2,-3) -> 62000 | AE4: =SUM(AB4,AD4) -> 282000 | AG4: =Y5 -> 0.23 | AH4: =AG4*$AH$2 -> 230000 | AI4: =ROUNDUP(AG4*0.2,3) -> 0.046 | AJ4: =AI4*$AJ$2 -> 64400 | AK4: =ROUNDUP(SUM(AH4,AJ4),-3) -> 295000 | AM4: =SUM(I4:I4) -> 0.5 | AN4: =SUM(J4:J4) -> 1 | AO4: =SUM(K4:K4) -> 0.5 | AP4: =SUM(L4:L4) -> 0 | AQ4: =SUM(M4:M4) -> 1 | AR4: =SUM(N4:N4) -> 1 | AS4: =SUM(P4:P4) -> 4.4 | AU4: =SUM(R4:R4) -> 0.025 | AV4: =SUM(S4:S4) -> 0.05 | AW4: =SUM(T4:T4) -> 0.025 | AX4: =SUM(U4:U4) -> 0 | AY4: =SUM(V4:V4) -> 0.05 | AZ4: =SUM(W4:W4) -> 0.05 | BA4: =SUM(Y4:Y4) -> 0.2
A5: 見積の前提条件 | R5: 0.03 | S5: 0.05 | T5: 0.03 | U5: 0 | V5: 0.05 | W5: 0.05 | X5: 0.02 | Y5: =SUM(R5:X5) -> 0.23
B7: 改修案件について、初期流動工数は含まれておりません。なお、問い合わせ対応は保守工数で処理する想定です。
B8: 費用は開発業務と管理業務別々に算出しております。
B9: 作業は弊社千葉事業所（在宅勤務を含む）で行うことを前提としています。
B10: 遠隔地での作業が発生した場合、工数を変更する可能性があります。
B11: 遠隔地での作業が発生した場合は、交通費や宿泊費等の必要経費を別途請求させていただきます。
B12: 見積もりの工数にはハードウェアやミドルウェア等にかかる費用は含まれておりません。
B13: リリース作業は2名で対応いたします。なお、連携NASの準備は見積もりに含まれません。
B14: プロジェクト期間は1.5か月から2か月を想定しています。<例>5月開始の場合は、6月後半にリリースを予定しております。
B15: 5月開始をご希望される場合は、契約を4月23日までに締結できるようご協力をお願いいたします。
B16: 上記の対応が難しい場合、5月以降に現在の担当者の空きが発生し、別案件対応をお願いする可能性がございます。この場合、ご希望のタイミングでの案件開始が難しくなる場合がありますので、ご了承ください。

Sheet スケジュール概算
N1: (人日) | R1: 2025 | X1: 夏季休暇
A2: No. | B2: 案件名 | C2: 内容 | D2: 完成希望日 | E2: 設計 | F2: PG | G2: IT | H2: UAT | I2: リリース | J2: 初期流動 | K2: 小計 | L2: 合計 | M2: 管理工数込み | O2: 着手 | P2: リリース | S2: 45873 | T2: 45874 | U2: 45875 | V2: 45876 | W2: 45877 | X2: 45878 | Y2: 45879 | Z2: 45880 | AA2: 45881 | AB2: 45882 | AC2: 45883 | AD2: 45884 | AE2: 45885 | AF2: 45886 | AG2: 45887 | AH2: 45888 | AI2: 45889 | AJ2: 45890 | AK2: 45891 | AL2: 45892 | AM2: 45893 | AN2: 45894 | AO2: 45895 | AP2: 45896 | AQ2: 45897 | AR2: 45898 | AS2: 45899 | AT2: 45900
A3: ='IFCポータル_概算見積（内部用）'!A4 -> 1 | B3: ='IFCポータル_概算見積（内部用）'!B4 -> 下請法対応概算見積 | C3: ='IFCポータル_概算見積（内部用）'!D4 -> 下請法対応機能を追加する。 （文言表示機能） | D3: ='IFCポータル_概算見積（内部用）'!C4 -> 45900 | E3: ='IFCポータル_概算見積（内部用）'!I4 -> 0.5 | F3: ='IFCポータル_概算見積（内部用）'!J4 -> 1 | G3: ='IFCポータル_概算見積（内部用）'!K4 -> 0.5 | H3: ='IFCポータル_概算見積（内部用）'!M4 -> 1 | I3: ='IFCポータル_概算見積（内部用）'!N4 -> 1 | J3: 0.4 | K3: =SUM(E3:J3) -> 4.4 | L3: =K3 -> 4.4 | M3: ='IFCポータル_概算見積（内部用）'!H4 -> 5.28 | O3: 45887 | P3: 45896 | Q3: 設計 | R3: =E3 -> 0.5
Q4: PG | R4: =F3 -> 1
Q5: IT | R5: =G3 -> 0.5
A6: 体制 | Q6: UAT | R6: =H3 -> 1
B7: PM | C7: 髙橋裕輔 | Q7: リリース | R7: =I3 -> 1
B8: SE
