Workbook

Sheet 想定作業
A1: 前提
B2: 業務・機能変更は行わない。
B3: サーバ構成は現行踏襲とする。
B4: DBは現行踏襲（Oracle、SQLSever継続）
B5: JavaフレームワークはStruts継続
B6: テストは新規構築した本番環境（次期本番機）にて行う。
B7: ※検証、予備環境は最低限の動作確認（アプリ起動、ログイン確認程度）を想定
A10: 想定作業
A11: 全パターン共通
B12: IP,ホスト名変更に伴う各種（IF、DB等）向け先変更、検証
B13: データ移行
B14: アプリ動作検証（全画面、帳票、バッチ、IF打鍵※現新比較）
B15: アプリケーション構築、ミドルウェアのセットアップ
B16: IF連携ID変更（連携NASを利用しているもの）※新システム
A18: （１）次期アーキテクチャとしてAzure環境に再構築
B19: DB構築（構成の検討から） | E19: ※本見積は各システム毎に個別にOracle構築を想定
B20: Office 365化に伴うExcel帳票の非互換調査、対応
B21: DBバージョンアップ（19c⇒22c）に伴う非互換調査、対応
B22: WebLogic⇒Tomcat移行に伴う非互換調査、対応
B23: スケジューラ変更（Systemwalker Operation Manager⇒A-AUTO）に伴う非互換調査、対応
A25: （２）Azureに構築される縮小版の共通基盤に移行
B26: 全パターン共通の作業のみ
B27: JDKとWLSはマイナーバージョンアップされるが、Strutsへの非互換は無い認識
B28: ※DBを個別構築する場合は以下が追加
B29: DB構築（構成の検討から）
B30: DBバージョンアップ（19c⇒22c）に伴う非互換調査、対応
A32: （３）現地Windows2016サーバ再構築
B33: サーバ構築（実際の構築作業は出光だが、スペック見積等）
B34: DB構築
B35: DBバージョンアップ（Oracle19c⇒22c、SQLServer2016⇒2022）に伴う非互換調査、対応
B36: .NET Framework非互換調査、64bit非互換調査（製品倉庫、ABC、数量ポリマー）
B37: Office 365化に伴うExcel帳票の非互換調査、対応（製品倉庫のみ）
B38: Azure環境制約（Dドライブ、OSユーザ）※ヤード予備機がAzure構築のため、現地本番も構成合わせる必要

Sheet 背景・作業内容
C5: 背景
D6: 2025年の8月から各事業所ごとにサーバの更新を行うので周辺システムの更新対応を行う
D8: ・北海道：9月
D10: ・千葉：10月
D12: ・愛知：8月
D14: ・徳山：11月
D16: ・四日市：1月
D18: PIMSDBのクライアントのバージョンアップ
E19: 工場の3システムについては、バージョンアップ作業を実施予定
C21: 対応方針
D22: PIMSDB接続をしているファイルの向け先変更を行う
D23: PIMSDBのクライアントのバージョンアップを実施する

Sheet 概要図(千葉)
C1: ファイル連携 | F1: 工場系保守対象 | I1: 館林管理
C2: DBデータ連携 | F2: 工場系保守対象外 | I2: 現地管理

Sheet 概要図(徳山)
C1: ファイル連携 | F1: 工場系保守対象 | I1: 館林管理
C2: DBデータ連携 | F2: 工場系保守対象外 | I2: 現地管理

Sheet システム概要
F1: システム概要 | N1: システム規模 | T1: 共通基盤利用状況（現状）
A2: サービス: サービス番号 | B2: サービス名 | C2: 保守領域 | D2: 移行状況 | E2: 作業パターン ※想定作業シート参照 | F2: 業務概要 | G2: OS | H2: アプリ | I2: DB | J2: ミドルウェア | K2: フレームワーク | L2: その他 | M2: サーバ構成 | N2: 画面 | O2: 帳票 | P2: バッチ | Q2: IF | R2: テーブル | S2: その他 | T2: 共通AP | U2: 共通DB | V2: 連携 | W2: レポート | X2: 認証 | Y2: バッチ
A3: SVC-00000710 | B3: 千葉数量確定システム | C3: 工場系 | D3: 未実施（共通基盤） | E3: （1）or（2） | F3: 千葉事業所及び徳山事業所の石油化学装置の生産、在庫、PL(パイプライン)出荷、品目転換数量の管理を行うシステム。またタンクヤードの日報作成(ヤード日報)機能も持つ。 | G3: Red Hat Enterprise Linux7.3 | H3: java 1.8.0_152 WebLogic 12.2.1.2.0 | I3: Oracle19C | J3: Systemwalker Operation Manager | K3: struts 1.2.9 | M3: 本番 共通基盤（館林） 検証 共通基盤（館林） | N3: 千葉：41 徳山：30 | O3: 千葉：23 徳山：7 | P3: 共通：2 千葉：9 徳山：4 | Q3: 千葉：8 徳山：4 | R3: 共通：58 千葉：16 徳山：9 | T3: 〇 | U3: 〇 | V3: 〇 | W3: × | X3: 〇 | Y3: 〇 | Z3: e
A4: SVC-00000857 | B4: 徳山工場数量確定システム | Z4: e
A5: - | B5: 千葉工場用役管理システム | C5: 工場系 | D5: 未実施（共通基盤） | E5: （1）or（2） | F5: 石油化学装置の生産数量、用役数量の管理を行うシステム。 | G5: Red Hat Enterprise Linux7.3 | H5: java 1.8.0_152 WebLogic 12.2.1.2.0 | I5: Oracle19C | J5: Systemwalker Operation Manager | K5: struts 1.2.9 | M5: 本番 共通基盤（館林） 検証 共通基盤（館林） | N5: 千葉：28 徳山：17 | O5: 千葉：43 徳山：6 | P5: 共通：0 千葉：0 徳山：0 | Q5: 千葉：0 徳山：0 | R5: 共通：11 千葉：1 徳山：11 | T5: 〇 | U5: 〇 | V5: 〇 | W5: × | X5: 〇 | Y5: 〇 | Z5: e
A6: SVC-00000858 | B6: 徳山工場用役管理システム | Z6: e
A7: SVC-00001700 | B7: 千葉化学品質管理システム | C7: 工場系 | D7: 未実施（共通基盤） | E7: （1）or（2） | F7: 千葉事業所(工場)の品質管理課にて行う各種試験(工程、製品、物性)、及びそれに付随する業務(ロット管理、試験料金計算)を行うシステム。 | G7: Red Hat Enterprise Linux7.3 | H7: java 1.8.0_131 WebLogic 12.2.1.2.0 | I7: Oracle19C | J7: Systemwalker Operation Manager | K7: struts 1.2.9 | L7: List Creatorでの帳票作成 | M7: 本番 共通基盤（館林） 検証 共通基盤（館林） | N7: 83 | O7: 25 | P7: 5 | Q7: 4 | R7: 67 | T7: 〇 | U7: 〇 | V7: 〇 | W7: 〇 | X7: 〇 | Y7: 〇 | Z7: e
A8: SVC-00000854 | B8: ＬＭＰＰ包装システム | C8: 工場系 | D8: 未実施（共通基盤） | E8: （1）or（2） | F8: 千葉事業所(工場)のSPS、LMPP装置で生産される製品の包装管理を行うシステム。 | G8: Red Hat Enterprise Linux7.3 | H8: java 1.8.0_131 WebLogic 12.2.1.2.0 | I8: Oracle19C | J8: Systemwalker Operation Manager | K8: struts 1.2.9 | L8: List Creatorでの帳票作成 | M8: 本番 共通基盤（館林） 検証 共通基盤（館林） | N8: 17 | O8: 3 | P8: 1 | Q8: 3 | R8: 12 | T8: 〇 | U8: 〇 | V8: 〇 | W8: 〇 | X8: 〇 | Y8: 〇 | Z8: e
A9: SVC-00000877 | B9: 工場DB | C9: 工場系 | D9: 未実施（共通基盤） ※アプリはXenApp | E9: （1）or（2） | F9: 徳山事業所の石油化学装置の生産、在庫の計画値及び実績値を管理するDB及びエクセルマクロ群。 | G9: - | H9: Excel | I9: Oracle19C | J9: - | K9: - | M9: 本番 共通基盤（館林） 検証 共通基盤（館林） | N9: 0 | O9: 0 | P9: 0 | Q9: 0 | R9: 211 | T9: × | U9: 〇 | V9: × | W9: × | X9: × | Y9: × | Z9: e
A10: SVC-00000705 | B10: 千葉ヤ－ド操業システム | C10: 工場系 | D10: 未実施（共通基盤） | E10: （3） | F10: 千葉事業所及び徳山事業所の石油化学品の入出荷を管理するシステム。 | G10: WindowsServer2016 | H10: java 1.8.0_152 WebLogic 12.2.1.2.0 | I10: SQLServer2016 | J10: Systemwalker Operation Manager OWFT | K10: struts 1.2.9 | M10: 本番 AP/DBサーバ×2（現地） AP/DB予備×2（館林） 検証 AP/DBサーバ×2（館林） | N10: 80 | O10: 20 | P10: 千葉：20 徳山：19 | Q10: 千葉：16 徳山：15 | R10: 75 | T10: × | U10: 〇 | V10: 〇 | W10: × | X10: × | Y10: × | Z10: e
A11: SVC-00000707 | B11: 徳山ヤ－ド操業システム | T11: × | U11: 〇 | V11: 〇 | W11: × | X11: × | Y11: × | Z11: e
A12: SVC-00000704 | B12: 千葉製品倉庫システム | C12: 工場系 | D12: 未実施（現地サーバ） | E12: （3） | F12: 千葉事業所(工場)で生産されているポリマー製品の包装、入出荷、在庫管理を行うシステム。 | G12: WindowsServer2016 | H12: VB.NET | I12: Oracle12C | J12: Systemwalker Operation Manager OWFT | M12: 本番 AP/DBサーバ（現地） 検証 APサーバ（館林） | N12: 68 | O12: 43 | P12: 9 | Q12: 45 | R12: 205 | T12: × | U12: × | V12: 〇 | W12: × | X12: × | Y12: × | Z12: e
A13: SVC-00000901 | B13: 千葉工場数量確定システム（ポリマ－） | C13: 工場系 | D13: 未実施（現地サーバ） | E13: （3） | F13: 千葉事業所(工場)で生産されているポリマー製品の生産、在庫、PL(パイプライン)出荷、品目転換数量の管理を行うシステム。 | G13: WindowsServer2016 | H13: ASP.NET | I13: Oracle12C | J13: Systemwalker Operation Manager OWFT | N13: 20 | O13: 4 | P13: 2 | Q13: 2 | R13: 30 | T13: × | U13: × | V13: × | W13: × | X13: × | Y13: × | Z13: e
A14: SVC-00000711 | B14: ＡＢＣ数量確定システム | C14: 工場系 | D14: 未実施（現地サーバ） | E14: （3） | F14: 千葉事業所(工場)のABC装置で生産される製品の生産管理を行うシステム。 | G14: WindowsServer2016 | H14: C# | I14: Oracle12C | J14: Systemwalker Operation Manager OWFT | N14: 15 | O14: 0 | P14: 12 | Q14: 5 | R14: 24 | T14: × | U14: × | V14: × | W14: × | X14: × | Y14: × | Z14: e
A15: - | B15: 千葉L3.5 | C15: 工場系 | D15: 未実施（現地サーバ） | E15: （3） | F15: L3層に存在するシステムとL4層に存在するシステムの中継となるサーバ | G15: WindowsServer2016 | H15: - | I15: - | J15: Systemwalker Operation Manager OWFT | K15: - | M15: 本番 APサーバ（現地） 検証 APサーバ（館林） | N15: 0 | O15: 0 | P15: 2 | Q15: 千葉：52 徳山：22 | R15: 0 | T15: × | U15: × | V15: × | W15: × | X15: × | Y15: ×
A16: - | B16: 徳山L3.5 | T16: × | U16: × | V16: × | W16: × | X16: × | Y16: ×

Sheet スケジュール（工場）
A2: システム | B2: 担当 | C2: 2025年 | O2: 2026年
C3: 1月 | D3: 2月 | E3: 3月 | F3: 4月 | G3: 5月 | H3: 6月 | I3: 7月 | J3: 8月 | K3: 9月 | L3: 10月 | M3: 11月 | N3: 12月 | O3: 1月 | P3: 2月 | Q3: 3月 | R3: 4月 | S3: 5月
A4: マイルストン | L4: ★千葉切替 | M4: ★徳山切替
A5: 千葉PIMS
A6: 徳山PIMS
A8: 想定要員数（作業者のみ）
J9: 1 | L9: 0.3 | M9: 0.3
A14: 合計 | C14: =SUM(C9:C13) -> 0 | D14: =SUM(D9:D13) -> 0 | E14: =SUM(E9:E13) -> 0 | F14: =SUM(F9:F13) -> 0 | G14: =SUM(G9:G13) -> 0 | H14: =SUM(H9:H13) -> 0 | I14: =SUM(I9:I13) -> 0 | J14: =SUM(J9:J13) -> 1 | ... S14: =SUM(S9:S13) -> 0
A15: 作業者 | B15: 売上(1,000k) | C15: =C14*1000000 -> 0 | D15: =D14*1000000 -> 0 | E15: =E14*1000000 -> 0 | F15: =F14*1000000 -> 0 | G15: =G14*1000000 -> 0 | H15: =H14*1000000 -> 0 | I15: =I14*1000000 -> 0 | J15: =J14*1000000 -> 1000000 | ... S15: =S14*1000000 -> 0 | T15: =SUM(C15:S15) -> 1600000
B16: 経費(800k) | C16: =C14*800000 -> 0 | D16: =D14*800000 -> 0 | E16: =E14*800000 -> 0 | F16: =F14*800000 -> 0 | G16: =G14*800000 -> 0 | H16: =H14*800000 -> 0 | I16: =I14*800000 -> 0 | J16: =J14*800000 -> 800000 | ... S16: =S14*800000 -> 0 | T16: =SUM(C16:S16) -> 1280000
A17: 管理者 | B17: 売上(1,400k) | J17: 140000 | L17: 140000 | M17: 140000 | T17: =SUM(C17:S17) -> 420000
B18: 経費(1,000k) | J18: 100000 | L18: 100000 | M18: 100000 | T18: =SUM(C18:S18) -> 300000
R19: 売上合計 | T19: =T15+T17 -> 2020000
R20: 経費合計 | T20: =T16+T18 -> 1580000
R21: 粗利 | T21: =T19-T20 -> 440000
R22: 粗利率 | T22: =T21/T19 -> 0.21782178

Sheet 見積（数量確定システム）_bk
C1: システム名：数量確定システム
D2: パターン | E2: （１）次期アーキテクチャとしてAzure環境に再構築 | J2: （２）Azureに構築される縮小版の共通基盤に移行 | O2: （３）現地Windows2016サーバ再構築
E3: 想定工数(人月) | J3: 想定工数(人月) | O3: 想定工数(人月)
B4: No. | C4: 変更箇所カテゴリ | D4: タスク | E4: 要件定義・設計 | F4: 製造 | G4: 試験・本番稼働 | H4: 管理 | I4: 全体工数 | J4: 要件定義・設計 | K4: 製造 | L4: 試験・本番稼働 | M4: 管理 | N4: 全体工数 | O4: 要件定義・設計 | P4: 製造 | Q4: 試験・本番稼働 | R4: 管理 | S4: 全体工数 | T4: 備考
B5: 1 | C5: Azure移行 | D5: IP,ホスト名変更に伴う各種（IF、DB等）向け先変更、検証 | E5: 1 | F5: 0.5 | G5: 1 | H5: =SUM(E5:G5)*0.15 -> 0.375 | I5: =SUM(E5:H5) -> 2.875 | J5: 1 | K5: 0.5 | L5: 1 | M5: =SUM(J5:L5)*0.15 -> 0.375 | N5: =SUM(J5:M5) -> 2.875 | R5: =SUM(O5:Q5)*0.15 -> 0 | S5: =SUM(O5:R5) -> 0
B6: 2 | C6: Azure移行 | D6: アプリ動作検証（各パターンで検証範囲は異なる） | E6: 1.25 | F6: 0.5 | G6: 1 | H6: =SUM(E6:G6)*0.15 -> 0.4125 | I6: =SUM(E6:H6) -> 3.1625 | J6: 0.25 | K6: 0.25 | L6: 0.5 | M6: =SUM(J6:L6)*0.15 -> 0.15 | N6: =SUM(J6:M6) -> 1.15
B7: 3 | C7: サーバ更新 | D7: アプリケーション構築、ミドルウェアのセットアップ | E7: 1 | F7: 1 | G7: 0.5 | H7: =SUM(E7:G7)*0.15 -> 0.375 | I7: =SUM(E7:H7) -> 2.875 | J7: 0.5 | K7: 0.5 | L7: 0.5 | M7: =SUM(J7:L7)*0.15 -> 0.225 | N7: =SUM(J7:M7) -> 1.725 | R7: =SUM(O7:Q7)*0.15 -> 0 | S7: =SUM(O7:R7) -> 0
B8: 4 | C8: DB移行 | D8: データ移行 | E8: 0.25 | F8: 0.1 | G8: 0.1 | H8: =SUM(E8:G8)*0.15 -> 0.0675 | I8: =SUM(E8:H8) -> 0.5175 | J8: 0.1 | K8: 0.1 | L8: 0.25 | M8: =SUM(J8:L8)*0.15 -> 0.0675 | N8: =SUM(J8:M8) -> 0.5175 | R8: =SUM(O8:Q8)*0.15 -> 0 | S8: =SUM(O8:R8) -> 0
B9: 5 | C9: DB移行 | D9: DB構築（構成の検討から） | E9: 1.5 | F9: 1 | G9: 0.5 | H9: =SUM(E9:G9)*0.15 -> 0.45 | I9: =SUM(E9:H9) -> 3.45 | M9: =SUM(J9:L9)*0.15 -> 0 | N9: =SUM(J9:M9) -> 0
B10: 6 | C10: DB移行 | D10: DBバージョンアップ（19c⇒22c）に伴う非互換調査、対応 | E10: 1 | F10: 1 | G10: 0.5 | H10: =SUM(E10:G10)*0.15 -> 0.375 | I10: =SUM(E10:H10) -> 2.875 | M10: =SUM(J10:L10)*0.15 -> 0 | N10: =SUM(J10:M10) -> 0
B11: 7 | C11: Office更新 | D11: テンプレートファイル調査・対応 | E11: 0.1 | F11: 0.1 | G11: 0.1 | H11: =SUM(E11:G11)*0.15 -> 0.045 | I11: =SUM(E11:H11) -> 0.345 | M11: =SUM(J11:L11)*0.15 -> 0 | N11: =SUM(J11:M11) -> 0 | R11: =SUM(O11:Q11)*0.15 -> 0 | S11: =SUM(O11:R11) -> 0
B12: 8 | C12: TOMCAT移行 | D12: アプリケーションの移行 | E12: 0.1 | F12: 0.1 | G12: 0.1 | H12: =SUM(E12:G12)*0.15 -> 0.045 | I12: =SUM(E12:H12) -> 0.345 | M12: =SUM(J12:L12)*0.15 -> 0 | N12: =SUM(J12:M12) -> 0 | R12: =SUM(O12:Q12)*0.15 -> 0 | S12: =SUM(O12:R12) -> 0
B13: 9 | C13: ミドルウェア移行 | D13: A-Auto検証 | E13: 0.1 | F13: 0.1 | G13: 0.1 | H13: =SUM(E13:G13)*0.15 -> 0.045 | I13: =SUM(E13:H13) -> 0.345 | M13: =SUM(J13:L13)*0.15 -> 0 | N13: =SUM(J13:M13) -> 0 | R13: =SUM(O13:Q13)*0.15 -> 0 | S13: =SUM(O13:R13) -> 0 | T13: 非互換検証
B14: 10 | C14: ミドルウェア移行 | D14: オペマネのA-Auto更新 | E14: 0.5 | F14: 0.25 | G14: 0.25 | H14: =SUM(E14:G14)*0.15 -> 0.15 | I14: =SUM(E14:H14) -> 1.15 | M14: =SUM(J14:L14)*0.15 -> 0 | N14: =SUM(J14:M14) -> 0 | R14: =SUM(O14:Q14)*0.15 -> 0 | S14: =SUM(O14:R14) -> 0 | T14: A-AUTO14本
D16: 合計工数 | E16: =SUM(E5:E14) -> 6.8 | F16: =SUM(F5:F14) -> 4.65 | G16: =SUM(G5:G14) -> 4.15 | H16: =SUM(H5:H14) -> 2.34 | I16: =SUM(I5:I14) -> 17.94 | J16: =SUM(J5:J14) -> 1.85 | K16: =SUM(K5:K14) -> 1.35 | L16: =SUM(L5:L14) -> 2.25 | ... S16: =SUM(S5:S14) -> 0
D18: 単価(千円) | E18: 1000 | F18: 1000 | G18: 1000 | H18: 1200 | I18: =AVERAGE(E18:H18) -> 1050 | J18: 1000 | K18: 1000 | L18: 1000 | M18: 1200 | N18: =AVERAGE(J18:M18) -> 1050 | O18: 1000 | P18: 1000 | Q18: 1000 | R18: 1200 | S18: =AVERAGE(O18:R18) -> 1050
D19: 金額(千円) | E19: =E16*E18 -> 6800 | F19: =F16*F18 -> 4650 | G19: =G16*G18 -> 4150 | H19: =H16*H18 -> 2808 | I19: =SUM(E19:H19) -> 18408 | J19: =J16*J18 -> 1850 | K19: =K16*K18 -> 1350 | L19: =L16*L18 -> 2250 | M19: =M16*M18 -> 981 | N19: =SUM(J19:M19) -> 6431 | O19: =O16*O18 -> 0 | P19: =P16*P18 -> 0 | Q19: =Q16*Q18 -> 0 | R19: =R16*R18 -> 0 | S19: =SUM(O19:R19) -> 0

Sheet 見積（〇〇システム）
C1: システム名：
D2: パターン | E2: （１）次期アーキテクチャとしてAzure環境に再構築 | J2: （２）Azureに構築される縮小版の共通基盤に移行 | O2: （３）現地Windows2016サーバ再構築
E3: 想定工数(人月) | J3: 想定工数(人月) | O3: 想定工数(人月)
B4: No. | C4: 変更箇所カテゴリ | D4: タスク | E4: 要件定義・設計 | F4: 製造 | G4: 試験・本番稼働 | H4: 管理 | I4: 全体工数 | J4: 要件定義・設計 | K4: 製造 | L4: 試験・本番稼働 | M4: 管理 | N4: 全体工数 | O4: 要件定義・設計 | P4: 製造 | Q4: 試験・本番稼働 | R4: 管理 | S4: 全体工数 | T4: 備考
B5: 1 | C5: Azure移行 | D5: アプリケーション構築、向け先変更、IF検証、ミドルウェアのセットアップ | E5: 1 | F5: 0.5 | G5: 1 | H5: =SUM(E5:G5)*0.15 -> 0.375 | I5: =SUM(E5:H5) -> 2.875 | J5: 1 | K5: 0.5 | L5: 1 | M5: =SUM(J5:L5)*0.15 -> 0.375 | N5: =SUM(J5:M5) -> 2.875 | O5: 1 | P5: 0.5 | Q5: 1 | R5: =SUM(O5:Q5)*0.15 -> 0.375 | S5: =SUM(O5:R5) -> 2.875 | T5: 参考：Windows Server 2012 更新対応
B6: 2 | C6: Azure移行 | D6: アプリケーション構築、向け先変更、IF検証、ミドルウェアのセットアップ | E6: 0.25 | F6: 0.5 | G6: 1 | H6: =SUM(E6:G6)*0.15 -> 0.2625 | I6: =SUM(E6:H6) -> 2.0125 | J6: 0.25 | K6: 0.5 | L6: 1 | M6: =SUM(J6:L6)*0.15 -> 0.2625 | N6: =SUM(J6:M6) -> 2.0125 | O6: 0.25 | P6: 0.5 | Q6: 1 | R6: =SUM(O6:Q6)*0.15 -> 0.2625 | S6: =SUM(O6:R6) -> 2.0125 | T6: 参考：Windows Server 2012 更新対応
B7: 3 | C7: Azure移行 | D7: アプリケーション構築、向け先変更、IF検証、ミドルウェアのセットアップ | E7: 1 | F7: 0.5 | G7: 1 | H7: =SUM(E7:G7)*0.15 -> 0.375 | I7: =SUM(E7:H7) -> 2.875 | J7: 1 | K7: 0.5 | L7: 1 | M7: =SUM(J7:L7)*0.15 -> 0.375 | N7: =SUM(J7:M7) -> 2.875 | O7: 1 | P7: 0.5 | Q7: 1 | R7: =SUM(O7:Q7)*0.15 -> 0.375 | S7: =SUM(O7:R7) -> 2.875 | T7: 参考：Windows Server 2012 更新対応
B8: 4 | C8: Azure移行 | D8: アプリケーション構築、向け先変更、IF検証、ミドルウェアのセットアップ | E8: 1 | F8: 0.5 | G8: 1 | H8: =SUM(E8:G8)*0.15 -> 0.375 | I8: =SUM(E8:H8) -> 2.875 | J8: 1 | K8: 0.5 | L8: 1 | M8: =SUM(J8:L8)*0.15 -> 0.375 | N8: =SUM(J8:M8) -> 2.875 | O8: 1 | P8: 0.5 | Q8: 1 | R8: =SUM(O8:Q8)*0.15 -> 0.375 | S8: =SUM(O8:R8) -> 2.875 | T8: 参考：Windows Server 2012 更新対応
B9: 5 | C9: Azure移行 | D9: アプリケーション構築、向け先変更、IF検証、ミドルウェアのセットアップ | E9: 1 | F9: 0.5 | G9: 1 | H9: =SUM(E9:G9)*0.15 -> 0.375 | I9: =SUM(E9:H9) -> 2.875 | J9: 1 | K9: 0.5 | L9: 1 | M9: =SUM(J9:L9)*0.15 -> 0.375 | N9: =SUM(J9:M9) -> 2.875 | O9: 1 | P9: 0.5 | Q9: 1 | R9: =SUM(O9:Q9)*0.15 -> 0.375 | S9: =SUM(O9:R9) -> 2.875 | T9: 参考：Windows Server 2012 更新対応
B10: 6 | C10: サーバ更新 | D10: 向け先変更、IF検証、ミドルウェアのセットアップ | E10: 1 | F10: 0.25 | G10: 0.5 | H10: =SUM(E10:G10)*0.15 -> 0.2625 | I10: =SUM(E10:H10) -> 2.0125 | J10: 1 | K10: 0.25 | L10: 0.5 | M10: =SUM(J10:L10)*0.15 -> 0.2625 | N10: =SUM(J10:M10) -> 2.0125 | O10: 1 | P10: 0.25 | Q10: 0.5 | R10: =SUM(O10:Q10)*0.15 -> 0.2625 | S10: =SUM(O10:R10) -> 2.0125
B11: 7 | C11: サーバ更新 | D11: 向け先変更、IF検証、ミドルウェアのセットアップ | E11: 0.25 | F11: 0.25 | G11: 0.5 | H11: =SUM(E11:G11)*0.15 -> 0.15 | I11: =SUM(E11:H11) -> 1.15 | J11: 0.25 | K11: 0.25 | L11: 0.5 | M11: =SUM(J11:L11)*0.15 -> 0.15 | N11: =SUM(J11:M11) -> 1.15 | O11: 0.25 | P11: 0.25 | Q11: 0.5 | R11: =SUM(O11:Q11)*0.15 -> 0.15 | S11: =SUM(O11:R11) -> 1.15
B12: 8 | C12: OS更新 | D12: .netFramework非互換調査、64bit非互換調査 | E12: 0.5 | F12: 0.5 | G12: 1 | H12: =SUM(E12:G12)*0.15 -> 0.3 | I12: =SUM(E12:H12) -> 2.3 | J12: 0.5 | K12: 0.5 | L12: 1 | M12: =SUM(J12:L12)*0.15 -> 0.3 | N12: =SUM(J12:M12) -> 2.3 | O12: 0.5 | P12: 0.5 | Q12: 1 | R12: =SUM(O12:Q12)*0.15 -> 0.3 | S12: =SUM(O12:R12) -> 2.3
B13: 9 | C13: OS更新 | D13: .netFramework非互換調査、64bit非互換調査 | E13: 0.5 | F13: 0.25 | G13: 1 | H13: =SUM(E13:G13)*0.15 -> 0.2625 | I13: =SUM(E13:H13) -> 2.0125 | J13: 0.5 | K13: 0.25 | L13: 1 | M13: =SUM(J13:L13)*0.15 -> 0.2625 | N13: =SUM(J13:M13) -> 2.0125 | O13: 0.5 | P13: 0.25 | Q13: 1 | R13: =SUM(O13:Q13)*0.15 -> 0.2625 | S13: =SUM(O13:R13) -> 2.0125
B14: 10 | C14: OS更新 | D14: .netFramework非互換調査、64bit非互換調査 | E14: 0.5 | F14: 0.25 | G14: 0.5 | H14: =SUM(E14:G14)*0.15 -> 0.1875 | I14: =SUM(E14:H14) -> 1.4375 | J14: 0.5 | K14: 0.25 | L14: 0.5 | M14: =SUM(J14:L14)*0.15 -> 0.1875 | N14: =SUM(J14:M14) -> 1.4375 | O14: 0.5 | P14: 0.25 | Q14: 0.5 | R14: =SUM(O14:Q14)*0.15 -> 0.1875 | S14: =SUM(O14:R14) -> 1.4375
B15: 11 | C15: OS更新 | D15: .netFramework非互換調査、64bit非互換調査 | E15: 1 | F15: 1 | G15: 1 | H15: =SUM(E15:G15)*0.15 -> 0.45 | I15: =SUM(E15:H15) -> 3.45 | J15: 1 | K15: 1 | L15: 1 | M15: =SUM(J15:L15)*0.15 -> 0.45 | N15: =SUM(J15:M15) -> 3.45 | O15: 1 | P15: 1 | Q15: 1 | R15: =SUM(O15:Q15)*0.15 -> 0.45 | S15: =SUM(O15:R15) -> 3.45
B16: 12 | C16: OS更新 | D16: .netFramework非互換調査、64bit非互換調査 | E16: - | F16: 0.25 | G16: 0.5 | H16: =SUM(E16:G16)*0.15 -> 0.1125 | I16: =SUM(E16:H16) -> 0.8625 | J16: - | K16: 0.25 | L16: 0.5 | M16: =SUM(J16:L16)*0.15 -> 0.1125 | N16: =SUM(J16:M16) -> 0.8625 | O16: - | P16: 0.25 | Q16: 0.5 | R16: =SUM(O16:Q16)*0.15 -> 0.1125 | S16: =SUM(O16:R16) -> 0.8625
B17: 13 | C17: Office更新 | D17: テンプレートファイル調査・対応 | E17: 0.1 | F17: 0.1 | G17: 0.1 | H17: =SUM(E17:G17)*0.15 -> 0.045 | I17: =SUM(E17:H17) -> 0.345 | J17: 0.1 | K17: 0.1 | L17: 0.1 | M17: =SUM(J17:L17)*0.15 -> 0.045 | N17: =SUM(J17:M17) -> 0.345 | O17: 0.1 | P17: 0.1 | Q17: 0.1 | R17: =SUM(O17:Q17)*0.15 -> 0.045 | S17: =SUM(O17:R17) -> 0.345
B18: 14 | C18: Office更新 | D18: テンプレートファイル調査・対応 | E18: 0.1 | F18: 0.1 | G18: 0.1 | H18: =SUM(E18:G18)*0.15 -> 0.045 | I18: =SUM(E18:H18) -> 0.345 | J18: 0.1 | K18: 0.1 | L18: 0.1 | M18: =SUM(J18:L18)*0.15 -> 0.045 | N18: =SUM(J18:M18) -> 0.345 | O18: 0.1 | P18: 0.1 | Q18: 0.1 | R18: =SUM(O18:Q18)*0.15 -> 0.045 | S18: =SUM(O18:R18) -> 0.345
B19: 15 | C19: Office更新 | D19: テンプレートファイル調査・対応 | E19: 0.1 | F19: 0.1 | G19: 0.1 | H19: =SUM(E19:G19)*0.15 -> 0.045 | I19: =SUM(E19:H19) -> 0.345 | J19: 0.1 | K19: 0.1 | L19: 0.1 | M19: =SUM(J19:L19)*0.15 -> 0.045 | N19: =SUM(J19:M19) -> 0.345 | O19: 0.1 | P19: 0.1 | Q19: 0.1 | R19: =SUM(O19:Q19)*0.15 -> 0.045 | S19: =SUM(O19:R19) -> 0.345
B20: 16 | C20: DB移行 | D20: バージョンアップ、データ移行、向け先変更 | E20: 0.1 | F20: 0.1 | G20: 0.1 | H20: =SUM(E20:G20)*0.15 -> 0.045 | I20: =SUM(E20:H20) -> 0.345 | J20: 0.1 | K20: 0.1 | L20: 0.1 | M20: =SUM(J20:L20)*0.15 -> 0.045 | N20: =SUM(J20:M20) -> 0.345 | O20: 0.1 | P20: 0.1 | Q20: 0.1 | R20: =SUM(O20:Q20)*0.15 -> 0.045 | S20: =SUM(O20:R20) -> 0.345
B21: 17 | C21: DB移行 | D21: バージョンアップ、データ移行、向け先変更 | E21: 0.1 | F21: 0.1 | G21: 0.1 | H21: =SUM(E21:G21)*0.15 -> 0.045 | I21: =SUM(E21:H21) -> 0.345 | J21: 0.1 | K21: 0.1 | L21: 0.1 | M21: =SUM(J21:L21)*0.15 -> 0.045 | N21: =SUM(J21:M21) -> 0.345 | O21: 0.1 | P21: 0.1 | Q21: 0.1 | R21: =SUM(O21:Q21)*0.15 -> 0.045 | S21: =SUM(O21:R21) -> 0.345
B22: 18 | C22: DB移行 | D22: バージョンアップ、データ移行、向け先変更 | E22: 0.1 | F22: 0.1 | G22: 0.1 | H22: =SUM(E22:G22)*0.15 -> 0.045 | I22: =SUM(E22:H22) -> 0.345 | J22: 0.1 | K22: 0.1 | L22: 0.1 | M22: =SUM(J22:L22)*0.15 -> 0.045 | N22: =SUM(J22:M22) -> 0.345 | O22: 0.1 | P22: 0.1 | Q22: 0.1 | R22: =SUM(O22:Q22)*0.15 -> 0.045 | S22: =SUM(O22:R22) -> 0.345
B23: 19 | C23: DB移行 | D23: バージョンアップ、データ移行、向け先変更 | E23: 0.1 | F23: 0.1 | G23: 0.1 | H23: =SUM(E23:G23)*0.15 -> 0.045 | I23: =SUM(E23:H23) -> 0.345 | J23: 0.1 | K23: 0.1 | L23: 0.1 | M23: =SUM(J23:L23)*0.15 -> 0.045 | N23: =SUM(J23:M23) -> 0.345 | O23: 0.1 | P23: 0.1 | Q23: 0.1 | R23: =SUM(O23:Q23)*0.15 -> 0.045 | S23: =SUM(O23:R23) -> 0.345
B24: 20 | C24: DB移行 | D24: バージョンアップ、データ移行、向け先変更 | E24: 0.1 | F24: 0.1 | G24: 0.1 | H24: =SUM(E24:G24)*0.15 -> 0.045 | I24: =SUM(E24:H24) -> 0.345 | J24: 0.1 | K24: 0.1 | L24: 0.1 | M24: =SUM(J24:L24)*0.15 -> 0.045 | N24: =SUM(J24:M24) -> 0.345 | O24: 0.1 | P24: 0.1 | Q24: 0.1 | R24: =SUM(O24:Q24)*0.15 -> 0.045 | S24: =SUM(O24:R24) -> 0.345
B25: 21 | C25: TOMCAT移行 | D25: アプリケーションの移行 | E25: 0.1 | F25: 0.1 | G25: 0.1 | H25: =SUM(E25:G25)*0.15 -> 0.045 | I25: =SUM(E25:H25) -> 0.345 | J25: 0.1 | K25: 0.1 | L25: 0.1 | M25: =SUM(J25:L25)*0.15 -> 0.045 | N25: =SUM(J25:M25) -> 0.345 | O25: 0.1 | P25: 0.1 | Q25: 0.1 | R25: =SUM(O25:Q25)*0.15 -> 0.045 | S25: =SUM(O25:R25) -> 0.345
B26: 22 | C26: TOMCAT移行 | D26: アプリケーションの移行 | E26: 0.1 | F26: 0.1 | G26: 0.1 | H26: =SUM(E26:G26)*0.15 -> 0.045 | I26: =SUM(E26:H26) -> 0.345 | J26: 0.1 | K26: 0.1 | L26: 0.1 | M26: =SUM(J26:L26)*0.15 -> 0.045 | N26: =SUM(J26:M26) -> 0.345 | O26: 0.1 | P26: 0.1 | Q26: 0.1 | R26: =SUM(O26:Q26)*0.15 -> 0.045 | S26: =SUM(O26:R26) -> 0.345
B27: 23 | C27: TOMCAT移行 | D27: アプリケーションの移行 | E27: 0.1 | F27: 0.1 | G27: 0.1 | H27: =SUM(E27:G27)*0.15 -> 0.045 | I27: =SUM(E27:H27) -> 0.345 | J27: 0.1 | K27: 0.1 | L27: 0.1 | M27: =SUM(J27:L27)*0.15 -> 0.045 | N27: =SUM(J27:M27) -> 0.345 | O27: 0.1 | P27: 0.1 | Q27: 0.1 | R27: =SUM(O27:Q27)*0.15 -> 0.045 | S27: =SUM(O27:R27) -> 0.345
B28: 24 | C28: TOMCAT移行 | D28: アプリケーションの移行 | E28: 0.1 | F28: 0.1 | G28: 0.1 | H28: =SUM(E28:G28)*0.15 -> 0.045 | I28: =SUM(E28:H28) -> 0.345 | J28: 0.1 | K28: 0.1 | L28: 0.1 | M28: =SUM(J28:L28)*0.15 -> 0.045 | N28: =SUM(J28:M28) -> 0.345 | O28: 0.1 | P28: 0.1 | Q28: 0.1 | R28: =SUM(O28:Q28)*0.15 -> 0.045 | S28: =SUM(O28:R28) -> 0.345
B29: 25 | C29: ミドルウェア移行 | D29: A-Auto検証 | E29: 0.1 | F29: 0.1 | G29: 0.1 | H29: =SUM(E29:G29)*0.15 -> 0.045 | I29: =SUM(E29:H29) -> 0.345 | J29: 0.1 | K29: 0.1 | L29: 0.1 | M29: =SUM(J29:L29)*0.15 -> 0.045 | N29: =SUM(J29:M29) -> 0.345 | O29: 0.1 | P29: 0.1 | Q29: 0.1 | R29: =SUM(O29:Q29)*0.15 -> 0.045 | S29: =SUM(O29:R29) -> 0.345 | T29: 非互換検証
B30: 26 | C30: ミドルウェア移行 | D30: オペマネのA-Auto更新 | E30: 0.1 | F30: 0.1 | G30: 0.1 | H30: =SUM(E30:G30)*0.15 -> 0.045 | I30: =SUM(E30:H30) -> 0.345 | J30: 0.1 | K30: 0.1 | L30: 0.1 | M30: =SUM(J30:L30)*0.15 -> 0.045 | N30: =SUM(J30:M30) -> 0.345 | O30: 0.1 | P30: 0.1 | Q30: 0.1 | R30: =SUM(O30:Q30)*0.15 -> 0.045 | S30: =SUM(O30:R30) -> 0.345 | T30: A-AUTO14本
B31: 27 | C31: ミドルウェア移行 | D31: オペマネのA-Auto更新 | E31: 0.1 | F31: 0.1 | G31: 0.1 | H31: =SUM(E31:G31)*0.15 -> 0.045 | I31: =SUM(E31:H31) -> 0.345 | J31: 0.1 | K31: 0.1 | L31: 0.1 | M31: =SUM(J31:L31)*0.15 -> 0.045 | N31: =SUM(J31:M31) -> 0.345 | O31: 0.1 | P31: 0.1 | Q31: 0.1 | R31: =SUM(O31:Q31)*0.15 -> 0.045 | S31: =SUM(O31:R31) -> 0.345 | T31: A-AUTO6本
D33: 合計工数 | E33: =SUM(E17:E31) -> 1.5 | F33: =SUM(F17:F31) -> 1.5 | G33: =SUM(G17:G31) -> 1.5 | H33: =SUM(H17:H31) -> 0.675 | I33: =SUM(I17:I31) -> 5.175 | J33: =SUM(J17:J31) -> 1.5 | K33: =SUM(K17:K31) -> 1.5 | L33: =SUM(L17:L31) -> 1.5 | ... S33: =SUM(S17:S31) -> 5.175
D35: 単価(千円) | E35: 1000 | F35: 1000 | G35: 1000 | H35: 1200 | I35: =AVERAGE(E35:H35) -> 1050 | J35: 1000 | K35: 1000 | L35: 1000 | M35: 1200 | N35: =AVERAGE(J35:M35) -> 1050 | O35: 1000 | P35: 1000 | Q35: 1000 | R35: 1200 | S35: =AVERAGE(O35:R35) -> 1050
D36: 金額(千円) | E36: =E33*E35 -> 1500 | F36: =F33*F35 -> 1500 | G36: =G33*G35 -> 1500 | H36: =H33*H35 -> 810 | I36: =SUM(E36:H36) -> 5310 | J36: =J33*J35 -> 1500 | K36: =K33*K35 -> 1500 | L36: =L33*L35 -> 1500 | M36: =M33*M35 -> 810 | N36: =SUM(J36:M36) -> 5310 | O36: =O33*O35 -> 1500 | P36: =P33*P35 -> 1500 | Q36: =Q33*Q35 -> 1500 | R36: =R33*R35 -> 810 | S36: =SUM(O36:R36) -> 5310

Sheet スケジュール（XenAPP）
B3: ざっくりスケジュール | D3: ２０２５年 | M3: 2026
B4: PIMSDBスケジュール | D4: ４月 | E4: ５月 | F4: ６月 | G4: ７月 | H4: ８月 | I4: ９月 | J4: １０月 | K4: １１月 | L4: １２月 | M4: １月 | N4: ２月 | O4: ３月
B5: 北海道 | I5: リリース
B6: 千葉 | J6: リリース
B7: 愛知 | H7: リリース
B8: 徳山 | K8: リリース
B9: 四日市 | M9: リリース
B11: XenApp移行スケジュール | D11: ４月 | E11: ５月 | F11: ６月 | G11: ７月 | H11: ８月 | I11: ９月 | J11: １０月 | K11: １１月 | L11: １２月 | M11: １月 | N11: ２月 | O11: ３月
B12: 北海道
B13: 千葉
B14: 愛知
B15: 徳山
B16: 四日市
B18: 要件定義
B19: 基本・詳細設計
B20: 愛知 | C20: 開発
B21: 愛知 | C21: 結合テスト
B22: 愛知 | C22: 受入テスト
B23: 愛知 | C23: 本番作業
B24: 愛知 | C24: 初期流動
B25: 北海道 | C25: 開発
B26: 北海道 | C26: 結合テスト
B27: 北海道 | C27: 受入テスト
B28: 北海道 | C28: 本番作業
B29: 北海道 | C29: 初期流動
B30: 千葉 | C30: 開発
B31: 千葉 | C31: 結合テスト
... B44: 四日市 | C44: 初期流動
C45: 売上
B46: PM | C46: 1400000 | E46: 0.25 | F46: 0.25 | G46: 0.25 | H46: 0.25 | I46: 0.25 | J46: 0.25 | K46: 0.25 | L46: 0.25 | M46: 0.25
B47: 作業者 | C47: 1000000 | E47: 1 | F47: 1.5 | G47: 1.5 | H47: 1.5 | I47: 1.5 | J47: 1.5 | K47: 1.5 | L47: 1 | M47: 1
E48: =($C46*E46)+($C47*E47) -> 1350000 | F48: =($C46*F46)+($C47*F47) -> 1850000 | G48: =($C46*G46)+($C47*G47) -> 1850000 | H48: =($C46*H46)+($C47*H47) -> 1850000 | I48: =($C46*I46)+($C47*I47) -> 1850000 | J48: =($C46*J46)+($C47*J47) -> 1850000 | K48: =($C46*K46)+($C47*K47) -> 1850000 | L48: =($C46*L46)+($C47*L47) -> 1350000 | M48: =($C46*M46)+($C47*M47) -> 1350000 | N48: =SUM(E48:M48) -> 15150000
C50: 原価
B51: PM | C51: 1000000
B52: 作業者 | C52: 800000 | O52: 利益 | P52: 利益率
E53: =($C51*E46)+($C52*E47) -> 1050000 | F53: =($C51*F46)+($C52*F47) -> 1450000 | G53: =($C51*G46)+($C52*G47) -> 1450000 | H53: =($C51*H46)+($C52*H47) -> 1450000 | I53: =($C51*I46)+($C52*I47) -> 1450000 | J53: =($C51*J46)+($C52*J47) -> 1450000 | K53: =($C51*K46)+($C52*K47) -> 1450000 | L53: =($C51*L46)+($C52*L47) -> 1050000 | M53: =($C51*M46)+($C52*M47) -> 1050000 | N53: =SUM(E53:M53) -> 11850000 | O53: =N48-N53 -> 3300000 | P53: =O53/N48 -> 0.21782178

Sheet 見積 (サマリ)
C2: パターン | D2: PIMS更新 | L2: 備考
D3: アプリ
B4: No. | C4: システム | D4: 調査・要件定義 | E4: 設計 | F4: 製造 | G4: 試験 | H4: 本番稼働 | I4: 管理 | J4: 工数計 | K4: 金額
B5: 1 | C5: 千葉 | D5: ='見積（工場千葉）'!E4 -> 0.05 | E5: ='見積（工場千葉）'!E5 -> 0.05 | F5: ='見積（工場千葉）'!E6 -> 0.3 | G5: ='見積（工場千葉）'!E8 -> 0.1 | H5: ='見積（工場千葉）'!E9 -> 0.35 | I5: ='見積（工場千葉）'!E11 -> 0.2 | J5: =SUM(D5:I5) -> 1.05 | K5: =SUM(D5:H5)*1000000+I5*1400000 -> 1130000
B6: 2 | C6: 徳山 | D6: ='見積（工場徳山）'!E4 -> 0.05 | E6: ='見積（工場徳山）'!E5 -> 0.05 | F6: ='見積（工場徳山）'!E6 -> 0.18 | G6: ='見積（工場徳山）'!E8 -> 0.05 | H6: ='見積（工場徳山）'!E9 -> 0.3 | I6: ='見積（工場徳山）'!E11 -> 0.15 | J6: =SUM(D6:I6) -> 0.78 | K6: =SUM(D6:H6)*1000000+I6*1400000 -> 840000
B7: 3 | C7: XenApp | D7: ='見積（XenApp）'!E4 -> 1 | E7: ='見積（XenApp）'!E5 -> 0.55 | F7: ='見積（XenApp）'!E6 -> 5.41 | G7: ='見積（XenApp）'!E8 -> 1.28 | H7: ='見積（XenApp）'!E9 -> 3.63 | I7: ='見積（XenApp）'!E11 -> 2.45 | J7: =SUM(D7:I7) -> 14.32 | K7: =SUM(D7:H7)*1000000+I7*1400000 -> 15300000
B8: 計 | D8: =SUM(D5:D7) -> 1.1 | E8: =SUM(E5:E7) -> 0.65 | F8: =SUM(F5:F7) -> 5.89 | G8: =SUM(G5:G7) -> 1.43 | H8: =SUM(H5:H7) -> 4.28 | I8: =SUM(I5:I7) -> 2.8 | J8: =SUM(D8:I8) -> 16.15 | K8: =SUM(K5:K7) -> 17270000
B9: 単価 | D9: 1000000 | E9: 1000000 | F9: 1000000 | G9: 1000000 | H9: 1000000 | I9: 1400000
B10: 金額 | D10: =D8*D9 -> 1100000 | E10: =E8*E9 -> 650000 | F10: =F8*F9 -> 5890000 | G10: =G8*G9 -> 1430000 | H10: =H8*H9 -> 4280000 | I10: =I8*I9 -> 3920000

Sheet 見積（工場千葉）
B1: システム名： | C1: 千葉数量確定システム、数量確定ポリマー
B3: 工程 | C3: タスク | D3: 概算工数 | E3: 工数計 | F3: 成果物 | G3: 備考 | H3: 人日
B4: 調査・要件定義 | C4: IP,ホスト名変更に伴う影響箇所調査 | D4: =ROUND(H4/20,2) -> 0.05 | E4: 0.05 | F4: 調査結果資料 | G4: IP,ホスト名使用箇所GREP調査 | H4: 1
B5: 設計 | C5: IP,ホスト名変更に伴う影響箇所対応 | D5: =ROUND(H5/20,2) -> 0.05 | E5: 0.05 | F5: 基本設計書、詳細設計書 運用ドキュメント FW設定依頼書 | G5: 設計書、運用ドキュメント修正 千葉数量確定、数量確定ポリマー | H5: 1
B6: 製造 | C6: クライアントバージョンアップ | D6: =ROUND(H6/20,2) -> 0.25 | E6: 0.3 | F6: バージョンアップ手順書 | G6: 千葉ヤード操業サーバ：本番、検証 PRMAP・DBサーバ：本番、検証 | H6: 5
C7: IP,ホスト名変更に伴う影響箇所対応 | D7: =ROUND(H7/20,2) -> 0.05 | F7: PG一式 | G7: 千葉ヤード操業サーバ：本番、検証 PRMAP・DBサーバ：本番、検証 | H7: 1
B8: 試験 | C8: 内部テスト | D8: =ROUND(H8/20,2) -> 0.1 | E8: 0.1 | F8: テスト仕様書兼結果報告書 | G8: 各検証機とPIMSサーバ間のテスト 機能数=2 | H8: 2
B9: 本番稼働 | C9: アプリ移行 | D9: =ROUND(H9/20,2) -> 0.1 | E9: 0.35 | F9: 本番移行手順書 | G9: 移行手順書作成 移行作業 2システム実施 | H9: 2
C10: 初期流動 | D10: =ROUND(H10/20,2) -> 0.25 | F10: 初期流動管理表 | G10: 1週間×1名 | H10: 5
B11: 管理 | C11: PJ管理 | D11: =ROUND(H11/20,2) -> 0.2 | E11: 0.2 | F11: プロジェクト計画書 課題管理表 スケジュール（WBS） 議事録 レビュー管理表 +週次報告(3h*1*4) | G11: PJ管理、定例会、各工程完了レビュー | H11: =SUM(H4:H10)*0.15+I11 -> 4.05 | I11: =12/8 -> 1.5
B12: 合計 | E12: =SUM(E4:E11) -> 1.05 | H12: =SUM(H4:H11) -> 21.05

Sheet Sheet1
B2: 【対応方針】
C3: ・共通基盤DBに乗っているDB(数量確定、工場DB、品管、包装)は縮小基盤へ移動
C4: ・基本全てのオペマネはA-AUTOに変更
C5: ・独立したサーバとして寄せられるシステムは寄せる(数量確定システムと用役管理システム、品管と包装)
B8: 【対象】
B9: No | C9: サーバ名 | E9: 構成 | F9: 超概算(人月) | G9: 内訳 | H9: 内訳(端数切り上げ) | I9: 備考
B10: 1 | C10: 千葉ヤード操業サーバ | E10: WindowsServer2022 SQLServer2022 | F10: 5.75 | G10: ベース金額 +webシステムテスト +webシステムテスト修正 +tomcat非互換 +個別DB | H10: 4 +0.5 +0.25 +0.5 +0.5 | I10: Azure構築 A-AOUT化無し | J10: =4 +0.5 +0.25 +0.5 +0.5 -> 5.75
B11: 2 | C11: 徳山ヤード操業サーバ | E11: WindowsServer2022 SQLServer2022 | F11: 5.75 | G11: ベース金額 +webシステムテスト +webシステムテスト修正 +tomcat非互換 +個別DB | H11: 4 +0.5 +0.25 +0.5 +0.5 | I11: Azure構築 A-AOUT化無し | J11: =4 +0.5 +0.25 +0.5 +0.5 -> 5.75
B12: 3 | C12: 数量用役システムサーバ | E12: Red Hat Enterprise Linux8.6 | F12: 8.5 | G12: ベース金額 +webシステムテスト×4 +webシステムテスト修正×4 +tomcat非互換×2 +A-AUTO14本 | H12: 4 +0.5*4 +0.25*4 +0.5*2 +0.5(14*5/8/20) | I12: Azure構築 | J12: =4 +0.5*4 +0.25*4 +0.5*2 +0.5 -> 8.5
B13: 4 | C13: 品管包装システムサーバ | E13: Red Hat Enterprise Linux8.6 | F13: 6.75 | G13: ベース金額 +webシステムテスト×2 +webシステムテスト修正×2 +tomcat非互換×2 +A-AUTO6本 | H13: 4 +0.5*2 +0.25*2 +0.5*2 +0.25(6*5/8/20) | I13: Azure構築 | J13: =4 +0.5*2 +0.25*2 +0.5*2 +0.25 -> 6.75
B14: 5 | C14: 工場DB | F14: 0.5 | G14: システムテスト | H14: 0.5 | I14: Azure構築、DB構築後のエクセルでのテスト実施
B15: 6 | C15: PRMサーバ | E15: WindowsServer2022 Oracle22c | F15: 6.75 | G15: ベース金額 +webシステムテスト×3 +webシステムテスト修正×3 +個別DB | H15: 4 +0.5*3 +0.25*3 +0.5 | I15: Azure構築、 PRM資産の為DB個別構築想定 | J15: =4 +0.5*3 +0.25*3 +0.5 -> 6.75
B16: 7 | C16: 千葉L3.5サーバ | E16: WindowsServer2022 | F16: 4 | G16: ベース金額 | H16: 4 | I16: 現地作成 A-AOUT化無し
B17: 8 | C17: 徳山L3.5サーバ | E17: WindowsServer2022 | F17: 4 | G17: ベース金額 | H17: 4 | I17: 現地作成 A-AOUT化無し
B18: 9 | C18: DBサーバ | E18: Oracle22c | I18: 縮小基盤への移設
C19: (参考)2012サーバ更新 | F19: 3.35 | I19: Azure構築
F21: ベース金額：4人月(内容：調査、基本設計、環境構築、結合テスト 、システムテスト、本番移行・初期流動、プロジェクト管理)
F22: webシステムテスト：0.5人月
F23: webシステムテスト修正：0.25人月
F24: tomcat非互換：0.5人月
F25: 個別DB：0.5人月
F26: A-AUTO：1本＊5H
H27: =350+50*4+20*4+50*2+50 -> 780
F28: =14*5/8*(100/20) -> 43.75 | H28: =350+50*3+20*3+80 -> 640
F29: =12*5/8*(100/20) -> 37.5
F30: =19*5/8*(100/20) -> 59.375
F31: =6*5/8*(100/20) -> 18.75
F32: =24*5/8*(100/20) -> 75
F33: =3*5/8*(100/20) -> 9.375

Sheet 見積（工場徳山）
B1: システム名： | C1: 徳山数量確定システム
B3: 工程 | C3: タスク | D3: 概算工数 | E3: 工数計 | F3: 成果物 | G3: 備考 | H3: 人日
B4: 調査・要件定義 | C4: IP,ホスト名変更に伴う影響箇所調査 | D4: =ROUND(H4/20,2) -> 0.05 | E4: 0.05 | F4: 調査結果資料 | G4: IP,ホスト名使用箇所GREP調査 | H4: 1
B5: 設計 | C5: IP,ホスト名変更に伴う影響箇所対応 | D5: =ROUND(H5/20,2) -> 0.05 | E5: 0.05 | F5: 基本設計書、詳細設計書 運用ドキュメント FW設定依頼書 | G5: 設計書、運用ドキュメント修正 徳山数量確定 | H5: 1
B6: 製造 | C6: クライアントバージョンアップ | D6: =ROUND(H6/20,2) -> 0.13 | E6: 0.18 | F6: バージョンアップ手順書 | G6: 徳山ヤード操業サーバ：本番、検証 | H6: 2.5
C7: IP,ホスト名変更に伴う影響箇所対応 | D7: =ROUND(H7/20,2) -> 0.05 | F7: PG一式 | G7: 徳山ヤード操業サーバ：本番、検証 | H7: 1
B8: 試験 | C8: 内部テスト | D8: =ROUND(H8/20,2) -> 0.05 | E8: 0.05 | F8: テスト仕様書兼結果報告書 | G8: 各検証機とPIMSサーバ間のテスト 機能数=1 | H8: 1
B9: 本番稼働 | C9: アプリ移行 | D9: =ROUND(H9/20,2) -> 0.05 | E9: 0.3 | F9: 本番移行手順書 | G9: 移行手順書作成 移行作業 1システム実施 | H9: 1
C10: 初期流動 | D10: =ROUND(H10/20,2) -> 0.25 | F10: 初期流動管理表 | G10: 1週間×1名 | H10: 5
B11: 管理 | C11: PJ管理 | D11: =ROUND(H11/20,2) -> 0.15 | E11: 0.15 | F11: プロジェクト計画書 課題管理表 スケジュール（WBS） 議事録 レビュー管理表 +週次報告(3h*1*3) | G11: PJ管理、定例会、各工程完了レビュー | H11: =SUM(H4:H10)*0.15+I11 -> 3 | I11: =9/8 -> 1.125
B12: 合計 | E12: =SUM(E4:E11) -> 0.78 | H12: =SUM(H4:H11) -> 15.5

Sheet 見積（XenApp）
B1: システム名： | C1: XenApp
B3: 工程 | C3: タスク | D3: 概算工数 | E3: 工数計 | F3: 成果物 | G3: 備考 | H3: 人日
B4: 調査・要件定義 | C4: IP,ホスト名変更に伴う影響箇所調査 | D4: =ROUND(H4/20,2) -> 1 | E4: 1 | F4: 調査結果資料 | G4: IP,ホスト名使用箇所GREP調査 | H4: 20
B5: 設計 | C5: IP,ホスト名変更に伴う影響箇所対応 | D5: =ROUND(H5/20,2) -> 0.55 | E5: 0.55 | F5: 基本設計書、詳細設計書 運用ドキュメント FW設定依頼書 | G5: 設計書、運用ドキュメント修正 徳山数量確定 | H5: 11
B6: 製造 | C6: クライアントバージョンアップ | D6: =ROUND(H6/20,2) -> 0 | E6: 5.41 | F6: バージョンアップ手順書 | G6: 徳山ヤード操業サーバ：本番、検証 | H6: 0
C7: IP,ホスト名変更に伴う影響箇所対応 | D7: =ROUND(H7/20,2) -> 5.41 | F7: PG一式 | G7: 徳山ヤード操業サーバ：本番、検証 | H7: 108.25
B8: 試験 | C8: 内部テスト | D8: =ROUND(H8/20,2) -> 1.28 | E8: 1.28 | F8: テスト仕様書兼結果報告書 | G8: 各検証機とPIMSサーバ間のテスト 機能数=1 | H8: 25.5
B9: 本番稼働 | C9: アプリ移行 | D9: =ROUND(H9/20,2) -> 1.13 | E9: 3.63 | F9: 本番移行手順書 | G9: 移行手順書作成 移行作業 1システム実施 | H9: 22.5
C10: 初期流動 | D10: =ROUND(H10/20,2) -> 2.5 | F10: 初期流動管理表 | G10: 1週間×1名 | H10: 50 | I10: 加算する 人日 | J10: pj全体の 打合せ時間 | K10: １日の 基準時間 | L10: 期間(週)： 打合せ回数 | M10: 打合せ１回に かかる時間 | N10: 期間(月) | O10: 週数
B11: 管理 | C11: PJ管理 | D11: =ROUND(H11/20,2) -> 2.45 | E11: 2.45 | F11: プロジェクト計画書 課題管理表 スケジュール（WBS） 議事録 レビュー管理表 +週次報告(3h*1*3) | G11: PJ管理、定例会、各工程完了レビュー | H11: =SUM(H4:H10)*0.15+I11 -> 49.0875 | I11: =J11/K11 -> 13.5 | J11: =L11*M11 -> 108 | K11: 8 | L11: =N11*O11 -> 36 | M11: 3 | N11: 9 | O11: 4
B12: 合計 | E12: =SUM(E4:E11) -> 14.32 | H12: =SUM(H4:H11) -> 286.3375

Sheet XenAPP算出根拠
A1: 対応タスク
C3: XenApp | D3: 要件定義 | G3: =SUM(I22:I25) -> 20 | H3: 人日 | I3: =G3/20 -> 1 | J3: 人月 | K3: 準委任
D4: 基本・詳細設計 | G4: =SUM(I26:I28) -> 11 | H4: 人日 | I4: =G4/20 -> 0.55 | J4: 人月 | K4: 請負
D5: 開発 | G5: =SUM(I29:I41) -> 108.25 | H5: 人日 | I5: =G5/20 -> 5.4125 | J5: 人月 | K5: 請負
D6: 結合テスト | G6: =SUM(I42:I51) -> 17.5 | H6: 人日 | I6: =G6/20 -> 0.875 | J6: 人月 | K6: 請負
D7: 受入テスト | G7: =SUM(I52:I58) -> 20 | H7: 人日 | I7: =G7/20 -> 1 | J7: 人月 | K7: 請負
D8: 本番作業 | G8: =SUM(I59:I61) -> 72.5 | H8: 人日 | I8: =G8/20 -> 3.625 | J8: 人月 | K8: 請負/準委任 | L8: 初期流動は準委任
D9: 管理費 | E9: 15%＋会議費(週1回3時間) | F9: =36*3 -> 108 | G9: =F9/8+ROUND(SUM(G3:G8)*0.15,0) -> 50.5 | H9: 人日+20% | I9: =SUM(I3:I8)*0.2 -> 2.4925 | J9: 人月 | K9: -
D10: 合計 | G10: =SUM(G3:G9) -> 299.75 | H10: 人日 | I10: =SUM(I3:I9) -> 14.955 | J10: 人月 | K10: -
C13: 前提条件
C14: 5 | D14: 開発のエクセルの工数は、２０１９年から２０２２年にかけて行った「情報系ヒストリアン更新対応」案件で実際に修正したファイルの本数をベースにしております。
C15: 6 | D15: エクセルの本数については、要件定義時に精査し確定させます。
C16: 7 | D16: 本案件の対応内容は、向け先の変更のみで、ロジックの修正は実施しない想定をしております。
C17: 8 | D17: テストでは、エラー時にのみエビデンスを取得します。
C18: 9 | D18: 本案件のテストは、改修対象のエクセルの１割を対象にサンプリングしテストすることを想定しております。
C19: 10 | D19: 初期流動は、準委任契約を想定しており、期間中は、対象外のファイルでも可能な限り対応することを想定しております。・
B21: ◆ | C21: XenApp_PIMSDB接続ファイル向け先変更対応 | I21: 人日 | J21: 備考
D22: 要件定義 | E22: 簡易動作検証による修正方法検証 | F22: 端末へのインストール及び動作検証 | I22: 2
E23: 対象ファイル一覧の整理 | F23: 外だしファイルか、腹持ちのシート上か等の修正個所も整理したい | I23: 10
E24: テストの範囲、方式検討 | I24: 3
E25: 移行方式の検討 | I25: 5
D26: 基本・詳細設計 | E26: 変更仕様書作成 | F26: パターンごとの修正方法を整理 | I26: 3
E27: テスト仕様書の作成 | F27: 要件定義時に作成したファイル一覧を元に作成 | I27: 3
E28: 移行用ツールの設計 | F28: 移行方式に合わせて必要なツールを設計 | I28: 5
D29: 開発 | E29: 移行バッチの作成 | F29: 移行ツールの設計書に基づいたバッチの作成、複数作成することを想定 | I29: 5 | K29: 過去案件参考資料： | L29: https://app.box.com/folder/160850577328
E30: エクセルファイル | F30: 修正内容は、向け先の変更のみを想定
F31: 1ファイルあたり | G31: 10分 | H31: 1日8時間で48ファイル対応想定
H32: 48
G33: ↓前回更新時改修ファイル数 | J33: いつのどの案件か明確にしておく | K33: 前提に算出のベースを記載
F34: 北海道分 | G34: 355 | H34: =G34/$H$32 -> 7.3958333 | I34: 7.4 | K34: 要件定義で精査して確定させることを記載しておく
F35: 千葉分 | G35: 1499 | H35: =G35/$H$32 -> 31.229167 | I35: 31.3
F36: 愛知分 | G36: 348 | H36: =G36/$H$32 -> 7.25 | I36: 7.25
F37: 徳山分 | G37: 589 | H37: =G37/$H$32 -> 12.270833 | I37: 12.3
G38: 四日市は新規のため総数
F39: 四日市分 | G39: 4668 | H39: =G39/$H$32 -> 97.25 | J39: 総数
G40: 2166 | H40: =G40/$H$32 -> 45.125 | I40: 45 | J40: フォルダ構成から日付やバックアップなどの文言を含むものを目視で除外
D42: 結合テスト | E42: 移行用ツールのテスト | I42: 2
E43: エクセルの接続確認テスト | K43: 前提に、正常時のエビデンスは取得せず
F44: 1ファイルあたり | G44: 15分 | H44: 1日8時間で32ファイル対応想定 | K44: エラー時のみ取得することを記載する
F45: 各所でサンプリングしてテスト | G45: 10%程度 | K45: 前提に、改修対象の1割を対象とし、要件定義のテスト範囲決めの際に相談させていただく
...

Sheet 再見積もり_XenAPPサマリー(開発フェーズ以降)
B2: 崔再見積もり工数 | L2: 管理工数のみ
B3: 拠点 | C3: 工程 | D3: 人月 | E3: 金額 | G3: 拠点 | H3: 再見積もり | I3: 概算 | J3: 差額 | L3: 拠点 | M3: 人月 | N3: 金額
B4: 愛知 | C4: 開発 | D4: ='XenAPP算出根拠 (愛知)'!I5 -> 0.8 | E4: ='XenAPP算出根拠 (愛知)'!K5 -> 800000 | G4: 愛知 | H4: ='XenAPP算出根拠 (愛知)'!K10 -> 3072000 | I4: ='XenAPP算出根拠 (愛知)'!Q10 -> 1380000 | J4: =H4-I4 -> 1692000 | L4: 愛知 | M4: 0.38 | N4: =M4*1400000 -> 532000
B5: 徳山 | C5: 結合テスト | D5: ='XenAPP算出根拠 (愛知)'!I6 -> 0.22 | E5: ='XenAPP算出根拠 (愛知)'!K6 -> 220000 | G5: 北海道 | H5: ='XenAPP算出根拠 (北海道)'!K10 -> 2520000 | I5: ='XenAPP算出根拠 (北海道)'!Q10 -> 1782000 | J5: =H5-I5 -> 738000 | L5: 北海道 | M5: 0.59 | N5: =M5*1400000 -> 826000
B6: 徳山 | C6: 受入テスト | D6: ='XenAPP算出根拠 (愛知)'!I7 -> 0.15 | E6: ='XenAPP算出根拠 (愛知)'!K7 -> 150000 | G6: 千葉 | H6: ='XenAPP算出根拠 (千葉)'!K10 -> 6262000 | I6: ='XenAPP算出根拠 (千葉)'!Q10 -> 3682000 | J6: =H6-I6 -> 2580000 | L6: 千葉 | M6: 0.38 | N6: =M6*1400000 -> 532000
B7: 徳山 | C7: 本番作業 | D7: ='XenAPP算出根拠 (愛知)'!I8 -> 1.23 | E7: ='XenAPP算出根拠 (愛知)'!K8 -> 1230000 | G7: 徳山 | H7: ='XenAPP算出根拠 (徳山) '!K10 -> 4726000 | I7: ='XenAPP算出根拠 (徳山) '!Q10 -> 2210000 | J7: =H7-I7 -> 2516000 | L7: 徳山 | M7: 0.48 | N7: =M7*1400000 -> 672000
B8: 徳山 | C8: 管理費 | D8: ='XenAPP算出根拠 (愛知)'!I9 -> 0.48 | E8: ='XenAPP算出根拠 (愛知)'!K9 -> 672000 | G8: 四日市 | H8: 0 | I8: ='XenAPP算出根拠 (四日市) '!Q10 -> 4636000 | J8: =H8-I8 -> -4636000 | L8: 工場システム | M8: 0.35 | N8: =M8*1400000 -> 490000
B9: 徳山 | C9: 小計 | D9: ='XenAPP算出根拠 (愛知)'!I10 -> 2.88 | E9: ='XenAPP算出根拠 (愛知)'!K10 -> 3072000 | G9: 工場システム | H9: 1970000 | I9: 1970000 | J9: =H9-I9 -> 0 | L9: 合計 | M9: =SUM(M4:M8) -> 2.18 | N9: =SUM(N4:N8) -> 3052000
B10: 北海道 | C10: 開発 | D10: ='XenAPP算出根拠 (北海道)'!I5 -> 0.3 | E10: {='XenAPP算出根拠 (北海道)'!K5:K10} -> 300000 | G10: 合計 | H10: =SUM(H4:H9) -> 18550000 | I10: =SUM(I4:I9) -> 15660000 | J10: =SUM(J4:J9) -> 2890000
B11: 北海道 | C11: 結合テスト | D11: ='XenAPP算出根拠 (北海道)'!I6 -> 0.13 | E11: 130000
B12: 北海道 | C12: 受入テスト | D12: ='XenAPP算出根拠 (北海道)'!I7 -> 0.3 | E12: 300000
B13: 北海道 | C13: 本番作業 | D13: ='XenAPP算出根拠 (北海道)'!I8 -> 1.23 | E13: 1230000
B14: 北海道 | C14: 管理費 | D14: ='XenAPP算出根拠 (北海道)'!I9 -> 0.4 | E14: 560000
B15: 北海道 | C15: 小計 | D15: ='XenAPP算出根拠 (北海道)'!I10 -> 2.36 | E15: 2520000
B16: 千葉 | C16: 開発 | D16: {='XenAPP算出根拠 (千葉)'!I5:I10} -> 1.93 | E16: {='XenAPP算出根拠 (千葉)'!K5:K10} -> 1930000
B17: 千葉 | C17: 結合テスト | D17: 0.68 | E17: 680000
B18: 千葉 | C18: 受入テスト | D18: 0.8 | E18: 800000
B19: 千葉 | C19: 本番作業 | D19: 1.48 | E19: 1480000
B20: 千葉 | C20: 管理費 | D20: 0.98 | E20: 1372000
B21: 千葉 | C21: 小計 | D21: 5.87 | E21: 6262000
B22: 徳山 | C22: 開発 | D22: {='XenAPP算出根拠 (徳山) '!I5:I10} -> 1.25 | E22: {='XenAPP算出根拠 (徳山) '!K5:K10} -> 1250000
B23: 徳山 | C23: 結合テスト | D23: 0.41 | E23: 410000
B24: 徳山 | C24: 受入テスト | D24: 0.55 | E24: 550000
B25: 徳山 | C25: 本番作業 | D25: 1.48 | E25: 1480000
B26: 徳山 | C26: 管理費 | D26: 0.74 | E26: 1036000
B27: 徳山 | C27: 小計 | D27: 4.43 | E27: 4726000
B28: 四日市 | C28: 開発 | D28: {='XenAPP算出根拠 (四日市) '!I5:I10} -> 1.55 | E28: {='XenAPP算出根拠 (四日市) '!K5:K10} -> 1550000
B29: 四日市 | C29: 結合テスト | D29: 0.58 | E29: 580000
B30: 四日市 | C30: 受入テスト | D30: 0.15 | E30: 150000
B31: 四日市 | C31: 本番作業 | D31: 1.23 | E31: 1230000
B32: 四日市 | C32: 管理費 | D32: 0.71 | E32: 994000
B33: 四日市 | C33: 小計 | D33: 4.22 | E33: 4504000

Sheet XenAPP算出根拠 (愛知)
A1: 対応タスク
K2: 再見積もり | Q2: 参考（概算見積）
C3: XenApp | D3: 要件定義 | G3: =SUM(I22:I25) -> 0 | H3: 人日 | I3: =G3/20 -> 0 | J3: 人月 | L3: 準委任
D4: 基本・詳細設計 | G4: =SUM(I26:I28) -> 0 | H4: 人日 | I4: =G4/20 -> 0 | J4: 人月 | L4: 請負
D5: 開発 | G5: =SUM(I29:I41) -> 16 | H5: 人日 | I5: =ROUNDUP(G5/20,2) -> 0.8 | J5: 人月 | K5: =I5*1000000 -> 800000 | L5: 請負 | Q5: 410000
D6: 結合テスト | G6: =SUM(I42:I49) -> 4.3 | H6: 人日 | I6: =ROUNDUP(G6/20,2) -> 0.22 | J6: 人月 | K6: =I6*1000000 -> 220000 | L6: 請負 | Q6: 90000
D7: 受入テスト | G7: =SUM(I50:I56) -> 3 | H7: 人日 | I7: =ROUNDUP(G7/20,2) -> 0.15 | J7: 人月 | K7: =I7*1000000 -> 150000 | L7: 請負 | Q7: 150000
D8: 本番作業 | G8: =SUM(I57:I59) -> 24.5 | H8: 人日 | I8: =ROUNDUP(G8/20,2) -> 1.23 | J8: 人月 | K8: =I8*1000000 -> 1230000 | L8: 請負/準委任 | M8: 初期流動は準委任 | Q8: 230000
D9: 管理費 | E9: 15%＋会議費(週1回3時間) | F9: =36*3 -> 108 | G9: =F9/8+ROUND(SUM(G3:G8)*0.15,0) -> 20.5 | H9: 人日+20% | I9: =ROUNDUP(SUM(I3:I8)*0.2,2) -> 0.48 | J9: 人月 | K9: =I9*1400000 -> 672000 | L9: - | Q9: 500000
D10: 合計 | G10: =SUM(G3:G9) -> 68.3 | H10: 人日 | I10: =SUM(I3:I9) -> 2.88 | J10: 人月 | K10: =SUM(K3:K9) -> 3072000 | L10: - | Q10: =SUM(Q5:Q9) -> 1380000
P11: 差額 | Q11: =K10-+Q10 -> 1692000
C13: 前提条件
C14: 5 | D14: 開発のエクセルの工数は、２０１９年から２０２２年にかけて行った「情報系ヒストリアン更新対応」案件で実際に修正したファイルの本数をベースにしております。
C15: 6 | D15: エクセルの本数については、要件定義時に精査し確定させます。
C16: 7 | D16: 本案件の対応内容は、向け先の変更のみで、ロジックの修正は実施しない想定をしております。
C17: 8 | D17: テストでは、エラー時にのみエビデンスを取得します。
C18: 9 | D18: 本案件のテストは、出光様指定の日報、月報ファイルをテストすることを想定しております。
C19: 10 | D19: 初期流動は、準委任契約を想定しており、期間中は、対象外のファイルでも可能な限り対応することを想定しております。・
B21: ◆ | C21: XenApp_PIMSDB接続ファイル向け先変更対応 | I21: 人日 | J21: 備考
D22: 要件定義 | E22: 簡易動作検証による修正方法検証 | F22: 端末へのインストール及び動作検証
E23: 対象ファイル一覧の整理 | F23: 外だしファイルか、腹持ちのシート上か等の修正個所も整理したい
E24: テストの範囲、方式検討
E25: 移行方式の検討
D26: 基本・詳細設計 | E26: 変更仕様書作成 | F26: パターンごとの修正方法を整理
E27: テスト仕様書の作成 | F27: 要件定義時に作成したファイル一覧を元に作成
E28: 移行用ツールの設計 | F28: 移行方式に合わせて必要なツールを設計
D29: 開発 | E29: 移行バッチの作成 | F29: 移行ツールの設計書に基づいたバッチの作成、複数作成することを想定 | I29: 5 | L29: 過去案件参考資料： | M29: https://app.box.com/folder/160850577328
E30: タグ調査 | F30: 1ファイルあたり | G30: 10分 | H30: 1日8時間で10ファイル対応想定 | J30: 追加タスク
G31: 53 | I31: =G31/10 -> 5.3
E32: エクセルファイル | F32: 修正内容は、向け先の変更のみを想定
F33: 1ファイルあたり | G33: 10分 | H33: 1日8時間で48ファイル対応想定
H34: 48
G35: ↓改修ファイル数 | J35: いつのどの案件か明確にしておく | L35: 前提に算出のベースを記載
F36: 愛知分 | G36: 233 | H36: =G36/$H$34 -> 4.8541667 | I36: 5.1
E38: リリースまでのファイル更新対応
F39: リリースまでに修正ファイル20%程更新が発生すると想定
F40: 愛知分 | G40: =ROUNDUP($G36*0.2,0) -> 47 | H40: =G40/$H$34 -> 0.97916667 | I40: 0.6
D42: 結合テスト | E42: 移行用ツールのテスト | I42: 2
E43: エクセルの接続確認テスト | L43: 前提に、正常時のエビデンスは取得せず
F44: 1ファイルあたり | G44: 15⇒20分 | H44: 1日8時間で24ファイル対応想定 | L44: エラー時のみ取得することを記載する
...

Sheet XenAPP算出根拠 (北海道)
A1: 対応タスク
K2: 再見積もり | Q2: 参考（概算見積）
C3: XenApp | D3: 要件定義 | G3: =SUM(I22:I25) -> 0 | H3: 人日 | I3: =G3/20 -> 0 | J3: 人月 | L3: 準委任
D4: 基本・詳細設計 | G4: =SUM(I26:I28) -> 0 | H4: 人日 | I4: =G4/20 -> 0 | J4: 人月 | L4: 請負
D5: 開発 | G5: =SUM(I29:I41) -> 6 | H5: 人日 | I5: =ROUNDUP(G5/20,2) -> 0.3 | J5: 人月 | K5: =I5*1000000 -> 300000 | L5: 請負 | Q5: 420000
D6: 結合テスト | G6: =SUM(I42:I49) -> 2.5 | H6: 人日 | I6: =ROUNDUP(G6/20,2) -> 0.13 | J6: 人月 | K6: =I6*1000000 -> 130000 | L6: 請負 | Q6: 90000
D7: 受入テスト | G7: =SUM(I50:I56) -> 6 | H7: 人日 | I7: =ROUNDUP(G7/20,2) -> 0.3 | J7: 人月 | K7: =I7*1000000 -> 300000 | L7: 請負 | Q7: 150000
D8: 本番作業 | G8: =SUM(I57:I59) -> 24.5 | H8: 人日 | I8: =ROUNDUP(G8/20,2) -> 1.23 | J8: 人月 | K8: =I8*1000000 -> 1230000 | L8: 請負/準委任 | M8: 初期流動は準委任 | Q8: 730000
D9: 管理費 | E9: 15%＋会議費(週1回3時間) | F9: =36*3 -> 108 | G9: =F9/8+ROUND(SUM(G3:G8)*0.15,0) -> 19.5 | H9: 人日+20% | I9: =ROUNDUP(SUM(I3:I8)*0.2,2) -> 0.4 | J9: 人月 | K9: =I9*1400000 -> 560000 | L9: - | Q9: 392000
D10: 合計 | G10: =SUM(G3:G9) -> 58.5 | H10: 人日 | I10: =SUM(I3:I9) -> 2.36 | J10: 人月 | K10: =SUM(K3:K9) -> 2520000 | L10: - | Q10: =SUM(Q5:Q9) -> 1782000
P11: 差額 | Q11: =K10-+Q10 -> 738000
C13: 前提条件
C14: 5 | D14: 開発のエクセルの工数は、２０１９年から２０２２年にかけて行った「情報系ヒストリアン更新対応」案件で実際に修正したファイルの本数をベースにしております。
C15: 6 | D15: エクセルの本数については、要件定義時に精査し確定させます。
C16: 7 | D16: 本案件の対応内容は、向け先の変更のみで、ロジックの修正は実施しない想定をしております。
C17: 8 | D17: テストでは、エラー時にのみエビデンスを取得します。
C18: 9 | D18: 本案件のテストは、出光様指定の日報、月報ファイルをテストすることを想定しております。
C19: 10 | D19: 初期流動は、準委任契約を想定しており、期間中は、対象外のファイルでも可能な限り対応することを想定しております。・
B21: ◆ | C21: XenApp_PIMSDB接続ファイル向け先変更対応 | I21: 人日 | J21: 備考
D22: 要件定義 | E22: 簡易動作検証による修正方法検証 | F22: 端末へのインストール及び動作検証
E23: 対象ファイル一覧の整理 | F23: 外だしファイルか、腹持ちのシート上か等の修正個所も整理したい
E24: テストの範囲、方式検討
E25: 移行方式の検討
D26: 基本・詳細設計 | E26: 変更仕様書作成 | F26: パターンごとの修正方法を整理
E27: テスト仕様書の作成 | F27: 要件定義時に作成したファイル一覧を元に作成
E28: 移行用ツールの設計 | F28: 移行方式に合わせて必要なツールを設計
D29: 開発 | E29: 移行バッチの作成 | F29: 移行ツールの設計書に基づいたバッチの作成、複数作成することを想定 | I29: 1 | L29: 過去案件参考資料： | M29: https://app.box.com/folder/160850577328
E30: タグ調査 | F30: 1ファイルあたり | H30: 1日8時間で8ファイル対応想定 | J30: 追加タスク(愛知実績より対象ファイル数修正) 58ファイル⇒7人日
G31: 12 | I31: =ROUNDUP(G31/7,1) -> 1.8 | J31: 7/7(月)対象本数連絡あり
E32: エクセルファイル | F32: 修正内容は、向け先の変更のみを想定
F33: 1ファイルあたり | G33: 10分 | H33: 1日8時間で48ファイル対応想定
H34: 48
G35: ↓改修ファイル数 | J35: いつのどの案件か明確にしておく | L35: 前提に算出のベースを記載
F36: 北海道分 | G36: 124 | H36: =G36/$H$34 -> 2.5833333 | I36: =ROUNDUP(H36,1) -> 2.6
E38: リリースまでのファイル更新対応
F39: リリースまでに修正ファイル20%程更新が発生すると想定
F40: 北海道分 | G40: =ROUNDUP($G36*0.2,0) -> 25 | H40: =G40/$H$34 -> 0.52083333 | I40: =ROUNDUP(H40,1) -> 0.6
D42: 結合テスト | E42: 移行用ツールのテスト | I42: 2
E43: エクセルの接続確認テスト | L43: 前提に、正常時のエビデンスは取得せず
F44: 1ファイルあたり | G44: 15⇒20分 | H44: 1日8時間で24ファイル対応想定 | L44: エラー時のみ取得することを記載する
...

Sheet XenAPP算出根拠 (千葉)
A1: 対応タスク
K2: 再見積もり | Q2: 参考（概算見積）
C3: XenApp | D3: 要件定義 | G3: =SUM(I22:I25) -> 0 | H3: 人日 | I3: =G3/20 -> 0 | J3: 人月 | L3: 準委任
D4: 基本・詳細設計 | G4: =SUM(I26:I28) -> 0 | H4: 人日 | I4: =G4/20 -> 0 | J4: 人月 | L4: 請負
D5: 開発 | G5: =SUM(I29:I41) -> 38.5 | H5: 人日 | I5: =ROUNDUP(G5/20,2) -> 1.93 | J5: 人月 | K5: =I5*1000000 -> 1930000 | L5: 請負 | Q5: 1620000
D6: 結合テスト | G6: =SUM(I42:I49) -> 13.5 | H6: 人日 | I6: =ROUNDUP(G6/20,2) -> 0.68 | J6: 人月 | K6: =I6*1000000 -> 680000 | L6: 請負 | Q6: 270000
D7: 受入テスト | G7: =SUM(I50:I56) -> 16 | H7: 人日 | I7: =ROUNDUP(G7/20,2) -> 0.8 | J7: 人月 | K7: =I7*1000000 -> 800000 | L7: 請負 | Q7: 250000
D8: 本番作業 | G8: =SUM(I57:I59) -> 29.5 | H8: 人日 | I8: =ROUNDUP(G8/20,2) -> 1.48 | J8: 人月 | K8: =I8*1000000 -> 1480000 | L8: 請負/準委任 | M8: 初期流動は準委任 | Q8: 730000
D9: 管理費 | E9: 15%＋会議費(週1回3時間) | F9: =36*3 -> 108 | G9: =F9/8+ROUND(SUM(G3:G8)*0.15,0) -> 28.5 | H9: 人日+20% | I9: =ROUNDUP(SUM(I3:I8)*0.2,2) -> 0.98 | J9: 人月 | K9: =I9*1400000 -> 1372000 | L9: - | Q9: 812000
D10: 合計 | G10: =SUM(G3:G9) -> 126 | H10: 人日 | I10: =SUM(I3:I9) -> 5.87 | J10: 人月 | K10: =SUM(K3:K9) -> 6262000 | L10: - | Q10: =SUM(Q5:Q9) -> 3682000
P11: 差額 | Q11: =K10-+Q10 -> 2580000
C13: 前提条件
C14: 5 | D14: 開発のエクセルの工数は、２０１９年から２０２２年にかけて行った「情報系ヒストリアン更新対応」案件で実際に修正したファイルの本数をベースにしております。
C15: 6 | D15: エクセルの本数については、要件定義時に精査し確定させます。
C16: 7 | D16: 本案件の対応内容は、向け先の変更のみで、ロジックの修正は実施しない想定をしております。
C17: 8 | D17: テストでは、エラー時にのみエビデンスを取得します。
C18: 9 | D18: 本案件のテストは、出光様指定の日報、月報ファイルをテストすることを想定しております。
C19: 10 | D19: 初期流動は、準委任契約を想定しており、期間中は、対象外のファイルでも可能な限り対応することを想定しております。・
B21: ◆ | C21: XenApp_PIMSDB接続ファイル向け先変更対応 | I21: 人日 | J21: 備考
D22: 要件定義 | E22: 簡易動作検証による修正方法検証 | F22: 端末へのインストール及び動作検証
E23: 対象ファイル一覧の整理 | F23: 外だしファイルか、腹持ちのシート上か等の修正個所も整理したい
E24: テストの範囲、方式検討
E25: 移行方式の検討
D26: 基本・詳細設計 | E26: 変更仕様書作成 | F26: パターンごとの修正方法を整理
E27: テスト仕様書の作成 | F27: 要件定義時に作成したファイル一覧を元に作成
E28: 移行用ツールの設計 | F28: 移行方式に合わせて必要なツールを設計
D29: 開発 | E29: 移行バッチの作成 | F29: 移行ツールの設計書に基づいたバッチの作成、複数作成することを想定 | I29: 1 | L29: 過去案件参考資料： | M29: https://app.box.com/folder/160850577328
E30: タグ調査 | F30: 1ファイルあたり | H30: 1日8時間で8ファイル対応想定 | J30: 追加タスク
G31: 60 | I31: =ROUNDUP(G31/7,1) -> 8.6 | J31: 愛知と同程度（60本）程度を想定
E32: エクセルファイル | F32: 修正内容は、向け先の変更のみを想定
F33: 1ファイルあたり | G33: 10分 | H33: 1日8時間で48ファイル対応想定
H34: 48
G35: ↓改修ファイル数 | J35: いつのどの案件か明確にしておく | L35: 前提に算出のベースを記載
F36: 千葉分 | G36: 1151 | H36: =G36/$H$34 -> 23.979167 | I36: =ROUNDUP(H36,1) -> 24 | J36: 要件定義調査結果1104 追加：出光様追加ファイル47
E38: リリースまでのファイル更新対応
F39: リリースまでに修正ファイル20%程更新が発生すると想定
F40: 千葉分 | G40: =ROUNDUP($G36*0.2,0) -> 231 | H40: =G40/$H$34 -> 4.8125 | I40: =ROUNDUP(H40,1) -> 4.9
D42: 結合テスト | E42: 移行用ツールのテスト | I42: 2
E43: エクセルの接続確認テスト | L43: 前提に、正常時のエビデンスは取得せず
F44: 1ファイルあたり | G44: 15⇒20分 | H44: 1日8時間で24ファイル対応想定 | L44: エラー時のみ取得することを記載する
...

Sheet XenAPP算出根拠 (千葉) (追加)
A1: 対応タスク
K2: 再見積もり | Q2: 参考（概算見積）
C3: XenApp | D3: 要件定義 | G3: =SUM(I20:I23) -> 0 | H3: 人日 | I3: =G3/20 -> 0 | J3: 人月 | L3: 準委任
D4: 基本・詳細設計 | G4: =SUM(I24:I26) -> 0 | H4: 人日 | I4: =G4/20 -> 0 | J4: 人月 | L4: 請負
D5: 開発 | G5: =SUM(I27:I41) -> 35.8 | H5: 人日 | I5: =ROUNDUP(G5/20,2) -> 1.79 | J5: 人月 | K5: =I5*1000000 -> 1790000 | L5: 請負 | Q5: 1620000
D6: 結合テスト | G6: =SUM(I42:I49) -> 0 | H6: 人日 | I6: =ROUNDUP(G6/20,2) -> 0 | J6: 人月 | K6: =I6*1000000 -> 0 | L6: 請負 | Q6: 270000
D7: 受入テスト | G7: =SUM(I50:I56) -> 5 | H7: 人日 | I7: =ROUNDUP(G7/20,2) -> 0.25 | J7: 人月 | K7: =I7*1000000 -> 250000 | L7: 請負 | Q7: 250000
D8: 本番作業 | G8: =SUM(I57:I59) -> 0 | H8: 人日 | I8: =ROUNDUP(G8/20,2) -> 0 | J8: 人月 | K8: =I8*1000000 -> 0 | L8: 請負/準委任 | M8: 初期流動は準委任 | Q8: 730000
D9: 管理費 | E9: 15%＋会議費(週1回3時間) | G9: =F9/8+ROUND(SUM(G3:G8)*0.15,0) -> 6 | H9: 人日+15% | I9: =ROUNDUP(SUM(I3:I8)*0.2,2) -> 0.41 | J9: 人月 | K9: =I9*1400000 -> 574000 | L9: - | Q9: 812000
D10: 合計 | G10: =SUM(G3:G9) -> 46.8 | H10: 人日 | I10: =SUM(I3:I9) -> 2.45 | J10: 人月 | K10: =SUM(K3:K9) -> 2614000 | L10: - | Q10: =SUM(Q5:Q9) -> 3682000
P11: 差額 | Q11: =K10-+Q10 -> -1068000
C13: 前提条件
C14: 1 | D14: 本案件の対応内容は、向け先の変更のみで、ロジックの修正は実施しない想定をしております。
C15: 2 | D15: テストでは、エラー時にのみエビデンスを取得します。
C16: 3 | D16: 追加要望のテストは出光様にて確認とし、テストは簡易動作確認として10ファイル程度の確認とします。
C17: 4 | D17: 本番リリース、初期流動については千葉の対応でお見積りをした工数に含めております。
B19: ◆ | C19: XenApp_PIMSDB接続ファイル向け先変更対応 | I19: 人日 | J19: 備考
D20: 要件定義 | E20: 簡易動作検証による修正方法検証 | F20: 端末へのインストール及び動作検証
E21: 対象ファイル一覧の整理 | F21: 外だしファイルか、腹持ちのシート上か等の修正個所も整理したい
E22: テストの範囲、方式検討
E23: 移行方式の検討
D24: 基本・詳細設計 | E24: 変更仕様書作成 | F24: パターンごとの修正方法を整理
E25: テスト仕様書の作成 | F25: 要件定義時に作成したファイル一覧を元に作成
E26: 移行用ツールの設計 | F26: 移行方式に合わせて必要なツールを設計
D27: 開発 | E27: 移行バッチの作成 | F27: 移行ツールの設計書に基づいたバッチの作成、複数作成することを想定 | L27: 過去案件参考資料： | M27: https://app.box.com/folder/160850577328
E28: タグ調査 | F28: 1ファイルあたり | H28: 1日8時間で8ファイル対応想定
I29: =ROUNDUP(G29/7,1) -> 0 | J29: タグ調査不要
E30: エクセルファイル | F30: 修正内容は、向け先の変更のみを想定 | I30: 5 | J30: 修正チェックリストメンテナンス
I31: 3 | J31: ファイルコピー
F32: 1ファイルあたり | H32: 1日8時間で130ファイル対応想定
H33: 130
G34: ↓改修ファイル数 | J34: いつのどの案件か明確にしておく | L34: 前提に算出のベースを記載
F35: 千葉分 | G35: 3540 | H35: =G35/$H$33 -> 27.230769 | I35: =ROUNDUP(H35,1) -> 27.3 | J35: 分析ツール実行、ホスト名修正 | K35: ※千葉(1151)で分析5日、ホスト名変換で3日（ツール実行エラーにより複数回実行が必要であった）
I36: 0.5 | J36: ファイル配備・簡易動作検証（10ファイル程度） | K36: 本数約3倍のため 8 *3 +バッファ =27人日
E38: リリースまでのファイル更新対応
F39: リリースまでに修正ファイル20%程更新が発生すると想定
F40: 千葉分 | H40: =G40/$H$33 -> 0 | I40: =ROUNDUP(H40,1) -> 0
D42: 結合テスト | E42: 移行用ツールのテスト
E43: エクセルの接続確認テスト | L43: 前提に、正常時のエビデンスは取得せず
F44: 1ファイルあたり | G44: 15⇒20分 | H44: 1日8時間で24ファイル対応想定 | L44: エラー時のみ取得することを記載する
...

Sheet XenAPP算出根拠 (徳山) 
A1: 対応タスク
K2: 再見積もり | Q2: 参考（概算見積）
C3: XenApp | D3: 要件定義 | G3: =SUM(I22:I25) -> 0 | H3: 人日 | I3: =G3/20 -> 0 | J3: 人月 | L3: 準委任
D4: 基本・詳細設計 | G4: =SUM(I26:I28) -> 0 | H4: 人日 | I4: =G4/20 -> 0 | J4: 人月 | L4: 請負
D5: 開発 | G5: =SUM(I29:I41) -> 25 | H5: 人日 | I5: =ROUNDUP(G5/20,2) -> 1.25 | J5: 人月 | K5: =I5*1000000 -> 1250000 | L5: 請負 | Q5: 670000
D6: 結合テスト | G6: =SUM(I42:I49) -> 8.2 | H6: 人日 | I6: =ROUNDUP(G6/20,2) -> 0.41 | J6: 人月 | K6: =I6*1000000 -> 410000 | L6: 請負 | Q6: 120000
D7: 受入テスト | G7: =SUM(I50:I56) -> 11 | H7: 人日 | I7: =ROUNDUP(G7/20,2) -> 0.55 | J7: 人月 | K7: =I7*1000000 -> 550000 | L7: 請負 | Q7: 200000
D8: 本番作業 | G8: =SUM(I57:I59) -> 29.5 | H8: 人日 | I8: =ROUNDUP(G8/20,2) -> 1.48 | J8: 人月 | K8: =I8*1000000 -> 1480000 | L8: 請負/準委任 | M8: 初期流動は準委任 | Q8: 730000
D9: 管理費 | E9: 15%＋会議費(週1回3時間) | F9: =36*3 -> 108 | G9: =F9/8+ROUND(SUM(G3:G8)*0.15,0) -> 24.5 | H9: 人日+20% | I9: =ROUNDUP(SUM(I3:I8)*0.2,2) -> 0.74 | J9: 人月 | K9: =I9*1400000 -> 1036000 | L9: - | Q9: 490000
D10: 合計 | G10: =SUM(G3:G9) -> 98.2 | H10: 人日 | I10: =SUM(I3:I9) -> 4.43 | J10: 人月 | K10: =SUM(K3:K9) -> 4726000 | L10: - | Q10: =SUM(Q5:Q9) -> 2210000
P11: 差額 | Q11: =K10-Q10 -> 2516000
C13: 前提条件
C14: 5 | D14: 開発のエクセルの工数は、２０１９年から２０２２年にかけて行った「情報系ヒストリアン更新対応」案件で実際に修正したファイルの本数をベースにしております。
C15: 6 | D15: エクセルの本数については、要件定義時に精査し確定させます。
C16: 7 | D16: 本案件の対応内容は、向け先の変更のみで、ロジックの修正は実施しない想定をしております。
C17: 8 | D17: テストでは、エラー時にのみエビデンスを取得します。
C18: 9 | D18: 本案件のテストは、出光様指定の日報、月報ファイルをテストすることを想定しております。
C19: 10 | D19: 初期流動は、準委任契約を想定しており、期間中は、対象外のファイルでも可能な限り対応することを想定しております。・
B21: ◆ | C21: XenApp_PIMSDB接続ファイル向け先変更対応 | I21: 人日 | J21: 備考
D22: 要件定義 | E22: 簡易動作検証による修正方法検証 | F22: 端末へのインストール及び動作検証
E23: 対象ファイル一覧の整理 | F23: 外だしファイルか、腹持ちのシート上か等の修正個所も整理したい
E24: テストの範囲、方式検討
E25: 移行方式の検討
D26: 基本・詳細設計 | E26: 変更仕様書作成 | F26: パターンごとの修正方法を整理
E27: テスト仕様書の作成 | F27: 要件定義時に作成したファイル一覧を元に作成
E28: 移行用ツールの設計 | F28: 移行方式に合わせて必要なツールを設計
D29: 開発 | E29: 移行バッチの作成 | F29: 移行ツールの設計書に基づいたバッチの作成、複数作成することを想定 | I29: 1 | L29: 過去案件参考資料： | M29: https://app.box.com/folder/160850577328
E30: タグ調査 | F30: 1ファイルあたり | H30: 1日8時間で8ファイル対応想定 | J30: 追加タスク
G31: 60 | I31: =ROUNDUP(G31/7,1) -> 8.6 | J31: 愛知と同程度（60本）程度を想定
E32: エクセルファイル | F32: 修正内容は、向け先の変更のみを想定
F33: 1ファイルあたり | G33: 10分 | H33: 1日8時間で48ファイル対応想定
H34: 48
G35: ↓改修ファイル数 | J35: いつのどの案件か明確にしておく | L35: 前提に算出のベースを記載
F36: 徳山分 | G36: 614 | H36: =G36/$H$34 -> 12.791667 | I36: =ROUNDUP(H36,1) -> 12.8
E38: リリースまでのファイル更新対応
F39: リリースまでに修正ファイル20%程更新が発生すると想定
F40: 徳山分 | G40: =ROUNDUP($G36*0.2,0) -> 123 | H40: =G40/$H$34 -> 2.5625 | I40: =ROUNDUP(H40,1) -> 2.6
D42: 結合テスト | E42: 移行用ツールのテスト | I42: 2
E43: エクセルの接続確認テスト | L43: 前提に、正常時のエビデンスは取得せず
F44: 1ファイルあたり | G44: 15⇒20分 | H44: 1日8時間で24ファイル対応想定 | L44: エラー時のみ取得することを記載する
...

Sheet XenAPP算出根拠 (四日市) 
A1: 対応タスク
K2: 再見積もり | Q2: 参考（概算見積）
C3: XenApp | D3: 要件定義 | G3: =SUM(I22:I25) -> 0 | H3: 人日 | I3: =G3/20 -> 0 | J3: 人月 | L3: 準委任
D4: 基本・詳細設計 | G4: =SUM(I26:I28) -> 0 | H4: 人日 | I4: =G4/20 -> 0 | J4: 人月 | L4: 請負
D5: 開発 | G5: =SUM(I29:I41) -> 31 | H5: 人日 | I5: =ROUNDUP(G5/20,2) -> 1.55 | J5: 人月 | K5: =I5*1000000 -> 1550000 | L5: 請負 | P5: 2.3 | Q5: 2300000
D6: 結合テスト | G6: =SUM(I42:I49) -> 11.6 | H6: 人日 | I6: =ROUNDUP(G6/20,2) -> 0.58 | J6: 人月 | K6: =I6*1000000 -> 580000 | L6: 請負 | P6: 0.33 | Q6: 334000
D7: 受入テスト | G7: =SUM(I50:I56) -> 3 | H7: 人日 | I7: =ROUNDUP(G7/20,2) -> 0.15 | J7: 人月 | K7: =I7*1000000 -> 150000 | L7: 請負 | P7: 0.25 | Q7: 250000
D8: 本番作業 | G8: =SUM(I57:I59) -> 24.5 | H8: 人日 | I8: =ROUNDUP(G8/20,2) -> 1.23 | J8: 人月 | K8: =I8*1000000 -> 1230000 | L8: 請負/準委任 | M8: 初期流動は準委任 | P8: 0.23 | Q8: 730000
D9: 管理費 | E9: 15%＋会議費(週1回3時間) | F9: =36*3 -> 108 | G9: =F9/8+ROUND(SUM(G3:G8)*0.15,0) -> 24.5 | H9: 人日+20% | I9: =ROUNDUP(SUM(I3:I8)*0.2,2) -> 0.71 | J9: 人月 | K9: =I9*1400000 -> 994000 | L9: - | P9: 0.73 | Q9: 1022000
D10: 合計 | G10: =SUM(G3:G9) -> 94.6 | H10: 人日 | I10: =SUM(I3:I9) -> 4.22 | J10: 人月 | K10: =SUM(K3:K9) -> 4504000 | L10: - | Q10: =SUM(Q5:Q9) -> 4636000
P11: 差額 | Q11: =K10-+Q10 -> -132000
C13: 前提条件
C14: 5 | D14: 開発のエクセルの工数は、２０１９年から２０２２年にかけて行った「情報系ヒストリアン更新対応」案件で実際に修正したファイルの本数をベースにしております。
C15: 6 | D15: エクセルの本数については、要件定義時に精査し確定させます。
C16: 7 | D16: 本案件の対応内容は、向け先の変更のみで、ロジックの修正は実施しない想定をしております。
C17: 8 | D17: テストでは、エラー時にのみエビデンスを取得します。
C18: 9 | D18: 本案件のテストは、出光様指定の日報、月報ファイルをテストすることを想定しております。
C19: 10 | D19: 初期流動は、準委任契約を想定しており、期間中は、対象外のファイルでも可能な限り対応することを想定しております。・
B21: ◆ | C21: XenApp_PIMSDB接続ファイル向け先変更対応 | I21: 人日 | J21: 備考
D22: 要件定義 | E22: 簡易動作検証による修正方法検証 | F22: 端末へのインストール及び動作検証
E23: 対象ファイル一覧の整理 | F23: 外だしファイルか、腹持ちのシート上か等の修正個所も整理したい
E24: テストの範囲、方式検討
E25: 移行方式の検討
D26: 基本・詳細設計 | E26: 変更仕様書作成 | F26: パターンごとの修正方法を整理
E27: テスト仕様書の作成 | F27: 要件定義時に作成したファイル一覧を元に作成
E28: 移行用ツールの設計 | F28: 移行方式に合わせて必要なツールを設計
D29: 開発 | E29: 移行バッチの作成 | F29: 移行ツールの設計書に基づいたバッチの作成、複数作成することを想定 | I29: 1 | L29: 過去案件参考資料： | M29: https://app.box.com/folder/160850577328
E30: タグ調査 | F30: 1ファイルあたり | G30: 10分 | H30: 1日8時間で10ファイル対応想定
G31: 60 | H31: 愛知と同程度の調査対象を想定 | I31: =G31/10 -> 6
E32: エクセルファイル | F32: 修正内容は、向け先の変更のみを想定
F33: 1ファイルあたり | G33: 10分 | H33: 1日8時間で48ファイル対応想定
H34: 48
G35: ↓改修ファイル数 | J35: いつのどの案件か明確にしておく | L35: 前提に算出のベースを記載
F36: 四日市 | G36: 956 | H36: =G36/$H$34 -> 19.916667 | I36: 20
E38: リリースまでのファイル更新対応
F39: リリースまでに修正ファイル20%程更新が発生すると想定
F40: 愛知分 | G40: =ROUNDUP($G36*0.2,0) -> 192 | H40: =G40/$H$34 -> 4 | I40: 4
D42: 結合テスト | E42: 移行用ツールのテスト | I42: 2
E43: エクセルの接続確認テスト | L43: 前提に、正常時のエビデンスは取得せず
F44: 1ファイルあたり | G44: 15⇒20分 | H44: 1日8時間で24ファイル対応想定 | L44: エラー時のみ取得することを記載する
...

Sheet XenAPP事業所別見積
A2: 事業所 | B2: 工程
B3: 要件定義 | D3: 設計 | F3: 製造 | H3: テスト | J3: 受入 | L3: 本番切替 | N3: 初期流動 | P3: プロジェクト管理
B4: 工数 | C4: 金額 | D4: 工数 | E4: 金額 | F4: 工数 | G4: 金額 | H4: 工数 | I4: 金額 | J4: 工数 | K4: 金額 | L4: 工数 | M4: 金額 | N4: 工数 | O4: 金額 | P4: 工数 | Q4: 金額
A5: 全所（全般） | B5: 1 | C5: =B5*C$14 -> 1000000 | D5: 0.55 | E5: =D5*E$14 -> 550000 | F5: - | G5: - | H5: - | I5: - | J5: - | K5: - | L5: - | M5: - | N5: - | O5: - | P5: =ROUNDUP(SUM(B5,D5,F5,H5,J5,L5,N5)*0.2,2) -> 0.31 | Q5: =P5*Q$14 -> 434000 | R5: =SUM(B5,D5,F5,H5,J5,L5,N5,P5) -> 1.86 | S5: =SUM(C5,E5,G5,I5,K5,M5,O5,Q5) -> 1984000
A6: 愛知 | B6: - | C6: - | D6: - | E6: - | F6: =0.36+0.05 -> 0.41 | G6: =F6*G$14 -> 410000 | H6: =0.06+0.03 -> 0.09 | I6: =H6*I$14 -> 90000 | J6: 0.15 | K6: =J6*K$14 -> 150000 | L6: 0.23 | M6: =L6*M$14 -> 230000 | N6: 0.5 | O6: =N6*O$14 -> 500000 | P6: =ROUNDUP(SUM(B6,D6,F6,H6,J6,L6,N6)*0.2,2) -> 0.28 | Q6: =P6*Q$14 -> 392000 | R6: =SUM(B6,D6,F6,H6,J6,L6,N6,P6) -> 1.66 | S6: =SUM(C6,E6,G6,I6,K6,M6,O6,Q6) -> 1772000
A7: 北海道 | B7: - | C7: - | D7: - | E7: - | F7: =0.37+0.05 -> 0.42 | G7: =F7*G$14 -> 420000 | H7: =0.06+0.03 -> 0.09 | I7: =H7*I$14 -> 90000 | J7: 0.15 | K7: =J7*K$14 -> 150000 | L7: 0.23 | M7: =L7*M$14 -> 230000 | N7: 0.5 | O7: =N7*O$14 -> 500000 | P7: =ROUNDUP(SUM(B7,D7,F7,H7,J7,L7,N7)*0.2,2) -> 0.28 | Q7: =P7*Q$14 -> 392000 | R7: =SUM(B7,D7,F7,H7,J7,L7,N7,P7) -> 1.67 | S7: =SUM(C7,E7,G7,I7,K7,M7,O7,Q7) -> 1782000
A8: 千葉 | B8: - | C8: - | D8: - | E8: - | F8: =1.57+0.05 -> 1.62 | G8: =F8*G$14 -> 1620000 | H8: =0.24+0.03 -> 0.27 | I8: =H8*I$14 -> 270000 | J8: 0.25 | K8: =J8*K$14 -> 250000 | L8: 0.23 | M8: =L8*M$14 -> 230000 | N8: 0.5 | O8: =N8*O$14 -> 500000 | P8: =ROUNDUP(SUM(B8,D8,F8,H8,J8,L8,N8)*0.2,2) -> 0.58 | Q8: =P8*Q$14 -> 812000 | R8: =SUM(B8,D8,F8,H8,J8,L8,N8,P8) -> 3.45 | S8: =SUM(C8,E8,G8,I8,K8,M8,O8,Q8) -> 3682000
A9: 徳山 | B9: - | C9: - | D9: - | E9: - | F9: =0.62+0.05 -> 0.67 | G9: =F9*G$14 -> 670000 | H9: =0.09+0.03 -> 0.12 | I9: =H9*I$14 -> 120000 | J9: 0.2 | K9: =J9*K$14 -> 200000 | L9: 0.23 | M9: =L9*M$14 -> 230000 | N9: 0.5 | O9: =N9*O$14 -> 500000 | P9: =ROUNDUP(SUM(B9,D9,F9,H9,J9,L9,N9)*0.2,2) -> 0.35 | Q9: =P9*Q$14 -> 490000 | R9: =SUM(B9,D9,F9,H9,J9,L9,N9,P9) -> 2.07 | S9: =SUM(C9,E9,G9,I9,K9,M9,O9,Q9) -> 2210000
A10: 四日市 | B10: - | C10: - | D10: - | E10: - | F10: =2.25+0.05 -> 2.3 | G10: =F10*G$14 -> 2300000 | H10: 0.334 | I10: =H10*I$14 -> 334000 | J10: 0.25 | K10: =J10*K$14 -> 250000 | L10: 0.23 | M10: =L10*M$14 -> 230000 | N10: 0.5 | O10: =N10*O$14 -> 500000 | P10: =ROUNDUP(SUM(B10,D10,F10,H10,J10,L10,N10)*0.2,2) -> 0.73 | Q10: =P10*Q$14 -> 1022000 | R10: =SUM(B10,D10,F10,H10,J10,L10,N10,P10) -> 4.344 | S10: =SUM(C10,E10,G10,I10,K10,M10,O10,Q10) -> 4636000
A11: 合計 | B11: =SUM(B5:B10) -> 1 | C11: =SUM(C5:C10) -> 1000000 | D11: =SUM(D5:D10) -> 0.55 | E11: =SUM(E5:E10) -> 550000 | F11: =SUM(F5:F10) -> 5.42 | G11: =SUM(G5:G10) -> 5420000 | H11: =SUM(H5:H10) -> 0.904 | I11: =SUM(I5:I10) -> 904000 | ... Q11: =SUM(Q5:Q10) -> 3542000
P12: =SUM(B11,D11,F11,H11,J11,L11,N11,P11) -> 15.054 | Q12: =SUM(C11,E11,G11,I11,K11,M11,O11,Q11) -> 16066000
A14: 単価 | C14: 1000000 | E14: 1000000 | G14: 1000000 | I14: 1000000 | K14: 1000000 | M14: 1000000 | O14: 1000000 | Q14: 1400000
O15: フェーズ別管理工数
O16: 要件定義 | P16: =P5 -> 0.31 | Q16: =Q5 -> 434000
O17: 開発 | P17: =ROUNDUP(SUM(F11,H11,J11)*0.2,2)+0.02 -> 1.49 | Q17: =P17*Q14 -> 2086000
O18: 移行 | P18: =ROUNDUP(SUM(L11,N11)*0.2,2) -> 0.73 | Q18: =P18*Q14 -> 1022000
P19: =SUM(P16:P18) -> 2.53 | Q19: =SUM(Q16:Q18) -> 3542000
