Workbook
Name その他係数: 積算基準!$L$35
Name バッチ係数: 積算基準!$F$29
Name 移行切替係数: 積算基準!$K$35
Name 画面係数: 積算基準!$D$29
Name 基本設計係数: 積算基準!$E$35
Name 結合テスト係数: 積算基準!$H$35
Name 高係数: 積算基準!$E$41
Name 参照上限高: 積算基準!$E$17
Name 参照上限中: 積算基準!$F$17
Name 参照上限低: 積算基準!$G$17
Name 参照上限特高: 積算基準!$D$17
Name 参照上限特低: 積算基準!$H$17
Name 受入支援係数: 積算基準!$J$35
Name 詳細設計係数: 積算基準!$F$35
Name 製作係数: 積算基準!$G$35
Name 総合テスト係数: 積算基準!$I$35
Name 中係数: 積算基準!$F$41
Name 帳票係数: 積算基準!$E$29
Name 低係数: 積算基準!$G$41
Name 登録上限高: 積算基準!$E$16
Name 登録上限中: 積算基準!$F$16
Name 登録上限低: 積算基準!$G$16
Name 登録上限特高: 積算基準!$D$16
Name 登録上限特低: 積算基準!$H$16
Name 特高係数: 積算基準!$D$41
Name 特低係数: 積算基準!$H$41
Name 要件定義係数: 積算基準!$D$35

Sheet サマリ
B1: プロジェクト名
B4: ■御見積金額 | E4: ■最適工期
B6: 見積金額合計 | C6: =工数算出!C4 -> 7381000 | E6: 全体工期 | F6: =(工数算出!U4^(1/3))*2.4 -> 4.5943118
B9: ■御見積内訳
B11: 要件定義（SA） | C11: =工数算出!J5 -> 500000 | E11: 要件定義（SA） | F11: =F6*積算基準!P35 -> 0.36754494
B12: 基本設計（UI） | C12: =工数算出!K5 -> 700000 | E12: 基本設計（UI） | F12: =F6*積算基準!Q35 -> 0.78011123
B13: 詳細設計（SS） | C13: =工数算出!L5 -> 800000 | E13: 詳細設計（SS） | F13: =F6*積算基準!R35 -> 0.71413168
B14: 開発（PS/PG/PT） | C14: =工数算出!M5 -> 1600000 | E14: 開発（PS/PG/PT） | F14: =F6*積算基準!S35 -> 0.9625253
B15: 結合テスト（IT） | C15: =工数算出!N5 -> 800000 | E15: 結合テスト（IT） | F15: =F6*積算基準!T35 -> 0.64038982
B16: システムテスト（ST） | C16: =工数算出!O5 -> 900000 | E16: システムテスト（ST） | F16: =F6*積算基準!U35 -> 0.57829141
B17: 運用テスト（OT） | C17: =工数算出!P5 -> 300000 | E17: 運用テスト（OT） | F17: =F6*積算基準!V35 -> 0.18377247
B18: 本番移行・初期流動（RL） | C18: =工数算出!Q5 -> 500000 | E18: 本番移行・初期流動（RL） | F18: =サマリ!F6*積算基準!W35 -> 0.36754494
B19: その他 | C19: =工数算出!R5 -> 0 | E19: その他 | F19: -
B20: 調整 | C20: =工数算出!S5 -> 0 | E20: 調整 | F20: -
B21: プロジェクト管理（PM） | C21: =工数算出!T5 -> 1281000 | E21: プロジェクト管理（PM） | F21: -

Sheet 工数算出
A1: =サマリ!B1 -> プロジェクト名 | J1: SA | K1: UI | L1: SS | M1: PS/PG/PT | N1: IT | O1: ST | P1: OT | Q1: RL | R1: その他 | S1: 調整 | T1: PM | U1: 合計
F2: 工数（人日） | J2: =SUM(J10:J39) -> 9.1 | K2: =SUM(K10:K39) -> 14 | L2: =SUM(L10:L39) -> 15.3 | M2: =SUM(M10:M39) -> 30.1 | N2: =SUM(N10:N39) -> 15.3 | O2: =SUM(O10:O39) -> 16.3 | P2: =SUM(P10:P39) -> 4.9 | Q2: =SUM(Q10:Q39) -> 9.1 | ... T2: =SUM(T10:T39) -> 34 | U2: =SUM(J2:T2) -> 148.1
F3: 工数（人月） | J3: =J2/20 -> 0.455 | K3: =K2/20 -> 0.7 | L3: =L2/20 -> 0.765 | M3: =M2/20 -> 1.505 | N3: =N2/20 -> 0.765 | O3: =O2/20 -> 0.815 | P3: =P2/20 -> 0.245 | Q3: =Q2/20 -> 0.455 | ... T3: =T2/20 -> 1.7 | U3: =SUM(J3:T3) -> 7.405
A4: 見積金額 | C4: =U5 -> 7381000 | F4: 調整後工数（人月） | J4: =ROUNDUP(J3,1) -> 0.5 | K4: =ROUNDUP(K3,1) -> 0.7 | L4: =ROUNDUP(L3,1) -> 0.8 | M4: =ROUNDUP(M3,1) -> 1.6 | N4: =ROUNDUP(N3,1) -> 0.8 | O4: =ROUNDUP(O3,1) -> 0.9 | P4: =ROUNDUP(P3,1) -> 0.3 | Q4: =ROUNDUP(Q3,1) -> 0.5 | ... S4: =ROUNDUP(S3,1) -> 0 | T4: =SUM(J4:S4)*T8 -> 0.915 | U4: =SUM(J4:T4) -> 7.015
F5: 金額 | J5: =J4*J9 -> 500000 | K5: =K4*K9 -> 700000 | L5: =L4*L9 -> 800000 | M5: =M4*M9 -> 1600000 | N5: =N4*N9 -> 800000 | O5: =O4*O9 -> 900000 | P5: =P4*P9 -> 300000 | Q5: =Q4*Q9 -> 500000 | ... T5: =T4*T9 -> 1281000 | U5: =SUM(J5:T5) -> 7381000
B6: ：削除・集約候補
A7: No, | B7: 分類 | C7: 項目 | D7: 種別 | E7: 登録 | F7: 項目数 | G7: 難易度（手動） | H7: 難易度（計算） | I7: 難易度（採用） | J7: SA | K7: UI | L7: SS | M7: PS/PG/PT | N7: IT | O7: ST | P7: OT | Q7: RL | R7: その他 | S7: 調整 | T7: PM | U7: 合計（人日） | V7: 合計（人月） | W7: 金額 | X7: 備考
J8: 1 | K8: 1 | L8: 1 | M8: 1 | N8: 1 | O8: 1 | P8: 1 | Q8: 1 | R8: 1 | T8: 0.15
J9: 1000000 | K9: 1000000 | L9: 1000000 | M9: 1000000 | N9: 1000000 | O9: 1000000 | P9: 1000000 | Q9: 1000000 | R9: 1000000 | S9: 900000 | T9: 1400000
A10: 1 | C10: メニュー | D10: 画面 | E10: 有 | F10: 15 | I10: =IF(OR(E10="",F10=""),"", IF(E10="有",IF(F10<=登録上限特低,"特低",IF(F10<=登録上限低,"低",IF(F10<=登録上限中,"中",IF(F10<=登録上限高,"高","特高")))), IF(E10="無",IF(F10<=参照上限特低,"特低",IF(F10<=参照上限低,"低",IF(F10<=参照上限中,"中",IF(F10<=参照上限高,"高","特高")))),""))) -> 中 | J10: =ROUNDUP(IF($D10="画面",画面係数,IF($D10="帳票",帳票係数,IF($D10="バッチ",バッチ係数,0))) * IF($I10="特高",特高係数,IF($I10="高",高係数,IF($I10="中",中係数,IF($I10="低",低係数,IF($I10="特低",特低係数,0))))) * IF(J$7="SA",要件定義係数,IF(J$7="UI",基本設計係数,IF(J$7="SS",詳細設計係数,IF(J$7="PS/PG/PT",製作係数,IF(J$7="IT",結合テスト係数,IF(J$7="ST",総合テスト係数,IF(J$7="OT",受入支援係数,IF(J$7="RL",移行切替係数,IF(J$7="その他",その他係数,0))))))))) * J$8,1) -> 2.2 | K10: =ROUNDUP(IF($D10="画面",画面係数,IF($D10="帳票",帳票係数,IF($D10="バッチ",バッチ係数,0))) * IF($I10="特高",特高係数,IF($I10="高",高係数,IF($I10="中",中係数,IF($I10="低",低係数,IF($I10="特低",特低係数,0))))) * IF(K$7="SA",要件定義係数,IF(K$7="UI",基本設計係数,IF(K$7="SS",詳細設計係数,IF(K$7="PS/PG/PT",製作係数,IF(K$7="IT",結合テスト係数,IF(K$7="ST",総合テスト係数,IF(K$7="OT",受入支援係数,IF(K$7="RL",移行切替係数,IF(K$7="その他",その他係数,0))))))))) * K$8,1) -> 3.3 | L10: =ROUNDUP(IF($D10="画面",画面係数,IF($D10="帳票",帳票係数,IF($D10="バッチ",バッチ係数,0))) * IF($I10="特高",特高係数,IF($I10="高",高係数,IF($I10="中",中係数,IF($I10="低",低係数,IF($I10="特低",特低係数,0))))) * IF(L$7="SA",要件定義係数,IF(L$7="UI",基本設計係数,IF(L$7="SS",詳細設計係数,IF(L$7="PS/PG/PT",製作係数,IF(L$7="IT",結合テスト係数,IF(L$7="ST",総合テスト係数,IF(L$7="OT",受入支援係数,IF(L$7="RL",移行切替係数,IF(L$7="その他",その他係数,0))))))))) * L$8,1) -> 3.7 | M10: =ROUNDUP(IF($D10="画面",画面係数,IF($D10="帳票",帳票係数,IF($D10="バッチ",バッチ係数,0))) * IF($I10="特高",特高係数,IF($I10="高",高係数,IF($I10="中",中係数,IF($I10="低",低係数,IF($I10="特低",特低係数,0))))) * IF(M$7="SA",要件定義係数,IF(M$7="UI",基本設計係数,IF(M$7="SS",詳細設計係数,IF(M$7="PS/PG/PT",製作係数,IF(M$7="IT",結合テスト係数,IF(M$7="ST",総合テスト係数,IF(M$7="OT",受入支援係数,IF(M$7="RL",移行切替係数,IF(M$7="その他",その他係数,0))))))))) * M$8,1) -> 7.3 | N10: =ROUNDUP(IF($D10="画面",画面係数,IF($D10="帳票",帳票係数,IF($D10="バッチ",バッチ係数,0))) * IF($I10="特高",特高係数,IF($I10="高",高係数,IF($I10="中",中係数,IF($I10="低",低係数,IF($I10="特低",特低係数,0))))) * IF(N$7="SA",要件定義係数,IF(N$7="UI",基本設計係数,IF(N$7="SS",詳細設計係数,IF(N$7="PS/PG/PT",製作係数,IF(N$7="IT",結合テスト係数,IF(N$7="ST",総合テスト係数,IF(N$7="OT",受入支援係数,IF(N$7="RL",移行切替係数,IF(N$7="その他",その他係数,0))))))))) * N$8,1) -> 3.7 | O10: =ROUNDUP(IF($D10="画面",画面係数,IF($D10="帳票",帳票係数,IF($D10="バッチ",バッチ係数,0))) * IF($I10="特高",特高係数,IF($I10="高",高係数,IF($I10="中",中係数,IF($I10="低",低係数,IF($I10="特低",特低係数,0))))) * IF(O$7="SA",要件定義係数,IF(O$7="UI",基本設計係数,IF(O$7="SS",詳細設計係数,IF(O$7="PS/PG/PT",製作係数,IF(O$7="IT",結合テスト係数,IF(O$7="ST",総合テスト係数,IF(O$7="OT",受入支援係数,IF(O$7="RL",移行切替係数,IF(O$7="その他",その他係数,0))))))))) * O$8,1) -> 3.9 | P10: =ROUNDUP(IF($D10="画面",画面係数,IF($D10="帳票",帳票係数,IF($D10="バッチ",バッチ係数,0))) * IF($I10="特高",特高係数,IF($I10="高",高係数,IF($I10="中",中係数,IF($I10="低",低係数,IF($I10="特低",特低係数,0))))) * IF(P$7="SA",要件定義係数,IF(P$7="UI",基本設計係数,IF(P$7="SS",詳細設計係数,IF(P$7="PS/PG/PT",製作係数,IF(P$7="IT",結合テスト係数,IF(P$7="ST",総合テスト係数,IF(P$7="OT",受入支援係数,IF(P$7="RL",移行切替係数,IF(P$7="その他",その他係数,0))))))))) * P$8,1) -> 1.1 | Q10: =ROUNDUP(IF($D10="画面",画面係数,IF($D10="帳票",帳票係数,IF($D10="バッチ",バッチ係数,0))) * IF($I10="特高",特高係数,IF($I10="高",高係数,IF($I10="中",中係数,IF($I10="低",低係数,IF($I10="特低",特低係数,0))))) * IF(Q$7="SA",要件定義係数,IF(Q$7="UI",基本設計係数,IF(Q$7="SS",詳細設計係数,IF(Q$7="PS/PG/PT",製作係数,IF(Q$7="IT",結合テスト係数,IF(Q$7="ST",総合テスト係数,IF(Q$7="OT",受入支援係数,IF(Q$7="RL",移行切替係数,IF(Q$7="その他",その他係数,0))))))))) * Q$8,1) -> 2.2 | R10: =ROUNDUP(IF($D10="画面",画面係数,IF($D10="帳票",帳票係数,IF($D10="バッチ",バッチ係数,0))) * IF($I10="特高",特高係数,IF($I10="高",高係数,IF($I10="中",中係数,IF($I10="低",低係数,IF($I10="特低",特低係数,0))))) * IF(R$7="SA",要件定義係数,IF(R$7="UI",基本設計係数,IF(R$7="SS",詳細設計係数,IF(R$7="PS/PG/PT",製作係数,IF(R$7="IT",結合テスト係数,IF(R$7="ST",総合テスト係数,IF(R$7="OT",受入支援係数,IF(R$7="RL",移行切替係数,IF(R$7="その他",その他係数,0))))))))) * R$8,1) -> 0 | T10: =ROUNDUP(SUM(J10:S10)*T$8,1) -> 4.2 | U10: =SUM(J10:T10) -> 31.6 | V10: =U10/20 -> 1.58 | W10: =((J10*J$9) + (K10*K$9) + (L10*L$9) + (M10*M$9) + (N10*N$9) + (O10*O$9) + (P10*P$9) + (Q10*Q$9) + (R10*R$9) + (S10*S$9) + (T10*T$9))/20 -> 1664000
A11: 4 | C11: MEKローリー予約送信(ファイル出力) | D11: バッチ | E11: 有 | F11: 30 | I11: =IF(OR(E11="",F11=""),"", IF(E11="有",IF(F11<=登録上限特低,"特低",IF(F11<=登録上限低,"低",IF(F11<=登録上限中,"中",IF(F11<=登録上限高,"高","特高")))), IF(E11="無",IF(F11<=参照上限特低,"特低",IF(F11<=参照上限低,"低",IF(F11<=参照上限中,"中",IF(F11<=参照上限高,"高","特高")))),""))) -> 高 | J11: =ROUNDUP(IF($D11="画面",画面係数,IF($D11="帳票",帳票係数,IF($D11="バッチ",バッチ係数,0))) * IF($I11="特高",特高係数,IF($I11="高",高係数,IF($I11="中",中係数,IF($I11="低",低係数,IF($I11="特低",特低係数,0))))) * IF(J$7="SA",要件定義係数,IF(J$7="UI",基本設計係数,IF(J$7="SS",詳細設計係数,IF(J$7="PS/PG/PT",製作係数,IF(J$7="IT",結合テスト係数,IF(J$7="ST",総合テスト係数,IF(J$7="OT",受入支援係数,IF(J$7="RL",移行切替係数,IF(J$7="その他",その他係数,0))))))))) * J$8,1) -> 0.7 | K11: =ROUNDUP(IF($D11="画面",画面係数,IF($D11="帳票",帳票係数,IF($D11="バッチ",バッチ係数,0))) * IF($I11="特高",特高係数,IF($I11="高",高係数,IF($I11="中",中係数,IF($I11="低",低係数,IF($I11="特低",特低係数,0))))) * IF(K$7="SA",要件定義係数,IF(K$7="UI",基本設計係数,IF(K$7="SS",詳細設計係数,IF(K$7="PS/PG/PT",製作係数,IF(K$7="IT",結合テスト係数,IF(K$7="ST",総合テスト係数,IF(K$7="OT",受入支援係数,IF(K$7="RL",移行切替係数,IF(K$7="その他",その他係数,0))))))))) * K$8,1) -> 1.1 | L11: =ROUNDUP(IF($D11="画面",画面係数,IF($D11="帳票",帳票係数,IF($D11="バッチ",バッチ係数,0))) * IF($I11="特高",特高係数,IF($I11="高",高係数,IF($I11="中",中係数,IF($I11="低",低係数,IF($I11="特低",特低係数,0))))) * IF(L$7="SA",要件定義係数,IF(L$7="UI",基本設計係数,IF(L$7="SS",詳細設計係数,IF(L$7="PS/PG/PT",製作係数,IF(L$7="IT",結合テスト係数,IF(L$7="ST",総合テスト係数,IF(L$7="OT",受入支援係数,IF(L$7="RL",移行切替係数,IF(L$7="その他",その他係数,0))))))))) * L$8,1) -> 1.2 | M11: =ROUNDUP(IF($D11="画面",画面係数,IF($D11="帳票",帳票係数,IF($D11="バッチ",バッチ係数,0))) * IF($I11="特高",特高係数,IF($I11="高",高係数,IF($I11="中",中係数,IF($I11="低",低係数,IF($I11="特低",特低係数,0))))) * IF(M$7="SA",要件定義係数,IF(M$7="UI",基本設計係数,IF(M$7="SS",詳細設計係数,IF(M$7="PS/PG/PT",製作係数,IF(M$7="IT",結合テスト係数,IF(M$7="ST",総合テスト係数,IF(M$7="OT",受入支援係数,IF(M$7="RL",移行切替係数,IF(M$7="その他",その他係数,0))))))))) * M$8,1) -> 2.3 | N11: =ROUNDUP(IF($D11="画面",画面係数,IF($D11="帳票",帳票係数,IF($D11="バッチ",バッチ係数,0))) * IF($I11="特高",特高係数,IF($I11="高",高係数,IF($I11="中",中係数,IF($I11="低",低係数,IF($I11="特低",特低係数,0))))) * IF(N$7="SA",要件定義係数,IF(N$7="UI",基本設計係数,IF(N$7="SS",詳細設計係数,IF(N$7="PS/PG/PT",製作係数,IF(N$7="IT",結合テスト係数,IF(N$7="ST",総合テスト係数,IF(N$7="OT",受入支援係数,IF(N$7="RL",移行切替係数,IF(N$7="その他",その他係数,0))))))))) * N$8,1) -> 1.2 | O11: =ROUNDUP(IF($D11="画面",画面係数,IF($D11="帳票",帳票係数,IF($D11="バッチ",バッチ係数,0))) * IF($I11="特高",特高係数,IF($I11="高",高係数,IF($I11="中",中係数,IF($I11="低",低係数,IF($I11="特低",特低係数,0))))) * IF(O$7="SA",要件定義係数,IF(O$7="UI",基本設計係数,IF(O$7="SS",詳細設計係数,IF(O$7="PS/PG/PT",製作係数,IF(O$7="IT",結合テスト係数,IF(O$7="ST",総合テスト係数,IF(O$7="OT",受入支援係数,IF(O$7="RL",移行切替係数,IF(O$7="その他",その他係数,0))))))))) * O$8,1) -> 1.2 | P11: =ROUNDUP(IF($D11="画面",画面係数,IF($D11="帳票",帳票係数,IF($D11="バッチ",バッチ係数,0))) * IF($I11="特高",特高係数,IF($I11="高",高係数,IF($I11="中",中係数,IF($I11="低",低係数,IF($I11="特低",特低係数,0))))) * IF(P$7="SA",要件定義係数,IF(P$7="UI",基本設計係数,IF(P$7="SS",詳細設計係数,IF(P$7="PS/PG/PT",製作係数,IF(P$7="IT",結合テスト係数,IF(P$7="ST",総合テスト係数,IF(P$7="OT",受入支援係数,IF(P$7="RL",移行切替係数,IF(P$7="その他",その他係数,0))))))))) * P$8,1) -> 0.4 | Q11: =ROUNDUP(IF($D11="画面",画面係数,IF($D11="帳票",帳票係数,IF($D11="バッチ",バッチ係数,0))) * IF($I11="特高",特高係数,IF($I11="高",高係数,IF($I11="中",中係数,IF($I11="低",低係数,IF($I11="特低",特低係数,0))))) * IF(Q$7="SA",要件定義係数,IF(Q$7="UI",基本設計係数,IF(Q$7="SS",詳細設計係数,IF(Q$7="PS/PG/PT",製作係数,IF(Q$7="IT",結合テスト係数,IF(Q$7="ST",総合テスト係数,IF(Q$7="OT",受入支援係数,IF(Q$7="RL",移行切替係数,IF(Q$7="その他",その他係数,0))))))))) * Q$8,1) -> 0.7 | R11: =ROUNDUP(IF($D11="画面",画面係数,IF($D11="帳票",帳票係数,IF($D11="バッチ",バッチ係数,0))) * IF($I11="特高",特高係数,IF($I11="高",高係数,IF($I11="中",中係数,IF($I11="低",低係数,IF($I11="特低",特低係数,0))))) * IF(R$7="SA",要件定義係数,IF(R$7="UI",基本設計係数,IF(R$7="SS",詳細設計係数,IF(R$7="PS/PG/PT",製作係数,IF(R$7="IT",結合テスト係数,IF(R$7="ST",総合テスト係数,IF(R$7="OT",受入支援係数,IF(R$7="RL",移行切替係数,IF(R$7="その他",その他係数,0))))))))) * R$8,1) -> 0 | T11: =ROUNDUP(SUM(J11:S11)*T$8,1) -> 1.4 | U11: =SUM(J11:T11) -> 10.2 | V11: =U11/20 -> 0.51 | W11: =((J11*J$9) + (K11*K$9) + (L11*L$9) + (M11*M$9) + (N11*N$9) + (O11*O$9) + (P11*P$9) + (Q11*Q$9) + (R11*R$9) + (S11*S$9) + (T11*T$9))/20 -> 538000
A12: 5 | C12: MEKローリー予約送信(監視ジョブ) | D12: バッチ | E12: 無 | F12: 15 | I12: =IF(OR(E12="",F12=""),"", IF(E12="有",IF(F12<=登録上限特低,"特低",IF(F12<=登録上限低,"低",IF(F12<=登録上限中,"中",IF(F12<=登録上限高,"高","特高")))), IF(E12="無",IF(F12<=参照上限特低,"特低",IF(F12<=参照上限低,"低",IF(F12<=参照上限中,"中",IF(F12<=参照上限高,"高","特高")))),""))) -> 低 | J12: =ROUNDUP(IF($D12="画面",画面係数,IF($D12="帳票",帳票係数,IF($D12="バッチ",バッチ係数,0))) * IF($I12="特高",特高係数,IF($I12="高",高係数,IF($I12="中",中係数,IF($I12="低",低係数,IF($I12="特低",特低係数,0))))) * IF(J$7="SA",要件定義係数,IF(J$7="UI",基本設計係数,IF(J$7="SS",詳細設計係数,IF(J$7="PS/PG/PT",製作係数,IF(J$7="IT",結合テスト係数,IF(J$7="ST",総合テスト係数,IF(J$7="OT",受入支援係数,IF(J$7="RL",移行切替係数,IF(J$7="その他",その他係数,0))))))))) * J$8,1) -> 0.3 | K12: =ROUNDUP(IF($D12="画面",画面係数,IF($D12="帳票",帳票係数,IF($D12="バッチ",バッチ係数,0))) * IF($I12="特高",特高係数,IF($I12="高",高係数,IF($I12="中",中係数,IF($I12="低",低係数,IF($I12="特低",特低係数,0))))) * IF(K$7="SA",要件定義係数,IF(K$7="UI",基本設計係数,IF(K$7="SS",詳細設計係数,IF(K$7="PS/PG/PT",製作係数,IF(K$7="IT",結合テスト係数,IF(K$7="ST",総合テスト係数,IF(K$7="OT",受入支援係数,IF(K$7="RL",移行切替係数,IF(K$7="その他",その他係数,0))))))))) * K$8,1) -> 0.5 | L12: =ROUNDUP(IF($D12="画面",画面係数,IF($D12="帳票",帳票係数,IF($D12="バッチ",バッチ係数,0))) * IF($I12="特高",特高係数,IF($I12="高",高係数,IF($I12="中",中係数,IF($I12="低",低係数,IF($I12="特低",特低係数,0))))) * IF(L$7="SA",要件定義係数,IF(L$7="UI",基本設計係数,IF(L$7="SS",詳細設計係数,IF(L$7="PS/PG/PT",製作係数,IF(L$7="IT",結合テスト係数,IF(L$7="ST",総合テスト係数,IF(L$7="OT",受入支援係数,IF(L$7="RL",移行切替係数,IF(L$7="その他",その他係数,0))))))))) * L$8,1) -> 0.5 | M12: =ROUNDUP(IF($D12="画面",画面係数,IF($D12="帳票",帳票係数,IF($D12="バッチ",バッチ係数,0))) * IF($I12="特高",特高係数,IF($I12="高",高係数,IF($I12="中",中係数,IF($I12="低",低係数,IF($I12="特低",特低係数,0))))) * IF(M$7="SA",要件定義係数,IF(M$7="UI",基本設計係数,IF(M$7="SS",詳細設計係数,IF(M$7="PS/PG/PT",製作係数,IF(M$7="IT",結合テスト係数,IF(M$7="ST",総合テスト係数,IF(M$7="OT",受入支援係数,IF(M$7="RL",移行切替係数,IF(M$7="その他",その他係数,0))))))))) * M$8,1) -> 1 | N12: =ROUNDUP(IF($D12="画面",画面係数,IF($D12="帳票",帳票係数,IF($D12="バッチ",バッチ係数,0))) * IF($I12="特高",特高係数,IF($I12="高",高係数,IF($I12="中",中係数,IF($I12="低",低係数,IF($I12="特低",特低係数,0))))) * IF(N$7="SA",要件定義係数,IF(N$7="UI",基本設計係数,IF(N$7="SS",詳細設計係数,IF(N$7="PS/PG/PT",製作係数,IF(N$7="IT",結合テスト係数,IF(N$7="ST",総合テスト係数,IF(N$7="OT",受入支援係数,IF(N$7="RL",移行切替係数,IF(N$7="その他",その他係数,0))))))))) * N$8,1) -> 0.5 | O12: =ROUNDUP(IF($D12="画面",画面係数,IF($D12="帳票",帳票係数,IF($D12="バッチ",バッチ係数,0))) * IF($I12="特高",特高係数,IF($I12="高",高係数,IF($I12="中",中係数,IF($I12="低",低係数,IF($I12="特低",特低係数,0))))) * IF(O$7="SA",要件定義係数,IF(O$7="UI",基本設計係数,IF(O$7="SS",詳細設計係数,IF(O$7="PS/PG/PT",製作係数,IF(O$7="IT",結合テスト係数,IF(O$7="ST",総合テスト係数,IF(O$7="OT",受入支援係数,IF(O$7="RL",移行切替係数,IF(O$7="その他",その他係数,0))))))))) * O$8,1) -> 0.6 | P12: =ROUNDUP(IF($D12="画面",画面係数,IF($D12="帳票",帳票係数,IF($D12="バッチ",バッチ係数,0))) * IF($I12="特高",特高係数,IF($I12="高",高係数,IF($I12="中",中係数,IF($I12="低",低係数,IF($I12="特低",特低係数,0))))) * IF(P$7="SA",要件定義係数,IF(P$7="UI",基本設計係数,IF(P$7="SS",詳細設計係数,IF(P$7="PS/PG/PT",製作係数,IF(P$7="IT",結合テスト係数,IF(P$7="ST",総合テスト係数,IF(P$7="OT",受入支援係数,IF(P$7="RL",移行切替係数,IF(P$7="その他",その他係数,0))))))))) * P$8,1) -> 0.2 | Q12: =ROUNDUP(IF($D12="画面",画面係数,IF($D12="帳票",帳票係数,IF($D12="バッチ",バッチ係数,0))) * IF($I12="特高",特高係数,IF($I12="高",高係数,IF($I12="中",中係数,IF($I12="低",低係数,IF($I12="特低",特低係数,0))))) * IF(Q$7="SA",要件定義係数,IF(Q$7="UI",基本設計係数,IF(Q$7="SS",詳細設計係数,IF(Q$7="PS/PG/PT",製作係数,IF(Q$7="IT",結合テスト係数,IF(Q$7="ST",総合テスト係数,IF(Q$7="OT",受入支援係数,IF(Q$7="RL",移行切替係数,IF(Q$7="その他",その他係数,0))))))))) * Q$8,1) -> 0.3 | R12: =ROUNDUP(IF($D12="画面",画面係数,IF($D12="帳票",帳票係数,IF($D12="バッチ",バッチ係数,0))) * IF($I12="特高",特高係数,IF($I12="高",高係数,IF($I12="中",中係数,IF($I12="低",低係数,IF($I12="特低",特低係数,0))))) * IF(R$7="SA",要件定義係数,IF(R$7="UI",基本設計係数,IF(R$7="SS",詳細設計係数,IF(R$7="PS/PG/PT",製作係数,IF(R$7="IT",結合テスト係数,IF(R$7="ST",総合テスト係数,IF(R$7="OT",受入支援係数,IF(R$7="RL",移行切替係数,IF(R$7="その他",その他係数,0))))))))) * R$8,1) -> 0 | T12: =ROUNDUP(SUM(J12:S12)*T$8,1) -> 0.6 | U12: =SUM(J12:T12) -> 4.5 | V12: =U12/20 -> 0.225 | W12: =((J12*J$9) + (K12*K$9) + (L12*L$9) + (M12*M$9) + (N12*N$9) + (O12*O$9) + (P12*P$9) + (Q12*Q$9) + (R12*R$9) + (S12*S$9) + (T12*T$9))/20 -> 237000
A13: 6 | C13: MEKローリー予約送信(OWFT) | D13: バッチ | E13: 有 | F13: 20 | I13: =IF(OR(E13="",F13=""),"", IF(E13="有",IF(F13<=登録上限特低,"特低",IF(F13<=登録上限低,"低",IF(F13<=登録上限中,"中",IF(F13<=登録上限高,"高","特高")))), IF(E13="無",IF(F13<=参照上限特低,"特低",IF(F13<=参照上限低,"低",IF(F13<=参照上限中,"中",IF(F13<=参照上限高,"高","特高")))),""))) -> 中 | J13: =ROUNDUP(IF($D13="画面",画面係数,IF($D13="帳票",帳票係数,IF($D13="バッチ",バッチ係数,0))) * IF($I13="特高",特高係数,IF($I13="高",高係数,IF($I13="中",中係数,IF($I13="低",低係数,IF($I13="特低",特低係数,0))))) * IF(J$7="SA",要件定義係数,IF(J$7="UI",基本設計係数,IF(J$7="SS",詳細設計係数,IF(J$7="PS/PG/PT",製作係数,IF(J$7="IT",結合テスト係数,IF(J$7="ST",総合テスト係数,IF(J$7="OT",受入支援係数,IF(J$7="RL",移行切替係数,IF(J$7="その他",その他係数,0))))))))) * J$8,1) -> 0.6 | K13: =ROUNDUP(IF($D13="画面",画面係数,IF($D13="帳票",帳票係数,IF($D13="バッチ",バッチ係数,0))) * IF($I13="特高",特高係数,IF($I13="高",高係数,IF($I13="中",中係数,IF($I13="低",低係数,IF($I13="特低",特低係数,0))))) * IF(K$7="SA",要件定義係数,IF(K$7="UI",基本設計係数,IF(K$7="SS",詳細設計係数,IF(K$7="PS/PG/PT",製作係数,IF(K$7="IT",結合テスト係数,IF(K$7="ST",総合テスト係数,IF(K$7="OT",受入支援係数,IF(K$7="RL",移行切替係数,IF(K$7="その他",その他係数,0))))))))) * K$8,1) -> 0.9 | L13: =ROUNDUP(IF($D13="画面",画面係数,IF($D13="帳票",帳票係数,IF($D13="バッチ",バッチ係数,0))) * IF($I13="特高",特高係数,IF($I13="高",高係数,IF($I13="中",中係数,IF($I13="低",低係数,IF($I13="特低",特低係数,0))))) * IF(L$7="SA",要件定義係数,IF(L$7="UI",基本設計係数,IF(L$7="SS",詳細設計係数,IF(L$7="PS/PG/PT",製作係数,IF(L$7="IT",結合テスト係数,IF(L$7="ST",総合テスト係数,IF(L$7="OT",受入支援係数,IF(L$7="RL",移行切替係数,IF(L$7="その他",その他係数,0))))))))) * L$8,1) -> 1 | M13: =ROUNDUP(IF($D13="画面",画面係数,IF($D13="帳票",帳票係数,IF($D13="バッチ",バッチ係数,0))) * IF($I13="特高",特高係数,IF($I13="高",高係数,IF($I13="中",中係数,IF($I13="低",低係数,IF($I13="特低",特低係数,0))))) * IF(M$7="SA",要件定義係数,IF(M$7="UI",基本設計係数,IF(M$7="SS",詳細設計係数,IF(M$7="PS/PG/PT",製作係数,IF(M$7="IT",結合テスト係数,IF(M$7="ST",総合テスト係数,IF(M$7="OT",受入支援係数,IF(M$7="RL",移行切替係数,IF(M$7="その他",その他係数,0))))))))) * M$8,1) -> 2 | N13: =ROUNDUP(IF($D13="画面",画面係数,IF($D13="帳票",帳票係数,IF($D13="バッチ",バッチ係数,0))) * IF($I13="特高",特高係数,IF($I13="高",高係数,IF($I13="中",中係数,IF($I13="低",低係数,IF($I13="特低",特低係数,0))))) * IF(N$7="SA",要件定義係数,IF(N$7="UI",基本設計係数,IF(N$7="SS",詳細設計係数,IF(N$7="PS/PG/PT",製作係数,IF(N$7="IT",結合テスト係数,IF(N$7="ST",総合テスト係数,IF(N$7="OT",受入支援係数,IF(N$7="RL",移行切替係数,IF(N$7="その他",その他係数,0))))))))) * N$8,1) -> 1 | O13: =ROUNDUP(IF($D13="画面",画面係数,IF($D13="帳票",帳票係数,IF($D13="バッチ",バッチ係数,0))) * IF($I13="特高",特高係数,IF($I13="高",高係数,IF($I13="中",中係数,IF($I13="低",低係数,IF($I13="特低",特低係数,0))))) * IF(O$7="SA",要件定義係数,IF(O$7="UI",基本設計係数,IF(O$7="SS",詳細設計係数,IF(O$7="PS/PG/PT",製作係数,IF(O$7="IT",結合テスト係数,IF(O$7="ST",総合テスト係数,IF(O$7="OT",受入支援係数,IF(O$7="RL",移行切替係数,IF(O$7="その他",その他係数,0))))))))) * O$8,1) -> 1.1 | P13: =ROUNDUP(IF($D13="画面",画面係数,IF($D13="帳票",帳票係数,IF($D13="バッチ",バッチ係数,0))) * IF($I13="特高",特高係数,IF($I13="高",高係数,IF($I13="中",中係数,IF($I13="低",低係数,IF($I13="特低",特低係数,0))))) * IF(P$7="SA",要件定義係数,IF(P$7="UI",基本設計係数,IF(P$7="SS",詳細設計係数,IF(P$7="PS/PG/PT",製作係数,IF(P$7="IT",結合テスト係数,IF(P$7="ST",総合テスト係数,IF(P$7="OT",受入支援係数,IF(P$7="RL",移行切替係数,IF(P$7="その他",その他係数,0))))))))) * P$8,1) -> 0.3 | Q13: =ROUNDUP(IF($D13="画面",画面係数,IF($D13="帳票",帳票係数,IF($D13="バッチ",バッチ係数,0))) * IF($I13="特高",特高係数,IF($I13="高",高係数,IF($I13="中",中係数,IF($I13="低",低係数,IF($I13="特低",特低係数,0))))) * IF(Q$7="SA",要件定義係数,IF(Q$7="UI",基本設計係数,IF(Q$7="SS",詳細設計係数,IF(Q$7="PS/PG/PT",製作係数,IF(Q$7="IT",結合テスト係数,IF(Q$7="ST",総合テスト係数,IF(Q$7="OT",受入支援係数,IF(Q$7="RL",移行切替係数,IF(Q$7="その他",その他係数,0))))))))) * Q$8,1) -> 0.6 | R13: =ROUNDUP(IF($D13="画面",画面係数,IF($D13="帳票",帳票係数,IF($D13="バッチ",バッチ係数,0))) * IF($I13="特高",特高係数,IF($I13="高",高係数,IF($I13="中",中係数,IF($I13="低",低係数,IF($I13="特低",特低係数,0))))) * IF(R$7="SA",要件定義係数,IF(R$7="UI",基本設計係数,IF(R$7="SS",詳細設計係数,IF(R$7="PS/PG/PT",製作係数,IF(R$7="IT",結合テスト係数,IF(R$7="ST",総合テスト係数,IF(R$7="OT",受入支援係数,IF(R$7="RL",移行切替係数,IF(R$7="その他",その他係数,0))))))))) * R$8,1) -> 0 | T13: =ROUNDUP(SUM(J13:S13)*T$8,1) -> 1.2 | U13: =SUM(J13:T13) -> 8.7 | V13: =U13/20 -> 0.435 | W13: =((J13*J$9) + (K13*K$9) + (L13*L$9) + (M13*M$9) + (N13*N$9) + (O13*O$9) + (P13*P$9) + (Q13*Q$9) + (R13*R$9) + (S13*S$9) + (T13*T$9))/20 -> 459000
A14: 7 | C14: MEKドラム出荷予約送信(ファイル出力) | D14: バッチ | E14: 有 | F14: 30 | I14: =IF(OR(E14="",F14=""),"", IF(E14="有",IF(F14<=登録上限特低,"特低",IF(F14<=登録上限低,"低",IF(F14<=登録上限中,"中",IF(F14<=登録上限高,"高","特高")))), IF(E14="無",IF(F14<=参照上限特低,"特低",IF(F14<=参照上限低,"低",IF(F14<=参照上限中,"中",IF(F14<=参照上限高,"高","特高")))),""))) -> 高 | J14: =ROUNDUP(IF($D14="画面",画面係数,IF($D14="帳票",帳票係数,IF($D14="バッチ",バッチ係数,0))) * IF($I14="特高",特高係数,IF($I14="高",高係数,IF($I14="中",中係数,IF($I14="低",低係数,IF($I14="特低",特低係数,0))))) * IF(J$7="SA",要件定義係数,IF(J$7="UI",基本設計係数,IF(J$7="SS",詳細設計係数,IF(J$7="PS/PG/PT",製作係数,IF(J$7="IT",結合テスト係数,IF(J$7="ST",総合テスト係数,IF(J$7="OT",受入支援係数,IF(J$7="RL",移行切替係数,IF(J$7="その他",その他係数,0))))))))) * J$8,1) -> 0.7 | K14: =ROUNDUP(IF($D14="画面",画面係数,IF($D14="帳票",帳票係数,IF($D14="バッチ",バッチ係数,0))) * IF($I14="特高",特高係数,IF($I14="高",高係数,IF($I14="中",中係数,IF($I14="低",低係数,IF($I14="特低",特低係数,0))))) * IF(K$7="SA",要件定義係数,IF(K$7="UI",基本設計係数,IF(K$7="SS",詳細設計係数,IF(K$7="PS/PG/PT",製作係数,IF(K$7="IT",結合テスト係数,IF(K$7="ST",総合テスト係数,IF(K$7="OT",受入支援係数,IF(K$7="RL",移行切替係数,IF(K$7="その他",その他係数,0))))))))) * K$8,1) -> 1.1 | L14: =ROUNDUP(IF($D14="画面",画面係数,IF($D14="帳票",帳票係数,IF($D14="バッチ",バッチ係数,0))) * IF($I14="特高",特高係数,IF($I14="高",高係数,IF($I14="中",中係数,IF($I14="低",低係数,IF($I14="特低",特低係数,0))))) * IF(L$7="SA",要件定義係数,IF(L$7="UI",基本設計係数,IF(L$7="SS",詳細設計係数,IF(L$7="PS/PG/PT",製作係数,IF(L$7="IT",結合テスト係数,IF(L$7="ST",総合テスト係数,IF(L$7="OT",受入支援係数,IF(L$7="RL",移行切替係数,IF(L$7="その他",その他係数,0))))))))) * L$8,1) -> 1.2 | M14: =ROUNDUP(IF($D14="画面",画面係数,IF($D14="帳票",帳票係数,IF($D14="バッチ",バッチ係数,0))) * IF($I14="特高",特高係数,IF($I14="高",高係数,IF($I14="中",中係数,IF($I14="低",低係数,IF($I14="特低",特低係数,0))))) * IF(M$7="SA",要件定義係数,IF(M$7="UI",基本設計係数,IF(M$7="SS",詳細設計係数,IF(M$7="PS/PG/PT",製作係数,IF(M$7="IT",結合テスト係数,IF(M$7="ST",総合テスト係数,IF(M$7="OT",受入支援係数,IF(M$7="RL",移行切替係数,IF(M$7="その他",その他係数,0))))))))) * M$8,1) -> 2.3 | N14: =ROUNDUP(IF($D14="画面",画面係数,IF($D14="帳票",帳票係数,IF($D14="バッチ",バッチ係数,0))) * IF($I14="特高",特高係数,IF($I14="高",高係数,IF($I14="中",中係数,IF($I14="低",低係数,IF($I14="特低",特低係数,0))))) * IF(N$7="SA",要件定義係数,IF(N$7="UI",基本設計係数,IF(N$7="SS",詳細設計係数,IF(N$7="PS/PG/PT",製作係数,IF(N$7="IT",結合テスト係数,IF(N$7="ST",総合テスト係数,IF(N$7="OT",受入支援係数,IF(N$7="RL",移行切替係数,IF(N$7="その他",その他係数,0))))))))) * N$8,1) -> 1.2 | O14: =ROUNDUP(IF($D14="画面",画面係数,IF($D14="帳票",帳票係数,IF($D14="バッチ",バッチ係数,0))) * IF($I14="特高",特高係数,IF($I14="高",高係数,IF($I14="中",中係数,IF($I14="低",低係数,IF($I14="特低",特低係数,0))))) * IF(O$7="SA",要件定義係数,IF(O$7="UI",基本設計係数,IF(O$7="SS",詳細設計係数,IF(O$7="PS/PG/PT",製作係数,IF(O$7="IT",結合テスト係数,IF(O$7="ST",総合テスト係数,IF(O$7="OT",受入支援係数,IF(O$7="RL",移行切替係数,IF(O$7="その他",その他係数,0))))))))) * O$8,1) -> 1.2 | P14: =ROUNDUP(IF($D14="画面",画面係数,IF($D14="帳票",帳票係数,IF($D14="バッチ",バッチ係数,0))) * IF($I14="特高",特高係数,IF($I14="高",高係数,IF($I14="中",中係数,IF($I14="低",低係数,IF($I14="特低",特低係数,0))))) * IF(P$7="SA",要件定義係数,IF(P$7="UI",基本設計係数,IF(P$7="SS",詳細設計係数,IF(P$7="PS/PG/PT",製作係数,IF(P$7="IT",結合テスト係数,IF(P$7="ST",総合テスト係数,IF(P$7="OT",受入支援係数,IF(P$7="RL",移行切替係数,IF(P$7="その他",その他係数,0))))))))) * P$8,1) -> 0.4 | Q14: =ROUNDUP(IF($D14="画面",画面係数,IF($D14="帳票",帳票係数,IF($D14="バッチ",バッチ係数,0))) * IF($I14="特高",特高係数,IF($I14="高",高係数,IF($I14="中",中係数,IF($I14="低",低係数,IF($I14="特低",特低係数,0))))) * IF(Q$7="SA",要件定義係数,IF(Q$7="UI",基本設計係数,IF(Q$7="SS",詳細設計係数,IF(Q$7="PS/PG/PT",製作係数,IF(Q$7="IT",結合テスト係数,IF(Q$7="ST",総合テスト係数,IF(Q$7="OT",受入支援係数,IF(Q$7="RL",移行切替係数,IF(Q$7="その他",その他係数,0))))))))) * Q$8,1) -> 0.7 | R14: =ROUNDUP(IF($D14="画面",画面係数,IF($D14="帳票",帳票係数,IF($D14="バッチ",バッチ係数,0))) * IF($I14="特高",特高係数,IF($I14="高",高係数,IF($I14="中",中係数,IF($I14="低",低係数,IF($I14="特低",特低係数,0))))) * IF(R$7="SA",要件定義係数,IF(R$7="UI",基本設計係数,IF(R$7="SS",詳細設計係数,IF(R$7="PS/PG/PT",製作係数,IF(R$7="IT",結合テスト係数,IF(R$7="ST",総合テスト係数,IF(R$7="OT",受入支援係数,IF(R$7="RL",移行切替係数,IF(R$7="その他",その他係数,0))))))))) * R$8,1) -> 0 | T14: =ROUNDUP(SUM(J14:S14)*T$8,1) -> 1.4 | U14: =SUM(J14:T14) -> 10.2 | V14: =U14/20 -> 0.51 | W14: =((J14*J$9) + (K14*K$9) + (L14*L$9) + (M14*M$9) + (N14*N$9) + (O14*O$9) + (P14*P$9) + (Q14*Q$9) + (R14*R$9) + (S14*S$9) + (T14*T$9))/20 -> 538000
A15: 8 | C15: MEKドラム出荷予約送信(監視ジョブ) | D15: バッチ | E15: 無 | F15: 15 | I15: =IF(OR(E15="",F15=""),"", IF(E15="有",IF(F15<=登録上限特低,"特低",IF(F15<=登録上限低,"低",IF(F15<=登録上限中,"中",IF(F15<=登録上限高,"高","特高")))), IF(E15="無",IF(F15<=参照上限特低,"特低",IF(F15<=参照上限低,"低",IF(F15<=参照上限中,"中",IF(F15<=参照上限高,"高","特高")))),""))) -> 低 | J15: =ROUNDUP(IF($D15="画面",画面係数,IF($D15="帳票",帳票係数,IF($D15="バッチ",バッチ係数,0))) * IF($I15="特高",特高係数,IF($I15="高",高係数,IF($I15="中",中係数,IF($I15="低",低係数,IF($I15="特低",特低係数,0))))) * IF(J$7="SA",要件定義係数,IF(J$7="UI",基本設計係数,IF(J$7="SS",詳細設計係数,IF(J$7="PS/PG/PT",製作係数,IF(J$7="IT",結合テスト係数,IF(J$7="ST",総合テスト係数,IF(J$7="OT",受入支援係数,IF(J$7="RL",移行切替係数,IF(J$7="その他",その他係数,0))))))))) * J$8,1) -> 0.3 | K15: =ROUNDUP(IF($D15="画面",画面係数,IF($D15="帳票",帳票係数,IF($D15="バッチ",バッチ係数,0))) * IF($I15="特高",特高係数,IF($I15="高",高係数,IF($I15="中",中係数,IF($I15="低",低係数,IF($I15="特低",特低係数,0))))) * IF(K$7="SA",要件定義係数,IF(K$7="UI",基本設計係数,IF(K$7="SS",詳細設計係数,IF(K$7="PS/PG/PT",製作係数,IF(K$7="IT",結合テスト係数,IF(K$7="ST",総合テスト係数,IF(K$7="OT",受入支援係数,IF(K$7="RL",移行切替係数,IF(K$7="その他",その他係数,0))))))))) * K$8,1) -> 0.5 | L15: =ROUNDUP(IF($D15="画面",画面係数,IF($D15="帳票",帳票係数,IF($D15="バッチ",バッチ係数,0))) * IF($I15="特高",特高係数,IF($I15="高",高係数,IF($I15="中",中係数,IF($I15="低",低係数,IF($I15="特低",特低係数,0))))) * IF(L$7="SA",要件定義係数,IF(L$7="UI",基本設計係数,IF(L$7="SS",詳細設計係数,IF(L$7="PS/PG/PT",製作係数,IF(L$7="IT",結合テスト係数,IF(L$7="ST",総合テスト係数,IF(L$7="OT",受入支援係数,IF(L$7="RL",移行切替係数,IF(L$7="その他",その他係数,0))))))))) * L$8,1) -> 0.5 | M15: =ROUNDUP(IF($D15="画面",画面係数,IF($D15="帳票",帳票係数,IF($D15="バッチ",バッチ係数,0))) * IF($I15="特高",特高係数,IF($I15="高",高係数,IF($I15="中",中係数,IF($I15="低",低係数,IF($I15="特低",特低係数,0))))) * IF(M$7="SA",要件定義係数,IF(M$7="UI",基本設計係数,IF(M$7="SS",詳細設計係数,IF(M$7="PS/PG/PT",製作係数,IF(M$7="IT",結合テスト係数,IF(M$7="ST",総合テスト係数,IF(M$7="OT",受入支援係数,IF(M$7="RL",移行切替係数,IF(M$7="その他",その他係数,0))))))))) * M$8,1) -> 1 | N15: =ROUNDUP(IF($D15="画面",画面係数,IF($D15="帳票",帳票係数,IF($D15="バッチ",バッチ係数,0))) * IF($I15="特高",特高係数,IF($I15="高",高係数,IF($I15="中",中係数,IF($I15="低",低係数,IF($I15="特低",特低係数,0))))) * IF(N$7="SA",要件定義係数,IF(N$7="UI",基本設計係数,IF(N$7="SS",詳細設計係数,IF(N$7="PS/PG/PT",製作係数,IF(N$7="IT",結合テスト係数,IF(N$7="ST",総合テスト係数,IF(N$7="OT",受入支援係数,IF(N$7="RL",移行切替係数,IF(N$7="その他",その他係数,0))))))))) * N$8,1) -> 0.5 | O15: =ROUNDUP(IF($D15="画面",画面係数,IF($D15="帳票",帳票係数,IF($D15="バッチ",バッチ係数,0))) * IF($I15="特高",特高係数,IF($I15="高",高係数,IF($I15="中",中係数,IF($I15="低",低係数,IF($I15="特低",特低係数,0))))) * IF(O$7="SA",要件定義係数,IF(O$7="UI",基本設計係数,IF(O$7="SS",詳細設計係数,IF(O$7="PS/PG/PT",製作係数,IF(O$7="IT",結合テスト係数,IF(O$7="ST",総合テスト係数,IF(O$7="OT",受入支援係数,IF(O$7="RL",移行切替係数,IF(O$7="その他",その他係数,0))))))))) * O$8,1) -> 0.6 | P15: =ROUNDUP(IF($D15="画面",画面係数,IF($D15="帳票",帳票係数,IF($D15="バッチ",バッチ係数,0))) * IF($I15="特高",特高係数,IF($I15="高",高係数,IF($I15="中",中係数,IF($I15="低",低係数,IF($I15="特低",特低係数,0))))) * IF(P$7="SA",要件定義係数,IF(P$7="UI",基本設計係数,IF(P$7="SS",詳細設計係数,IF(P$7="PS/PG/PT",製作係数,IF(P$7="IT",結合テスト係数,IF(P$7="ST",総合テスト係数,IF(P$7="OT",受入支援係数,IF(P$7="RL",移行切替係数,IF(P$7="その他",その他係数,0))))))))) * P$8,1) -> 0.2 | Q15: =ROUNDUP(IF($D15="画面",画面係数,IF($D15="帳票",帳票係数,IF($D15="バッチ",バッチ係数,0))) * IF($I15="特高",特高係数,IF($I15="高",高係数,IF($I15="中",中係数,IF($I15="低",低係数,IF($I15="特低",特低係数,0))))) * IF(Q$7="SA",要件定義係数,IF(Q$7="UI",基本設計係数,IF(Q$7="SS",詳細設計係数,IF(Q$7="PS/PG/PT",製作係数,IF(Q$7="IT",結合テスト係数,IF(Q$7="ST",総合テスト係数,IF(Q$7="OT",受入支援係数,IF(Q$7="RL",移行切替係数,IF(Q$7="その他",その他係数,0))))))))) * Q$8,1) -> 0.3 | R15: =ROUNDUP(IF($D15="画面",画面係数,IF($D15="帳票",帳票係数,IF($D15="バッチ",バッチ係数,0))) * IF($I15="特高",特高係数,IF($I15="高",高係数,IF($I15="中",中係数,IF($I15="低",低係数,IF($I15="特低",特低係数,0))))) * IF(R$7="SA",要件定義係数,IF(R$7="UI",基本設計係数,IF(R$7="SS",詳細設計係数,IF(R$7="PS/PG/PT",製作係数,IF(R$7="IT",結合テスト係数,IF(R$7="ST",総合テスト係数,IF(R$7="OT",受入支援係数,IF(R$7="RL",移行切替係数,IF(R$7="その他",その他係数,0))))))))) * R$8,1) -> 0 | T15: =ROUNDUP(SUM(J15:S15)*T$8,1) -> 0.6 | U15: =SUM(J15:T15) -> 4.5 | V15: =U15/20 -> 0.225 | W15: =((J15*J$9) + (K15*K$9) + (L15*L$9) + (M15*M$9) + (N15*N$9) + (O15*O$9) + (P15*P$9) + (Q15*Q$9) + (R15*R$9) + (S15*S$9) + (T15*T$9))/20 -> 237000
A16: 9 | C16: MEKドラム出荷予約送信(OWFT) | D16: バッチ | E16: 有 | F16: 20 | I16: =IF(OR(E16="",F16=""),"", IF(E16="有",IF(F16<=登録上限特低,"特低",IF(F16<=登録上限低,"低",IF(F16<=登録上限中,"中",IF(F16<=登録上限高,"高","特高")))), IF(E16="無",IF(F16<=参照上限特低,"特低",IF(F16<=参照上限低,"低",IF(F16<=参照上限中,"中",IF(F16<=参照上限高,"高","特高")))),""))) -> 中 | J16: =ROUNDUP(IF($D16="画面",画面係数,IF($D16="帳票",帳票係数,IF($D16="バッチ",バッチ係数,0))) * IF($I16="特高",特高係数,IF($I16="高",高係数,IF($I16="中",中係数,IF($I16="低",低係数,IF($I16="特低",特低係数,0))))) * IF(J$7="SA",要件定義係数,IF(J$7="UI",基本設計係数,IF(J$7="SS",詳細設計係数,IF(J$7="PS/PG/PT",製作係数,IF(J$7="IT",結合テスト係数,IF(J$7="ST",総合テスト係数,IF(J$7="OT",受入支援係数,IF(J$7="RL",移行切替係数,IF(J$7="その他",その他係数,0))))))))) * J$8,1) -> 0.6 | K16: =ROUNDUP(IF($D16="画面",画面係数,IF($D16="帳票",帳票係数,IF($D16="バッチ",バッチ係数,0))) * IF($I16="特高",特高係数,IF($I16="高",高係数,IF($I16="中",中係数,IF($I16="低",低係数,IF($I16="特低",特低係数,0))))) * IF(K$7="SA",要件定義係数,IF(K$7="UI",基本設計係数,IF(K$7="SS",詳細設計係数,IF(K$7="PS/PG/PT",製作係数,IF(K$7="IT",結合テスト係数,IF(K$7="ST",総合テスト係数,IF(K$7="OT",受入支援係数,IF(K$7="RL",移行切替係数,IF(K$7="その他",その他係数,0))))))))) * K$8,1) -> 0.9 | L16: =ROUNDUP(IF($D16="画面",画面係数,IF($D16="帳票",帳票係数,IF($D16="バッチ",バッチ係数,0))) * IF($I16="特高",特高係数,IF($I16="高",高係数,IF($I16="中",中係数,IF($I16="低",低係数,IF($I16="特低",特低係数,0))))) * IF(L$7="SA",要件定義係数,IF(L$7="UI",基本設計係数,IF(L$7="SS",詳細設計係数,IF(L$7="PS/PG/PT",製作係数,IF(L$7="IT",結合テスト係数,IF(L$7="ST",総合テスト係数,IF(L$7="OT",受入支援係数,IF(L$7="RL",移行切替係数,IF(L$7="その他",その他係数,0))))))))) * L$8,1) -> 1 | M16: =ROUNDUP(IF($D16="画面",画面係数,IF($D16="帳票",帳票係数,IF($D16="バッチ",バッチ係数,0))) * IF($I16="特高",特高係数,IF($I16="高",高係数,IF($I16="中",中係数,IF($I16="低",低係数,IF($I16="特低",特低係数,0))))) * IF(M$7="SA",要件定義係数,IF(M$7="UI",基本設計係数,IF(M$7="SS",詳細設計係数,IF(M$7="PS/PG/PT",製作係数,IF(M$7="IT",結合テスト係数,IF(M$7="ST",総合テスト係数,IF(M$7="OT",受入支援係数,IF(M$7="RL",移行切替係数,IF(M$7="その他",その他係数,0))))))))) * M$8,1) -> 2 | N16: =ROUNDUP(IF($D16="画面",画面係数,IF($D16="帳票",帳票係数,IF($D16="バッチ",バッチ係数,0))) * IF($I16="特高",特高係数,IF($I16="高",高係数,IF($I16="中",中係数,IF($I16="低",低係数,IF($I16="特低",特低係数,0))))) * IF(N$7="SA",要件定義係数,IF(N$7="UI",基本設計係数,IF(N$7="SS",詳細設計係数,IF(N$7="PS/PG/PT",製作係数,IF(N$7="IT",結合テスト係数,IF(N$7="ST",総合テスト係数,IF(N$7="OT",受入支援係数,IF(N$7="RL",移行切替係数,IF(N$7="その他",その他係数,0))))))))) * N$8,1) -> 1 | O16: =ROUNDUP(IF($D16="画面",画面係数,IF($D16="帳票",帳票係数,IF($D16="バッチ",バッチ係数,0))) * IF($I16="特高",特高係数,IF($I16="高",高係数,IF($I16="中",中係数,IF($I16="低",低係数,IF($I16="特低",特低係数,0))))) * IF(O$7="SA",要件定義係数,IF(O$7="UI",基本設計係数,IF(O$7="SS",詳細設計係数,IF(O$7="PS/PG/PT",製作係数,IF(O$7="IT",結合テスト係数,IF(O$7="ST",総合テスト係数,IF(O$7="OT",受入支援係数,IF(O$7="RL",移行切替係数,IF(O$7="その他",その他係数,0))))))))) * O$8,1) -> 1.1 | P16: =ROUNDUP(IF($D16="画面",画面係数,IF($D16="帳票",帳票係数,IF($D16="バッチ",バッチ係数,0))) * IF($I16="特高",特高係数,IF($I16="高",高係数,IF($I16="中",中係数,IF($I16="低",低係数,IF($I16="特低",特低係数,0))))) * IF(P$7="SA",要件定義係数,IF(P$7="UI",基本設計係数,IF(P$7="SS",詳細設計係数,IF(P$7="PS/PG/PT",製作係数,IF(P$7="IT",結合テスト係数,IF(P$7="ST",総合テスト係数,IF(P$7="OT",受入支援係数,IF(P$7="RL",移行切替係数,IF(P$7="その他",その他係数,0))))))))) * P$8,1) -> 0.3 | Q16: =ROUNDUP(IF($D16="画面",画面係数,IF($D16="帳票",帳票係数,IF($D16="バッチ",バッチ係数,0))) * IF($I16="特高",特高係数,IF($I16="高",高係数,IF($I16="中",中係数,IF($I16="低",低係数,IF($I16="特低",特低係数,0))))) * IF(Q$7="SA",要件定義係数,IF(Q$7="UI",基本設計係数,IF(Q$7="SS",詳細設計係数,IF(Q$7="PS/PG/PT",製作係数,IF(Q$7="IT",結合テスト係数,IF(Q$7="ST",総合テスト係数,IF(Q$7="OT",受入支援係数,IF(Q$7="RL",移行切替係数,IF(Q$7="その他",その他係数,0))))))))) * Q$8,1) -> 0.6 | R16: =ROUNDUP(IF($D16="画面",画面係数,IF($D16="帳票",帳票係数,IF($D16="バッチ",バッチ係数,0))) * IF($I16="特高",特高係数,IF($I16="高",高係数,IF($I16="中",中係数,IF($I16="低",低係数,IF($I16="特低",特低係数,0))))) * IF(R$7="SA",要件定義係数,IF(R$7="UI",基本設計係数,IF(R$7="SS",詳細設計係数,IF(R$7="PS/PG/PT",製作係数,IF(R$7="IT",結合テスト係数,IF(R$7="ST",総合テスト係数,IF(R$7="OT",受入支援係数,IF(R$7="RL",移行切替係数,IF(R$7="その他",その他係数,0))))))))) * R$8,1) -> 0 | T16: =ROUNDUP(SUM(J16:S16)*T$8,1) -> 1.2 | U16: =SUM(J16:T16) -> 8.7 | V16: =U16/20 -> 0.435 | W16: =((J16*J$9) + (K16*K$9) + (L16*L$9) + (M16*M$9) + (N16*N$9) + (O16*O$9) + (P16*P$9) + (Q16*Q$9) + (R16*R$9) + (S16*S$9) + (T16*T$9))/20 -> 459000
A17: 10 | C17: MEKローリー実績受信(ファイル取込) | D17: バッチ | E17: 有 | F17: 30 | I17: =IF(OR(E17="",F17=""),"", IF(E17="有",IF(F17<=登録上限特低,"特低",IF(F17<=登録上限低,"低",IF(F17<=登録上限中,"中",IF(F17<=登録上限高,"高","特高")))), IF(E17="無",IF(F17<=参照上限特低,"特低",IF(F17<=参照上限低,"低",IF(F17<=参照上限中,"中",IF(F17<=参照上限高,"高","特高")))),""))) -> 高 | J17: =ROUNDUP(IF($D17="画面",画面係数,IF($D17="帳票",帳票係数,IF($D17="バッチ",バッチ係数,0))) * IF($I17="特高",特高係数,IF($I17="高",高係数,IF($I17="中",中係数,IF($I17="低",低係数,IF($I17="特低",特低係数,0))))) * IF(J$7="SA",要件定義係数,IF(J$7="UI",基本設計係数,IF(J$7="SS",詳細設計係数,IF(J$7="PS/PG/PT",製作係数,IF(J$7="IT",結合テスト係数,IF(J$7="ST",総合テスト係数,IF(J$7="OT",受入支援係数,IF(J$7="RL",移行切替係数,IF(J$7="その他",その他係数,0))))))))) * J$8,1) -> 0.7 | K17: =ROUNDUP(IF($D17="画面",画面係数,IF($D17="帳票",帳票係数,IF($D17="バッチ",バッチ係数,0))) * IF($I17="特高",特高係数,IF($I17="高",高係数,IF($I17="中",中係数,IF($I17="低",低係数,IF($I17="特低",特低係数,0))))) * IF(K$7="SA",要件定義係数,IF(K$7="UI",基本設計係数,IF(K$7="SS",詳細設計係数,IF(K$7="PS/PG/PT",製作係数,IF(K$7="IT",結合テスト係数,IF(K$7="ST",総合テスト係数,IF(K$7="OT",受入支援係数,IF(K$7="RL",移行切替係数,IF(K$7="その他",その他係数,0))))))))) * K$8,1) -> 1.1 | L17: =ROUNDUP(IF($D17="画面",画面係数,IF($D17="帳票",帳票係数,IF($D17="バッチ",バッチ係数,0))) * IF($I17="特高",特高係数,IF($I17="高",高係数,IF($I17="中",中係数,IF($I17="低",低係数,IF($I17="特低",特低係数,0))))) * IF(L$7="SA",要件定義係数,IF(L$7="UI",基本設計係数,IF(L$7="SS",詳細設計係数,IF(L$7="PS/PG/PT",製作係数,IF(L$7="IT",結合テスト係数,IF(L$7="ST",総合テスト係数,IF(L$7="OT",受入支援係数,IF(L$7="RL",移行切替係数,IF(L$7="その他",その他係数,0))))))))) * L$8,1) -> 1.2 | M17: =ROUNDUP(IF($D17="画面",画面係数,IF($D17="帳票",帳票係数,IF($D17="バッチ",バッチ係数,0))) * IF($I17="特高",特高係数,IF($I17="高",高係数,IF($I17="中",中係数,IF($I17="低",低係数,IF($I17="特低",特低係数,0))))) * IF(M$7="SA",要件定義係数,IF(M$7="UI",基本設計係数,IF(M$7="SS",詳細設計係数,IF(M$7="PS/PG/PT",製作係数,IF(M$7="IT",結合テスト係数,IF(M$7="ST",総合テスト係数,IF(M$7="OT",受入支援係数,IF(M$7="RL",移行切替係数,IF(M$7="その他",その他係数,0))))))))) * M$8,1) -> 2.3 | N17: =ROUNDUP(IF($D17="画面",画面係数,IF($D17="帳票",帳票係数,IF($D17="バッチ",バッチ係数,0))) * IF($I17="特高",特高係数,IF($I17="高",高係数,IF($I17="中",中係数,IF($I17="低",低係数,IF($I17="特低",特低係数,0))))) * IF(N$7="SA",要件定義係数,IF(N$7="UI",基本設計係数,IF(N$7="SS",詳細設計係数,IF(N$7="PS/PG/PT",製作係数,IF(N$7="IT",結合テスト係数,IF(N$7="ST",総合テスト係数,IF(N$7="OT",受入支援係数,IF(N$7="RL",移行切替係数,IF(N$7="その他",その他係数,0))))))))) * N$8,1) -> 1.2 | O17: =ROUNDUP(IF($D17="画面",画面係数,IF($D17="帳票",帳票係数,IF($D17="バッチ",バッチ係数,0))) * IF($I17="特高",特高係数,IF($I17="高",高係数,IF($I17="中",中係数,IF($I17="低",低係数,IF($I17="特低",特低係数,0))))) * IF(O$7="SA",要件定義係数,IF(O$7="UI",基本設計係数,IF(O$7="SS",詳細設計係数,IF(O$7="PS/PG/PT",製作係数,IF(O$7="IT",結合テスト係数,IF(O$7="ST",総合テスト係数,IF(O$7="OT",受入支援係数,IF(O$7="RL",移行切替係数,IF(O$7="その他",その他係数,0))))))))) * O$8,1) -> 1.2 | P17: =ROUNDUP(IF($D17="画面",画面係数,IF($D17="帳票",帳票係数,IF($D17="バッチ",バッチ係数,0))) * IF($I17="特高",特高係数,IF($I17="高",高係数,IF($I17="中",中係数,IF($I17="低",低係数,IF($I17="特低",特低係数,0))))) * IF(P$7="SA",要件定義係数,IF(P$7="UI",基本設計係数,IF(P$7="SS",詳細設計係数,IF(P$7="PS/PG/PT",製作係数,IF(P$7="IT",結合テスト係数,IF(P$7="ST",総合テスト係数,IF(P$7="OT",受入支援係数,IF(P$7="RL",移行切替係数,IF(P$7="その他",その他係数,0))))))))) * P$8,1) -> 0.4 | Q17: =ROUNDUP(IF($D17="画面",画面係数,IF($D17="帳票",帳票係数,IF($D17="バッチ",バッチ係数,0))) * IF($I17="特高",特高係数,IF($I17="高",高係数,IF($I17="中",中係数,IF($I17="低",低係数,IF($I17="特低",特低係数,0))))) * IF(Q$7="SA",要件定義係数,IF(Q$7="UI",基本設計係数,IF(Q$7="SS",詳細設計係数,IF(Q$7="PS/PG/PT",製作係数,IF(Q$7="IT",結合テスト係数,IF(Q$7="ST",総合テスト係数,IF(Q$7="OT",受入支援係数,IF(Q$7="RL",移行切替係数,IF(Q$7="その他",その他係数,0))))))))) * Q$8,1) -> 0.7 | R17: =ROUNDUP(IF($D17="画面",画面係数,IF($D17="帳票",帳票係数,IF($D17="バッチ",バッチ係数,0))) * IF($I17="特高",特高係数,IF($I17="高",高係数,IF($I17="中",中係数,IF($I17="低",低係数,IF($I17="特低",特低係数,0))))) * IF(R$7="SA",要件定義係数,IF(R$7="UI",基本設計係数,IF(R$7="SS",詳細設計係数,IF(R$7="PS/PG/PT",製作係数,IF(R$7="IT",結合テスト係数,IF(R$7="ST",総合テスト係数,IF(R$7="OT",受入支援係数,IF(R$7="RL",移行切替係数,IF(R$7="その他",その他係数,0))))))))) * R$8,1) -> 0 | T17: =ROUNDUP(SUM(J17:S17)*T$8,1) -> 1.4 | U17: =SUM(J17:T17) -> 10.2 | V17: =U17/20 -> 0.51 | W17: =((J17*J$9) + (K17*K$9) + (L17*L$9) + (M17*M$9) + (N17*N$9) + (O17*O$9) + (P17*P$9) + (Q17*Q$9) + (R17*R$9) + (S17*S$9) + (T17*T$9))/20 -> 538000
A18: 12 | C18: MEKローリー実績受信(OWFT) | D18: バッチ | E18: 有 | F18: 20 | I18: =IF(OR(E18="",F18=""),"", IF(E18="有",IF(F18<=登録上限特低,"特低",IF(F18<=登録上限低,"低",IF(F18<=登録上限中,"中",IF(F18<=登録上限高,"高","特高")))), IF(E18="無",IF(F18<=参照上限特低,"特低",IF(F18<=参照上限低,"低",IF(F18<=参照上限中,"中",IF(F18<=参照上限高,"高","特高")))),""))) -> 中 | J18: =ROUNDUP(IF($D18="画面",画面係数,IF($D18="帳票",帳票係数,IF($D18="バッチ",バッチ係数,0))) * IF($I18="特高",特高係数,IF($I18="高",高係数,IF($I18="中",中係数,IF($I18="低",低係数,IF($I18="特低",特低係数,0))))) * IF(J$7="SA",要件定義係数,IF(J$7="UI",基本設計係数,IF(J$7="SS",詳細設計係数,IF(J$7="PS/PG/PT",製作係数,IF(J$7="IT",結合テスト係数,IF(J$7="ST",総合テスト係数,IF(J$7="OT",受入支援係数,IF(J$7="RL",移行切替係数,IF(J$7="その他",その他係数,0))))))))) * J$8,1) -> 0.6 | K18: =ROUNDUP(IF($D18="画面",画面係数,IF($D18="帳票",帳票係数,IF($D18="バッチ",バッチ係数,0))) * IF($I18="特高",特高係数,IF($I18="高",高係数,IF($I18="中",中係数,IF($I18="低",低係数,IF($I18="特低",特低係数,0))))) * IF(K$7="SA",要件定義係数,IF(K$7="UI",基本設計係数,IF(K$7="SS",詳細設計係数,IF(K$7="PS/PG/PT",製作係数,IF(K$7="IT",結合テスト係数,IF(K$7="ST",総合テスト係数,IF(K$7="OT",受入支援係数,IF(K$7="RL",移行切替係数,IF(K$7="その他",その他係数,0))))))))) * K$8,1) -> 0.9 | L18: =ROUNDUP(IF($D18="画面",画面係数,IF($D18="帳票",帳票係数,IF($D18="バッチ",バッチ係数,0))) * IF($I18="特高",特高係数,IF($I18="高",高係数,IF($I18="中",中係数,IF($I18="低",低係数,IF($I18="特低",特低係数,0))))) * IF(L$7="SA",要件定義係数,IF(L$7="UI",基本設計係数,IF(L$7="SS",詳細設計係数,IF(L$7="PS/PG/PT",製作係数,IF(L$7="IT",結合テスト係数,IF(L$7="ST",総合テスト係数,IF(L$7="OT",受入支援係数,IF(L$7="RL",移行切替係数,IF(L$7="その他",その他係数,0))))))))) * L$8,1) -> 1 | M18: =ROUNDUP(IF($D18="画面",画面係数,IF($D18="帳票",帳票係数,IF($D18="バッチ",バッチ係数,0))) * IF($I18="特高",特高係数,IF($I18="高",高係数,IF($I18="中",中係数,IF($I18="低",低係数,IF($I18="特低",特低係数,0))))) * IF(M$7="SA",要件定義係数,IF(M$7="UI",基本設計係数,IF(M$7="SS",詳細設計係数,IF(M$7="PS/PG/PT",製作係数,IF(M$7="IT",結合テスト係数,IF(M$7="ST",総合テスト係数,IF(M$7="OT",受入支援係数,IF(M$7="RL",移行切替係数,IF(M$7="その他",その他係数,0))))))))) * M$8,1) -> 2 | N18: =ROUNDUP(IF($D18="画面",画面係数,IF($D18="帳票",帳票係数,IF($D18="バッチ",バッチ係数,0))) * IF($I18="特高",特高係数,IF($I18="高",高係数,IF($I18="中",中係数,IF($I18="低",低係数,IF($I18="特低",特低係数,0))))) * IF(N$7="SA",要件定義係数,IF(N$7="UI",基本設計係数,IF(N$7="SS",詳細設計係数,IF(N$7="PS/PG/PT",製作係数,IF(N$7="IT",結合テスト係数,IF(N$7="ST",総合テスト係数,IF(N$7="OT",受入支援係数,IF(N$7="RL",移行切替係数,IF(N$7="その他",その他係数,0))))))))) * N$8,1) -> 1 | O18: =ROUNDUP(IF($D18="画面",画面係数,IF($D18="帳票",帳票係数,IF($D18="バッチ",バッチ係数,0))) * IF($I18="特高",特高係数,IF($I18="高",高係数,IF($I18="中",中係数,IF($I18="低",低係数,IF($I18="特低",特低係数,0))))) * IF(O$7="SA",要件定義係数,IF(O$7="UI",基本設計係数,IF(O$7="SS",詳細設計係数,IF(O$7="PS/PG/PT",製作係数,IF(O$7="IT",結合テスト係数,IF(O$7="ST",総合テスト係数,IF(O$7="OT",受入支援係数,IF(O$7="RL",移行切替係数,IF(O$7="その他",その他係数,0))))))))) * O$8,1) -> 1.1 | P18: =ROUNDUP(IF($D18="画面",画面係数,IF($D18="帳票",帳票係数,IF($D18="バッチ",バッチ係数,0))) * IF($I18="特高",特高係数,IF($I18="高",高係数,IF($I18="中",中係数,IF($I18="低",低係数,IF($I18="特低",特低係数,0))))) * IF(P$7="SA",要件定義係数,IF(P$7="UI",基本設計係数,IF(P$7="SS",詳細設計係数,IF(P$7="PS/PG/PT",製作係数,IF(P$7="IT",結合テスト係数,IF(P$7="ST",総合テスト係数,IF(P$7="OT",受入支援係数,IF(P$7="RL",移行切替係数,IF(P$7="その他",その他係数,0))))))))) * P$8,1) -> 0.3 | Q18: =ROUNDUP(IF($D18="画面",画面係数,IF($D18="帳票",帳票係数,IF($D18="バッチ",バッチ係数,0))) * IF($I18="特高",特高係数,IF($I18="高",高係数,IF($I18="中",中係数,IF($I18="低",低係数,IF($I18="特低",特低係数,0))))) * IF(Q$7="SA",要件定義係数,IF(Q$7="UI",基本設計係数,IF(Q$7="SS",詳細設計係数,IF(Q$7="PS/PG/PT",製作係数,IF(Q$7="IT",結合テスト係数,IF(Q$7="ST",総合テスト係数,IF(Q$7="OT",受入支援係数,IF(Q$7="RL",移行切替係数,IF(Q$7="その他",その他係数,0))))))))) * Q$8,1) -> 0.6 | R18: =ROUNDUP(IF($D18="画面",画面係数,IF($D18="帳票",帳票係数,IF($D18="バッチ",バッチ係数,0))) * IF($I18="特高",特高係数,IF($I18="高",高係数,IF($I18="中",中係数,IF($I18="低",低係数,IF($I18="特低",特低係数,0))))) * IF(R$7="SA",要件定義係数,IF(R$7="UI",基本設計係数,IF(R$7="SS",詳細設計係数,IF(R$7="PS/PG/PT",製作係数,IF(R$7="IT",結合テスト係数,IF(R$7="ST",総合テスト係数,IF(R$7="OT",受入支援係数,IF(R$7="RL",移行切替係数,IF(R$7="その他",その他係数,0))))))))) * R$8,1) -> 0 | T18: =ROUNDUP(SUM(J18:S18)*T$8,1) -> 1.2 | U18: =SUM(J18:T18) -> 8.7 | V18: =U18/20 -> 0.435 | W18: =((J18*J$9) + (K18*K$9) + (L18*L$9) + (M18*M$9) + (N18*N$9) + (O18*O$9) + (P18*P$9) + (Q18*Q$9) + (R18*R$9) + (S18*S$9) + (T18*T$9))/20 -> 459000
A19: 13 | C19: MEKドラム出荷実績受信(ファイル取込) | D19: バッチ | E19: 有 | F19: 30 | I19: =IF(OR(E19="",F19=""),"", IF(E19="有",IF(F19<=登録上限特低,"特低",IF(F19<=登録上限低,"低",IF(F19<=登録上限中,"中",IF(F19<=登録上限高,"高","特高")))), IF(E19="無",IF(F19<=参照上限特低,"特低",IF(F19<=参照上限低,"低",IF(F19<=参照上限中,"中",IF(F19<=参照上限高,"高","特高")))),""))) -> 高 | J19: =ROUNDUP(IF($D19="画面",画面係数,IF($D19="帳票",帳票係数,IF($D19="バッチ",バッチ係数,0))) * IF($I19="特高",特高係数,IF($I19="高",高係数,IF($I19="中",中係数,IF($I19="低",低係数,IF($I19="特低",特低係数,0))))) * IF(J$7="SA",要件定義係数,IF(J$7="UI",基本設計係数,IF(J$7="SS",詳細設計係数,IF(J$7="PS/PG/PT",製作係数,IF(J$7="IT",結合テスト係数,IF(J$7="ST",総合テスト係数,IF(J$7="OT",受入支援係数,IF(J$7="RL",移行切替係数,IF(J$7="その他",その他係数,0))))))))) * J$8,1) -> 0.7 | K19: =ROUNDUP(IF($D19="画面",画面係数,IF($D19="帳票",帳票係数,IF($D19="バッチ",バッチ係数,0))) * IF($I19="特高",特高係数,IF($I19="高",高係数,IF($I19="中",中係数,IF($I19="低",低係数,IF($I19="特低",特低係数,0))))) * IF(K$7="SA",要件定義係数,IF(K$7="UI",基本設計係数,IF(K$7="SS",詳細設計係数,IF(K$7="PS/PG/PT",製作係数,IF(K$7="IT",結合テスト係数,IF(K$7="ST",総合テスト係数,IF(K$7="OT",受入支援係数,IF(K$7="RL",移行切替係数,IF(K$7="その他",その他係数,0))))))))) * K$8,1) -> 1.1 | L19: =ROUNDUP(IF($D19="画面",画面係数,IF($D19="帳票",帳票係数,IF($D19="バッチ",バッチ係数,0))) * IF($I19="特高",特高係数,IF($I19="高",高係数,IF($I19="中",中係数,IF($I19="低",低係数,IF($I19="特低",特低係数,0))))) * IF(L$7="SA",要件定義係数,IF(L$7="UI",基本設計係数,IF(L$7="SS",詳細設計係数,IF(L$7="PS/PG/PT",製作係数,IF(L$7="IT",結合テスト係数,IF(L$7="ST",総合テスト係数,IF(L$7="OT",受入支援係数,IF(L$7="RL",移行切替係数,IF(L$7="その他",その他係数,0))))))))) * L$8,1) -> 1.2 | M19: =ROUNDUP(IF($D19="画面",画面係数,IF($D19="帳票",帳票係数,IF($D19="バッチ",バッチ係数,0))) * IF($I19="特高",特高係数,IF($I19="高",高係数,IF($I19="中",中係数,IF($I19="低",低係数,IF($I19="特低",特低係数,0))))) * IF(M$7="SA",要件定義係数,IF(M$7="UI",基本設計係数,IF(M$7="SS",詳細設計係数,IF(M$7="PS/PG/PT",製作係数,IF(M$7="IT",結合テスト係数,IF(M$7="ST",総合テスト係数,IF(M$7="OT",受入支援係数,IF(M$7="RL",移行切替係数,IF(M$7="その他",その他係数,0))))))))) * M$8,1) -> 2.3 | N19: =ROUNDUP(IF($D19="画面",画面係数,IF($D19="帳票",帳票係数,IF($D19="バッチ",バッチ係数,0))) * IF($I19="特高",特高係数,IF($I19="高",高係数,IF($I19="中",中係数,IF($I19="低",低係数,IF($I19="特低",特低係数,0))))) * IF(N$7="SA",要件定義係数,IF(N$7="UI",基本設計係数,IF(N$7="SS",詳細設計係数,IF(N$7="PS/PG/PT",製作係数,IF(N$7="IT",結合テスト係数,IF(N$7="ST",総合テスト係数,IF(N$7="OT",受入支援係数,IF(N$7="RL",移行切替係数,IF(N$7="その他",その他係数,0))))))))) * N$8,1) -> 1.2 | O19: =ROUNDUP(IF($D19="画面",画面係数,IF($D19="帳票",帳票係数,IF($D19="バッチ",バッチ係数,0))) * IF($I19="特高",特高係数,IF($I19="高",高係数,IF($I19="中",中係数,IF($I19="低",低係数,IF($I19="特低",特低係数,0))))) * IF(O$7="SA",要件定義係数,IF(O$7="UI",基本設計係数,IF(O$7="SS",詳細設計係数,IF(O$7="PS/PG/PT",製作係数,IF(O$7="IT",結合テスト係数,IF(O$7="ST",総合テスト係数,IF(O$7="OT",受入支援係数,IF(O$7="RL",移行切替係数,IF(O$7="その他",その他係数,0))))))))) * O$8,1) -> 1.2 | P19: =ROUNDUP(IF($D19="画面",画面係数,IF($D19="帳票",帳票係数,IF($D19="バッチ",バッチ係数,0))) * IF($I19="特高",特高係数,IF($I19="高",高係数,IF($I19="中",中係数,IF($I19="低",低係数,IF($I19="特低",特低係数,0))))) * IF(P$7="SA",要件定義係数,IF(P$7="UI",基本設計係数,IF(P$7="SS",詳細設計係数,IF(P$7="PS/PG/PT",製作係数,IF(P$7="IT",結合テスト係数,IF(P$7="ST",総合テスト係数,IF(P$7="OT",受入支援係数,IF(P$7="RL",移行切替係数,IF(P$7="その他",その他係数,0))))))))) * P$8,1) -> 0.4 | Q19: =ROUNDUP(IF($D19="画面",画面係数,IF($D19="帳票",帳票係数,IF($D19="バッチ",バッチ係数,0))) * IF($I19="特高",特高係数,IF($I19="高",高係数,IF($I19="中",中係数,IF($I19="低",低係数,IF($I19="特低",特低係数,0))))) * IF(Q$7="SA",要件定義係数,IF(Q$7="UI",基本設計係数,IF(Q$7="SS",詳細設計係数,IF(Q$7="PS/PG/PT",製作係数,IF(Q$7="IT",結合テスト係数,IF(Q$7="ST",総合テスト係数,IF(Q$7="OT",受入支援係数,IF(Q$7="RL",移行切替係数,IF(Q$7="その他",その他係数,0))))))))) * Q$8,1) -> 0.7 | R19: =ROUNDUP(IF($D19="画面",画面係数,IF($D19="帳票",帳票係数,IF($D19="バッチ",バッチ係数,0))) * IF($I19="特高",特高係数,IF($I19="高",高係数,IF($I19="中",中係数,IF($I19="低",低係数,IF($I19="特低",特低係数,0))))) * IF(R$7="SA",要件定義係数,IF(R$7="UI",基本設計係数,IF(R$7="SS",詳細設計係数,IF(R$7="PS/PG/PT",製作係数,IF(R$7="IT",結合テスト係数,IF(R$7="ST",総合テスト係数,IF(R$7="OT",受入支援係数,IF(R$7="RL",移行切替係数,IF(R$7="その他",その他係数,0))))))))) * R$8,1) -> 0 | T19: =ROUNDUP(SUM(J19:S19)*T$8,1) -> 1.4 | U19: =SUM(J19:T19) -> 10.2 | V19: =U19/20 -> 0.51 | W19: =((J19*J$9) + (K19*K$9) + (L19*L$9) + (M19*M$9) + (N19*N$9) + (O19*O$9) + (P19*P$9) + (Q19*Q$9) + (R19*R$9) + (S19*S$9) + (T19*T$9))/20 -> 538000
A20: 15 | C20: MEKドラム出荷実績受信(OWFT) | D20: バッチ | E20: 有 | F20: 20 | I20: =IF(OR(E20="",F20=""),"", IF(E20="有",IF(F20<=登録上限特低,"特低",IF(F20<=登録上限低,"低",IF(F20<=登録上限中,"中",IF(F20<=登録上限高,"高","特高")))), IF(E20="無",IF(F20<=参照上限特低,"特低",IF(F20<=参照上限低,"低",IF(F20<=参照上限中,"中",IF(F20<=参照上限高,"高","特高")))),""))) -> 中 | J20: =ROUNDUP(IF($D20="画面",画面係数,IF($D20="帳票",帳票係数,IF($D20="バッチ",バッチ係数,0))) * IF($I20="特高",特高係数,IF($I20="高",高係数,IF($I20="中",中係数,IF($I20="低",低係数,IF($I20="特低",特低係数,0))))) * IF(J$7="SA",要件定義係数,IF(J$7="UI",基本設計係数,IF(J$7="SS",詳細設計係数,IF(J$7="PS/PG/PT",製作係数,IF(J$7="IT",結合テスト係数,IF(J$7="ST",総合テスト係数,IF(J$7="OT",受入支援係数,IF(J$7="RL",移行切替係数,IF(J$7="その他",その他係数,0))))))))) * J$8,1) -> 0.6 | K20: =ROUNDUP(IF($D20="画面",画面係数,IF($D20="帳票",帳票係数,IF($D20="バッチ",バッチ係数,0))) * IF($I20="特高",特高係数,IF($I20="高",高係数,IF($I20="中",中係数,IF($I20="低",低係数,IF($I20="特低",特低係数,0))))) * IF(K$7="SA",要件定義係数,IF(K$7="UI",基本設計係数,IF(K$7="SS",詳細設計係数,IF(K$7="PS/PG/PT",製作係数,IF(K$7="IT",結合テスト係数,IF(K$7="ST",総合テスト係数,IF(K$7="OT",受入支援係数,IF(K$7="RL",移行切替係数,IF(K$7="その他",その他係数,0))))))))) * K$8,1) -> 0.9 | L20: =ROUNDUP(IF($D20="画面",画面係数,IF($D20="帳票",帳票係数,IF($D20="バッチ",バッチ係数,0))) * IF($I20="特高",特高係数,IF($I20="高",高係数,IF($I20="中",中係数,IF($I20="低",低係数,IF($I20="特低",特低係数,0))))) * IF(L$7="SA",要件定義係数,IF(L$7="UI",基本設計係数,IF(L$7="SS",詳細設計係数,IF(L$7="PS/PG/PT",製作係数,IF(L$7="IT",結合テスト係数,IF(L$7="ST",総合テスト係数,IF(L$7="OT",受入支援係数,IF(L$7="RL",移行切替係数,IF(L$7="その他",その他係数,0))))))))) * L$8,1) -> 1 | M20: =ROUNDUP(IF($D20="画面",画面係数,IF($D20="帳票",帳票係数,IF($D20="バッチ",バッチ係数,0))) * IF($I20="特高",特高係数,IF($I20="高",高係数,IF($I20="中",中係数,IF($I20="低",低係数,IF($I20="特低",特低係数,0))))) * IF(M$7="SA",要件定義係数,IF(M$7="UI",基本設計係数,IF(M$7="SS",詳細設計係数,IF(M$7="PS/PG/PT",製作係数,IF(M$7="IT",結合テスト係数,IF(M$7="ST",総合テスト係数,IF(M$7="OT",受入支援係数,IF(M$7="RL",移行切替係数,IF(M$7="その他",その他係数,0))))))))) * M$8,1) -> 2 | N20: =ROUNDUP(IF($D20="画面",画面係数,IF($D20="帳票",帳票係数,IF($D20="バッチ",バッチ係数,0))) * IF($I20="特高",特高係数,IF($I20="高",高係数,IF($I20="中",中係数,IF($I20="低",低係数,IF($I20="特低",特低係数,0))))) * IF(N$7="SA",要件定義係数,IF(N$7="UI",基本設計係数,IF(N$7="SS",詳細設計係数,IF(N$7="PS/PG/PT",製作係数,IF(N$7="IT",結合テスト係数,IF(N$7="ST",総合テスト係数,IF(N$7="OT",受入支援係数,IF(N$7="RL",移行切替係数,IF(N$7="その他",その他係数,0))))))))) * N$8,1) -> 1 | O20: =ROUNDUP(IF($D20="画面",画面係数,IF($D20="帳票",帳票係数,IF($D20="バッチ",バッチ係数,0))) * IF($I20="特高",特高係数,IF($I20="高",高係数,IF($I20="中",中係数,IF($I20="低",低係数,IF($I20="特低",特低係数,0))))) * IF(O$7="SA",要件定義係数,IF(O$7="UI",基本設計係数,IF(O$7="SS",詳細設計係数,IF(O$7="PS/PG/PT",製作係数,IF(O$7="IT",結合テスト係数,IF(O$7="ST",総合テスト係数,IF(O$7="OT",受入支援係数,IF(O$7="RL",移行切替係数,IF(O$7="その他",その他係数,0))))))))) * O$8,1) -> 1.1 | P20: =ROUNDUP(IF($D20="画面",画面係数,IF($D20="帳票",帳票係数,IF($D20="バッチ",バッチ係数,0))) * IF($I20="特高",特高係数,IF($I20="高",高係数,IF($I20="中",中係数,IF($I20="低",低係数,IF($I20="特低",特低係数,0))))) * IF(P$7="SA",要件定義係数,IF(P$7="UI",基本設計係数,IF(P$7="SS",詳細設計係数,IF(P$7="PS/PG/PT",製作係数,IF(P$7="IT",結合テスト係数,IF(P$7="ST",総合テスト係数,IF(P$7="OT",受入支援係数,IF(P$7="RL",移行切替係数,IF(P$7="その他",その他係数,0))))))))) * P$8,1) -> 0.3 | Q20: =ROUNDUP(IF($D20="画面",画面係数,IF($D20="帳票",帳票係数,IF($D20="バッチ",バッチ係数,0))) * IF($I20="特高",特高係数,IF($I20="高",高係数,IF($I20="中",中係数,IF($I20="低",低係数,IF($I20="特低",特低係数,0))))) * IF(Q$7="SA",要件定義係数,IF(Q$7="UI",基本設計係数,IF(Q$7="SS",詳細設計係数,IF(Q$7="PS/PG/PT",製作係数,IF(Q$7="IT",結合テスト係数,IF(Q$7="ST",総合テスト係数,IF(Q$7="OT",受入支援係数,IF(Q$7="RL",移行切替係数,IF(Q$7="その他",その他係数,0))))))))) * Q$8,1) -> 0.6 | R20: =ROUNDUP(IF($D20="画面",画面係数,IF($D20="帳票",帳票係数,IF($D20="バッチ",バッチ係数,0))) * IF($I20="特高",特高係数,IF($I20="高",高係数,IF($I20="中",中係数,IF($I20="低",低係数,IF($I20="特低",特低係数,0))))) * IF(R$7="SA",要件定義係数,IF(R$7="UI",基本設計係数,IF(R$7="SS",詳細設計係数,IF(R$7="PS/PG/PT",製作係数,IF(R$7="IT",結合テスト係数,IF(R$7="ST",総合テスト係数,IF(R$7="OT",受入支援係数,IF(R$7="RL",移行切替係数,IF(R$7="その他",その他係数,0))))))))) * R$8,1) -> 0 | T20: =ROUNDUP(SUM(J20:S20)*T$8,1) -> 1.2 | U20: =SUM(J20:T20) -> 8.7 | V20: =U20/20 -> 0.435 | W20: =((J20*J$9) + (K20*K$9) + (L20*L$9) + (M20*M$9) + (N20*N$9) + (O20*O$9) + (P20*P$9) + (Q20*Q$9) + (R20*R$9) + (S20*S$9) + (T20*T$9))/20 -> 459000
A21: 16 | C21: ログ処理 | D21: バッチ | E21: 無 | F21: 15 | I21: =IF(OR(E21="",F21=""),"", IF(E21="有",IF(F21<=登録上限特低,"特低",IF(F21<=登録上限低,"低",IF(F21<=登録上限中,"中",IF(F21<=登録上限高,"高","特高")))), IF(E21="無",IF(F21<=参照上限特低,"特低",IF(F21<=参照上限低,"低",IF(F21<=参照上限中,"中",IF(F21<=参照上限高,"高","特高")))),""))) -> 低 | J21: =ROUNDUP(IF($D21="画面",画面係数,IF($D21="帳票",帳票係数,IF($D21="バッチ",バッチ係数,0))) * IF($I21="特高",特高係数,IF($I21="高",高係数,IF($I21="中",中係数,IF($I21="低",低係数,IF($I21="特低",特低係数,0))))) * IF(J$7="SA",要件定義係数,IF(J$7="UI",基本設計係数,IF(J$7="SS",詳細設計係数,IF(J$7="PS/PG/PT",製作係数,IF(J$7="IT",結合テスト係数,IF(J$7="ST",総合テスト係数,IF(J$7="OT",受入支援係数,IF(J$7="RL",移行切替係数,IF(J$7="その他",その他係数,0))))))))) * J$8,1) -> 0.3 | K21: =ROUNDUP(IF($D21="画面",画面係数,IF($D21="帳票",帳票係数,IF($D21="バッチ",バッチ係数,0))) * IF($I21="特高",特高係数,IF($I21="高",高係数,IF($I21="中",中係数,IF($I21="低",低係数,IF($I21="特低",特低係数,0))))) * IF(K$7="SA",要件定義係数,IF(K$7="UI",基本設計係数,IF(K$7="SS",詳細設計係数,IF(K$7="PS/PG/PT",製作係数,IF(K$7="IT",結合テスト係数,IF(K$7="ST",総合テスト係数,IF(K$7="OT",受入支援係数,IF(K$7="RL",移行切替係数,IF(K$7="その他",その他係数,0))))))))) * K$8,1) -> 0.5 | L21: =ROUNDUP(IF($D21="画面",画面係数,IF($D21="帳票",帳票係数,IF($D21="バッチ",バッチ係数,0))) * IF($I21="特高",特高係数,IF($I21="高",高係数,IF($I21="中",中係数,IF($I21="低",低係数,IF($I21="特低",特低係数,0))))) * IF(L$7="SA",要件定義係数,IF(L$7="UI",基本設計係数,IF(L$7="SS",詳細設計係数,IF(L$7="PS/PG/PT",製作係数,IF(L$7="IT",結合テスト係数,IF(L$7="ST",総合テスト係数,IF(L$7="OT",受入支援係数,IF(L$7="RL",移行切替係数,IF(L$7="その他",その他係数,0))))))))) * L$8,1) -> 0.5 | M21: =ROUNDUP(IF($D21="画面",画面係数,IF($D21="帳票",帳票係数,IF($D21="バッチ",バッチ係数,0))) * IF($I21="特高",特高係数,IF($I21="高",高係数,IF($I21="中",中係数,IF($I21="低",低係数,IF($I21="特低",特低係数,0))))) * IF(M$7="SA",要件定義係数,IF(M$7="UI",基本設計係数,IF(M$7="SS",詳細設計係数,IF(M$7="PS/PG/PT",製作係数,IF(M$7="IT",結合テスト係数,IF(M$7="ST",総合テスト係数,IF(M$7="OT",受入支援係数,IF(M$7="RL",移行切替係数,IF(M$7="その他",その他係数,0))))))))) * M$8,1) -> 1 | N21: =ROUNDUP(IF($D21="画面",画面係数,IF($D21="帳票",帳票係数,IF($D21="バッチ",バッチ係数,0))) * IF($I21="特高",特高係数,IF($I21="高",高係数,IF($I21="中",中係数,IF($I21="低",低係数,IF($I21="特低",特低係数,0))))) * IF(N$7="SA",要件定義係数,IF(N$7="UI",基本設計係数,IF(N$7="SS",詳細設計係数,IF(N$7="PS/PG/PT",製作係数,IF(N$7="IT",結合テスト係数,IF(N$7="ST",総合テスト係数,IF(N$7="OT",受入支援係数,IF(N$7="RL",移行切替係数,IF(N$7="その他",その他係数,0))))))))) * N$8,1) -> 0.5 | O21: =ROUNDUP(IF($D21="画面",画面係数,IF($D21="帳票",帳票係数,IF($D21="バッチ",バッチ係数,0))) * IF($I21="特高",特高係数,IF($I21="高",高係数,IF($I21="中",中係数,IF($I21="低",低係数,IF($I21="特低",特低係数,0))))) * IF(O$7="SA",要件定義係数,IF(O$7="UI",基本設計係数,IF(O$7="SS",詳細設計係数,IF(O$7="PS/PG/PT",製作係数,IF(O$7="IT",結合テスト係数,IF(O$7="ST",総合テスト係数,IF(O$7="OT",受入支援係数,IF(O$7="RL",移行切替係数,IF(O$7="その他",その他係数,0))))))))) * O$8,1) -> 0.6 | P21: =ROUNDUP(IF($D21="画面",画面係数,IF($D21="帳票",帳票係数,IF($D21="バッチ",バッチ係数,0))) * IF($I21="特高",特高係数,IF($I21="高",高係数,IF($I21="中",中係数,IF($I21="低",低係数,IF($I21="特低",特低係数,0))))) * IF(P$7="SA",要件定義係数,IF(P$7="UI",基本設計係数,IF(P$7="SS",詳細設計係数,IF(P$7="PS/PG/PT",製作係数,IF(P$7="IT",結合テスト係数,IF(P$7="ST",総合テスト係数,IF(P$7="OT",受入支援係数,IF(P$7="RL",移行切替係数,IF(P$7="その他",その他係数,0))))))))) * P$8,1) -> 0.2 | Q21: =ROUNDUP(IF($D21="画面",画面係数,IF($D21="帳票",帳票係数,IF($D21="バッチ",バッチ係数,0))) * IF($I21="特高",特高係数,IF($I21="高",高係数,IF($I21="中",中係数,IF($I21="低",低係数,IF($I21="特低",特低係数,0))))) * IF(Q$7="SA",要件定義係数,IF(Q$7="UI",基本設計係数,IF(Q$7="SS",詳細設計係数,IF(Q$7="PS/PG/PT",製作係数,IF(Q$7="IT",結合テスト係数,IF(Q$7="ST",総合テスト係数,IF(Q$7="OT",受入支援係数,IF(Q$7="RL",移行切替係数,IF(Q$7="その他",その他係数,0))))))))) * Q$8,1) -> 0.3 | R21: =ROUNDUP(IF($D21="画面",画面係数,IF($D21="帳票",帳票係数,IF($D21="バッチ",バッチ係数,0))) * IF($I21="特高",特高係数,IF($I21="高",高係数,IF($I21="中",中係数,IF($I21="低",低係数,IF($I21="特低",特低係数,0))))) * IF(R$7="SA",要件定義係数,IF(R$7="UI",基本設計係数,IF(R$7="SS",詳細設計係数,IF(R$7="PS/PG/PT",製作係数,IF(R$7="IT",結合テスト係数,IF(R$7="ST",総合テスト係数,IF(R$7="OT",受入支援係数,IF(R$7="RL",移行切替係数,IF(R$7="その他",その他係数,0))))))))) * R$8,1) -> 0 | T21: =ROUNDUP(SUM(J21:S21)*T$8,1) -> 0.6 | U21: =SUM(J21:T21) -> 4.5 | V21: =U21/20 -> 0.225 | W21: =((J21*J$9) + (K21*K$9) + (L21*L$9) + (M21*M$9) + (N21*N$9) + (O21*O$9) + (P21*P$9) + (Q21*Q$9) + (R21*R$9) + (S21*S$9) + (T21*T$9))/20 -> 237000
A22: 19 | I22: =IF(OR(E22="",F22=""),"", IF(E22="有",IF(F22<=登録上限特低,"特低",IF(F22<=登録上限低,"低",IF(F22<=登録上限中,"中",IF(F22<=登録上限高,"高","特高")))), IF(E22="無",IF(F22<=参照上限特低,"特低",IF(F22<=参照上限低,"低",IF(F22<=参照上限中,"中",IF(F22<=参照上限高,"高","特高")))),""))) | J22: =ROUNDUP(IF($D22="画面",画面係数,IF($D22="帳票",帳票係数,IF($D22="バッチ",バッチ係数,0))) * IF($I22="特高",特高係数,IF($I22="高",高係数,IF($I22="中",中係数,IF($I22="低",低係数,IF($I22="特低",特低係数,0))))) * IF(J$7="SA",要件定義係数,IF(J$7="UI",基本設計係数,IF(J$7="SS",詳細設計係数,IF(J$7="PS/PG/PT",製作係数,IF(J$7="IT",結合テスト係数,IF(J$7="ST",総合テスト係数,IF(J$7="OT",受入支援係数,IF(J$7="RL",移行切替係数,IF(J$7="その他",その他係数,0))))))))) * J$8,1) -> 0 | K22: =ROUNDUP(IF($D22="画面",画面係数,IF($D22="帳票",帳票係数,IF($D22="バッチ",バッチ係数,0))) * IF($I22="特高",特高係数,IF($I22="高",高係数,IF($I22="中",中係数,IF($I22="低",低係数,IF($I22="特低",特低係数,0))))) * IF(K$7="SA",要件定義係数,IF(K$7="UI",基本設計係数,IF(K$7="SS",詳細設計係数,IF(K$7="PS/PG/PT",製作係数,IF(K$7="IT",結合テスト係数,IF(K$7="ST",総合テスト係数,IF(K$7="OT",受入支援係数,IF(K$7="RL",移行切替係数,IF(K$7="その他",その他係数,0))))))))) * K$8,1) -> 0 | L22: =ROUNDUP(IF($D22="画面",画面係数,IF($D22="帳票",帳票係数,IF($D22="バッチ",バッチ係数,0))) * IF($I22="特高",特高係数,IF($I22="高",高係数,IF($I22="中",中係数,IF($I22="低",低係数,IF($I22="特低",特低係数,0))))) * IF(L$7="SA",要件定義係数,IF(L$7="UI",基本設計係数,IF(L$7="SS",詳細設計係数,IF(L$7="PS/PG/PT",製作係数,IF(L$7="IT",結合テスト係数,IF(L$7="ST",総合テスト係数,IF(L$7="OT",受入支援係数,IF(L$7="RL",移行切替係数,IF(L$7="その他",その他係数,0))))))))) * L$8,1) -> 0 | M22: =ROUNDUP(IF($D22="画面",画面係数,IF($D22="帳票",帳票係数,IF($D22="バッチ",バッチ係数,0))) * IF($I22="特高",特高係数,IF($I22="高",高係数,IF($I22="中",中係数,IF($I22="低",低係数,IF($I22="特低",特低係数,0))))) * IF(M$7="SA",要件定義係数,IF(M$7="UI",基本設計係数,IF(M$7="SS",詳細設計係数,IF(M$7="PS/PG/PT",製作係数,IF(M$7="IT",結合テスト係数,IF(M$7="ST",総合テスト係数,IF(M$7="OT",受入支援係数,IF(M$7="RL",移行切替係数,IF(M$7="その他",その他係数,0))))))))) * M$8,1) -> 0 | N22: =ROUNDUP(IF($D22="画面",画面係数,IF($D22="帳票",帳票係数,IF($D22="バッチ",バッチ係数,0))) * IF($I22="特高",特高係数,IF($I22="高",高係数,IF($I22="中",中係数,IF($I22="低",低係数,IF($I22="特低",特低係数,0))))) * IF(N$7="SA",要件定義係数,IF(N$7="UI",基本設計係数,IF(N$7="SS",詳細設計係数,IF(N$7="PS/PG/PT",製作係数,IF(N$7="IT",結合テスト係数,IF(N$7="ST",総合テスト係数,IF(N$7="OT",受入支援係数,IF(N$7="RL",移行切替係数,IF(N$7="その他",その他係数,0))))))))) * N$8,1) -> 0 | O22: =ROUNDUP(IF($D22="画面",画面係数,IF($D22="帳票",帳票係数,IF($D22="バッチ",バッチ係数,0))) * IF($I22="特高",特高係数,IF($I22="高",高係数,IF($I22="中",中係数,IF($I22="低",低係数,IF($I22="特低",特低係数,0))))) * IF(O$7="SA",要件定義係数,IF(O$7="UI",基本設計係数,IF(O$7="SS",詳細設計係数,IF(O$7="PS/PG/PT",製作係数,IF(O$7="IT",結合テスト係数,IF(O$7="ST",総合テスト係数,IF(O$7="OT",受入支援係数,IF(O$7="RL",移行切替係数,IF(O$7="その他",その他係数,0))))))))) * O$8,1) -> 0 | P22: =ROUNDUP(IF($D22="画面",画面係数,IF($D22="帳票",帳票係数,IF($D22="バッチ",バッチ係数,0))) * IF($I22="特高",特高係数,IF($I22="高",高係数,IF($I22="中",中係数,IF($I22="低",低係数,IF($I22="特低",特低係数,0))))) * IF(P$7="SA",要件定義係数,IF(P$7="UI",基本設計係数,IF(P$7="SS",詳細設計係数,IF(P$7="PS/PG/PT",製作係数,IF(P$7="IT",結合テスト係数,IF(P$7="ST",総合テスト係数,IF(P$7="OT",受入支援係数,IF(P$7="RL",移行切替係数,IF(P$7="その他",その他係数,0))))))))) * P$8,1) -> 0 | Q22: =ROUNDUP(IF($D22="画面",画面係数,IF($D22="帳票",帳票係数,IF($D22="バッチ",バッチ係数,0))) * IF($I22="特高",特高係数,IF($I22="高",高係数,IF($I22="中",中係数,IF($I22="低",低係数,IF($I22="特低",特低係数,0))))) * IF(Q$7="SA",要件定義係数,IF(Q$7="UI",基本設計係数,IF(Q$7="SS",詳細設計係数,IF(Q$7="PS/PG/PT",製作係数,IF(Q$7="IT",結合テスト係数,IF(Q$7="ST",総合テスト係数,IF(Q$7="OT",受入支援係数,IF(Q$7="RL",移行切替係数,IF(Q$7="その他",その他係数,0))))))))) * Q$8,1) -> 0 | R22: =ROUNDUP(IF($D22="画面",画面係数,IF($D22="帳票",帳票係数,IF($D22="バッチ",バッチ係数,0))) * IF($I22="特高",特高係数,IF($I22="高",高係数,IF($I22="中",中係数,IF($I22="低",低係数,IF($I22="特低",特低係数,0))))) * IF(R$7="SA",要件定義係数,IF(R$7="UI",基本設計係数,IF(R$7="SS",詳細設計係数,IF(R$7="PS/PG/PT",製作係数,IF(R$7="IT",結合テスト係数,IF(R$7="ST",総合テスト係数,IF(R$7="OT",受入支援係数,IF(R$7="RL",移行切替係数,IF(R$7="その他",その他係数,0))))))))) * R$8,1) -> 0 | T22: =ROUNDUP(SUM(J22:S22)*T$8,1) -> 0 | U22: =SUM(J22:T22) -> 0 | V22: =U22/20 -> 0 | W22: =((J22*J$9) + (K22*K$9) + (L22*L$9) + (M22*M$9) + (N22*N$9) + (O22*O$9) + (P22*P$9) + (Q22*Q$9) + (R22*R$9) + (S22*S$9) + (T22*T$9))/20 -> 0
A23: 20 | I23: =IF(OR(E23="",F23=""),"", IF(E23="有",IF(F23<=登録上限特低,"特低",IF(F23<=登録上限低,"低",IF(F23<=登録上限中,"中",IF(F23<=登録上限高,"高","特高")))), IF(E23="無",IF(F23<=参照上限特低,"特低",IF(F23<=参照上限低,"低",IF(F23<=参照上限中,"中",IF(F23<=参照上限高,"高","特高")))),""))) | J23: =ROUNDUP(IF($D23="画面",画面係数,IF($D23="帳票",帳票係数,IF($D23="バッチ",バッチ係数,0))) * IF($I23="特高",特高係数,IF($I23="高",高係数,IF($I23="中",中係数,IF($I23="低",低係数,IF($I23="特低",特低係数,0))))) * IF(J$7="SA",要件定義係数,IF(J$7="UI",基本設計係数,IF(J$7="SS",詳細設計係数,IF(J$7="PS/PG/PT",製作係数,IF(J$7="IT",結合テスト係数,IF(J$7="ST",総合テスト係数,IF(J$7="OT",受入支援係数,IF(J$7="RL",移行切替係数,IF(J$7="その他",その他係数,0))))))))) * J$8,1) -> 0 | K23: =ROUNDUP(IF($D23="画面",画面係数,IF($D23="帳票",帳票係数,IF($D23="バッチ",バッチ係数,0))) * IF($I23="特高",特高係数,IF($I23="高",高係数,IF($I23="中",中係数,IF($I23="低",低係数,IF($I23="特低",特低係数,0))))) * IF(K$7="SA",要件定義係数,IF(K$7="UI",基本設計係数,IF(K$7="SS",詳細設計係数,IF(K$7="PS/PG/PT",製作係数,IF(K$7="IT",結合テスト係数,IF(K$7="ST",総合テスト係数,IF(K$7="OT",受入支援係数,IF(K$7="RL",移行切替係数,IF(K$7="その他",その他係数,0))))))))) * K$8,1) -> 0 | L23: =ROUNDUP(IF($D23="画面",画面係数,IF($D23="帳票",帳票係数,IF($D23="バッチ",バッチ係数,0))) * IF($I23="特高",特高係数,IF($I23="高",高係数,IF($I23="中",中係数,IF($I23="低",低係数,IF($I23="特低",特低係数,0))))) * IF(L$7="SA",要件定義係数,IF(L$7="UI",基本設計係数,IF(L$7="SS",詳細設計係数,IF(L$7="PS/PG/PT",製作係数,IF(L$7="IT",結合テスト係数,IF(L$7="ST",総合テスト係数,IF(L$7="OT",受入支援係数,IF(L$7="RL",移行切替係数,IF(L$7="その他",その他係数,0))))))))) * L$8,1) -> 0 | M23: =ROUNDUP(IF($D23="画面",画面係数,IF($D23="帳票",帳票係数,IF($D23="バッチ",バッチ係数,0))) * IF($I23="特高",特高係数,IF($I23="高",高係数,IF($I23="中",中係数,IF($I23="低",低係数,IF($I23="特低",特低係数,0))))) * IF(M$7="SA",要件定義係数,IF(M$7="UI",基本設計係数,IF(M$7="SS",詳細設計係数,IF(M$7="PS/PG/PT",製作係数,IF(M$7="IT",結合テスト係数,IF(M$7="ST",総合テスト係数,IF(M$7="OT",受入支援係数,IF(M$7="RL",移行切替係数,IF(M$7="その他",その他係数,0))))))))) * M$8,1) -> 0 | N23: =ROUNDUP(IF($D23="画面",画面係数,IF($D23="帳票",帳票係数,IF($D23="バッチ",バッチ係数,0))) * IF($I23="特高",特高係数,IF($I23="高",高係数,IF($I23="中",中係数,IF($I23="低",低係数,IF($I23="特低",特低係数,0))))) * IF(N$7="SA",要件定義係数,IF(N$7="UI",基本設計係数,IF(N$7="SS",詳細設計係数,IF(N$7="PS/PG/PT",製作係数,IF(N$7="IT",結合テスト係数,IF(N$7="ST",総合テスト係数,IF(N$7="OT",受入支援係数,IF(N$7="RL",移行切替係数,IF(N$7="その他",その他係数,0))))))))) * N$8,1) -> 0 | O23: =ROUNDUP(IF($D23="画面",画面係数,IF($D23="帳票",帳票係数,IF($D23="バッチ",バッチ係数,0))) * IF($I23="特高",特高係数,IF($I23="高",高係数,IF($I23="中",中係数,IF($I23="低",低係数,IF($I23="特低",特低係数,0))))) * IF(O$7="SA",要件定義係数,IF(O$7="UI",基本設計係数,IF(O$7="SS",詳細設計係数,IF(O$7="PS/PG/PT",製作係数,IF(O$7="IT",結合テスト係数,IF(O$7="ST",総合テスト係数,IF(O$7="OT",受入支援係数,IF(O$7="RL",移行切替係数,IF(O$7="その他",その他係数,0))))))))) * O$8,1) -> 0 | P23: =ROUNDUP(IF($D23="画面",画面係数,IF($D23="帳票",帳票係数,IF($D23="バッチ",バッチ係数,0))) * IF($I23="特高",特高係数,IF($I23="高",高係数,IF($I23="中",中係数,IF($I23="低",低係数,IF($I23="特低",特低係数,0))))) * IF(P$7="SA",要件定義係数,IF(P$7="UI",基本設計係数,IF(P$7="SS",詳細設計係数,IF(P$7="PS/PG/PT",製作係数,IF(P$7="IT",結合テスト係数,IF(P$7="ST",総合テスト係数,IF(P$7="OT",受入支援係数,IF(P$7="RL",移行切替係数,IF(P$7="その他",その他係数,0))))))))) * P$8,1) -> 0 | Q23: =ROUNDUP(IF($D23="画面",画面係数,IF($D23="帳票",帳票係数,IF($D23="バッチ",バッチ係数,0))) * IF($I23="特高",特高係数,IF($I23="高",高係数,IF($I23="中",中係数,IF($I23="低",低係数,IF($I23="特低",特低係数,0))))) * IF(Q$7="SA",要件定義係数,IF(Q$7="UI",基本設計係数,IF(Q$7="SS",詳細設計係数,IF(Q$7="PS/PG/PT",製作係数,IF(Q$7="IT",結合テスト係数,IF(Q$7="ST",総合テスト係数,IF(Q$7="OT",受入支援係数,IF(Q$7="RL",移行切替係数,IF(Q$7="その他",その他係数,0))))))))) * Q$8,1) -> 0 | R23: =ROUNDUP(IF($D23="画面",画面係数,IF($D23="帳票",帳票係数,IF($D23="バッチ",バッチ係数,0))) * IF($I23="特高",特高係数,IF($I23="高",高係数,IF($I23="中",中係数,IF($I23="低",低係数,IF($I23="特低",特低係数,0))))) * IF(R$7="SA",要件定義係数,IF(R$7="UI",基本設計係数,IF(R$7="SS",詳細設計係数,IF(R$7="PS/PG/PT",製作係数,IF(R$7="IT",結合テスト係数,IF(R$7="ST",総合テスト係数,IF(R$7="OT",受入支援係数,IF(R$7="RL",移行切替係数,IF(R$7="その他",その他係数,0))))))))) * R$8,1) -> 0 | T23: =ROUNDUP(SUM(J23:S23)*T$8,1) -> 0 | U23: =SUM(J23:T23) -> 0 | V23: =U23/20 -> 0 | W23: =((J23*J$9) + (K23*K$9) + (L23*L$9) + (M23*M$9) + (N23*N$9) + (O23*O$9) + (P23*P$9) + (Q23*Q$9) + (R23*R$9) + (S23*S$9) + (T23*T$9))/20 -> 0
