Workbook
Name その他係数: [1]積算基準!$L$35
Name その他係数: 積算基準!$L$35
Name バッチ係数: [1]積算基準!$F$29
Name バッチ係数: 積算基準!$F$29
Name 移行切替係数: [1]積算基準!$K$35
Name 移行切替係数: 積算基準!$K$35
Name 画面係数: [1]積算基準!$D$29
Name 画面係数: 積算基準!$D$29
Name 基本設計係数: [1]積算基準!$E$35
Name 基本設計係数: 積算基準!$E$35
Name 結合テスト係数: [1]積算基準!$H$35
Name 結合テスト係数: 積算基準!$H$35
Name 高係数: [1]積算基準!$E$41
Name 高係数: 積算基準!$E$41
Name 参照上限高: [1]積算基準!$E$17
Name 参照上限高: 積算基準!$E$17
Name 参照上限中: [1]積算基準!$F$17
Name 参照上限中: 積算基準!$F$17
Name 参照上限低: [1]積算基準!$G$17
Name 参照上限低: 積算基準!$G$17
Name 参照上限特高: 積算基準!$D$17
Name 参照上限特低: [1]積算基準!$H$17
Name 参照上限特低: 積算基準!$H$17
Name 受入支援係数: [1]積算基準!$J$35
Name 受入支援係数: 積算基準!$J$35
Name 詳細設計係数: [1]積算基準!$F$35
Name 詳細設計係数: 積算基準!$F$35
Name 製作係数: [1]積算基準!$G$35
Name 製作係数: 積算基準!$G$35
Name 総合テスト係数: [1]積算基準!$I$35
Name 総合テスト係数: 積算基準!$I$35
Name 中係数: [1]積算基準!$F$41
Name 中係数: 積算基準!$F$41
Name 帳票係数: [1]積算基準!$E$29
Name 帳票係数: 積算基準!$E$29
Name 低係数: [1]積算基準!$G$41
Name 低係数: 積算基準!$G$41
Name 登録上限高: [1]積算基準!$E$16
Name 登録上限高: 積算基準!$E$16
Name 登録上限中: [1]積算基準!$F$16
Name 登録上限中: 積算基準!$F$16
Name 登録上限低: [1]積算基準!$G$16
Name 登録上限低: 積算基準!$G$16
Name 登録上限特高: 積算基準!$D$16
Name 登録上限特低: [1]積算基準!$H$16
Name 登録上限特低: 積算基準!$H$16
Name 特高係数: [1]積算基準!$D$41
Name 特高係数: 積算基準!$D$41
Name 特低係数: [1]積算基準!$H$41
Name 特低係数: 積算基準!$H$41
Name 要件定義係数: [1]積算基準!$D$35
Name 要件定義係数: 積算基準!$D$35

Sheet サマリ
B1: 新IRIS操業品質Azure移行
B3: ■最適工期 | E3: ■御見積金額(全工程の場合) | L3: ■御見積金額(全工程の場合) ：工数丸め
B5: 全体工期 | C5: =(工数算出!U4^(1/3))*2.69 -> 9.3527375 | E5: 見積金額合計 | F5: =SUM(I9:I19) -> 44226000 | L5: 見積金額合計 | M5: =SUM(P9:P19) -> 44800000
B8: 工程 | C8: 工期 | E8: 工程 | F8: 工数 | H8: 単価 | I8: 金額 | L8: 工程 | M8: 工数 | O8: 単価 | P8: 金額 | U8: 契約ごとのPJ工数
B9: 要件定義（SA） | C9: =C5*積算基準!P35 -> 1.0391931 | E9: 要件定義（SA） | F9: 1 | G9: =工数算出!$J4 -> 4.72 | H9: 1000000 | I9: =G9*H9 -> 4720000 | L9: 要件定義（SA） | M9: 1 | N9: =ROUNDDOWN(G9,1) -> 4.7 | O9: 1000000 | P9: =N9*O9 -> 4700000 | R9: =N9/SUM($N$9:$N$16) -> 0.12912088 | S9: =$N$19*R9 -> 0.77472527
B10: 基本設計（UI） | C10: =C5*積算基準!Q35 -> 1.4340864 | E10: 基本設計（UI） | F10: 1 | G10: =工数算出!$K4 -> 5.05 | H10: 1000000 | I10: =G10*H10 -> 5050000 | L10: 基本設計（UI） | M10: 1 | N10: =ROUNDDOWN(G10,1) -> 5 | O10: 1000000 | P10: =N10*O10 -> 5000000 | R10: =N10/SUM($N$9:$N$16) -> 0.13736264 | S10: =$N$19*R10 -> 0.82417582 | T10: =S9+S10 -> 1.5989011 | U10: 1.5 | V10: =U10*O19 -> 2100000
B11: 詳細設計（SS） | C11: =C5*積算基準!R35 -> 1.2123919 | E11: 詳細設計（SS） | F11: 1 | G11: =工数算出!$L4 -> 3.43 | H11: 1000000 | I11: =G11*H11 -> 3430000 | L11: 詳細設計（SS） | M11: 1 | N11: =ROUNDDOWN(G11,1) -> 3.4 | O11: 1000000 | P11: =N11*O11 -> 3400000 | R11: =N11/SUM($N$9:$N$16) -> 0.093406593 | S11: =$N$19*R11 -> 0.56043956
B12: 開発（PS/PG/PT） | C12: =C5*積算基準!S35 -> 1.7250605 | E12: 開発（PS/PG/PT） | F12: 1 | G12: =工数算出!$M4 -> 6.15 | H12: 1000000 | I12: =G12*H12 -> 6150000 | L12: 開発（PS/PG/PT） | M12: 1 | N12: =ROUNDDOWN(G12,0) -> 6 | O12: 1000000 | P12: =N12*O12 -> 6000000 | R12: =N12/SUM($N$9:$N$16) -> 0.16483516 | S12: =$N$19*R12 -> 0.98901099
B13: 結合テスト（IT） | C13: =C5*積算基準!T35 -> 1.3370951 | E13: 結合テスト（IT） | F13: 1 | G13: =工数算出!$N4 -> 5.84 | H13: 1000000 | I13: =G13*H13 -> 5840000 | L13: 結合テスト（IT） | M13: 1 | N13: =ROUNDUP(G13,0) -> 6 | O13: 1000000 | P13: =N13*O13 -> 6000000 | R13: =N13/SUM($N$9:$N$16) -> 0.16483516 | S13: =$N$19*R13 -> 0.98901099 | T13: =S11+S12+S13 -> 2.5384615 | U13: 2.5 | V13: =U13*O19 -> 3500000
B14: システムテスト（ST） | C14: =C5*積算基準!U35 -> 1.2193198 | E14: システムテスト（ST） | F14: 1 | G14: =工数算出!$O4 -> 5.8 | H14: 1000000 | I14: =G14*H14 -> 5800000 | L14: システムテスト（ST） | M14: 1 | N14: =ROUNDDOWN(G14,1) -> 5.8 | O14: 1000000 | P14: =N14*O14 -> 5800000 | R14: =N14/SUM($N$9:$N$16) -> 0.15934066 | S14: =$N$19*R14 -> 0.95604396
B15: 運用テスト（OT） | C15: =C5*積算基準!V35 -> 0.34639768 | E15: 運用テスト（OT） | F15: 1 | G15: =工数算出!$P4 -> 1.45 | H15: 1000000 | I15: =G15*H15 -> 1450000 | L15: 運用テスト（OT） | M15: 1 | N15: =ROUNDUP(G15,1) -> 1.5 | O15: 1000000 | P15: =N15*O15 -> 1500000 | R15: =N15/SUM($N$9:$N$16) -> 0.041208791 | S15: =$N$19*R15 -> 0.24725275
B16: 本番移行・初期流動（RL） | C16: =サマリ!C5*積算基準!W35 -> 1.0391931 | E16: 本番移行・初期流動（RL） | F16: 1 | G16: =工数算出!$Q4 -> 4.1 | H16: 1000000 | I16: =G16*H16 -> 4100000 | L16: 本番移行・初期流動（RL） | M16: 1 | N16: =ROUNDDOWN(G16,0) -> 4 | O16: 1000000 | P16: =N16*O16 -> 4000000 | R16: =N16/SUM($N$9:$N$16) -> 0.10989011 | S16: =$N$19*R16 -> 0.65934066 | T16: =S14+S15+S16 -> 1.8626374 | U16: 2 | V16: =U16*O19 -> 2800000
B17: その他 | C17: - | E17: その他 | F17: 1 | G17: =工数算出!R4 -> 0 | H17: 1000000 | I17: =G17*H17 -> 0 | L17: その他 | M17: 1 | N17: =工数算出!AD4 -> 0 | O17: 1000000 | P17: =N17*O17 -> 0 | R17: =SUM(R9:R16) -> 1 | S17: =SUM(S9:S16) -> 6
B18: 調整 | C18: - | E18: 調整 | F18: - | H18: 1000000 | I18: =G18*H18 -> 0 | L18: 調整 | M18: - | O18: 1000000 | P18: =N18*O18 -> 0
B19: プロジェクト管理（PM） | C19: - | E19: プロジェクト管理（PM） | F19: 0.15 | G19: =工数算出!T4 -> 5.49 | H19: 1400000 | I19: =G19*H19 -> 7686000 | L19: プロジェクト管理（PM） | M19: 0.15 | N19: =ROUNDUP(SUM($G9:$G18)*0.15,0) -> 6 | O19: 1400000 | P19: =N19*O19 -> 8400000
B23: 参考：STEP数からの見積工数
B25: 工数＝ステップ数÷開発生産性
B26: STEP数 | C26: 557000
B27: 開発生産性（STEP数/月） | C27: 1000
B28: 工数 | C28: =C26/C27 -> 557

Sheet 積算基準
A1: 積算基準
B3: １．難易度を「特高」～「特低」までの５段階に分類する。
C5: 難易度
C6: 特高
C7: 高
C8: 中
C9: 低
C10: 特低
B12: ２．難易度の判断基準は、項目数により、区別する。
C14: 難易度判定：基準項目数
C15: 難易度 | D15: 特高 | E15: 高 | F15: 中 | G15: 低 | H15: 特低
C16: 登録 | D16: 50 | E16: 40 | F16: 30 | G16: 20 | H16: 0
C17: 参照 | D17: 60 | E17: 48 | F17: 36 | G17: 24 | H17: 12
B19: ３．IPA発行「ソフトウェア開発データ白書」に基づく、各工程の工数比率を使用する。
C21: 工数比率（IPA ソフトウェア開発データ白書 2018-2019より） | O21: 工期比率（IPA ソフトウェア開発データ白書 2018-2019より）
C22: 工程 | D22: 基本設計 | E22: 詳細設計 | F22: 製作 | G22: 結合テスト | H22: 総合テスト | I22: 計 | O22: 工程 | P22: 基本設計 | Q22: 詳細設計 | R22: 製作 | S22: 結合テスト | T22: 総合テスト | U22: 計
C23: 工数比率 | D23: 0.169 | E23: 0.175 | F23: 0.326 | G23: 0.2 | H23: 0.13 | I23: =SUM(D23:H23) -> 1 | O23: 工期比率 | P23: 0.207 | Q23: 0.175 | R23: 0.249 | S23: 0.193 | T23: 0.176 | U23: =SUM(P23:T23) -> 1
B25: ４．難易度「中」の基本設計～システムテストまでの標準工数を以下とする。
C27: 標準工数（JUASソフトウェアメトリックス調査より）
C28: 種別 | D28: 画面 | E28: 帳票 | F28: バッチ
C29: 登録 | D29: =0.97*20 -> 19.4 | E29: =0.97*0.7*20 -> 13.58 | F29: =0.26*20 -> 5.2 | H29: =SUM(D29:E29) -> 32.98
B31: ５．他の工程の工数を下記の基準により算出する。
C33: 工程 | D33: 要件定義 | E33: 基本設計 | F33: 詳細設計 | G33: 製作 | H33: 結合テスト | I33: 総合テスト | J33: 運用テスト | K33: 移行切替 | L33: その他 | M33: 計 | O33: 工程 | P33: 要件定義 | Q33: 基本設計 | R33: 詳細設計 | S33: 製作 | T33: 結合テスト | U33: 総合テスト | V33: 運用テスト | W33: 移行切替 | X33: その他 | Y33: 計
C34: 5工程基準 | D34: =SUM(E34:I34)*0.15 -> 0.15 | E34: =D23 -> 0.169 | F34: =E23 -> 0.175 | G34: =F23 -> 0.326 | H34: =G23 -> 0.2 | I34: =H23 -> 0.13 | J34: =SUM(E34:I34)*0.05 -> 0.05 | K34: 0.15 | L34: 0 | M34: =SUM(D34:L34) -> 1.35 | O34: 5工程基準 | P34: =SUM(Q34:U34)*0.15 -> 0.15 | Q34: =P23 -> 0.207 | R34: =Q23 -> 0.175 | S34: =R23 -> 0.249 | T34: =S23 -> 0.193 | U34: =T23 -> 0.176 | V34: =SUM(Q34:U34)*0.05 -> 0.05 | W34: 0.15 | X34: 0 | Y34: =SUM(P34:X34) -> 1.35
C35: 全体比率 | D35: =D34/$M34 -> 0.11111111 | E35: =E34/$M34 -> 0.12518519 | F35: =F34/$M34 -> 0.12962963 | G35: =G34/$M34 -> 0.24148148 | H35: =H34/$M34 -> 0.14814815 | I35: =I34/$M34 -> 0.096296296 | J35: =J34/$M34 -> 0.037037037 | K35: =K34/$M34 -> 0.11111111 | L35: =L34/$M34 -> 0 | M35: =SUM(D35:L35) -> 1 | O35: 全体比率 | P35: =P34/$Y34 -> 0.11111111 | Q35: =Q34/$Y34 -> 0.15333333 | R35: =R34/$Y34 -> 0.12962963 | S35: =S34/$Y34 -> 0.18444444 | T35: =T34/$Y34 -> 0.14296296 | U35: =U34/$Y34 -> 0.13037037 | V35: =V34/$Y34 -> 0.037037037 | W35: =W34/$Y34 -> 0.11111111 | X35: =X34/$Y34 -> 0 | Y35: =SUM(P35:X35) -> 1
B37: ６．他の難易度の工数は、下記の係数に基づき、積算する。
C39: 難易度別の工数係数
C40: 難易度 | D40: 特高 | E40: 高 | F40: 中 | G40: 低 | H40: 特低
C41: 工数比率 | D41: 3 | E41: 1.4 | F41: 1 | G41: 0.6 | H41: 0.2

Sheet 機能一覧
A1: =サマリ!B1 -> 新IRIS操業品質Azure移行
A2: No | B2: 分類 | C2: 名称 | D2: プログラム | E2: 形式 As-Is | F2: 形式 To-Be | G2: 種別 | H2: 対応方針 | I2: 備考
A3: =ROW()-2 -> 1 | B3: PG | C3: メインメニュー | G3: 画面 | H3: 新規
A4: =ROW()-2 -> 2 | B4: PG | C4: AD認証 | G4: 画面 | H4: 新規
A5: =ROW()-2 -> 3 | B5: PG | C5: サブメニュー | G5: 画面 | H5: 新規
A6: =ROW()-2 -> 4 | B6: PG | C6: 各拠点メニュー（北海道） | G6: 画面 | H6: 新規
A7: =ROW()-2 -> 5 | B7: PG | C7: 各拠点メニュー（千葉） | G7: 画面 | H7: 新規
A8: =ROW()-2 -> 6 | B8: PG | C8: 各拠点メニュー（愛知） | G8: 画面 | H8: 新規
A9: =ROW()-2 -> 7 | B9: PG | C9: 各拠点メニュー（徳山） | G9: 画面 | H9: 新規
A10: =ROW()-2 -> 8 | B10: PG | C10: 装置稼動実績データ作成 | D10: D:\skhoksei\App\Sougyou\bin\BINAS_SOUTI.exe | E10: バッチ | G10: 画面 | H10: 再構築
A11: =ROW()-1 -> 10 | B11: PG | C11: 装置稼動実績データ作成 | D11: D:\skchisei\App\Sougyou\bin\BINAS_SOUTI.exe | E11: バッチ
A12: =ROW()-1 -> 11 | B12: PG | C12: 装置稼動実績データ作成 | D12: D:\skaicsei\App\Sougyou\bin\BINAS_SOUTI.exe | E12: バッチ
A13: =ROW()-1 -> 12 | B13: PG | C13: 装置稼動実績データ作成 | D13: D:\sktoksei\App\Sougyou\bin\BINAS_SOUTI.exe | E13: バッチ
A14: =ROW()-1 -> 13 | B14: PG | C14: 二次加工DB | D14: D:\skaicsei\App\Common\DBCOLECT\COL_SERVER.exe | E14: バッチ | G14: 画面 | H14: 廃止 | I14: ※YJPのPGのため、対応不可
A15: =ROW()-1 -> 14 | B15: PG | C15: 製油所データ作成 | D15: D:\skaicsei\App\Sougyou\bin\BINAS_SEIYU.exe | E15: バッチ | G15: 画面 | H15: 再構築
A16: =ROW()-1 -> 15 | B16: PG | C16: DB削除 | D16: D:\skaicsei\App\Sougyou\bin\DELETE_DB.exe | E16: バッチ | G16: 画面 | H16: 再構築
A17: =ROW()-1 -> 16 | B17: PG | C17: 潤滑油タンク在庫編集 | D17: D:\skaicsei\App\Sougyou\bin\EDT_JNKTZAIK.exe | E17: バッチ | G17: 画面 | H17: 再構築
A18: =ROW()-1 -> 17 | B18: PG | C18: 自家燃使用量作成 | D18: D:\skaicsei\App\Sougyou\bin\JIKANEN.exe | E18: バッチ | G18: 画面 | H18: 廃止 | I18: ※廃止。Xenapp側で吸収
A19: =ROW()-1 -> 18 | B19: PG | C19: 自家燃使用量履歴DB格納処理 | D19: D:\skaicsei\App\Sougyou\bin\JIKANEN_HIST.exe | E19: バッチ | G19: 画面 | H19: 廃止 | I19: ※廃止。Xenapp側で吸収
A20: =ROW()-1 -> 19 | B20: PG | C20: PGキック用 | D20: D:\Common\Kick\Kick.exe | E20: バッチ | G20: 共通 | H20: 廃止
A21: =ROW()-1 -> 20 | B21: PG | C21: 潤滑油ファイルからテーブル書込み | D21: D:\skaicsei\App\Sougyou\bin\JUNKATUY_RCV.exe | E21: バッチ | G21: 画面 | H21: 再構築
A22: =ROW()-1 -> 21 | B22: PG | C22: 「潤滑油タンク在庫データ」の作成 | D22: D:\skaicsei\App\Sougyou\bin\JYUNKATU_TRANS.exe | E22: バッチ | G22: 画面 | H22: 再構築
A23: =ROW()-1 -> 22 | B23: PG | C23: 基材加工DB | D23: D:\skaicsei\App\Sougyou\bin\kakouDB.exe | E23: バッチ | G23: 画面 | H23: 再構築
A24: =ROW()-1 -> 23 | B24: PG | C24: 自家燃タンク在庫作成 | D24: D:\skaicsei\App\Sougyou\bin\TANKZAIKO.exe | E24: バッチ | G24: 画面 | H24: 再構築
A25: =ROW()-1 -> 24 | B25: PG | C25: タンク受払実績月報 | D25: D:\skaicsei\App\Sougyou\bin\UKEHARAI.exe | E25: バッチ | G25: 画面 | H25: 再構築
A26: =ROW()-1 -> 25 | B26: PG | C26: 装置運転状況加工DB | D26: D:\skaicsei\App\Sougyou\bin\UNTEN_JYOKYO.exe | E26: バッチ | G26: 画面 | H26: 再構築
A27: =ROW()-1 -> 26 | B27: PG | C27: 用役省エネ単価比較加工ＤＢ | D27: D:\skaicsei\App\Sougyou\bin\YSYOUENE_YOKO.exe | E27: バッチ | G27: 画面 | H27: 再構築
A28: =ROW()-1 -> 27 | B28: PG | C28: タンク増減日報通油量算出 | D28: D:\skaicsei\App\Sougyou\bin\zogen.exe | E28: バッチ | G28: 画面 | H28: 再構築
A29: =ROW()-1 -> 28 | B29: PG | C29: オフサイト実績受信 | D29: G:\EAI\skhoksei\INI\IRIS_OFFSITE.ini | E29: バッチ | G29: ファイル | H29: 継続利用可能
A30: =ROW()-1 -> 29 | B30: PG | C30: オフサイト実績受信 | D30: G:\EAI\skchisei\INI\IRIS_OFFSITE.ini | E30: バッチ | G30: ファイル | H30: 継続利用可能
A31: =ROW()-1 -> 30 | B31: PG | C31: オフサイト実績受信 | D31: G:\EAI\skaicsei\INI\IRIS_OFFSITE.ini | E31: バッチ | G31: ファイル | H31: 継続利用可能
... A50: =ROW()-1 -> 49 | B50: PG | C50: 海上・パイプライン出荷予定実績（子JOB）DB設定 | D50: G:\EAI\skhoksei\DEF\P504.csv | E50: バッチ | G50: ファイル | H50: 継続利用可能
A51: =ROW()-1 -> 50 | B51: PG | C51: オフサイト実績DB取り込み | D51: G:\EAI\skchisei\EXE\File2Db.exe | E51: バッチ
A52: =ROW()-1 -> 51 | B52: PG | C52: オフサイト実績DB取り込み | D52: G:\EAI\skaicsei\EXE\File2Db.exe | E52: バッチ
A53: =ROW()-1 -> 52 | B53: PG | C53: オフサイト実績DB取り込み | D53: G:\EAI\sktoksei\EXE\File2Db.exe | E53: バッチ
A54: =ROW()-1 -> 53 | B54: PG | C54: 海上・パイプライン出荷予定実績（子JOB）DB設定 | D54: G:\EAI\skchisei\DEF\P504.csv | E54: バッチ | G54: ファイル | H54: 継続利用可能
A55: =ROW()-1 -> 54 | B55: PG | C55: 新IRIS連携 変換処理 | D55: G:\EAI\skchisei\EXE\IRIS_convert.exe | E55: バッチ
A56: =ROW()-1 -> 55 | B56: PG | C56: 新IRIS連携 変換処理 | D56: G:\EAI\skaicsei\EXE\IRIS_convert.exe | E56: バッチ
A57: =ROW()-1 -> 56 | B57: PG | C57: 新IRIS連携 変換処理 | D57: G:\EAI\sktoksei\EXE\IRIS_convert.exe | E57: バッチ
A58: =ROW()-1 -> 57 | B58: PG | C58: 海上・パイプライン出荷予定実績（子JOB）DB設定 | D58: G:\EAI\skaicsei\DEF\P504.csv | E58: バッチ | G58: ファイル | H58: 継続利用可能
...

Sheet 工数算出
A1: =サマリ!B1 -> 新IRIS操業品質Azure移行 | J1: SA | K1: UI | L1: SS | M1: PS/PG/PT | N1: IT | O1: ST | P1: OT | Q1: RL | R1: その他 | S1: 調整 | T1: PM | U1: 合計
G2: 工数（人日） | J2: =SUM(J10:J519) -> 94.3 | K2: =SUM(K10:K519) -> 100.9 | L2: =SUM(L10:L519) -> 68.5 | M2: =SUM(M10:M519) -> 122.9 | N2: =SUM(N10:N519) -> 116.6 | O2: =SUM(O10:O519) -> 115.9 | P2: =SUM(P10:P519) -> 29 | Q2: =SUM(Q10:Q519) -> 81.9 | ... T2: =SUM(T10:T519) -> 132.6 | U2: =SUM(J2:T2) -> 862.6
G3: 工数（人月） | J3: =J2/20 -> 4.715 | K3: =K2/20 -> 5.045 | L3: =L2/20 -> 3.425 | M3: =M2/20 -> 6.145 | N3: =N2/20 -> 5.83 | O3: =O2/20 -> 5.795 | P3: =P2/20 -> 1.45 | Q3: =Q2/20 -> 4.095 | ... T3: =T2/20 -> 6.63 | U3: =SUM(J3:T3) -> 43.13
A4: 見積金額 | D4: =U5 -> 44226000 | G4: 調整後工数（人月） | J4: =ROUNDUP(J3,2) -> 4.72 | K4: =ROUNDUP(K3,2) -> 5.05 | L4: =ROUNDUP(L3,2) -> 3.43 | M4: =ROUNDUP(M3,2) -> 6.15 | N4: =ROUNDUP(N3,2) -> 5.84 | O4: =ROUNDUP(O3,2) -> 5.8 | P4: =ROUNDUP(P3,2) -> 1.45 | Q4: =ROUNDUP(Q3,2) -> 4.1 | ... S4: =ROUNDUP(S3,2) -> 0 | T4: =ROUNDUP(SUM(J4:S4)*T8,2) -> 5.49 | U4: =SUM(J4:T4) -> 42.03
G5: 金額 | J5: =J4*J9 -> 4720000 | K5: =K4*K9 -> 5050000 | L5: =L4*L9 -> 3430000 | M5: =M4*M9 -> 6150000 | N5: =N4*N9 -> 5840000 | O5: =O4*O9 -> 5800000 | P5: =P4*P9 -> 1450000 | Q5: =Q4*Q9 -> 4100000 | ... T5: =T4*T9 -> 7686000 | U5: =SUM(J5:T5) -> 44226000
A7: No, | B7: 分類 | D7: 項目 | E7: 種別 | F7: 登録 | G7: 項目数 | H7: STEP数 | I7: 難易度 | J7: SA | K7: UI | L7: SS | M7: PS/PG/PT | N7: IT | O7: ST | P7: OT | Q7: RL | R7: その他 | S7: 調整 | T7: PM | U7: 合計（人日） | V7: 合計（人月） | W7: 金額 | X7: 備考
J8: =サマリ!F9 -> 1 | K8: =サマリ!F10 -> 1 | L8: =サマリ!F11 -> 1 | M8: =サマリ!F12 -> 1 | N8: =サマリ!F13 -> 1 | O8: =サマリ!F14 -> 1 | P8: =サマリ!F15 -> 1 | Q8: =サマリ!F16 -> 1 | R8: =サマリ!F17 -> 1 | S8: =サマリ!F18 -> - | T8: =サマリ!F19 -> 0.15
J9: =サマリ!H9 -> 1000000 | K9: =サマリ!H10 -> 1000000 | L9: =サマリ!H11 -> 1000000 | M9: =サマリ!H12 -> 1000000 | N9: =サマリ!H13 -> 1000000 | O9: =サマリ!H14 -> 1000000 | P9: =サマリ!H15 -> 1000000 | Q9: =サマリ!H16 -> 1000000 | R9: =サマリ!H17 -> 1000000 | S9: =サマリ!H18 -> 1000000 | T9: =サマリ!H19 -> 1400000
A10: =ROW()-9 -> 1 | B10: PG | C10: メインメニュー | E10: 画面 | I10: 低 | J10: =ROUNDUP(IF($E10="画面",画面係数,IF($E10="帳票",帳票係数,IF($E10="バッチ",バッチ係数,0))) * IF($I10="特高",特高係数,IF($I10="高",高係数,IF($I10="中",中係数,IF($I10="低",低係数,IF($I10="特低",特低係数,0))))) * IF(J$7="SA",要件定義係数,IF(J$7="UI",基本設計係数,IF(J$7="SS",詳細設計係数,IF(J$7="PS/PG/PT",製作係数,IF(J$7="IT",結合テスト係数,IF(J$7="ST",総合テスト係数,IF(J$7="OT",受入支援係数,IF(J$7="RL",移行切替係数,IF(J$7="その他",その他係数,0))))))))) * J$8,1) -> 1.3 | K10: =ROUNDUP(IF($E10="画面",画面係数,IF($E10="帳票",帳票係数,IF($E10="バッチ",バッチ係数,0))) * IF($I10="特高",特高係数,IF($I10="高",高係数,IF($I10="中",中係数,IF($I10="低",低係数,IF($I10="特低",特低係数,0))))) * IF(K$7="SA",要件定義係数,IF(K$7="UI",基本設計係数,IF(K$7="SS",詳細設計係数,IF(K$7="PS/PG/PT",製作係数,IF(K$7="IT",結合テスト係数,IF(K$7="ST",総合テスト係数,IF(K$7="OT",受入支援係数,IF(K$7="RL",移行切替係数,IF(K$7="その他",その他係数,0))))))))) * K$8,1) -> 1.5 | L10: =ROUNDUP(IF($E10="画面",画面係数,IF($E10="帳票",帳票係数,IF($E10="バッチ",バッチ係数,0))) * IF($I10="特高",特高係数,IF($I10="高",高係数,IF($I10="中",中係数,IF($I10="低",低係数,IF($I10="特低",特低係数,0))))) * IF(L$7="SA",要件定義係数,IF(L$7="UI",基本設計係数,IF(L$7="SS",詳細設計係数,IF(L$7="PS/PG/PT",製作係数,IF(L$7="IT",結合テスト係数,IF(L$7="ST",総合テスト係数,IF(L$7="OT",受入支援係数,IF(L$7="RL",移行切替係数,IF(L$7="その他",その他係数,0))))))))) * L$8,1) -> 1.6 | M10: =ROUNDUP(IF($E10="画面",画面係数,IF($E10="帳票",帳票係数,IF($E10="バッチ",バッチ係数,0))) * IF($I10="特高",特高係数,IF($I10="高",高係数,IF($I10="中",中係数,IF($I10="低",低係数,IF($I10="特低",特低係数,0))))) * IF(M$7="SA",要件定義係数,IF(M$7="UI",基本設計係数,IF(M$7="SS",詳細設計係数,IF(M$7="PS/PG/PT",製作係数,IF(M$7="IT",結合テスト係数,IF(M$7="ST",総合テスト係数,IF(M$7="OT",受入支援係数,IF(M$7="RL",移行切替係数,IF(M$7="その他",その他係数,0))))))))) * M$8,1) -> 2.9 | N10: =ROUNDUP(IF($E10="画面",画面係数,IF($E10="帳票",帳票係数,IF($E10="バッチ",バッチ係数,0))) * IF($I10="特高",特高係数,IF($I10="高",高係数,IF($I10="中",中係数,IF($I10="低",低係数,IF($I10="特低",特低係数,0))))) * IF(N$7="SA",要件定義係数,IF(N$7="UI",基本設計係数,IF(N$7="SS",詳細設計係数,IF(N$7="PS/PG/PT",製作係数,IF(N$7="IT",結合テスト係数,IF(N$7="ST",総合テスト係数,IF(N$7="OT",受入支援係数,IF(N$7="RL",移行切替係数,IF(N$7="その他",その他係数,0))))))))) * N$8,1) -> 1.8 | O10: =ROUNDUP(IF($E10="画面",画面係数,IF($E10="帳票",帳票係数,IF($E10="バッチ",バッチ係数,0))) * IF($I10="特高",特高係数,IF($I10="高",高係数,IF($I10="中",中係数,IF($I10="低",低係数,IF($I10="特低",特低係数,0))))) * IF(O$7="SA",要件定義係数,IF(O$7="UI",基本設計係数,IF(O$7="SS",詳細設計係数,IF(O$7="PS/PG/PT",製作係数,IF(O$7="IT",結合テスト係数,IF(O$7="ST",総合テスト係数,IF(O$7="OT",受入支援係数,IF(O$7="RL",移行切替係数,IF(O$7="その他",その他係数,0))))))))) * O$8,1) -> 1.2 | P10: =ROUNDUP(IF($E10="画面",画面係数,IF($E10="帳票",帳票係数,IF($E10="バッチ",バッチ係数,0))) * IF($I10="特高",特高係数,IF($I10="高",高係数,IF($I10="中",中係数,IF($I10="低",低係数,IF($I10="特低",特低係数,0))))) * IF(P$7="SA",要件定義係数,IF(P$7="UI",基本設計係数,IF(P$7="SS",詳細設計係数,IF(P$7="PS/PG/PT",製作係数,IF(P$7="IT",結合テスト係数,IF(P$7="ST",総合テスト係数,IF(P$7="OT",受入支援係数,IF(P$7="RL",移行切替係数,IF(P$7="その他",その他係数,0))))))))) * P$8,1) -> 0.5 | Q10: =ROUNDUP(IF($E10="画面",画面係数,IF($E10="帳票",帳票係数,IF($E10="バッチ",バッチ係数,0))) * IF($I10="特高",特高係数,IF($I10="高",高係数,IF($I10="中",中係数,IF($I10="低",低係数,IF($I10="特低",特低係数,0))))) * IF(Q$7="SA",要件定義係数,IF(Q$7="UI",基本設計係数,IF(Q$7="SS",詳細設計係数,IF(Q$7="PS/PG/PT",製作係数,IF(Q$7="IT",結合テスト係数,IF(Q$7="ST",総合テスト係数,IF(Q$7="OT",受入支援係数,IF(Q$7="RL",移行切替係数,IF(Q$7="その他",その他係数,0))))))))) * Q$8,1) -> 1.3 | R10: =ROUNDUP(IF($E10="画面",画面係数,IF($E10="帳票",帳票係数,IF($E10="バッチ",バッチ係数,0))) * IF($I10="特高",特高係数,IF($I10="高",高係数,IF($I10="中",中係数,IF($I10="低",低係数,IF($I10="特低",特低係数,0))))) * IF(R$7="SA",要件定義係数,IF(R$7="UI",基本設計係数,IF(R$7="SS",詳細設計係数,IF(R$7="PS/PG/PT",製作係数,IF(R$7="IT",結合テスト係数,IF(R$7="ST",総合テスト係数,IF(R$7="OT",受入支援係数,IF(R$7="RL",移行切替係数,IF(R$7="その他",その他係数,0))))))))) * R$8,1) -> 0 | T10: =ROUNDUP(SUM(J10:S10)*T$8,1) -> 1.9 | U10: =SUM(J10:T10) -> 14 | V10: =U10/20 -> 0.7 | W10: =((J10*J$9) + (K10*K$9) + (L10*L$9) + (M10*M$9) + (N10*N$9) + (O10*O$9) + (P10*P$9) + (Q10*Q$9) + (R10*R$9) + (S10*S$9) + (T10*T$9))/20 -> 738000
A11: =ROW()-9 -> 2 | B11: PG | C11: AD認証 | E11: 画面 | I11: 高 | J11: =ROUNDUP(IF($E11="画面",画面係数,IF($E11="帳票",帳票係数,IF($E11="バッチ",バッチ係数,0))) * IF($I11="特高",特高係数,IF($I11="高",高係数,IF($I11="中",中係数,IF($I11="低",低係数,IF($I11="特低",特低係数,0))))) * IF(J$7="SA",要件定義係数,IF(J$7="UI",基本設計係数,IF(J$7="SS",詳細設計係数,IF(J$7="PS/PG/PT",製作係数,IF(J$7="IT",結合テスト係数,IF(J$7="ST",総合テスト係数,IF(J$7="OT",受入支援係数,IF(J$7="RL",移行切替係数,IF(J$7="その他",その他係数,0))))))))) * J$8,1) -> 3.1 | K11: =ROUNDUP(IF($E11="画面",画面係数,IF($E11="帳票",帳票係数,IF($E11="バッチ",バッチ係数,0))) * IF($I11="特高",特高係数,IF($I11="高",高係数,IF($I11="中",中係数,IF($I11="低",低係数,IF($I11="特低",特低係数,0))))) * IF(K$7="SA",要件定義係数,IF(K$7="UI",基本設計係数,IF(K$7="SS",詳細設計係数,IF(K$7="PS/PG/PT",製作係数,IF(K$7="IT",結合テスト係数,IF(K$7="ST",総合テスト係数,IF(K$7="OT",受入支援係数,IF(K$7="RL",移行切替係数,IF(K$7="その他",その他係数,0))))))))) * K$8,1) -> 3.5 | L11: =ROUNDUP(IF($E11="画面",画面係数,IF($E11="帳票",帳票係数,IF($E11="バッチ",バッチ係数,0))) * IF($I11="特高",特高係数,IF($I11="高",高係数,IF($I11="中",中係数,IF($I11="低",低係数,IF($I11="特低",特低係数,0))))) * IF(L$7="SA",要件定義係数,IF(L$7="UI",基本設計係数,IF(L$7="SS",詳細設計係数,IF(L$7="PS/PG/PT",製作係数,IF(L$7="IT",結合テスト係数,IF(L$7="ST",総合テスト係数,IF(L$7="OT",受入支援係数,IF(L$7="RL",移行切替係数,IF(L$7="その他",その他係数,0))))))))) * L$8,1) -> 3.6 | M11: =ROUNDUP(IF($E11="画面",画面係数,IF($E11="帳票",帳票係数,IF($E11="バッチ",バッチ係数,0))) * IF($I11="特高",特高係数,IF($I11="高",高係数,IF($I11="中",中係数,IF($I11="低",低係数,IF($I11="特低",特低係数,0))))) * IF(M$7="SA",要件定義係数,IF(M$7="UI",基本設計係数,IF(M$7="SS",詳細設計係数,IF(M$7="PS/PG/PT",製作係数,IF(M$7="IT",結合テスト係数,IF(M$7="ST",総合テスト係数,IF(M$7="OT",受入支援係数,IF(M$7="RL",移行切替係数,IF(M$7="その他",その他係数,0))))))))) * M$8,1) -> 6.6 | N11: =ROUNDUP(IF($E11="画面",画面係数,IF($E11="帳票",帳票係数,IF($E11="バッチ",バッチ係数,0))) * IF($I11="特高",特高係数,IF($I11="高",高係数,IF($I11="中",中係数,IF($I11="低",低係数,IF($I11="特低",特低係数,0))))) * IF(N$7="SA",要件定義係数,IF(N$7="UI",基本設計係数,IF(N$7="SS",詳細設計係数,IF(N$7="PS/PG/PT",製作係数,IF(N$7="IT",結合テスト係数,IF(N$7="ST",総合テスト係数,IF(N$7="OT",受入支援係数,IF(N$7="RL",移行切替係数,IF(N$7="その他",その他係数,0))))))))) * N$8,1) -> 4.1 | O11: =ROUNDUP(IF($E11="画面",画面係数,IF($E11="帳票",帳票係数,IF($E11="バッチ",バッチ係数,0))) * IF($I11="特高",特高係数,IF($I11="高",高係数,IF($I11="中",中係数,IF($I11="低",低係数,IF($I11="特低",特低係数,0))))) * IF(O$7="SA",要件定義係数,IF(O$7="UI",基本設計係数,IF(O$7="SS",詳細設計係数,IF(O$7="PS/PG/PT",製作係数,IF(O$7="IT",結合テスト係数,IF(O$7="ST",総合テスト係数,IF(O$7="OT",受入支援係数,IF(O$7="RL",移行切替係数,IF(O$7="その他",その他係数,0))))))))) * O$8,1) -> 2.7 | P11: =ROUNDUP(IF($E11="画面",画面係数,IF($E11="帳票",帳票係数,IF($E11="バッチ",バッチ係数,0))) * IF($I11="特高",特高係数,IF($I11="高",高係数,IF($I11="中",中係数,IF($I11="低",低係数,IF($I11="特低",特低係数,0))))) * IF(P$7="SA",要件定義係数,IF(P$7="UI",基本設計係数,IF(P$7="SS",詳細設計係数,IF(P$7="PS/PG/PT",製作係数,IF(P$7="IT",結合テスト係数,IF(P$7="ST",総合テスト係数,IF(P$7="OT",受入支援係数,IF(P$7="RL",移行切替係数,IF(P$7="その他",その他係数,0))))))))) * P$8,1) -> 1.1 | Q11: =ROUNDUP(IF($E11="画面",画面係数,IF($E11="帳票",帳票係数,IF($E11="バッチ",バッチ係数,0))) * IF($I11="特高",特高係数,IF($I11="高",高係数,IF($I11="中",中係数,IF($I11="低",低係数,IF($I11="特低",特低係数,0))))) * IF(Q$7="SA",要件定義係数,IF(Q$7="UI",基本設計係数,IF(Q$7="SS",詳細設計係数,IF(Q$7="PS/PG/PT",製作係数,IF(Q$7="IT",結合テスト係数,IF(Q$7="ST",総合テスト係数,IF(Q$7="OT",受入支援係数,IF(Q$7="RL",移行切替係数,IF(Q$7="その他",その他係数,0))))))))) * Q$8,1) -> 3.1 | R11: =ROUNDUP(IF($E11="画面",画面係数,IF($E11="帳票",帳票係数,IF($E11="バッチ",バッチ係数,0))) * IF($I11="特高",特高係数,IF($I11="高",高係数,IF($I11="中",中係数,IF($I11="低",低係数,IF($I11="特低",特低係数,0))))) * IF(R$7="SA",要件定義係数,IF(R$7="UI",基本設計係数,IF(R$7="SS",詳細設計係数,IF(R$7="PS/PG/PT",製作係数,IF(R$7="IT",結合テスト係数,IF(R$7="ST",総合テスト係数,IF(R$7="OT",受入支援係数,IF(R$7="RL",移行切替係数,IF(R$7="その他",その他係数,0))))))))) * R$8,1) -> 0 | T11: =ROUNDUP(SUM(J11:S11)*T$8,1) -> 4.2 | U11: =SUM(J11:T11) -> 32 | V11: =U11/20 -> 1.6 | W11: =((J11*J$9) + (K11*K$9) + (L11*L$9) + (M11*M$9) + (N11*N$9) + (O11*O$9) + (P11*P$9) + (Q11*Q$9) + (R11*R$9) + (S11*S$9) + (T11*T$9))/20 -> 1684000
A12: =ROW()-9 -> 3 | B12: PG | C12: サブメニュー | E12: 画面 | I12: 低 | J12: =ROUNDUP(IF($E12="画面",画面係数,IF($E12="帳票",帳票係数,IF($E12="バッチ",バッチ係数,0))) * IF($I12="特高",特高係数,IF($I12="高",高係数,IF($I12="中",中係数,IF($I12="低",低係数,IF($I12="特低",特低係数,0))))) * IF(J$7="SA",要件定義係数,IF(J$7="UI",基本設計係数,IF(J$7="SS",詳細設計係数,IF(J$7="PS/PG/PT",製作係数,IF(J$7="IT",結合テスト係数,IF(J$7="ST",総合テスト係数,IF(J$7="OT",受入支援係数,IF(J$7="RL",移行切替係数,IF(J$7="その他",その他係数,0))))))))) * J$8,1) -> 1.3 | K12: =ROUNDUP(IF($E12="画面",画面係数,IF($E12="帳票",帳票係数,IF($E12="バッチ",バッチ係数,0))) * IF($I12="特高",特高係数,IF($I12="高",高係数,IF($I12="中",中係数,IF($I12="低",低係数,IF($I12="特低",特低係数,0))))) * IF(K$7="SA",要件定義係数,IF(K$7="UI",基本設計係数,IF(K$7="SS",詳細設計係数,IF(K$7="PS/PG/PT",製作係数,IF(K$7="IT",結合テスト係数,IF(K$7="ST",総合テスト係数,IF(K$7="OT",受入支援係数,IF(K$7="RL",移行切替係数,IF(K$7="その他",その他係数,0))))))))) * K$8,1) -> 1.5 | L12: =ROUNDUP(IF($E12="画面",画面係数,IF($E12="帳票",帳票係数,IF($E12="バッチ",バッチ係数,0))) * IF($I12="特高",特高係数,IF($I12="高",高係数,IF($I12="中",中係数,IF($I12="低",低係数,IF($I12="特低",特低係数,0))))) * IF(L$7="SA",要件定義係数,IF(L$7="UI",基本設計係数,IF(L$7="SS",詳細設計係数,IF(L$7="PS/PG/PT",製作係数,IF(L$7="IT",結合テスト係数,IF(L$7="ST",総合テスト係数,IF(L$7="OT",受入支援係数,IF(L$7="RL",移行切替係数,IF(L$7="その他",その他係数,0))))))))) * L$8,1) -> 1.6 | M12: =ROUNDUP(IF($E12="画面",画面係数,IF($E12="帳票",帳票係数,IF($E12="バッチ",バッチ係数,0))) * IF($I12="特高",特高係数,IF($I12="高",高係数,IF($I12="中",中係数,IF($I12="低",低係数,IF($I12="特低",特低係数,0))))) * IF(M$7="SA",要件定義係数,IF(M$7="UI",基本設計係数,IF(M$7="SS",詳細設計係数,IF(M$7="PS/PG/PT",製作係数,IF(M$7="IT",結合テスト係数,IF(M$7="ST",総合テスト係数,IF(M$7="OT",受入支援係数,IF(M$7="RL",移行切替係数,IF(M$7="その他",その他係数,0))))))))) * M$8,1) -> 2.9 | N12: =ROUNDUP(IF($E12="画面",画面係数,IF($E12="帳票",帳票係数,IF($E12="バッチ",バッチ係数,0))) * IF($I12="特高",特高係数,IF($I12="高",高係数,IF($I12="中",中係数,IF($I12="低",低係数,IF($I12="特低",特低係数,0))))) * IF(N$7="SA",要件定義係数,IF(N$7="UI",基本設計係数,IF(N$7="SS",詳細設計係数,IF(N$7="PS/PG/PT",製作係数,IF(N$7="IT",結合テスト係数,IF(N$7="ST",総合テスト係数,IF(N$7="OT",受入支援係数,IF(N$7="RL",移行切替係数,IF(N$7="その他",その他係数,0))))))))) * N$8,1) -> 1.8 | O12: =ROUNDUP(IF($E12="画面",画面係数,IF($E12="帳票",帳票係数,IF($E12="バッチ",バッチ係数,0))) * IF($I12="特高",特高係数,IF($I12="高",高係数,IF($I12="中",中係数,IF($I12="低",低係数,IF($I12="特低",特低係数,0))))) * IF(O$7="SA",要件定義係数,IF(O$7="UI",基本設計係数,IF(O$7="SS",詳細設計係数,IF(O$7="PS/PG/PT",製作係数,IF(O$7="IT",結合テスト係数,IF(O$7="ST",総合テスト係数,IF(O$7="OT",受入支援係数,IF(O$7="RL",移行切替係数,IF(O$7="その他",その他係数,0))))))))) * O$8,1) -> 1.2 | P12: =ROUNDUP(IF($E12="画面",画面係数,IF($E12="帳票",帳票係数,IF($E12="バッチ",バッチ係数,0))) * IF($I12="特高",特高係数,IF($I12="高",高係数,IF($I12="中",中係数,IF($I12="低",低係数,IF($I12="特低",特低係数,0))))) * IF(P$7="SA",要件定義係数,IF(P$7="UI",基本設計係数,IF(P$7="SS",詳細設計係数,IF(P$7="PS/PG/PT",製作係数,IF(P$7="IT",結合テスト係数,IF(P$7="ST",総合テスト係数,IF(P$7="OT",受入支援係数,IF(P$7="RL",移行切替係数,IF(P$7="その他",その他係数,0))))))))) * P$8,1) -> 0.5 | Q12: =ROUNDUP(IF($E12="画面",画面係数,IF($E12="帳票",帳票係数,IF($E12="バッチ",バッチ係数,0))) * IF($I12="特高",特高係数,IF($I12="高",高係数,IF($I12="中",中係数,IF($I12="低",低係数,IF($I12="特低",特低係数,0))))) * IF(Q$7="SA",要件定義係数,IF(Q$7="UI",基本設計係数,IF(Q$7="SS",詳細設計係数,IF(Q$7="PS/PG/PT",製作係数,IF(Q$7="IT",結合テスト係数,IF(Q$7="ST",総合テスト係数,IF(Q$7="OT",受入支援係数,IF(Q$7="RL",移行切替係数,IF(Q$7="その他",その他係数,0))))))))) * Q$8,1) -> 1.3 | R12: =ROUNDUP(IF($E12="画面",画面係数,IF($E12="帳票",帳票係数,IF($E12="バッチ",バッチ係数,0))) * IF($I12="特高",特高係数,IF($I12="高",高係数,IF($I12="中",中係数,IF($I12="低",低係数,IF($I12="特低",特低係数,0))))) * IF(R$7="SA",要件定義係数,IF(R$7="UI",基本設計係数,IF(R$7="SS",詳細設計係数,IF(R$7="PS/PG/PT",製作係数,IF(R$7="IT",結合テスト係数,IF(R$7="ST",総合テスト係数,IF(R$7="OT",受入支援係数,IF(R$7="RL",移行切替係数,IF(R$7="その他",その他係数,0))))))))) * R$8,1) -> 0 | T12: =ROUNDUP(SUM(J12:S12)*T$8,1) -> 1.9 | U12: =SUM(J12:T12) -> 14 | V12: =U12/20 -> 0.7 | W12: =((J12*J$9) + (K12*K$9) + (L12*L$9) + (M12*M$9) + (N12*N$9) + (O12*O$9) + (P12*P$9) + (Q12*Q$9) + (R12*R$9) + (S12*S$9) + (T12*T$9))/20 -> 738000
A13: =ROW()-9 -> 4 | B13: PG | C13: 各拠点メニュー（北海道） | E13: 画面 | I13: 低 | J13: =ROUNDUP(IF($E13="画面",画面係数,IF($E13="帳票",帳票係数,IF($E13="バッチ",バッチ係数,0))) * IF($I13="特高",特高係数,IF($I13="高",高係数,IF($I13="中",中係数,IF($I13="低",低係数,IF($I13="特低",特低係数,0))))) * IF(J$7="SA",要件定義係数,IF(J$7="UI",基本設計係数,IF(J$7="SS",詳細設計係数,IF(J$7="PS/PG/PT",製作係数,IF(J$7="IT",結合テスト係数,IF(J$7="ST",総合テスト係数,IF(J$7="OT",受入支援係数,IF(J$7="RL",移行切替係数,IF(J$7="その他",その他係数,0))))))))) * J$8,1) -> 1.3 | K13: =ROUNDUP(IF($E13="画面",画面係数,IF($E13="帳票",帳票係数,IF($E13="バッチ",バッチ係数,0))) * IF($I13="特高",特高係数,IF($I13="高",高係数,IF($I13="中",中係数,IF($I13="低",低係数,IF($I13="特低",特低係数,0))))) * IF(K$7="SA",要件定義係数,IF(K$7="UI",基本設計係数,IF(K$7="SS",詳細設計係数,IF(K$7="PS/PG/PT",製作係数,IF(K$7="IT",結合テスト係数,IF(K$7="ST",総合テスト係数,IF(K$7="OT",受入支援係数,IF(K$7="RL",移行切替係数,IF(K$7="その他",その他係数,0))))))))) * K$8,1) -> 1.5 | L13: =ROUNDUP(IF($E13="画面",画面係数,IF($E13="帳票",帳票係数,IF($E13="バッチ",バッチ係数,0))) * IF($I13="特高",特高係数,IF($I13="高",高係数,IF($I13="中",中係数,IF($I13="低",低係数,IF($I13="特低",特低係数,0))))) * IF(L$7="SA",要件定義係数,IF(L$7="UI",基本設計係数,IF(L$7="SS",詳細設計係数,IF(L$7="PS/PG/PT",製作係数,IF(L$7="IT",結合テスト係数,IF(L$7="ST",総合テスト係数,IF(L$7="OT",受入支援係数,IF(L$7="RL",移行切替係数,IF(L$7="その他",その他係数,0))))))))) * L$8,1) -> 1.6 | M13: =ROUNDUP(IF($E13="画面",画面係数,IF($E13="帳票",帳票係数,IF($E13="バッチ",バッチ係数,0))) * IF($I13="特高",特高係数,IF($I13="高",高係数,IF($I13="中",中係数,IF($I13="低",低係数,IF($I13="特低",特低係数,0))))) * IF(M$7="SA",要件定義係数,IF(M$7="UI",基本設計係数,IF(M$7="SS",詳細設計係数,IF(M$7="PS/PG/PT",製作係数,IF(M$7="IT",結合テスト係数,IF(M$7="ST",総合テスト係数,IF(M$7="OT",受入支援係数,IF(M$7="RL",移行切替係数,IF(M$7="その他",その他係数,0))))))))) * M$8,1) -> 2.9 | N13: =ROUNDUP(IF($E13="画面",画面係数,IF($E13="帳票",帳票係数,IF($E13="バッチ",バッチ係数,0))) * IF($I13="特高",特高係数,IF($I13="高",高係数,IF($I13="中",中係数,IF($I13="低",低係数,IF($I13="特低",特低係数,0))))) * IF(N$7="SA",要件定義係数,IF(N$7="UI",基本設計係数,IF(N$7="SS",詳細設計係数,IF(N$7="PS/PG/PT",製作係数,IF(N$7="IT",結合テスト係数,IF(N$7="ST",総合テスト係数,IF(N$7="OT",受入支援係数,IF(N$7="RL",移行切替係数,IF(N$7="その他",その他係数,0))))))))) * N$8,1) -> 1.8 | O13: =ROUNDUP(IF($E13="画面",画面係数,IF($E13="帳票",帳票係数,IF($E13="バッチ",バッチ係数,0))) * IF($I13="特高",特高係数,IF($I13="高",高係数,IF($I13="中",中係数,IF($I13="低",低係数,IF($I13="特低",特低係数,0))))) * IF(O$7="SA",要件定義係数,IF(O$7="UI",基本設計係数,IF(O$7="SS",詳細設計係数,IF(O$7="PS/PG/PT",製作係数,IF(O$7="IT",結合テスト係数,IF(O$7="ST",総合テスト係数,IF(O$7="OT",受入支援係数,IF(O$7="RL",移行切替係数,IF(O$7="その他",その他係数,0))))))))) * O$8,1) -> 1.2 | P13: =ROUNDUP(IF($E13="画面",画面係数,IF($E13="帳票",帳票係数,IF($E13="バッチ",バッチ係数,0))) * IF($I13="特高",特高係数,IF($I13="高",高係数,IF($I13="中",中係数,IF($I13="低",低係数,IF($I13="特低",特低係数,0))))) * IF(P$7="SA",要件定義係数,IF(P$7="UI",基本設計係数,IF(P$7="SS",詳細設計係数,IF(P$7="PS/PG/PT",製作係数,IF(P$7="IT",結合テスト係数,IF(P$7="ST",総合テスト係数,IF(P$7="OT",受入支援係数,IF(P$7="RL",移行切替係数,IF(P$7="その他",その他係数,0))))))))) * P$8,1) -> 0.5 | Q13: =ROUNDUP(IF($E13="画面",画面係数,IF($E13="帳票",帳票係数,IF($E13="バッチ",バッチ係数,0))) * IF($I13="特高",特高係数,IF($I13="高",高係数,IF($I13="中",中係数,IF($I13="低",低係数,IF($I13="特低",特低係数,0))))) * IF(Q$7="SA",要件定義係数,IF(Q$7="UI",基本設計係数,IF(Q$7="SS",詳細設計係数,IF(Q$7="PS/PG/PT",製作係数,IF(Q$7="IT",結合テスト係数,IF(Q$7="ST",総合テスト係数,IF(Q$7="OT",受入支援係数,IF(Q$7="RL",移行切替係数,IF(Q$7="その他",その他係数,0))))))))) * Q$8,1) -> 1.3 | R13: =ROUNDUP(IF($E13="画面",画面係数,IF($E13="帳票",帳票係数,IF($E13="バッチ",バッチ係数,0))) * IF($I13="特高",特高係数,IF($I13="高",高係数,IF($I13="中",中係数,IF($I13="低",低係数,IF($I13="特低",特低係数,0))))) * IF(R$7="SA",要件定義係数,IF(R$7="UI",基本設計係数,IF(R$7="SS",詳細設計係数,IF(R$7="PS/PG/PT",製作係数,IF(R$7="IT",結合テスト係数,IF(R$7="ST",総合テスト係数,IF(R$7="OT",受入支援係数,IF(R$7="RL",移行切替係数,IF(R$7="その他",その他係数,0))))))))) * R$8,1) -> 0 | T13: =ROUNDUP(SUM(J13:S13)*T$8,1) -> 1.9 | U13: =SUM(J13:T13) -> 14 | V13: =U13/20 -> 0.7 | W13: =((J13*J$9) + (K13*K$9) + (L13*L$9) + (M13*M$9) + (N13*N$9) + (O13*O$9) + (P13*P$9) + (Q13*Q$9) + (R13*R$9) + (S13*S$9) + (T13*T$9))/20 -> 738000
A14: =ROW()-9 -> 5 | B14: PG | C14: 各拠点メニュー（千葉） | E14: 画面 | I14: 低 | J14: =ROUNDUP(IF($E14="画面",画面係数,IF($E14="帳票",帳票係数,IF($E14="バッチ",バッチ係数,0))) * IF($I14="特高",特高係数,IF($I14="高",高係数,IF($I14="中",中係数,IF($I14="低",低係数,IF($I14="特低",特低係数,0))))) * IF(J$7="SA",要件定義係数,IF(J$7="UI",基本設計係数,IF(J$7="SS",詳細設計係数,IF(J$7="PS/PG/PT",製作係数,IF(J$7="IT",結合テスト係数,IF(J$7="ST",総合テスト係数,IF(J$7="OT",受入支援係数,IF(J$7="RL",移行切替係数,IF(J$7="その他",その他係数,0))))))))) * J$8,1) -> 1.3 | K14: =ROUNDUP(IF($E14="画面",画面係数,IF($E14="帳票",帳票係数,IF($E14="バッチ",バッチ係数,0))) * IF($I14="特高",特高係数,IF($I14="高",高係数,IF($I14="中",中係数,IF($I14="低",低係数,IF($I14="特低",特低係数,0))))) * IF(K$7="SA",要件定義係数,IF(K$7="UI",基本設計係数,IF(K$7="SS",詳細設計係数,IF(K$7="PS/PG/PT",製作係数,IF(K$7="IT",結合テスト係数,IF(K$7="ST",総合テスト係数,IF(K$7="OT",受入支援係数,IF(K$7="RL",移行切替係数,IF(K$7="その他",その他係数,0))))))))) * K$8,1) -> 1.5 | L14: =ROUNDUP(IF($E14="画面",画面係数,IF($E14="帳票",帳票係数,IF($E14="バッチ",バッチ係数,0))) * IF($I14="特高",特高係数,IF($I14="高",高係数,IF($I14="中",中係数,IF($I14="低",低係数,IF($I14="特低",特低係数,0))))) * IF(L$7="SA",要件定義係数,IF(L$7="UI",基本設計係数,IF(L$7="SS",詳細設計係数,IF(L$7="PS/PG/PT",製作係数,IF(L$7="IT",結合テスト係数,IF(L$7="ST",総合テスト係数,IF(L$7="OT",受入支援係数,IF(L$7="RL",移行切替係数,IF(L$7="その他",その他係数,0))))))))) * L$8,1) -> 1.6 | M14: =ROUNDUP(IF($E14="画面",画面係数,IF($E14="帳票",帳票係数,IF($E14="バッチ",バッチ係数,0))) * IF($I14="特高",特高係数,IF($I14="高",高係数,IF($I14="中",中係数,IF($I14="低",低係数,IF($I14="特低",特低係数,0))))) * IF(M$7="SA",要件定義係数,IF(M$7="UI",基本設計係数,IF(M$7="SS",詳細設計係数,IF(M$7="PS/PG/PT",製作係数,IF(M$7="IT",結合テスト係数,IF(M$7="ST",総合テスト係数,IF(M$7="OT",受入支援係数,IF(M$7="RL",移行切替係数,IF(M$7="その他",その他係数,0))))))))) * M$8,1) -> 2.9 | N14: =ROUNDUP(IF($E14="画面",画面係数,IF($E14="帳票",帳票係数,IF($E14="バッチ",バッチ係数,0))) * IF($I14="特高",特高係数,IF($I14="高",高係数,IF($I14="中",中係数,IF($I14="低",低係数,IF($I14="特低",特低係数,0))))) * IF(N$7="SA",要件定義係数,IF(N$7="UI",基本設計係数,IF(N$7="SS",詳細設計係数,IF(N$7="PS/PG/PT",製作係数,IF(N$7="IT",結合テスト係数,IF(N$7="ST",総合テスト係数,IF(N$7="OT",受入支援係数,IF(N$7="RL",移行切替係数,IF(N$7="その他",その他係数,0))))))))) * N$8,1) -> 1.8 | O14: =ROUNDUP(IF($E14="画面",画面係数,IF($E14="帳票",帳票係数,IF($E14="バッチ",バッチ係数,0))) * IF($I14="特高",特高係数,IF($I14="高",高係数,IF($I14="中",中係数,IF($I14="低",低係数,IF($I14="特低",特低係数,0))))) * IF(O$7="SA",要件定義係数,IF(O$7="UI",基本設計係数,IF(O$7="SS",詳細設計係数,IF(O$7="PS/PG/PT",製作係数,IF(O$7="IT",結合テスト係数,IF(O$7="ST",総合テスト係数,IF(O$7="OT",受入支援係数,IF(O$7="RL",移行切替係数,IF(O$7="その他",その他係数,0))))))))) * O$8,1) -> 1.2 | P14: =ROUNDUP(IF($E14="画面",画面係数,IF($E14="帳票",帳票係数,IF($E14="バッチ",バッチ係数,0))) * IF($I14="特高",特高係数,IF($I14="高",高係数,IF($I14="中",中係数,IF($I14="低",低係数,IF($I14="特低",特低係数,0))))) * IF(P$7="SA",要件定義係数,IF(P$7="UI",基本設計係数,IF(P$7="SS",詳細設計係数,IF(P$7="PS/PG/PT",製作係数,IF(P$7="IT",結合テスト係数,IF(P$7="ST",総合テスト係数,IF(P$7="OT",受入支援係数,IF(P$7="RL",移行切替係数,IF(P$7="その他",その他係数,0))))))))) * P$8,1) -> 0.5 | Q14: =ROUNDUP(IF($E14="画面",画面係数,IF($E14="帳票",帳票係数,IF($E14="バッチ",バッチ係数,0))) * IF($I14="特高",特高係数,IF($I14="高",高係数,IF($I14="中",中係数,IF($I14="低",低係数,IF($I14="特低",特低係数,0))))) * IF(Q$7="SA",要件定義係数,IF(Q$7="UI",基本設計係数,IF(Q$7="SS",詳細設計係数,IF(Q$7="PS/PG/PT",製作係数,IF(Q$7="IT",結合テスト係数,IF(Q$7="ST",総合テスト係数,IF(Q$7="OT",受入支援係数,IF(Q$7="RL",移行切替係数,IF(Q$7="その他",その他係数,0))))))))) * Q$8,1) -> 1.3 | R14: =ROUNDUP(IF($E14="画面",画面係数,IF($E14="帳票",帳票係数,IF($E14="バッチ",バッチ係数,0))) * IF($I14="特高",特高係数,IF($I14="高",高係数,IF($I14="中",中係数,IF($I14="低",低係数,IF($I14="特低",特低係数,0))))) * IF(R$7="SA",要件定義係数,IF(R$7="UI",基本設計係数,IF(R$7="SS",詳細設計係数,IF(R$7="PS/PG/PT",製作係数,IF(R$7="IT",結合テスト係数,IF(R$7="ST",総合テスト係数,IF(R$7="OT",受入支援係数,IF(R$7="RL",移行切替係数,IF(R$7="その他",その他係数,0))))))))) * R$8,1) -> 0 | T14: =ROUNDUP(SUM(J14:S14)*T$8,1) -> 1.9 | U14: =SUM(J14:T14) -> 14 | V14: =U14/20 -> 0.7 | W14: =((J14*J$9) + (K14*K$9) + (L14*L$9) + (M14*M$9) + (N14*N$9) + (O14*O$9) + (P14*P$9) + (Q14*Q$9) + (R14*R$9) + (S14*S$9) + (T14*T$9))/20 -> 738000
A15: =ROW()-9 -> 6 | B15: PG | C15: 各拠点メニュー（愛知） | E15: 画面 | I15: 低 | J15: =ROUNDUP(IF($E15="画面",画面係数,IF($E15="帳票",帳票係数,IF($E15="バッチ",バッチ係数,0))) * IF($I15="特高",特高係数,IF($I15="高",高係数,IF($I15="中",中係数,IF($I15="低",低係数,IF($I15="特低",特低係数,0))))) * IF(J$7="SA",要件定義係数,IF(J$7="UI",基本設計係数,IF(J$7="SS",詳細設計係数,IF(J$7="PS/PG/PT",製作係数,IF(J$7="IT",結合テスト係数,IF(J$7="ST",総合テスト係数,IF(J$7="OT",受入支援係数,IF(J$7="RL",移行切替係数,IF(J$7="その他",その他係数,0))))))))) * J$8,1) -> 1.3 | K15: =ROUNDUP(IF($E15="画面",画面係数,IF($E15="帳票",帳票係数,IF($E15="バッチ",バッチ係数,0))) * IF($I15="特高",特高係数,IF($I15="高",高係数,IF($I15="中",中係数,IF($I15="低",低係数,IF($I15="特低",特低係数,0))))) * IF(K$7="SA",要件定義係数,IF(K$7="UI",基本設計係数,IF(K$7="SS",詳細設計係数,IF(K$7="PS/PG/PT",製作係数,IF(K$7="IT",結合テスト係数,IF(K$7="ST",総合テスト係数,IF(K$7="OT",受入支援係数,IF(K$7="RL",移行切替係数,IF(K$7="その他",その他係数,0))))))))) * K$8,1) -> 1.5 | L15: =ROUNDUP(IF($E15="画面",画面係数,IF($E15="帳票",帳票係数,IF($E15="バッチ",バッチ係数,0))) * IF($I15="特高",特高係数,IF($I15="高",高係数,IF($I15="中",中係数,IF($I15="低",低係数,IF($I15="特低",特低係数,0))))) * IF(L$7="SA",要件定義係数,IF(L$7="UI",基本設計係数,IF(L$7="SS",詳細設計係数,IF(L$7="PS/PG/PT",製作係数,IF(L$7="IT",結合テスト係数,IF(L$7="ST",総合テスト係数,IF(L$7="OT",受入支援係数,IF(L$7="RL",移行切替係数,IF(L$7="その他",その他係数,0))))))))) * L$8,1) -> 1.6 | M15: =ROUNDUP(IF($E15="画面",画面係数,IF($E15="帳票",帳票係数,IF($E15="バッチ",バッチ係数,0))) * IF($I15="特高",特高係数,IF($I15="高",高係数,IF($I15="中",中係数,IF($I15="低",低係数,IF($I15="特低",特低係数,0))))) * IF(M$7="SA",要件定義係数,IF(M$7="UI",基本設計係数,IF(M$7="SS",詳細設計係数,IF(M$7="PS/PG/PT",製作係数,IF(M$7="IT",結合テスト係数,IF(M$7="ST",総合テスト係数,IF(M$7="OT",受入支援係数,IF(M$7="RL",移行切替係数,IF(M$7="その他",その他係数,0))))))))) * M$8,1) -> 2.9 | N15: =ROUNDUP(IF($E15="画面",画面係数,IF($E15="帳票",帳票係数,IF($E15="バッチ",バッチ係数,0))) * IF($I15="特高",特高係数,IF($I15="高",高係数,IF($I15="中",中係数,IF($I15="低",低係数,IF($I15="特低",特低係数,0))))) * IF(N$7="SA",要件定義係数,IF(N$7="UI",基本設計係数,IF(N$7="SS",詳細設計係数,IF(N$7="PS/PG/PT",製作係数,IF(N$7="IT",結合テスト係数,IF(N$7="ST",総合テスト係数,IF(N$7="OT",受入支援係数,IF(N$7="RL",移行切替係数,IF(N$7="その他",その他係数,0))))))))) * N$8,1) -> 1.8 | O15: =ROUNDUP(IF($E15="画面",画面係数,IF($E15="帳票",帳票係数,IF($E15="バッチ",バッチ係数,0))) * IF($I15="特高",特高係数,IF($I15="高",高係数,IF($I15="中",中係数,IF($I15="低",低係数,IF($I15="特低",特低係数,0))))) * IF(O$7="SA",要件定義係数,IF(O$7="UI",基本設計係数,IF(O$7="SS",詳細設計係数,IF(O$7="PS/PG/PT",製作係数,IF(O$7="IT",結合テスト係数,IF(O$7="ST",総合テスト係数,IF(O$7="OT",受入支援係数,IF(O$7="RL",移行切替係数,IF(O$7="その他",その他係数,0))))))))) * O$8,1) -> 1.2 | P15: =ROUNDUP(IF($E15="画面",画面係数,IF($E15="帳票",帳票係数,IF($E15="バッチ",バッチ係数,0))) * IF($I15="特高",特高係数,IF($I15="高",高係数,IF($I15="中",中係数,IF($I15="低",低係数,IF($I15="特低",特低係数,0))))) * IF(P$7="SA",要件定義係数,IF(P$7="UI",基本設計係数,IF(P$7="SS",詳細設計係数,IF(P$7="PS/PG/PT",製作係数,IF(P$7="IT",結合テスト係数,IF(P$7="ST",総合テスト係数,IF(P$7="OT",受入支援係数,IF(P$7="RL",移行切替係数,IF(P$7="その他",その他係数,0))))))))) * P$8,1) -> 0.5 | Q15: =ROUNDUP(IF($E15="画面",画面係数,IF($E15="帳票",帳票係数,IF($E15="バッチ",バッチ係数,0))) * IF($I15="特高",特高係数,IF($I15="高",高係数,IF($I15="中",中係数,IF($I15="低",低係数,IF($I15="特低",特低係数,0))))) * IF(Q$7="SA",要件定義係数,IF(Q$7="UI",基本設計係数,IF(Q$7="SS",詳細設計係数,IF(Q$7="PS/PG/PT",製作係数,IF(Q$7="IT",結合テスト係数,IF(Q$7="ST",総合テスト係数,IF(Q$7="OT",受入支援係数,IF(Q$7="RL",移行切替係数,IF(Q$7="その他",その他係数,0))))))))) * Q$8,1) -> 1.3 | R15: =ROUNDUP(IF($E15="画面",画面係数,IF($E15="帳票",帳票係数,IF($E15="バッチ",バッチ係数,0))) * IF($I15="特高",特高係数,IF($I15="高",高係数,IF($I15="中",中係数,IF($I15="低",低係数,IF($I15="特低",特低係数,0))))) * IF(R$7="SA",要件定義係数,IF(R$7="UI",基本設計係数,IF(R$7="SS",詳細設計係数,IF(R$7="PS/PG/PT",製作係数,IF(R$7="IT",結合テスト係数,IF(R$7="ST",総合テスト係数,IF(R$7="OT",受入支援係数,IF(R$7="RL",移行切替係数,IF(R$7="その他",その他係数,0))))))))) * R$8,1) -> 0 | T15: =ROUNDUP(SUM(J15:S15)*T$8,1) -> 1.9 | U15: =SUM(J15:T15) -> 14 | V15: =U15/20 -> 0.7 | W15: =((J15*J$9) + (K15*K$9) + (L15*L$9) + (M15*M$9) + (N15*N$9) + (O15*O$9) + (P15*P$9) + (Q15*Q$9) + (R15*R$9) + (S15*S$9) + (T15*T$9))/20 -> 738000
A16: =ROW()-9 -> 7 | B16: PG | C16: 各拠点メニュー（徳山） | E16: 画面 | I16: 低 | J16: =ROUNDUP(IF($E16="画面",画面係数,IF($E16="帳票",帳票係数,IF($E16="バッチ",バッチ係数,0))) * IF($I16="特高",特高係数,IF($I16="高",高係数,IF($I16="中",中係数,IF($I16="低",低係数,IF($I16="特低",特低係数,0))))) * IF(J$7="SA",要件定義係数,IF(J$7="UI",基本設計係数,IF(J$7="SS",詳細設計係数,IF(J$7="PS/PG/PT",製作係数,IF(J$7="IT",結合テスト係数,IF(J$7="ST",総合テスト係数,IF(J$7="OT",受入支援係数,IF(J$7="RL",移行切替係数,IF(J$7="その他",その他係数,0))))))))) * J$8,1) -> 1.3 | K16: =ROUNDUP(IF($E16="画面",画面係数,IF($E16="帳票",帳票係数,IF($E16="バッチ",バッチ係数,0))) * IF($I16="特高",特高係数,IF($I16="高",高係数,IF($I16="中",中係数,IF($I16="低",低係数,IF($I16="特低",特低係数,0))))) * IF(K$7="SA",要件定義係数,IF(K$7="UI",基本設計係数,IF(K$7="SS",詳細設計係数,IF(K$7="PS/PG/PT",製作係数,IF(K$7="IT",結合テスト係数,IF(K$7="ST",総合テスト係数,IF(K$7="OT",受入支援係数,IF(K$7="RL",移行切替係数,IF(K$7="その他",その他係数,0))))))))) * K$8,1) -> 1.5 | L16: =ROUNDUP(IF($E16="画面",画面係数,IF($E16="帳票",帳票係数,IF($E16="バッチ",バッチ係数,0))) * IF($I16="特高",特高係数,IF($I16="高",高係数,IF($I16="中",中係数,IF($I16="低",低係数,IF($I16="特低",特低係数,0))))) * IF(L$7="SA",要件定義係数,IF(L$7="UI",基本設計係数,IF(L$7="SS",詳細設計係数,IF(L$7="PS/PG/PT",製作係数,IF(L$7="IT",結合テスト係数,IF(L$7="ST",総合テスト係数,IF(L$7="OT",受入支援係数,IF(L$7="RL",移行切替係数,IF(L$7="その他",その他係数,0))))))))) * L$8,1) -> 1.6 | M16: =ROUNDUP(IF($E16="画面",画面係数,IF($E16="帳票",帳票係数,IF($E16="バッチ",バッチ係数,0))) * IF($I16="特高",特高係数,IF($I16="高",高係数,IF($I16="中",中係数,IF($I16="低",低係数,IF($I16="特低",特低係数,0))))) * IF(M$7="SA",要件定義係数,IF(M$7="UI",基本設計係数,IF(M$7="SS",詳細設計係数,IF(M$7="PS/PG/PT",製作係数,IF(M$7="IT",結合テスト係数,IF(M$7="ST",総合テスト係数,IF(M$7="OT",受入支援係数,IF(M$7="RL",移行切替係数,IF(M$7="その他",その他係数,0))))))))) * M$8,1) -> 2.9 | N16: =ROUNDUP(IF($E16="画面",画面係数,IF($E16="帳票",帳票係数,IF($E16="バッチ",バッチ係数,0))) * IF($I16="特高",特高係数,IF($I16="高",高係数,IF($I16="中",中係数,IF($I16="低",低係数,IF($I16="特低",特低係数,0))))) * IF(N$7="SA",要件定義係数,IF(N$7="UI",基本設計係数,IF(N$7="SS",詳細設計係数,IF(N$7="PS/PG/PT",製作係数,IF(N$7="IT",結合テスト係数,IF(N$7="ST",総合テスト係数,IF(N$7="OT",受入支援係数,IF(N$7="RL",移行切替係数,IF(N$7="その他",その他係数,0))))))))) * N$8,1) -> 1.8 | O16: =ROUNDUP(IF($E16="画面",画面係数,IF($E16="帳票",帳票係数,IF($E16="バッチ",バッチ係数,0))) * IF($I16="特高",特高係数,IF($I16="高",高係数,IF($I16="中",中係数,IF($I16="低",低係数,IF($I16="特低",特低係数,0))))) * IF(O$7="SA",要件定義係数,IF(O$7="UI",基本設計係数,IF(O$7="SS",詳細設計係数,IF(O$7="PS/PG/PT",製作係数,IF(O$7="IT",結合テスト係数,IF(O$7="ST",総合テスト係数,IF(O$7="OT",受入支援係数,IF(O$7="RL",移行切替係数,IF(O$7="その他",その他係数,0))))))))) * O$8,1) -> 1.2 | P16: =ROUNDUP(IF($E16="画面",画面係数,IF($E16="帳票",帳票係数,IF($E16="バッチ",バッチ係数,0))) * IF($I16="特高",特高係数,IF($I16="高",高係数,IF($I16="中",中係数,IF($I16="低",低係数,IF($I16="特低",特低係数,0))))) * IF(P$7="SA",要件定義係数,IF(P$7="UI",基本設計係数,IF(P$7="SS",詳細設計係数,IF(P$7="PS/PG/PT",製作係数,IF(P$7="IT",結合テスト係数,IF(P$7="ST",総合テスト係数,IF(P$7="OT",受入支援係数,IF(P$7="RL",移行切替係数,IF(P$7="その他",その他係数,0))))))))) * P$8,1) -> 0.5 | Q16: =ROUNDUP(IF($E16="画面",画面係数,IF($E16="帳票",帳票係数,IF($E16="バッチ",バッチ係数,0))) * IF($I16="特高",特高係数,IF($I16="高",高係数,IF($I16="中",中係数,IF($I16="低",低係数,IF($I16="特低",特低係数,0))))) * IF(Q$7="SA",要件定義係数,IF(Q$7="UI",基本設計係数,IF(Q$7="SS",詳細設計係数,IF(Q$7="PS/PG/PT",製作係数,IF(Q$7="IT",結合テスト係数,IF(Q$7="ST",総合テスト係数,IF(Q$7="OT",受入支援係数,IF(Q$7="RL",移行切替係数,IF(Q$7="その他",その他係数,0))))))))) * Q$8,1) -> 1.3 | R16: =ROUNDUP(IF($E16="画面",画面係数,IF($E16="帳票",帳票係数,IF($E16="バッチ",バッチ係数,0))) * IF($I16="特高",特高係数,IF($I16="高",高係数,IF($I16="中",中係数,IF($I16="低",低係数,IF($I16="特低",特低係数,0))))) * IF(R$7="SA",要件定義係数,IF(R$7="UI",基本設計係数,IF(R$7="SS",詳細設計係数,IF(R$7="PS/PG/PT",製作係数,IF(R$7="IT",結合テスト係数,IF(R$7="ST",総合テスト係数,IF(R$7="OT",受入支援係数,IF(R$7="RL",移行切替係数,IF(R$7="その他",その他係数,0))))))))) * R$8,1) -> 0 | T16: =ROUNDUP(SUM(J16:S16)*T$8,1) -> 1.9 | U16: =SUM(J16:T16) -> 14 | V16: =U16/20 -> 0.7 | W16: =((J16*J$9) + (K16*K$9) + (L16*L$9) + (M16*M$9) + (N16*N$9) + (O16*O$9) + (P16*P$9) + (Q16*Q$9) + (R16*R$9) + (S16*S$9) + (T16*T$9))/20 -> 738000
A17: =ROW()-9 -> 8 | B17: PG | C17: 装置稼動実績データ作成 | D17: D:\skhoksei\App\Sougyou\bin\BINAS_SOUTI.exe | E17: 画面 | I17: 高 | J17: =ROUNDUP(IF($E17="画面",画面係数,IF($E17="帳票",帳票係数,IF($E17="バッチ",バッチ係数,0))) * IF($I17="特高",特高係数,IF($I17="高",高係数,IF($I17="中",中係数,IF($I17="低",低係数,IF($I17="特低",特低係数,0))))) * IF(J$7="SA",要件定義係数,IF(J$7="UI",基本設計係数,IF(J$7="SS",詳細設計係数,IF(J$7="PS/PG/PT",製作係数,IF(J$7="IT",結合テスト係数,IF(J$7="ST",総合テスト係数,IF(J$7="OT",受入支援係数,IF(J$7="RL",移行切替係数,IF(J$7="その他",その他係数,0))))))))) * J$8,1) -> 3.1 | K17: =ROUNDUP(IF($E17="画面",画面係数,IF($E17="帳票",帳票係数,IF($E17="バッチ",バッチ係数,0))) * IF($I17="特高",特高係数,IF($I17="高",高係数,IF($I17="中",中係数,IF($I17="低",低係数,IF($I17="特低",特低係数,0))))) * IF(K$7="SA",要件定義係数,IF(K$7="UI",基本設計係数,IF(K$7="SS",詳細設計係数,IF(K$7="PS/PG/PT",製作係数,IF(K$7="IT",結合テスト係数,IF(K$7="ST",総合テスト係数,IF(K$7="OT",受入支援係数,IF(K$7="RL",移行切替係数,IF(K$7="その他",その他係数,0))))))))) * K$8,1) -> 3.5 | L17: =ROUNDUP(IF($E17="画面",画面係数,IF($E17="帳票",帳票係数,IF($E17="バッチ",バッチ係数,0))) * IF($I17="特高",特高係数,IF($I17="高",高係数,IF($I17="中",中係数,IF($I17="低",低係数,IF($I17="特低",特低係数,0))))) * IF(L$7="SA",要件定義係数,IF(L$7="UI",基本設計係数,IF(L$7="SS",詳細設計係数,IF(L$7="PS/PG/PT",製作係数,IF(L$7="IT",結合テスト係数,IF(L$7="ST",総合テスト係数,IF(L$7="OT",受入支援係数,IF(L$7="RL",移行切替係数,IF(L$7="その他",その他係数,0))))))))) * L$8,1) -> 3.6 | M17: =ROUNDUP(IF($E17="画面",画面係数,IF($E17="帳票",帳票係数,IF($E17="バッチ",バッチ係数,0))) * IF($I17="特高",特高係数,IF($I17="高",高係数,IF($I17="中",中係数,IF($I17="低",低係数,IF($I17="特低",特低係数,0))))) * IF(M$7="SA",要件定義係数,IF(M$7="UI",基本設計係数,IF(M$7="SS",詳細設計係数,IF(M$7="PS/PG/PT",製作係数,IF(M$7="IT",結合テスト係数,IF(M$7="ST",総合テスト係数,IF(M$7="OT",受入支援係数,IF(M$7="RL",移行切替係数,IF(M$7="その他",その他係数,0))))))))) * M$8,1) -> 6.6 | N17: =ROUNDUP(IF($E17="画面",画面係数,IF($E17="帳票",帳票係数,IF($E17="バッチ",バッチ係数,0))) * IF($I17="特高",特高係数,IF($I17="高",高係数,IF($I17="中",中係数,IF($I17="低",低係数,IF($I17="特低",特低係数,0))))) * IF(N$7="SA",要件定義係数,IF(N$7="UI",基本設計係数,IF(N$7="SS",詳細設計係数,IF(N$7="PS/PG/PT",製作係数,IF(N$7="IT",結合テスト係数,IF(N$7="ST",総合テスト係数,IF(N$7="OT",受入支援係数,IF(N$7="RL",移行切替係数,IF(N$7="その他",その他係数,0))))))))) * N$8,1) -> 4.1 | O17: =ROUNDUP(IF($E17="画面",画面係数,IF($E17="帳票",帳票係数,IF($E17="バッチ",バッチ係数,0))) * IF($I17="特高",特高係数,IF($I17="高",高係数,IF($I17="中",中係数,IF($I17="低",低係数,IF($I17="特低",特低係数,0))))) * IF(O$7="SA",要件定義係数,IF(O$7="UI",基本設計係数,IF(O$7="SS",詳細設計係数,IF(O$7="PS/PG/PT",製作係数,IF(O$7="IT",結合テスト係数,IF(O$7="ST",総合テスト係数,IF(O$7="OT",受入支援係数,IF(O$7="RL",移行切替係数,IF(O$7="その他",その他係数,0))))))))) * O$8,1) -> 2.7 | P17: =ROUNDUP(IF($E17="画面",画面係数,IF($E17="帳票",帳票係数,IF($E17="バッチ",バッチ係数,0))) * IF($I17="特高",特高係数,IF($I17="高",高係数,IF($I17="中",中係数,IF($I17="低",低係数,IF($I17="特低",特低係数,0))))) * IF(P$7="SA",要件定義係数,IF(P$7="UI",基本設計係数,IF(P$7="SS",詳細設計係数,IF(P$7="PS/PG/PT",製作係数,IF(P$7="IT",結合テスト係数,IF(P$7="ST",総合テスト係数,IF(P$7="OT",受入支援係数,IF(P$7="RL",移行切替係数,IF(P$7="その他",その他係数,0))))))))) * P$8,1) -> 1.1 | Q17: =ROUNDUP(IF($E17="画面",画面係数,IF($E17="帳票",帳票係数,IF($E17="バッチ",バッチ係数,0))) * IF($I17="特高",特高係数,IF($I17="高",高係数,IF($I17="中",中係数,IF($I17="低",低係数,IF($I17="特低",特低係数,0))))) * IF(Q$7="SA",要件定義係数,IF(Q$7="UI",基本設計係数,IF(Q$7="SS",詳細設計係数,IF(Q$7="PS/PG/PT",製作係数,IF(Q$7="IT",結合テスト係数,IF(Q$7="ST",総合テスト係数,IF(Q$7="OT",受入支援係数,IF(Q$7="RL",移行切替係数,IF(Q$7="その他",その他係数,0))))))))) * Q$8,1) -> 3.1 | R17: =ROUNDUP(IF($E17="画面",画面係数,IF($E17="帳票",帳票係数,IF($E17="バッチ",バッチ係数,0))) * IF($I17="特高",特高係数,IF($I17="高",高係数,IF($I17="中",中係数,IF($I17="低",低係数,IF($I17="特低",特低係数,0))))) * IF(R$7="SA",要件定義係数,IF(R$7="UI",基本設計係数,IF(R$7="SS",詳細設計係数,IF(R$7="PS/PG/PT",製作係数,IF(R$7="IT",結合テスト係数,IF(R$7="ST",総合テスト係数,IF(R$7="OT",受入支援係数,IF(R$7="RL",移行切替係数,IF(R$7="その他",その他係数,0))))))))) * R$8,1) -> 0 | T17: =ROUNDUP(SUM(J17:S17)*T$8,1) -> 4.2 | U17: =SUM(J17:T17) -> 32 | V17: =U17/20 -> 1.6 | W17: =((J17*J$9) + (K17*K$9) + (L17*L$9) + (M17*M$9) + (N17*N$9) + (O17*O$9) + (P17*P$9) + (Q17*Q$9) + (R17*R$9) + (S17*S$9) + (T17*T$9))/20 -> 1684000
A18: =ROW()-9 -> 9 | B18: PG | C18: 二次加工DB | D18: D:\skaicsei\App\Common\DBCOLECT\COL_SERVER.exe | E18: 画面 | J18: =ROUNDUP(IF($E18="画面",画面係数,IF($E18="帳票",帳票係数,IF($E18="バッチ",バッチ係数,0))) * IF($I18="特高",特高係数,IF($I18="高",高係数,IF($I18="中",中係数,IF($I18="低",低係数,IF($I18="特低",特低係数,0))))) * IF(J$7="SA",要件定義係数,IF(J$7="UI",基本設計係数,IF(J$7="SS",詳細設計係数,IF(J$7="PS/PG/PT",製作係数,IF(J$7="IT",結合テスト係数,IF(J$7="ST",総合テスト係数,IF(J$7="OT",受入支援係数,IF(J$7="RL",移行切替係数,IF(J$7="その他",その他係数,0))))))))) * J$8,1) -> 0 | K18: =ROUNDUP(IF($E18="画面",画面係数,IF($E18="帳票",帳票係数,IF($E18="バッチ",バッチ係数,0))) * IF($I18="特高",特高係数,IF($I18="高",高係数,IF($I18="中",中係数,IF($I18="低",低係数,IF($I18="特低",特低係数,0))))) * IF(K$7="SA",要件定義係数,IF(K$7="UI",基本設計係数,IF(K$7="SS",詳細設計係数,IF(K$7="PS/PG/PT",製作係数,IF(K$7="IT",結合テスト係数,IF(K$7="ST",総合テスト係数,IF(K$7="OT",受入支援係数,IF(K$7="RL",移行切替係数,IF(K$7="その他",その他係数,0))))))))) * K$8,1) -> 0 | L18: =ROUNDUP(IF($E18="画面",画面係数,IF($E18="帳票",帳票係数,IF($E18="バッチ",バッチ係数,0))) * IF($I18="特高",特高係数,IF($I18="高",高係数,IF($I18="中",中係数,IF($I18="低",低係数,IF($I18="特低",特低係数,0))))) * IF(L$7="SA",要件定義係数,IF(L$7="UI",基本設計係数,IF(L$7="SS",詳細設計係数,IF(L$7="PS/PG/PT",製作係数,IF(L$7="IT",結合テスト係数,IF(L$7="ST",総合テスト係数,IF(L$7="OT",受入支援係数,IF(L$7="RL",移行切替係数,IF(L$7="その他",その他係数,0))))))))) * L$8,1) -> 0 | M18: =ROUNDUP(IF($E18="画面",画面係数,IF($E18="帳票",帳票係数,IF($E18="バッチ",バッチ係数,0))) * IF($I18="特高",特高係数,IF($I18="高",高係数,IF($I18="中",中係数,IF($I18="低",低係数,IF($I18="特低",特低係数,0))))) * IF(M$7="SA",要件定義係数,IF(M$7="UI",基本設計係数,IF(M$7="SS",詳細設計係数,IF(M$7="PS/PG/PT",製作係数,IF(M$7="IT",結合テスト係数,IF(M$7="ST",総合テスト係数,IF(M$7="OT",受入支援係数,IF(M$7="RL",移行切替係数,IF(M$7="その他",その他係数,0))))))))) * M$8,1) -> 0 | N18: =ROUNDUP(IF($E18="画面",画面係数,IF($E18="帳票",帳票係数,IF($E18="バッチ",バッチ係数,0))) * IF($I18="特高",特高係数,IF($I18="高",高係数,IF($I18="中",中係数,IF($I18="低",低係数,IF($I18="特低",特低係数,0))))) * IF(N$7="SA",要件定義係数,IF(N$7="UI",基本設計係数,IF(N$7="SS",詳細設計係数,IF(N$7="PS/PG/PT",製作係数,IF(N$7="IT",結合テスト係数,IF(N$7="ST",総合テスト係数,IF(N$7="OT",受入支援係数,IF(N$7="RL",移行切替係数,IF(N$7="その他",その他係数,0))))))))) * N$8,1) -> 0 | O18: =ROUNDUP(IF($E18="画面",画面係数,IF($E18="帳票",帳票係数,IF($E18="バッチ",バッチ係数,0))) * IF($I18="特高",特高係数,IF($I18="高",高係数,IF($I18="中",中係数,IF($I18="低",低係数,IF($I18="特低",特低係数,0))))) * IF(O$7="SA",要件定義係数,IF(O$7="UI",基本設計係数,IF(O$7="SS",詳細設計係数,IF(O$7="PS/PG/PT",製作係数,IF(O$7="IT",結合テスト係数,IF(O$7="ST",総合テスト係数,IF(O$7="OT",受入支援係数,IF(O$7="RL",移行切替係数,IF(O$7="その他",その他係数,0))))))))) * O$8,1) -> 0 | P18: =ROUNDUP(IF($E18="画面",画面係数,IF($E18="帳票",帳票係数,IF($E18="バッチ",バッチ係数,0))) * IF($I18="特高",特高係数,IF($I18="高",高係数,IF($I18="中",中係数,IF($I18="低",低係数,IF($I18="特低",特低係数,0))))) * IF(P$7="SA",要件定義係数,IF(P$7="UI",基本設計係数,IF(P$7="SS",詳細設計係数,IF(P$7="PS/PG/PT",製作係数,IF(P$7="IT",結合テスト係数,IF(P$7="ST",総合テスト係数,IF(P$7="OT",受入支援係数,IF(P$7="RL",移行切替係数,IF(P$7="その他",その他係数,0))))))))) * P$8,1) -> 0 | Q18: =ROUNDUP(IF($E18="画面",画面係数,IF($E18="帳票",帳票係数,IF($E18="バッチ",バッチ係数,0))) * IF($I18="特高",特高係数,IF($I18="高",高係数,IF($I18="中",中係数,IF($I18="低",低係数,IF($I18="特低",特低係数,0))))) * IF(Q$7="SA",要件定義係数,IF(Q$7="UI",基本設計係数,IF(Q$7="SS",詳細設計係数,IF(Q$7="PS/PG/PT",製作係数,IF(Q$7="IT",結合テスト係数,IF(Q$7="ST",総合テスト係数,IF(Q$7="OT",受入支援係数,IF(Q$7="RL",移行切替係数,IF(Q$7="その他",その他係数,0))))))))) * Q$8,1) -> 0 | R18: =ROUNDUP(IF($E18="画面",画面係数,IF($E18="帳票",帳票係数,IF($E18="バッチ",バッチ係数,0))) * IF($I18="特高",特高係数,IF($I18="高",高係数,IF($I18="中",中係数,IF($I18="低",低係数,IF($I18="特低",特低係数,0))))) * IF(R$7="SA",要件定義係数,IF(R$7="UI",基本設計係数,IF(R$7="SS",詳細設計係数,IF(R$7="PS/PG/PT",製作係数,IF(R$7="IT",結合テスト係数,IF(R$7="ST",総合テスト係数,IF(R$7="OT",受入支援係数,IF(R$7="RL",移行切替係数,IF(R$7="その他",その他係数,0))))))))) * R$8,1) -> 0 | T18: =ROUNDUP(SUM(J18:S18)*T$8,1) -> 0 | U18: =SUM(J18:T18) -> 0 | V18: =U18/20 -> 0 | W18: =((J18*J$9) + (K18*K$9) + (L18*L$9) + (M18*M$9) + (N18*N$9) + (O18*O$9) + (P18*P$9) + (Q18*Q$9) + (R18*R$9) + (S18*S$9) + (T18*T$9))/20 -> 0
A19: =ROW()-9 -> 10 | B19: PG | C19: 製油所データ作成 | D19: D:\skaicsei\App\Sougyou\bin\BINAS_SEIYU.exe | E19: 画面 | I19: 高 | J19: =ROUNDUP(IF($E19="画面",画面係数,IF($E19="帳票",帳票係数,IF($E19="バッチ",バッチ係数,0))) * IF($I19="特高",特高係数,IF($I19="高",高係数,IF($I19="中",中係数,IF($I19="低",低係数,IF($I19="特低",特低係数,0))))) * IF(J$7="SA",要件定義係数,IF(J$7="UI",基本設計係数,IF(J$7="SS",詳細設計係数,IF(J$7="PS/PG/PT",製作係数,IF(J$7="IT",結合テスト係数,IF(J$7="ST",総合テスト係数,IF(J$7="OT",受入支援係数,IF(J$7="RL",移行切替係数,IF(J$7="その他",その他係数,0))))))))) * J$8,1) -> 3.1 | K19: =ROUNDUP(IF($E19="画面",画面係数,IF($E19="帳票",帳票係数,IF($E19="バッチ",バッチ係数,0))) * IF($I19="特高",特高係数,IF($I19="高",高係数,IF($I19="中",中係数,IF($I19="低",低係数,IF($I19="特低",特低係数,0))))) * IF(K$7="SA",要件定義係数,IF(K$7="UI",基本設計係数,IF(K$7="SS",詳細設計係数,IF(K$7="PS/PG/PT",製作係数,IF(K$7="IT",結合テスト係数,IF(K$7="ST",総合テスト係数,IF(K$7="OT",受入支援係数,IF(K$7="RL",移行切替係数,IF(K$7="その他",その他係数,0))))))))) * K$8,1) -> 3.5 | L19: =ROUNDUP(IF($E19="画面",画面係数,IF($E19="帳票",帳票係数,IF($E19="バッチ",バッチ係数,0))) * IF($I19="特高",特高係数,IF($I19="高",高係数,IF($I19="中",中係数,IF($I19="低",低係数,IF($I19="特低",特低係数,0))))) * IF(L$7="SA",要件定義係数,IF(L$7="UI",基本設計係数,IF(L$7="SS",詳細設計係数,IF(L$7="PS/PG/PT",製作係数,IF(L$7="IT",結合テスト係数,IF(L$7="ST",総合テスト係数,IF(L$7="OT",受入支援係数,IF(L$7="RL",移行切替係数,IF(L$7="その他",その他係数,0))))))))) * L$8,1) -> 3.6 | M19: =ROUNDUP(IF($E19="画面",画面係数,IF($E19="帳票",帳票係数,IF($E19="バッチ",バッチ係数,0))) * IF($I19="特高",特高係数,IF($I19="高",高係数,IF($I19="中",中係数,IF($I19="低",低係数,IF($I19="特低",特低係数,0))))) * IF(M$7="SA",要件定義係数,IF(M$7="UI",基本設計係数,IF(M$7="SS",詳細設計係数,IF(M$7="PS/PG/PT",製作係数,IF(M$7="IT",結合テスト係数,IF(M$7="ST",総合テスト係数,IF(M$7="OT",受入支援係数,IF(M$7="RL",移行切替係数,IF(M$7="その他",その他係数,0))))))))) * M$8,1) -> 6.6 | N19: =ROUNDUP(IF($E19="画面",画面係数,IF($E19="帳票",帳票係数,IF($E19="バッチ",バッチ係数,0))) * IF($I19="特高",特高係数,IF($I19="高",高係数,IF($I19="中",中係数,IF($I19="低",低係数,IF($I19="特低",特低係数,0))))) * IF(N$7="SA",要件定義係数,IF(N$7="UI",基本設計係数,IF(N$7="SS",詳細設計係数,IF(N$7="PS/PG/PT",製作係数,IF(N$7="IT",結合テスト係数,IF(N$7="ST",総合テスト係数,IF(N$7="OT",受入支援係数,IF(N$7="RL",移行切替係数,IF(N$7="その他",その他係数,0))))))))) * N$8,1) -> 4.1 | O19: =ROUNDUP(IF($E19="画面",画面係数,IF($E19="帳票",帳票係数,IF($E19="バッチ",バッチ係数,0))) * IF($I19="特高",特高係数,IF($I19="高",高係数,IF($I19="中",中係数,IF($I19="低",低係数,IF($I19="特低",特低係数,0))))) * IF(O$7="SA",要件定義係数,IF(O$7="UI",基本設計係数,IF(O$7="SS",詳細設計係数,IF(O$7="PS/PG/PT",製作係数,IF(O$7="IT",結合テスト係数,IF(O$7="ST",総合テスト係数,IF(O$7="OT",受入支援係数,IF(O$7="RL",移行切替係数,IF(O$7="その他",その他係数,0))))))))) * O$8,1) -> 2.7 | P19: =ROUNDUP(IF($E19="画面",画面係数,IF($E19="帳票",帳票係数,IF($E19="バッチ",バッチ係数,0))) * IF($I19="特高",特高係数,IF($I19="高",高係数,IF($I19="中",中係数,IF($I19="低",低係数,IF($I19="特低",特低係数,0))))) * IF(P$7="SA",要件定義係数,IF(P$7="UI",基本設計係数,IF(P$7="SS",詳細設計係数,IF(P$7="PS/PG/PT",製作係数,IF(P$7="IT",結合テスト係数,IF(P$7="ST",総合テスト係数,IF(P$7="OT",受入支援係数,IF(P$7="RL",移行切替係数,IF(P$7="その他",その他係数,0))))))))) * P$8,1) -> 1.1 | Q19: =ROUNDUP(IF($E19="画面",画面係数,IF($E19="帳票",帳票係数,IF($E19="バッチ",バッチ係数,0))) * IF($I19="特高",特高係数,IF($I19="高",高係数,IF($I19="中",中係数,IF($I19="低",低係数,IF($I19="特低",特低係数,0))))) * IF(Q$7="SA",要件定義係数,IF(Q$7="UI",基本設計係数,IF(Q$7="SS",詳細設計係数,IF(Q$7="PS/PG/PT",製作係数,IF(Q$7="IT",結合テスト係数,IF(Q$7="ST",総合テスト係数,IF(Q$7="OT",受入支援係数,IF(Q$7="RL",移行切替係数,IF(Q$7="その他",その他係数,0))))))))) * Q$8,1) -> 3.1 | R19: =ROUNDUP(IF($E19="画面",画面係数,IF($E19="帳票",帳票係数,IF($E19="バッチ",バッチ係数,0))) * IF($I19="特高",特高係数,IF($I19="高",高係数,IF($I19="中",中係数,IF($I19="低",低係数,IF($I19="特低",特低係数,0))))) * IF(R$7="SA",要件定義係数,IF(R$7="UI",基本設計係数,IF(R$7="SS",詳細設計係数,IF(R$7="PS/PG/PT",製作係数,IF(R$7="IT",結合テスト係数,IF(R$7="ST",総合テスト係数,IF(R$7="OT",受入支援係数,IF(R$7="RL",移行切替係数,IF(R$7="その他",その他係数,0))))))))) * R$8,1) -> 0 | T19: =ROUNDUP(SUM(J19:S19)*T$8,1) -> 4.2 | U19: =SUM(J19:T19) -> 32 | V19: =U19/20 -> 1.6 | W19: =((J19*J$9) + (K19*K$9) + (L19*L$9) + (M19*M$9) + (N19*N$9) + (O19*O$9) + (P19*P$9) + (Q19*Q$9) + (R19*R$9) + (S19*S$9) + (T19*T$9))/20 -> 1684000
A20: =ROW()-9 -> 11 | B20: PG | C20: DB削除 | D20: D:\skaicsei\App\Sougyou\bin\DELETE_DB.exe | E20: 画面 | I20: 高 | J20: =ROUNDUP(IF($E20="画面",画面係数,IF($E20="帳票",帳票係数,IF($E20="バッチ",バッチ係数,0))) * IF($I20="特高",特高係数,IF($I20="高",高係数,IF($I20="中",中係数,IF($I20="低",低係数,IF($I20="特低",特低係数,0))))) * IF(J$7="SA",要件定義係数,IF(J$7="UI",基本設計係数,IF(J$7="SS",詳細設計係数,IF(J$7="PS/PG/PT",製作係数,IF(J$7="IT",結合テスト係数,IF(J$7="ST",総合テスト係数,IF(J$7="OT",受入支援係数,IF(J$7="RL",移行切替係数,IF(J$7="その他",その他係数,0))))))))) * J$8,1) -> 3.1 | K20: =ROUNDUP(IF($E20="画面",画面係数,IF($E20="帳票",帳票係数,IF($E20="バッチ",バッチ係数,0))) * IF($I20="特高",特高係数,IF($I20="高",高係数,IF($I20="中",中係数,IF($I20="低",低係数,IF($I20="特低",特低係数,0))))) * IF(K$7="SA",要件定義係数,IF(K$7="UI",基本設計係数,IF(K$7="SS",詳細設計係数,IF(K$7="PS/PG/PT",製作係数,IF(K$7="IT",結合テスト係数,IF(K$7="ST",総合テスト係数,IF(K$7="OT",受入支援係数,IF(K$7="RL",移行切替係数,IF(K$7="その他",その他係数,0))))))))) * K$8,1) -> 3.5 | L20: =ROUNDUP(IF($E20="画面",画面係数,IF($E20="帳票",帳票係数,IF($E20="バッチ",バッチ係数,0))) * IF($I20="特高",特高係数,IF($I20="高",高係数,IF($I20="中",中係数,IF($I20="低",低係数,IF($I20="特低",特低係数,0))))) * IF(L$7="SA",要件定義係数,IF(L$7="UI",基本設計係数,IF(L$7="SS",詳細設計係数,IF(L$7="PS/PG/PT",製作係数,IF(L$7="IT",結合テスト係数,IF(L$7="ST",総合テスト係数,IF(L$7="OT",受入支援係数,IF(L$7="RL",移行切替係数,IF(L$7="その他",その他係数,0))))))))) * L$8,1) -> 3.6 | M20: =ROUNDUP(IF($E20="画面",画面係数,IF($E20="帳票",帳票係数,IF($E20="バッチ",バッチ係数,0))) * IF($I20="特高",特高係数,IF($I20="高",高係数,IF($I20="中",中係数,IF($I20="低",低係数,IF($I20="特低",特低係数,0))))) * IF(M$7="SA",要件定義係数,IF(M$7="UI",基本設計係数,IF(M$7="SS",詳細設計係数,IF(M$7="PS/PG/PT",製作係数,IF(M$7="IT",結合テスト係数,IF(M$7="ST",総合テスト係数,IF(M$7="OT",受入支援係数,IF(M$7="RL",移行切替係数,IF(M$7="その他",その他係数,0))))))))) * M$8,1) -> 6.6 | N20: =ROUNDUP(IF($E20="画面",画面係数,IF($E20="帳票",帳票係数,IF($E20="バッチ",バッチ係数,0))) * IF($I20="特高",特高係数,IF($I20="高",高係数,IF($I20="中",中係数,IF($I20="低",低係数,IF($I20="特低",特低係数,0))))) * IF(N$7="SA",要件定義係数,IF(N$7="UI",基本設計係数,IF(N$7="SS",詳細設計係数,IF(N$7="PS/PG/PT",製作係数,IF(N$7="IT",結合テスト係数,IF(N$7="ST",総合テスト係数,IF(N$7="OT",受入支援係数,IF(N$7="RL",移行切替係数,IF(N$7="その他",その他係数,0))))))))) * N$8,1) -> 4.1 | O20: =ROUNDUP(IF($E20="画面",画面係数,IF($E20="帳票",帳票係数,IF($E20="バッチ",バッチ係数,0))) * IF($I20="特高",特高係数,IF($I20="高",高係数,IF($I20="中",中係数,IF($I20="低",低係数,IF($I20="特低",特低係数,0))))) * IF(O$7="SA",要件定義係数,IF(O$7="UI",基本設計係数,IF(O$7="SS",詳細設計係数,IF(O$7="PS/PG/PT",製作係数,IF(O$7="IT",結合テスト係数,IF(O$7="ST",総合テスト係数,IF(O$7="OT",受入支援係数,IF(O$7="RL",移行切替係数,IF(O$7="その他",その他係数,0))))))))) * O$8,1) -> 2.7 | P20: =ROUNDUP(IF($E20="画面",画面係数,IF($E20="帳票",帳票係数,IF($E20="バッチ",バッチ係数,0))) * IF($I20="特高",特高係数,IF($I20="高",高係数,IF($I20="中",中係数,IF($I20="低",低係数,IF($I20="特低",特低係数,0))))) * IF(P$7="SA",要件定義係数,IF(P$7="UI",基本設計係数,IF(P$7="SS",詳細設計係数,IF(P$7="PS/PG/PT",製作係数,IF(P$7="IT",結合テスト係数,IF(P$7="ST",総合テスト係数,IF(P$7="OT",受入支援係数,IF(P$7="RL",移行切替係数,IF(P$7="その他",その他係数,0))))))))) * P$8,1) -> 1.1 | Q20: =ROUNDUP(IF($E20="画面",画面係数,IF($E20="帳票",帳票係数,IF($E20="バッチ",バッチ係数,0))) * IF($I20="特高",特高係数,IF($I20="高",高係数,IF($I20="中",中係数,IF($I20="低",低係数,IF($I20="特低",特低係数,0))))) * IF(Q$7="SA",要件定義係数,IF(Q$7="UI",基本設計係数,IF(Q$7="SS",詳細設計係数,IF(Q$7="PS/PG/PT",製作係数,IF(Q$7="IT",結合テスト係数,IF(Q$7="ST",総合テスト係数,IF(Q$7="OT",受入支援係数,IF(Q$7="RL",移行切替係数,IF(Q$7="その他",その他係数,0))))))))) * Q$8,1) -> 3.1 | R20: =ROUNDUP(IF($E20="画面",画面係数,IF($E20="帳票",帳票係数,IF($E20="バッチ",バッチ係数,0))) * IF($I20="特高",特高係数,IF($I20="高",高係数,IF($I20="中",中係数,IF($I20="低",低係数,IF($I20="特低",特低係数,0))))) * IF(R$7="SA",要件定義係数,IF(R$7="UI",基本設計係数,IF(R$7="SS",詳細設計係数,IF(R$7="PS/PG/PT",製作係数,IF(R$7="IT",結合テスト係数,IF(R$7="ST",総合テスト係数,IF(R$7="OT",受入支援係数,IF(R$7="RL",移行切替係数,IF(R$7="その他",その他係数,0))))))))) * R$8,1) -> 0 | T20: =ROUNDUP(SUM(J20:S20)*T$8,1) -> 4.2 | U20: =SUM(J20:T20) -> 32 | V20: =U20/20 -> 1.6 | W20: =((J20*J$9) + (K20*K$9) + (L20*L$9) + (M20*M$9) + (N20*N$9) + (O20*O$9) + (P20*P$9) + (Q20*Q$9) + (R20*R$9) + (S20*S$9) + (T20*T$9))/20 -> 1684000
A21: =ROW()-9 -> 12 | B21: PG | C21: 潤滑油タンク在庫編集 | D21: D:\skaicsei\App\Sougyou\bin\EDT_JNKTZAIK.exe | E21: 画面 | I21: 高 | J21: =ROUNDUP(IF($E21="画面",画面係数,IF($E21="帳票",帳票係数,IF($E21="バッチ",バッチ係数,0))) * IF($I21="特高",特高係数,IF($I21="高",高係数,IF($I21="中",中係数,IF($I21="低",低係数,IF($I21="特低",特低係数,0))))) * IF(J$7="SA",要件定義係数,IF(J$7="UI",基本設計係数,IF(J$7="SS",詳細設計係数,IF(J$7="PS/PG/PT",製作係数,IF(J$7="IT",結合テスト係数,IF(J$7="ST",総合テスト係数,IF(J$7="OT",受入支援係数,IF(J$7="RL",移行切替係数,IF(J$7="その他",その他係数,0))))))))) * J$8,1) -> 3.1 | K21: =ROUNDUP(IF($E21="画面",画面係数,IF($E21="帳票",帳票係数,IF($E21="バッチ",バッチ係数,0))) * IF($I21="特高",特高係数,IF($I21="高",高係数,IF($I21="中",中係数,IF($I21="低",低係数,IF($I21="特低",特低係数,0))))) * IF(K$7="SA",要件定義係数,IF(K$7="UI",基本設計係数,IF(K$7="SS",詳細設計係数,IF(K$7="PS/PG/PT",製作係数,IF(K$7="IT",結合テスト係数,IF(K$7="ST",総合テスト係数,IF(K$7="OT",受入支援係数,IF(K$7="RL",移行切替係数,IF(K$7="その他",その他係数,0))))))))) * K$8,1) -> 3.5 | L21: =ROUNDUP(IF($E21="画面",画面係数,IF($E21="帳票",帳票係数,IF($E21="バッチ",バッチ係数,0))) * IF($I21="特高",特高係数,IF($I21="高",高係数,IF($I21="中",中係数,IF($I21="低",低係数,IF($I21="特低",特低係数,0))))) * IF(L$7="SA",要件定義係数,IF(L$7="UI",基本設計係数,IF(L$7="SS",詳細設計係数,IF(L$7="PS/PG/PT",製作係数,IF(L$7="IT",結合テスト係数,IF(L$7="ST",総合テスト係数,IF(L$7="OT",受入支援係数,IF(L$7="RL",移行切替係数,IF(L$7="その他",その他係数,0))))))))) * L$8,1) -> 3.6 | M21: =ROUNDUP(IF($E21="画面",画面係数,IF($E21="帳票",帳票係数,IF($E21="バッチ",バッチ係数,0))) * IF($I21="特高",特高係数,IF($I21="高",高係数,IF($I21="中",中係数,IF($I21="低",低係数,IF($I21="特低",特低係数,0))))) * IF(M$7="SA",要件定義係数,IF(M$7="UI",基本設計係数,IF(M$7="SS",詳細設計係数,IF(M$7="PS/PG/PT",製作係数,IF(M$7="IT",結合テスト係数,IF(M$7="ST",総合テスト係数,IF(M$7="OT",受入支援係数,IF(M$7="RL",移行切替係数,IF(M$7="その他",その他係数,0))))))))) * M$8,1) -> 6.6 | N21: =ROUNDUP(IF($E21="画面",画面係数,IF($E21="帳票",帳票係数,IF($E21="バッチ",バッチ係数,0))) * IF($I21="特高",特高係数,IF($I21="高",高係数,IF($I21="中",中係数,IF($I21="低",低係数,IF($I21="特低",特低係数,0))))) * IF(N$7="SA",要件定義係数,IF(N$7="UI",基本設計係数,IF(N$7="SS",詳細設計係数,IF(N$7="PS/PG/PT",製作係数,IF(N$7="IT",結合テスト係数,IF(N$7="ST",総合テスト係数,IF(N$7="OT",受入支援係数,IF(N$7="RL",移行切替係数,IF(N$7="その他",その他係数,0))))))))) * N$8,1) -> 4.1 | O21: =ROUNDUP(IF($E21="画面",画面係数,IF($E21="帳票",帳票係数,IF($E21="バッチ",バッチ係数,0))) * IF($I21="特高",特高係数,IF($I21="高",高係数,IF($I21="中",中係数,IF($I21="低",低係数,IF($I21="特低",特低係数,0))))) * IF(O$7="SA",要件定義係数,IF(O$7="UI",基本設計係数,IF(O$7="SS",詳細設計係数,IF(O$7="PS/PG/PT",製作係数,IF(O$7="IT",結合テスト係数,IF(O$7="ST",総合テスト係数,IF(O$7="OT",受入支援係数,IF(O$7="RL",移行切替係数,IF(O$7="その他",その他係数,0))))))))) * O$8,1) -> 2.7 | P21: =ROUNDUP(IF($E21="画面",画面係数,IF($E21="帳票",帳票係数,IF($E21="バッチ",バッチ係数,0))) * IF($I21="特高",特高係数,IF($I21="高",高係数,IF($I21="中",中係数,IF($I21="低",低係数,IF($I21="特低",特低係数,0))))) * IF(P$7="SA",要件定義係数,IF(P$7="UI",基本設計係数,IF(P$7="SS",詳細設計係数,IF(P$7="PS/PG/PT",製作係数,IF(P$7="IT",結合テスト係数,IF(P$7="ST",総合テスト係数,IF(P$7="OT",受入支援係数,IF(P$7="RL",移行切替係数,IF(P$7="その他",その他係数,0))))))))) * P$8,1) -> 1.1 | Q21: =ROUNDUP(IF($E21="画面",画面係数,IF($E21="帳票",帳票係数,IF($E21="バッチ",バッチ係数,0))) * IF($I21="特高",特高係数,IF($I21="高",高係数,IF($I21="中",中係数,IF($I21="低",低係数,IF($I21="特低",特低係数,0))))) * IF(Q$7="SA",要件定義係数,IF(Q$7="UI",基本設計係数,IF(Q$7="SS",詳細設計係数,IF(Q$7="PS/PG/PT",製作係数,IF(Q$7="IT",結合テスト係数,IF(Q$7="ST",総合テスト係数,IF(Q$7="OT",受入支援係数,IF(Q$7="RL",移行切替係数,IF(Q$7="その他",その他係数,0))))))))) * Q$8,1) -> 3.1 | R21: =ROUNDUP(IF($E21="画面",画面係数,IF($E21="帳票",帳票係数,IF($E21="バッチ",バッチ係数,0))) * IF($I21="特高",特高係数,IF($I21="高",高係数,IF($I21="中",中係数,IF($I21="低",低係数,IF($I21="特低",特低係数,0))))) * IF(R$7="SA",要件定義係数,IF(R$7="UI",基本設計係数,IF(R$7="SS",詳細設計係数,IF(R$7="PS/PG/PT",製作係数,IF(R$7="IT",結合テスト係数,IF(R$7="ST",総合テスト係数,IF(R$7="OT",受入支援係数,IF(R$7="RL",移行切替係数,IF(R$7="その他",その他係数,0))))))))) * R$8,1) -> 0 | T21: =ROUNDUP(SUM(J21:S21)*T$8,1) -> 4.2 | U21: =SUM(J21:T21) -> 32 | V21: =U21/20 -> 1.6 | W21: =((J21*J$9) + (K21*K$9) + (L21*L$9) + (M21*M$9) + (N21*N$9) + (O21*O$9) + (P21*P$9) + (Q21*Q$9) + (R21*R$9) + (S21*S$9) + (T21*T$9))/20 -> 1684000
