Workbook
Name その他係数: 積算基準!$L$35
Name バッチ係数: 積算基準!$F$29
Name 移行切替係数: 積算基準!$K$35
Name 画面係数: 積算基準!$D$29
Name 基本設計係数: 積算基準!$E$35
Name 結合テスト係数: 積算基準!$H$35
Name 高係数: 積算基準!$E$41
Name 参照上限高: 積算基準!$E$17
Name 参照上限中: 積算基準!$F$17
Name 参照上限低: 積算基準!$G$17
Name 参照上限特高: 積算基準!$D$17
Name 参照上限特低: 積算基準!$H$17
Name 受入支援係数: 積算基準!$J$35
Name 詳細設計係数: 積算基準!$F$35
Name 製作係数: 積算基準!$G$35
Name 総合テスト係数: 積算基準!$I$35
Name 中係数: 積算基準!$F$41
Name 帳票係数: 積算基準!$E$29
Name 低係数: 積算基準!$G$41
Name 登録上限高: 積算基準!$E$16
Name 登録上限中: 積算基準!$F$16
Name 登録上限低: 積算基準!$G$16
Name 登録上限特高: 積算基準!$D$16
Name 登録上限特低: 積算基準!$H$16
Name 特高係数: 積算基準!$D$41
Name 特低係数: 積算基準!$H$41
Name 要件定義係数: 積算基準!$D$35

Sheet サマリ
B1: 千葉運転管理システム（制御通信サーバ）
B3: ■最適工期 | E3: ■御見積金額(全工程の場合) | L3: ■御見積金額(全工程の場合) ：工数丸め
B5: 全体工期 | C5: =(工数算出!U4^(1/3))*2.69 -> 18.35342 | E5: 見積金額合計 | F5: =SUM(I9:I19) -> 347991000 | L5: 見積金額合計 | M5: =SUM(P9:P19) -> 339150000
B8: 工程 | C8: 工期 | E8: 工程 | F8: 工数 | H8: 単価 | I8: 金額 | L8: 工程 | M8: 工数 | O8: 単価 | P8: 金額
B9: 要件定義（SA） | C9: =C5*積算基準!P35 -> 2.0392689 | E9: 要件定義（SA） | F9: 1 | G9: =工数算出!$J4 -> 30.75 | H9: 1050000 | I9: =G9*H9 -> 32287500 | L9: 要件定義（SA） | M9: 1 | N9: 15 | O9: 1050000 | P9: =N9*O9 -> 15750000
B10: 基本設計（UI） | C10: =C5*積算基準!Q35 -> 2.8141911 | E10: 基本設計（UI） | F10: 1 | G10: =工数算出!$K4 -> 34.59 | H10: 1050000 | I10: =G10*H10 -> 36319500 | L10: 基本設計（UI） | M10: 1 | N10: 35 | O10: 1050000 | P10: =N10*O10 -> 36750000
B11: 詳細設計（SS） | C11: =C5*積算基準!R35 -> 2.379147 | E11: 詳細設計（SS） | F11: 1 | G11: =工数算出!$L4 -> 35.77 | H11: 1050000 | I11: =G11*H11 -> 37558500 | L11: 詳細設計（SS） | M11: 1 | N11: 36 | O11: 1050000 | P11: =N11*O11 -> 37800000
B12: 開発（PS/PG/PT） | C12: =C5*積算基準!S35 -> 3.3851864 | E12: 開発（PS/PG/PT） | F12: 1 | G12: =工数算出!$M4 -> 65.28 | H12: 1050000 | I12: =G12*H12 -> 68544000 | L12: 開発（PS/PG/PT） | M12: 1 | N12: 65 | O12: 1050000 | P12: =N12*O12 -> 68250000
B13: 結合テスト（IT） | C13: =C5*積算基準!T35 -> 2.6238593 | E13: 結合テスト（IT） | F13: 1 | G13: =工数算出!$N4 -> 40.65 | H13: 1050000 | I13: =G13*H13 -> 42682500 | L13: 結合テスト（IT） | M13: 1 | N13: 40 | O13: 1050000 | P13: =N13*O13 -> 42000000
B14: システムテスト（ST） | C14: =C5*積算基準!U35 -> 2.3927422 | E14: システムテスト（ST） | F14: 1 | G14: =工数算出!$O4 -> 27.32 | H14: 1050000 | I14: =G14*H14 -> 28686000 | L14: システムテスト（ST） | M14: 1 | N14: 30 | O14: 1050000 | P14: =N14*O14 -> 31500000
B15: 運用テスト（OT） | C15: =C5*積算基準!V35 -> 0.6797563 | E15: 運用テスト（OT） | F15: 1 | G15: =工数算出!$P4 -> 11.07 | H15: 1050000 | I15: =G15*H15 -> 11623500 | L15: 運用テスト（OT） | M15: 1 | N15: 12 | O15: 1050000 | P15: =N15*O15 -> 12600000
B16: 本番移行・初期流動（RL） | C16: =サマリ!C5*積算基準!W35 -> 2.0392689 | E16: 本番移行・初期流動（RL） | F16: 1 | G16: =工数算出!$Q4 -> 30.75 | H16: 1050000 | I16: =G16*H16 -> 32287500 | L16: 本番移行・初期流動（RL） | M16: 1 | N16: 30 | O16: 1050000 | P16: =N16*O16 -> 31500000
B17: その他 | C17: - | E17: その他 | F17: 1 | G17: =工数算出!R4 -> 0 | H17: 1050000 | I17: =G17*H17 -> 0 | L17: その他 | M17: 1 | N17: =工数算出!AD4 -> 0 | O17: 1050000 | P17: =N17*O17 -> 0
B18: 調整 | C18: - | E18: 調整 | F18: - | H18: 1050000 | I18: =G18*H18 -> 0 | L18: 調整 | M18: - | O18: 1050000 | P18: =N18*O18 -> 0
B19: プロジェクト管理（PM） | C19: - | E19: プロジェクト管理（PM） | F19: 0.15 | G19: =工数算出!T4 -> 41.43 | H19: 1400000 | I19: =G19*H19 -> 58002000 | L19: プロジェクト管理（PM） | M19: 0.15 | N19: 45 | O19: 1400000 | P19: =N19*O19 -> 63000000
B23: 参考：STEP数からの見積工数
B25: 工数＝ステップ数÷開発生産性
B26: STEP数 | C26: 557000
B27: 開発生産性（STEP数/月） | C27: 1000
B28: 工数 | C28: =C26/C27 -> 557

Sheet 積算基準
A1: 積算基準
B3: １．難易度を「特高」～「特低」までの５段階に分類する。
C5: 難易度
C6: 特高
C7: 高
C8: 中
C9: 低
C10: 特低
B12: ２．難易度の判断基準は、項目数により、区別する。
C14: 難易度判定：基準項目数
C15: 難易度 | D15: 特高 | E15: 高 | F15: 中 | G15: 低 | H15: 特低
C16: 登録 | D16: 50 | E16: 40 | F16: 30 | G16: 20 | H16: 0
C17: 参照 | D17: 60 | E17: 48 | F17: 36 | G17: 24 | H17: 12
B19: ３．IPA発行「ソフトウェア開発データ白書」に基づく、各工程の工数比率を使用する。
C21: 工数比率（IPA ソフトウェア開発データ白書 2018-2019より） | O21: 工期比率（IPA ソフトウェア開発データ白書 2018-2019より）
C22: 工程 | D22: 基本設計 | E22: 詳細設計 | F22: 製作 | G22: 結合テスト | H22: 総合テスト | I22: 計 | O22: 工程 | P22: 基本設計 | Q22: 詳細設計 | R22: 製作 | S22: 結合テスト | T22: 総合テスト | U22: 計
C23: 工数比率 | D23: 0.169 | E23: 0.175 | F23: 0.326 | G23: 0.2 | H23: 0.13 | I23: =SUM(D23:H23) -> 1 | O23: 工期比率 | P23: 0.207 | Q23: 0.175 | R23: 0.249 | S23: 0.193 | T23: 0.176 | U23: =SUM(P23:T23) -> 1
B25: ４．難易度「中」の基本設計～システムテストまでの標準工数を以下とする。
C27: 標準工数（JUASソフトウェアメトリックス調査より）
C28: 種別 | D28: 画面 | E28: 帳票 | F28: バッチ
C29: 登録 | D29: =0.97*20 -> 19.4 | E29: =0.97*0.7*20 -> 13.58 | F29: =0.26*20 -> 5.2 | H29: =SUM(D29:E29) -> 32.98
B31: ５．他の工程の工数を下記の基準により算出する。
C33: 工程 | D33: 要件定義 | E33: 基本設計 | F33: 詳細設計 | G33: 製作 | H33: 結合テスト | I33: 総合テスト | J33: 運用テスト | K33: 移行切替 | L33: その他 | M33: 計 | O33: 工程 | P33: 要件定義 | Q33: 基本設計 | R33: 詳細設計 | S33: 製作 | T33: 結合テスト | U33: 総合テスト | V33: 運用テスト | W33: 移行切替 | X33: その他 | Y33: 計
C34: 5工程基準 | D34: =SUM(E34:I34)*0.15 -> 0.15 | E34: =D23 -> 0.169 | F34: =E23 -> 0.175 | G34: =F23 -> 0.326 | H34: =G23 -> 0.2 | I34: =H23 -> 0.13 | J34: =SUM(E34:I34)*0.05 -> 0.05 | K34: 0.15 | L34: 0 | M34: =SUM(D34:L34) -> 1.35 | O34: 5工程基準 | P34: =SUM(Q34:U34)*0.15 -> 0.15 | Q34: =P23 -> 0.207 | R34: =Q23 -> 0.175 | S34: =R23 -> 0.249 | T34: =S23 -> 0.193 | U34: =T23 -> 0.176 | V34: =SUM(Q34:U34)*0.05 -> 0.05 | W34: 0.15 | X34: 0 | Y34: =SUM(P34:X34) -> 1.35
C35: 全体比率 | D35: =D34/$M34 -> 0.11111111 | E35: =E34/$M34 -> 0.12518519 | F35: =F34/$M34 -> 0.12962963 | G35: =G34/$M34 -> 0.24148148 | H35: =H34/$M34 -> 0.14814815 | I35: =I34/$M34 -> 0.096296296 | J35: =J34/$M34 -> 0.037037037 | K35: =K34/$M34 -> 0.11111111 | L35: =L34/$M34 -> 0 | M35: =SUM(D35:L35) -> 1 | O35: 全体比率 | P35: =P34/$Y34 -> 0.11111111 | Q35: =Q34/$Y34 -> 0.15333333 | R35: =R34/$Y34 -> 0.12962963 | S35: =S34/$Y34 -> 0.18444444 | T35: =T34/$Y34 -> 0.14296296 | U35: =U34/$Y34 -> 0.13037037 | V35: =V34/$Y34 -> 0.037037037 | W35: =W34/$Y34 -> 0.11111111 | X35: =X34/$Y34 -> 0 | Y35: =SUM(P35:X35) -> 1
B37: ６．他の難易度の工数は、下記の係数に基づき、積算する。
C39: 難易度別の工数係数
C40: 難易度 | D40: 特高 | E40: 高 | F40: 中 | G40: 低 | H40: 特低
C41: 工数比率 | D41: 3 | E41: 1.4 | F41: 1 | G41: 0.6 | H41: 0.2

Sheet 工数算出
A1: =サマリ!B1 -> 千葉運転管理システム（制御通信サーバ） | J1: SA | K1: UI | L1: SS | M1: PS/PG/PT | N1: IT | O1: ST | P1: OT | Q1: RL | R1: その他 | S1: 調整 | T1: PM | U1: 合計
G2: 工数（人日） | J2: =SUM(J10:J450) -> 614.9 | K2: =SUM(K10:K450) -> 691.8 | L2: =SUM(L10:L450) -> 715.3 | M2: =SUM(M10:M450) -> 1305.6 | N2: =SUM(N10:N450) -> 812.9 | O2: =SUM(O10:O450) -> 546.4 | P2: =SUM(P10:P450) -> 221.3 | Q2: =SUM(Q10:Q450) -> 614.9 | ... T2: =SUM(T10:T450) -> 850.1 | U2: =SUM(J2:T2) -> 6373.2
G3: 工数（人月） | J3: =J2/20 -> 30.745 | K3: =K2/20 -> 34.59 | L3: =L2/20 -> 35.765 | M3: =M2/20 -> 65.28 | N3: =N2/20 -> 40.645 | O3: =O2/20 -> 27.32 | P3: =P2/20 -> 11.065 | Q3: =Q2/20 -> 30.745 | ... T3: =T2/20 -> 42.505 | U3: =SUM(J3:T3) -> 318.66
A4: 見積金額 | D4: =U5 -> 347991000 | G4: 調整後工数（人月） | J4: =ROUNDUP(J3,2) -> 30.75 | K4: =ROUNDUP(K3,2) -> 34.59 | L4: =ROUNDUP(L3,2) -> 35.77 | M4: =ROUNDUP(M3,2) -> 65.28 | N4: =ROUNDUP(N3,2) -> 40.65 | O4: =ROUNDUP(O3,2) -> 27.32 | P4: =ROUNDUP(P3,2) -> 11.07 | Q4: =ROUNDUP(Q3,2) -> 30.75 | ... S4: =ROUNDUP(S3,2) -> 0 | T4: =ROUNDUP(SUM(J4:S4)*T8,2) -> 41.43 | U4: =SUM(J4:T4) -> 317.61
G5: 金額 | J5: =J4*J9 -> 32287500 | K5: =K4*K9 -> 36319500 | L5: =L4*L9 -> 37558500 | M5: =M4*M9 -> 68544000 | N5: =N4*N9 -> 42682500 | O5: =O4*O9 -> 28686000 | P5: =P4*P9 -> 11623500 | Q5: =Q4*Q9 -> 32287500 | ... T5: =T4*T9 -> 58002000 | U5: =SUM(J5:T5) -> 347991000
A7: No, | B7: 分類 | D7: 項目 | E7: 種別 | F7: 登録 | G7: 項目数 | H7: STEP数 | I7: 難易度 | J7: SA | K7: UI | L7: SS | M7: PS/PG/PT | N7: IT | O7: ST | P7: OT | Q7: RL | R7: その他 | S7: 調整 | T7: PM | U7: 合計（人日） | V7: 合計（人月） | W7: 金額 | X7: 備考
J8: =サマリ!F9 -> 1 | K8: =サマリ!F10 -> 1 | L8: =サマリ!F11 -> 1 | M8: =サマリ!F12 -> 1 | N8: =サマリ!F13 -> 1 | O8: =サマリ!F14 -> 1 | P8: =サマリ!F15 -> 1 | Q8: =サマリ!F16 -> 1 | R8: =サマリ!F17 -> 1 | S8: =サマリ!F18 -> - | T8: =サマリ!F19 -> 0.15
J9: =サマリ!H9 -> 1050000 | K9: =サマリ!H10 -> 1050000 | L9: =サマリ!H11 -> 1050000 | M9: =サマリ!H12 -> 1050000 | N9: =サマリ!H13 -> 1050000 | O9: =サマリ!H14 -> 1050000 | P9: =サマリ!H15 -> 1050000 | Q9: =サマリ!H16 -> 1050000 | R9: =サマリ!H17 -> 1050000 | S9: =サマリ!H18 -> 1050000 | T9: =サマリ!H19 -> 1400000
A10: =ROW()-9 -> 1 | B10: メニュー | C10: メインメニュー | D10: メニュー | E10: 画面 | I10: 低 | J10: =ROUNDUP(IF($E10="画面",画面係数,IF($E10="帳票",帳票係数,IF($E10="バッチ",バッチ係数,0))) * IF($I10="特高",特高係数,IF($I10="高",高係数,IF($I10="中",中係数,IF($I10="低",低係数,IF($I10="特低",特低係数,0))))) * IF(J$7="SA",要件定義係数,IF(J$7="UI",基本設計係数,IF(J$7="SS",詳細設計係数,IF(J$7="PS/PG/PT",製作係数,IF(J$7="IT",結合テスト係数,IF(J$7="ST",総合テスト係数,IF(J$7="OT",受入支援係数,IF(J$7="RL",移行切替係数,IF(J$7="その他",その他係数,0))))))))) * J$8,1) -> 1.3 | K10: =ROUNDUP(IF($E10="画面",画面係数,IF($E10="帳票",帳票係数,IF($E10="バッチ",バッチ係数,0))) * IF($I10="特高",特高係数,IF($I10="高",高係数,IF($I10="中",中係数,IF($I10="低",低係数,IF($I10="特低",特低係数,0))))) * IF(K$7="SA",要件定義係数,IF(K$7="UI",基本設計係数,IF(K$7="SS",詳細設計係数,IF(K$7="PS/PG/PT",製作係数,IF(K$7="IT",結合テスト係数,IF(K$7="ST",総合テスト係数,IF(K$7="OT",受入支援係数,IF(K$7="RL",移行切替係数,IF(K$7="その他",その他係数,0))))))))) * K$8,1) -> 1.5 | L10: =ROUNDUP(IF($E10="画面",画面係数,IF($E10="帳票",帳票係数,IF($E10="バッチ",バッチ係数,0))) * IF($I10="特高",特高係数,IF($I10="高",高係数,IF($I10="中",中係数,IF($I10="低",低係数,IF($I10="特低",特低係数,0))))) * IF(L$7="SA",要件定義係数,IF(L$7="UI",基本設計係数,IF(L$7="SS",詳細設計係数,IF(L$7="PS/PG/PT",製作係数,IF(L$7="IT",結合テスト係数,IF(L$7="ST",総合テスト係数,IF(L$7="OT",受入支援係数,IF(L$7="RL",移行切替係数,IF(L$7="その他",その他係数,0))))))))) * L$8,1) -> 1.6 | M10: =ROUNDUP(IF($E10="画面",画面係数,IF($E10="帳票",帳票係数,IF($E10="バッチ",バッチ係数,0))) * IF($I10="特高",特高係数,IF($I10="高",高係数,IF($I10="中",中係数,IF($I10="低",低係数,IF($I10="特低",特低係数,0))))) * IF(M$7="SA",要件定義係数,IF(M$7="UI",基本設計係数,IF(M$7="SS",詳細設計係数,IF(M$7="PS/PG/PT",製作係数,IF(M$7="IT",結合テスト係数,IF(M$7="ST",総合テスト係数,IF(M$7="OT",受入支援係数,IF(M$7="RL",移行切替係数,IF(M$7="その他",その他係数,0))))))))) * M$8,1) -> 2.9 | N10: =ROUNDUP(IF($E10="画面",画面係数,IF($E10="帳票",帳票係数,IF($E10="バッチ",バッチ係数,0))) * IF($I10="特高",特高係数,IF($I10="高",高係数,IF($I10="中",中係数,IF($I10="低",低係数,IF($I10="特低",特低係数,0))))) * IF(N$7="SA",要件定義係数,IF(N$7="UI",基本設計係数,IF(N$7="SS",詳細設計係数,IF(N$7="PS/PG/PT",製作係数,IF(N$7="IT",結合テスト係数,IF(N$7="ST",総合テスト係数,IF(N$7="OT",受入支援係数,IF(N$7="RL",移行切替係数,IF(N$7="その他",その他係数,0))))))))) * N$8,1) -> 1.8 | O10: =ROUNDUP(IF($E10="画面",画面係数,IF($E10="帳票",帳票係数,IF($E10="バッチ",バッチ係数,0))) * IF($I10="特高",特高係数,IF($I10="高",高係数,IF($I10="中",中係数,IF($I10="低",低係数,IF($I10="特低",特低係数,0))))) * IF(O$7="SA",要件定義係数,IF(O$7="UI",基本設計係数,IF(O$7="SS",詳細設計係数,IF(O$7="PS/PG/PT",製作係数,IF(O$7="IT",結合テスト係数,IF(O$7="ST",総合テスト係数,IF(O$7="OT",受入支援係数,IF(O$7="RL",移行切替係数,IF(O$7="その他",その他係数,0))))))))) * O$8,1) -> 1.2 | P10: =ROUNDUP(IF($E10="画面",画面係数,IF($E10="帳票",帳票係数,IF($E10="バッチ",バッチ係数,0))) * IF($I10="特高",特高係数,IF($I10="高",高係数,IF($I10="中",中係数,IF($I10="低",低係数,IF($I10="特低",特低係数,0))))) * IF(P$7="SA",要件定義係数,IF(P$7="UI",基本設計係数,IF(P$7="SS",詳細設計係数,IF(P$7="PS/PG/PT",製作係数,IF(P$7="IT",結合テスト係数,IF(P$7="ST",総合テスト係数,IF(P$7="OT",受入支援係数,IF(P$7="RL",移行切替係数,IF(P$7="その他",その他係数,0))))))))) * P$8,1) -> 0.5 | Q10: =ROUNDUP(IF($E10="画面",画面係数,IF($E10="帳票",帳票係数,IF($E10="バッチ",バッチ係数,0))) * IF($I10="特高",特高係数,IF($I10="高",高係数,IF($I10="中",中係数,IF($I10="低",低係数,IF($I10="特低",特低係数,0))))) * IF(Q$7="SA",要件定義係数,IF(Q$7="UI",基本設計係数,IF(Q$7="SS",詳細設計係数,IF(Q$7="PS/PG/PT",製作係数,IF(Q$7="IT",結合テスト係数,IF(Q$7="ST",総合テスト係数,IF(Q$7="OT",受入支援係数,IF(Q$7="RL",移行切替係数,IF(Q$7="その他",その他係数,0))))))))) * Q$8,1) -> 1.3 | R10: =ROUNDUP(IF($E10="画面",画面係数,IF($E10="帳票",帳票係数,IF($E10="バッチ",バッチ係数,0))) * IF($I10="特高",特高係数,IF($I10="高",高係数,IF($I10="中",中係数,IF($I10="低",低係数,IF($I10="特低",特低係数,0))))) * IF(R$7="SA",要件定義係数,IF(R$7="UI",基本設計係数,IF(R$7="SS",詳細設計係数,IF(R$7="PS/PG/PT",製作係数,IF(R$7="IT",結合テスト係数,IF(R$7="ST",総合テスト係数,IF(R$7="OT",受入支援係数,IF(R$7="RL",移行切替係数,IF(R$7="その他",その他係数,0))))))))) * R$8,1) -> 0 | T10: =ROUNDUP(SUM(J10:S10)*T$8,1) -> 1.9 | U10: =SUM(J10:T10) -> 14 | V10: =U10/20 -> 0.7 | W10: =((J10*J$9) + (K10*K$9) + (L10*L$9) + (M10*M$9) + (N10*N$9) + (O10*O$9) + (P10*P$9) + (Q10*Q$9) + (R10*R$9) + (S10*S$9) + (T10*T$9))/20 -> 768250 | X10: Javaに作り直し
A11: =ROW()-9 -> 2 | B11: メニュー | C11: 受注・入出荷メニュー | D11: メニュー | E11: 画面 | I11: 低 | J11: =ROUNDUP(IF($E11="画面",画面係数,IF($E11="帳票",帳票係数,IF($E11="バッチ",バッチ係数,0))) * IF($I11="特高",特高係数,IF($I11="高",高係数,IF($I11="中",中係数,IF($I11="低",低係数,IF($I11="特低",特低係数,0))))) * IF(J$7="SA",要件定義係数,IF(J$7="UI",基本設計係数,IF(J$7="SS",詳細設計係数,IF(J$7="PS/PG/PT",製作係数,IF(J$7="IT",結合テスト係数,IF(J$7="ST",総合テスト係数,IF(J$7="OT",受入支援係数,IF(J$7="RL",移行切替係数,IF(J$7="その他",その他係数,0))))))))) * J$8,1) -> 1.3 | K11: =ROUNDUP(IF($E11="画面",画面係数,IF($E11="帳票",帳票係数,IF($E11="バッチ",バッチ係数,0))) * IF($I11="特高",特高係数,IF($I11="高",高係数,IF($I11="中",中係数,IF($I11="低",低係数,IF($I11="特低",特低係数,0))))) * IF(K$7="SA",要件定義係数,IF(K$7="UI",基本設計係数,IF(K$7="SS",詳細設計係数,IF(K$7="PS/PG/PT",製作係数,IF(K$7="IT",結合テスト係数,IF(K$7="ST",総合テスト係数,IF(K$7="OT",受入支援係数,IF(K$7="RL",移行切替係数,IF(K$7="その他",その他係数,0))))))))) * K$8,1) -> 1.5 | L11: =ROUNDUP(IF($E11="画面",画面係数,IF($E11="帳票",帳票係数,IF($E11="バッチ",バッチ係数,0))) * IF($I11="特高",特高係数,IF($I11="高",高係数,IF($I11="中",中係数,IF($I11="低",低係数,IF($I11="特低",特低係数,0))))) * IF(L$7="SA",要件定義係数,IF(L$7="UI",基本設計係数,IF(L$7="SS",詳細設計係数,IF(L$7="PS/PG/PT",製作係数,IF(L$7="IT",結合テスト係数,IF(L$7="ST",総合テスト係数,IF(L$7="OT",受入支援係数,IF(L$7="RL",移行切替係数,IF(L$7="その他",その他係数,0))))))))) * L$8,1) -> 1.6 | M11: =ROUNDUP(IF($E11="画面",画面係数,IF($E11="帳票",帳票係数,IF($E11="バッチ",バッチ係数,0))) * IF($I11="特高",特高係数,IF($I11="高",高係数,IF($I11="中",中係数,IF($I11="低",低係数,IF($I11="特低",特低係数,0))))) * IF(M$7="SA",要件定義係数,IF(M$7="UI",基本設計係数,IF(M$7="SS",詳細設計係数,IF(M$7="PS/PG/PT",製作係数,IF(M$7="IT",結合テスト係数,IF(M$7="ST",総合テスト係数,IF(M$7="OT",受入支援係数,IF(M$7="RL",移行切替係数,IF(M$7="その他",その他係数,0))))))))) * M$8,1) -> 2.9 | N11: =ROUNDUP(IF($E11="画面",画面係数,IF($E11="帳票",帳票係数,IF($E11="バッチ",バッチ係数,0))) * IF($I11="特高",特高係数,IF($I11="高",高係数,IF($I11="中",中係数,IF($I11="低",低係数,IF($I11="特低",特低係数,0))))) * IF(N$7="SA",要件定義係数,IF(N$7="UI",基本設計係数,IF(N$7="SS",詳細設計係数,IF(N$7="PS/PG/PT",製作係数,IF(N$7="IT",結合テスト係数,IF(N$7="ST",総合テスト係数,IF(N$7="OT",受入支援係数,IF(N$7="RL",移行切替係数,IF(N$7="その他",その他係数,0))))))))) * N$8,1) -> 1.8 | O11: =ROUNDUP(IF($E11="画面",画面係数,IF($E11="帳票",帳票係数,IF($E11="バッチ",バッチ係数,0))) * IF($I11="特高",特高係数,IF($I11="高",高係数,IF($I11="中",中係数,IF($I11="低",低係数,IF($I11="特低",特低係数,0))))) * IF(O$7="SA",要件定義係数,IF(O$7="UI",基本設計係数,IF(O$7="SS",詳細設計係数,IF(O$7="PS/PG/PT",製作係数,IF(O$7="IT",結合テスト係数,IF(O$7="ST",総合テスト係数,IF(O$7="OT",受入支援係数,IF(O$7="RL",移行切替係数,IF(O$7="その他",その他係数,0))))))))) * O$8,1) -> 1.2 | P11: =ROUNDUP(IF($E11="画面",画面係数,IF($E11="帳票",帳票係数,IF($E11="バッチ",バッチ係数,0))) * IF($I11="特高",特高係数,IF($I11="高",高係数,IF($I11="中",中係数,IF($I11="低",低係数,IF($I11="特低",特低係数,0))))) * IF(P$7="SA",要件定義係数,IF(P$7="UI",基本設計係数,IF(P$7="SS",詳細設計係数,IF(P$7="PS/PG/PT",製作係数,IF(P$7="IT",結合テスト係数,IF(P$7="ST",総合テスト係数,IF(P$7="OT",受入支援係数,IF(P$7="RL",移行切替係数,IF(P$7="その他",その他係数,0))))))))) * P$8,1) -> 0.5 | Q11: =ROUNDUP(IF($E11="画面",画面係数,IF($E11="帳票",帳票係数,IF($E11="バッチ",バッチ係数,0))) * IF($I11="特高",特高係数,IF($I11="高",高係数,IF($I11="中",中係数,IF($I11="低",低係数,IF($I11="特低",特低係数,0))))) * IF(Q$7="SA",要件定義係数,IF(Q$7="UI",基本設計係数,IF(Q$7="SS",詳細設計係数,IF(Q$7="PS/PG/PT",製作係数,IF(Q$7="IT",結合テスト係数,IF(Q$7="ST",総合テスト係数,IF(Q$7="OT",受入支援係数,IF(Q$7="RL",移行切替係数,IF(Q$7="その他",その他係数,0))))))))) * Q$8,1) -> 1.3 | R11: =ROUNDUP(IF($E11="画面",画面係数,IF($E11="帳票",帳票係数,IF($E11="バッチ",バッチ係数,0))) * IF($I11="特高",特高係数,IF($I11="高",高係数,IF($I11="中",中係数,IF($I11="低",低係数,IF($I11="特低",特低係数,0))))) * IF(R$7="SA",要件定義係数,IF(R$7="UI",基本設計係数,IF(R$7="SS",詳細設計係数,IF(R$7="PS/PG/PT",製作係数,IF(R$7="IT",結合テスト係数,IF(R$7="ST",総合テスト係数,IF(R$7="OT",受入支援係数,IF(R$7="RL",移行切替係数,IF(R$7="その他",その他係数,0))))))))) * R$8,1) -> 0 | T11: =ROUNDUP(SUM(J11:S11)*T$8,1) -> 1.9 | U11: =SUM(J11:T11) -> 14 | V11: =U11/20 -> 0.7 | W11: =((J11*J$9) + (K11*K$9) + (L11*L$9) + (M11*M$9) + (N11*N$9) + (O11*O$9) + (P11*P$9) + (Q11*Q$9) + (R11*R$9) + (S11*S$9) + (T11*T$9))/20 -> 768250 | X11: Javaに作り直し
A12: =ROW()-9 -> 3 | B12: メニュー | C12: BO荷繰／シフト計画メニュー | D12: メニュー | E12: 画面 | I12: 低 | J12: =ROUNDUP(IF($E12="画面",画面係数,IF($E12="帳票",帳票係数,IF($E12="バッチ",バッチ係数,0))) * IF($I12="特高",特高係数,IF($I12="高",高係数,IF($I12="中",中係数,IF($I12="低",低係数,IF($I12="特低",特低係数,0))))) * IF(J$7="SA",要件定義係数,IF(J$7="UI",基本設計係数,IF(J$7="SS",詳細設計係数,IF(J$7="PS/PG/PT",製作係数,IF(J$7="IT",結合テスト係数,IF(J$7="ST",総合テスト係数,IF(J$7="OT",受入支援係数,IF(J$7="RL",移行切替係数,IF(J$7="その他",その他係数,0))))))))) * J$8,1) -> 1.3 | K12: =ROUNDUP(IF($E12="画面",画面係数,IF($E12="帳票",帳票係数,IF($E12="バッチ",バッチ係数,0))) * IF($I12="特高",特高係数,IF($I12="高",高係数,IF($I12="中",中係数,IF($I12="低",低係数,IF($I12="特低",特低係数,0))))) * IF(K$7="SA",要件定義係数,IF(K$7="UI",基本設計係数,IF(K$7="SS",詳細設計係数,IF(K$7="PS/PG/PT",製作係数,IF(K$7="IT",結合テスト係数,IF(K$7="ST",総合テスト係数,IF(K$7="OT",受入支援係数,IF(K$7="RL",移行切替係数,IF(K$7="その他",その他係数,0))))))))) * K$8,1) -> 1.5 | L12: =ROUNDUP(IF($E12="画面",画面係数,IF($E12="帳票",帳票係数,IF($E12="バッチ",バッチ係数,0))) * IF($I12="特高",特高係数,IF($I12="高",高係数,IF($I12="中",中係数,IF($I12="低",低係数,IF($I12="特低",特低係数,0))))) * IF(L$7="SA",要件定義係数,IF(L$7="UI",基本設計係数,IF(L$7="SS",詳細設計係数,IF(L$7="PS/PG/PT",製作係数,IF(L$7="IT",結合テスト係数,IF(L$7="ST",総合テスト係数,IF(L$7="OT",受入支援係数,IF(L$7="RL",移行切替係数,IF(L$7="その他",その他係数,0))))))))) * L$8,1) -> 1.6 | M12: =ROUNDUP(IF($E12="画面",画面係数,IF($E12="帳票",帳票係数,IF($E12="バッチ",バッチ係数,0))) * IF($I12="特高",特高係数,IF($I12="高",高係数,IF($I12="中",中係数,IF($I12="低",低係数,IF($I12="特低",特低係数,0))))) * IF(M$7="SA",要件定義係数,IF(M$7="UI",基本設計係数,IF(M$7="SS",詳細設計係数,IF(M$7="PS/PG/PT",製作係数,IF(M$7="IT",結合テスト係数,IF(M$7="ST",総合テスト係数,IF(M$7="OT",受入支援係数,IF(M$7="RL",移行切替係数,IF(M$7="その他",その他係数,0))))))))) * M$8,1) -> 2.9 | N12: =ROUNDUP(IF($E12="画面",画面係数,IF($E12="帳票",帳票係数,IF($E12="バッチ",バッチ係数,0))) * IF($I12="特高",特高係数,IF($I12="高",高係数,IF($I12="中",中係数,IF($I12="低",低係数,IF($I12="特低",特低係数,0))))) * IF(N$7="SA",要件定義係数,IF(N$7="UI",基本設計係数,IF(N$7="SS",詳細設計係数,IF(N$7="PS/PG/PT",製作係数,IF(N$7="IT",結合テスト係数,IF(N$7="ST",総合テスト係数,IF(N$7="OT",受入支援係数,IF(N$7="RL",移行切替係数,IF(N$7="その他",その他係数,0))))))))) * N$8,1) -> 1.8 | O12: =ROUNDUP(IF($E12="画面",画面係数,IF($E12="帳票",帳票係数,IF($E12="バッチ",バッチ係数,0))) * IF($I12="特高",特高係数,IF($I12="高",高係数,IF($I12="中",中係数,IF($I12="低",低係数,IF($I12="特低",特低係数,0))))) * IF(O$7="SA",要件定義係数,IF(O$7="UI",基本設計係数,IF(O$7="SS",詳細設計係数,IF(O$7="PS/PG/PT",製作係数,IF(O$7="IT",結合テスト係数,IF(O$7="ST",総合テスト係数,IF(O$7="OT",受入支援係数,IF(O$7="RL",移行切替係数,IF(O$7="その他",その他係数,0))))))))) * O$8,1) -> 1.2 | P12: =ROUNDUP(IF($E12="画面",画面係数,IF($E12="帳票",帳票係数,IF($E12="バッチ",バッチ係数,0))) * IF($I12="特高",特高係数,IF($I12="高",高係数,IF($I12="中",中係数,IF($I12="低",低係数,IF($I12="特低",特低係数,0))))) * IF(P$7="SA",要件定義係数,IF(P$7="UI",基本設計係数,IF(P$7="SS",詳細設計係数,IF(P$7="PS/PG/PT",製作係数,IF(P$7="IT",結合テスト係数,IF(P$7="ST",総合テスト係数,IF(P$7="OT",受入支援係数,IF(P$7="RL",移行切替係数,IF(P$7="その他",その他係数,0))))))))) * P$8,1) -> 0.5 | Q12: =ROUNDUP(IF($E12="画面",画面係数,IF($E12="帳票",帳票係数,IF($E12="バッチ",バッチ係数,0))) * IF($I12="特高",特高係数,IF($I12="高",高係数,IF($I12="中",中係数,IF($I12="低",低係数,IF($I12="特低",特低係数,0))))) * IF(Q$7="SA",要件定義係数,IF(Q$7="UI",基本設計係数,IF(Q$7="SS",詳細設計係数,IF(Q$7="PS/PG/PT",製作係数,IF(Q$7="IT",結合テスト係数,IF(Q$7="ST",総合テスト係数,IF(Q$7="OT",受入支援係数,IF(Q$7="RL",移行切替係数,IF(Q$7="その他",その他係数,0))))))))) * Q$8,1) -> 1.3 | R12: =ROUNDUP(IF($E12="画面",画面係数,IF($E12="帳票",帳票係数,IF($E12="バッチ",バッチ係数,0))) * IF($I12="特高",特高係数,IF($I12="高",高係数,IF($I12="中",中係数,IF($I12="低",低係数,IF($I12="特低",特低係数,0))))) * IF(R$7="SA",要件定義係数,IF(R$7="UI",基本設計係数,IF(R$7="SS",詳細設計係数,IF(R$7="PS/PG/PT",製作係数,IF(R$7="IT",結合テスト係数,IF(R$7="ST",総合テスト係数,IF(R$7="OT",受入支援係数,IF(R$7="RL",移行切替係数,IF(R$7="その他",その他係数,0))))))))) * R$8,1) -> 0 | T12: =ROUNDUP(SUM(J12:S12)*T$8,1) -> 1.9 | U12: =SUM(J12:T12) -> 14 | V12: =U12/20 -> 0.7 | W12: =((J12*J$9) + (K12*K$9) + (L12*L$9) + (M12*M$9) + (N12*N$9) + (O12*O$9) + (P12*P$9) + (Q12*Q$9) + (R12*R$9) + (S12*S$9) + (T12*T$9))/20 -> 768250 | X12: Javaに作り直し
A13: =ROW()-9 -> 4 | B13: メニュー | C13: 生産計画・発注メニュー | D13: メニュー | E13: 画面 | I13: 低 | J13: =ROUNDUP(IF($E13="画面",画面係数,IF($E13="帳票",帳票係数,IF($E13="バッチ",バッチ係数,0))) * IF($I13="特高",特高係数,IF($I13="高",高係数,IF($I13="中",中係数,IF($I13="低",低係数,IF($I13="特低",特低係数,0))))) * IF(J$7="SA",要件定義係数,IF(J$7="UI",基本設計係数,IF(J$7="SS",詳細設計係数,IF(J$7="PS/PG/PT",製作係数,IF(J$7="IT",結合テスト係数,IF(J$7="ST",総合テスト係数,IF(J$7="OT",受入支援係数,IF(J$7="RL",移行切替係数,IF(J$7="その他",その他係数,0))))))))) * J$8,1) -> 1.3 | K13: =ROUNDUP(IF($E13="画面",画面係数,IF($E13="帳票",帳票係数,IF($E13="バッチ",バッチ係数,0))) * IF($I13="特高",特高係数,IF($I13="高",高係数,IF($I13="中",中係数,IF($I13="低",低係数,IF($I13="特低",特低係数,0))))) * IF(K$7="SA",要件定義係数,IF(K$7="UI",基本設計係数,IF(K$7="SS",詳細設計係数,IF(K$7="PS/PG/PT",製作係数,IF(K$7="IT",結合テスト係数,IF(K$7="ST",総合テスト係数,IF(K$7="OT",受入支援係数,IF(K$7="RL",移行切替係数,IF(K$7="その他",その他係数,0))))))))) * K$8,1) -> 1.5 | L13: =ROUNDUP(IF($E13="画面",画面係数,IF($E13="帳票",帳票係数,IF($E13="バッチ",バッチ係数,0))) * IF($I13="特高",特高係数,IF($I13="高",高係数,IF($I13="中",中係数,IF($I13="低",低係数,IF($I13="特低",特低係数,0))))) * IF(L$7="SA",要件定義係数,IF(L$7="UI",基本設計係数,IF(L$7="SS",詳細設計係数,IF(L$7="PS/PG/PT",製作係数,IF(L$7="IT",結合テスト係数,IF(L$7="ST",総合テスト係数,IF(L$7="OT",受入支援係数,IF(L$7="RL",移行切替係数,IF(L$7="その他",その他係数,0))))))))) * L$8,1) -> 1.6 | M13: =ROUNDUP(IF($E13="画面",画面係数,IF($E13="帳票",帳票係数,IF($E13="バッチ",バッチ係数,0))) * IF($I13="特高",特高係数,IF($I13="高",高係数,IF($I13="中",中係数,IF($I13="低",低係数,IF($I13="特低",特低係数,0))))) * IF(M$7="SA",要件定義係数,IF(M$7="UI",基本設計係数,IF(M$7="SS",詳細設計係数,IF(M$7="PS/PG/PT",製作係数,IF(M$7="IT",結合テスト係数,IF(M$7="ST",総合テスト係数,IF(M$7="OT",受入支援係数,IF(M$7="RL",移行切替係数,IF(M$7="その他",その他係数,0))))))))) * M$8,1) -> 2.9 | N13: =ROUNDUP(IF($E13="画面",画面係数,IF($E13="帳票",帳票係数,IF($E13="バッチ",バッチ係数,0))) * IF($I13="特高",特高係数,IF($I13="高",高係数,IF($I13="中",中係数,IF($I13="低",低係数,IF($I13="特低",特低係数,0))))) * IF(N$7="SA",要件定義係数,IF(N$7="UI",基本設計係数,IF(N$7="SS",詳細設計係数,IF(N$7="PS/PG/PT",製作係数,IF(N$7="IT",結合テスト係数,IF(N$7="ST",総合テスト係数,IF(N$7="OT",受入支援係数,IF(N$7="RL",移行切替係数,IF(N$7="その他",その他係数,0))))))))) * N$8,1) -> 1.8 | O13: =ROUNDUP(IF($E13="画面",画面係数,IF($E13="帳票",帳票係数,IF($E13="バッチ",バッチ係数,0))) * IF($I13="特高",特高係数,IF($I13="高",高係数,IF($I13="中",中係数,IF($I13="低",低係数,IF($I13="特低",特低係数,0))))) * IF(O$7="SA",要件定義係数,IF(O$7="UI",基本設計係数,IF(O$7="SS",詳細設計係数,IF(O$7="PS/PG/PT",製作係数,IF(O$7="IT",結合テスト係数,IF(O$7="ST",総合テスト係数,IF(O$7="OT",受入支援係数,IF(O$7="RL",移行切替係数,IF(O$7="その他",その他係数,0))))))))) * O$8,1) -> 1.2 | P13: =ROUNDUP(IF($E13="画面",画面係数,IF($E13="帳票",帳票係数,IF($E13="バッチ",バッチ係数,0))) * IF($I13="特高",特高係数,IF($I13="高",高係数,IF($I13="中",中係数,IF($I13="低",低係数,IF($I13="特低",特低係数,0))))) * IF(P$7="SA",要件定義係数,IF(P$7="UI",基本設計係数,IF(P$7="SS",詳細設計係数,IF(P$7="PS/PG/PT",製作係数,IF(P$7="IT",結合テスト係数,IF(P$7="ST",総合テスト係数,IF(P$7="OT",受入支援係数,IF(P$7="RL",移行切替係数,IF(P$7="その他",その他係数,0))))))))) * P$8,1) -> 0.5 | Q13: =ROUNDUP(IF($E13="画面",画面係数,IF($E13="帳票",帳票係数,IF($E13="バッチ",バッチ係数,0))) * IF($I13="特高",特高係数,IF($I13="高",高係数,IF($I13="中",中係数,IF($I13="低",低係数,IF($I13="特低",特低係数,0))))) * IF(Q$7="SA",要件定義係数,IF(Q$7="UI",基本設計係数,IF(Q$7="SS",詳細設計係数,IF(Q$7="PS/PG/PT",製作係数,IF(Q$7="IT",結合テスト係数,IF(Q$7="ST",総合テスト係数,IF(Q$7="OT",受入支援係数,IF(Q$7="RL",移行切替係数,IF(Q$7="その他",その他係数,0))))))))) * Q$8,1) -> 1.3 | R13: =ROUNDUP(IF($E13="画面",画面係数,IF($E13="帳票",帳票係数,IF($E13="バッチ",バッチ係数,0))) * IF($I13="特高",特高係数,IF($I13="高",高係数,IF($I13="中",中係数,IF($I13="低",低係数,IF($I13="特低",特低係数,0))))) * IF(R$7="SA",要件定義係数,IF(R$7="UI",基本設計係数,IF(R$7="SS",詳細設計係数,IF(R$7="PS/PG/PT",製作係数,IF(R$7="IT",結合テスト係数,IF(R$7="ST",総合テスト係数,IF(R$7="OT",受入支援係数,IF(R$7="RL",移行切替係数,IF(R$7="その他",その他係数,0))))))))) * R$8,1) -> 0 | T13: =ROUNDUP(SUM(J13:S13)*T$8,1) -> 1.9 | U13: =SUM(J13:T13) -> 14 | V13: =U13/20 -> 0.7 | W13: =((J13*J$9) + (K13*K$9) + (L13*L$9) + (M13*M$9) + (N13*N$9) + (O13*O$9) + (P13*P$9) + (Q13*Q$9) + (R13*R$9) + (S13*S$9) + (T13*T$9))/20 -> 768250 | X13: Javaに作り直し
A14: =ROW()-9 -> 5 | B14: メニュー | C14: 商品管理メニュー | D14: メニュー | E14: 画面 | I14: 低 | J14: =ROUNDUP(IF($E14="画面",画面係数,IF($E14="帳票",帳票係数,IF($E14="バッチ",バッチ係数,0))) * IF($I14="特高",特高係数,IF($I14="高",高係数,IF($I14="中",中係数,IF($I14="低",低係数,IF($I14="特低",特低係数,0))))) * IF(J$7="SA",要件定義係数,IF(J$7="UI",基本設計係数,IF(J$7="SS",詳細設計係数,IF(J$7="PS/PG/PT",製作係数,IF(J$7="IT",結合テスト係数,IF(J$7="ST",総合テスト係数,IF(J$7="OT",受入支援係数,IF(J$7="RL",移行切替係数,IF(J$7="その他",その他係数,0))))))))) * J$8,1) -> 1.3 | K14: =ROUNDUP(IF($E14="画面",画面係数,IF($E14="帳票",帳票係数,IF($E14="バッチ",バッチ係数,0))) * IF($I14="特高",特高係数,IF($I14="高",高係数,IF($I14="中",中係数,IF($I14="低",低係数,IF($I14="特低",特低係数,0))))) * IF(K$7="SA",要件定義係数,IF(K$7="UI",基本設計係数,IF(K$7="SS",詳細設計係数,IF(K$7="PS/PG/PT",製作係数,IF(K$7="IT",結合テスト係数,IF(K$7="ST",総合テスト係数,IF(K$7="OT",受入支援係数,IF(K$7="RL",移行切替係数,IF(K$7="その他",その他係数,0))))))))) * K$8,1) -> 1.5 | L14: =ROUNDUP(IF($E14="画面",画面係数,IF($E14="帳票",帳票係数,IF($E14="バッチ",バッチ係数,0))) * IF($I14="特高",特高係数,IF($I14="高",高係数,IF($I14="中",中係数,IF($I14="低",低係数,IF($I14="特低",特低係数,0))))) * IF(L$7="SA",要件定義係数,IF(L$7="UI",基本設計係数,IF(L$7="SS",詳細設計係数,IF(L$7="PS/PG/PT",製作係数,IF(L$7="IT",結合テスト係数,IF(L$7="ST",総合テスト係数,IF(L$7="OT",受入支援係数,IF(L$7="RL",移行切替係数,IF(L$7="その他",その他係数,0))))))))) * L$8,1) -> 1.6 | M14: =ROUNDUP(IF($E14="画面",画面係数,IF($E14="帳票",帳票係数,IF($E14="バッチ",バッチ係数,0))) * IF($I14="特高",特高係数,IF($I14="高",高係数,IF($I14="中",中係数,IF($I14="低",低係数,IF($I14="特低",特低係数,0))))) * IF(M$7="SA",要件定義係数,IF(M$7="UI",基本設計係数,IF(M$7="SS",詳細設計係数,IF(M$7="PS/PG/PT",製作係数,IF(M$7="IT",結合テスト係数,IF(M$7="ST",総合テスト係数,IF(M$7="OT",受入支援係数,IF(M$7="RL",移行切替係数,IF(M$7="その他",その他係数,0))))))))) * M$8,1) -> 2.9 | N14: =ROUNDUP(IF($E14="画面",画面係数,IF($E14="帳票",帳票係数,IF($E14="バッチ",バッチ係数,0))) * IF($I14="特高",特高係数,IF($I14="高",高係数,IF($I14="中",中係数,IF($I14="低",低係数,IF($I14="特低",特低係数,0))))) * IF(N$7="SA",要件定義係数,IF(N$7="UI",基本設計係数,IF(N$7="SS",詳細設計係数,IF(N$7="PS/PG/PT",製作係数,IF(N$7="IT",結合テスト係数,IF(N$7="ST",総合テスト係数,IF(N$7="OT",受入支援係数,IF(N$7="RL",移行切替係数,IF(N$7="その他",その他係数,0))))))))) * N$8,1) -> 1.8 | O14: =ROUNDUP(IF($E14="画面",画面係数,IF($E14="帳票",帳票係数,IF($E14="バッチ",バッチ係数,0))) * IF($I14="特高",特高係数,IF($I14="高",高係数,IF($I14="中",中係数,IF($I14="低",低係数,IF($I14="特低",特低係数,0))))) * IF(O$7="SA",要件定義係数,IF(O$7="UI",基本設計係数,IF(O$7="SS",詳細設計係数,IF(O$7="PS/PG/PT",製作係数,IF(O$7="IT",結合テスト係数,IF(O$7="ST",総合テスト係数,IF(O$7="OT",受入支援係数,IF(O$7="RL",移行切替係数,IF(O$7="その他",その他係数,0))))))))) * O$8,1) -> 1.2 | P14: =ROUNDUP(IF($E14="画面",画面係数,IF($E14="帳票",帳票係数,IF($E14="バッチ",バッチ係数,0))) * IF($I14="特高",特高係数,IF($I14="高",高係数,IF($I14="中",中係数,IF($I14="低",低係数,IF($I14="特低",特低係数,0))))) * IF(P$7="SA",要件定義係数,IF(P$7="UI",基本設計係数,IF(P$7="SS",詳細設計係数,IF(P$7="PS/PG/PT",製作係数,IF(P$7="IT",結合テスト係数,IF(P$7="ST",総合テスト係数,IF(P$7="OT",受入支援係数,IF(P$7="RL",移行切替係数,IF(P$7="その他",その他係数,0))))))))) * P$8,1) -> 0.5 | Q14: =ROUNDUP(IF($E14="画面",画面係数,IF($E14="帳票",帳票係数,IF($E14="バッチ",バッチ係数,0))) * IF($I14="特高",特高係数,IF($I14="高",高係数,IF($I14="中",中係数,IF($I14="低",低係数,IF($I14="特低",特低係数,0))))) * IF(Q$7="SA",要件定義係数,IF(Q$7="UI",基本設計係数,IF(Q$7="SS",詳細設計係数,IF(Q$7="PS/PG/PT",製作係数,IF(Q$7="IT",結合テスト係数,IF(Q$7="ST",総合テスト係数,IF(Q$7="OT",受入支援係数,IF(Q$7="RL",移行切替係数,IF(Q$7="その他",その他係数,0))))))))) * Q$8,1) -> 1.3 | R14: =ROUNDUP(IF($E14="画面",画面係数,IF($E14="帳票",帳票係数,IF($E14="バッチ",バッチ係数,0))) * IF($I14="特高",特高係数,IF($I14="高",高係数,IF($I14="中",中係数,IF($I14="低",低係数,IF($I14="特低",特低係数,0))))) * IF(R$7="SA",要件定義係数,IF(R$7="UI",基本設計係数,IF(R$7="SS",詳細設計係数,IF(R$7="PS/PG/PT",製作係数,IF(R$7="IT",結合テスト係数,IF(R$7="ST",総合テスト係数,IF(R$7="OT",受入支援係数,IF(R$7="RL",移行切替係数,IF(R$7="その他",その他係数,0))))))))) * R$8,1) -> 0 | T14: =ROUNDUP(SUM(J14:S14)*T$8,1) -> 1.9 | U14: =SUM(J14:T14) -> 14 | V14: =U14/20 -> 0.7 | W14: =((J14*J$9) + (K14*K$9) + (L14*L$9) + (M14*M$9) + (N14*N$9) + (O14*O$9) + (P14*P$9) + (Q14*Q$9) + (R14*R$9) + (S14*S$9) + (T14*T$9))/20 -> 768250 | X14: Javaに作り直し
A15: =ROW()-9 -> 6 | B15: メニュー | C15: 品質管理メニュー | D15: メニュー | E15: 画面 | I15: 低 | J15: =ROUNDUP(IF($E15="画面",画面係数,IF($E15="帳票",帳票係数,IF($E15="バッチ",バッチ係数,0))) * IF($I15="特高",特高係数,IF($I15="高",高係数,IF($I15="中",中係数,IF($I15="低",低係数,IF($I15="特低",特低係数,0))))) * IF(J$7="SA",要件定義係数,IF(J$7="UI",基本設計係数,IF(J$7="SS",詳細設計係数,IF(J$7="PS/PG/PT",製作係数,IF(J$7="IT",結合テスト係数,IF(J$7="ST",総合テスト係数,IF(J$7="OT",受入支援係数,IF(J$7="RL",移行切替係数,IF(J$7="その他",その他係数,0))))))))) * J$8,1) -> 1.3 | K15: =ROUNDUP(IF($E15="画面",画面係数,IF($E15="帳票",帳票係数,IF($E15="バッチ",バッチ係数,0))) * IF($I15="特高",特高係数,IF($I15="高",高係数,IF($I15="中",中係数,IF($I15="低",低係数,IF($I15="特低",特低係数,0))))) * IF(K$7="SA",要件定義係数,IF(K$7="UI",基本設計係数,IF(K$7="SS",詳細設計係数,IF(K$7="PS/PG/PT",製作係数,IF(K$7="IT",結合テスト係数,IF(K$7="ST",総合テスト係数,IF(K$7="OT",受入支援係数,IF(K$7="RL",移行切替係数,IF(K$7="その他",その他係数,0))))))))) * K$8,1) -> 1.5 | L15: =ROUNDUP(IF($E15="画面",画面係数,IF($E15="帳票",帳票係数,IF($E15="バッチ",バッチ係数,0))) * IF($I15="特高",特高係数,IF($I15="高",高係数,IF($I15="中",中係数,IF($I15="低",低係数,IF($I15="特低",特低係数,0))))) * IF(L$7="SA",要件定義係数,IF(L$7="UI",基本設計係数,IF(L$7="SS",詳細設計係数,IF(L$7="PS/PG/PT",製作係数,IF(L$7="IT",結合テスト係数,IF(L$7="ST",総合テスト係数,IF(L$7="OT",受入支援係数,IF(L$7="RL",移行切替係数,IF(L$7="その他",その他係数,0))))))))) * L$8,1) -> 1.6 | M15: =ROUNDUP(IF($E15="画面",画面係数,IF($E15="帳票",帳票係数,IF($E15="バッチ",バッチ係数,0))) * IF($I15="特高",特高係数,IF($I15="高",高係数,IF($I15="中",中係数,IF($I15="低",低係数,IF($I15="特低",特低係数,0))))) * IF(M$7="SA",要件定義係数,IF(M$7="UI",基本設計係数,IF(M$7="SS",詳細設計係数,IF(M$7="PS/PG/PT",製作係数,IF(M$7="IT",結合テスト係数,IF(M$7="ST",総合テスト係数,IF(M$7="OT",受入支援係数,IF(M$7="RL",移行切替係数,IF(M$7="その他",その他係数,0))))))))) * M$8,1) -> 2.9 | N15: =ROUNDUP(IF($E15="画面",画面係数,IF($E15="帳票",帳票係数,IF($E15="バッチ",バッチ係数,0))) * IF($I15="特高",特高係数,IF($I15="高",高係数,IF($I15="中",中係数,IF($I15="低",低係数,IF($I15="特低",特低係数,0))))) * IF(N$7="SA",要件定義係数,IF(N$7="UI",基本設計係数,IF(N$7="SS",詳細設計係数,IF(N$7="PS/PG/PT",製作係数,IF(N$7="IT",結合テスト係数,IF(N$7="ST",総合テスト係数,IF(N$7="OT",受入支援係数,IF(N$7="RL",移行切替係数,IF(N$7="その他",その他係数,0))))))))) * N$8,1) -> 1.8 | O15: =ROUNDUP(IF($E15="画面",画面係数,IF($E15="帳票",帳票係数,IF($E15="バッチ",バッチ係数,0))) * IF($I15="特高",特高係数,IF($I15="高",高係数,IF($I15="中",中係数,IF($I15="低",低係数,IF($I15="特低",特低係数,0))))) * IF(O$7="SA",要件定義係数,IF(O$7="UI",基本設計係数,IF(O$7="SS",詳細設計係数,IF(O$7="PS/PG/PT",製作係数,IF(O$7="IT",結合テスト係数,IF(O$7="ST",総合テスト係数,IF(O$7="OT",受入支援係数,IF(O$7="RL",移行切替係数,IF(O$7="その他",その他係数,0))))))))) * O$8,1) -> 1.2 | P15: =ROUNDUP(IF($E15="画面",画面係数,IF($E15="帳票",帳票係数,IF($E15="バッチ",バッチ係数,0))) * IF($I15="特高",特高係数,IF($I15="高",高係数,IF($I15="中",中係数,IF($I15="低",低係数,IF($I15="特低",特低係数,0))))) * IF(P$7="SA",要件定義係数,IF(P$7="UI",基本設計係数,IF(P$7="SS",詳細設計係数,IF(P$7="PS/PG/PT",製作係数,IF(P$7="IT",結合テスト係数,IF(P$7="ST",総合テスト係数,IF(P$7="OT",受入支援係数,IF(P$7="RL",移行切替係数,IF(P$7="その他",その他係数,0))))))))) * P$8,1) -> 0.5 | Q15: =ROUNDUP(IF($E15="画面",画面係数,IF($E15="帳票",帳票係数,IF($E15="バッチ",バッチ係数,0))) * IF($I15="特高",特高係数,IF($I15="高",高係数,IF($I15="中",中係数,IF($I15="低",低係数,IF($I15="特低",特低係数,0))))) * IF(Q$7="SA",要件定義係数,IF(Q$7="UI",基本設計係数,IF(Q$7="SS",詳細設計係数,IF(Q$7="PS/PG/PT",製作係数,IF(Q$7="IT",結合テスト係数,IF(Q$7="ST",総合テスト係数,IF(Q$7="OT",受入支援係数,IF(Q$7="RL",移行切替係数,IF(Q$7="その他",その他係数,0))))))))) * Q$8,1) -> 1.3 | R15: =ROUNDUP(IF($E15="画面",画面係数,IF($E15="帳票",帳票係数,IF($E15="バッチ",バッチ係数,0))) * IF($I15="特高",特高係数,IF($I15="高",高係数,IF($I15="中",中係数,IF($I15="低",低係数,IF($I15="特低",特低係数,0))))) * IF(R$7="SA",要件定義係数,IF(R$7="UI",基本設計係数,IF(R$7="SS",詳細設計係数,IF(R$7="PS/PG/PT",製作係数,IF(R$7="IT",結合テスト係数,IF(R$7="ST",総合テスト係数,IF(R$7="OT",受入支援係数,IF(R$7="RL",移行切替係数,IF(R$7="その他",その他係数,0))))))))) * R$8,1) -> 0 | T15: =ROUNDUP(SUM(J15:S15)*T$8,1) -> 1.9 | U15: =SUM(J15:T15) -> 14 | V15: =U15/20 -> 0.7 | W15: =((J15*J$9) + (K15*K$9) + (L15*L$9) + (M15*M$9) + (N15*N$9) + (O15*O$9) + (P15*P$9) + (Q15*Q$9) + (R15*R$9) + (S15*S$9) + (T15*T$9))/20 -> 768250 | X15: Javaに作り直し
A16: =ROW()-9 -> 7 | B16: メニュー | C16: マスタデータ保守メニュー | D16: メニュー | E16: 画面 | I16: 低 | J16: =ROUNDUP(IF($E16="画面",画面係数,IF($E16="帳票",帳票係数,IF($E16="バッチ",バッチ係数,0))) * IF($I16="特高",特高係数,IF($I16="高",高係数,IF($I16="中",中係数,IF($I16="低",低係数,IF($I16="特低",特低係数,0))))) * IF(J$7="SA",要件定義係数,IF(J$7="UI",基本設計係数,IF(J$7="SS",詳細設計係数,IF(J$7="PS/PG/PT",製作係数,IF(J$7="IT",結合テスト係数,IF(J$7="ST",総合テスト係数,IF(J$7="OT",受入支援係数,IF(J$7="RL",移行切替係数,IF(J$7="その他",その他係数,0))))))))) * J$8,1) -> 1.3 | K16: =ROUNDUP(IF($E16="画面",画面係数,IF($E16="帳票",帳票係数,IF($E16="バッチ",バッチ係数,0))) * IF($I16="特高",特高係数,IF($I16="高",高係数,IF($I16="中",中係数,IF($I16="低",低係数,IF($I16="特低",特低係数,0))))) * IF(K$7="SA",要件定義係数,IF(K$7="UI",基本設計係数,IF(K$7="SS",詳細設計係数,IF(K$7="PS/PG/PT",製作係数,IF(K$7="IT",結合テスト係数,IF(K$7="ST",総合テスト係数,IF(K$7="OT",受入支援係数,IF(K$7="RL",移行切替係数,IF(K$7="その他",その他係数,0))))))))) * K$8,1) -> 1.5 | L16: =ROUNDUP(IF($E16="画面",画面係数,IF($E16="帳票",帳票係数,IF($E16="バッチ",バッチ係数,0))) * IF($I16="特高",特高係数,IF($I16="高",高係数,IF($I16="中",中係数,IF($I16="低",低係数,IF($I16="特低",特低係数,0))))) * IF(L$7="SA",要件定義係数,IF(L$7="UI",基本設計係数,IF(L$7="SS",詳細設計係数,IF(L$7="PS/PG/PT",製作係数,IF(L$7="IT",結合テスト係数,IF(L$7="ST",総合テスト係数,IF(L$7="OT",受入支援係数,IF(L$7="RL",移行切替係数,IF(L$7="その他",その他係数,0))))))))) * L$8,1) -> 1.6 | M16: =ROUNDUP(IF($E16="画面",画面係数,IF($E16="帳票",帳票係数,IF($E16="バッチ",バッチ係数,0))) * IF($I16="特高",特高係数,IF($I16="高",高係数,IF($I16="中",中係数,IF($I16="低",低係数,IF($I16="特低",特低係数,0))))) * IF(M$7="SA",要件定義係数,IF(M$7="UI",基本設計係数,IF(M$7="SS",詳細設計係数,IF(M$7="PS/PG/PT",製作係数,IF(M$7="IT",結合テスト係数,IF(M$7="ST",総合テスト係数,IF(M$7="OT",受入支援係数,IF(M$7="RL",移行切替係数,IF(M$7="その他",その他係数,0))))))))) * M$8,1) -> 2.9 | N16: =ROUNDUP(IF($E16="画面",画面係数,IF($E16="帳票",帳票係数,IF($E16="バッチ",バッチ係数,0))) * IF($I16="特高",特高係数,IF($I16="高",高係数,IF($I16="中",中係数,IF($I16="低",低係数,IF($I16="特低",特低係数,0))))) * IF(N$7="SA",要件定義係数,IF(N$7="UI",基本設計係数,IF(N$7="SS",詳細設計係数,IF(N$7="PS/PG/PT",製作係数,IF(N$7="IT",結合テスト係数,IF(N$7="ST",総合テスト係数,IF(N$7="OT",受入支援係数,IF(N$7="RL",移行切替係数,IF(N$7="その他",その他係数,0))))))))) * N$8,1) -> 1.8 | O16: =ROUNDUP(IF($E16="画面",画面係数,IF($E16="帳票",帳票係数,IF($E16="バッチ",バッチ係数,0))) * IF($I16="特高",特高係数,IF($I16="高",高係数,IF($I16="中",中係数,IF($I16="低",低係数,IF($I16="特低",特低係数,0))))) * IF(O$7="SA",要件定義係数,IF(O$7="UI",基本設計係数,IF(O$7="SS",詳細設計係数,IF(O$7="PS/PG/PT",製作係数,IF(O$7="IT",結合テスト係数,IF(O$7="ST",総合テスト係数,IF(O$7="OT",受入支援係数,IF(O$7="RL",移行切替係数,IF(O$7="その他",その他係数,0))))))))) * O$8,1) -> 1.2 | P16: =ROUNDUP(IF($E16="画面",画面係数,IF($E16="帳票",帳票係数,IF($E16="バッチ",バッチ係数,0))) * IF($I16="特高",特高係数,IF($I16="高",高係数,IF($I16="中",中係数,IF($I16="低",低係数,IF($I16="特低",特低係数,0))))) * IF(P$7="SA",要件定義係数,IF(P$7="UI",基本設計係数,IF(P$7="SS",詳細設計係数,IF(P$7="PS/PG/PT",製作係数,IF(P$7="IT",結合テスト係数,IF(P$7="ST",総合テスト係数,IF(P$7="OT",受入支援係数,IF(P$7="RL",移行切替係数,IF(P$7="その他",その他係数,0))))))))) * P$8,1) -> 0.5 | Q16: =ROUNDUP(IF($E16="画面",画面係数,IF($E16="帳票",帳票係数,IF($E16="バッチ",バッチ係数,0))) * IF($I16="特高",特高係数,IF($I16="高",高係数,IF($I16="中",中係数,IF($I16="低",低係数,IF($I16="特低",特低係数,0))))) * IF(Q$7="SA",要件定義係数,IF(Q$7="UI",基本設計係数,IF(Q$7="SS",詳細設計係数,IF(Q$7="PS/PG/PT",製作係数,IF(Q$7="IT",結合テスト係数,IF(Q$7="ST",総合テスト係数,IF(Q$7="OT",受入支援係数,IF(Q$7="RL",移行切替係数,IF(Q$7="その他",その他係数,0))))))))) * Q$8,1) -> 1.3 | R16: =ROUNDUP(IF($E16="画面",画面係数,IF($E16="帳票",帳票係数,IF($E16="バッチ",バッチ係数,0))) * IF($I16="特高",特高係数,IF($I16="高",高係数,IF($I16="中",中係数,IF($I16="低",低係数,IF($I16="特低",特低係数,0))))) * IF(R$7="SA",要件定義係数,IF(R$7="UI",基本設計係数,IF(R$7="SS",詳細設計係数,IF(R$7="PS/PG/PT",製作係数,IF(R$7="IT",結合テスト係数,IF(R$7="ST",総合テスト係数,IF(R$7="OT",受入支援係数,IF(R$7="RL",移行切替係数,IF(R$7="その他",その他係数,0))))))))) * R$8,1) -> 0 | T16: =ROUNDUP(SUM(J16:S16)*T$8,1) -> 1.9 | U16: =SUM(J16:T16) -> 14 | V16: =U16/20 -> 0.7 | W16: =((J16*J$9) + (K16*K$9) + (L16*L$9) + (M16*M$9) + (N16*N$9) + (O16*O$9) + (P16*P$9) + (Q16*Q$9) + (R16*R$9) + (S16*S$9) + (T16*T$9))/20 -> 768250 | X16: Javaに作り直し
A17: =ROW()-9 -> 8 | B17: メニュー | C17: 検索／管理資料メニュー | D17: メニュー | E17: 画面 | I17: 低 | J17: =ROUNDUP(IF($E17="画面",画面係数,IF($E17="帳票",帳票係数,IF($E17="バッチ",バッチ係数,0))) * IF($I17="特高",特高係数,IF($I17="高",高係数,IF($I17="中",中係数,IF($I17="低",低係数,IF($I17="特低",特低係数,0))))) * IF(J$7="SA",要件定義係数,IF(J$7="UI",基本設計係数,IF(J$7="SS",詳細設計係数,IF(J$7="PS/PG/PT",製作係数,IF(J$7="IT",結合テスト係数,IF(J$7="ST",総合テスト係数,IF(J$7="OT",受入支援係数,IF(J$7="RL",移行切替係数,IF(J$7="その他",その他係数,0))))))))) * J$8,1) -> 1.3 | K17: =ROUNDUP(IF($E17="画面",画面係数,IF($E17="帳票",帳票係数,IF($E17="バッチ",バッチ係数,0))) * IF($I17="特高",特高係数,IF($I17="高",高係数,IF($I17="中",中係数,IF($I17="低",低係数,IF($I17="特低",特低係数,0))))) * IF(K$7="SA",要件定義係数,IF(K$7="UI",基本設計係数,IF(K$7="SS",詳細設計係数,IF(K$7="PS/PG/PT",製作係数,IF(K$7="IT",結合テスト係数,IF(K$7="ST",総合テスト係数,IF(K$7="OT",受入支援係数,IF(K$7="RL",移行切替係数,IF(K$7="その他",その他係数,0))))))))) * K$8,1) -> 1.5 | L17: =ROUNDUP(IF($E17="画面",画面係数,IF($E17="帳票",帳票係数,IF($E17="バッチ",バッチ係数,0))) * IF($I17="特高",特高係数,IF($I17="高",高係数,IF($I17="中",中係数,IF($I17="低",低係数,IF($I17="特低",特低係数,0))))) * IF(L$7="SA",要件定義係数,IF(L$7="UI",基本設計係数,IF(L$7="SS",詳細設計係数,IF(L$7="PS/PG/PT",製作係数,IF(L$7="IT",結合テスト係数,IF(L$7="ST",総合テスト係数,IF(L$7="OT",受入支援係数,IF(L$7="RL",移行切替係数,IF(L$7="その他",その他係数,0))))))))) * L$8,1) -> 1.6 | M17: =ROUNDUP(IF($E17="画面",画面係数,IF($E17="帳票",帳票係数,IF($E17="バッチ",バッチ係数,0))) * IF($I17="特高",特高係数,IF($I17="高",高係数,IF($I17="中",中係数,IF($I17="低",低係数,IF($I17="特低",特低係数,0))))) * IF(M$7="SA",要件定義係数,IF(M$7="UI",基本設計係数,IF(M$7="SS",詳細設計係数,IF(M$7="PS/PG/PT",製作係数,IF(M$7="IT",結合テスト係数,IF(M$7="ST",総合テスト係数,IF(M$7="OT",受入支援係数,IF(M$7="RL",移行切替係数,IF(M$7="その他",その他係数,0))))))))) * M$8,1) -> 2.9 | N17: =ROUNDUP(IF($E17="画面",画面係数,IF($E17="帳票",帳票係数,IF($E17="バッチ",バッチ係数,0))) * IF($I17="特高",特高係数,IF($I17="高",高係数,IF($I17="中",中係数,IF($I17="低",低係数,IF($I17="特低",特低係数,0))))) * IF(N$7="SA",要件定義係数,IF(N$7="UI",基本設計係数,IF(N$7="SS",詳細設計係数,IF(N$7="PS/PG/PT",製作係数,IF(N$7="IT",結合テスト係数,IF(N$7="ST",総合テスト係数,IF(N$7="OT",受入支援係数,IF(N$7="RL",移行切替係数,IF(N$7="その他",その他係数,0))))))))) * N$8,1) -> 1.8 | O17: =ROUNDUP(IF($E17="画面",画面係数,IF($E17="帳票",帳票係数,IF($E17="バッチ",バッチ係数,0))) * IF($I17="特高",特高係数,IF($I17="高",高係数,IF($I17="中",中係数,IF($I17="低",低係数,IF($I17="特低",特低係数,0))))) * IF(O$7="SA",要件定義係数,IF(O$7="UI",基本設計係数,IF(O$7="SS",詳細設計係数,IF(O$7="PS/PG/PT",製作係数,IF(O$7="IT",結合テスト係数,IF(O$7="ST",総合テスト係数,IF(O$7="OT",受入支援係数,IF(O$7="RL",移行切替係数,IF(O$7="その他",その他係数,0))))))))) * O$8,1) -> 1.2 | P17: =ROUNDUP(IF($E17="画面",画面係数,IF($E17="帳票",帳票係数,IF($E17="バッチ",バッチ係数,0))) * IF($I17="特高",特高係数,IF($I17="高",高係数,IF($I17="中",中係数,IF($I17="低",低係数,IF($I17="特低",特低係数,0))))) * IF(P$7="SA",要件定義係数,IF(P$7="UI",基本設計係数,IF(P$7="SS",詳細設計係数,IF(P$7="PS/PG/PT",製作係数,IF(P$7="IT",結合テスト係数,IF(P$7="ST",総合テスト係数,IF(P$7="OT",受入支援係数,IF(P$7="RL",移行切替係数,IF(P$7="その他",その他係数,0))))))))) * P$8,1) -> 0.5 | Q17: =ROUNDUP(IF($E17="画面",画面係数,IF($E17="帳票",帳票係数,IF($E17="バッチ",バッチ係数,0))) * IF($I17="特高",特高係数,IF($I17="高",高係数,IF($I17="中",中係数,IF($I17="低",低係数,IF($I17="特低",特低係数,0))))) * IF(Q$7="SA",要件定義係数,IF(Q$7="UI",基本設計係数,IF(Q$7="SS",詳細設計係数,IF(Q$7="PS/PG/PT",製作係数,IF(Q$7="IT",結合テスト係数,IF(Q$7="ST",総合テスト係数,IF(Q$7="OT",受入支援係数,IF(Q$7="RL",移行切替係数,IF(Q$7="その他",その他係数,0))))))))) * Q$8,1) -> 1.3 | R17: =ROUNDUP(IF($E17="画面",画面係数,IF($E17="帳票",帳票係数,IF($E17="バッチ",バッチ係数,0))) * IF($I17="特高",特高係数,IF($I17="高",高係数,IF($I17="中",中係数,IF($I17="低",低係数,IF($I17="特低",特低係数,0))))) * IF(R$7="SA",要件定義係数,IF(R$7="UI",基本設計係数,IF(R$7="SS",詳細設計係数,IF(R$7="PS/PG/PT",製作係数,IF(R$7="IT",結合テスト係数,IF(R$7="ST",総合テスト係数,IF(R$7="OT",受入支援係数,IF(R$7="RL",移行切替係数,IF(R$7="その他",その他係数,0))))))))) * R$8,1) -> 0 | T17: =ROUNDUP(SUM(J17:S17)*T$8,1) -> 1.9 | U17: =SUM(J17:T17) -> 14 | V17: =U17/20 -> 0.7 | W17: =((J17*J$9) + (K17*K$9) + (L17*L$9) + (M17*M$9) + (N17*N$9) + (O17*O$9) + (P17*P$9) + (Q17*Q$9) + (R17*R$9) + (S17*S$9) + (T17*T$9))/20 -> 768250 | X17: Javaに作り直し
A18: =ROW()-9 -> 9 | B18: メニュー | C18: ユーティリティ | D18: メニュー | E18: 画面 | I18: 低 | J18: =ROUNDUP(IF($E18="画面",画面係数,IF($E18="帳票",帳票係数,IF($E18="バッチ",バッチ係数,0))) * IF($I18="特高",特高係数,IF($I18="高",高係数,IF($I18="中",中係数,IF($I18="低",低係数,IF($I18="特低",特低係数,0))))) * IF(J$7="SA",要件定義係数,IF(J$7="UI",基本設計係数,IF(J$7="SS",詳細設計係数,IF(J$7="PS/PG/PT",製作係数,IF(J$7="IT",結合テスト係数,IF(J$7="ST",総合テスト係数,IF(J$7="OT",受入支援係数,IF(J$7="RL",移行切替係数,IF(J$7="その他",その他係数,0))))))))) * J$8,1) -> 1.3 | K18: =ROUNDUP(IF($E18="画面",画面係数,IF($E18="帳票",帳票係数,IF($E18="バッチ",バッチ係数,0))) * IF($I18="特高",特高係数,IF($I18="高",高係数,IF($I18="中",中係数,IF($I18="低",低係数,IF($I18="特低",特低係数,0))))) * IF(K$7="SA",要件定義係数,IF(K$7="UI",基本設計係数,IF(K$7="SS",詳細設計係数,IF(K$7="PS/PG/PT",製作係数,IF(K$7="IT",結合テスト係数,IF(K$7="ST",総合テスト係数,IF(K$7="OT",受入支援係数,IF(K$7="RL",移行切替係数,IF(K$7="その他",その他係数,0))))))))) * K$8,1) -> 1.5 | L18: =ROUNDUP(IF($E18="画面",画面係数,IF($E18="帳票",帳票係数,IF($E18="バッチ",バッチ係数,0))) * IF($I18="特高",特高係数,IF($I18="高",高係数,IF($I18="中",中係数,IF($I18="低",低係数,IF($I18="特低",特低係数,0))))) * IF(L$7="SA",要件定義係数,IF(L$7="UI",基本設計係数,IF(L$7="SS",詳細設計係数,IF(L$7="PS/PG/PT",製作係数,IF(L$7="IT",結合テスト係数,IF(L$7="ST",総合テスト係数,IF(L$7="OT",受入支援係数,IF(L$7="RL",移行切替係数,IF(L$7="その他",その他係数,0))))))))) * L$8,1) -> 1.6 | M18: =ROUNDUP(IF($E18="画面",画面係数,IF($E18="帳票",帳票係数,IF($E18="バッチ",バッチ係数,0))) * IF($I18="特高",特高係数,IF($I18="高",高係数,IF($I18="中",中係数,IF($I18="低",低係数,IF($I18="特低",特低係数,0))))) * IF(M$7="SA",要件定義係数,IF(M$7="UI",基本設計係数,IF(M$7="SS",詳細設計係数,IF(M$7="PS/PG/PT",製作係数,IF(M$7="IT",結合テスト係数,IF(M$7="ST",総合テスト係数,IF(M$7="OT",受入支援係数,IF(M$7="RL",移行切替係数,IF(M$7="その他",その他係数,0))))))))) * M$8,1) -> 2.9 | N18: =ROUNDUP(IF($E18="画面",画面係数,IF($E18="帳票",帳票係数,IF($E18="バッチ",バッチ係数,0))) * IF($I18="特高",特高係数,IF($I18="高",高係数,IF($I18="中",中係数,IF($I18="低",低係数,IF($I18="特低",特低係数,0))))) * IF(N$7="SA",要件定義係数,IF(N$7="UI",基本設計係数,IF(N$7="SS",詳細設計係数,IF(N$7="PS/PG/PT",製作係数,IF(N$7="IT",結合テスト係数,IF(N$7="ST",総合テスト係数,IF(N$7="OT",受入支援係数,IF(N$7="RL",移行切替係数,IF(N$7="その他",その他係数,0))))))))) * N$8,1) -> 1.8 | O18: =ROUNDUP(IF($E18="画面",画面係数,IF($E18="帳票",帳票係数,IF($E18="バッチ",バッチ係数,0))) * IF($I18="特高",特高係数,IF($I18="高",高係数,IF($I18="中",中係数,IF($I18="低",低係数,IF($I18="特低",特低係数,0))))) * IF(O$7="SA",要件定義係数,IF(O$7="UI",基本設計係数,IF(O$7="SS",詳細設計係数,IF(O$7="PS/PG/PT",製作係数,IF(O$7="IT",結合テスト係数,IF(O$7="ST",総合テスト係数,IF(O$7="OT",受入支援係数,IF(O$7="RL",移行切替係数,IF(O$7="その他",その他係数,0))))))))) * O$8,1) -> 1.2 | P18: =ROUNDUP(IF($E18="画面",画面係数,IF($E18="帳票",帳票係数,IF($E18="バッチ",バッチ係数,0))) * IF($I18="特高",特高係数,IF($I18="高",高係数,IF($I18="中",中係数,IF($I18="低",低係数,IF($I18="特低",特低係数,0))))) * IF(P$7="SA",要件定義係数,IF(P$7="UI",基本設計係数,IF(P$7="SS",詳細設計係数,IF(P$7="PS/PG/PT",製作係数,IF(P$7="IT",結合テスト係数,IF(P$7="ST",総合テスト係数,IF(P$7="OT",受入支援係数,IF(P$7="RL",移行切替係数,IF(P$7="その他",その他係数,0))))))))) * P$8,1) -> 0.5 | Q18: =ROUNDUP(IF($E18="画面",画面係数,IF($E18="帳票",帳票係数,IF($E18="バッチ",バッチ係数,0))) * IF($I18="特高",特高係数,IF($I18="高",高係数,IF($I18="中",中係数,IF($I18="低",低係数,IF($I18="特低",特低係数,0))))) * IF(Q$7="SA",要件定義係数,IF(Q$7="UI",基本設計係数,IF(Q$7="SS",詳細設計係数,IF(Q$7="PS/PG/PT",製作係数,IF(Q$7="IT",結合テスト係数,IF(Q$7="ST",総合テスト係数,IF(Q$7="OT",受入支援係数,IF(Q$7="RL",移行切替係数,IF(Q$7="その他",その他係数,0))))))))) * Q$8,1) -> 1.3 | R18: =ROUNDUP(IF($E18="画面",画面係数,IF($E18="帳票",帳票係数,IF($E18="バッチ",バッチ係数,0))) * IF($I18="特高",特高係数,IF($I18="高",高係数,IF($I18="中",中係数,IF($I18="低",低係数,IF($I18="特低",特低係数,0))))) * IF(R$7="SA",要件定義係数,IF(R$7="UI",基本設計係数,IF(R$7="SS",詳細設計係数,IF(R$7="PS/PG/PT",製作係数,IF(R$7="IT",結合テスト係数,IF(R$7="ST",総合テスト係数,IF(R$7="OT",受入支援係数,IF(R$7="RL",移行切替係数,IF(R$7="その他",その他係数,0))))))))) * R$8,1) -> 0 | T18: =ROUNDUP(SUM(J18:S18)*T$8,1) -> 1.9 | U18: =SUM(J18:T18) -> 14 | V18: =U18/20 -> 0.7 | W18: =((J18*J$9) + (K18*K$9) + (L18*L$9) + (M18*M$9) + (N18*N$9) + (O18*O$9) + (P18*P$9) + (Q18*Q$9) + (R18*R$9) + (S18*S$9) + (T18*T$9))/20 -> 768250 | X18: Javaに作り直し
A19: =ROW()-9 -> 10 | B19: 業務画面 | C19: 入出荷予定受信 | D19: 受注・入出荷／オーダー入力 | E19: 画面 | I19: 中 | J19: =ROUNDUP(IF($E19="画面",画面係数,IF($E19="帳票",帳票係数,IF($E19="バッチ",バッチ係数,0))) * IF($I19="特高",特高係数,IF($I19="高",高係数,IF($I19="中",中係数,IF($I19="低",低係数,IF($I19="特低",特低係数,0))))) * IF(J$7="SA",要件定義係数,IF(J$7="UI",基本設計係数,IF(J$7="SS",詳細設計係数,IF(J$7="PS/PG/PT",製作係数,IF(J$7="IT",結合テスト係数,IF(J$7="ST",総合テスト係数,IF(J$7="OT",受入支援係数,IF(J$7="RL",移行切替係数,IF(J$7="その他",その他係数,0))))))))) * J$8,1) -> 2.2 | K19: =ROUNDUP(IF($E19="画面",画面係数,IF($E19="帳票",帳票係数,IF($E19="バッチ",バッチ係数,0))) * IF($I19="特高",特高係数,IF($I19="高",高係数,IF($I19="中",中係数,IF($I19="低",低係数,IF($I19="特低",特低係数,0))))) * IF(K$7="SA",要件定義係数,IF(K$7="UI",基本設計係数,IF(K$7="SS",詳細設計係数,IF(K$7="PS/PG/PT",製作係数,IF(K$7="IT",結合テスト係数,IF(K$7="ST",総合テスト係数,IF(K$7="OT",受入支援係数,IF(K$7="RL",移行切替係数,IF(K$7="その他",その他係数,0))))))))) * K$8,1) -> 2.5 | L19: =ROUNDUP(IF($E19="画面",画面係数,IF($E19="帳票",帳票係数,IF($E19="バッチ",バッチ係数,0))) * IF($I19="特高",特高係数,IF($I19="高",高係数,IF($I19="中",中係数,IF($I19="低",低係数,IF($I19="特低",特低係数,0))))) * IF(L$7="SA",要件定義係数,IF(L$7="UI",基本設計係数,IF(L$7="SS",詳細設計係数,IF(L$7="PS/PG/PT",製作係数,IF(L$7="IT",結合テスト係数,IF(L$7="ST",総合テスト係数,IF(L$7="OT",受入支援係数,IF(L$7="RL",移行切替係数,IF(L$7="その他",その他係数,0))))))))) * L$8,1) -> 2.6 | M19: =ROUNDUP(IF($E19="画面",画面係数,IF($E19="帳票",帳票係数,IF($E19="バッチ",バッチ係数,0))) * IF($I19="特高",特高係数,IF($I19="高",高係数,IF($I19="中",中係数,IF($I19="低",低係数,IF($I19="特低",特低係数,0))))) * IF(M$7="SA",要件定義係数,IF(M$7="UI",基本設計係数,IF(M$7="SS",詳細設計係数,IF(M$7="PS/PG/PT",製作係数,IF(M$7="IT",結合テスト係数,IF(M$7="ST",総合テスト係数,IF(M$7="OT",受入支援係数,IF(M$7="RL",移行切替係数,IF(M$7="その他",その他係数,0))))))))) * M$8,1) -> 4.7 | N19: =ROUNDUP(IF($E19="画面",画面係数,IF($E19="帳票",帳票係数,IF($E19="バッチ",バッチ係数,0))) * IF($I19="特高",特高係数,IF($I19="高",高係数,IF($I19="中",中係数,IF($I19="低",低係数,IF($I19="特低",特低係数,0))))) * IF(N$7="SA",要件定義係数,IF(N$7="UI",基本設計係数,IF(N$7="SS",詳細設計係数,IF(N$7="PS/PG/PT",製作係数,IF(N$7="IT",結合テスト係数,IF(N$7="ST",総合テスト係数,IF(N$7="OT",受入支援係数,IF(N$7="RL",移行切替係数,IF(N$7="その他",その他係数,0))))))))) * N$8,1) -> 2.9 | O19: =ROUNDUP(IF($E19="画面",画面係数,IF($E19="帳票",帳票係数,IF($E19="バッチ",バッチ係数,0))) * IF($I19="特高",特高係数,IF($I19="高",高係数,IF($I19="中",中係数,IF($I19="低",低係数,IF($I19="特低",特低係数,0))))) * IF(O$7="SA",要件定義係数,IF(O$7="UI",基本設計係数,IF(O$7="SS",詳細設計係数,IF(O$7="PS/PG/PT",製作係数,IF(O$7="IT",結合テスト係数,IF(O$7="ST",総合テスト係数,IF(O$7="OT",受入支援係数,IF(O$7="RL",移行切替係数,IF(O$7="その他",その他係数,0))))))))) * O$8,1) -> 1.9 | P19: =ROUNDUP(IF($E19="画面",画面係数,IF($E19="帳票",帳票係数,IF($E19="バッチ",バッチ係数,0))) * IF($I19="特高",特高係数,IF($I19="高",高係数,IF($I19="中",中係数,IF($I19="低",低係数,IF($I19="特低",特低係数,0))))) * IF(P$7="SA",要件定義係数,IF(P$7="UI",基本設計係数,IF(P$7="SS",詳細設計係数,IF(P$7="PS/PG/PT",製作係数,IF(P$7="IT",結合テスト係数,IF(P$7="ST",総合テスト係数,IF(P$7="OT",受入支援係数,IF(P$7="RL",移行切替係数,IF(P$7="その他",その他係数,0))))))))) * P$8,1) -> 0.8 | Q19: =ROUNDUP(IF($E19="画面",画面係数,IF($E19="帳票",帳票係数,IF($E19="バッチ",バッチ係数,0))) * IF($I19="特高",特高係数,IF($I19="高",高係数,IF($I19="中",中係数,IF($I19="低",低係数,IF($I19="特低",特低係数,0))))) * IF(Q$7="SA",要件定義係数,IF(Q$7="UI",基本設計係数,IF(Q$7="SS",詳細設計係数,IF(Q$7="PS/PG/PT",製作係数,IF(Q$7="IT",結合テスト係数,IF(Q$7="ST",総合テスト係数,IF(Q$7="OT",受入支援係数,IF(Q$7="RL",移行切替係数,IF(Q$7="その他",その他係数,0))))))))) * Q$8,1) -> 2.2 | R19: =ROUNDUP(IF($E19="画面",画面係数,IF($E19="帳票",帳票係数,IF($E19="バッチ",バッチ係数,0))) * IF($I19="特高",特高係数,IF($I19="高",高係数,IF($I19="中",中係数,IF($I19="低",低係数,IF($I19="特低",特低係数,0))))) * IF(R$7="SA",要件定義係数,IF(R$7="UI",基本設計係数,IF(R$7="SS",詳細設計係数,IF(R$7="PS/PG/PT",製作係数,IF(R$7="IT",結合テスト係数,IF(R$7="ST",総合テスト係数,IF(R$7="OT",受入支援係数,IF(R$7="RL",移行切替係数,IF(R$7="その他",その他係数,0))))))))) * R$8,1) -> 0 | T19: =ROUNDUP(SUM(J19:S19)*T$8,1) -> 3 | U19: =SUM(J19:T19) -> 22.8 | V19: =U19/20 -> 1.14 | W19: =((J19*J$9) + (K19*K$9) + (L19*L$9) + (M19*M$9) + (N19*N$9) + (O19*O$9) + (P19*P$9) + (Q19*Q$9) + (R19*R$9) + (S19*S$9) + (T19*T$9))/20 -> 1249500 | X19: Javaに作り直し
A20: =ROW()-9 -> 11 | B20: 業務画面 | C20: 入出荷予定再登録 | D20: 受注・入出荷／オーダー入力 | E20: 画面 | I20: 中 | J20: =ROUNDUP(IF($E20="画面",画面係数,IF($E20="帳票",帳票係数,IF($E20="バッチ",バッチ係数,0))) * IF($I20="特高",特高係数,IF($I20="高",高係数,IF($I20="中",中係数,IF($I20="低",低係数,IF($I20="特低",特低係数,0))))) * IF(J$7="SA",要件定義係数,IF(J$7="UI",基本設計係数,IF(J$7="SS",詳細設計係数,IF(J$7="PS/PG/PT",製作係数,IF(J$7="IT",結合テスト係数,IF(J$7="ST",総合テスト係数,IF(J$7="OT",受入支援係数,IF(J$7="RL",移行切替係数,IF(J$7="その他",その他係数,0))))))))) * J$8,1) -> 2.2 | K20: =ROUNDUP(IF($E20="画面",画面係数,IF($E20="帳票",帳票係数,IF($E20="バッチ",バッチ係数,0))) * IF($I20="特高",特高係数,IF($I20="高",高係数,IF($I20="中",中係数,IF($I20="低",低係数,IF($I20="特低",特低係数,0))))) * IF(K$7="SA",要件定義係数,IF(K$7="UI",基本設計係数,IF(K$7="SS",詳細設計係数,IF(K$7="PS/PG/PT",製作係数,IF(K$7="IT",結合テスト係数,IF(K$7="ST",総合テスト係数,IF(K$7="OT",受入支援係数,IF(K$7="RL",移行切替係数,IF(K$7="その他",その他係数,0))))))))) * K$8,1) -> 2.5 | L20: =ROUNDUP(IF($E20="画面",画面係数,IF($E20="帳票",帳票係数,IF($E20="バッチ",バッチ係数,0))) * IF($I20="特高",特高係数,IF($I20="高",高係数,IF($I20="中",中係数,IF($I20="低",低係数,IF($I20="特低",特低係数,0))))) * IF(L$7="SA",要件定義係数,IF(L$7="UI",基本設計係数,IF(L$7="SS",詳細設計係数,IF(L$7="PS/PG/PT",製作係数,IF(L$7="IT",結合テスト係数,IF(L$7="ST",総合テスト係数,IF(L$7="OT",受入支援係数,IF(L$7="RL",移行切替係数,IF(L$7="その他",その他係数,0))))))))) * L$8,1) -> 2.6 | M20: =ROUNDUP(IF($E20="画面",画面係数,IF($E20="帳票",帳票係数,IF($E20="バッチ",バッチ係数,0))) * IF($I20="特高",特高係数,IF($I20="高",高係数,IF($I20="中",中係数,IF($I20="低",低係数,IF($I20="特低",特低係数,0))))) * IF(M$7="SA",要件定義係数,IF(M$7="UI",基本設計係数,IF(M$7="SS",詳細設計係数,IF(M$7="PS/PG/PT",製作係数,IF(M$7="IT",結合テスト係数,IF(M$7="ST",総合テスト係数,IF(M$7="OT",受入支援係数,IF(M$7="RL",移行切替係数,IF(M$7="その他",その他係数,0))))))))) * M$8,1) -> 4.7 | N20: =ROUNDUP(IF($E20="画面",画面係数,IF($E20="帳票",帳票係数,IF($E20="バッチ",バッチ係数,0))) * IF($I20="特高",特高係数,IF($I20="高",高係数,IF($I20="中",中係数,IF($I20="低",低係数,IF($I20="特低",特低係数,0))))) * IF(N$7="SA",要件定義係数,IF(N$7="UI",基本設計係数,IF(N$7="SS",詳細設計係数,IF(N$7="PS/PG/PT",製作係数,IF(N$7="IT",結合テスト係数,IF(N$7="ST",総合テスト係数,IF(N$7="OT",受入支援係数,IF(N$7="RL",移行切替係数,IF(N$7="その他",その他係数,0))))))))) * N$8,1) -> 2.9 | O20: =ROUNDUP(IF($E20="画面",画面係数,IF($E20="帳票",帳票係数,IF($E20="バッチ",バッチ係数,0))) * IF($I20="特高",特高係数,IF($I20="高",高係数,IF($I20="中",中係数,IF($I20="低",低係数,IF($I20="特低",特低係数,0))))) * IF(O$7="SA",要件定義係数,IF(O$7="UI",基本設計係数,IF(O$7="SS",詳細設計係数,IF(O$7="PS/PG/PT",製作係数,IF(O$7="IT",結合テスト係数,IF(O$7="ST",総合テスト係数,IF(O$7="OT",受入支援係数,IF(O$7="RL",移行切替係数,IF(O$7="その他",その他係数,0))))))))) * O$8,1) -> 1.9 | P20: =ROUNDUP(IF($E20="画面",画面係数,IF($E20="帳票",帳票係数,IF($E20="バッチ",バッチ係数,0))) * IF($I20="特高",特高係数,IF($I20="高",高係数,IF($I20="中",中係数,IF($I20="低",低係数,IF($I20="特低",特低係数,0))))) * IF(P$7="SA",要件定義係数,IF(P$7="UI",基本設計係数,IF(P$7="SS",詳細設計係数,IF(P$7="PS/PG/PT",製作係数,IF(P$7="IT",結合テスト係数,IF(P$7="ST",総合テスト係数,IF(P$7="OT",受入支援係数,IF(P$7="RL",移行切替係数,IF(P$7="その他",その他係数,0))))))))) * P$8,1) -> 0.8 | Q20: =ROUNDUP(IF($E20="画面",画面係数,IF($E20="帳票",帳票係数,IF($E20="バッチ",バッチ係数,0))) * IF($I20="特高",特高係数,IF($I20="高",高係数,IF($I20="中",中係数,IF($I20="低",低係数,IF($I20="特低",特低係数,0))))) * IF(Q$7="SA",要件定義係数,IF(Q$7="UI",基本設計係数,IF(Q$7="SS",詳細設計係数,IF(Q$7="PS/PG/PT",製作係数,IF(Q$7="IT",結合テスト係数,IF(Q$7="ST",総合テスト係数,IF(Q$7="OT",受入支援係数,IF(Q$7="RL",移行切替係数,IF(Q$7="その他",その他係数,0))))))))) * Q$8,1) -> 2.2 | R20: =ROUNDUP(IF($E20="画面",画面係数,IF($E20="帳票",帳票係数,IF($E20="バッチ",バッチ係数,0))) * IF($I20="特高",特高係数,IF($I20="高",高係数,IF($I20="中",中係数,IF($I20="低",低係数,IF($I20="特低",特低係数,0))))) * IF(R$7="SA",要件定義係数,IF(R$7="UI",基本設計係数,IF(R$7="SS",詳細設計係数,IF(R$7="PS/PG/PT",製作係数,IF(R$7="IT",結合テスト係数,IF(R$7="ST",総合テスト係数,IF(R$7="OT",受入支援係数,IF(R$7="RL",移行切替係数,IF(R$7="その他",その他係数,0))))))))) * R$8,1) -> 0 | T20: =ROUNDUP(SUM(J20:S20)*T$8,1) -> 3 | U20: =SUM(J20:T20) -> 22.8 | V20: =U20/20 -> 1.14 | W20: =((J20*J$9) + (K20*K$9) + (L20*L$9) + (M20*M$9) + (N20*N$9) + (O20*O$9) + (P20*P$9) + (Q20*Q$9) + (R20*R$9) + (S20*S$9) + (T20*T$9))/20 -> 1249500 | X20: Javaに作り直し
A21: =ROW()-9 -> 12 | B21: 業務画面 | C21: オーダー新規入力 | D21: 受注・入出荷／オーダー入力 | E21: 画面 | I21: 高 | J21: =ROUNDUP(IF($E21="画面",画面係数,IF($E21="帳票",帳票係数,IF($E21="バッチ",バッチ係数,0))) * IF($I21="特高",特高係数,IF($I21="高",高係数,IF($I21="中",中係数,IF($I21="低",低係数,IF($I21="特低",特低係数,0))))) * IF(J$7="SA",要件定義係数,IF(J$7="UI",基本設計係数,IF(J$7="SS",詳細設計係数,IF(J$7="PS/PG/PT",製作係数,IF(J$7="IT",結合テスト係数,IF(J$7="ST",総合テスト係数,IF(J$7="OT",受入支援係数,IF(J$7="RL",移行切替係数,IF(J$7="その他",その他係数,0))))))))) * J$8,1) -> 3.1 | K21: =ROUNDUP(IF($E21="画面",画面係数,IF($E21="帳票",帳票係数,IF($E21="バッチ",バッチ係数,0))) * IF($I21="特高",特高係数,IF($I21="高",高係数,IF($I21="中",中係数,IF($I21="低",低係数,IF($I21="特低",特低係数,0))))) * IF(K$7="SA",要件定義係数,IF(K$7="UI",基本設計係数,IF(K$7="SS",詳細設計係数,IF(K$7="PS/PG/PT",製作係数,IF(K$7="IT",結合テスト係数,IF(K$7="ST",総合テスト係数,IF(K$7="OT",受入支援係数,IF(K$7="RL",移行切替係数,IF(K$7="その他",その他係数,0))))))))) * K$8,1) -> 3.5 | L21: =ROUNDUP(IF($E21="画面",画面係数,IF($E21="帳票",帳票係数,IF($E21="バッチ",バッチ係数,0))) * IF($I21="特高",特高係数,IF($I21="高",高係数,IF($I21="中",中係数,IF($I21="低",低係数,IF($I21="特低",特低係数,0))))) * IF(L$7="SA",要件定義係数,IF(L$7="UI",基本設計係数,IF(L$7="SS",詳細設計係数,IF(L$7="PS/PG/PT",製作係数,IF(L$7="IT",結合テスト係数,IF(L$7="ST",総合テスト係数,IF(L$7="OT",受入支援係数,IF(L$7="RL",移行切替係数,IF(L$7="その他",その他係数,0))))))))) * L$8,1) -> 3.6 | M21: =ROUNDUP(IF($E21="画面",画面係数,IF($E21="帳票",帳票係数,IF($E21="バッチ",バッチ係数,0))) * IF($I21="特高",特高係数,IF($I21="高",高係数,IF($I21="中",中係数,IF($I21="低",低係数,IF($I21="特低",特低係数,0))))) * IF(M$7="SA",要件定義係数,IF(M$7="UI",基本設計係数,IF(M$7="SS",詳細設計係数,IF(M$7="PS/PG/PT",製作係数,IF(M$7="IT",結合テスト係数,IF(M$7="ST",総合テスト係数,IF(M$7="OT",受入支援係数,IF(M$7="RL",移行切替係数,IF(M$7="その他",その他係数,0))))))))) * M$8,1) -> 6.6 | N21: =ROUNDUP(IF($E21="画面",画面係数,IF($E21="帳票",帳票係数,IF($E21="バッチ",バッチ係数,0))) * IF($I21="特高",特高係数,IF($I21="高",高係数,IF($I21="中",中係数,IF($I21="低",低係数,IF($I21="特低",特低係数,0))))) * IF(N$7="SA",要件定義係数,IF(N$7="UI",基本設計係数,IF(N$7="SS",詳細設計係数,IF(N$7="PS/PG/PT",製作係数,IF(N$7="IT",結合テスト係数,IF(N$7="ST",総合テスト係数,IF(N$7="OT",受入支援係数,IF(N$7="RL",移行切替係数,IF(N$7="その他",その他係数,0))))))))) * N$8,1) -> 4.1 | O21: =ROUNDUP(IF($E21="画面",画面係数,IF($E21="帳票",帳票係数,IF($E21="バッチ",バッチ係数,0))) * IF($I21="特高",特高係数,IF($I21="高",高係数,IF($I21="中",中係数,IF($I21="低",低係数,IF($I21="特低",特低係数,0))))) * IF(O$7="SA",要件定義係数,IF(O$7="UI",基本設計係数,IF(O$7="SS",詳細設計係数,IF(O$7="PS/PG/PT",製作係数,IF(O$7="IT",結合テスト係数,IF(O$7="ST",総合テスト係数,IF(O$7="OT",受入支援係数,IF(O$7="RL",移行切替係数,IF(O$7="その他",その他係数,0))))))))) * O$8,1) -> 2.7 | P21: =ROUNDUP(IF($E21="画面",画面係数,IF($E21="帳票",帳票係数,IF($E21="バッチ",バッチ係数,0))) * IF($I21="特高",特高係数,IF($I21="高",高係数,IF($I21="中",中係数,IF($I21="低",低係数,IF($I21="特低",特低係数,0))))) * IF(P$7="SA",要件定義係数,IF(P$7="UI",基本設計係数,IF(P$7="SS",詳細設計係数,IF(P$7="PS/PG/PT",製作係数,IF(P$7="IT",結合テスト係数,IF(P$7="ST",総合テスト係数,IF(P$7="OT",受入支援係数,IF(P$7="RL",移行切替係数,IF(P$7="その他",その他係数,0))))))))) * P$8,1) -> 1.1 | Q21: =ROUNDUP(IF($E21="画面",画面係数,IF($E21="帳票",帳票係数,IF($E21="バッチ",バッチ係数,0))) * IF($I21="特高",特高係数,IF($I21="高",高係数,IF($I21="中",中係数,IF($I21="低",低係数,IF($I21="特低",特低係数,0))))) * IF(Q$7="SA",要件定義係数,IF(Q$7="UI",基本設計係数,IF(Q$7="SS",詳細設計係数,IF(Q$7="PS/PG/PT",製作係数,IF(Q$7="IT",結合テスト係数,IF(Q$7="ST",総合テスト係数,IF(Q$7="OT",受入支援係数,IF(Q$7="RL",移行切替係数,IF(Q$7="その他",その他係数,0))))))))) * Q$8,1) -> 3.1 | R21: =ROUNDUP(IF($E21="画面",画面係数,IF($E21="帳票",帳票係数,IF($E21="バッチ",バッチ係数,0))) * IF($I21="特高",特高係数,IF($I21="高",高係数,IF($I21="中",中係数,IF($I21="低",低係数,IF($I21="特低",特低係数,0))))) * IF(R$7="SA",要件定義係数,IF(R$7="UI",基本設計係数,IF(R$7="SS",詳細設計係数,IF(R$7="PS/PG/PT",製作係数,IF(R$7="IT",結合テスト係数,IF(R$7="ST",総合テスト係数,IF(R$7="OT",受入支援係数,IF(R$7="RL",移行切替係数,IF(R$7="その他",その他係数,0))))))))) * R$8,1) -> 0 | T21: =ROUNDUP(SUM(J21:S21)*T$8,1) -> 4.2 | U21: =SUM(J21:T21) -> 32 | V21: =U21/20 -> 1.6 | W21: =((J21*J$9) + (K21*K$9) + (L21*L$9) + (M21*M$9) + (N21*N$9) + (O21*O$9) + (P21*P$9) + (Q21*Q$9) + (R21*R$9) + (S21*S$9) + (T21*T$9))/20 -> 1753500 | X21: Javaに作り直し
... A194: =ROW()-9 -> 185 | B194: 業務画面 | C194: 計画手配データ作成 | D194: 生産計画・発注／指図確定・送信 | E194: 画面 | I194: 中 | J194: =ROUNDUP(IF($E194="画面",画面係数,IF($E194="帳票",帳票係数,IF($E194="バッチ",バッチ係数,0))) * IF($I194="特高",特高係数,IF($I194="高",高係数,IF($I194="中",中係数,IF($I194="低",低係数,IF($I194="特低",特低係数,0))))) * IF(J$7="SA",要件定義係数,IF(J$7="UI",基本設計係数,IF(J$7="SS",詳細設計係数,IF(J$7="PS/PG/PT",製作係数,IF(J$7="IT",結合テスト係数,IF(J$7="ST",総合テスト係数,IF(J$7="OT",受入支援係数,IF(J$7="RL",移行切替係数,IF(J$7="その他",その他係数,0))))))))) * J$8,1) -> 2.2 | K194: =ROUNDUP(IF($E194="画面",画面係数,IF($E194="帳票",帳票係数,IF($E194="バッチ",バッチ係数,0))) * IF($I194="特高",特高係数,IF($I194="高",高係数,IF($I194="中",中係数,IF($I194="低",低係数,IF($I194="特低",特低係数,0))))) * IF(K$7="SA",要件定義係数,IF(K$7="UI",基本設計係数,IF(K$7="SS",詳細設計係数,IF(K$7="PS/PG/PT",製作係数,IF(K$7="IT",結合テスト係数,IF(K$7="ST",総合テスト係数,IF(K$7="OT",受入支援係数,IF(K$7="RL",移行切替係数,IF(K$7="その他",その他係数,0))))))))) * K$8,1) -> 2.5 | L194: =ROUNDUP(IF($E194="画面",画面係数,IF($E194="帳票",帳票係数,IF($E194="バッチ",バッチ係数,0))) * IF($I194="特高",特高係数,IF($I194="高",高係数,IF($I194="中",中係数,IF($I194="低",低係数,IF($I194="特低",特低係数,0))))) * IF(L$7="SA",要件定義係数,IF(L$7="UI",基本設計係数,IF(L$7="SS",詳細設計係数,IF(L$7="PS/PG/PT",製作係数,IF(L$7="IT",結合テスト係数,IF(L$7="ST",総合テスト係数,IF(L$7="OT",受入支援係数,IF(L$7="RL",移行切替係数,IF(L$7="その他",その他係数,0))))))))) * L$8,1) -> 2.6 | M194: =ROUNDUP(IF($E194="画面",画面係数,IF($E194="帳票",帳票係数,IF($E194="バッチ",バッチ係数,0))) * IF($I194="特高",特高係数,IF($I194="高",高係数,IF($I194="中",中係数,IF($I194="低",低係数,IF($I194="特低",特低係数,0))))) * IF(M$7="SA",要件定義係数,IF(M$7="UI",基本設計係数,IF(M$7="SS",詳細設計係数,IF(M$7="PS/PG/PT",製作係数,IF(M$7="IT",結合テスト係数,IF(M$7="ST",総合テスト係数,IF(M$7="OT",受入支援係数,IF(M$7="RL",移行切替係数,IF(M$7="その他",その他係数,0))))))))) * M$8,1) -> 4.7 | N194: =ROUNDUP(IF($E194="画面",画面係数,IF($E194="帳票",帳票係数,IF($E194="バッチ",バッチ係数,0))) * IF($I194="特高",特高係数,IF($I194="高",高係数,IF($I194="中",中係数,IF($I194="低",低係数,IF($I194="特低",特低係数,0))))) * IF(N$7="SA",要件定義係数,IF(N$7="UI",基本設計係数,IF(N$7="SS",詳細設計係数,IF(N$7="PS/PG/PT",製作係数,IF(N$7="IT",結合テスト係数,IF(N$7="ST",総合テスト係数,IF(N$7="OT",受入支援係数,IF(N$7="RL",移行切替係数,IF(N$7="その他",その他係数,0))))))))) * N$8,1) -> 2.9 | O194: =ROUNDUP(IF($E194="画面",画面係数,IF($E194="帳票",帳票係数,IF($E194="バッチ",バッチ係数,0))) * IF($I194="特高",特高係数,IF($I194="高",高係数,IF($I194="中",中係数,IF($I194="低",低係数,IF($I194="特低",特低係数,0))))) * IF(O$7="SA",要件定義係数,IF(O$7="UI",基本設計係数,IF(O$7="SS",詳細設計係数,IF(O$7="PS/PG/PT",製作係数,IF(O$7="IT",結合テスト係数,IF(O$7="ST",総合テスト係数,IF(O$7="OT",受入支援係数,IF(O$7="RL",移行切替係数,IF(O$7="その他",その他係数,0))))))))) * O$8,1) -> 1.9 | P194: =ROUNDUP(IF($E194="画面",画面係数,IF($E194="帳票",帳票係数,IF($E194="バッチ",バッチ係数,0))) * IF($I194="特高",特高係数,IF($I194="高",高係数,IF($I194="中",中係数,IF($I194="低",低係数,IF($I194="特低",特低係数,0))))) * IF(P$7="SA",要件定義係数,IF(P$7="UI",基本設計係数,IF(P$7="SS",詳細設計係数,IF(P$7="PS/PG/PT",製作係数,IF(P$7="IT",結合テスト係数,IF(P$7="ST",総合テスト係数,IF(P$7="OT",受入支援係数,IF(P$7="RL",移行切替係数,IF(P$7="その他",その他係数,0))))))))) * P$8,1) -> 0.8 | Q194: =ROUNDUP(IF($E194="画面",画面係数,IF($E194="帳票",帳票係数,IF($E194="バッチ",バッチ係数,0))) * IF($I194="特高",特高係数,IF($I194="高",高係数,IF($I194="中",中係数,IF($I194="低",低係数,IF($I194="特低",特低係数,0))))) * IF(Q$7="SA",要件定義係数,IF(Q$7="UI",基本設計係数,IF(Q$7="SS",詳細設計係数,IF(Q$7="PS/PG/PT",製作係数,IF(Q$7="IT",結合テスト係数,IF(Q$7="ST",総合テスト係数,IF(Q$7="OT",受入支援係数,IF(Q$7="RL",移行切替係数,IF(Q$7="その他",その他係数,0))))))))) * Q$8,1) -> 2.2 | R194: =ROUNDUP(IF($E194="画面",画面係数,IF($E194="帳票",帳票係数,IF($E194="バッチ",バッチ係数,0))) * IF($I194="特高",特高係数,IF($I194="高",高係数,IF($I194="中",中係数,IF($I194="低",低係数,IF($I194="特低",特低係数,0))))) * IF(R$7="SA",要件定義係数,IF(R$7="UI",基本設計係数,IF(R$7="SS",詳細設計係数,IF(R$7="PS/PG/PT",製作係数,IF(R$7="IT",結合テスト係数,IF(R$7="ST",総合テスト係数,IF(R$7="OT",受入支援係数,IF(R$7="RL",移行切替係数,IF(R$7="その他",その他係数,0))))))))) * R$8,1) -> 0 | T194: =ROUNDUP(SUM(J194:S194)*T$8,1) -> 3 | U194: =SUM(J194:T194) -> 22.8 | V194: =U194/20 -> 1.14 | W194: =((J194*J$9) + (K194*K$9) + (L194*L$9) + (M194*M$9) + (N194*N$9) + (O194*O$9) + (P194*P$9) + (Q194*Q$9) + (R194*R$9) + (S194*S$9) + (T194*T$9))/20 -> 1249500 | X194: 各所ごとをやめる
