Workbook
Name FP試算法データファンクション: [1]FP係数!$B$26:$B$27
Name 計測種別: [1]FP係数!$B$20:$B$21
Name 高係数: 積算基準!$D$49
Name 高係数_IF: 積算基準!$D$50
Name 参照上限高: 積算基準!$D$17
Name 参照上限中: 積算基準!$E$17
Name 参照上限低: 積算基準!$F$17
Name 参照上限特高: 積算基準!$C$17
Name 参照上限特低: 積算基準!$G$17
Name 成形原料処置: '[2]【参考】UI-22 業務コード定義'!$C$15
Name 単価ランク: [1]IFPUG法・FP概算法!$J$10:$J$14
Name 中係数: 積算基準!$E$49
Name 中係数_IF: 積算基準!$E$50
Name 低係数: 積算基準!$F$49
Name 低係数_IF: 積算基準!$F$50
Name 登録上限高: 積算基準!$D$16
Name 登録上限中: 積算基準!$E$16
Name 登録上限低: 積算基準!$F$16
Name 登録上限特高: 積算基準!$C$16
Name 登録上限特低: 積算基準!$G$16
Name 特高係数: 積算基準!$C$49
Name 特高係数_IF: 積算基準!$C$50
Name 特低係数: 積算基準!$G$49
Name 特低係数_IF: 積算基準!$G$50
Name 標準成形不可時: '[2]【参考】UI-22 業務コード定義'!$C$14

Sheet スケジュール・要員計画
C1: 4月 | D1: 5月 | E1: 6月 | F1: 7月 | G1: 8月 | H1: 9月 | I1: 10月 | J1: 11月 | K1: 12月 | L1: 1月 | M1: 2月 | N1: 3月 | O1: 4月
B2: 要件定義 | Q2: 外部IFは対象外
B3: 基本設計 | Q3: インフラ構築は対象外
B4: UI検討 | Q4: インフラ構成の設計はやる（ヒアリングシートの作成のみ）
B5: 詳細設計 | Q5: 要件定義後に再見積り
B6: 開発 | Q6: 要件定義、総合テスト以降は準委任契約とする
B7: 単体テスト | Q7: 脆弱性診断の実施費用は含まれていない（修正作業は含まれている）
B8: 結合テスト | Q8: オフショア利用の可能性あり
B9: 総合テスト | Q9: ソフトウェア費用は含まれていない
B10: 受入テスト | Q10: 頂いた資料分の見積りしかいれていない（※ユーザー管理は追加した）
B11: 本稼働 | Q11: 出張費用は含まれていない
B12: 初期流動 | Q12: マニュアル作成は含まれている
Q13: ユーザー教育は含まれていない
Q14: PCブラウザのシステムを想定している（タブレット、スマホ対応なし）
Q15: スクラッチ開発を想定している
Q19: 工数 | R19: 単価 | S19: 金額 | T19: 原価 | U19: 粗利 | V19: 粗利率
A20: JP | B20: PM | D20: 1 | E20: 1 | F20: 1 | G20: 1 | H20: 1 | I20: 0.5 | J20: 0.5 | K20: 0.5 | L20: 0.5 | M20: 0.5 | N20: 0.5 | Q20: =SUM(C20:O20) -> 8 | R20: 140 | S20: =Q20*R20 -> 1120 | T20: 65 | U20: =S20-(T20*Q20) -> 600
A21: JP | B21: SE（BP） | D21: 1 | E21: 1 | F21: 1 | G21: 1 | H21: 1 | I21: 1 | J21: 1 | K21: 1 | L21: 1 | M21: 1 | N21: 1 | Q21: =SUM(C21:O21) -> 11 | R21: 110 | S21: =Q21*R21 -> 1210 | T21: 90 | U21: =S21-(T21*Q21) -> 220
A22: JP | B22: SE（BP） | G22: 1 | H22: 1 | I22: 1 | J22: 1 | K22: 1 | Q22: =SUM(C22:O22) -> 5 | R22: 110 | S22: =Q22*R22 -> 550 | T22: 90 | U22: =S22-(T22*Q22) -> 100
A23: JP | B23: PG（BP） | Q23: =SUM(C23:O23) -> 0 | R23: 100 | S23: =Q23*R23 -> 0 | T23: 90 | U23: =S23-(T23*Q23) -> 0
A24: JP | B24: PG（BP） | Q24: =SUM(C24:O24) -> 0 | R24: 100 | S24: =Q24*R24 -> 0 | T24: 90 | U24: =S24-(T24*Q24) -> 0
Q25: =SUM(Q20:Q24) -> 24 | S25: =SUM(S20:S24) -> 2880 | U25: =SUM(U20:U24) -> 920 | V25: =U25/S25 -> 0.31944444
S26: =S25*1.2 -> 3456
A27: JP | B27: PM | D27: 1 | E27: 1 | F27: 1 | G27: 1 | H27: 1 | I27: 0.5 | J27: 0.5 | K27: 0.5 | L27: 0.5 | M27: 0.5 | N27: 0.5 | Q27: =SUM(C27:O27) -> 8 | R27: 140 | S27: =Q27*R27 -> 1120 | T27: 65 | U27: =S27-(T27*Q27) -> 600
A28: JP | B28: PL | Q28: =SUM(C28:O28) -> 0 | R28: 120 | S28: =Q28*R28 -> 0 | T28: 65 | U28: =S28-(T28*Q28) -> 0
A29: JP | B29: SE（BP） | D29: 1 | E29: 1 | F29: 1 | G29: 1 | H29: 1 | I29: 1 | J29: 1 | K29: 1 | L29: 1 | M29: 1 | N29: 1 | Q29: =SUM(C29:O29) -> 11 | R29: 110 | S29: =Q29*R29 -> 1210 | T29: 90 | U29: =S29-(T29*Q29) -> 220
A30: VN | B30: BG | G30: 0.5 | H30: 0.5 | I30: 0.5 | J30: 0.5 | K30: 0.5 | L30: 0.5 | M30: 0.5 | N30: 0.5 | Q30: =SUM(C30:O30) -> 4 | R30: 80 | S30: =Q30*R30 -> 320 | T30: 50 | U30: =S30-(T30*Q30) -> 120
A31: VN | B31: SE | G31: 1 | H31: 1 | I31: 1 | J31: 1 | K31: 1 | L31: 1 | M31: 1 | N31: 1 | Q31: =SUM(C31:O31) -> 8 | R31: 70 | S31: =Q31*R31 -> 560 | T31: 35 | U31: =S31-(T31*Q31) -> 280
A32: VN | B32: PG | G32: 1 | H32: 1 | I32: 1 | J32: 1 | K32: 1 | L32: 1 | M32: 1 | Q32: =SUM(C32:O32) -> 7 | R32: 70 | S32: =Q32*R32 -> 490 | T32: 35 | U32: =S32-(T32*Q32) -> 245
A33: VN | B33: PG | Q33: =SUM(C33:O33) -> 0 | R33: 70 | S33: =Q33*R33 -> 0 | T33: 35 | U33: =S33-(T33*Q33) -> 0
Q34: =SUM(Q27:Q33) -> 38 | S34: =SUM(S27:S33) -> 3700 | U34: =SUM(U27:U33) -> 1465 | V34: =U34/S34 -> 0.39594595
S35: =S34*1.2 -> 4440

Sheet 御見積(画面・機能)
A2: № | B2: システム名 | C2: 機能名 | F2: 分類 | G2: 機能画面説明 | H2: 項目数 | I2: 難易度 | J2: 新規 改修 | K2: 工程別工数（人日） | R2: 合計 （人日） | S2: 合計 （人月） | T2: 備考
C3: 大項目 | D3: 中項目 | E3: 小項目 | K3: 要件定義 | L3: レビュー | M3: 設計 | N3: レビュー | O3: 開発/単体テスト | P3: 結合(総合)テスト | Q3: 受入テスト
A4: 基準工数 | K4: =積算基準!D58 -> 1 | M4: =積算基準!E58 -> 3.125 | O4: =積算基準!F58 -> 3.25 | P4: =積算基準!G58 -> 2.625 | Q4: =積算基準!H58 -> 0.375
A5: =ROW()-4 -> 1 | B5: アスファルト受注業務システム構築 | C5: 共通 | D5: アーキテクチャ | F5: 機能 | G5: システムアーキテクチャを構築 | I5: 特高 | J5: 新規 | K5: =CEILING(IF($J5="新規", IF($I5="特高", K$4*特高係数,IF($I5="高",K$4*高係数,IF($I5="中",K$4*中係数,IF($I5="低",K$4*低係数, IF($I5="特低",K$4*特低係数, 0))))), IF($I5="特高", K$4*特高係数,IF($I5="高",K$4*高係数,IF($I5="中",K$4*中係数,IF($I5="低",K$4*低係数, IF($I5="特低",K$4*特低係数, 0)))))),0.125) -> 2.625 | L5: =K5*0.2 -> 0.525 | M5: =CEILING(IF($J5="新規", IF($I5="特高", M$4*特高係数,IF($I5="高",M$4*高係数,IF($I5="中",M$4*中係数,IF($I5="低",M$4*低係数, IF($I5="特低",M$4*特低係数, 0))))), IF($I5="特高", M$4*特高係数,IF($I5="高",M$4*高係数,IF($I5="中",M$4*中係数,IF($I5="低",M$4*低係数, IF($I5="特低",M$4*特低係数, 0)))))),0.125) -> 8.125 | N5: 0.525 | O5: =CEILING(IF($J5="新規", IF($I5="特高", O$4*特高係数,IF($I5="高",O$4*高係数,IF($I5="中",O$4*中係数,IF($I5="低",O$4*低係数, IF($I5="特低",O$4*特低係数, 0))))), IF($I5="特高", O$4*特高係数,IF($I5="高",O$4*高係数,IF($I5="中",O$4*中係数,IF($I5="低",O$4*低係数, IF($I5="特低",O$4*特低係数, 0)))))),0.125) -> 8.5 | P5: =CEILING(IF($J5="新規", IF($I5="特高", P$4*特高係数,IF($I5="高",P$4*高係数,IF($I5="中",P$4*中係数,IF($I5="低",P$4*低係数, IF($I5="特低",P$4*特低係数, 0))))), IF($I5="特高", P$4*特高係数,IF($I5="高",P$4*高係数,IF($I5="中",P$4*中係数,IF($I5="低",P$4*低係数, IF($I5="特低",P$4*特低係数, 0)))))),0.125) -> 6.875 | Q5: =CEILING(IF($J5="新規", IF($I5="特高", Q$4*特高係数,IF($I5="高",Q$4*高係数,IF($I5="中",Q$4*中係数,IF($I5="低",Q$4*低係数, IF($I5="特低",Q$4*特低係数, 0))))), IF($I5="特高", Q$4*特高係数,IF($I5="高",Q$4*高係数,IF($I5="中",Q$4*中係数,IF($I5="低",Q$4*低係数, IF($I5="特低",Q$4*特低係数, 0)))))),0.125) -> 1 | R5: =SUM(K5:Q5) -> 28.175 | S5: =R5/20 -> 1.40875
A6: =ROW()-4 -> 2 | D6: 認証 | F6: 機能 | G6: 出光共通認証基盤を利用 ・出光社員はIDMにて認証 ・外部ユーザーは別途認証 | I6: 特高 | J6: 新規 | K6: =CEILING(IF($J6="新規", IF($I6="特高", K$4*特高係数,IF($I6="高",K$4*高係数,IF($I6="中",K$4*中係数,IF($I6="低",K$4*低係数, IF($I6="特低",K$4*特低係数, 0))))), IF($I6="特高", K$4*特高係数,IF($I6="高",K$4*高係数,IF($I6="中",K$4*中係数,IF($I6="低",K$4*低係数, IF($I6="特低",K$4*特低係数, 0)))))),0.125) -> 2.625 | L6: =K6*0.2 -> 0.525 | M6: =CEILING(IF($J6="新規", IF($I6="特高", M$4*特高係数,IF($I6="高",M$4*高係数,IF($I6="中",M$4*中係数,IF($I6="低",M$4*低係数, IF($I6="特低",M$4*特低係数, 0))))), IF($I6="特高", M$4*特高係数,IF($I6="高",M$4*高係数,IF($I6="中",M$4*中係数,IF($I6="低",M$4*低係数, IF($I6="特低",M$4*特低係数, 0)))))),0.125) -> 8.125 | N6: 0.525 | O6: =CEILING(IF($J6="新規", IF($I6="特高", O$4*特高係数,IF($I6="高",O$4*高係数,IF($I6="中",O$4*中係数,IF($I6="低",O$4*低係数, IF($I6="特低",O$4*特低係数, 0))))), IF($I6="特高", O$4*特高係数,IF($I6="高",O$4*高係数,IF($I6="中",O$4*中係数,IF($I6="低",O$4*低係数, IF($I6="特低",O$4*特低係数, 0)))))),0.125) -> 8.5 | P6: =CEILING(IF($J6="新規", IF($I6="特高", P$4*特高係数,IF($I6="高",P$4*高係数,IF($I6="中",P$4*中係数,IF($I6="低",P$4*低係数, IF($I6="特低",P$4*特低係数, 0))))), IF($I6="特高", P$4*特高係数,IF($I6="高",P$4*高係数,IF($I6="中",P$4*中係数,IF($I6="低",P$4*低係数, IF($I6="特低",P$4*特低係数, 0)))))),0.125) -> 6.875 | Q6: =CEILING(IF($J6="新規", IF($I6="特高", Q$4*特高係数,IF($I6="高",Q$4*高係数,IF($I6="中",Q$4*中係数,IF($I6="低",Q$4*低係数, IF($I6="特低",Q$4*特低係数, 0))))), IF($I6="特高", Q$4*特高係数,IF($I6="高",Q$4*高係数,IF($I6="中",Q$4*中係数,IF($I6="低",Q$4*低係数, IF($I6="特低",Q$4*特低係数, 0)))))),0.125) -> 1 | R6: =SUM(K6:Q6) -> 28.175 | S6: =R6/20 -> 1.40875
A7: =ROW()-4 -> 3 | D7: 権限管理 | F7: 機能 | G7: 出光権限管理IDMシステムを利用 | I7: 高 | J7: 新規 | K7: =CEILING(IF($J7="新規", IF($I7="特高", K$4*特高係数,IF($I7="高",K$4*高係数,IF($I7="中",K$4*中係数,IF($I7="低",K$4*低係数, IF($I7="特低",K$4*特低係数, 0))))), IF($I7="特高", K$4*特高係数,IF($I7="高",K$4*高係数,IF($I7="中",K$4*中係数,IF($I7="低",K$4*低係数, IF($I7="特低",K$4*特低係数, 0)))))),0.125) -> 2 | L7: =K7*0.2 -> 0.4 | M7: =CEILING(IF($J7="新規", IF($I7="特高", M$4*特高係数,IF($I7="高",M$4*高係数,IF($I7="中",M$4*中係数,IF($I7="低",M$4*低係数, IF($I7="特低",M$4*特低係数, 0))))), IF($I7="特高", M$4*特高係数,IF($I7="高",M$4*高係数,IF($I7="中",M$4*中係数,IF($I7="低",M$4*低係数, IF($I7="特低",M$4*特低係数, 0)))))),0.125) -> 6.25 | N7: 0.525 | O7: =CEILING(IF($J7="新規", IF($I7="特高", O$4*特高係数,IF($I7="高",O$4*高係数,IF($I7="中",O$4*中係数,IF($I7="低",O$4*低係数, IF($I7="特低",O$4*特低係数, 0))))), IF($I7="特高", O$4*特高係数,IF($I7="高",O$4*高係数,IF($I7="中",O$4*中係数,IF($I7="低",O$4*低係数, IF($I7="特低",O$4*特低係数, 0)))))),0.125) -> 6.5 | P7: =CEILING(IF($J7="新規", IF($I7="特高", P$4*特高係数,IF($I7="高",P$4*高係数,IF($I7="中",P$4*中係数,IF($I7="低",P$4*低係数, IF($I7="特低",P$4*特低係数, 0))))), IF($I7="特高", P$4*特高係数,IF($I7="高",P$4*高係数,IF($I7="中",P$4*中係数,IF($I7="低",P$4*低係数, IF($I7="特低",P$4*特低係数, 0)))))),0.125) -> 5.25 | Q7: =CEILING(IF($J7="新規", IF($I7="特高", Q$4*特高係数,IF($I7="高",Q$4*高係数,IF($I7="中",Q$4*中係数,IF($I7="低",Q$4*低係数, IF($I7="特低",Q$4*特低係数, 0))))), IF($I7="特高", Q$4*特高係数,IF($I7="高",Q$4*高係数,IF($I7="中",Q$4*中係数,IF($I7="低",Q$4*低係数, IF($I7="特低",Q$4*特低係数, 0)))))),0.125) -> 0.75 | R7: =SUM(K7:Q7) -> 21.675 | S7: =R7/20 -> 1.08375
A8: =ROW()-4 -> 4 | C8: ログイン | D8: ログイン画面 | F8: 画面 | G8: ・ログイン（出光社員、外部ユーザー） | I8: 低 | J8: 新規 | K8: =CEILING(IF($J8="新規", IF($I8="特高", K$4*特高係数,IF($I8="高",K$4*高係数,IF($I8="中",K$4*中係数,IF($I8="低",K$4*低係数, IF($I8="特低",K$4*特低係数, 0))))), IF($I8="特高", K$4*特高係数,IF($I8="高",K$4*高係数,IF($I8="中",K$4*中係数,IF($I8="低",K$4*低係数, IF($I8="特低",K$4*特低係数, 0)))))),0.125) -> 0.75 | L8: =K8*0.2 -> 0.15 | M8: =CEILING(IF($J8="新規", IF($I8="特高", M$4*特高係数,IF($I8="高",M$4*高係数,IF($I8="中",M$4*中係数,IF($I8="低",M$4*低係数, IF($I8="特低",M$4*特低係数, 0))))), IF($I8="特高", M$4*特高係数,IF($I8="高",M$4*高係数,IF($I8="中",M$4*中係数,IF($I8="低",M$4*低係数, IF($I8="特低",M$4*特低係数, 0)))))),0.125) -> 2.25 | N8: 0.525 | O8: =CEILING(IF($J8="新規", IF($I8="特高", O$4*特高係数,IF($I8="高",O$4*高係数,IF($I8="中",O$4*中係数,IF($I8="低",O$4*低係数, IF($I8="特低",O$4*特低係数, 0))))), IF($I8="特高", O$4*特高係数,IF($I8="高",O$4*高係数,IF($I8="中",O$4*中係数,IF($I8="低",O$4*低係数, IF($I8="特低",O$4*特低係数, 0)))))),0.125) -> 2.375 | P8: =CEILING(IF($J8="新規", IF($I8="特高", P$4*特高係数,IF($I8="高",P$4*高係数,IF($I8="中",P$4*中係数,IF($I8="低",P$4*低係数, IF($I8="特低",P$4*特低係数, 0))))), IF($I8="特高", P$4*特高係数,IF($I8="高",P$4*高係数,IF($I8="中",P$4*中係数,IF($I8="低",P$4*低係数, IF($I8="特低",P$4*特低係数, 0)))))),0.125) -> 1.875 | Q8: =CEILING(IF($J8="新規", IF($I8="特高", Q$4*特高係数,IF($I8="高",Q$4*高係数,IF($I8="中",Q$4*中係数,IF($I8="低",Q$4*低係数, IF($I8="特低",Q$4*特低係数, 0))))), IF($I8="特高", Q$4*特高係数,IF($I8="高",Q$4*高係数,IF($I8="中",Q$4*中係数,IF($I8="低",Q$4*低係数, IF($I8="特低",Q$4*特低係数, 0)))))),0.125) -> 0.375 | R8: =SUM(K8:Q8) -> 8.3 | S8: =R8/20 -> 0.415
A9: =ROW()-4 -> 5 | C9: 発注 （特販店、需要家） | D9: 注文一覧画面 | F9: 画面 | G9: ・注文一覧の表示 ・検索（各ステータスを検索可能とする。注文中、注文確定、過去履歴など） ・新規注文ボタン ・複写新規ボタン | I9: 高 | J9: 新規 | K9: =CEILING(IF($J9="新規", IF($I9="特高", K$4*特高係数,IF($I9="高",K$4*高係数,IF($I9="中",K$4*中係数,IF($I9="低",K$4*低係数, IF($I9="特低",K$4*特低係数, 0))))), IF($I9="特高", K$4*特高係数,IF($I9="高",K$4*高係数,IF($I9="中",K$4*中係数,IF($I9="低",K$4*低係数, IF($I9="特低",K$4*特低係数, 0)))))),0.125) -> 2 | L9: =K9*0.2 -> 0.4 | M9: =CEILING(IF($J9="新規", IF($I9="特高", M$4*特高係数,IF($I9="高",M$4*高係数,IF($I9="中",M$4*中係数,IF($I9="低",M$4*低係数, IF($I9="特低",M$4*特低係数, 0))))), IF($I9="特高", M$4*特高係数,IF($I9="高",M$4*高係数,IF($I9="中",M$4*中係数,IF($I9="低",M$4*低係数, IF($I9="特低",M$4*特低係数, 0)))))),0.125) -> 6.25 | N9: 0.525 | O9: =CEILING(IF($J9="新規", IF($I9="特高", O$4*特高係数,IF($I9="高",O$4*高係数,IF($I9="中",O$4*中係数,IF($I9="低",O$4*低係数, IF($I9="特低",O$4*特低係数, 0))))), IF($I9="特高", O$4*特高係数,IF($I9="高",O$4*高係数,IF($I9="中",O$4*中係数,IF($I9="低",O$4*低係数, IF($I9="特低",O$4*特低係数, 0)))))),0.125) -> 6.5 | P9: =CEILING(IF($J9="新規", IF($I9="特高", P$4*特高係数,IF($I9="高",P$4*高係数,IF($I9="中",P$4*中係数,IF($I9="低",P$4*低係数, IF($I9="特低",P$4*特低係数, 0))))), IF($I9="特高", P$4*特高係数,IF($I9="高",P$4*高係数,IF($I9="中",P$4*中係数,IF($I9="低",P$4*低係数, IF($I9="特低",P$4*特低係数, 0)))))),0.125) -> 5.25 | Q9: =CEILING(IF($J9="新規", IF($I9="特高", Q$4*特高係数,IF($I9="高",Q$4*高係数,IF($I9="中",Q$4*中係数,IF($I9="低",Q$4*低係数, IF($I9="特低",Q$4*特低係数, 0))))), IF($I9="特高", Q$4*特高係数,IF($I9="高",Q$4*高係数,IF($I9="中",Q$4*中係数,IF($I9="低",Q$4*低係数, IF($I9="特低",Q$4*特低係数, 0)))))),0.125) -> 0.75 | R9: =SUM(K9:Q9) -> 21.675 | S9: =R9/20 -> 1.08375
A10: =ROW()-4 -> 6 | D10: 注文画面 | F10: 機能 | G10: ・注文情報の表示 ・注文情報の入力 ・マスタより出荷基地を設定（変更可）※注文者に紐づく出荷基地がある ・マスタより運送会社を設定（変更可）※注文者に紐づく運送会社がある ・マスタより積時間を仮決定（変更可） ⇒希望着日時は30分単位、AM/PM/終日フリーが選択可 ⇒選択可能な希望着日時は基地により異なる（選べないかバリデーションエラーにするかは要検討）。年末年始などイレギュラー都合を考慮し、受注不可日時も基地ごとに事前設定できるようにしたい。（希望着日時の混雑状況をわかるようにしなくてよい。） ・必須入力（品目、数量、出荷基地、出荷先、希望着日時、第1運送会社、第2運送会社） ※品目ごとに数量単位が異なる ・バリデーション ・一時保存 ・注文登録 | I10: 特高 | J10: 新規 | K10: =CEILING(IF($J10="新規", IF($I10="特高", K$4*特高係数,IF($I10="高",K$4*高係数,IF($I10="中",K$4*中係数,IF($I10="低",K$4*低係数, IF($I10="特低",K$4*特低係数, 0))))), IF($I10="特高", K$4*特高係数,IF($I10="高",K$4*高係数,IF($I10="中",K$4*中係数,IF($I10="低",K$4*低係数, IF($I10="特低",K$4*特低係数, 0)))))),0.125) -> 2.625 | L10: =K10*0.2 -> 0.525 | M10: =CEILING(IF($J10="新規", IF($I10="特高", M$4*特高係数,IF($I10="高",M$4*高係数,IF($I10="中",M$4*中係数,IF($I10="低",M$4*低係数, IF($I10="特低",M$4*特低係数, 0))))), IF($I10="特高", M$4*特高係数,IF($I10="高",M$4*高係数,IF($I10="中",M$4*中係数,IF($I10="低",M$4*低係数, IF($I10="特低",M$4*特低係数, 0)))))),0.125) -> 8.125 | N10: 0.325 | O10: =CEILING(IF($J10="新規", IF($I10="特高", O$4*特高係数,IF($I10="高",O$4*高係数,IF($I10="中",O$4*中係数,IF($I10="低",O$4*低係数, IF($I10="特低",O$4*特低係数, 0))))), IF($I10="特高", O$4*特高係数,IF($I10="高",O$4*高係数,IF($I10="中",O$4*中係数,IF($I10="低",O$4*低係数, IF($I10="特低",O$4*特低係数, 0)))))),0.125) -> 8.5 | P10: =CEILING(IF($J10="新規", IF($I10="特高", P$4*特高係数,IF($I10="高",P$4*高係数,IF($I10="中",P$4*中係数,IF($I10="低",P$4*低係数, IF($I10="特低",P$4*特低係数, 0))))), IF($I10="特高", P$4*特高係数,IF($I10="高",P$4*高係数,IF($I10="中",P$4*中係数,IF($I10="低",P$4*低係数, IF($I10="特低",P$4*特低係数, 0)))))),0.125) -> 6.875 | Q10: =CEILING(IF($J10="新規", IF($I10="特高", Q$4*特高係数,IF($I10="高",Q$4*高係数,IF($I10="中",Q$4*中係数,IF($I10="低",Q$4*低係数, IF($I10="特低",Q$4*特低係数, 0))))), IF($I10="特高", Q$4*特高係数,IF($I10="高",Q$4*高係数,IF($I10="中",Q$4*中係数,IF($I10="低",Q$4*低係数, IF($I10="特低",Q$4*特低係数, 0)))))),0.125) -> 1 | R10: =SUM(K10:Q10) -> 27.975 | S10: =R10/20 -> 1.39875
A11: =ROW()-4 -> 7 | C11: 出荷確認 （基地） | D11: 注文一覧画面 | F11: 画面 | G11: 発注時と同様 ※権限制御、テストのみ考慮する | I11: 特低 | J11: 新規 | K11: =CEILING(IF($J11="新規", IF($I11="特高", K$4*特高係数,IF($I11="高",K$4*高係数,IF($I11="中",K$4*中係数,IF($I11="低",K$4*低係数, IF($I11="特低",K$4*特低係数, 0))))), IF($I11="特高", K$4*特高係数,IF($I11="高",K$4*高係数,IF($I11="中",K$4*中係数,IF($I11="低",K$4*低係数, IF($I11="特低",K$4*特低係数, 0)))))),0.125) -> 0.375 | L11: =K11*0.2 -> 0.075 | M11: =CEILING(IF($J11="新規", IF($I11="特高", M$4*特高係数,IF($I11="高",M$4*高係数,IF($I11="中",M$4*中係数,IF($I11="低",M$4*低係数, IF($I11="特低",M$4*特低係数, 0))))), IF($I11="特高", M$4*特高係数,IF($I11="高",M$4*高係数,IF($I11="中",M$4*中係数,IF($I11="低",M$4*低係数, IF($I11="特低",M$4*特低係数, 0)))))),0.125) -> 1 | N11: 0.15 | O11: =CEILING(IF($J11="新規", IF($I11="特高", O$4*特高係数,IF($I11="高",O$4*高係数,IF($I11="中",O$4*中係数,IF($I11="低",O$4*低係数, IF($I11="特低",O$4*特低係数, 0))))), IF($I11="特高", O$4*特高係数,IF($I11="高",O$4*高係数,IF($I11="中",O$4*中係数,IF($I11="低",O$4*低係数, IF($I11="特低",O$4*特低係数, 0)))))),0.125) -> 1 | P11: =CEILING(IF($J11="新規", IF($I11="特高", P$4*特高係数,IF($I11="高",P$4*高係数,IF($I11="中",P$4*中係数,IF($I11="低",P$4*低係数, IF($I11="特低",P$4*特低係数, 0))))), IF($I11="特高", P$4*特高係数,IF($I11="高",P$4*高係数,IF($I11="中",P$4*中係数,IF($I11="低",P$4*低係数, IF($I11="特低",P$4*特低係数, 0)))))),0.125) -> 0.875 | Q11: =CEILING(IF($J11="新規", IF($I11="特高", Q$4*特高係数,IF($I11="高",Q$4*高係数,IF($I11="中",Q$4*中係数,IF($I11="低",Q$4*低係数, IF($I11="特低",Q$4*特低係数, 0))))), IF($I11="特高", Q$4*特高係数,IF($I11="高",Q$4*高係数,IF($I11="中",Q$4*中係数,IF($I11="低",Q$4*低係数, IF($I11="特低",Q$4*特低係数, 0)))))),0.125) -> 0.125 | R11: =SUM(K11:Q11) -> 3.6 | S11: =R11/20 -> 0.18
A12: =ROW()-4 -> 8 | D12: 注文画面 | F12: 画面 | G12: 発注時と同様 ※権限制御、テストのみ考慮する | I12: 特低 | J12: 新規 | K12: =CEILING(IF($J12="新規", IF($I12="特高", K$4*特高係数,IF($I12="高",K$4*高係数,IF($I12="中",K$4*中係数,IF($I12="低",K$4*低係数, IF($I12="特低",K$4*特低係数, 0))))), IF($I12="特高", K$4*特高係数,IF($I12="高",K$4*高係数,IF($I12="中",K$4*中係数,IF($I12="低",K$4*低係数, IF($I12="特低",K$4*特低係数, 0)))))),0.125) -> 0.375 | L12: =K12*0.2 -> 0.075 | M12: =CEILING(IF($J12="新規", IF($I12="特高", M$4*特高係数,IF($I12="高",M$4*高係数,IF($I12="中",M$4*中係数,IF($I12="低",M$4*低係数, IF($I12="特低",M$4*特低係数, 0))))), IF($I12="特高", M$4*特高係数,IF($I12="高",M$4*高係数,IF($I12="中",M$4*中係数,IF($I12="低",M$4*低係数, IF($I12="特低",M$4*特低係数, 0)))))),0.125) -> 1 | N12: 0.325 | O12: =CEILING(IF($J12="新規", IF($I12="特高", O$4*特高係数,IF($I12="高",O$4*高係数,IF($I12="中",O$4*中係数,IF($I12="低",O$4*低係数, IF($I12="特低",O$4*特低係数, 0))))), IF($I12="特高", O$4*特高係数,IF($I12="高",O$4*高係数,IF($I12="中",O$4*中係数,IF($I12="低",O$4*低係数, IF($I12="特低",O$4*特低係数, 0)))))),0.125) -> 1 | P12: =CEILING(IF($J12="新規", IF($I12="特高", P$4*特高係数,IF($I12="高",P$4*高係数,IF($I12="中",P$4*中係数,IF($I12="低",P$4*低係数, IF($I12="特低",P$4*特低係数, 0))))), IF($I12="特高", P$4*特高係数,IF($I12="高",P$4*高係数,IF($I12="中",P$4*中係数,IF($I12="低",P$4*低係数, IF($I12="特低",P$4*特低係数, 0)))))),0.125) -> 0.875 | Q12: =CEILING(IF($J12="新規", IF($I12="特高", Q$4*特高係数,IF($I12="高",Q$4*高係数,IF($I12="中",Q$4*中係数,IF($I12="低",Q$4*低係数, IF($I12="特低",Q$4*特低係数, 0))))), IF($I12="特高", Q$4*特高係数,IF($I12="高",Q$4*高係数,IF($I12="中",Q$4*中係数,IF($I12="低",Q$4*低係数, IF($I12="特低",Q$4*特低係数, 0)))))),0.125) -> 0.125 | R12: =SUM(K12:Q12) -> 3.775 | S12: =R12/20 -> 0.18875
A13: =ROW()-4 -> 9 | D13: 出荷画面 | F13: 画面 | G13: ・出荷情報（積時間、出荷可否）の入力 ※在庫・生産計画は別システムにて確認するため、スコープ外 ・バリデーション ・出荷可否登録 ・注文NGメール送付 | I13: 特高 | J13: 新規 | K13: =CEILING(IF($J13="新規", IF($I13="特高", K$4*特高係数,IF($I13="高",K$4*高係数,IF($I13="中",K$4*中係数,IF($I13="低",K$4*低係数, IF($I13="特低",K$4*特低係数, 0))))), IF($I13="特高", K$4*特高係数,IF($I13="高",K$4*高係数,IF($I13="中",K$4*中係数,IF($I13="低",K$4*低係数, IF($I13="特低",K$4*特低係数, 0)))))),0.125) -> 2.625 | L13: =K13*0.2 -> 0.525 | M13: =CEILING(IF($J13="新規", IF($I13="特高", M$4*特高係数,IF($I13="高",M$4*高係数,IF($I13="中",M$4*中係数,IF($I13="低",M$4*低係数, IF($I13="特低",M$4*特低係数, 0))))), IF($I13="特高", M$4*特高係数,IF($I13="高",M$4*高係数,IF($I13="中",M$4*中係数,IF($I13="低",M$4*低係数, IF($I13="特低",M$4*特低係数, 0)))))),0.125) -> 8.125 | N13: 0.325 | O13: =CEILING(IF($J13="新規", IF($I13="特高", O$4*特高係数,IF($I13="高",O$4*高係数,IF($I13="中",O$4*中係数,IF($I13="低",O$4*低係数, IF($I13="特低",O$4*特低係数, 0))))), IF($I13="特高", O$4*特高係数,IF($I13="高",O$4*高係数,IF($I13="中",O$4*中係数,IF($I13="低",O$4*低係数, IF($I13="特低",O$4*特低係数, 0)))))),0.125) -> 8.5 | P13: =CEILING(IF($J13="新規", IF($I13="特高", P$4*特高係数,IF($I13="高",P$4*高係数,IF($I13="中",P$4*中係数,IF($I13="低",P$4*低係数, IF($I13="特低",P$4*特低係数, 0))))), IF($I13="特高", P$4*特高係数,IF($I13="高",P$4*高係数,IF($I13="中",P$4*中係数,IF($I13="低",P$4*低係数, IF($I13="特低",P$4*特低係数, 0)))))),0.125) -> 6.875 | Q13: =CEILING(IF($J13="新規", IF($I13="特高", Q$4*特高係数,IF($I13="高",Q$4*高係数,IF($I13="中",Q$4*中係数,IF($I13="低",Q$4*低係数, IF($I13="特低",Q$4*特低係数, 0))))), IF($I13="特高", Q$4*特高係数,IF($I13="高",Q$4*高係数,IF($I13="中",Q$4*中係数,IF($I13="低",Q$4*低係数, IF($I13="特低",Q$4*特低係数, 0)))))),0.125) -> 1 | R13: =SUM(K13:Q13) -> 27.975 | S13: =R13/20 -> 1.39875
A14: =ROW()-4 -> 10 | C14: 運送手配 （運送会社） | D14: 注文一覧画面 | F14: 画面 | G14: 出荷確認時と同様 ※権限制御、テストのみ考慮する | I14: 特低 | J14: 新規 | K14: =CEILING(IF($J14="新規", IF($I14="特高", K$4*特高係数,IF($I14="高",K$4*高係数,IF($I14="中",K$4*中係数,IF($I14="低",K$4*低係数, IF($I14="特低",K$4*特低係数, 0))))), IF($I14="特高", K$4*特高係数,IF($I14="高",K$4*高係数,IF($I14="中",K$4*中係数,IF($I14="低",K$4*低係数, IF($I14="特低",K$4*特低係数, 0)))))),0.125) -> 0.375 | L14: =K14*0.2 -> 0.075 | M14: =CEILING(IF($J14="新規", IF($I14="特高", M$4*特高係数,IF($I14="高",M$4*高係数,IF($I14="中",M$4*中係数,IF($I14="低",M$4*低係数, IF($I14="特低",M$4*特低係数, 0))))), IF($I14="特高", M$4*特高係数,IF($I14="高",M$4*高係数,IF($I14="中",M$4*中係数,IF($I14="低",M$4*低係数, IF($I14="特低",M$4*特低係数, 0)))))),0.125) -> 1 | N14: 0.525 | O14: =CEILING(IF($J14="新規", IF($I14="特高", O$4*特高係数,IF($I14="高",O$4*高係数,IF($I14="中",O$4*中係数,IF($I14="低",O$4*低係数, IF($I14="特低",O$4*特低係数, 0))))), IF($I14="特高", O$4*特高係数,IF($I14="高",O$4*高係数,IF($I14="中",O$4*中係数,IF($I14="低",O$4*低係数, IF($I14="特低",O$4*特低係数, 0)))))),0.125) -> 1 | P14: =CEILING(IF($J14="新規", IF($I14="特高", P$4*特高係数,IF($I14="高",P$4*高係数,IF($I14="中",P$4*中係数,IF($I14="低",P$4*低係数, IF($I14="特低",P$4*特低係数, 0))))), IF($I14="特高", P$4*特高係数,IF($I14="高",P$4*高係数,IF($I14="中",P$4*中係数,IF($I14="低",P$4*低係数, IF($I14="特低",P$4*特低係数, 0)))))),0.125) -> 0.875 | Q14: =CEILING(IF($J14="新規", IF($I14="特高", Q$4*特高係数,IF($I14="高",Q$4*高係数,IF($I14="中",Q$4*中係数,IF($I14="低",Q$4*低係数, IF($I14="特低",Q$4*特低係数, 0))))), IF($I14="特高", Q$4*特高係数,IF($I14="高",Q$4*高係数,IF($I14="中",Q$4*中係数,IF($I14="低",Q$4*低係数, IF($I14="特低",Q$4*特低係数, 0)))))),0.125) -> 0.125 | R14: =SUM(K14:Q14) -> 3.975 | S14: =R14/20 -> 0.19875
A15: =ROW()-4 -> 11 | D15: 注文画面 | F15: 画面 | G15: 出荷確認時と同様 ※権限制御、テストのみ考慮する | I15: 特低 | J15: 新規 | K15: =CEILING(IF($J15="新規", IF($I15="特高", K$4*特高係数,IF($I15="高",K$4*高係数,IF($I15="中",K$4*中係数,IF($I15="低",K$4*低係数, IF($I15="特低",K$4*特低係数, 0))))), IF($I15="特高", K$4*特高係数,IF($I15="高",K$4*高係数,IF($I15="中",K$4*中係数,IF($I15="低",K$4*低係数, IF($I15="特低",K$4*特低係数, 0)))))),0.125) -> 0.375 | L15: =K15*0.2 -> 0.075 | M15: =CEILING(IF($J15="新規", IF($I15="特高", M$4*特高係数,IF($I15="高",M$4*高係数,IF($I15="中",M$4*中係数,IF($I15="低",M$4*低係数, IF($I15="特低",M$4*特低係数, 0))))), IF($I15="特高", M$4*特高係数,IF($I15="高",M$4*高係数,IF($I15="中",M$4*中係数,IF($I15="低",M$4*低係数, IF($I15="特低",M$4*特低係数, 0)))))),0.125) -> 1 | N15: 0.525 | O15: =CEILING(IF($J15="新規", IF($I15="特高", O$4*特高係数,IF($I15="高",O$4*高係数,IF($I15="中",O$4*中係数,IF($I15="低",O$4*低係数, IF($I15="特低",O$4*特低係数, 0))))), IF($I15="特高", O$4*特高係数,IF($I15="高",O$4*高係数,IF($I15="中",O$4*中係数,IF($I15="低",O$4*低係数, IF($I15="特低",O$4*特低係数, 0)))))),0.125) -> 1 | P15: =CEILING(IF($J15="新規", IF($I15="特高", P$4*特高係数,IF($I15="高",P$4*高係数,IF($I15="中",P$4*中係数,IF($I15="低",P$4*低係数, IF($I15="特低",P$4*特低係数, 0))))), IF($I15="特高", P$4*特高係数,IF($I15="高",P$4*高係数,IF($I15="中",P$4*中係数,IF($I15="低",P$4*低係数, IF($I15="特低",P$4*特低係数, 0)))))),0.125) -> 0.875 | Q15: =CEILING(IF($J15="新規", IF($I15="特高", Q$4*特高係数,IF($I15="高",Q$4*高係数,IF($I15="中",Q$4*中係数,IF($I15="低",Q$4*低係数, IF($I15="特低",Q$4*特低係数, 0))))), IF($I15="特高", Q$4*特高係数,IF($I15="高",Q$4*高係数,IF($I15="中",Q$4*中係数,IF($I15="低",Q$4*低係数, IF($I15="特低",Q$4*特低係数, 0)))))),0.125) -> 0.125 | R15: =SUM(K15:Q15) -> 3.975 | S15: =R15/20 -> 0.19875
A16: =ROW()-4 -> 12 | D16: 出荷画面 | F16: 画面 | G16: 出荷確認時と同様 ※権限制御、テストのみ考慮する | I16: 特低 | J16: 新規 | K16: =CEILING(IF($J16="新規", IF($I16="特高", K$4*特高係数,IF($I16="高",K$4*高係数,IF($I16="中",K$4*中係数,IF($I16="低",K$4*低係数, IF($I16="特低",K$4*特低係数, 0))))), IF($I16="特高", K$4*特高係数,IF($I16="高",K$4*高係数,IF($I16="中",K$4*中係数,IF($I16="低",K$4*低係数, IF($I16="特低",K$4*特低係数, 0)))))),0.125) -> 0.375 | L16: =K16*0.2 -> 0.075 | M16: =CEILING(IF($J16="新規", IF($I16="特高", M$4*特高係数,IF($I16="高",M$4*高係数,IF($I16="中",M$4*中係数,IF($I16="低",M$4*低係数, IF($I16="特低",M$4*特低係数, 0))))), IF($I16="特高", M$4*特高係数,IF($I16="高",M$4*高係数,IF($I16="中",M$4*中係数,IF($I16="低",M$4*低係数, IF($I16="特低",M$4*特低係数, 0)))))),0.125) -> 1 | N16: 0.325 | O16: =CEILING(IF($J16="新規", IF($I16="特高", O$4*特高係数,IF($I16="高",O$4*高係数,IF($I16="中",O$4*中係数,IF($I16="低",O$4*低係数, IF($I16="特低",O$4*特低係数, 0))))), IF($I16="特高", O$4*特高係数,IF($I16="高",O$4*高係数,IF($I16="中",O$4*中係数,IF($I16="低",O$4*低係数, IF($I16="特低",O$4*特低係数, 0)))))),0.125) -> 1 | P16: =CEILING(IF($J16="新規", IF($I16="特高", P$4*特高係数,IF($I16="高",P$4*高係数,IF($I16="中",P$4*中係数,IF($I16="低",P$4*低係数, IF($I16="特低",P$4*特低係数, 0))))), IF($I16="特高", P$4*特高係数,IF($I16="高",P$4*高係数,IF($I16="中",P$4*中係数,IF($I16="低",P$4*低係数, IF($I16="特低",P$4*特低係数, 0)))))),0.125) -> 0.875 | Q16: =CEILING(IF($J16="新規", IF($I16="特高", Q$4*特高係数,IF($I16="高",Q$4*高係数,IF($I16="中",Q$4*中係数,IF($I16="低",Q$4*低係数, IF($I16="特低",Q$4*特低係数, 0))))), IF($I16="特高", Q$4*特高係数,IF($I16="高",Q$4*高係数,IF($I16="中",Q$4*中係数,IF($I16="低",Q$4*低係数, IF($I16="特低",Q$4*特低係数, 0)))))),0.125) -> 0.125 | R16: =SUM(K16:Q16) -> 3.775 | S16: =R16/20 -> 0.18875
A17: =ROW()-4 -> 13 | D17: 車両手配画面 | F17: 画面 | G17: ・車両手配情報（車番、運送可否）の入力 ・バリデーション ・運送会社変更 ・運送可否登録 ・注文NGメール送付 | I17: 特高 | J17: 新規 | K17: =CEILING(IF($J17="新規", IF($I17="特高", K$4*特高係数,IF($I17="高",K$4*高係数,IF($I17="中",K$4*中係数,IF($I17="低",K$4*低係数, IF($I17="特低",K$4*特低係数, 0))))), IF($I17="特高", K$4*特高係数,IF($I17="高",K$4*高係数,IF($I17="中",K$4*中係数,IF($I17="低",K$4*低係数, IF($I17="特低",K$4*特低係数, 0)))))),0.125) -> 2.625 | L17: =K17*0.2 -> 0.525 | M17: =CEILING(IF($J17="新規", IF($I17="特高", M$4*特高係数,IF($I17="高",M$4*高係数,IF($I17="中",M$4*中係数,IF($I17="低",M$4*低係数, IF($I17="特低",M$4*特低係数, 0))))), IF($I17="特高", M$4*特高係数,IF($I17="高",M$4*高係数,IF($I17="中",M$4*中係数,IF($I17="低",M$4*低係数, IF($I17="特低",M$4*特低係数, 0)))))),0.125) -> 8.125 | N17: 0.325 | O17: =CEILING(IF($J17="新規", IF($I17="特高", O$4*特高係数,IF($I17="高",O$4*高係数,IF($I17="中",O$4*中係数,IF($I17="低",O$4*低係数, IF($I17="特低",O$4*特低係数, 0))))), IF($I17="特高", O$4*特高係数,IF($I17="高",O$4*高係数,IF($I17="中",O$4*中係数,IF($I17="低",O$4*低係数, IF($I17="特低",O$4*特低係数, 0)))))),0.125) -> 8.5 | P17: =CEILING(IF($J17="新規", IF($I17="特高", P$4*特高係数,IF($I17="高",P$4*高係数,IF($I17="中",P$4*中係数,IF($I17="低",P$4*低係数, IF($I17="特低",P$4*特低係数, 0))))), IF($I17="特高", P$4*特高係数,IF($I17="高",P$4*高係数,IF($I17="中",P$4*中係数,IF($I17="低",P$4*低係数, IF($I17="特低",P$4*特低係数, 0)))))),0.125) -> 6.875 | Q17: =CEILING(IF($J17="新規", IF($I17="特高", Q$4*特高係数,IF($I17="高",Q$4*高係数,IF($I17="中",Q$4*中係数,IF($I17="低",Q$4*低係数, IF($I17="特低",Q$4*特低係数, 0))))), IF($I17="特高", Q$4*特高係数,IF($I17="高",Q$4*高係数,IF($I17="中",Q$4*中係数,IF($I17="低",Q$4*低係数, IF($I17="特低",Q$4*特低係数, 0)))))),0.125) -> 1 | R17: =SUM(K17:Q17) -> 27.975 | S17: =R17/20 -> 1.39875
A18: =ROW()-4 -> 14 | C18: 最終合意 （特販店、需要家） | D18: 最終合意 | F18: 機能 | G18: ・バリデーション（期限など） ・最終合意処理を行う ・受注確定メール送付 | I18: 高 | J18: 新規 | K18: =CEILING(IF($J18="新規", IF($I18="特高", K$4*特高係数,IF($I18="高",K$4*高係数,IF($I18="中",K$4*中係数,IF($I18="低",K$4*低係数, IF($I18="特低",K$4*特低係数, 0))))), IF($I18="特高", K$4*特高係数,IF($I18="高",K$4*高係数,IF($I18="中",K$4*中係数,IF($I18="低",K$4*低係数, IF($I18="特低",K$4*特低係数, 0)))))),0.125) -> 2 | L18: =K18*0.2 -> 0.4 | M18: =CEILING(IF($J18="新規", IF($I18="特高", M$4*特高係数,IF($I18="高",M$4*高係数,IF($I18="中",M$4*中係数,IF($I18="低",M$4*低係数, IF($I18="特低",M$4*特低係数, 0))))), IF($I18="特高", M$4*特高係数,IF($I18="高",M$4*高係数,IF($I18="中",M$4*中係数,IF($I18="低",M$4*低係数, IF($I18="特低",M$4*特低係数, 0)))))),0.125) -> 6.25 | N18: 0.325 | O18: =CEILING(IF($J18="新規", IF($I18="特高", O$4*特高係数,IF($I18="高",O$4*高係数,IF($I18="中",O$4*中係数,IF($I18="低",O$4*低係数, IF($I18="特低",O$4*特低係数, 0))))), IF($I18="特高", O$4*特高係数,IF($I18="高",O$4*高係数,IF($I18="中",O$4*中係数,IF($I18="低",O$4*低係数, IF($I18="特低",O$4*特低係数, 0)))))),0.125) -> 6.5 | P18: =CEILING(IF($J18="新規", IF($I18="特高", P$4*特高係数,IF($I18="高",P$4*高係数,IF($I18="中",P$4*中係数,IF($I18="低",P$4*低係数, IF($I18="特低",P$4*特低係数, 0))))), IF($I18="特高", P$4*特高係数,IF($I18="高",P$4*高係数,IF($I18="中",P$4*中係数,IF($I18="低",P$4*低係数, IF($I18="特低",P$4*特低係数, 0)))))),0.125) -> 5.25 | Q18: =CEILING(IF($J18="新規", IF($I18="特高", Q$4*特高係数,IF($I18="高",Q$4*高係数,IF($I18="中",Q$4*中係数,IF($I18="低",Q$4*低係数, IF($I18="特低",Q$4*特低係数, 0))))), IF($I18="特高", Q$4*特高係数,IF($I18="高",Q$4*高係数,IF($I18="中",Q$4*中係数,IF($I18="低",Q$4*低係数, IF($I18="特低",Q$4*特低係数, 0)))))),0.125) -> 0.75 | R18: =SUM(K18:Q18) -> 21.475 | S18: =R18/20 -> 1.07375
A19: =ROW()-4 -> 15 | C19: マスタ | D19: 品目 | F19: 画面 | G19: ・一覧表示 ・新規登録、編集 ・データ想定 品目 単位 作成時間 | I19: 低 | J19: 新規 | K19: =CEILING(IF($J19="新規", IF($I19="特高", K$4*特高係数,IF($I19="高",K$4*高係数,IF($I19="中",K$4*中係数,IF($I19="低",K$4*低係数, IF($I19="特低",K$4*特低係数, 0))))), IF($I19="特高", K$4*特高係数,IF($I19="高",K$4*高係数,IF($I19="中",K$4*中係数,IF($I19="低",K$4*低係数, IF($I19="特低",K$4*特低係数, 0)))))),0.125) -> 0.75 | L19: =K19*0.2 -> 0.15 | M19: =CEILING(IF($J19="新規", IF($I19="特高", M$4*特高係数,IF($I19="高",M$4*高係数,IF($I19="中",M$4*中係数,IF($I19="低",M$4*低係数, IF($I19="特低",M$4*特低係数, 0))))), IF($I19="特高", M$4*特高係数,IF($I19="高",M$4*高係数,IF($I19="中",M$4*中係数,IF($I19="低",M$4*低係数, IF($I19="特低",M$4*特低係数, 0)))))),0.125) -> 2.25 | N19: 0.4 | O19: =CEILING(IF($J19="新規", IF($I19="特高", O$4*特高係数,IF($I19="高",O$4*高係数,IF($I19="中",O$4*中係数,IF($I19="低",O$4*低係数, IF($I19="特低",O$4*特低係数, 0))))), IF($I19="特高", O$4*特高係数,IF($I19="高",O$4*高係数,IF($I19="中",O$4*中係数,IF($I19="低",O$4*低係数, IF($I19="特低",O$4*特低係数, 0)))))),0.125) -> 2.375 | P19: =CEILING(IF($J19="新規", IF($I19="特高", P$4*特高係数,IF($I19="高",P$4*高係数,IF($I19="中",P$4*中係数,IF($I19="低",P$4*低係数, IF($I19="特低",P$4*特低係数, 0))))), IF($I19="特高", P$4*特高係数,IF($I19="高",P$4*高係数,IF($I19="中",P$4*中係数,IF($I19="低",P$4*低係数, IF($I19="特低",P$4*特低係数, 0)))))),0.125) -> 1.875 | Q19: =CEILING(IF($J19="新規", IF($I19="特高", Q$4*特高係数,IF($I19="高",Q$4*高係数,IF($I19="中",Q$4*中係数,IF($I19="低",Q$4*低係数, IF($I19="特低",Q$4*特低係数, 0))))), IF($I19="特高", Q$4*特高係数,IF($I19="高",Q$4*高係数,IF($I19="中",Q$4*中係数,IF($I19="低",Q$4*低係数, IF($I19="特低",Q$4*特低係数, 0)))))),0.125) -> 0.375 | R19: =SUM(K19:Q19) -> 8.175 | S19: =R19/20 -> 0.40875
A20: =ROW()-4 -> 16 | D20: 出荷基地 | F20: 画面 | G20: ・一覧表示 ・新規登録、編集 ・データ想定 需要家/特販店 出荷基地 | I20: 低 | J20: 新規 | K20: =CEILING(IF($J20="新規", IF($I20="特高", K$4*特高係数,IF($I20="高",K$4*高係数,IF($I20="中",K$4*中係数,IF($I20="低",K$4*低係数, IF($I20="特低",K$4*特低係数, 0))))), IF($I20="特高", K$4*特高係数,IF($I20="高",K$4*高係数,IF($I20="中",K$4*中係数,IF($I20="低",K$4*低係数, IF($I20="特低",K$4*特低係数, 0)))))),0.125) -> 0.75 | L20: =K20*0.2 -> 0.15 | M20: =CEILING(IF($J20="新規", IF($I20="特高", M$4*特高係数,IF($I20="高",M$4*高係数,IF($I20="中",M$4*中係数,IF($I20="低",M$4*低係数, IF($I20="特低",M$4*特低係数, 0))))), IF($I20="特高", M$4*特高係数,IF($I20="高",M$4*高係数,IF($I20="中",M$4*中係数,IF($I20="低",M$4*低係数, IF($I20="特低",M$4*特低係数, 0)))))),0.125) -> 2.25 | N20: 0.4 | O20: =CEILING(IF($J20="新規", IF($I20="特高", O$4*特高係数,IF($I20="高",O$4*高係数,IF($I20="中",O$4*中係数,IF($I20="低",O$4*低係数, IF($I20="特低",O$4*特低係数, 0))))), IF($I20="特高", O$4*特高係数,IF($I20="高",O$4*高係数,IF($I20="中",O$4*中係数,IF($I20="低",O$4*低係数, IF($I20="特低",O$4*特低係数, 0)))))),0.125) -> 2.375 | P20: =CEILING(IF($J20="新規", IF($I20="特高", P$4*特高係数,IF($I20="高",P$4*高係数,IF($I20="中",P$4*中係数,IF($I20="低",P$4*低係数, IF($I20="特低",P$4*特低係数, 0))))), IF($I20="特高", P$4*特高係数,IF($I20="高",P$4*高係数,IF($I20="中",P$4*中係数,IF($I20="低",P$4*低係数, IF($I20="特低",P$4*特低係数, 0)))))),0.125) -> 1.875 | Q20: =CEILING(IF($J20="新規", IF($I20="特高", Q$4*特高係数,IF($I20="高",Q$4*高係数,IF($I20="中",Q$4*中係数,IF($I20="低",Q$4*低係数, IF($I20="特低",Q$4*特低係数, 0))))), IF($I20="特高", Q$4*特高係数,IF($I20="高",Q$4*高係数,IF($I20="中",Q$4*中係数,IF($I20="低",Q$4*低係数, IF($I20="特低",Q$4*特低係数, 0)))))),0.125) -> 0.375 | R20: =SUM(K20:Q20) -> 8.175 | S20: =R20/20 -> 0.40875
A21: =ROW()-4 -> 17 | D21: 運送会社 | F21: 画面 | G21: ・一覧表示 ・新規登録、編集 ・データ想定 需要家/特販店 or 出荷先 運送会社 | I21: 低 | J21: 新規 | K21: =CEILING(IF($J21="新規", IF($I21="特高", K$4*特高係数,IF($I21="高",K$4*高係数,IF($I21="中",K$4*中係数,IF($I21="低",K$4*低係数, IF($I21="特低",K$4*特低係数, 0))))), IF($I21="特高", K$4*特高係数,IF($I21="高",K$4*高係数,IF($I21="中",K$4*中係数,IF($I21="低",K$4*低係数, IF($I21="特低",K$4*特低係数, 0)))))),0.125) -> 0.75 | L21: =K21*0.2 -> 0.15 | M21: =CEILING(IF($J21="新規", IF($I21="特高", M$4*特高係数,IF($I21="高",M$4*高係数,IF($I21="中",M$4*中係数,IF($I21="低",M$4*低係数, IF($I21="特低",M$4*特低係数, 0))))), IF($I21="特高", M$4*特高係数,IF($I21="高",M$4*高係数,IF($I21="中",M$4*中係数,IF($I21="低",M$4*低係数, IF($I21="特低",M$4*特低係数, 0)))))),0.125) -> 2.25 | N21: 0.325 | O21: =CEILING(IF($J21="新規", IF($I21="特高", O$4*特高係数,IF($I21="高",O$4*高係数,IF($I21="中",O$4*中係数,IF($I21="低",O$4*低係数, IF($I21="特低",O$4*特低係数, 0))))), IF($I21="特高", O$4*特高係数,IF($I21="高",O$4*高係数,IF($I21="中",O$4*中係数,IF($I21="低",O$4*低係数, IF($I21="特低",O$4*特低係数, 0)))))),0.125) -> 2.375 | P21: =CEILING(IF($J21="新規", IF($I21="特高", P$4*特高係数,IF($I21="高",P$4*高係数,IF($I21="中",P$4*中係数,IF($I21="低",P$4*低係数, IF($I21="特低",P$4*特低係数, 0))))), IF($I21="特高", P$4*特高係数,IF($I21="高",P$4*高係数,IF($I21="中",P$4*中係数,IF($I21="低",P$4*低係数, IF($I21="特低",P$4*特低係数, 0)))))),0.125) -> 1.875 | Q21: =CEILING(IF($J21="新規", IF($I21="特高", Q$4*特高係数,IF($I21="高",Q$4*高係数,IF($I21="中",Q$4*中係数,IF($I21="低",Q$4*低係数, IF($I21="特低",Q$4*特低係数, 0))))), IF($I21="特高", Q$4*特高係数,IF($I21="高",Q$4*高係数,IF($I21="中",Q$4*中係数,IF($I21="低",Q$4*低係数, IF($I21="特低",Q$4*特低係数, 0)))))),0.125) -> 0.375 | R21: =SUM(K21:Q21) -> 8.1 | S21: =R21/20 -> 0.405
A22: =ROW()-4 -> 18 | D22: 出荷先 | F22: 画面 | G22: ・一覧表示 ・新規登録、編集 ・データ想定 需要家/特販店 | I22: 低 | J22: 新規 | K22: =CEILING(IF($J22="新規", IF($I22="特高", K$4*特高係数,IF($I22="高",K$4*高係数,IF($I22="中",K$4*中係数,IF($I22="低",K$4*低係数, IF($I22="特低",K$4*特低係数, 0))))), IF($I22="特高", K$4*特高係数,IF($I22="高",K$4*高係数,IF($I22="中",K$4*中係数,IF($I22="低",K$4*低係数, IF($I22="特低",K$4*特低係数, 0)))))),0.125) -> 0.75 | L22: =K22*0.2 -> 0.15 | M22: =CEILING(IF($J22="新規", IF($I22="特高", M$4*特高係数,IF($I22="高",M$4*高係数,IF($I22="中",M$4*中係数,IF($I22="低",M$4*低係数, IF($I22="特低",M$4*特低係数, 0))))), IF($I22="特高", M$4*特高係数,IF($I22="高",M$4*高係数,IF($I22="中",M$4*中係数,IF($I22="低",M$4*低係数, IF($I22="特低",M$4*特低係数, 0)))))),0.125) -> 2.25 | N22: 0.325 | O22: =CEILING(IF($J22="新規", IF($I22="特高", O$4*特高係数,IF($I22="高",O$4*高係数,IF($I22="中",O$4*中係数,IF($I22="低",O$4*低係数, IF($I22="特低",O$4*特低係数, 0))))), IF($I22="特高", O$4*特高係数,IF($I22="高",O$4*高係数,IF($I22="中",O$4*中係数,IF($I22="低",O$4*低係数, IF($I22="特低",O$4*特低係数, 0)))))),0.125) -> 2.375 | P22: =CEILING(IF($J22="新規", IF($I22="特高", P$4*特高係数,IF($I22="高",P$4*高係数,IF($I22="中",P$4*中係数,IF($I22="低",P$4*低係数, IF($I22="特低",P$4*特低係数, 0))))), IF($I22="特高", P$4*特高係数,IF($I22="高",P$4*高係数,IF($I22="中",P$4*中係数,IF($I22="低",P$4*低係数, IF($I22="特低",P$4*特低係数, 0)))))),0.125) -> 1.875 | Q22: =CEILING(IF($J22="新規", IF($I22="特高", Q$4*特高係数,IF($I22="高",Q$4*高係数,IF($I22="中",Q$4*中係数,IF($I22="低",Q$4*低係数, IF($I22="特低",Q$4*特低係数, 0))))), IF($I22="特高", Q$4*特高係数,IF($I22="高",Q$4*高係数,IF($I22="中",Q$4*中係数,IF($I22="低",Q$4*低係数, IF($I22="特低",Q$4*特低係数, 0)))))),0.125) -> 0.375 | R22: =SUM(K22:Q22) -> 8.1 | S22: =R22/20 -> 0.405
A23: =ROW()-4 -> 19 | D23: ユーザー | F23: 画面 | G23: ・一覧表示 ・新規登録、編集 | I23: 低 | J23: 新規 | K23: =CEILING(IF($J23="新規", IF($I23="特高", K$4*特高係数,IF($I23="高",K$4*高係数,IF($I23="中",K$4*中係数,IF($I23="低",K$4*低係数, IF($I23="特低",K$4*特低係数, 0))))), IF($I23="特高", K$4*特高係数,IF($I23="高",K$4*高係数,IF($I23="中",K$4*中係数,IF($I23="低",K$4*低係数, IF($I23="特低",K$4*特低係数, 0)))))),0.125) -> 0.75 | L23: =K23*0.2 -> 0.15 | M23: =CEILING(IF($J23="新規", IF($I23="特高", M$4*特高係数,IF($I23="高",M$4*高係数,IF($I23="中",M$4*中係数,IF($I23="低",M$4*低係数, IF($I23="特低",M$4*特低係数, 0))))), IF($I23="特高", M$4*特高係数,IF($I23="高",M$4*高係数,IF($I23="中",M$4*中係数,IF($I23="低",M$4*低係数, IF($I23="特低",M$4*特低係数, 0)))))),0.125) -> 2.25 | N23: 0.325 | O23: =CEILING(IF($J23="新規", IF($I23="特高", O$4*特高係数,IF($I23="高",O$4*高係数,IF($I23="中",O$4*中係数,IF($I23="低",O$4*低係数, IF($I23="特低",O$4*特低係数, 0))))), IF($I23="特高", O$4*特高係数,IF($I23="高",O$4*高係数,IF($I23="中",O$4*中係数,IF($I23="低",O$4*低係数, IF($I23="特低",O$4*特低係数, 0)))))),0.125) -> 2.375 | P23: =CEILING(IF($J23="新規", IF($I23="特高", P$4*特高係数,IF($I23="高",P$4*高係数,IF($I23="中",P$4*中係数,IF($I23="低",P$4*低係数, IF($I23="特低",P$4*特低係数, 0))))), IF($I23="特高", P$4*特高係数,IF($I23="高",P$4*高係数,IF($I23="中",P$4*中係数,IF($I23="低",P$4*低係数, IF($I23="特低",P$4*特低係数, 0)))))),0.125) -> 1.875 | Q23: =CEILING(IF($J23="新規", IF($I23="特高", Q$4*特高係数,IF($I23="高",Q$4*高係数,IF($I23="中",Q$4*中係数,IF($I23="低",Q$4*低係数, IF($I23="特低",Q$4*特低係数, 0))))), IF($I23="特高", Q$4*特高係数,IF($I23="高",Q$4*高係数,IF($I23="中",Q$4*中係数,IF($I23="低",Q$4*低係数, IF($I23="特低",Q$4*特低係数, 0)))))),0.125) -> 0.375 | R23: =SUM(K23:Q23) -> 8.1 | S23: =R23/20 -> 0.405
A24: =ROW()-4 -> 20 | C24: その他 | D24: 脆弱性診断 | F24: 機能 | I24: 高 | J24: 新規 | K24: =CEILING(IF($J24="新規", IF($I24="特高", K$4*特高係数,IF($I24="高",K$4*高係数,IF($I24="中",K$4*中係数,IF($I24="低",K$4*低係数, IF($I24="特低",K$4*特低係数, 0))))), IF($I24="特高", K$4*特高係数,IF($I24="高",K$4*高係数,IF($I24="中",K$4*中係数,IF($I24="低",K$4*低係数, IF($I24="特低",K$4*特低係数, 0)))))),0.125) -> 2 | L24: =K24*0.2 -> 0.4 | M24: =CEILING(IF($J24="新規", IF($I24="特高", M$4*特高係数,IF($I24="高",M$4*高係数,IF($I24="中",M$4*中係数,IF($I24="低",M$4*低係数, IF($I24="特低",M$4*特低係数, 0))))), IF($I24="特高", M$4*特高係数,IF($I24="高",M$4*高係数,IF($I24="中",M$4*中係数,IF($I24="低",M$4*低係数, IF($I24="特低",M$4*特低係数, 0)))))),0.125) -> 6.25 | N24: 0.325 | O24: =CEILING(IF($J24="新規", IF($I24="特高", O$4*特高係数,IF($I24="高",O$4*高係数,IF($I24="中",O$4*中係数,IF($I24="低",O$4*低係数, IF($I24="特低",O$4*特低係数, 0))))), IF($I24="特高", O$4*特高係数,IF($I24="高",O$4*高係数,IF($I24="中",O$4*中係数,IF($I24="低",O$4*低係数, IF($I24="特低",O$4*特低係数, 0)))))),0.125) -> 6.5 | P24: =CEILING(IF($J24="新規", IF($I24="特高", P$4*特高係数,IF($I24="高",P$4*高係数,IF($I24="中",P$4*中係数,IF($I24="低",P$4*低係数, IF($I24="特低",P$4*特低係数, 0))))), IF($I24="特高", P$4*特高係数,IF($I24="高",P$4*高係数,IF($I24="中",P$4*中係数,IF($I24="低",P$4*低係数, IF($I24="特低",P$4*特低係数, 0)))))),0.125) -> 5.25 | Q24: =CEILING(IF($J24="新規", IF($I24="特高", Q$4*特高係数,IF($I24="高",Q$4*高係数,IF($I24="中",Q$4*中係数,IF($I24="低",Q$4*低係数, IF($I24="特低",Q$4*特低係数, 0))))), IF($I24="特高", Q$4*特高係数,IF($I24="高",Q$4*高係数,IF($I24="中",Q$4*中係数,IF($I24="低",Q$4*低係数, IF($I24="特低",Q$4*特低係数, 0)))))),0.125) -> 0.75 | R24: =SUM(K24:Q24) -> 21.475 | S24: =R24/20 -> 1.07375
A25: =ROW()-4 -> 21 | D25: 画面デザイン | F25: 画面 | G25: 出荷画面の「積時間を調整するUI」について ・ドラッグアンドドロップなど直感的な操作とする ・一括編集可能とする | I25: 高 | J25: 新規 | K25: =CEILING(IF($J25="新規", IF($I25="特高", K$4*特高係数,IF($I25="高",K$4*高係数,IF($I25="中",K$4*中係数,IF($I25="低",K$4*低係数, IF($I25="特低",K$4*特低係数, 0))))), IF($I25="特高", K$4*特高係数,IF($I25="高",K$4*高係数,IF($I25="中",K$4*中係数,IF($I25="低",K$4*低係数, IF($I25="特低",K$4*特低係数, 0)))))),0.125) -> 2 | L25: =K25*0.2 -> 0.4 | M25: =CEILING(IF($J25="新規", IF($I25="特高", M$4*特高係数,IF($I25="高",M$4*高係数,IF($I25="中",M$4*中係数,IF($I25="低",M$4*低係数, IF($I25="特低",M$4*特低係数, 0))))), IF($I25="特高", M$4*特高係数,IF($I25="高",M$4*高係数,IF($I25="中",M$4*中係数,IF($I25="低",M$4*低係数, IF($I25="特低",M$4*特低係数, 0)))))),0.125) -> 6.25 | N25: 0.4 | O25: =CEILING(IF($J25="新規", IF($I25="特高", O$4*特高係数,IF($I25="高",O$4*高係数,IF($I25="中",O$4*中係数,IF($I25="低",O$4*低係数, IF($I25="特低",O$4*特低係数, 0))))), IF($I25="特高", O$4*特高係数,IF($I25="高",O$4*高係数,IF($I25="中",O$4*中係数,IF($I25="低",O$4*低係数, IF($I25="特低",O$4*特低係数, 0)))))),0.125) -> 6.5 | P25: =CEILING(IF($J25="新規", IF($I25="特高", P$4*特高係数,IF($I25="高",P$4*高係数,IF($I25="中",P$4*中係数,IF($I25="低",P$4*低係数, IF($I25="特低",P$4*特低係数, 0))))), IF($I25="特高", P$4*特高係数,IF($I25="高",P$4*高係数,IF($I25="中",P$4*中係数,IF($I25="低",P$4*低係数, IF($I25="特低",P$4*特低係数, 0)))))),0.125) -> 5.25 | Q25: =CEILING(IF($J25="新規", IF($I25="特高", Q$4*特高係数,IF($I25="高",Q$4*高係数,IF($I25="中",Q$4*中係数,IF($I25="低",Q$4*低係数, IF($I25="特低",Q$4*特低係数, 0))))), IF($I25="特高", Q$4*特高係数,IF($I25="高",Q$4*高係数,IF($I25="中",Q$4*中係数,IF($I25="低",Q$4*低係数, IF($I25="特低",Q$4*特低係数, 0)))))),0.125) -> 0.75 | R25: =SUM(K25:Q25) -> 21.55 | S25: =R25/20 -> 1.0775
K26: =CEILING(IF($J26="新規", IF($I26="特高", K$4*特高係数,IF($I26="高",K$4*高係数,IF($I26="中",K$4*中係数,IF($I26="低",K$4*低係数, IF($I26="特低",K$4*特低係数, 0))))), IF($I26="特高", K$4*特高係数,IF($I26="高",K$4*高係数,IF($I26="中",K$4*中係数,IF($I26="低",K$4*低係数, IF($I26="特低",K$4*特低係数, 0)))))),0.125) -> 0 | M26: =CEILING(IF($J26="新規", IF($I26="特高", M$4*特高係数,IF($I26="高",M$4*高係数,IF($I26="中",M$4*中係数,IF($I26="低",M$4*低係数, IF($I26="特低",M$4*特低係数, 0))))), IF($I26="特高", M$4*特高係数,IF($I26="高",M$4*高係数,IF($I26="中",M$4*中係数,IF($I26="低",M$4*低係数, IF($I26="特低",M$4*特低係数, 0)))))),0.125) -> 0 | N26: =M26*0.2 -> 0 | O26: =CEILING(IF($J26="新規", IF($I26="特高", O$4*特高係数,IF($I26="高",O$4*高係数,IF($I26="中",O$4*中係数,IF($I26="低",O$4*低係数, IF($I26="特低",O$4*特低係数, 0))))), IF($I26="特高", O$4*特高係数,IF($I26="高",O$4*高係数,IF($I26="中",O$4*中係数,IF($I26="低",O$4*低係数, IF($I26="特低",O$4*特低係数, 0)))))),0.125) -> 0 | P26: =CEILING(IF($J26="新規", IF($I26="特高", P$4*特高係数,IF($I26="高",P$4*高係数,IF($I26="中",P$4*中係数,IF($I26="低",P$4*低係数, IF($I26="特低",P$4*特低係数, 0))))), IF($I26="特高", P$4*特高係数,IF($I26="高",P$4*高係数,IF($I26="中",P$4*中係数,IF($I26="低",P$4*低係数, IF($I26="特低",P$4*特低係数, 0)))))),0.125) -> 0 | Q26: =CEILING(IF($J26="新規", IF($I26="特高", Q$4*特高係数,IF($I26="高",Q$4*高係数,IF($I26="中",Q$4*中係数,IF($I26="低",Q$4*低係数, IF($I26="特低",Q$4*特低係数, 0))))), IF($I26="特高", Q$4*特高係数,IF($I26="高",Q$4*高係数,IF($I26="中",Q$4*中係数,IF($I26="低",Q$4*低係数, IF($I26="特低",Q$4*特低係数, 0)))))),0.125) -> 0 | R26: =SUM(K26:Q26) -> 0 | S26: =R26/20 -> 0
A27: 合計（人日） | K27: =SUM(K5:K26) -> 29.5 | L27: =SUM(L5:L26) -> 5.9 | M27: =SUM(M5:M26) -> 90.375 | N27: =SUM(N5:N26) -> 8.275 | O27: =SUM(O5:O26) -> 94.25 | P27: =SUM(P5:P26) -> 76.25 | Q27: =SUM(Q5:Q26) -> 11.625 | R27: =SUM(K27:Q27) -> 316.175
A28: 合計（人月） | K28: =K27/20 -> 1.475 | L28: =L27/20 -> 0.295 | M28: =M27/20 -> 4.51875 | N28: =N27/20 -> 0.41375 | O28: =O27/20 -> 4.7125 | P28: =P27/20 -> 3.8125 | Q28: =Q27/20 -> 0.58125 | S28: =SUM(K28:Q28) -> 15.80875
A29: 管理工数（合計工数の20%) | R29: =R27*0.2 -> 63.235 | S29: =R29/20 -> 3.16175
A30: 超概算によるブレ工数（合計工数の10%） | R30: =R27*0.1 -> 31.6175 | S30: =R30/20 -> 1.580875
A31: 総工数 | R31: =SUM(R27:R30) -> 411.0275 | S31: =R31/20 -> 20.551375
A33: 費用 | R33: =S31*積算基準!C61*10000 -> 20551375
A34: 端数値引
A35: 費用合計 | R35: =R33-R34 -> 20551375

Sheet 積算基準
A1: 積算基準
A3: １．難易度を「特高」~「特低」までの５段階に分類する。
B5: 難易度
B6: 特高
B7: 高
B8: 中
B9: 低
B10: 特低
A12: ２．難易度の判断基準は、項目数により、区別する。
B14: 難易度判定：基準項目数
B15: 分類 | C15: 特高 | D15: 高 | E15: 中 | F15: 低 | G15: 特低
B16: 登録 | C16: 40 | D16: 30 | E16: 20 | F16: 10 | G16: 0
B17: 参照 | C17: 50 | D17: 40 | E17: 30 | F17: 20 | G17: 10
A19: ３．IPA発行「ソフトウェア開発データ白書」に基づく、各工程の工数比率を使用する。
B21: 工数比率（IPA ソフトウェア開発データ白書より）
B22: 基本設計 | C22: 詳細設計 | D22: 開発/単体テスト | E22: 結合テスト | F22: 総合テスト | G22: 合計
B23: 0.161 | C23: 0.175 | D23: 0.37 | E23: 0.167 | F23: 0.127 | G23: =SUM(B23:F23) -> 1
A26: ４．難易度「中」の基本設計～システムテストまでの標準工数を「8.75人日（全体工数が9.5人日となるよう調整）」とする。
B28: 画面・機能側標準工数（端数は0.125人日で丸め）
B29: 合計 | C29: 基本設計 | D29: 詳細設計 | E29: 開発/単体テスト | F29: 結合テスト | G29: 総合テスト
B30: 8.75 | C30: =CEILING($B30*B23,0.125) -> 1.5 | D30: =CEILING($B30*C23,0.125) -> 1.625 | E30: =CEILING($B30*D23,0.125) -> 3.25 | F30: =CEILING($B30*E23,0.125) -> 1.5 | G30: =CEILING($B30*F23,0.125) -> 1.125
B32: IF側標準工数（端数は0.125人日で丸め）
B33: 合計 | C33: 基本設計 | D33: 詳細設計 | E33: 開発/単体テスト | F33: 結合テスト | G33: 総合テスト
B34: 3.5 | C34: =CEILING($B34*B23,0.125) -> 0.625 | D34: =CEILING($B34*C23,0.125) -> 0.625 | E34: =CEILING($B34*D23,0.125) -> 1.375 | F34: =CEILING($B34*E23,0.125) -> 0.625 | G34: =CEILING($B34*F23,0.125) -> 0.5
A36: ５．他の工程の工数を下記の基準により算出する。
B38: 工程別 標準工数（端数は0.125人日で丸め）
B39: 工程 | C39: 合計 | D39: 要件定義 | E39: 基本設計 | F39: 詳細設計 | G39: 開発/単体テスト | H39: 結合テスト | I39: 総合テスト | J39: 受入テスト | K39: 本稼働 | L39: PJ管理
B40: 比率 | D40: 0.1 | E40: =B23 -> 0.161 | F40: =C23 -> 0.175 | G40: =D23 -> 0.37 | H40: =E23 -> 0.167 | I40: =F23 -> 0.127 | J40: 0.5 | K40: 0.25 | L40: 0.15
B41: 標準工数（画面・機能） | C41: =SUM(D41:L41) -> 12.875 | D41: =CEILING(SUM(E41:I41)*D40,0.125) -> 1 | E41: =C30 -> 1.5 | F41: =D30 -> 1.625 | G41: =E30 -> 3.25 | H41: =F30 -> 1.5 | I41: =G30 -> 1.125 | J41: =CEILING(H41*J40,0.125) -> 0.75 | K41: =CEILING(H41*K40,0.125) -> 0.375 | L41: =CEILING(SUM(D41:K41)*L40,0.125) -> 1.75
B42: 標準工数（IF） | C42: =SUM(D42:L42) -> 5.5 | D42: =CEILING(D40*SUM(E42:I42),0.125) -> 0.375 | E42: =C34 -> 0.625 | F42: =D34 -> 0.625 | G42: =E34 -> 1.375 | H42: =F34 -> 0.625 | I42: =G34 -> 0.5 | J42: =CEILING(J40*H42,0.125) -> 0.375 | K42: =CEILING(K40*H42,0.125) -> 0.25 | L42: =CEILING(L40*SUM(D42:K42),0.125) -> 0.75
B43: 0.5
A45: ６．他の難易度の工数は、下記の係数に基づき、積算する。
B47: 難易度別の工数係数
B48: 係数 | C48: 特高 | D48: 高 | E48: 中 | F48: 低 | G48: 特低
C49: 2.6 | D49: 2 | E49: 1.6 | F49: 0.7 | G49: 0.3 | H49: 画面・機能
C50: 1.5 | D50: 1.25 | E50: 1 | F50: 0.75 | G50: 0.2 | H50: IF
A53: 7．本案件の工程に合わせての工数を算出する。
B55: 工程別 標準工数（端数は0.125人日で丸め）
B56: 工程 | C56: 合計 | D56: 要件定義 | E56: 設計 | F56: 開発/単体テスト | G56: 結合（総合）テスト | H56: 受入テスト | I56: PJ管理
B57: 工数比率 | D57: 0.1 | E57: =SUM(B23:C23) -> 0.336 | F57: =D23 -> 0.37 | G57: =SUM(E23:F23) -> 0.294 | H57: 0.25 | I57: 0.15
...

Sheet Sheet1
A1: 工程 | B1: 役割 | D1: 単価 | E1: 工数 | F1: 費用 | G1: 工程別 | H1: 合計
A2: 要件定義 | B2: PM | C2: PJ管理 | D2: 140 | E2: 1.2 | F2: =D2*E2 -> 168 | G2: =SUM(F2:F4) -> 750 | H2: =SUM(G2:G36) -> 4130
B3: PM | C3: 要件定義 | D3: 140 | E3: 1.8 | F3: =D3*E3 -> 252
B4: SE | C4: 要件定義 | D4: 110 | E4: 3 | F4: =D4*E4 -> 330
A5: 基本設計 | B5: PM | C5: PJ管理 | D5: 140 | E5: 0.8 | F5: =D5*E5 -> 112 | G5: =SUM(F5:F9) -> 460
B6: PM | C6: 基本設計 | D6: 140 | E6: 0.2 | F6: =D6*E6 -> 28
B7: SE | C7: 基本設計 | D7: 110 | E7: 1 | F7: =D7*E7 -> 110
B8: SE | C8: 基本設計 | D8: 110 | E8: 1 | F8: =D8*E8 -> 110
B9: SE | C9: UI検討 | D9: 100 | E9: 1 | F9: =D9*E9 -> 100
A10: 詳細設計 | B10: PM | C10: PJ管理 | D10: 140 | E10: 0.8 | F10: =D10*E10 -> 112 | G10: =SUM(F10:F14) -> 460
B11: PM | C11: 詳細設計 | D11: 140 | E11: 0.2 | F11: =D11*E11 -> 28
B12: SE | C12: 詳細設計 | D12: 110 | E12: 1 | F12: =D12*E12 -> 110
B13: SE | C13: 詳細設計 | D13: 110 | E13: 1 | F13: =D13*E13 -> 110
B14: SE | C14: UI検討 | D14: 100 | E14: 1 | F14: =D14*E14 -> 100
A15: 開発・単体テスト | B15: PM | C15: PJ管理 | D15: 140 | E15: 1.6 | F15: =D15*E15 -> 224 | G15: =SUM(F15:F19) -> 920
B16: PM | C16: 開発・単体テスト | D16: 140 | E16: 0.4 | F16: =D16*E16 -> 56
B17: SE | C17: 開発・単体テスト | D17: 110 | E17: 2 | F17: =D17*E17 -> 220
B18: SE | C18: 開発・単体テスト | D18: 110 | E18: 2 | F18: =D18*E18 -> 220
B19: SE | C19: 開発・単体テスト | D19: 100 | E19: 2 | F19: =D19*E19 -> 200
A20: 結合テスト | B20: PM | C20: PJ管理 | D20: 140 | E20: 0.8 | F20: =D20*E20 -> 112 | G20: =SUM(F20:F24) -> 460
B21: PM | C21: 結合テスト | D21: 140 | E21: 0.2 | F21: =D21*E21 -> 28
B22: SE | C22: 結合テスト | D22: 110 | E22: 1 | F22: =D22*E22 -> 110
B23: SE | C23: 結合テスト | D23: 110 | E23: 1 | F23: =D23*E23 -> 110
B24: SE | C24: 結合テスト | D24: 100 | E24: 1 | F24: =D24*E24 -> 100
A25: システムテスト | B25: PM | C25: PJ管理 | D25: 140 | E25: 0.6 | F25: =D25*E25 -> 84 | G25: =SUM(F25:F28) -> 360
B26: PM | C26: システムテスト | D26: 140 | E26: 0.4 | F26: =D26*E26 -> 56
B27: SE | C27: システムテスト | D27: 110 | E27: 1 | F27: =D27*E27 -> 110
B28: SE | C28: システムテスト | D28: 110 | E28: 1 | F28: =D28*E28 -> 110
A29: 受入テスト | B29: PM | C29: PJ管理 | D29: 140 | E29: 0.6 | F29: =D29*E29 -> 84 | G29: =SUM(F29:F32) -> 360
B30: PM | C30: 受入テスト | D30: 140 | E30: 0.4 | F30: =D30*E30 -> 56
B31: SE | C31: 受入テスト | D31: 110 | E31: 1 | F31: =D31*E31 -> 110
B32: SE | C32: 受入テスト | D32: 110 | E32: 1 | F32: =D32*E32 -> 110
A33: 初期流動 | B33: PM | C33: PJ管理 | D33: 140 | E33: 0.6 | F33: =D33*E33 -> 84 | G33: =SUM(F33:F36) -> 360
B34: PM | C34: 初期流動 | D34: 140 | E34: 0.4 | F34: =D34*E34 -> 56
B35: SE | C35: 初期流動 | D35: 110 | E35: 1 | F35: =D35*E35 -> 110
B36: SE | C36: 初期流動 | D36: 110 | E36: 1 | F36: =D36*E36 -> 110
