Workbook

Sheet 依頼概要
B3: 1. 経緯
B4: 館林DCセンターの廃止に伴い、現在のサーバ郡を移転する必要がある。
B5: 期日までに以下のいずれかの対応をとる必要がある。
B6: （２）Azureに構築される縮小版の共通基盤に移行
B7: ※現状よりスペックは低下、Oracleは19C
B8: 加えて、館林DC以外（現地）のサーバに関してWindows2016サーバはサポート期限切れに伴い、再構築を行う必要がある。
B11: 2. 依頼事項
B12: 各システム毎に概算見積を行ってほしい。
B13: （２）Azureに構築される縮小版の共通基盤に移行
C14: 対象：現行共通基盤を利用しているシステム
C15: 時期：2025年度1Q以降見込
C16: 出光側で構築した縮小版共通基盤へアプリ、帳票、バッチを移行
C17: 縮小版共通基盤の構成は現行共通基盤を踏襲した形となるが、OS,MWのバージョンは変更となる見込み
B20: 3. 希望期日
B21: 2024/12中に概算見積提示
B24: 顧客受領資料より

Sheet 想定作業
A1: 前提
B2: 業務・機能変更は行わない。
B3: サーバ構成は現行踏襲とする。
B4: DBは現行踏襲（Oracle、SQLSever継続）
B5: JavaフレームワークはStruts継続
B6: テストは新規構築した本番環境（次期本番機）にて行う。
B7: 開始時期を2025/4月以降
B8: ※検証、予備環境は最低限の動作確認（アプリ起動、ログイン確認程度）を想定
A11: 想定作業
A12: 全パターン共通
B13: IP,ホスト名変更に伴う各種（IF、DB等）向け先変更、検証
B14: アプリ動作検証（全画面、帳票、バッチ、IF打鍵 ※初期画面の描画や正常系の動作に問題がないことを確認）
B15: アプリケーション構築、ミドルウェアのセットアップ ※デプロイ作業のみ想定
B16: ※関連基盤の切り替えは完了しており、アプリケーションのAzure移行の切り替え作業は1回の未実施を想定（基盤切り替えが複数回発生する場合は別途工数が必要となります）
A18: （２）Azureに構築される縮小版の共通基盤に移行
B19: 全パターン共通の作業のみ

Sheet 概要図(千葉)
C1: ファイル連携 | F1: 工場系保守対象 | I1: 館林管理
C2: DBデータ連携 | F2: 工場系保守対象外 | I2: 現地管理
K63: Azure環境
K121: Azure環境

Sheet 概要図(徳山)
C1: ファイル連携 | F1: 工場系保守対象 | I1: 館林管理
C2: DBデータ連携 | F2: 工場系保守対象外 | I2: 現地管理
C60: Azure環境
C114: Azure環境

Sheet システム概要
E1: システム概要 | M1: システム規模 | S1: 共通基盤利用状況（現状）
A2: サービス: サービス番号 | B2: サービス名 | C2: 保守領域 | D2: 移行状況 | E2: 業務概要 | F2: OS | G2: アプリ | H2: DB | I2: ミドルウェア | J2: フレームワーク | K2: その他 | L2: サーバ構成 | M2: 画面 | N2: 帳票 | O2: バッチ | P2: IF | Q2: テーブル | R2: その他 | S2: 共通AP | T2: 共通DB | U2: 連携 | V2: レポート | W2: 認証 | X2: バッチ
A3: SVC-00000710 | B3: 数量確定システム(千葉) | C3: 工場系 | D3: 縮小共通基盤移行中 ⇒クラウドアーキ環境へ移行へ方針変更 | E3: 千葉事業所及び徳山事業所の石油化学装置の生産、在庫、PL(パイプライン)出荷、品目転換数量の管理を行うシステム。またタンクヤードの日報作成(ヤード日報)機能も持つ。 | F3: Red Hat Enterprise Linux7.3 | G3: java 1.8.0_202 Tomcat 9.0 | H3: Oracle19C | I3: A-AUTO | J3: struts 1.2.9 | L3: 本番 共通基盤（館林） 検証 共通基盤（館林） | M3: 千葉：41 徳山：30 | N3: 千葉：23 徳山：7 | O3: 共通：2 千葉：9 徳山：4 | P3: 千葉：8 徳山：4 | Q3: 共通：58 千葉：16 徳山：9 | S3: 〇 | T3: 〇 | U3: 〇 | V3: × | W3: 〇 | X3: 〇 | Y3: e
A4: SVC-00000857 | B4: 数量確定システム(徳山) | Y4: e
A5: - | B5: 用役管理システム(千葉工場) | C5: 工場系 | D5: 縮小共通基盤移行中 ⇒クラウドアーキ環境へ移行へ方針変更 | E5: 石油化学装置の生産数量、用役数量の管理を行うシステム。 | F5: Red Hat Enterprise Linux7.3 | G5: java 1.8.0_202 Tomcat 9.0 | H5: Oracle19C | I5: A-AUTO | J5: struts 1.2.9 | L5: 本番 共通基盤（館林） 検証 共通基盤（館林） | M5: 千葉：28 徳山：17 | N5: 千葉：43 徳山：6 | O5: 共通：0 千葉：0 徳山：0 | P5: 千葉：0 徳山：0 | Q5: 共通：11 千葉：1 徳山：11 | S5: 〇 | T5: 〇 | U5: 〇 | V5: × | W5: 〇 | X5: 〇 | Y5: e
A6: SVC-00000858 | B6: 用役管理システム(徳山工場) | Y6: e
A7: SVC-00001700 | B7: 千葉化学品質管理システム | C7: 工場系 | D7: 縮小共通基盤移行中 ⇒クラウドアーキ環境へ移行へ方針変更 | E7: 千葉事業所(工場)の品質管理課にて行う各種試験(工程、製品、物性)、及びそれに付随する業務(ロット管理、試験料金計算)を行うシステム。 | F7: Red Hat Enterprise Linux7.3 | G7: java 1.8.0_202 Tomcat 9.0 | H7: Oracle19C | I7: A-AUTO | J7: struts 1.2.9 | K7: List Creatorでの帳票作成 | L7: 本番 共通基盤（館林） 検証 共通基盤（館林） | M7: 83 | N7: 25 | O7: 5 | P7: 4 | Q7: 67 | S7: 〇 | T7: 〇 | U7: 〇 | V7: 〇 | W7: 〇 | X7: 〇 | Y7: e
A8: SVC-00000854 | B8: ＬＭＰＰ包装システム | C8: 工場系 | D8: 縮小共通基盤移行中 ⇒クラウドアーキ環境へ移行へ方針変更 | E8: 千葉事業所(工場)のSPS、LMPP装置で生産される製品の包装管理を行うシステム。 | F8: Red Hat Enterprise Linux7.3 | G8: java 1.8.0_202 Tomcat 9.0 | H8: Oracle19C | I8: A-AUTO | J8: struts 1.2.9 | K8: List Creatorでの帳票作成 | L8: 本番 共通基盤（館林） 検証 共通基盤（館林） | M8: 17 | N8: 3 | O8: 1 | P8: 3 | Q8: 12 | S8: 〇 | T8: 〇 | U8: 〇 | V8: 〇 | W8: 〇 | X8: 〇 | Y8: e
A9: SVC-00000877 | B9: 工場DB | C9: 工場系 | D9: 縮小共通基盤移行中 ⇒クラウドアーキ環境へ移行へ方針変更 ※アプリはXenApp | E9: 徳山事業所の石油化学装置の生産、在庫の計画値及び実績値を管理するDB及びエクセルマクロ群。 | F9: - | G9: Excel | H9: Oracle19C | I9: - | J9: - | L9: 本番 共通基盤（館林） 検証 共通基盤（館林） | M9: 0 | N9: 0 | O9: 0 | P9: 0 | Q9: 211 | S9: × | T9: 〇 | U9: × | V9: × | W9: × | X9: × | Y9: e
A10: SVC-00000705 | B10: 千葉ヤ－ド操業システム | C10: 工場系 | D10: OS更新対応にて現地サーバ構築済み | E10: 千葉事業所及び徳山事業所の石油化学品の入出荷を管理するシステム。 | F10: WindowsServer2022 | G10: java 1.8.0_152 WebLogic 12.2.1.2.0 | H10: SQLServer2022 | I10: A-AUTO | J10: struts 1.2.9 | L10: 本番 AP/DBサーバ×2（現地） AP/DB予備×2（館林） 検証 AP/DBサーバ×2（館林） | M10: 80 | N10: 20 | O10: 千葉：20 徳山：19 | P10: 千葉：16 徳山：15 | Q10: 75 | S10: × | T10: 〇 | U10: 〇 | V10: × | W10: 〇 | X10: × | Y10: e
A11: SVC-00000707 | B11: 徳山ヤ－ド操業システム | S11: × | T11: 〇 | U11: 〇 | V11: × | W11: 〇 | X11: × | Y11: e
A12: SVC-00000704 | B12: 千葉製品倉庫システム | C12: 工場系 | D12: 未実施（現地サーバ） | E12: 千葉事業所(工場)で生産されているポリマー製品の包装、入出荷、在庫管理を行うシステム。 | F12: WindowsServer2016 | G12: VB.NET | H12: Oracle12C | I12: Systemwalker Operation Manager OWFT | L12: 本番 AP/DBサーバ（現地） 検証 APサーバ（館林） | M12: 68 | N12: 43 | O12: 9 | P12: 45 | Q12: 205 | S12: × | T12: × | U12: 〇 | V12: × | W12: × | X12: × | Y12: e
A13: SVC-00000901 | B13: 千葉工場数量確定システム（ポリマ－） | C13: 工場系 | D13: 未実施（現地サーバ） | E13: 千葉事業所(工場)で生産されているポリマー製品の生産、在庫、PL(パイプライン)出荷、品目転換数量の管理を行うシステム。 | F13: WindowsServer2016 | G13: ASP.NET | H13: Oracle12C | I13: Systemwalker Operation Manager OWFT | M13: 20 | N13: 4 | O13: 2 | P13: 2 | Q13: 30 | S13: × | T13: × | U13: × | V13: × | W13: × | X13: × | Y13: e
A14: SVC-00000711 | B14: ＡＢＣ数量確定システム | C14: 工場系 | D14: 未実施（現地サーバ） | E14: 千葉事業所(工場)のABC装置で生産される製品の生産管理を行うシステム。 | F14: WindowsServer2016 | G14: C# | H14: Oracle12C | I14: Systemwalker Operation Manager OWFT | M14: 15 | N14: 0 | O14: 12 | P14: 5 | Q14: 24 | S14: × | T14: × | U14: × | V14: × | W14: × | X14: × | Y14: e
A15: - | B15: 千葉L3.5 | C15: 工場系 | D15: 未実施（現地サーバ） | E15: L3層に存在するシステムとL4層に存在するシステムの中継となるサーバ | F15: WindowsServer2016 | G15: - | H15: - | I15: Systemwalker Operation Manager OWFT | J15: - | L15: 本番 APサーバ（現地） 検証 APサーバ（館林） | M15: 0 | N15: 0 | O15: 2 | P15: 千葉：52 徳山：14 | Q15: 0 | S15: × | T15: × | U15: × | V15: × | W15: × | X15: ×
A16: - | B16: 徳山L3.5 | S16: × | T16: × | U16: × | V16: × | W16: × | X16: ×
A17: SVC-00001969 | B17: 用役集計 | C17: 工場系 | D17: excelファイルでの構築の為不要 | E17: 用役管理システムで出力した帳票のデータをOneSAPへ連携する為のシステム。 | G17: Excel | S17: - | T17: 不明 | U17: - | V17: - | W17: - | X17: - | Y17: e
A18: SVC-00001975 | B18: PRM HULFT | C18: 工場系 | D18: 2023年Azure移行済み | E18: PRMSAP⇔製品倉庫等PRMシステムの連携中継サーバ | S18: × | T18: × | U18: × | V18: × | W18: × | X18: × | Y18: e
A19: SVC-00000702 | B19: ロット管理明細表システム（PRM） | C19: 工場系 | D19: XenAppにて稼働 | G19: Excel | S19: × | T19: × | U19: × | V19: × | W19: × | X19: × | Y19: e
A20: SVC-00000706 | B20: 工場ロ－カルＥｘｃｅｌシステム | C20: 工場系 | S20: × | T20: 不明 | U20: × | V20: × | W20: × | X20: × | Y20: e
A21: SVC-00000876 | B21: スクラップ管理システム | C21: 工場系 | S21: × | T21: × | U21: × | V21: × | W21: × | X21: × | Y21: e

Sheet Sheet1
B3: No | C3: パターン | D3: 説明 | E3: 金額
B4: 1 | C4: 次期アーキへ移行 | D4: 次期アーキへ移行のため概算総額 | E4: ='見積 (システム・基盤別サマリ) '!K12 -> 68960000
B5: 1-1 | D5: 上記の内、次期アーキ要件定義フェーズ金額 | E5: =SUM('見積 (システム・工程別サマリ)'!M21:M26) -> 12020000
B6: 1-2 | D6: 次期アーキ要件定義を現契約で実施するにあたり、現契約から追加で必要な金額 | E6: ='見積 (システム・工程別サマリ)'!Q28 -> 5213000
B7: 2 | C7: 縮小共通基盤へ移行 | D7: 中断中の移行フェーズを再開するにあたり、現契約から追加で必要な金額 | E7: ='見積 (縮小共通基盤継続） '!D23 -> 6549000
B8: 3 | C8: 縮小共通基盤へ移行後、次期アーキへ移行 | D8: No1+No2 | E8: ='見積 (システム・縮小共通基盤⇒クラウドアーキサマリ) '!M13 -> 75509000

Sheet 見積 (縮小共通基盤継続） 
C1: 工数直入力のため注意！！
C2: 移行フェーズ作業実績
G3: 備考
B5: No. | C5: 月 | D5: 作業内容 | E5: 工数 | F5: 金額
B6: 1 | C6: 7月（当初予定作業） | D6: 縮小共通基盤移行作業 ・環境構築 ・システムテスト準備 | E6: 2.335 | F6: 2444000 | G6: 石井：0.71人月*1,400k=\994,000 天川：0.5人月*1,000k=\500,000 馬場：0.5人月*1,000k=\500,000 BSE：0.125人月*800k=\100,000 VT：0.5人月*700k=\350,000
B7: 2 | C7: 8月（当初予定外作業） | D7: 次期アーキに向けた調査・検証作業 | E7: 4.38 | F7: 4366000 | G7: ①～8/25+残日数 石井：14.8人日+残2人日=0.84人月*1,400k=\1,176,000 天川：18.3人日+残4人日=1.12人月*1,000k=\1,120,000 馬場：19.3人日+残4人日=1.17人月*1,000k=\1,170,000 ②VT BSE：0.25人月*800k=\200,000 VT：1人月*700k=\700,000
B8: 3 | C8: 9月（当初予定外作業） | D8: 次期アーキに向けた調査・検証作業 | E8: 2.2 | F8: 2183000 | G8: 9月中旬に方針確定と想定し、8月の0.5人月分で算出
B9: 計 | E9: =SUM(E6:E8) -> 8.915 | F9: =SUM(F6:F8) -> 8993000
C12: 案件名 | D12: 見積金額
C13: LMPP包装システム Azure移行（移行フェーズ） | D13: 2160000
C14: 千葉化学品質管理システム Azure移行（移行フェーズ） | D14: 2160000
C15: 数量確定システム Azure移行（移行フェーズ） | D15: 5440000
C16: 用役管理システム Azure移行（移行フェーズ） | D16: 5300000
C17: 工場DB Azure移行（移行フェーズ） | D17: 740000
B18: ① | C18: 現契約合計 | D18: =SUM(D13:D17) -> 15800000
B19: ② | C19: 縮小共通基盤作業実績（7月作業実績） | D19: =F6 -> 2444000
B20: ③ | C20: 縮小共通基盤残作業分費用 （①-②） | D20: =D18-F6 -> 13356000
B21: ④ | C21: 次期アーキ調査・検証分費用 （8月、9月作業実績） | D21: =SUM(F7:F8) -> 6549000
B22: ⑤ | C22: 現契約残額（①-②-④） | D22: =D18-D19-D21 -> 6807000
B23: ⑥ | C23: 追加発注分（③-⑤） | D23: =D20-D22 -> 6549000
D24: ※ヤード認証基盤対応分は除く

Sheet 見積 (システム・基盤別サマリ) 
C1: 工数直入力のため注意！！
C2: 見積 (基盤別サマリ)
C3: パターン | D3: クラウドアーキ基盤に移行 | P3: 備考
D4: アプリ | L4: DB | N4: 全体
B5: No. | C5: システム | D5: 共通 (基盤に関わらず共通して必要な作業) | E5: AP基盤 | F5: 認証基盤 | G5: バッチ基盤 | H5: DB基盤 | I5: 管理 | J5: 工数計 | K5: 金額 | L5: 工数計 | M5: 金額 | N5: 工数計 | O5: 金額
B6: 1 | C6: 数量確定システム（千葉・徳山） | D6: 5.5 | E6: 9.2 | F6: 1.3 | G6: 0.9 | H6: 0 | I6: 3.8 | J6: =SUM(D6:I6) -> 20.7 | K6: =SUM(D6:H6)*1000000+I6*1400000 -> 22220000 | L6: 0 | M6: 0 | N6: =SUM(J6:J10)+L6 -> 58.3 | O6: =SUM(K6:K10)+M6 -> 62900000
B7: 2 | C7: 用役管理システム（千葉・徳山） | D7: 5.2 | E7: 5.3 | F7: 0.5 | G7: 0 | H7: 0 | I7: 2.6 | J7: =SUM(D7:I7) -> 13.6 | K7: =SUM(D7:H7)*1000000+I7*1400000 -> 14640000
B8: 3 | C8: 千葉化学品質管理システム | D8: 3.2 | E8: 7 | F8: 1.2 | G8: 0.7 | H8: 0 | I8: 2.7 | J8: =SUM(D8:I8) -> 14.8 | K8: =SUM(D8:H8)*1000000+I8*1400000 -> 15880000
B9: 4 | C9: ＬＭＰＰ包装システム | D9: 2.2 | E9: 3 | F9: 0.6 | G9: 0.6 | H9: 0 | I9: 1.9 | J9: =SUM(D9:I9) -> 8.3 | K9: =SUM(D9:H9)*1000000+I9*1400000 -> 9060000
B10: 5 | C10: 工場DB | D10: 0.4 | I10: 0.5 | J10: =SUM(D10:I10) -> 0.9 | K10: =SUM(D10:H10)*1000000+I10*1400000 -> 1100000
B11: 6 | C11: ヤ－ド操業システム（千葉・徳山） | D11: 2.4 | E11: 0 | F11: 2.4 | G11: 0 | H11: 0 | I11: 0.9 | J11: =SUM(D11:I11) -> 5.7 | K11: =SUM(D11:H11)*1000000+I11*1400000 -> 6060000 | L11: 0 | M11: =SUM(M5:M10) -> 0 | N11: =SUM(J11:J11)+L11 -> 5.7 | O11: =SUM(K11:K11)+M6 -> 6060000
B12: 計 | D12: =SUM(D6:D11) -> 18.9 | E12: =SUM(E6:E11) -> 24.5 | F12: =SUM(F6:F11) -> 6 | G12: =SUM(G6:G11) -> 2.2 | H12: =SUM(H6:H11) -> 0 | I12: =SUM(I6:I11) -> 12.4 | J12: =SUM(D12:I12) -> 64 | K12: =SUM(K6:K11) -> 68960000 | L12: =SUM(L6:L11) -> 0 | M12: =SUM(M6:M11) -> 0 | N12: =SUM(N6:N11) -> 64 | O12: =SUM(O6:O11) -> 68960000
B13: 単価 | D13: 1000000 | E13: 1000000 | F13: 1000000 | G13: 1000000 | H13: 1000000 | I13: 1400000
B14: 金額 | D14: =D12*D13 -> 18900000 | E14: =E12*E13 -> 24500000 | F14: =F12*F13 -> 6000000 | G14: =G12*G13 -> 2200000 | H14: =H12*H13 -> 0 | I14: =I12*I13 -> 17360000

Sheet 見積 (システム・工程別サマリ)
C1: 工数直入力のため注意！！
C2: 見積（工程別サマリ）
C3: パターン | D3: クラウドアーキ基盤に移行 | R3: 備考
D4: アプリ | N4: DB | P4: 全体
B5: No. | C5: システム | D5: 調査・要件定義 | E5: 設計 | F5: 製造 | G5: 結合テスト | H5: システムテスト | I5: ユーザテスト | J5: 本番稼働 | K5: 管理 | L5: 工数計 | M5: 金額 | N5: 工数計 | O5: 金額 | P5: 工数計 | Q5: 金額
B6: 1 | C6: 数量確定システム（千葉・徳山） | D6: 3.2 | E6: 1.6 | F6: 2.7 | G6: 5.2 | H6: 1.4 | I6: 0.8 | J6: 2 | K6: 3.8 | L6: =SUM(D6:K6) -> 20.7 | M6: =SUM(D6:J6)*1000000+K6*1400000 -> 22220000 | N6: 0 | O6: 0 | P6: =SUM(L6:L10)+N6 -> 58.3 | Q6: =SUM(M6:M10)+O6 -> 62900000
B7: 2 | C7: 用役管理システム（千葉・徳山） | D7: 1.4 | E7: 1.1 | F7: 1.5 | G7: 3.1 | H7: 1.1 | I7: 0.8 | J7: 2 | K7: 2.6 | L7: =SUM(D7:K7) -> 13.6 | M7: =SUM(D7:J7)*1000000+K7*1400000 -> 14640000
B8: 3 | C8: 千葉化学品質管理システム | D8: 1.7 | E8: 1.4 | F8: 1.6 | G8: 5.5 | H8: 0.8 | I8: 0.5 | J8: 0.6 | K8: 2.7 | L8: =SUM(D8:K8) -> 14.8 | M8: =SUM(D8:J8)*1000000+K8*1400000 -> 15880000
B9: 4 | C9: ＬＭＰＰ包装システム | D9: 1.3 | E9: 0.4 | F9: 1.6 | G9: 1.2 | H9: 0.8 | I9: 0.5 | J9: 0.6 | K9: 1.9 | L9: =SUM(D9:K9) -> 8.3 | M9: =SUM(D9:J9)*1000000+K9*1400000 -> 9060000
B10: 5 | C10: 工場DB | J10: 0.4 | K10: 0.5 | L10: =SUM(D10:K10) -> 0.9 | M10: =SUM(D10:J10)*1000000+K10*1400000 -> 1100000
B11: 6 | C11: ヤ－ド操業システム（千葉・徳山） | D11: 0.5 | E11: 0.4 | F11: 0.7 | G11: 1.4 | H11: 0.2 | I11: 0.1 | J11: 1.5 | K11: 0.9 | L11: =SUM(D11:K11) -> 5.7 | M11: =SUM(D11:J11)*1000000+K11*1400000 -> 6060000 | N11: 0 | O11: =SUM(O5:O10) -> 0 | P11: =SUM(L11:L11)+N11 -> 5.7 | Q11: =SUM(M11:M11)+O6 -> 6060000
B12: 計 | D12: =SUM(D6:D11) -> 8.1 | E12: =SUM(E6:E11) -> 4.9 | F12: =SUM(F6:F11) -> 8.1 | G12: =SUM(G6:G11) -> 16.4 | H12: =SUM(H6:H11) -> 4.3 | I12: =SUM(I6:I11) -> 2.7 | J12: =SUM(J6:J11) -> 7.1 | K12: =SUM(K6:K11) -> 12.4 | L12: =SUM(D12:K12) -> 64 | M12: =SUM(M6:M11) -> 68960000 | N12: =SUM(N6:N11) -> 0 | O12: =SUM(O6:O11) -> 0 | P12: =SUM(P6:P11) -> 64 | Q12: =SUM(Q6:Q11) -> 68960000
B13: 単価 | D13: 1000000 | E13: 1000000 | F13: 1000000 | G13: 1000000 | H13: 1000000 | I13: 1000000 | J13: 1000000 | K13: 1400000
B14: 金額 | D14: =D12*D13 -> 8100000 | E14: =E12*E13 -> 4900000 | F14: =F12*F13 -> 8100000 | G14: =G12*G13 -> 16400000 | H14: =H12*H13 -> 4300000 | I14: =I12*I13 -> 2700000 | J14: =J12*J13 -> 7100000 | K14: =K12*K13 -> 17360000
C17: 調査・要件定義（移行フェーズの契約変更）
C18: パターン | D18: クラウドアーキ基盤に移行 | R18: 備考
D19: アプリ | N19: DB | P19: 全体
B20: No. | C20: システム | D20: 調査・要件定義 | E20: 設計 | F20: 製造 | G20: 結合テスト | H20: システムテスト | I20: ユーザテスト | J20: 本番稼働 | K20: 管理 | L20: 工数計 | M20: 金額 | N20: 工数計 | O20: 金額 | P20: 工数計 | Q20: 金額
B21: 1 | C21: 数量確定システム（千葉・徳山） | D21: 3.2 | K21: 0.9 | L21: =SUM(D21:K21) -> 4.1 | M21: =SUM(D21:J21)*1000000+K21*1400000 -> 4460000 | N21: 0 | O21: 0 | P21: =SUM(L21:L25)+N21 -> 10.2 | Q21: =SUM(M21:M25)+O21 -> 11240000
B22: 2 | C22: 用役管理システム（千葉・徳山） | D22: 1.4 | K22: 0.6 | L22: =SUM(D22:K22) -> 2 | M22: =SUM(D22:J22)*1000000+K22*1400000 -> 2240000
B23: 3 | C23: 千葉化学品質管理システム | D23: 1.7 | K23: 0.6 | L23: =SUM(D23:K23) -> 2.3 | M23: =SUM(D23:J23)*1000000+K23*1400000 -> 2540000
B24: 4 | C24: ＬＭＰＰ包装システム | D24: 1.3 | K24: 0.5 | L24: =SUM(D24:K24) -> 1.8 | M24: =SUM(D24:J24)*1000000+K24*1400000 -> 2000000
B25: 5 | C25: 工場DB | L25: =SUM(D25:K25) -> 0 | M25: =SUM(D25:J25)*1000000+K25*1400000 -> 0
B26: 6 | C26: ヤ－ド操業システム（千葉・徳山） | D26: 0.5 | K26: 0.2 | L26: =SUM(D26:K26) -> 0.7 | M26: =SUM(D26:J26)*1000000+K26*1400000 -> 780000 | P26: =SUM(L26:L26)+N26 -> 0.7 | Q26: =SUM(M26:M26)+O26 -> 780000
B27: 7 | C27: 縮小共通基盤（移行フェーズ） | L27: =SUM(D27:K27) -> 0 | M27: -6807000 | P27: =SUM(L27:L27)+N27 -> 0 | Q27: =SUM(M27:M27)+O21 -> -6807000 | R27: 現契約残額を差し引き
B28: 計 | D28: =SUM(D21:D27) -> 8.1 | E28: =SUM(E21:E27) -> 0 | F28: =SUM(F21:F27) -> 0 | G28: =SUM(G21:G27) -> 0 | H28: =SUM(H21:H27) -> 0 | I28: =SUM(I21:I27) -> 0 | J28: =SUM(J21:J27) -> 0 | K28: =SUM(K22:K27) -> 1.9 | L28: =SUM(D28:K28) -> 10 | M28: =SUM(M21:M27) -> 5213000 | N28: =SUM(N21:N27) -> 0 | O28: =SUM(O21:O27) -> 0 | P28: =SUM(P21:P27) -> 10.9 | Q28: =SUM(Q21:Q27) -> 5213000
B29: 単価 | D29: 1000000 | E29: 1000000 | F29: 1000000 | G29: 1000000 | H29: 1000000 | I29: 1000000 | J29: 1000000 | K29: 1400000
B30: 金額 | D30: =D28*D29 -> 8100000 | E30: =E28*E29 -> 0 | F30: =F28*F29 -> 0 | G30: =G28*G29 -> 0 | H30: =H28*H29 -> 0 | I30: =I28*I29 -> 0 | J30: =J28*J29 -> 0 | K30: =K28*K29 -> 2660000
C32: 調査・要件定義(クラウドアーキから開始)
C33: パターン | D33: クラウドアーキ基盤に移行 | R33: 備考
D34: アプリ | N34: DB | P34: 全体
B35: No. | C35: システム | D35: 調査・要件定義 | E35: 設計 | F35: 製造 | G35: 結合テスト | H35: システムテスト | I35: ユーザテスト | J35: 本番稼働 | K35: 管理 | L35: 工数計 | M35: 金額 | N35: 工数計 | O35: 金額 | P35: 工数計 | Q35: 金額
B36: 1 | C36: 数量確定システム（千葉・徳山） | D36: 3.2 | K36: 0.9 | L36: =SUM(D36:K36) -> 4.1 | M36: =SUM(D36:J36)*1000000+K36*1400000 -> 4460000 | N36: 0 | O36: 0 | P36: =SUM(L36:L40)+N36 -> 10.2 | Q36: =SUM(M36:M40)+O36 -> 11240000
B37: 2 | C37: 用役管理システム（千葉・徳山） | D37: 1.4 | K37: 0.6 | L37: =SUM(D37:K37) -> 2 | M37: =SUM(D37:J37)*1000000+K37*1400000 -> 2240000
B38: 3 | C38: 千葉化学品質管理システム | D38: 1.7 | K38: 0.6 | L38: =SUM(D38:K38) -> 2.3 | M38: =SUM(D38:J38)*1000000+K38*1400000 -> 2540000
B39: 4 | C39: ＬＭＰＰ包装システム | D39: 1.3 | K39: 0.5 | L39: =SUM(D39:K39) -> 1.8 | M39: =SUM(D39:J39)*1000000+K39*1400000 -> 2000000
B40: 5 | C40: 工場DB | L40: =SUM(D40:K40) -> 0 | M40: =SUM(D40:J40)*1000000+K40*1400000 -> 0
B41: 6 | C41: ヤ－ド操業システム（千葉・徳山） | D41: 0.5 | K41: 0.2 | L41: =SUM(D41:K41) -> 0.7 | M41: =SUM(D41:J41)*1000000+K41*1400000 -> 780000 | P41: =SUM(L41:L41)+N41 -> 0.7 | Q41: =SUM(M41:M41)+O36 -> 780000
B42: 計 | D42: =SUM(D36:D41) -> 8.1 | E42: =SUM(E36:E41) -> 0 | F42: =SUM(F36:F41) -> 0 | G42: =SUM(G36:G41) -> 0 | H42: =SUM(H36:H41) -> 0 | I42: =SUM(I36:I41) -> 0 | J42: =SUM(J36:J41) -> 0 | K42: =SUM(K37:K41) -> 1.9 | L42: =SUM(D42:K42) -> 10 | M42: =SUM(M36:M41) -> 12020000 | N42: =SUM(N36:N41) -> 0 | O42: =SUM(O36:O41) -> 0 | P42: =SUM(P36:P41) -> 10.9 | Q42: =SUM(Q36:Q41) -> 12020000
B43: 単価 | D43: 1000000 | E43: 1000000 | F43: 1000000 | G43: 1000000 | H43: 1000000 | I43: 1000000 | J43: 1000000 | K43: 1400000
...

Sheet 見積 (システム・縮小共通基盤⇒クラウドアーキサマリ) 
C1: 工数直入力のため注意！！
C2: 見積（縮小共通基盤⇒クラウドアーキサマリ）
C3: パターン | D3: クラウドアーキ基盤に移行 | R3: 備考
D4: アプリ | N4: DB | P4: 全体
B5: No. | C5: システム | D5: 調査・要件定義 | E5: 設計 | F5: 製造 | G5: 結合テスト | H5: システムテスト | I5: ユーザテスト | J5: 本番稼働 | K5: 管理 | L5: 工数計 | M5: 金額 | N5: 工数計 | O5: 金額 | P5: 工数計 | Q5: 金額
B6: 1 | C6: 数量確定システム（千葉・徳山） | D6: 3.2 | E6: 1.6 | F6: 2.7 | G6: 5.2 | H6: 1.4 | I6: 0.8 | J6: 2 | K6: 3.8 | L6: =SUM(D6:K6) -> 20.7 | M6: =SUM(D6:J6)*1000000+K6*1400000 -> 22220000 | N6: 0 | O6: 0 | P6: =SUM(L6:L10)+N6 -> 58.3 | Q6: =SUM(M6:M10)+O6 -> 62900000
B7: 2 | C7: 用役管理システム（千葉・徳山） | D7: 1.4 | E7: 1.1 | F7: 1.5 | G7: 3.1 | H7: 1.1 | I7: 0.8 | J7: 2 | K7: 2.6 | L7: =SUM(D7:K7) -> 13.6 | M7: =SUM(D7:J7)*1000000+K7*1400000 -> 14640000
B8: 3 | C8: 千葉化学品質管理システム | D8: 1.7 | E8: 1.4 | F8: 1.6 | G8: 5.5 | H8: 0.8 | I8: 0.5 | J8: 0.6 | K8: 2.7 | L8: =SUM(D8:K8) -> 14.8 | M8: =SUM(D8:J8)*1000000+K8*1400000 -> 15880000
B9: 4 | C9: ＬＭＰＰ包装システム | D9: 1.3 | E9: 0.4 | F9: 1.6 | G9: 1.2 | H9: 0.8 | I9: 0.5 | J9: 0.6 | K9: 1.9 | L9: =SUM(D9:K9) -> 8.3 | M9: =SUM(D9:J9)*1000000+K9*1400000 -> 9060000
B10: 5 | C10: 工場DB | J10: 0.4 | K10: 0.5 | L10: =SUM(D10:K10) -> 0.9 | M10: =SUM(D10:J10)*1000000+K10*1400000 -> 1100000
B11: 6 | C11: ヤ－ド操業システム（千葉・徳山） | D11: 0.5 | E11: 0.4 | F11: 0.7 | G11: 1.4 | H11: 0.2 | I11: 0.1 | J11: 1.5 | K11: 0.9 | L11: =SUM(D11:K11) -> 5.7 | M11: =SUM(D11:J11)*1000000+K11*1400000 -> 6060000 | N11: 0 | O11: =SUM(O4:O9) -> 0 | P11: =SUM(L11:L11)+N11 -> 5.7 | Q11: =SUM(M11)+O11 -> 6060000
B12: 7 | C12: 縮小共通基盤対応 | M12: ='見積 (縮小共通基盤継続） '!D23 -> 6549000 | N12: 0 | O12: =SUM(O5:O10) -> 0 | P12: =SUM(L12:L12)+N12 -> 0 | Q12: =SUM(M12:M12)+O6 -> 6549000 | R12: 残作業工数
B13: 計 | D13: =SUM(D6:D12) -> 8.1 | E13: =SUM(E6:E12) -> 4.9 | F13: =SUM(F6:F12) -> 8.1 | G13: =SUM(G6:G12) -> 16.4 | H13: =SUM(H6:H12) -> 4.3 | I13: =SUM(I6:I12) -> 2.7 | J13: =SUM(J6:J12) -> 7.1 | K13: =SUM(K6:K12) -> 12.4 | L13: =SUM(D13:K13) -> 64 | M13: =SUM(M6:M12) -> 75509000 | N13: =SUM(N6:N12) -> 0 | O13: =SUM(O6:O12) -> 0 | P13: =SUM(P6:P12) -> 64 | Q13: =SUM(Q6:Q12) -> 75509000
B14: 単価 | D14: 1000000 | E14: 1000000 | F14: 1000000 | G14: 1000000 | H14: 1000000 | I14: 1000000 | J14: 1000000 | K14: 1400000
B15: 金額 | D15: =D13*D14 -> 8100000 | E15: =E13*E14 -> 4900000 | F15: =F13*F14 -> 8100000 | G15: =G13*G14 -> 16400000 | H15: =H13*H14 -> 4300000 | I15: =I13*I14 -> 2700000 | J15: =J13*J14 -> 7100000 | K15: =K13*K14 -> 17360000

Sheet 見積 (各フェーズ毎、品管包装付替済) 
C1: 工数直入力のため注意！！
C2: 見積（工程別サマリ）
C3: パターン | D3: クラウドアーキ基盤に移行 | R3: 備考
D4: アプリ | N4: DB | P4: 全体
B5: No. | C5: システム | D5: 調査・要件定義 | E5: 設計 | F5: 製造 | G5: 結合テスト | H5: システムテスト | I5: ユーザテスト | J5: 本番稼働 | K5: 管理 | L5: 工数計 | M5: 金額 | N5: 工数計 | O5: 金額 | P5: 工数計 | Q5: 金額
B6: 1 | C6: 数量確定システム（千葉・徳山） | D6: 3.2 | E6: 1.6 | F6: 2.7 | G6: 5.2 | H6: 1.4 | I6: 0.8 | J6: 2 | K6: 3.8 | L6: =SUM(D6:K6) -> 20.7 | M6: =SUM(D6:J6)*1000000+K6*1400000 -> 22220000 | N6: 0 | O6: 0 | P6: =SUM(L6:L10)+N6 -> 58.3 | Q6: =SUM(M6:M10)+O6 -> 62900000
B7: 2 | C7: 用役管理システム（千葉・徳山） | D7: 1.4 | E7: 1.1 | F7: 1.5 | G7: 3.1 | H7: 1.1 | I7: 0.8 | J7: 2 | K7: 2.6 | L7: =SUM(D7:K7) -> 13.6 | M7: =SUM(D7:J7)*1000000+K7*1400000 -> 14640000
B8: 3 | C8: 千葉化学品質管理システム | D8: 1.5 | E8: 0.9 | F8: 1.2 | G8: 3.1 | H8: 0.6 | I8: 0.3 | J8: 0.3 | K8: 2.2 | L8: =SUM(D8:K8) -> 10.1 | M8: =SUM(D8:J8)*1000000+K8*1400000 -> 10980000
B9: 4 | C9: ＬＭＰＰ包装システム | D9: 1.5 | E9: 0.9 | F9: 2 | G9: 3.6 | H9: 1 | I9: 0.7 | J9: 0.9 | K9: 2.4 | L9: =SUM(D9:K9) -> 13 | M9: =SUM(D9:J9)*1000000+K9*1400000 -> 13960000
B10: 5 | C10: 工場DB | J10: 0.4 | K10: 0.5 | L10: =SUM(D10:K10) -> 0.9 | M10: =SUM(D10:J10)*1000000+K10*1400000 -> 1100000
B11: 6 | C11: ヤ－ド操業システム（千葉・徳山） | D11: 0.5 | E11: 0.4 | F11: 0.7 | G11: 1.4 | H11: 0.2 | I11: 0.1 | J11: 1.5 | K11: 0.9 | L11: =SUM(D11:K11) -> 5.7 | M11: =SUM(D11:J11)*1000000+K11*1400000 -> 6060000 | N11: 0 | O11: =SUM(O5:O10) -> 0 | P11: =SUM(L11:L11)+N11 -> 5.7 | Q11: =SUM(M11:M11)+O6 -> 6060000
B12: 計 | D12: =SUM(D6:D11) -> 8.1 | E12: =SUM(E6:E11) -> 4.9 | F12: =SUM(F6:F11) -> 8.1 | G12: =SUM(G6:G11) -> 16.4 | H12: =SUM(H6:H11) -> 4.3 | I12: =SUM(I6:I11) -> 2.7 | J12: =SUM(J6:J11) -> 7.1 | K12: =SUM(K6:K11) -> 12.4 | L12: =SUM(D12:K12) -> 64 | M12: =SUM(M6:M11) -> 68960000 | N12: =SUM(N6:N11) -> 0 | O12: =SUM(O6:O11) -> 0 | P12: =SUM(P6:P11) -> 64 | Q12: =SUM(Q6:Q11) -> 68960000
B13: 単価 | D13: 1000000 | E13: 1000000 | F13: 1000000 | G13: 1000000 | H13: 1000000 | I13: 1000000 | J13: 1000000 | K13: 1400000
B14: 金額 | D14: =D12*D13 -> 8100000 | E14: =E12*E13 -> 4900000 | F14: =F12*F13 -> 8100000 | G14: =G12*G13 -> 16400000 | H14: =H12*H13 -> 4300000 | I14: =I12*I13 -> 2700000 | J14: =J12*J13 -> 7100000 | K14: =K12*K13 -> 17360000
C16: 調査・要件定義（移行フェーズの契約変更）
C17: パターン | D17: クラウドアーキ基盤に移行 | R17: 備考
D18: アプリ | N18: DB | P18: 全体
B19: No. | C19: システム | D19: 調査・要件定義 | E19: 設計 | F19: 製造 | G19: 結合テスト | H19: システムテスト | I19: ユーザテスト | J19: 本番稼働 | K19: 管理 | L19: 工数計 | M19: 金額 | N19: 工数計 | O19: 金額 | P19: 工数計 | Q19: 金額
B20: 1 | C20: 数量確定システム（千葉・徳山） | D20: 3.2 | K20: 0.9 | L20: =SUM(D20:K20) -> 4.1 | M20: =SUM(D20:J20)*1000000+K20*1400000 -> 4460000 | N20: 0 | O20: 0 | P20: =SUM(L20:L24)+N20 -> 10.2 | Q20: =SUM(M20:M24)+O20 -> 11240000
B21: 2 | C21: 用役管理システム（千葉・徳山） | D21: 1.4 | K21: 0.6 | L21: =SUM(D21:K21) -> 2 | M21: =SUM(D21:J21)*1000000+K21*1400000 -> 2240000
B22: 3 | C22: 千葉化学品質管理システム | D22: 1.7 | K22: 0.6 | L22: =SUM(D22:K22) -> 2.3 | M22: =SUM(D22:J22)*1000000+K22*1400000 -> 2540000
B23: 4 | C23: ＬＭＰＰ包装システム | D23: 1.3 | K23: 0.5 | L23: =SUM(D23:K23) -> 1.8 | M23: =SUM(D23:J23)*1000000+K23*1400000 -> 2000000
B24: 5 | C24: 工場DB | L24: =SUM(D24:K24) -> 0 | M24: =SUM(D24:J24)*1000000+K24*1400000 -> 0
B25: 6 | C25: ヤ－ド操業システム（千葉・徳山） | D25: 0.5 | K25: 0.2 | L25: =SUM(D25:K25) -> 0.7 | M25: =SUM(D25:J25)*1000000+K25*1400000 -> 780000 | P25: =SUM(L25:L25)+N25 -> 0.7 | Q25: =SUM(M25:M25)+O25 -> 780000
B26: 7 | C26: 縮小共通基盤（移行フェーズ） | L26: =SUM(D26:K26) -> 0 | M26: -6807000 | P26: =SUM(L26:L26)+N26 -> 0 | Q26: =SUM(M26:M26)+O20 -> -6807000 | R26: 現契約残額を差し引き
B27: 計 | D27: =SUM(D20:D26) -> 8.1 | E27: =SUM(E20:E26) -> 0 | F27: =SUM(F20:F26) -> 0 | G27: =SUM(G20:G26) -> 0 | H27: =SUM(H20:H26) -> 0 | I27: =SUM(I20:I26) -> 0 | J27: =SUM(J20:J26) -> 0 | K27: =SUM(K21:K26) -> 1.9 | L27: =SUM(D27:K27) -> 10 | M27: =SUM(M20:M26) -> 5213000 | N27: =SUM(N20:N26) -> 0 | O27: =SUM(O20:O26) -> 0 | P27: =SUM(P20:P26) -> 10.9 | Q27: =SUM(Q20:Q26) -> 5213000
B28: 単価 | D28: 1000000 | E28: 1000000 | F28: 1000000 | G28: 1000000 | H28: 1000000 | I28: 1000000 | J28: 1000000 | K28: 1400000
B29: 金額 | D29: =D27*D28 -> 8100000 | E29: =E27*E28 -> 0 | F29: =F27*F28 -> 0 | G29: =G27*G28 -> 0 | H29: =H27*H28 -> 0 | I29: =I27*I28 -> 0 | J29: =J27*J28 -> 0 | K29: =K27*K28 -> 2660000
C31: 調査・要件定義(クラウドアーキから開始)
C32: パターン | D32: クラウドアーキ基盤に移行 | R32: 備考
D33: アプリ | N33: DB | P33: 全体
B34: No. | C34: システム | D34: 調査・要件定義 | E34: 設計 | F34: 製造 | G34: 結合テスト | H34: システムテスト | I34: ユーザテスト | J34: 本番稼働 | K34: 管理 | L34: 工数計 | M34: 金額 | N34: 工数計 | O34: 金額 | P34: 工数計 | Q34: 金額
B35: 1 | C35: 数量確定システム（千葉・徳山） | D35: 3.2 | E35: 1.6 | K35: 0.8 | L35: =SUM(D35:K35) -> 5.6 | M35: =SUM(D35:J35)*1000000+K35*1400000 -> 5920000 | N35: 0 | O35: 0 | P35: =SUM(L35:L39)+N35 -> 15 | Q35: =SUM(M35:M39)+O35 -> 16160000
B36: 2 | C36: 用役管理システム（千葉・徳山） | D36: 1.4 | E36: 1.1 | K36: 0.7 | L36: =SUM(D36:K36) -> 3.2 | M36: =SUM(D36:J36)*1000000+K36*1400000 -> 3480000
B37: 3 | C37: 千葉化学品質管理システム | D37: 1.5 | E37: 0.9 | K37: 0.7 | L37: =SUM(D37:K37) -> 3.1 | M37: =SUM(D37:J37)*1000000+K37*1400000 -> 3380000
B38: 4 | C38: ＬＭＰＰ包装システム | D38: 1.5 | E38: 0.9 | K38: 0.7 | L38: =SUM(D38:K38) -> 3.1 | M38: =SUM(D38:J38)*1000000+K38*1400000 -> 3380000
B39: 5 | C39: 工場DB | L39: =SUM(D39:K39) -> 0 | M39: =SUM(D39:J39)*1000000+K39*1400000 -> 0
B40: 6 | C40: ヤ－ド操業システム（千葉・徳山） | D40: 0.5 | E40: 0.4 | K40: 0.3 | L40: =SUM(D40:K40) -> 1.2 | M40: =SUM(D40:J40)*1000000+K40*1400000 -> 1320000 | P40: =SUM(L40:L40)+N40 -> 1.2 | Q40: =SUM(M40:M40)+O35 -> 1320000
B41: 計 | D41: =SUM(D35:D40) -> 8.1 | E41: =SUM(E35:E40) -> 4.9 | F41: =SUM(F35:F40) -> 0 | G41: =SUM(G35:G40) -> 0 | H41: =SUM(H35:H40) -> 0 | I41: =SUM(I35:I40) -> 0 | J41: =SUM(J35:J40) -> 0 | K41: =SUM(K35:K40) -> 3.2 | L41: =SUM(D41:K41) -> 16.2 | M41: =SUM(M35:M40) -> 17480000 | N41: =SUM(N35:N40) -> 0 | O41: =SUM(O35:O40) -> 0 | P41: =SUM(P35:P40) -> 16.2 | Q41: =SUM(Q35:Q40) -> 17480000
B42: 単価 | D42: 1000000 | E42: 1000000 | F42: 1000000 | G42: 1000000 | H42: 1000000 | I42: 1000000 | J42: 1000000 | K42: 1400000
...

Sheet 見積 (要件_設計で区切り) 
C1: 工数直入力のため注意！！
C2: 見積（工程別サマリ）
C3: パターン | D3: クラウドアーキ基盤に移行 | R3: 備考
D4: アプリ | N4: DB | P4: 全体
B5: No. | C5: システム | D5: 調査・要件定義 | E5: 設計 | F5: 製造 | G5: 結合テスト | H5: システムテスト | I5: ユーザテスト | J5: 本番稼働 | K5: 管理 | L5: 工数計 | M5: 金額 | N5: 工数計 | O5: 金額 | P5: 工数計 | Q5: 金額
B6: 1 | C6: 数量確定システム（千葉・徳山） | D6: 3.2 | E6: 1.6 | F6: 2.7 | G6: 5.2 | H6: 1.4 | I6: 0.8 | J6: 2 | K6: 3.8 | L6: =SUM(D6:K6) -> 20.7 | M6: =SUM(D6:J6)*1000000+K6*1400000 -> 22220000 | N6: 0 | O6: 0 | P6: =SUM(L6:L10)+N6 -> 58.3 | Q6: =SUM(M6:M10)+O6 -> 62900000
B7: 2 | C7: 用役管理システム（千葉・徳山） | D7: 1.4 | E7: 1.1 | F7: 1.5 | G7: 3.1 | H7: 1.1 | I7: 0.8 | J7: 2 | K7: 2.6 | L7: =SUM(D7:K7) -> 13.6 | M7: =SUM(D7:J7)*1000000+K7*1400000 -> 14640000
B8: 3 | C8: 千葉化学品質管理システム | D8: 1.7 | E8: 1.4 | F8: 1.6 | G8: 5.5 | H8: 0.8 | I8: 0.5 | J8: 0.6 | K8: 2.7 | L8: =SUM(D8:K8) -> 14.8 | M8: =SUM(D8:J8)*1000000+K8*1400000 -> 15880000
B9: 4 | C9: ＬＭＰＰ包装システム | D9: 1.3 | E9: 0.4 | F9: 1.6 | G9: 1.2 | H9: 0.8 | I9: 0.5 | J9: 0.6 | K9: 1.9 | L9: =SUM(D9:K9) -> 8.3 | M9: =SUM(D9:J9)*1000000+K9*1400000 -> 9060000
B10: 5 | C10: 工場DB | J10: 0.4 | K10: 0.5 | L10: =SUM(D10:K10) -> 0.9 | M10: =SUM(D10:J10)*1000000+K10*1400000 -> 1100000
B11: 6 | C11: ヤ－ド操業システム（千葉・徳山） | D11: 0.5 | E11: 0.4 | F11: 0.7 | G11: 1.4 | H11: 0.2 | I11: 0.1 | J11: 1.5 | K11: 0.9 | L11: =SUM(D11:K11) -> 5.7 | M11: =SUM(D11:J11)*1000000+K11*1400000 -> 6060000 | N11: 0 | O11: =SUM(O5:O10) -> 0 | P11: =SUM(L11:L11)+N11 -> 5.7 | Q11: =SUM(M11:M11)+O6 -> 6060000
B12: 計 | D12: =SUM(D6:D11) -> 8.1 | E12: =SUM(E6:E11) -> 4.9 | F12: =SUM(F6:F11) -> 8.1 | G12: =SUM(G6:G11) -> 16.4 | H12: =SUM(H6:H11) -> 4.3 | I12: =SUM(I6:I11) -> 2.7 | J12: =SUM(J6:J11) -> 7.1 | K12: =SUM(K6:K11) -> 12.4 | L12: =SUM(D12:K12) -> 64 | M12: =SUM(M6:M11) -> 68960000 | N12: =SUM(N6:N11) -> 0 | O12: =SUM(O6:O11) -> 0 | P12: =SUM(P6:P11) -> 64 | Q12: =SUM(Q6:Q11) -> 68960000
B13: 単価 | D13: 1000000 | E13: 1000000 | F13: 1000000 | G13: 1000000 | H13: 1000000 | I13: 1000000 | J13: 1000000 | K13: 1400000
B14: 金額 | D14: =D12*D13 -> 8100000 | E14: =E12*E13 -> 4900000 | F14: =F12*F13 -> 8100000 | G14: =G12*G13 -> 16400000 | H14: =H12*H13 -> 4300000 | I14: =I12*I13 -> 2700000 | J14: =J12*J13 -> 7100000 | K14: =K12*K13 -> 17360000
C16: 調査・要件定義（移行フェーズの契約変更）
C17: パターン | D17: クラウドアーキ基盤に移行 | R17: 備考
D18: アプリ | N18: DB | P18: 全体
B19: No. | C19: システム | D19: 調査・要件定義 | E19: 設計 | F19: 製造 | G19: 結合テスト | H19: システムテスト | I19: ユーザテスト | J19: 本番稼働 | K19: 管理 | L19: 工数計 | M19: 金額 | N19: 工数計 | O19: 金額 | P19: 工数計 | Q19: 金額
B20: 1 | C20: 数量確定システム（千葉・徳山） | D20: 3.2 | K20: 0.9 | L20: =SUM(D20:K20) -> 4.1 | M20: =SUM(D20:J20)*1000000+K20*1400000 -> 4460000 | N20: 0 | O20: 0 | P20: =SUM(L20:L24)+N20 -> 10.2 | Q20: =SUM(M20:M24)+O20 -> 11240000
B21: 2 | C21: 用役管理システム（千葉・徳山） | D21: 1.4 | K21: 0.6 | L21: =SUM(D21:K21) -> 2 | M21: =SUM(D21:J21)*1000000+K21*1400000 -> 2240000
B22: 3 | C22: 千葉化学品質管理システム | D22: 1.7 | K22: 0.6 | L22: =SUM(D22:K22) -> 2.3 | M22: =SUM(D22:J22)*1000000+K22*1400000 -> 2540000
B23: 4 | C23: ＬＭＰＰ包装システム | D23: 1.3 | K23: 0.5 | L23: =SUM(D23:K23) -> 1.8 | M23: =SUM(D23:J23)*1000000+K23*1400000 -> 2000000
B24: 5 | C24: 工場DB | L24: =SUM(D24:K24) -> 0 | M24: =SUM(D24:J24)*1000000+K24*1400000 -> 0
B25: 6 | C25: ヤ－ド操業システム（千葉・徳山） | D25: 0.5 | K25: 0.2 | L25: =SUM(D25:K25) -> 0.7 | M25: =SUM(D25:J25)*1000000+K25*1400000 -> 780000 | P25: =SUM(L25:L25)+N25 -> 0.7 | Q25: =SUM(M25:M25)+O25 -> 780000
B26: 7 | C26: 縮小共通基盤（移行フェーズ） | L26: =SUM(D26:K26) -> 0 | M26: -6807000 | P26: =SUM(L26:L26)+N26 -> 0 | Q26: =SUM(M26:M26)+O20 -> -6807000 | R26: 現契約残額を差し引き
B27: 計 | D27: =SUM(D20:D26) -> 8.1 | E27: =SUM(E20:E26) -> 0 | F27: =SUM(F20:F26) -> 0 | G27: =SUM(G20:G26) -> 0 | H27: =SUM(H20:H26) -> 0 | I27: =SUM(I20:I26) -> 0 | J27: =SUM(J20:J26) -> 0 | K27: =SUM(K21:K26) -> 1.9 | L27: =SUM(D27:K27) -> 10 | M27: =SUM(M20:M26) -> 5213000 | N27: =SUM(N20:N26) -> 0 | O27: =SUM(O20:O26) -> 0 | P27: =SUM(P20:P26) -> 10.9 | Q27: =SUM(Q20:Q26) -> 5213000
B28: 単価 | D28: 1000000 | E28: 1000000 | F28: 1000000 | G28: 1000000 | H28: 1000000 | I28: 1000000 | J28: 1000000 | K28: 1400000
B29: 金額 | D29: =D27*D28 -> 8100000 | E29: =E27*E28 -> 0 | F29: =F27*F28 -> 0 | G29: =G27*G28 -> 0 | H29: =H27*H28 -> 0 | I29: =I27*I28 -> 0 | J29: =J27*J28 -> 0 | K29: =K27*K28 -> 2660000
C31: 調査・要件定義(クラウドアーキから開始)
C32: パターン | D32: クラウドアーキ基盤に移行 | R32: 備考
D33: アプリ | N33: DB | P33: 全体
B34: No. | C34: システム | D34: 調査・要件定義 | E34: 設計 | F34: 製造 | G34: 結合テスト | H34: システムテスト | I34: ユーザテスト | J34: 本番稼働 | K34: 管理 | L34: 工数計 | M34: 金額 | N34: 工数計 | O34: 金額 | P34: 工数計 | Q34: 金額
B35: 1 | C35: 数量確定システム（千葉・徳山） | D35: 3.2 | E35: 1.6 | K35: 1.2 | L35: =SUM(D35:K35) -> 6 | M35: =SUM(D35:J35)*1000000+K35*1400000 -> 6480000 | N35: 0 | O35: 0 | P35: =SUM(L35:L39)+N35 -> 15.6 | Q35: =SUM(M35:M39)+O35 -> 17000000
B36: 2 | C36: 用役管理システム（千葉・徳山） | D36: 1.4 | E36: 1.1 | K36: 0.8 | L36: =SUM(D36:K36) -> 3.3 | M36: =SUM(D36:J36)*1000000+K36*1400000 -> 3620000
B37: 3 | C37: 千葉化学品質管理システム | D37: 1.7 | E37: 1.4 | K37: 0.8 | L37: =SUM(D37:K37) -> 3.9 | M37: =SUM(D37:J37)*1000000+K37*1400000 -> 4220000
B38: 4 | C38: ＬＭＰＰ包装システム | D38: 1.3 | E38: 0.4 | K38: 0.7 | L38: =SUM(D38:K38) -> 2.4 | M38: =SUM(D38:J38)*1000000+K38*1400000 -> 2680000
B39: 5 | C39: 工場DB | L39: =SUM(D39:K39) -> 0 | M39: =SUM(D39:J39)*1000000+K39*1400000 -> 0
B40: 6 | C40: ヤ－ド操業システム（千葉・徳山） | D40: 0.5 | E40: 0.4 | K40: 0.3 | L40: =SUM(D40:K40) -> 1.2 | M40: =SUM(D40:J40)*1000000+K40*1400000 -> 1320000 | P40: =SUM(L40:L40)+N40 -> 1.2 | Q40: =SUM(M40:M40)+O35 -> 1320000
B41: 計 | D41: =SUM(D35:D40) -> 8.1 | E41: =SUM(E35:E40) -> 4.9 | F41: =SUM(F35:F40) -> 0 | G41: =SUM(G35:G40) -> 0 | H41: =SUM(H35:H40) -> 0 | I41: =SUM(I35:I40) -> 0 | J41: =SUM(J35:J40) -> 0 | K41: =SUM(K36:K40) -> 2.6 | L41: =SUM(D41:K41) -> 15.6 | M41: =SUM(M35:M40) -> 18320000 | N41: =SUM(N35:N40) -> 0 | O41: =SUM(O35:O40) -> 0 | P41: =SUM(P35:P40) -> 16.8 | Q41: =SUM(Q35:Q40) -> 18320000
B42: 単価 | D42: 1000000 | E42: 1000000 | F42: 1000000 | G42: 1000000 | H42: 1000000 | I42: 1000000 | J42: 1000000 | K42: 1400000
...

Sheet スケジュール案・要員計画（全体）
A2: システム | B2: 担当 | C2: 2024年 | O2: 2025年 | S2: 202６年
C3: 1月 | D3: 2月 | E3: 3月 | F3: 4月 | G3: 5月 | H3: 6月 | I3: 7月 | J3: 8月 | K3: 9月 | L3: 10月 | M3: 11月 | N3: 12月 | O3: 9月 | P3: 10月 | Q3: 11月 | R3: 12月 | S3: １月 | T3: ２月 | U3: ３月 | V3: ４月 | W3: ５月 | X3: ６月
A4: マイルストン | K4: ★縮小共通基盤構築 | P4: ★新共通基盤構築 | U4: ★館林DC廃止
A5: 数量確定システム（千葉・徳山）
A6: 用役管理システム（千葉・徳山）
A7: 千葉化学品質管理システム
A8: ＬＭＰＰ包装システム
A9: ヤード操業システム
A10: 工場DB
B12: 本番リリースタイミング
A13: 千葉化学品質管理システム | B13: 2026年2月上旬
A14: ＬＭＰＰ包装システム | B14: 2026年2月上旬
A15: 工場DB | B15: 2026年2月上旬
A16: ヤード操業システム（千葉・徳山） | B16: 2026年2月中旬
A17: 数量確定システム（千葉・徳山） | B17: 2026年2月下旬
A18: 用役管理システム（千葉・徳山） | B18: 2026年2月下旬
A20: 想定要員数
A21: 管理 | O21: 2 | P21: 2 | Q21: 2 | R21: 2 | S21: 2 | T21: 1.5
A22: 数量確定 | O22: 2 | P22: 2 | Q22: 3 | R22: 3.5 | S22: 2 | T22: 1
A23: 用役管理 | O23: 1 | P23: 2 | Q23: 3 | R23: 2.5 | S23: 2 | T23: 1
A24: 千葉化学 | O24: 1 | P24: 2 | Q24: 3 | R24: 3.5 | S24: 2 | T24: 0.5
A25: 包装 | O25: 1 | P25: 1 | Q25: 1 | R25: 1.5 | S25: 0.5 | T25: 0.5
A26: ヤード操業 | F26: 2 | G26: 2 | H26: 5 | I26: 5 | J26: 5 | K26: 5 | L26: 5 | M26: 5 | N26: 5 | O26: 1 | P26: 1 | Q26: 1 | R26: 1 | S26: 1 | T26: 0.5
A27: 合計 | C27: =SUM(C22:C26) -> 0 | D27: =SUM(D22:D26) -> 0 | E27: =SUM(E22:E26) -> 0 | F27: =SUM(F22:F26) -> 2 | G27: =SUM(G22:G26) -> 2 | H27: =SUM(H22:H26) -> 5 | I27: =SUM(I22:I26) -> 5 | J27: =SUM(J22:J26) -> 5 | ... N27: =SUM(N22:N26) -> 5 | O27: =SUM(O21:O26) -> 8 | P27: =SUM(P21:P26) -> 10 | Q27: =SUM(Q21:Q26) -> 13 | R27: =SUM(R21:R26) -> 14 | S27: =SUM(S21:S26) -> 9.5 | T27: =SUM(T21:T26) -> 5 | U27: =SUM(U21:U26) -> 0 | V27: =SUM(V21:V26) -> 0 | ... X27: =SUM(X21:X26) -> 0
A30: 要員
A31: 要員
A32: 管理（工場） | B32: 野村 | O32: 0.5 | P32: 0.5 | Q32: 0.5 | R32: 0.5 | S32: 0.5 | T32: 0.5 | U32: 0.25 | Y32: =SUM(O32:X32) -> 3.25 | Z32: 人月
A33: 管理（工場） | B33: 石井 | O33: 0.5 | P33: 0.5 | Q33: 0.5 | R33: 0.5 | S33: 0.5 | T33: 0.5 | U33: 0.5 | Y33: =SUM(O33:X33) -> 3.5 | Z33: 人月
A34: 管理（工場） | B34: グエン・タン・ドゥオック | O34: 0.5 | P34: 1 | Q34: 1 | R34: 1 | S34: 1 | T34: 1 | U34: 0.5 | Y34: =SUM(O34:X34) -> 6 | Z34: 人月
A35: 数量確定 | B35: 天川 | O35: 0.5 | P35: 0.5 | Q35: 0.5 | R35: 0.5 | S35: 0.5 | T35: 0.5 | U35: 0.5 | Y35: =SUM(O35:X35) -> 3.5 | Z35: 人月
A36: 数量確定 | B36: グエン・チュン・グエン | O36: 0.25 | P36: 0.5 | Q36: 0.5 | R36: 0.5 | S36: 0.5 | T36: 0.5 | U36: 0.25 | Y36: =SUM(O36:X36) -> 3 | Z36: 人月
A37: 数量確定 | B37: ドー・ﾘｲ・アイン・トゥ | O37: 0.5 | P37: 1 | Q37: 1 | R37: 1 | Y37: =SUM(O37:X37) -> 3.5 | Z37: 人月
A38: 数量確定 | B38: レ・ファム・バオ・ロック | O38: 0.5 | P38: 1 | Q38: 1 | R38: 1 | Y38: =SUM(O38:X38) -> 3.5 | Z38: 人月
A39: 数量確定 | B39: VT1 | Q39: 1 | R39: 1 | Y39: =SUM(O39:X39) -> 2 | Z39: 人月
A40: 数量確定 | B40: VT5 | R40: 0.5 | Y40: =SUM(O40:X40) -> 0.5 | Z40: 人月
A41: 用役管理 | B41: 天川 | O41: 0.5 | P41: 0.5 | Q41: 0.5 | R41: 0.5 | S41: 0.5 | T41: 0.5 | U41: 0.5 | Y41: =SUM(O41:X41) -> 3.5 | Z41: 人月
A42: 用役管理 | B42: グエン・チュン・グエン | O42: 0.25 | P42: 0.5 | Q42: 0.5 | R42: 0.5 | S42: 0.5 | T42: 0.5 | U42: 0.25 | Y42: =SUM(O42:X42) -> 3 | Z42: 人月
A43: 用役管理 | B43: ドー・グエン・ティ・トゥイ・ズイ | P43: 1 | Q43: 1 | R43: 1 | Y43: =SUM(O43:X43) -> 3 | Z43: 人月
A44: 用役管理 | B44: VT2 | Q44: 1 | R44: 1 | Y44: =SUM(O44:X44) -> 2 | Z44: 人月
A45: 用役管理 | B45: VT5 | R45: 0.5 | Y45: =SUM(O45:X45) -> 0.5 | Z45: 人月
...

Sheet スケジュール案・要員計画 (開発フェーズ_工程別)
O1: 調査・要件定義 | P1: 設計 | Q1: 製造 | R1: 結合テスト | S1: システムテスト | T1: ユーザテスト | U1: 本番稼働
A3: システム | B3: 担当 | C3: 2024年 | O3: 2025年 | S3: 202６年
C4: 1月 | D4: 2月 | E4: 3月 | F4: 4月 | G4: 5月 | H4: 6月 | I4: 7月 | J4: 8月 | K4: 9月 | L4: 10月 | M4: 11月 | N4: 12月 | O4: 9月 | P4: 10月 | Q4: 11月 | R4: 12月 | S4: １月 | T4: ２月 | U4: ３月 | V4: ４月 | W4: ５月 | X4: ６月
A5: マイルストン | K5: ★縮小共通基盤構築 | P5: ★新共通基盤構築 | U5: ★館林DC廃止
A6: 数量確定システム（千葉・徳山）
A7: 用役管理システム（千葉・徳山）
A8: 千葉化学品質管理システム
A9: ＬＭＰＰ包装システム
A10: ヤード操業システム
A11: 工場DB
B13: 本番リリースタイミング
A14: 千葉化学品質管理システム | B14: 2026年2月上旬
A15: ＬＭＰＰ包装システム | B15: 2026年2月上旬
A16: 工場DB | B16: 2026年2月上旬
A17: ヤード操業システム（千葉・徳山） | B17: 2026年2月中旬
A18: 数量確定システム（千葉・徳山） | B18: 2026年2月下旬
A19: 用役管理システム（千葉・徳山） | B19: 2026年2月下旬
A21: 想定要員数(工程単位) | Z21: 管理のみ
A22: 管理 | Q22: =AB29 -> 2.6 | R22: =AC29 -> 3.4 | S22: =AD29 -> 1.5 | T22: =AE29 -> 1.1 | U22: =AF29 -> 1.9 | V22: =SUM(Q22:U22) -> 10.5 | Z22: 調査・要件定義 | AA22: 設計 | AB22: 製造 | AC22: 結合テスト | AD22: システムテスト | AE22: ユーザテスト | AF22: 本番稼働
A23: 数量確定システム（千葉・徳山） | Q23: 3.2 | R23: 5.2 | S23: 1.4 | T23: 0.8 | U23: 2 | V23: =SUM(Q23:U23) -> 12.6 | Y23: 数量確定システム（千葉・徳山） | Z23: 0 | AA23: 0 | AB23: 0.8 | AC23: 1 | AD23: 0.5 | AE23: 0.3 | AF23: 0.5
A24: 用役管理システム（千葉・徳山） | Q24: 2.1 | R24: 3.1 | S24: 1.1 | T24: 0.8 | U24: 2 | V24: =SUM(Q24:U24) -> 9.1 | Y24: 用役管理システム（千葉・徳山） | Z24: 0 | AA24: 0 | AB24: 0.5 | AC24: 0.7 | AD24: 0.3 | AE24: 0.3 | AF24: 0.4
A25: 千葉化学品質管理システム | Q25: 2.2 | R25: 5.5 | S25: 0.8 | T25: 0.5 | U25: 0.5 | V25: =SUM(Q25:U25) -> 9.5 | Y25: 千葉化学品質管理システム | Z25: 0 | AA25: 0 | AB25: 0.6 | AC25: 1 | AD25: 0.3 | AE25: 0.2 | AF25: 0.2
A26: ＬＭＰＰ包装システム | Q26: 2 | R26: 1.2 | S26: 0.8 | T26: 0.5 | U26: 0.5 | V26: =SUM(Q26:U26) -> 5 | Y26: ＬＭＰＰ包装システム | Z26: 0 | AA26: 0 | AB26: 0.6 | AC26: 0.4 | AD26: 0.3 | AE26: 0.2 | AF26: 0.2
A27: 工場DB | Q27: 0 | R27: 0 | S27: 0 | T27: 0.1 | U27: 0.3 | V27: =SUM(Q27:U27) -> 0.4 | Y27: 工場DB | Z27: 0 | AA27: 0 | AB27: 0 | AC27: 0 | AD27: 0 | AE27: 0 | AF27: 0.4
A28: ヤ－ド操業システム（千葉・徳山） | Q28: 1 | R28: 1.4 | S28: 0.2 | T28: 0.1 | U28: 1.3 | V28: =SUM(Q28:U28) -> 4 | Y28: ヤ－ド操業システム（千葉・徳山） | Z28: 0 | AA28: 0 | AB28: 0.1 | AC28: 0.3 | AD28: 0.1 | AE28: 0.1 | AF28: 0.2
A29: 合計 | C29: =SUM(C24:C28) -> 0 | D29: =SUM(D24:D28) -> 0 | E29: =SUM(E24:E28) -> 0 | F29: =SUM(F24:F28) -> 0 | G29: =SUM(G24:G28) -> 0 | H29: =SUM(H24:H28) -> 0 | I29: =SUM(I24:I28) -> 0 | J29: =SUM(J24:J28) -> 0 | ... N29: =SUM(N24:N28) -> 0 | O29: =SUM(O23:O28) -> 0 | P29: =SUM(P23:P28) -> 0 | Q29: =SUM(Q22:Q28) -> 13.1 | R29: =SUM(R22:R28) -> 19.8 | S29: =SUM(S22:S28) -> 5.8 | T29: =SUM(T22:T28) -> 3.9 | U29: =SUM(U22:U28) -> 8.5 | V29: =SUM(Q29:U29) -> 51.1 | Z29: =SUM(Z23:Z28) -> 0 | AA29: =SUM(AA23:AA28) -> 0 | AB29: =SUM(AB23:AB28) -> 2.6 | AC29: =SUM(AC23:AC28) -> 3.4 | AD29: =SUM(AD23:AD28) -> 1.5 | AE29: =SUM(AE23:AE28) -> 1.1 | AF29: =SUM(AF23:AF28) -> 1.9
A31: 要員
A32: 管理（工場） | B32: 野村 | Q32: 0.5 | R32: 0.5 | S32: 0.5 | T32: 0.5 | U32: 0.25 | V32: =SUM(Q32:U32) -> 2.25
A33: 管理（工場） | B33: 石井 | Q33: 0.5 | R33: 0.5 | S33: 0.5 | T33: 0.5 | U33: 0.5 | V33: =SUM(Q33:U33) -> 2.5
A34: 管理（工場） | B34: グエン・タン・ドゥオック | Q34: 1 | R34: 1 | S34: 1 | T34: 1 | U34: 0.5 | V34: =SUM(Q34:U34) -> 4.5
A35: 数量確定 | B35: 天川 | Q35: 0.5 | R35: 0.5 | S35: 0.5 | T35: 0.5 | U35: 0.5 | V35: =SUM(Q35:U35) -> 2.5
A36: 数量確定 | B36: グエン・チュン・グエン | Q36: 0.5 | R36: 0.5 | S36: 0.5 | T36: 0.5 | U36: 0.5 | V36: =SUM(Q36:U36) -> 2.5
A37: 数量確定 | B37: ドー・ﾘｲ・アイン・トゥ | Q37: 1 | R37: 1 | V37: =SUM(Q37:U37) -> 2
A38: 数量確定 | B38: レ・ファム・バオ・ロック | Q38: 1 | R38: 1 | V38: =SUM(Q38:U38) -> 2
A39: 数量確定 | B39: VT1 | Q39: 0.5 | R39: 0.5 | V39: =SUM(Q39:U39) -> 1
A40: 用役管理 | B40: 天川 | Q40: 0.5 | R40: 0.5 | S40: 0.5 | T40: 0.5 | U40: 0.5 | V40: =SUM(Q40:U40) -> 2.5
A41: 用役管理 | B41: グエン・チュン・グエン | Q41: 0.5 | R41: 0.5 | S41: 0.5 | T41: 0.5 | U41: 0.5 | V41: =SUM(Q41:U41) -> 2.5
A42: 用役管理 | B42: ドー・グエン・ティ・トゥイ・ズイ | Q42: 1 | R42: 1 | V42: =SUM(Q42:U42) -> 2
A43: 用役管理 | B43: VT1 | Q43: 0.5 | R43: 0.5 | V43: =SUM(Q43:U43) -> 1
A44: 千葉化学 | B44: 馬場 | Q44: 0.5 | R44: 0.5 | S44: 0.5 | T44: 0.5 | U44: 0.5 | V44: =SUM(Q44:U44) -> 2.5
...

Sheet スケジュール案・要員計画 (開発フェーズ_月別)
A2: システム | B2: 担当 | C2: 2024年 | O2: 2025年 | S2: 202６年
C3: 1月 | D3: 2月 | E3: 3月 | F3: 4月 | G3: 5月 | H3: 6月 | I3: 7月 | J3: 8月 | K3: 9月 | L3: 10月 | M3: 11月 | N3: 12月 | O3: 9月 | P3: 10月 | Q3: 11月 | R3: 12月 | S3: １月 | T3: ２月 | U3: ３月
A4: マイルストン | K4: ★縮小共通基盤構築 | P4: ★新共通基盤構築 | U4: ★館林DC廃止
A5: 数量確定システム（千葉・徳山）
A6: 用役管理システム（千葉・徳山）
A7: 千葉化学品質管理システム
A8: ＬＭＰＰ包装システム
A9: ヤード操業システム
A10: 工場DB
B12: 本番リリースタイミング
A13: 千葉化学品質管理システム | B13: 2026年2月上旬
A14: ＬＭＰＰ包装システム | B14: 2026年2月上旬
A15: 工場DB | B15: 2026年2月上旬
A16: ヤード操業システム（千葉・徳山） | B16: 2026年2月中旬
A17: 数量確定システム（千葉・徳山） | B17: 2026年2月下旬
A18: 用役管理システム（千葉・徳山） | B18: 2026年2月下旬
A20: 想定要員数(月単位)
A21: 管理 | Q21: 3 | R21: 3 | S21: 1.5 | T21: 1.5 | U21: 1.5 | V21: =SUM(O21:U21) -> 10.5
A22: 数量確定システム（千葉・徳山） | Q22: 5.6 | R22: 4 | S22: 1 | T22: 1 | U22: 1 | V22: =SUM(O22:U22) -> 12.6
A23: 用役管理システム（千葉・徳山） | Q23: 3.6 | R23: 2.5 | S23: 1 | T23: 1 | U23: 1 | V23: =SUM(O23:U23) -> 9.1
A24: 千葉化学品質管理システム | Q24: 4 | R24: 3.5 | S24: 1 | T24: 1 | V24: =SUM(O24:U24) -> 9.5
A25: ＬＭＰＰ包装システム | Q25: 2 | R25: 2 | S25: 0.5 | T25: 0.5 | V25: =SUM(O25:U25) -> 5
A26: 工場DB | Q26: 0 | R26: 0 | S26: 0 | T26: 0.4 | V26: =SUM(O26:U26) -> 0.4
A27: ヤ－ド操業システム（千葉・徳山） | Q27: 1.5 | R27: 0.5 | S27: 1 | T27: 1 | V27: =SUM(O27:U27) -> 4
A28: 合計 | C28: =SUM(C22:C27) -> 0 | D28: =SUM(D22:D27) -> 0 | E28: =SUM(E22:E27) -> 0 | F28: =SUM(F22:F27) -> 0 | G28: =SUM(G22:G27) -> 0 | H28: =SUM(H22:H27) -> 0 | I28: =SUM(I22:I27) -> 0 | J28: =SUM(J22:J27) -> 0 | ... N28: =SUM(N22:N27) -> 0 | O28: =SUM(O21:O27) -> 0 | P28: =SUM(P21:P27) -> 0 | Q28: =SUM(Q21:Q27) -> 19.7 | R28: =SUM(R21:R27) -> 15.5 | S28: =SUM(S21:S27) -> 6 | T28: =SUM(T21:T27) -> 6.4 | U28: =SUM(U21:U27) -> 3.5 | V28: =SUM(O28:U28) -> 51.1
A31: 想定要員数(工程単位) | O31: 調査・要件定義 | P31: 設計 | Q31: 製造 | R31: 結合テスト | S31: システムテスト | T31: ユーザテスト | U31: 本番稼働
A32: 管理 | Q32: 2.6 | R32: 3.4 | S32: 1.5 | T32: 1.1 | U32: 1.9
A33: 数量確定システム（千葉・徳山） | Q33: 3.2 | R33: 5.2 | S33: 1.4 | T33: 0.8 | U33: 2
A34: 用役管理システム（千葉・徳山） | Q34: 2.1 | R34: 3.1 | S34: 1.1 | T34: 0.8 | U34: 2
A35: 千葉化学品質管理システム | Q35: 2.2 | R35: 5.5 | S35: 0.8 | T35: 0.5 | U35: 0.5
A36: ＬＭＰＰ包装システム | Q36: 2.1 | R36: 1.2 | S36: 0.8 | T36: 0.5 | U36: 0.5
A37: 工場DB | Q37: 0 | R37: 0 | S37: 0 | T37: 0.1 | U37: 0.3
A38: ヤ－ド操業システム（千葉・徳山） | Q38: 0.9 | R38: 1.4 | S38: 0.2 | T38: 0.1 | U38: 1.3
A39: 合計 | C39: =SUM(C34:C38) -> 0 | D39: =SUM(D34:D38) -> 0 | E39: =SUM(E34:E38) -> 0 | F39: =SUM(F34:F38) -> 0 | G39: =SUM(G34:G38) -> 0 | H39: =SUM(H34:H38) -> 0 | I39: =SUM(I34:I38) -> 0 | J39: =SUM(J34:J38) -> 0 | ... N39: =SUM(N34:N38) -> 0 | O39: =SUM(O33:O38) -> 0 | P39: =SUM(P33:P38) -> 0 | Q39: =SUM(Q32:Q38) -> 13.1 | R39: =SUM(R32:R38) -> 19.8 | S39: =SUM(S32:S38) -> 5.8 | T39: =SUM(T32:T38) -> 3.9 | U39: =SUM(U32:U38) -> 8.5
A41: 要員 | X41: 要員人数 | Z41: 計画(月) | AB41: 計画(工程)
A42: 管理（工場） | B42: 野村 | Q42: 0.5 | R42: 0.5 | S42: 0.5 | T42: 0.5 | U42: 0.25 | V42: =SUM(O42:U42) -> 2.25 | W42: 管理（工場） | X42: =SUMIF($A$42:$A$77,W42,$V$42:$V$77) -> 11.75 | Y42: 人月 | Z42: =V21 -> 10.5 | AA42: 人月 | AB42: 10.5
A43: 管理（工場） | B43: 石井 | Q43: 0.5 | R43: 0.5 | S43: 0.5 | T43: 0.5 | U43: 0.5 | V43: =SUM(O43:U43) -> 2.5 | W43: 数量確定 | X43: =SUMIF($A$42:$A$77,W43,$V$42:$V$77) -> 12.5 | Y43: 人月 | Z43: =V22 -> 12.6 | AA43: 人月 | AB43: 12.6
A44: 管理（工場） | B44: グエン・タン・ドゥオック | Q44: 1 | R44: 1 | S44: 1 | T44: 1 | U44: 0.5 | V44: =SUM(O44:U44) -> 4.5 | W44: 用役管理 | X44: =SUMIF($A$42:$A$77,W44,$V$42:$V$77) -> 10.5 | Y44: 人月 | Z44: =V23 -> 9.1 | AA44: 人月 | AB44: 9.1
A45: 数量確定 | B45: 天川 | Q45: 0.5 | R45: 0.5 | S45: 0.5 | T45: 0.5 | U45: 0.5 | V45: =SUM(O45:U45) -> 2.5 | W45: 千葉化学 | X45: =SUMIF($A$42:$A$77,W45,$V$42:$V$77) -> 12.5 | Y45: 人月 | Z45: =V24 -> 9.5 | AA45: 人月 | AB45: 9.5
A46: 数量確定 | B46: グエン・チュン・グエン | Q46: 0.5 | R46: 0.5 | S46: 0.5 | T46: 0.5 | U46: 0.5 | V46: =SUM(O46:U46) -> 2.5 | W46: 包装 | X46: =SUMIF($A$42:$A$77,W46,$V$42:$V$77) -> 8.5 | Y46: 人月 | Z46: =V25 -> 5 | AA46: 人月 | AB46: 5
...

Sheet 再見積 (システム・工程別サマリ)  (2)
C1: 工数直入力のため注意！！
C2: 見積（工程別サマリ）
C3: パターン | D3: クラウドアーキ基盤に移行 | R3: 備考
D4: アプリ | N4: DB | P4: 全体
B5: No. | C5: システム | D5: 調査・要件定義 | E5: 設計 | F5: 製造 | G5: 結合テスト | H5: システムテスト | I5: ユーザテスト | J5: 本番稼働 | K5: 管理 | L5: 工数計 | M5: 金額 | N5: 工数計 | O5: 金額 | P5: 工数計 | Q5: 金額
B6: 1 | C6: 数量確定システム（千葉・徳山） | D6: 3.2 | E6: 1.6 | F6: 2.7 | G6: 5.2 | H6: 1.4 | I6: 0.8 | J6: 2 | K6: 3.8 | L6: =SUM(D6:K6) -> 20.7 | M6: =SUM(D6:J6)*1000000+K6*1400000 -> 22220000 | N6: 0 | O6: 0 | P6: =SUM(L6:L10)+N6 -> 58.4 | Q6: =SUM(M6:M10)+O6 -> 63040000
B7: 2 | C7: 用役管理システム（千葉・徳山） | D7: 1.4 | E7: 1.1 | F7: 1.5 | G7: 3.1 | H7: 1.1 | I7: 0.8 | J7: 2 | K7: 2.6 | L7: =SUM(D7:K7) -> 13.6 | M7: =SUM(D7:J7)*1000000+K7*1400000 -> 14640000
B8: 3 | C8: 千葉化学品質管理システム | D8: 1.7 | E8: 1.4 | F8: 1.6 | G8: 5.5 | H8: 0.8 | I8: 0.5 | J8: 0.6 | K8: 2.8 | L8: =SUM(D8:K8) -> 14.9 | M8: =SUM(D8:J8)*1000000+K8*1400000 -> 16020000
B9: 4 | C9: ＬＭＰＰ包装システム | D9: 1.3 | E9: 0.4 | F9: 1.6 | G9: 1.2 | H9: 0.8 | I9: 0.5 | J9: 0.6 | K9: 1.9 | L9: =SUM(D9:K9) -> 8.3 | M9: =SUM(D9:J9)*1000000+K9*1400000 -> 9060000
B10: 5 | C10: 工場DB | J10: 0.4 | K10: 0.5 | L10: =SUM(D10:K10) -> 0.9 | M10: =SUM(D10:J10)*1000000+K10*1400000 -> 1100000
B11: 6 | C11: ヤ－ド操業システム（千葉・徳山） | D11: 0.5 | E11: 0.4 | F11: 0.7 | G11: 1.4 | H11: 0.2 | I11: 0.1 | J11: 1.5 | K11: 0.9 | L11: =SUM(D11:K11) -> 5.7 | M11: =SUM(D11:J11)*1000000+K11*1400000 -> 6060000 | N11: 0 | O11: =SUM(O5:O10) -> 0 | P11: =SUM(L11:L11)+N11 -> 5.7 | Q11: =SUM(M11:M11)+O6 -> 6060000
B12: 計 | D12: =SUM(D6:D11) -> 8.1 | E12: =SUM(E6:E11) -> 4.9 | F12: =SUM(F6:F11) -> 8.1 | G12: =SUM(G6:G11) -> 16.4 | H12: =SUM(H6:H11) -> 4.3 | I12: =SUM(I6:I11) -> 2.7 | J12: =SUM(J6:J11) -> 7.1 | K12: =SUM(K6:K11) -> 12.5 | L12: =SUM(D12:K12) -> 64.1 | M12: =SUM(M6:M11) -> 69100000 | N12: =SUM(N6:N11) -> 0 | O12: =SUM(O6:O11) -> 0 | P12: =SUM(P6:P11) -> 64.1 | Q12: =SUM(Q6:Q11) -> 69100000
B13: 単価 | D13: 1000000 | E13: 1000000 | F13: 1000000 | G13: 1000000 | H13: 1000000 | I13: 1000000 | J13: 1000000 | K13: 1400000
B14: 金額 | D14: =D12*D13 -> 8100000 | E14: =E12*E13 -> 4900000 | F14: =F12*F13 -> 8100000 | G14: =G12*G13 -> 16400000 | H14: =H12*H13 -> 4300000 | I14: =I12*I13 -> 2700000 | J14: =J12*J13 -> 7100000 | K14: =K12*K13 -> 17500000
C16: 再見積もり（工程別サマリ）
C17: パターン | D17: クラウドアーキ基盤に移行 | R17: 備考
D18: アプリ | N18: DB | P18: 全体
B19: No. | C19: システム | D19: 調査・要件定義 | E19: 設計 | F19: 製造 | G19: 結合テスト | H19: システムテスト | I19: ユーザテスト | J19: 本番稼働 | K19: 管理 | L19: 工数計 | M19: 金額 | N19: 工数計 | O19: 金額 | P19: 工数計 | Q19: 金額
B20: 1 | C20: 数量確定システム（千葉・徳山） | D20: 3.2 | E20: 1.6 | F20: 3.2 | G20: 5.2 | H20: 1.4 | I20: 0.8 | J20: 2 | K20: 3.9 | L20: =SUM(D20:K20) -> 21.3 | M20: =SUM(D20:J20)*1000000+K20*1400000 -> 22860000 | N20: 0 | O20: 0 | P20: =SUM(L20:L24)+N20 -> 61 | Q20: =SUM(M20:M24)+O20 -> 65800000
B21: 2 | C21: 用役管理システム（千葉・徳山） | D21: 1.4 | E21: 1.1 | F21: 2.1 | G21: 3.1 | H21: 1.1 | I21: 0.8 | J21: 2 | K21: 2.7 | L21: =SUM(D21:K21) -> 14.3 | M21: =SUM(D21:J21)*1000000+K21*1400000 -> 15380000
B22: 3 | C22: 千葉化学品質管理システム | D22: 1.7 | E22: 1.4 | F22: 2.2 | G22: 5.5 | H22: 0.8 | I22: 0.5 | J22: 0.6 | K22: 2.9 | L22: =SUM(D22:K22) -> 15.6 | M22: =SUM(D22:J22)*1000000+K22*1400000 -> 16760000
B23: 4 | C23: ＬＭＰＰ包装システム | D23: 1.3 | E23: 0.4 | F23: 2.1 | G23: 1.2 | H23: 0.8 | I23: 0.5 | J23: 0.6 | K23: 2 | L23: =SUM(D23:K23) -> 8.9 | M23: =SUM(D23:J23)*1000000+K23*1400000 -> 9700000
B24: 5 | C24: 工場DB | J24: 0.4 | K24: 0.5 | L24: =SUM(D24:K24) -> 0.9 | M24: =SUM(D24:J24)*1000000+K24*1400000 -> 1100000
B25: 6 | C25: ヤ－ド操業システム（千葉・徳山） | D25: 0.5 | E25: 0.4 | F25: 0.9 | G25: 1.4 | H25: 0.2 | I25: 0.1 | J25: 1.5 | K25: 0.9 | L25: =SUM(D25:K25) -> 5.9 | M25: =SUM(D25:J25)*1000000+K25*1400000 -> 6260000 | N25: 0 | O25: =SUM(O19:O24) -> 0 | P25: =SUM(L25:L25)+N25 -> 5.9 | Q25: =SUM(M25:M25)+O20 -> 6260000
B26: 計 | D26: =SUM(D20:D25) -> 8.1 | E26: =SUM(E20:E25) -> 4.9 | F26: =SUM(F20:F25) -> 10.5 | G26: =SUM(G20:G25) -> 16.4 | H26: =SUM(H20:H25) -> 4.3 | I26: =SUM(I20:I25) -> 2.7 | J26: =SUM(J20:J25) -> 7.1 | K26: =SUM(K20:K25) -> 12.9 | L26: =SUM(D26:K26) -> 66.9 | M26: =SUM(M20:M25) -> 72060000 | N26: =SUM(N20:N25) -> 0 | O26: =SUM(O20:O25) -> 0 | P26: =SUM(P20:P25) -> 66.9 | Q26: =SUM(Q20:Q25) -> 72060000
B27: 単価 | D27: 1000000 | E27: 1000000 | F27: 1000000 | G27: 1000000 | H27: 1000000 | I27: 1000000 | J27: 1000000 | K27: 1400000
B28: 金額 | D28: =D26*D27 -> 8100000 | E28: =E26*E27 -> 4900000 | F28: =F26*F27 -> 10500000 | G28: =G26*G27 -> 16400000 | H28: =H26*H27 -> 4300000 | I28: =I26*I27 -> 2700000 | J28: =J26*J27 -> 7100000 | K28: =K26*K27 -> 18060000
Q29: =Q26-Q12 -> 2960000
C31: 再見積もり（開発フェーズ以降）
C32: パターン | D32: クラウドアーキ基盤に移行 | R32: 備考
D33: アプリ | N33: DB | P33: 全体
B34: No. | C34: システム | D34: 調査・要件定義 | E34: 設計 | F34: 製造 | G34: 結合テスト | H34: システムテスト | I34: ユーザテスト | J34: 本番稼働 | K34: 管理 | L34: 工数計 | M34: 金額 | N34: 工数計 | O34: 金額 | P34: 工数計 | Q34: 金額
B35: 1 | C35: 数量確定システム（千葉・徳山） | F35: 3.2 | G35: 5.2 | H35: 1.4 | I35: 1 | J35: 2 | K35: 3.1 | L35: =SUM(D35:K35) -> 15.9 | M35: =SUM(D35:J35)*1000000+K35*1400000 -> 17140000 | N35: 0 | O35: 0 | P35: =SUM(L35:L39)+N35 -> 47.1 | Q35: =SUM(M35:M39)+O35 -> 50860000
B36: 2 | C36: 用役管理システム（千葉・徳山） | F36: 2.1 | G36: 3.1 | H36: 1.1 | I36: 1 | J36: 2 | K36: 2.2 | L36: =SUM(D36:K36) -> 11.5 | M36: =SUM(D36:J36)*1000000+K36*1400000 -> 12380000
B37: 3 | C37: 千葉化学品質管理システム | F37: 2.2 | G37: 5.5 | H37: 0.8 | I37: 0.7 | J37: 0.6 | K37: 2.3 | L37: =SUM(D37:K37) -> 12.1 | M37: =SUM(D37:J37)*1000000+K37*1400000 -> 13020000
B38: 4 | C38: ＬＭＰＰ包装システム | F38: 2.1 | G38: 1.2 | H38: 0.8 | I38: 0.7 | J38: 0.6 | K38: 1.7 | L38: =SUM(D38:K38) -> 7.1 | M38: =SUM(D38:J38)*1000000+K38*1400000 -> 7780000
B39: 5 | C39: 工場DB | J39: 0.4 | K39: 0.1 | L39: =SUM(D39:K39) -> 0.5 | M39: =SUM(D39:J39)*1000000+K39*1400000 -> 540000
B40: 6 | C40: ヤ－ド操業システム（千葉・徳山） | F40: 0.9 | G40: 1.4 | H40: 0.2 | I40: 0.3 | J40: 1.5 | K40: 0.7 | L40: =SUM(D40:K40) -> 5 | M40: =SUM(D40:J40)*1000000+K40*1400000 -> 5280000 | N40: 0 | O40: =SUM(O34:O39) -> 0 | P40: =SUM(L40:L40)+N40 -> 5 | Q40: =SUM(M40:M40)+O35 -> 5280000
B41: 計 | D41: =SUM(D35:D40) -> 0 | E41: =SUM(E35:E40) -> 0 | F41: =SUM(F35:F40) -> 10.5 | G41: =SUM(G35:G40) -> 16.4 | H41: =SUM(H35:H40) -> 4.3 | I41: =SUM(I35:I40) -> 3.7 | J41: =SUM(J35:J40) -> 7.1 | K41: =SUM(K35:K40) -> 10.1 | L41: =SUM(D41:K41) -> 52.1 | M41: =SUM(M35:M40) -> 56140000 | N41: =SUM(N35:N40) -> 0 | O41: =SUM(O35:O40) -> 0 | P41: =SUM(P35:P40) -> 52.1 | Q41: =SUM(Q35:Q40) -> 56140000
B42: 単価 | D42: 1000000 | E42: 1000000 | F42: 1000000 | G42: 1000000 | H42: 1000000 | I42: 1000000 | J42: 1000000 | K42: 1400000
...

Sheet スケジュール案・要員計画 (開発フェーズ_月別) (2)
A2: システム | B2: 担当 | C2: 2024年 | O2: 2025年 | S2: 202６年
C3: 1月 | D3: 2月 | E3: 3月 | F3: 4月 | G3: 5月 | H3: 6月 | I3: 7月 | J3: 8月 | K3: 9月 | L3: 10月 | M3: 11月 | N3: 12月 | O3: 9月 | P3: 10月 | Q3: 11月 | R3: 12月 | S3: １月 | T3: ２月 | U3: ３月
A4: マイルストン | K4: ★縮小共通基盤構築 | P4: ★新共通基盤構築 | U4: ★館林DC廃止
A5: 数量確定システム（千葉・徳山）
A6: 用役管理システム（千葉・徳山）
A7: 千葉化学品質管理システム
A8: ＬＭＰＰ包装システム
A9: ヤード操業システム
A10: 工場DB
B12: 本番リリースタイミング
A13: 千葉化学品質管理システム | B13: 2026年2月上旬
A14: ＬＭＰＰ包装システム | B14: 2026年2月上旬
A15: 工場DB | B15: 2026年2月上旬
A16: ヤード操業システム（千葉・徳山） | B16: 2026年2月中旬
A17: 数量確定システム（千葉・徳山） | B17: 2026年2月下旬
A18: 用役管理システム（千葉・徳山） | B18: 2026年2月下旬
A20: 想定要員数(月単位)
A21: 管理 | Q21: 3 | R21: 3 | S21: 1.5 | T21: 1.5 | U21: 1.5 | V21: =SUM(O21:U21) -> 10.5
A22: 数量確定システム（千葉・徳山） | Q22: 5.6 | R22: 4 | S22: 1 | T22: 1 | U22: 1 | V22: =SUM(O22:U22) -> 12.6
A23: 用役管理システム（千葉・徳山） | Q23: 3.6 | R23: 2.5 | S23: 1 | T23: 1 | U23: 1 | V23: =SUM(O23:U23) -> 9.1
A24: 千葉化学品質管理システム | Q24: 4 | R24: 3.5 | S24: 1 | T24: 1 | V24: =SUM(O24:U24) -> 9.5
A25: ＬＭＰＰ包装システム | Q25: 2 | R25: 2 | S25: 0.5 | T25: 0.5 | V25: =SUM(O25:U25) -> 5
A26: 工場DB | Q26: 0 | R26: 0 | S26: 0 | T26: 0.4 | V26: =SUM(O26:U26) -> 0.4
A27: ヤ－ド操業システム（千葉・徳山） | Q27: 1.5 | R27: 0.5 | S27: 1 | T27: 1 | V27: =SUM(O27:U27) -> 4
A28: 合計 | C28: =SUM(C22:C27) -> 0 | D28: =SUM(D22:D27) -> 0 | E28: =SUM(E22:E27) -> 0 | F28: =SUM(F22:F27) -> 0 | G28: =SUM(G22:G27) -> 0 | H28: =SUM(H22:H27) -> 0 | I28: =SUM(I22:I27) -> 0 | J28: =SUM(J22:J27) -> 0 | ... N28: =SUM(N22:N27) -> 0 | O28: =SUM(O21:O27) -> 0 | P28: =SUM(P21:P27) -> 0 | Q28: =SUM(Q21:Q27) -> 19.7 | R28: =SUM(R21:R27) -> 15.5 | S28: =SUM(S21:S27) -> 6 | T28: =SUM(T21:T27) -> 6.4 | U28: =SUM(U21:U27) -> 3.5 | V28: =SUM(O28:U28) -> 51.1
R29: 7.75
A31: 想定要員数(工程単位) | O31: 調査・要件定義 | P31: 設計 | Q31: 製造 | R31: 結合テスト | S31: システムテスト | T31: ユーザテスト | U31: 本番稼働
A32: 管理 | Q32: 2.6 | R32: 3.4 | S32: 1.5 | T32: 1.1 | U32: 1.9
A33: 数量確定システム（千葉・徳山） | Q33: 3.2 | R33: 5.2 | S33: 1.4 | T33: 0.8 | U33: 2
A34: 用役管理システム（千葉・徳山） | Q34: 2.1 | R34: 3.1 | S34: 1.1 | T34: 0.8 | U34: 2
A35: 千葉化学品質管理システム | Q35: 2.2 | R35: 5.5 | S35: 0.8 | T35: 0.5 | U35: 0.5
A36: ＬＭＰＰ包装システム | Q36: 2.1 | R36: 1.2 | S36: 0.8 | T36: 0.5 | U36: 0.5
A37: 工場DB | Q37: 0 | R37: 0 | S37: 0 | T37: 0.1 | U37: 0.3
A38: ヤ－ド操業システム（千葉・徳山） | Q38: 0.9 | R38: 1.4 | S38: 0.2 | T38: 0.1 | U38: 1.3
A39: 合計 | C39: =SUM(C34:C38) -> 0 | D39: =SUM(D34:D38) -> 0 | E39: =SUM(E34:E38) -> 0 | F39: =SUM(F34:F38) -> 0 | G39: =SUM(G34:G38) -> 0 | H39: =SUM(H34:H38) -> 0 | I39: =SUM(I34:I38) -> 0 | J39: =SUM(J34:J38) -> 0 | ... N39: =SUM(N34:N38) -> 0 | O39: =SUM(O33:O38) -> 0 | P39: =SUM(P33:P38) -> 0 | Q39: =SUM(Q32:Q38) -> 13.1 | R39: =SUM(R32:R38) -> 19.8 | S39: =SUM(S32:S38) -> 5.8 | T39: =SUM(T32:T38) -> 3.9 | U39: =SUM(U32:U38) -> 8.5
A41: 要員 | X41: 要員人数 | Z41: 計画(月) | AB41: 計画(工程)
A42: 管理（工場） | B42: 野村 | Q42: 0.5 | R42: 0.5 | S42: 0.5 | T42: 0.5 | U42: 0.25 | V42: =SUM(O42:U42) -> 2.25 | W42: 管理（工場） | X42: =SUMIF($A$42:$A$77,W42,$V$42:$V$77) -> 11.5 | Y42: 人月 | Z42: =V21 -> 10.5 | AA42: 人月 | AB42: 10.5
A43: 管理（工場） | B43: 石井 | Q43: 0.5 | R43: 0.5 | S43: 0.5 | T43: 0.5 | U43: 0.25 | V43: =SUM(O43:U43) -> 2.25 | W43: 数量確定 | X43: =SUMIF($A$42:$A$77,W43,$V$42:$V$77) -> 11.75 | Y43: 人月 | Z43: =V22 -> 12.6 | AA43: 人月 | AB43: 12.6
A44: 管理（工場） | B44: グエン・タン・ドゥオック | Q44: 1 | R44: 1 | S44: 1 | T44: 1 | U44: 0.5 | V44: =SUM(O44:U44) -> 4.5 | W44: 用役管理 | X44: =SUMIF($A$42:$A$77,W44,$V$42:$V$77) -> 9.25 | Y44: 人月 | Z44: =V23 -> 9.1 | AA44: 人月 | AB44: 9.1
A45: 数量確定 | B45: 天川 | Q45: 0.5 | R45: 0.5 | S45: 0.5 | T45: 0.5 | V45: =SUM(O45:U45) -> 2 | W45: 千葉化学 | X45: =SUMIF($A$42:$A$77,W45,$V$42:$V$77) -> 12 | Y45: 人月 | Z45: =V24 -> 9.5 | AA45: 人月 | AB45: 9.5
...

Sheet スケジュール案・要員計画 (開発フェーズ_工程別) (2)
O1: 調査・要件定義 | P1: 設計 | Q1: 製造 | R1: 結合テスト | S1: システムテスト | T1: ユーザテスト | U1: 本番稼働
A3: システム | B3: 担当 | C3: 2024年 | O3: 2025年 | S3: 202６年
C4: 1月 | D4: 2月 | E4: 3月 | F4: 4月 | G4: 5月 | H4: 6月 | I4: 7月 | J4: 8月 | K4: 9月 | L4: 10月 | M4: 11月 | N4: 12月 | O4: 9月 | P4: 10月 | Q4: 11月 | R4: 12月 | S4: １月 | T4: ２月 | U4: ３月 | V4: ４月 | W4: ５月 | X4: ６月
A5: マイルストン | K5: ★縮小共通基盤構築 | P5: ★新共通基盤構築 | U5: ★館林DC廃止
A6: 数量確定システム（千葉・徳山）
A7: 用役管理システム（千葉・徳山）
A8: 千葉化学品質管理システム
A9: ＬＭＰＰ包装システム
A10: ヤード操業システム
A11: 工場DB
B13: 本番リリースタイミング
A14: 千葉化学品質管理システム | B14: 2026年2月上旬
A15: ＬＭＰＰ包装システム | B15: 2026年2月上旬
A16: 工場DB | B16: 2026年2月上旬
A17: ヤード操業システム（千葉・徳山） | B17: 2026年2月中旬
A18: 数量確定システム（千葉・徳山） | B18: 2026年2月下旬
A19: 用役管理システム（千葉・徳山） | B19: 2026年2月下旬
A21: 想定要員数(工程単位) | Z21: 管理のみ
A22: 管理 | Q22: =AB29 -> 2.6 | R22: =AC29 -> 3.4 | S22: =AD29 -> 1.5 | T22: =AE29 -> 1.1 | U22: =AF29 -> 1.9 | V22: =SUM(Q22:U22) -> 10.5 | Z22: 調査・要件定義 | AA22: 設計 | AB22: 製造 | AC22: 結合テスト | AD22: システムテスト | AE22: ユーザテスト | AF22: 本番稼働
A23: 数量確定システム（千葉・徳山） | Q23: 3.2 | R23: 5.2 | S23: 1.4 | T23: 0.8 | U23: 2 | V23: =SUM(Q23:U23) -> 12.6 | Y23: 数量確定システム（千葉・徳山） | Z23: 0 | AA23: 0 | AB23: 0.8 | AC23: 1 | AD23: 0.5 | AE23: 0.3 | AF23: 0.5
A24: 用役管理システム（千葉・徳山） | Q24: 2.1 | R24: 3.1 | S24: 1.1 | T24: 0.8 | U24: 2 | V24: =SUM(Q24:U24) -> 9.1 | Y24: 用役管理システム（千葉・徳山） | Z24: 0 | AA24: 0 | AB24: 0.5 | AC24: 0.7 | AD24: 0.3 | AE24: 0.3 | AF24: 0.4
A25: 千葉化学品質管理システム | Q25: 2.2 | R25: 5.5 | S25: 0.8 | T25: 0.5 | U25: 0.5 | V25: =SUM(Q25:U25) -> 9.5 | Y25: 千葉化学品質管理システム | Z25: 0 | AA25: 0 | AB25: 0.6 | AC25: 1 | AD25: 0.3 | AE25: 0.2 | AF25: 0.2
A26: ＬＭＰＰ包装システム | Q26: 2 | R26: 1.2 | S26: 0.8 | T26: 0.5 | U26: 0.5 | V26: =SUM(Q26:U26) -> 5 | Y26: ＬＭＰＰ包装システム | Z26: 0 | AA26: 0 | AB26: 0.6 | AC26: 0.4 | AD26: 0.3 | AE26: 0.2 | AF26: 0.2
A27: 工場DB | Q27: 0 | R27: 0 | S27: 0 | T27: 0.1 | U27: 0.3 | V27: =SUM(Q27:U27) -> 0.4 | Y27: 工場DB | Z27: 0 | AA27: 0 | AB27: 0 | AC27: 0 | AD27: 0 | AE27: 0 | AF27: 0.4
A28: ヤ－ド操業システム（千葉・徳山） | Q28: 1 | R28: 1.4 | S28: 0.2 | T28: 0.1 | U28: 1.3 | V28: =SUM(Q28:U28) -> 4 | Y28: ヤ－ド操業システム（千葉・徳山） | Z28: 0 | AA28: 0 | AB28: 0.1 | AC28: 0.3 | AD28: 0.1 | AE28: 0.1 | AF28: 0.2
A29: 合計 | C29: =SUM(C24:C28) -> 0 | D29: =SUM(D24:D28) -> 0 | E29: =SUM(E24:E28) -> 0 | F29: =SUM(F24:F28) -> 0 | G29: =SUM(G24:G28) -> 0 | H29: =SUM(H24:H28) -> 0 | I29: =SUM(I24:I28) -> 0 | J29: =SUM(J24:J28) -> 0 | ... N29: =SUM(N24:N28) -> 0 | O29: =SUM(O23:O28) -> 0 | P29: =SUM(P23:P28) -> 0 | Q29: =SUM(Q22:Q28) -> 13.1 | R29: =SUM(R22:R28) -> 19.8 | S29: =SUM(S22:S28) -> 5.8 | T29: =SUM(T22:T28) -> 3.9 | U29: =SUM(U22:U28) -> 8.5 | V29: =SUM(Q29:U29) -> 51.1 | Z29: =SUM(Z23:Z28) -> 0 | AA29: =SUM(AA23:AA28) -> 0 | AB29: =SUM(AB23:AB28) -> 2.6 | AC29: =SUM(AC23:AC28) -> 3.4 | AD29: =SUM(AD23:AD28) -> 1.5 | AE29: =SUM(AE23:AE28) -> 1.1 | AF29: =SUM(AF23:AF28) -> 1.9
A31: 要員
A32: 管理（工場） | B32: 野村 | Q32: 0.5 | R32: 0.5 | S32: 0.5 | T32: 0.5 | U32: 0.25 | V32: =SUM(Q32:U32) -> 2.25
A33: 管理（工場） | B33: 石井 | Q33: 0.5 | R33: 0.5 | S33: 0.5 | T33: 0.5 | U33: 0.5 | V33: =SUM(Q33:U33) -> 2.5
A34: 管理（工場） | B34: グエン・タン・ドゥオック | Q34: 1 | R34: 1 | S34: 1 | T34: 1 | U34: 0.5 | V34: =SUM(Q34:U34) -> 4.5
A35: 数量確定 | B35: 天川 | Q35: 0.5 | R35: 0.5 | S35: 0.5 | T35: 0.5 | U35: 0.5 | V35: =SUM(Q35:U35) -> 2.5
A36: 数量確定 | B36: グエン・チュン・グエン | Q36: 0.5 | R36: 0.5 | S36: 0.5 | T36: 0.5 | U36: 0.5 | V36: =SUM(Q36:U36) -> 2.5
A37: 数量確定 | B37: ドー・ﾘｲ・アイン・トゥ | Q37: 1 | R37: 1 | V37: =SUM(Q37:U37) -> 2
A38: 数量確定 | B38: レ・ファム・バオ・ロック | Q38: 1 | R38: 1 | V38: =SUM(Q38:U38) -> 2
A39: 数量確定 | B39: VT1 | Q39: 0.5 | R39: 0.5 | V39: =SUM(Q39:U39) -> 1
A40: 用役管理 | B40: 天川 | Q40: 0.5 | R40: 0.5 | S40: 0.5 | T40: 0.5 | U40: 0.5 | V40: =SUM(Q40:U40) -> 2.5
A41: 用役管理 | B41: グエン・チュン・グエン | Q41: 0.5 | R41: 0.5 | S41: 0.5 | T41: 0.5 | U41: 0.5 | V41: =SUM(Q41:U41) -> 2.5
A42: 用役管理 | B42: ドー・グエン・ティ・トゥイ・ズイ | Q42: 1 | R42: 1 | V42: =SUM(Q42:U42) -> 2
A43: 用役管理 | B43: VT1 | Q43: 0.5 | R43: 0.5 | V43: =SUM(Q43:U43) -> 1
A44: 千葉化学 | B44: 馬場 | Q44: 0.5 | R44: 0.5 | S44: 0.5 | T44: 0.5 | U44: 0.5 | V44: =SUM(Q44:U44) -> 2.5
...

Sheet 再見積 (システム・工程別サマリ) _ベース
C1: 工数直入力のため注意！！
C2: 見積（工程別サマリ）
C3: パターン | D3: クラウドアーキ基盤に移行 | R3: 備考
D4: アプリ | N4: DB | P4: 全体
B5: No. | C5: システム | D5: 調査・要件定義 | E5: 設計 | F5: 製造 | G5: 結合テスト | H5: システムテスト | I5: ユーザテスト | J5: 本番稼働 | K5: 管理 | L5: 工数計 | M5: 金額 | N5: 工数計 | O5: 金額 | P5: 工数計 | Q5: 金額
B6: 1 | C6: 数量確定システム（千葉・徳山） | D6: 3.2 | E6: 1.6 | F6: 2.7 | G6: 5.2 | H6: 1.4 | I6: 0.8 | J6: 2 | K6: 3.8 | L6: =SUM(D6:K6) -> 20.7 | M6: =SUM(D6:J6)*1000000+K6*1400000 -> 22220000 | N6: 0 | O6: 0 | P6: =SUM(L6:L10)+N6 -> 58.4 | Q6: =SUM(M6:M10)+O6 -> 63040000
B7: 2 | C7: 用役管理システム（千葉・徳山） | D7: 1.4 | E7: 1.1 | F7: 1.5 | G7: 3.1 | H7: 1.1 | I7: 0.8 | J7: 2 | K7: 2.6 | L7: =SUM(D7:K7) -> 13.6 | M7: =SUM(D7:J7)*1000000+K7*1400000 -> 14640000
B8: 3 | C8: 千葉化学品質管理システム | D8: 1.7 | E8: 1.4 | F8: 1.6 | G8: 5.5 | H8: 0.8 | I8: 0.5 | J8: 0.6 | K8: 2.8 | L8: =SUM(D8:K8) -> 14.9 | M8: =SUM(D8:J8)*1000000+K8*1400000 -> 16020000
B9: 4 | C9: ＬＭＰＰ包装システム | D9: 1.3 | E9: 0.4 | F9: 1.6 | G9: 1.2 | H9: 0.8 | I9: 0.5 | J9: 0.6 | K9: 1.9 | L9: =SUM(D9:K9) -> 8.3 | M9: =SUM(D9:J9)*1000000+K9*1400000 -> 9060000
B10: 5 | C10: 工場DB | J10: 0.4 | K10: 0.5 | L10: =SUM(D10:K10) -> 0.9 | M10: =SUM(D10:J10)*1000000+K10*1400000 -> 1100000
B11: 6 | C11: ヤ－ド操業システム（千葉・徳山） | D11: 0.5 | E11: 0.4 | F11: 0.7 | G11: 1.4 | H11: 0.2 | I11: 0.1 | J11: 1.5 | K11: 0.9 | L11: =SUM(D11:K11) -> 5.7 | M11: =SUM(D11:J11)*1000000+K11*1400000 -> 6060000 | N11: 0 | O11: =SUM(O5:O10) -> 0 | P11: =SUM(L11:L11)+N11 -> 5.7 | Q11: =SUM(M11:M11)+O6 -> 6060000
B12: 計 | D12: =SUM(D6:D11) -> 8.1 | E12: =SUM(E6:E11) -> 4.9 | F12: =SUM(F6:F11) -> 8.1 | G12: =SUM(G6:G11) -> 16.4 | H12: =SUM(H6:H11) -> 4.3 | I12: =SUM(I6:I11) -> 2.7 | J12: =SUM(J6:J11) -> 7.1 | K12: =SUM(K6:K11) -> 12.5 | L12: =SUM(D12:K12) -> 64.1 | M12: =SUM(M6:M11) -> 69100000 | N12: =SUM(N6:N11) -> 0 | O12: =SUM(O6:O11) -> 0 | P12: =SUM(P6:P11) -> 64.1 | Q12: =SUM(Q6:Q11) -> 69100000
B13: 単価 | D13: 1000000 | E13: 1000000 | F13: 1000000 | G13: 1000000 | H13: 1000000 | I13: 1000000 | J13: 1000000 | K13: 1400000
B14: 金額 | D14: =D12*D13 -> 8100000 | E14: =E12*E13 -> 4900000 | F14: =F12*F13 -> 8100000 | G14: =G12*G13 -> 16400000 | H14: =H12*H13 -> 4300000 | I14: =I12*I13 -> 2700000 | J14: =J12*J13 -> 7100000 | K14: =K12*K13 -> 17500000
C16: 再見積もり（工程別サマリ）
C17: パターン | D17: クラウドアーキ基盤に移行 | R17: 備考
D18: アプリ | N18: DB | P18: 全体
B19: No. | C19: システム | D19: 調査・要件定義 | E19: 設計 | F19: 製造 | G19: 結合テスト | H19: システムテスト | I19: ユーザテスト | J19: 本番稼働 | K19: 管理 | L19: 工数計 | M19: 金額 | N19: 工数計 | O19: 金額 | P19: 工数計 | Q19: 金額
B20: 1 | C20: 数量確定システム（千葉・徳山） | D20: 3.2 | E20: 1.6 | F20: 3.2 | G20: 5.2 | H20: 1.4 | I20: 1.9 | J20: 2 | K20: 3.9 | L20: =SUM(D20:K20) -> 22.4 | M20: =SUM(D20:J20)*1000000+K20*1400000 -> 23960000 | N20: 0 | O20: 0 | P20: =SUM(L20:L24)+N20 -> 64.2 | Q20: =SUM(M20:M24)+O20 -> 68840000
B21: 2 | C21: 用役管理システム（千葉・徳山） | D21: 1.4 | E21: 1.1 | F21: 2.1 | G21: 3.1 | H21: 1.1 | I21: 1.9 | J21: 2 | K21: 2.7 | L21: =SUM(D21:K21) -> 15.4 | M21: =SUM(D21:J21)*1000000+K21*1400000 -> 16480000
B22: 3 | C22: 千葉化学品質管理システム | D22: 1.7 | E22: 1.4 | F22: 2.2 | G22: 5.5 | H22: 0.8 | I22: 1.2 | J22: 0.6 | K22: 2.9 | L22: =SUM(D22:K22) -> 16.3 | M22: =SUM(D22:J22)*1000000+K22*1400000 -> 17460000
B23: 4 | C23: ＬＭＰＰ包装システム | D23: 1.3 | E23: 0.4 | F23: 2.1 | G23: 1.2 | H23: 0.8 | I23: 1.2 | J23: 0.6 | K23: 2 | L23: =SUM(D23:K23) -> 9.6 | M23: =SUM(D23:J23)*1000000+K23*1400000 -> 10400000
B24: 5 | C24: 工場DB | J24: 0.4 | K24: 0.1 | L24: =SUM(D24:K24) -> 0.5 | M24: =SUM(D24:J24)*1000000+K24*1400000 -> 540000
