Workbook

Sheet 依頼概要
B3: 1. 経緯
B4: 館林DCセンターの廃止に伴い、現在のサーバ郡を移転する必要がある。
B5: 期日までに以下のいずれかの対応をとる必要がある。
B6: （２）Azureに構築される縮小版の共通基盤に移行
B7: ※現状よりスペックは低下、Oracleは19C
B8: 加えて、館林DC以外（現地）のサーバに関してWindows2016サーバはサポート期限切れに伴い、再構築を行う必要がある。
B11: 2. 依頼事項
B12: 各システム毎に概算見積を行ってほしい。
B13: （２）Azureに構築される縮小版の共通基盤に移行
C14: 対象：現行共通基盤を利用しているシステム
C15: 時期：2025年度1Q以降見込
C16: 出光側で構築した縮小版共通基盤へアプリ、帳票、バッチを移行
C17: 縮小版共通基盤の構成は現行共通基盤を踏襲した形となるが、OS,MWのバージョンは変更となる見込み
B20: 3. 希望期日
B21: 2024/12中に概算見積提示
B24: 顧客受領資料より

Sheet 想定作業
A1: 前提
B2: 業務・機能変更は行わない。
B3: サーバ構成は現行踏襲とする。
B4: DBは現行踏襲（Oracle、SQLSever継続）
B5: JavaフレームワークはStruts継続
B6: テストは新規構築した本番環境（次期本番機）にて行う。
B7: 開始時期を2025/4月以降
B8: ※検証、予備環境は最低限の動作確認（アプリ起動、ログイン確認程度）を想定
A11: 想定作業
A12: 全パターン共通
B13: IP,ホスト名変更に伴う各種（IF、DB等）向け先変更、検証
B14: アプリ動作検証（全画面、帳票、バッチ、IF打鍵 ※初期画面の描画や正常系の動作に問題がないことを確認）
B15: アプリケーション構築、ミドルウェアのセットアップ ※デプロイ作業のみ想定
B16: ※関連基盤の切り替えは完了しており、アプリケーションのAzure移行の切り替え作業は1回の未実施を想定（基盤切り替えが複数回発生する場合は別途工数が必要となります）
A18: （２）Azureに構築される縮小版の共通基盤に移行
B19: 全パターン共通の作業のみ

Sheet 概要図(千葉)
C1: ファイル連携 | F1: 工場系保守対象 | I1: 館林管理
C2: DBデータ連携 | F2: 工場系保守対象外 | I2: 現地管理
K63: Azure環境
K121: Azure環境

Sheet 概要図(徳山)
C1: ファイル連携 | F1: 工場系保守対象 | I1: 館林管理
C2: DBデータ連携 | F2: 工場系保守対象外 | I2: 現地管理
C60: Azure環境
C114: Azure環境

Sheet システム概要
E1: システム概要 | M1: システム規模 | S1: 共通基盤利用状況（現状）
A2: サービス: サービス番号 | B2: サービス名 | C2: 保守領域 | D2: 移行状況 | E2: 業務概要 | F2: OS | G2: アプリ | H2: DB | I2: ミドルウェア | J2: フレームワーク | K2: その他 | L2: サーバ構成 | M2: 画面 | N2: 帳票 | O2: バッチ | P2: IF | Q2: テーブル | R2: その他 | S2: 共通AP | T2: 共通DB | U2: 連携 | V2: レポート | W2: 認証 | X2: バッチ
A3: SVC-00000710 | B3: 数量確定システム(千葉) | C3: 工場系 | D3: 縮小共通基盤移行中 ⇒クラウドアーキ環境へ移行へ方針変更 | E3: 千葉事業所及び徳山事業所の石油化学装置の生産、在庫、PL(パイプライン)出荷、品目転換数量の管理を行うシステム。またタンクヤードの日報作成(ヤード日報)機能も持つ。 | F3: Red Hat Enterprise Linux7.3 | G3: java 1.8.0_202 Tomcat 9.0 | H3: Oracle19C | I3: A-AUTO | J3: struts 1.2.9 | L3: 本番 共通基盤（館林） 検証 共通基盤（館林） | M3: 千葉：41 徳山：30 | N3: 千葉：23 徳山：7 | O3: 共通：2 千葉：9 徳山：4 | P3: 千葉：8 徳山：4 | Q3: 共通：58 千葉：16 徳山：9 | S3: 〇 | T3: 〇 | U3: 〇 | V3: × | W3: 〇 | X3: 〇 | Y3: e
A4: SVC-00000857 | B4: 数量確定システム(徳山) | Y4: e
A5: - | B5: 用役管理システム(千葉工場) | C5: 工場系 | D5: 縮小共通基盤移行中 ⇒クラウドアーキ環境へ移行へ方針変更 | E5: 石油化学装置の生産数量、用役数量の管理を行うシステム。 | F5: Red Hat Enterprise Linux7.3 | G5: java 1.8.0_202 Tomcat 9.0 | H5: Oracle19C | I5: A-AUTO | J5: struts 1.2.9 | L5: 本番 共通基盤（館林） 検証 共通基盤（館林） | M5: 千葉：28 徳山：17 | N5: 千葉：43 徳山：6 | O5: 共通：0 千葉：0 徳山：0 | P5: 千葉：0 徳山：0 | Q5: 共通：11 千葉：1 徳山：11 | S5: 〇 | T5: 〇 | U5: 〇 | V5: × | W5: 〇 | X5: 〇 | Y5: e
A6: SVC-00000858 | B6: 用役管理システム(徳山工場) | Y6: e
A7: SVC-00001700 | B7: 千葉化学品質管理システム | C7: 工場系 | D7: 縮小共通基盤移行中 ⇒クラウドアーキ環境へ移行へ方針変更 | E7: 千葉事業所(工場)の品質管理課にて行う各種試験(工程、製品、物性)、及びそれに付随する業務(ロット管理、試験料金計算)を行うシステム。 | F7: Red Hat Enterprise Linux7.3 | G7: java 1.8.0_202 Tomcat 9.0 | H7: Oracle19C | I7: A-AUTO | J7: struts 1.2.9 | K7: List Creatorでの帳票作成 | L7: 本番 共通基盤（館林） 検証 共通基盤（館林） | M7: 83 | N7: 25 | O7: 5 | P7: 4 | Q7: 67 | S7: 〇 | T7: 〇 | U7: 〇 | V7: 〇 | W7: 〇 | X7: 〇 | Y7: e
A8: SVC-00000854 | B8: ＬＭＰＰ包装システム | C8: 工場系 | D8: 縮小共通基盤移行中 ⇒クラウドアーキ環境へ移行へ方針変更 | E8: 千葉事業所(工場)のSPS、LMPP装置で生産される製品の包装管理を行うシステム。 | F8: Red Hat Enterprise Linux7.3 | G8: java 1.8.0_202 Tomcat 9.0 | H8: Oracle19C | I8: A-AUTO | J8: struts 1.2.9 | K8: List Creatorでの帳票作成 | L8: 本番 共通基盤（館林） 検証 共通基盤（館林） | M8: 17 | N8: 3 | O8: 1 | P8: 3 | Q8: 12 | S8: 〇 | T8: 〇 | U8: 〇 | V8: 〇 | W8: 〇 | X8: 〇 | Y8: e
A9: SVC-00000877 | B9: 工場DB | C9: 工場系 | D9: 縮小共通基盤移行中 ⇒クラウドアーキ環境へ移行へ方針変更 ※アプリはXenApp | E9: 徳山事業所の石油化学装置の生産、在庫の計画値及び実績値を管理するDB及びエクセルマクロ群。 | F9: - | G9: Excel | H9: Oracle19C | I9: - | J9: - | L9: 本番 共通基盤（館林） 検証 共通基盤（館林） | M9: 0 | N9: 0 | O9: 0 | P9: 0 | Q9: 211 | S9: × | T9: 〇 | U9: × | V9: × | W9: × | X9: × | Y9: e
A10: SVC-00000705 | B10: 千葉ヤ－ド操業システム | C10: 工場系 | D10: OS更新対応にて現地サーバ構築済み | E10: 千葉事業所及び徳山事業所の石油化学品の入出荷を管理するシステム。 | F10: WindowsServer2022 | G10: java 1.8.0_152 WebLogic 12.2.1.2.0 | H10: SQLServer2022 | I10: A-AUTO | J10: struts 1.2.9 | L10: 本番 AP/DBサーバ×2（現地） AP/DB予備×2（館林） 検証 AP/DBサーバ×2（館林） | M10: 80 | N10: 20 | O10: 千葉：20 徳山：19 | P10: 千葉：16 徳山：15 | Q10: 75 | S10: × | T10: 〇 | U10: 〇 | V10: × | W10: 〇 | X10: × | Y10: e
A11: SVC-00000707 | B11: 徳山ヤ－ド操業システム | S11: × | T11: 〇 | U11: 〇 | V11: × | W11: 〇 | X11: × | Y11: e
A12: SVC-00000704 | B12: 千葉製品倉庫システム | C12: 工場系 | D12: 未実施（現地サーバ） | E12: 千葉事業所(工場)で生産されているポリマー製品の包装、入出荷、在庫管理を行うシステム。 | F12: WindowsServer2016 | G12: VB.NET | H12: Oracle12C | I12: Systemwalker Operation Manager OWFT | L12: 本番 AP/DBサーバ（現地） 検証 APサーバ（館林） | M12: 68 | N12: 43 | O12: 9 | P12: 45 | Q12: 205 | S12: × | T12: × | U12: 〇 | V12: × | W12: × | X12: × | Y12: e
A13: SVC-00000901 | B13: 千葉工場数量確定システム（ポリマ－） | C13: 工場系 | D13: 未実施（現地サーバ） | E13: 千葉事業所(工場)で生産されているポリマー製品の生産、在庫、PL(パイプライン)出荷、品目転換数量の管理を行うシステム。 | F13: WindowsServer2016 | G13: ASP.NET | H13: Oracle12C | I13: Systemwalker Operation Manager OWFT | M13: 20 | N13: 4 | O13: 2 | P13: 2 | Q13: 30 | S13: × | T13: × | U13: × | V13: × | W13: × | X13: × | Y13: e
A14: SVC-00000711 | B14: ＡＢＣ数量確定システム | C14: 工場系 | D14: 未実施（現地サーバ） | E14: 千葉事業所(工場)のABC装置で生産される製品の生産管理を行うシステム。 | F14: WindowsServer2016 | G14: C# | H14: Oracle12C | I14: Systemwalker Operation Manager OWFT | M14: 15 | N14: 0 | O14: 12 | P14: 5 | Q14: 24 | S14: × | T14: × | U14: × | V14: × | W14: × | X14: × | Y14: e
A15: - | B15: 千葉L3.5 | C15: 工場系 | D15: 未実施（現地サーバ） | E15: L3層に存在するシステムとL4層に存在するシステムの中継となるサーバ | F15: WindowsServer2016 | G15: - | H15: - | I15: Systemwalker Operation Manager OWFT | J15: - | L15: 本番 APサーバ（現地） 検証 APサーバ（館林） | M15: 0 | N15: 0 | O15: 2 | P15: 千葉：52 徳山：14 | Q15: 0 | S15: × | T15: × | U15: × | V15: × | W15: × | X15: ×
A16: - | B16: 徳山L3.5 | S16: × | T16: × | U16: × | V16: × | W16: × | X16: ×
A17: SVC-00001969 | B17: 用役集計 | C17: 工場系 | D17: excelファイルでの構築の為不要 | E17: 用役管理システムで出力した帳票のデータをOneSAPへ連携する為のシステム。 | G17: Excel | S17: - | T17: 不明 | U17: - | V17: - | W17: - | X17: - | Y17: e
A18: SVC-00001975 | B18: PRM HULFT | C18: 工場系 | D18: 2023年Azure移行済み | E18: PRMSAP⇔製品倉庫等PRMシステムの連携中継サーバ | S18: × | T18: × | U18: × | V18: × | W18: × | X18: × | Y18: e
A19: SVC-00000702 | B19: ロット管理明細表システム（PRM） | C19: 工場系 | D19: XenAppにて稼働 | G19: Excel | S19: × | T19: × | U19: × | V19: × | W19: × | X19: × | Y19: e
A20: SVC-00000706 | B20: 工場ロ－カルＥｘｃｅｌシステム | C20: 工場系 | S20: × | T20: 不明 | U20: × | V20: × | W20: × | X20: × | Y20: e
A21: SVC-00000876 | B21: スクラップ管理システム | C21: 工場系 | S21: × | T21: × | U21: × | V21: × | W21: × | X21: × | Y21: e

Sheet Sheet1
B3: No | C3: パターン | D3: 説明 | E3: 金額
B4: 1 | C4: 次期アーキへ移行 | D4: 次期アーキへ移行のため概算総額 | E4: ='見積 (システム・基盤別サマリ) '!K12 -> 68960000
B5: 1-1 | D5: 上記の内、次期アーキ要件定義フェーズ金額 | E5: =SUM('見積 (システム・工程別サマリ)'!M21:M26) -> 12020000
B6: 1-2 | D6: 次期アーキ要件定義を現契約で実施するにあたり、現契約から追加で必要な金額 | E6: ='見積 (システム・工程別サマリ)'!Q28 -> 5213000
B7: 2 | C7: 縮小共通基盤へ移行 | D7: 中断中の移行フェーズを再開するにあたり、現契約から追加で必要な金額 | E7: ='見積 (縮小共通基盤継続） '!D23 -> 6549000
B8: 3 | C8: 縮小共通基盤へ移行後、次期アーキへ移行 | D8: No1+No2 | E8: ='見積 (システム・縮小共通基盤⇒クラウドアーキサマリ) '!M13 -> 75509000

Sheet 見積 (縮小共通基盤継続） 
C1: 工数直入力のため注意！！
C2: 移行フェーズ作業実績
G3: 備考
B5: No. | C5: 月 | D5: 作業内容 | E5: 工数 | F5: 金額
B6: 1 | C6: 7月（当初予定作業） | D6: 縮小共通基盤移行作業 ・環境構築 ・システムテスト準備 | E6: 2.335 | F6: 2444000 | G6: 石井：0.71人月*1,400k=\994,000 天川：0.5人月*1,000k=\500,000 馬場：0.5人月*1,000k=\500,000 BSE：0.125人月*800k=\100,000 VT：0.5人月*700k=\350,000
B7: 2 | C7: 8月（当初予定外作業） | D7: 次期アーキに向けた調査・検証作業 | E7: 4.38 | F7: 4366000 | G7: ①～8/25+残日数 石井：14.8人日+残2人日=0.84人月*1,400k=\1,176,000 天川：18.3人日+残4人日=1.12人月*1,000k=\1,120,000 馬場：19.3人日+残4人日=1.17人月*1,000k=\1,170,000 ②VT BSE：0.25人月*800k=\200,000 VT：1人月*700k=\700,000
B8: 3 | C8: 9月（当初予定外作業） | D8: 次期アーキに向けた調査・検証作業 | E8: 2.2 | F8: 2183000 | G8: 9月中旬に方針確定と想定し、8月の0.5人月分で算出
B9: 計 | E9: =SUM(E6:E8) -> 8.915 | F9: =SUM(F6:F8) -> 8993000
C12: 案件名 | D12: 見積金額
C13: LMPP包装システム Azure移行（移行フェーズ） | D13: 2160000
C14: 千葉化学品質管理システム Azure移行（移行フェーズ） | D14: 2160000
C15: 数量確定システム Azure移行（移行フェーズ） | D15: 5440000
C16: 用役管理システム Azure移行（移行フェーズ） | D16: 5300000
C17: 工場DB Azure移行（移行フェーズ） | D17: 740000 | F17: 17480000
B18: ① | C18: 現契約合計 | D18: =SUM(D13:D17) -> 15800000 | F18: =D18-F9 -> 6807000
B19: ② | C19: 縮小共通基盤作業実績（7月作業実績） | D19: =F6 -> 2444000 | F19: =F17-F18 -> 10673000
B20: ③ | C20: 縮小共通基盤残作業分費用 （①-②） | D20: =D18-F6 -> 13356000
B21: ④ | C21: 次期アーキ調査・検証分費用 （8月、9月作業実績） | D21: =SUM(F7:F8) -> 6549000
B22: ⑤ | C22: 現契約残額（①-②-④） | D22: =D18-D19-D21 -> 6807000
B23: ⑥ | C23: 追加発注分（③-⑤） | D23: =D20-D22 -> 6549000
D24: ※ヤード認証基盤対応分は除く

Sheet 見積 (システム・基盤別サマリ) 
C1: 工数直入力のため注意！！
C2: 見積 (基盤別サマリ)
C3: パターン | D3: クラウドアーキ基盤に移行 | P3: 備考
D4: アプリ | L4: DB | N4: 全体
B5: No. | C5: システム | D5: 共通 (基盤に関わらず共通して必要な作業) | E5: AP基盤 | F5: 認証基盤 | G5: バッチ基盤 | H5: DB基盤 | I5: 管理 | J5: 工数計 | K5: 金額 | L5: 工数計 | M5: 金額 | N5: 工数計 | O5: 金額
B6: 1 | C6: 数量確定システム（千葉・徳山） | D6: 5.5 | E6: 9.2 | F6: 1.3 | G6: 0.9 | H6: 0 | I6: 3.8 | J6: =SUM(D6:I6) -> 20.7 | K6: =SUM(D6:H6)*1000000+I6*1400000 -> 22220000 | L6: 0 | M6: 0 | N6: =SUM(J6:J10)+L6 -> 58.3 | O6: =SUM(K6:K10)+M6 -> 62900000
B7: 2 | C7: 用役管理システム（千葉・徳山） | D7: 5.2 | E7: 5.3 | F7: 0.5 | G7: 0 | H7: 0 | I7: 2.6 | J7: =SUM(D7:I7) -> 13.6 | K7: =SUM(D7:H7)*1000000+I7*1400000 -> 14640000
B8: 3 | C8: 千葉化学品質管理システム | D8: 3.2 | E8: 7 | F8: 1.2 | G8: 0.7 | H8: 0 | I8: 2.7 | J8: =SUM(D8:I8) -> 14.8 | K8: =SUM(D8:H8)*1000000+I8*1400000 -> 15880000
B9: 4 | C9: ＬＭＰＰ包装システム | D9: 2.2 | E9: 3 | F9: 0.6 | G9: 0.6 | H9: 0 | I9: 1.9 | J9: =SUM(D9:I9) -> 8.3 | K9: =SUM(D9:H9)*1000000+I9*1400000 -> 9060000
B10: 5 | C10: 工場DB | D10: 0.4 | I10: 0.5 | J10: =SUM(D10:I10) -> 0.9 | K10: =SUM(D10:H10)*1000000+I10*1400000 -> 1100000
B11: 6 | C11: ヤ－ド操業システム（千葉・徳山） | D11: 2.4 | E11: 0 | F11: 2.4 | G11: 0 | H11: 0 | I11: 0.9 | J11: =SUM(D11:I11) -> 5.7 | K11: =SUM(D11:H11)*1000000+I11*1400000 -> 6060000 | L11: 0 | M11: =SUM(M5:M10) -> 0 | N11: =SUM(J11:J11)+L11 -> 5.7 | O11: =SUM(K11:K11)+M6 -> 6060000
B12: 計 | D12: =SUM(D6:D11) -> 18.9 | E12: =SUM(E6:E11) -> 24.5 | F12: =SUM(F6:F11) -> 6 | G12: =SUM(G6:G11) -> 2.2 | H12: =SUM(H6:H11) -> 0 | I12: =SUM(I6:I11) -> 12.4 | J12: =SUM(D12:I12) -> 64 | K12: =SUM(K6:K11) -> 68960000 | L12: =SUM(L6:L11) -> 0 | M12: =SUM(M6:M11) -> 0 | N12: =SUM(N6:N11) -> 64 | O12: =SUM(O6:O11) -> 68960000
B13: 単価 | D13: 1000000 | E13: 1000000 | F13: 1000000 | G13: 1000000 | H13: 1000000 | I13: 1400000
B14: 金額 | D14: =D12*D13 -> 18900000 | E14: =E12*E13 -> 24500000 | F14: =F12*F13 -> 6000000 | G14: =G12*G13 -> 2200000 | H14: =H12*H13 -> 0 | I14: =I12*I13 -> 17360000

Sheet 見積 (システム・工程別サマリ)
C1: 工数直入力のため注意！！
C2: 見積（工程別サマリ）
C3: パターン | D3: クラウドアーキ基盤に移行 | R3: 備考
D4: アプリ | N4: DB | P4: 全体
B5: No. | C5: システム | D5: 調査・要件定義 | E5: 設計 | F5: 製造 | G5: 結合テスト | H5: システムテスト | I5: ユーザテスト | J5: 本番稼働 | K5: 管理 | L5: 工数計 | M5: 金額 | N5: 工数計 | O5: 金額 | P5: 工数計 | Q5: 金額
B6: 1 | C6: 数量確定システム（千葉・徳山） | D6: 3.2 | E6: 1.6 | F6: 2.7 | G6: 5.2 | H6: 1.4 | I6: 0.8 | J6: 2 | K6: 3.8 | L6: =SUM(D6:K6) -> 20.7 | M6: =SUM(D6:J6)*1000000+K6*1400000 -> 22220000 | N6: 0 | O6: 0 | P6: =SUM(L6:L10)+N6 -> 58.3 | Q6: =SUM(M6:M10)+O6 -> 62900000
B7: 2 | C7: 用役管理システム（千葉・徳山） | D7: 1.4 | E7: 1.1 | F7: 1.5 | G7: 3.1 | H7: 1.1 | I7: 0.8 | J7: 2 | K7: 2.6 | L7: =SUM(D7:K7) -> 13.6 | M7: =SUM(D7:J7)*1000000+K7*1400000 -> 14640000
B8: 3 | C8: 千葉化学品質管理システム | D8: 1.7 | E8: 1.4 | F8: 1.6 | G8: 5.5 | H8: 0.8 | I8: 0.5 | J8: 0.6 | K8: 2.7 | L8: =SUM(D8:K8) -> 14.8 | M8: =SUM(D8:J8)*1000000+K8*1400000 -> 15880000
B9: 4 | C9: ＬＭＰＰ包装システム | D9: 1.3 | E9: 0.4 | F9: 1.6 | G9: 1.2 | H9: 0.8 | I9: 0.5 | J9: 0.6 | K9: 1.9 | L9: =SUM(D9:K9) -> 8.3 | M9: =SUM(D9:J9)*1000000+K9*1400000 -> 9060000
B10: 5 | C10: 工場DB | J10: 0.4 | K10: 0.5 | L10: =SUM(D10:K10) -> 0.9 | M10: =SUM(D10:J10)*1000000+K10*1400000 -> 1100000
B11: 6 | C11: ヤ－ド操業システム（千葉・徳山） | D11: 0.5 | E11: 0.4 | F11: 0.7 | G11: 1.4 | H11: 0.2 | I11: 0.1 | J11: 1.5 | K11: 0.9 | L11: =SUM(D11:K11) -> 5.7 | M11: =SUM(D11:J11)*1000000+K11*1400000 -> 6060000 | N11: 0 | O11: =SUM(O5:O10) -> 0 | P11: =SUM(L11:L11)+N11 -> 5.7 | Q11: =SUM(M11:M11)+O6 -> 6060000
B12: 計 | D12: =SUM(D6:D11) -> 8.1 | E12: =SUM(E6:E11) -> 4.9 | F12: =SUM(F6:F11) -> 8.1 | G12: =SUM(G6:G11) -> 16.4 | H12: =SUM(H6:H11) -> 4.3 | I12: =SUM(I6:I11) -> 2.7 | J12: =SUM(J6:J11) -> 7.1 | K12: =SUM(K6:K11) -> 12.4 | L12: =SUM(D12:K12) -> 64 | M12: =SUM(M6:M11) -> 68960000 | N12: =SUM(N6:N11) -> 0 | O12: =SUM(O6:O11) -> 0 | P12: =SUM(P6:P11) -> 64 | Q12: =SUM(Q6:Q11) -> 68960000
B13: 単価 | D13: 1000000 | E13: 1000000 | F13: 1000000 | G13: 1000000 | H13: 1000000 | I13: 1000000 | J13: 1000000 | K13: 1400000
B14: 金額 | D14: =D12*D13 -> 8100000 | E14: =E12*E13 -> 4900000 | F14: =F12*F13 -> 8100000 | G14: =G12*G13 -> 16400000 | H14: =H12*H13 -> 4300000 | I14: =I12*I13 -> 2700000 | J14: =J12*J13 -> 7100000 | K14: =K12*K13 -> 17360000
C17: 調査・要件定義（移行フェーズの契約変更）
C18: パターン | D18: クラウドアーキ基盤に移行 | R18: 備考
D19: アプリ | N19: DB | P19: 全体
B20: No. | C20: システム | D20: 調査・要件定義 | E20: 設計 | F20: 製造 | G20: 結合テスト | H20: システムテスト | I20: ユーザテスト | J20: 本番稼働 | K20: 管理 | L20: 工数計 | M20: 金額 | N20: 工数計 | O20: 金額 | P20: 工数計 | Q20: 金額
B21: 1 | C21: 数量確定システム（千葉・徳山） | D21: 3.2 | K21: 0.9 | L21: =SUM(D21:K21) -> 4.1 | M21: =SUM(D21:J21)*1000000+K21*1400000 -> 4460000 | N21: 0 | O21: 0 | P21: =SUM(L21:L25)+N21 -> 10.2 | Q21: =SUM(M21:M25)+O21 -> 11240000
B22: 2 | C22: 用役管理システム（千葉・徳山） | D22: 1.4 | K22: 0.6 | L22: =SUM(D22:K22) -> 2 | M22: =SUM(D22:J22)*1000000+K22*1400000 -> 2240000
B23: 3 | C23: 千葉化学品質管理システム | D23: 1.7 | K23: 0.6 | L23: =SUM(D23:K23) -> 2.3 | M23: =SUM(D23:J23)*1000000+K23*1400000 -> 2540000
B24: 4 | C24: ＬＭＰＰ包装システム | D24: 1.3 | K24: 0.5 | L24: =SUM(D24:K24) -> 1.8 | M24: =SUM(D24:J24)*1000000+K24*1400000 -> 2000000
B25: 5 | C25: 工場DB | L25: =SUM(D25:K25) -> 0 | M25: =SUM(D25:J25)*1000000+K25*1400000 -> 0
B26: 6 | C26: ヤ－ド操業システム（千葉・徳山） | D26: 0.5 | K26: 0.2 | L26: =SUM(D26:K26) -> 0.7 | M26: =SUM(D26:J26)*1000000+K26*1400000 -> 780000 | P26: =SUM(L26:L26)+N26 -> 0.7 | Q26: =SUM(M26:M26)+O26 -> 780000
B27: 7 | C27: 縮小共通基盤（移行フェーズ） | L27: =SUM(D27:K27) -> 0 | M27: -6807000 | P27: =SUM(L27:L27)+N27 -> 0 | Q27: =SUM(M27:M27)+O21 -> -6807000 | R27: 現契約残額を差し引き
B28: 計 | D28: =SUM(D21:D27) -> 8.1 | E28: =SUM(E21:E27) -> 0 | F28: =SUM(F21:F27) -> 0 | G28: =SUM(G21:G27) -> 0 | H28: =SUM(H21:H27) -> 0 | I28: =SUM(I21:I27) -> 0 | J28: =SUM(J21:J27) -> 0 | K28: =SUM(K22:K27) -> 1.9 | L28: =SUM(D28:K28) -> 10 | M28: =SUM(M21:M27) -> 5213000 | N28: =SUM(N21:N27) -> 0 | O28: =SUM(O21:O27) -> 0 | P28: =SUM(P21:P27) -> 10.9 | Q28: =SUM(Q21:Q27) -> 5213000
B29: 単価 | D29: 1000000 | E29: 1000000 | F29: 1000000 | G29: 1000000 | H29: 1000000 | I29: 1000000 | J29: 1000000 | K29: 1400000
B30: 金額 | D30: =D28*D29 -> 8100000 | E30: =E28*E29 -> 0 | F30: =F28*F29 -> 0 | G30: =G28*G29 -> 0 | H30: =H28*H29 -> 0 | I30: =I28*I29 -> 0 | J30: =J28*J29 -> 0 | K30: =K28*K29 -> 2660000
C32: 調査・要件定義(クラウドアーキから開始)
C33: パターン | D33: クラウドアーキ基盤に移行 | R33: 備考
D34: アプリ | N34: DB | P34: 全体
B35: No. | C35: システム | D35: 調査・要件定義 | E35: 設計 | F35: 製造 | G35: 結合テスト | H35: システムテスト | I35: ユーザテスト | J35: 本番稼働 | K35: 管理 | L35: 工数計 | M35: 金額 | N35: 工数計 | O35: 金額 | P35: 工数計 | Q35: 金額
B36: 1 | C36: 数量確定システム（千葉・徳山） | D36: 3.2 | K36: 0.9 | L36: =SUM(D36:K36) -> 4.1 | M36: =SUM(D36:J36)*1000000+K36*1400000 -> 4460000 | N36: 0 | O36: 0 | P36: =SUM(L36:L40)+N36 -> 10.2 | Q36: =SUM(M36:M40)+O36 -> 11240000
B37: 2 | C37: 用役管理システム（千葉・徳山） | D37: 1.4 | K37: 0.6 | L37: =SUM(D37:K37) -> 2 | M37: =SUM(D37:J37)*1000000+K37*1400000 -> 2240000
B38: 3 | C38: 千葉化学品質管理システム | D38: 1.7 | K38: 0.6 | L38: =SUM(D38:K38) -> 2.3 | M38: =SUM(D38:J38)*1000000+K38*1400000 -> 2540000
B39: 4 | C39: ＬＭＰＰ包装システム | D39: 1.3 | K39: 0.5 | L39: =SUM(D39:K39) -> 1.8 | M39: =SUM(D39:J39)*1000000+K39*1400000 -> 2000000
B40: 5 | C40: 工場DB | L40: =SUM(D40:K40) -> 0 | M40: =SUM(D40:J40)*1000000+K40*1400000 -> 0
B41: 6 | C41: ヤ－ド操業システム（千葉・徳山） | D41: 0.5 | K41: 0.2 | L41: =SUM(D41:K41) -> 0.7 | M41: =SUM(D41:J41)*1000000+K41*1400000 -> 780000 | P41: =SUM(L41:L41)+N41 -> 0.7 | Q41: =SUM(M41:M41)+O36 -> 780000
B42: 計 | D42: =SUM(D36:D41) -> 8.1 | E42: =SUM(E36:E41) -> 0 | F42: =SUM(F36:F41) -> 0 | G42: =SUM(G36:G41) -> 0 | H42: =SUM(H36:H41) -> 0 | I42: =SUM(I36:I41) -> 0 | J42: =SUM(J36:J41) -> 0 | K42: =SUM(K37:K41) -> 1.9 | L42: =SUM(D42:K42) -> 10 | M42: =SUM(M36:M41) -> 12020000 | N42: =SUM(N36:N41) -> 0 | O42: =SUM(O36:O41) -> 0 | P42: =SUM(P36:P41) -> 10.9 | Q42: =SUM(Q36:Q41) -> 12020000
B43: 単価 | D43: 1000000 | E43: 1000000 | F43: 1000000 | G43: 1000000 | H43: 1000000 | I43: 1000000 | J43: 1000000 | K43: 1400000
...

Sheet 見積 (システム・縮小共通基盤⇒クラウドアーキサマリ) 
C1: 工数直入力のため注意！！
C2: 見積（縮小共通基盤⇒クラウドアーキサマリ）
C3: パターン | D3: クラウドアーキ基盤に移行 | R3: 備考
D4: アプリ | N4: DB | P4: 全体
B5: No. | C5: システム | D5: 調査・要件定義 | E5: 設計 | F5: 製造 | G5: 結合テスト | H5: システムテスト | I5: ユーザテスト | J5: 本番稼働 | K5: 管理 | L5: 工数計 | M5: 金額 | N5: 工数計 | O5: 金額 | P5: 工数計 | Q5: 金額
B6: 1 | C6: 数量確定システム（千葉・徳山） | D6: 3.2 | E6: 1.6 | F6: 2.7 | G6: 5.2 | H6: 1.4 | I6: 0.8 | J6: 2 | K6: 3.8 | L6: =SUM(D6:K6) -> 20.7 | M6: =SUM(D6:J6)*1000000+K6*1400000 -> 22220000 | N6: 0 | O6: 0 | P6: =SUM(L6:L10)+N6 -> 58.3 | Q6: =SUM(M6:M10)+O6 -> 62900000
B7: 2 | C7: 用役管理システム（千葉・徳山） | D7: 1.4 | E7: 1.1 | F7: 1.5 | G7: 3.1 | H7: 1.1 | I7: 0.8 | J7: 2 | K7: 2.6 | L7: =SUM(D7:K7) -> 13.6 | M7: =SUM(D7:J7)*1000000+K7*1400000 -> 14640000
B8: 3 | C8: 千葉化学品質管理システム | D8: 1.7 | E8: 1.4 | F8: 1.6 | G8: 5.5 | H8: 0.8 | I8: 0.5 | J8: 0.6 | K8: 2.7 | L8: =SUM(D8:K8) -> 14.8 | M8: =SUM(D8:J8)*1000000+K8*1400000 -> 15880000
B9: 4 | C9: ＬＭＰＰ包装システム | D9: 1.3 | E9: 0.4 | F9: 1.6 | G9: 1.2 | H9: 0.8 | I9: 0.5 | J9: 0.6 | K9: 1.9 | L9: =SUM(D9:K9) -> 8.3 | M9: =SUM(D9:J9)*1000000+K9*1400000 -> 9060000
B10: 5 | C10: 工場DB | J10: 0.4 | K10: 0.5 | L10: =SUM(D10:K10) -> 0.9 | M10: =SUM(D10:J10)*1000000+K10*1400000 -> 1100000
B11: 6 | C11: ヤ－ド操業システム（千葉・徳山） | D11: 0.5 | E11: 0.4 | F11: 0.7 | G11: 1.4 | H11: 0.2 | I11: 0.1 | J11: 1.5 | K11: 0.9 | L11: =SUM(D11:K11) -> 5.7 | M11: =SUM(D11:J11)*1000000+K11*1400000 -> 6060000 | N11: 0 | O11: =SUM(O4:O9) -> 0 | P11: =SUM(L11:L11)+N11 -> 5.7 | Q11: =SUM(M11)+O11 -> 6060000
B12: 7 | C12: 縮小共通基盤対応 | M12: ='見積 (縮小共通基盤継続） '!D23 -> 6549000 | N12: 0 | O12: =SUM(O5:O10) -> 0 | P12: =SUM(L12:L12)+N12 -> 0 | Q12: =SUM(M12:M12)+O6 -> 6549000 | R12: 残作業工数
B13: 計 | D13: =SUM(D6:D12) -> 8.1 | E13: =SUM(E6:E12) -> 4.9 | F13: =SUM(F6:F12) -> 8.1 | G13: =SUM(G6:G12) -> 16.4 | H13: =SUM(H6:H12) -> 4.3 | I13: =SUM(I6:I12) -> 2.7 | J13: =SUM(J6:J12) -> 7.1 | K13: =SUM(K6:K12) -> 12.4 | L13: =SUM(D13:K13) -> 64 | M13: =SUM(M6:M12) -> 75509000 | N13: =SUM(N6:N12) -> 0 | O13: =SUM(O6:O12) -> 0 | P13: =SUM(P6:P12) -> 64 | Q13: =SUM(Q6:Q12) -> 75509000
B14: 単価 | D14: 1000000 | E14: 1000000 | F14: 1000000 | G14: 1000000 | H14: 1000000 | I14: 1000000 | J14: 1000000 | K14: 1400000
B15: 金額 | D15: =D13*D14 -> 8100000 | E15: =E13*E14 -> 4900000 | F15: =F13*F14 -> 8100000 | G15: =G13*G14 -> 16400000 | H15: =H13*H14 -> 4300000 | I15: =I13*I14 -> 2700000 | J15: =J13*J14 -> 7100000 | K15: =K13*K14 -> 17360000

Sheet 見積 (各フェーズ毎、品管包装付替済) 
C1: 工数直入力のため注意！！
C2: 見積（工程別サマリ）
C3: パターン | D3: クラウドアーキ基盤に移行 | R3: 備考
D4: アプリ | N4: DB | P4: 全体
B5: No. | C5: システム | D5: 調査・要件定義 | E5: 設計 | F5: 製造 | G5: 結合テスト | H5: システムテスト | I5: ユーザテスト | J5: 本番稼働 | K5: 管理 | L5: 工数計 | M5: 金額 | N5: 工数計 | O5: 金額 | P5: 工数計 | Q5: 金額
B6: 1 | C6: 数量確定システム（千葉・徳山） | D6: 3.2 | E6: 1.6 | F6: 2.7 | G6: 5.2 | H6: 1.4 | I6: 0.8 | J6: 2 | K6: 3.8 | L6: =SUM(D6:K6) -> 20.7 | M6: =SUM(D6:J6)*1000000+K6*1400000 -> 22220000 | N6: 0 | O6: 0 | P6: =SUM(L6:L10)+N6 -> 58.3 | Q6: =SUM(M6:M10)+O6 -> 62900000
B7: 2 | C7: 用役管理システム（千葉・徳山） | D7: 1.4 | E7: 1.1 | F7: 1.5 | G7: 3.1 | H7: 1.1 | I7: 0.8 | J7: 2 | K7: 2.6 | L7: =SUM(D7:K7) -> 13.6 | M7: =SUM(D7:J7)*1000000+K7*1400000 -> 14640000
B8: 3 | C8: 千葉化学品質管理システム | D8: 1.5 | E8: 0.9 | F8: 1.2 | G8: 3.1 | H8: 0.6 | I8: 0.3 | J8: 0.3 | K8: 2.2 | L8: =SUM(D8:K8) -> 10.1 | M8: =SUM(D8:J8)*1000000+K8*1400000 -> 10980000
B9: 4 | C9: ＬＭＰＰ包装システム | D9: 1.5 | E9: 0.9 | F9: 2 | G9: 3.6 | H9: 1 | I9: 0.7 | J9: 0.9 | K9: 2.4 | L9: =SUM(D9:K9) -> 13 | M9: =SUM(D9:J9)*1000000+K9*1400000 -> 13960000
B10: 5 | C10: 工場DB | J10: 0.4 | K10: 0.5 | L10: =SUM(D10:K10) -> 0.9 | M10: =SUM(D10:J10)*1000000+K10*1400000 -> 1100000
B11: 6 | C11: ヤ－ド操業システム（千葉・徳山） | D11: 0.5 | E11: 0.4 | F11: 0.7 | G11: 1.4 | H11: 0.2 | I11: 0.1 | J11: 1.5 | K11: 0.9 | L11: =SUM(D11:K11) -> 5.7 | M11: =SUM(D11:J11)*1000000+K11*1400000 -> 6060000 | N11: 0 | O11: =SUM(O5:O10) -> 0 | P11: =SUM(L11:L11)+N11 -> 5.7 | Q11: =SUM(M11:M11)+O6 -> 6060000
B12: 計 | D12: =SUM(D6:D11) -> 8.1 | E12: =SUM(E6:E11) -> 4.9 | F12: =SUM(F6:F11) -> 8.1 | G12: =SUM(G6:G11) -> 16.4 | H12: =SUM(H6:H11) -> 4.3 | I12: =SUM(I6:I11) -> 2.7 | J12: =SUM(J6:J11) -> 7.1 | K12: =SUM(K6:K11) -> 12.4 | L12: =SUM(D12:K12) -> 64 | M12: =SUM(M6:M11) -> 68960000 | N12: =SUM(N6:N11) -> 0 | O12: =SUM(O6:O11) -> 0 | P12: =SUM(P6:P11) -> 64 | Q12: =SUM(Q6:Q11) -> 68960000
B13: 単価 | D13: 1000000 | E13: 1000000 | F13: 1000000 | G13: 1000000 | H13: 1000000 | I13: 1000000 | J13: 1000000 | K13: 1400000
B14: 金額 | D14: =D12*D13 -> 8100000 | E14: =E12*E13 -> 4900000 | F14: =F12*F13 -> 8100000 | G14: =G12*G13 -> 16400000 | H14: =H12*H13 -> 4300000 | I14: =I12*I13 -> 2700000 | J14: =J12*J13 -> 7100000 | K14: =K12*K13 -> 17360000
C16: 調査・要件定義（移行フェーズの契約変更）
C17: パターン | D17: クラウドアーキ基盤に移行 | R17: 備考
D18: アプリ | N18: DB | P18: 全体
B19: No. | C19: システム | D19: 調査・要件定義 | E19: 設計 | F19: 製造 | G19: 結合テスト | H19: システムテスト | I19: ユーザテスト | J19: 本番稼働 | K19: 管理 | L19: 工数計 | M19: 金額 | N19: 工数計 | O19: 金額 | P19: 工数計 | Q19: 金額
B20: 1 | C20: 数量確定システム（千葉・徳山） | D20: 3.2 | K20: 0.9 | L20: =SUM(D20:K20) -> 4.1 | M20: =SUM(D20:J20)*1000000+K20*1400000 -> 4460000 | N20: 0 | O20: 0 | P20: =SUM(L20:L24)+N20 -> 10.2 | Q20: =SUM(M20:M24)+O20 -> 11240000
B21: 2 | C21: 用役管理システム（千葉・徳山） | D21: 1.4 | K21: 0.6 | L21: =SUM(D21:K21) -> 2 | M21: =SUM(D21:J21)*1000000+K21*1400000 -> 2240000
B22: 3 | C22: 千葉化学品質管理システム | D22: 1.7 | K22: 0.6 | L22: =SUM(D22:K22) -> 2.3 | M22: =SUM(D22:J22)*1000000+K22*1400000 -> 2540000
B23: 4 | C23: ＬＭＰＰ包装システム | D23: 1.3 | K23: 0.5 | L23: =SUM(D23:K23) -> 1.8 | M23: =SUM(D23:J23)*1000000+K23*1400000 -> 2000000
B24: 5 | C24: 工場DB | L24: =SUM(D24:K24) -> 0 | M24: =SUM(D24:J24)*1000000+K24*1400000 -> 0
B25: 6 | C25: ヤ－ド操業システム（千葉・徳山） | D25: 0.5 | K25: 0.2 | L25: =SUM(D25:K25) -> 0.7 | M25: =SUM(D25:J25)*1000000+K25*1400000 -> 780000 | P25: =SUM(L25:L25)+N25 -> 0.7 | Q25: =SUM(M25:M25)+O25 -> 780000
B26: 7 | C26: 縮小共通基盤（移行フェーズ） | L26: =SUM(D26:K26) -> 0 | M26: -6807000 | P26: =SUM(L26:L26)+N26 -> 0 | Q26: =SUM(M26:M26)+O20 -> -6807000 | R26: 現契約残額を差し引き
B27: 計 | D27: =SUM(D20:D26) -> 8.1 | E27: =SUM(E20:E26) -> 0 | F27: =SUM(F20:F26) -> 0 | G27: =SUM(G20:G26) -> 0 | H27: =SUM(H20:H26) -> 0 | I27: =SUM(I20:I26) -> 0 | J27: =SUM(J20:J26) -> 0 | K27: =SUM(K21:K26) -> 1.9 | L27: =SUM(D27:K27) -> 10 | M27: =SUM(M20:M26) -> 5213000 | N27: =SUM(N20:N26) -> 0 | O27: =SUM(O20:O26) -> 0 | P27: =SUM(P20:P26) -> 10.9 | Q27: =SUM(Q20:Q26) -> 5213000
B28: 単価 | D28: 1000000 | E28: 1000000 | F28: 1000000 | G28: 1000000 | H28: 1000000 | I28: 1000000 | J28: 1000000 | K28: 1400000
B29: 金額 | D29: =D27*D28 -> 8100000 | E29: =E27*E28 -> 0 | F29: =F27*F28 -> 0 | G29: =G27*G28 -> 0 | H29: =H27*H28 -> 0 | I29: =I27*I28 -> 0 | J29: =J27*J28 -> 0 | K29: =K27*K28 -> 2660000
C31: 調査・要件定義(クラウドアーキから開始)
C32: パターン | D32: クラウドアーキ基盤に移行 | R32: 備考
D33: アプリ | N33: DB | P33: 全体
B34: No. | C34: システム | D34: 調査・要件定義 | E34: 設計 | F34: 製造 | G34: 結合テスト | H34: システムテスト | I34: ユーザテスト | J34: 本番稼働 | K34: 管理 | L34: 工数計 | M34: 金額 | N34: 工数計 | O34: 金額 | P34: 工数計 | Q34: 金額
B35: 1 | C35: 数量確定システム（千葉・徳山） | D35: 3.2 | E35: 1.6 | K35: 0.8 | L35: =SUM(D35:K35) -> 5.6 | M35: =SUM(D35:J35)*1000000+K35*1400000 -> 5920000 | N35: 0 | O35: 0 | P35: =SUM(L35:L39)+N35 -> 15 | Q35: =SUM(M35:M39)+O35 -> 16160000
B36: 2 | C36: 用役管理システム（千葉・徳山） | D36: 1.4 | E36: 1.1 | K36: 0.7 | L36: =SUM(D36:K36) -> 3.2 | M36: =SUM(D36:J36)*1000000+K36*1400000 -> 3480000
B37: 3 | C37: 千葉化学品質管理システム | D37: 1.5 | E37: 0.9 | K37: 0.7 | L37: =SUM(D37:K37) -> 3.1 | M37: =SUM(D37:J37)*1000000+K37*1400000 -> 3380000
B38: 4 | C38: ＬＭＰＰ包装システム | D38: 1.5 | E38: 0.9 | K38: 0.7 | L38: =SUM(D38:K38) -> 3.1 | M38: =SUM(D38:J38)*1000000+K38*1400000 -> 3380000
B39: 5 | C39: 工場DB | L39: =SUM(D39:K39) -> 0 | M39: =SUM(D39:J39)*1000000+K39*1400000 -> 0
B40: 6 | C40: ヤ－ド操業システム（千葉・徳山） | D40: 0.5 | E40: 0.4 | K40: 0.3 | L40: =SUM(D40:K40) -> 1.2 | M40: =SUM(D40:J40)*1000000+K40*1400000 -> 1320000 | P40: =SUM(L40:L40)+N40 -> 1.2 | Q40: =SUM(M40:M40)+O35 -> 1320000
B41: 計 | D41: =SUM(D35:D40) -> 8.1 | E41: =SUM(E35:E40) -> 4.9 | F41: =SUM(F35:F40) -> 0 | G41: =SUM(G35:G40) -> 0 | H41: =SUM(H35:H40) -> 0 | I41: =SUM(I35:I40) -> 0 | J41: =SUM(J35:J40) -> 0 | K41: =SUM(K35:K40) -> 3.2 | L41: =SUM(D41:K41) -> 16.2 | M41: =SUM(M35:M40) -> 17480000 | N41: =SUM(N35:N40) -> 0 | O41: =SUM(O35:O40) -> 0 | P41: =SUM(P35:P40) -> 16.2 | Q41: =SUM(Q35:Q40) -> 17480000
B42: 単価 | D42: 1000000 | E42: 1000000 | F42: 1000000 | G42: 1000000 | H42: 1000000 | I42: 1000000 | J42: 1000000 | K42: 1400000
...

Sheet 見積 (要件_設計で区切り) 
C1: 工数直入力のため注意！！
C2: 見積（工程別サマリ）
C3: パターン | D3: クラウドアーキ基盤に移行 | R3: 備考
D4: アプリ | N4: DB | P4: 全体
B5: No. | C5: システム | D5: 調査・要件定義 | E5: 設計 | F5: 製造 | G5: 結合テスト | H5: システムテスト | I5: ユーザテスト | J5: 本番稼働 | K5: 管理 | L5: 工数計 | M5: 金額 | N5: 工数計 | O5: 金額 | P5: 工数計 | Q5: 金額
B6: 1 | C6: 数量確定システム（千葉・徳山） | D6: 3.2 | E6: 1.6 | F6: 2.7 | G6: 5.2 | H6: 1.4 | I6: 0.8 | J6: 2 | K6: 3.8 | L6: =SUM(D6:K6) -> 20.7 | M6: =SUM(D6:J6)*1000000+K6*1400000 -> 22220000 | N6: 0 | O6: 0 | P6: =SUM(L6:L10)+N6 -> 58.3 | Q6: =SUM(M6:M10)+O6 -> 62900000
B7: 2 | C7: 用役管理システム（千葉・徳山） | D7: 1.4 | E7: 1.1 | F7: 1.5 | G7: 3.1 | H7: 1.1 | I7: 0.8 | J7: 2 | K7: 2.6 | L7: =SUM(D7:K7) -> 13.6 | M7: =SUM(D7:J7)*1000000+K7*1400000 -> 14640000
B8: 3 | C8: 千葉化学品質管理システム | D8: 1.7 | E8: 1.4 | F8: 1.6 | G8: 5.5 | H8: 0.8 | I8: 0.5 | J8: 0.6 | K8: 2.7 | L8: =SUM(D8:K8) -> 14.8 | M8: =SUM(D8:J8)*1000000+K8*1400000 -> 15880000
B9: 4 | C9: ＬＭＰＰ包装システム | D9: 1.3 | E9: 0.4 | F9: 1.6 | G9: 1.2 | H9: 0.8 | I9: 0.5 | J9: 0.6 | K9: 1.9 | L9: =SUM(D9:K9) -> 8.3 | M9: =SUM(D9:J9)*1000000+K9*1400000 -> 9060000
B10: 5 | C10: 工場DB | J10: 0.4 | K10: 0.5 | L10: =SUM(D10:K10) -> 0.9 | M10: =SUM(D10:J10)*1000000+K10*1400000 -> 1100000
B11: 6 | C11: ヤ－ド操業システム（千葉・徳山） | D11: 0.5 | E11: 0.4 | F11: 0.7 | G11: 1.4 | H11: 0.2 | I11: 0.1 | J11: 1.5 | K11: 0.9 | L11: =SUM(D11:K11) -> 5.7 | M11: =SUM(D11:J11)*1000000+K11*1400000 -> 6060000 | N11: 0 | O11: =SUM(O5:O10) -> 0 | P11: =SUM(L11:L11)+N11 -> 5.7 | Q11: =SUM(M11:M11)+O6 -> 6060000
B12: 計 | D12: =SUM(D6:D11) -> 8.1 | E12: =SUM(E6:E11) -> 4.9 | F12: =SUM(F6:F11) -> 8.1 | G12: =SUM(G6:G11) -> 16.4 | H12: =SUM(H6:H11) -> 4.3 | I12: =SUM(I6:I11) -> 2.7 | J12: =SUM(J6:J11) -> 7.1 | K12: =SUM(K6:K11) -> 12.4 | L12: =SUM(D12:K12) -> 64 | M12: =SUM(M6:M11) -> 68960000 | N12: =SUM(N6:N11) -> 0 | O12: =SUM(O6:O11) -> 0 | P12: =SUM(P6:P11) -> 64 | Q12: =SUM(Q6:Q11) -> 68960000
B13: 単価 | D13: 1000000 | E13: 1000000 | F13: 1000000 | G13: 1000000 | H13: 1000000 | I13: 1000000 | J13: 1000000 | K13: 1400000
B14: 金額 | D14: =D12*D13 -> 8100000 | E14: =E12*E13 -> 4900000 | F14: =F12*F13 -> 8100000 | G14: =G12*G13 -> 16400000 | H14: =H12*H13 -> 4300000 | I14: =I12*I13 -> 2700000 | J14: =J12*J13 -> 7100000 | K14: =K12*K13 -> 17360000
C16: 調査・要件定義（移行フェーズの契約変更）
C17: パターン | D17: クラウドアーキ基盤に移行 | R17: 備考
D18: アプリ | N18: DB | P18: 全体
B19: No. | C19: システム | D19: 調査・要件定義 | E19: 設計 | F19: 製造 | G19: 結合テスト | H19: システムテスト | I19: ユーザテスト | J19: 本番稼働 | K19: 管理 | L19: 工数計 | M19: 金額 | N19: 工数計 | O19: 金額 | P19: 工数計 | Q19: 金額
B20: 1 | C20: 数量確定システム（千葉・徳山） | D20: 3.2 | K20: 0.9 | L20: =SUM(D20:K20) -> 4.1 | M20: =SUM(D20:J20)*1000000+K20*1400000 -> 4460000 | N20: 0 | O20: 0 | P20: =SUM(L20:L24)+N20 -> 10.2 | Q20: =SUM(M20:M24)+O20 -> 11240000
B21: 2 | C21: 用役管理システム（千葉・徳山） | D21: 1.4 | K21: 0.6 | L21: =SUM(D21:K21) -> 2 | M21: =SUM(D21:J21)*1000000+K21*1400000 -> 2240000
B22: 3 | C22: 千葉化学品質管理システム | D22: 1.7 | K22: 0.6 | L22: =SUM(D22:K22) -> 2.3 | M22: =SUM(D22:J22)*1000000+K22*1400000 -> 2540000
B23: 4 | C23: ＬＭＰＰ包装システム | D23: 1.3 | K23: 0.5 | L23: =SUM(D23:K23) -> 1.8 | M23: =SUM(D23:J23)*1000000+K23*1400000 -> 2000000
B24: 5 | C24: 工場DB | L24: =SUM(D24:K24) -> 0 | M24: =SUM(D24:J24)*1000000+K24*1400000 -> 0
B25: 6 | C25: ヤ－ド操業システム（千葉・徳山） | D25: 0.5 | K25: 0.2 | L25: =SUM(D25:K25) -> 0.7 | M25: =SUM(D25:J25)*1000000+K25*1400000 -> 780000 | P25: =SUM(L25:L25)+N25 -> 0.7 | Q25: =SUM(M25:M25)+O25 -> 780000
B26: 7 | C26: 縮小共通基盤（移行フェーズ） | L26: =SUM(D26:K26) -> 0 | M26: -6807000 | P26: =SUM(L26:L26)+N26 -> 0 | Q26: =SUM(M26:M26)+O20 -> -6807000 | R26: 現契約残額を差し引き
B27: 計 | D27: =SUM(D20:D26) -> 8.1 | E27: =SUM(E20:E26) -> 0 | F27: =SUM(F20:F26) -> 0 | G27: =SUM(G20:G26) -> 0 | H27: =SUM(H20:H26) -> 0 | I27: =SUM(I20:I26) -> 0 | J27: =SUM(J20:J26) -> 0 | K27: =SUM(K21:K26) -> 1.9 | L27: =SUM(D27:K27) -> 10 | M27: =SUM(M20:M26) -> 5213000 | N27: =SUM(N20:N26) -> 0 | O27: =SUM(O20:O26) -> 0 | P27: =SUM(P20:P26) -> 10.9 | Q27: =SUM(Q20:Q26) -> 5213000
B28: 単価 | D28: 1000000 | E28: 1000000 | F28: 1000000 | G28: 1000000 | H28: 1000000 | I28: 1000000 | J28: 1000000 | K28: 1400000
B29: 金額 | D29: =D27*D28 -> 8100000 | E29: =E27*E28 -> 0 | F29: =F27*F28 -> 0 | G29: =G27*G28 -> 0 | H29: =H27*H28 -> 0 | I29: =I27*I28 -> 0 | J29: =J27*J28 -> 0 | K29: =K27*K28 -> 2660000
C31: 調査・要件定義(クラウドアーキから開始)
C32: パターン | D32: クラウドアーキ基盤に移行 | R32: 備考
D33: アプリ | N33: DB | P33: 全体
B34: No. | C34: システム | D34: 調査・要件定義 | E34: 設計 | F34: 製造 | G34: 結合テスト | H34: システムテスト | I34: ユーザテスト | J34: 本番稼働 | K34: 管理 | L34: 工数計 | M34: 金額 | N34: 工数計 | O34: 金額 | P34: 工数計 | Q34: 金額
B35: 1 | C35: 数量確定システム（千葉・徳山） | D35: 3.2 | E35: 1.6 | K35: 1.2 | L35: =SUM(D35:K35) -> 6 | M35: =SUM(D35:J35)*1000000+K35*1400000 -> 6480000 | N35: 0 | O35: 0 | P35: =SUM(L35:L39)+N35 -> 15.6 | Q35: =SUM(M35:M39)+O35 -> 17000000
B36: 2 | C36: 用役管理システム（千葉・徳山） | D36: 1.4 | E36: 1.1 | K36: 0.8 | L36: =SUM(D36:K36) -> 3.3 | M36: =SUM(D36:J36)*1000000+K36*1400000 -> 3620000
B37: 3 | C37: 千葉化学品質管理システム | D37: 1.7 | E37: 1.4 | K37: 0.8 | L37: =SUM(D37:K37) -> 3.9 | M37: =SUM(D37:J37)*1000000+K37*1400000 -> 4220000
B38: 4 | C38: ＬＭＰＰ包装システム | D38: 1.3 | E38: 0.4 | K38: 0.7 | L38: =SUM(D38:K38) -> 2.4 | M38: =SUM(D38:J38)*1000000+K38*1400000 -> 2680000
B39: 5 | C39: 工場DB | L39: =SUM(D39:K39) -> 0 | M39: =SUM(D39:J39)*1000000+K39*1400000 -> 0
B40: 6 | C40: ヤ－ド操業システム（千葉・徳山） | D40: 0.5 | E40: 0.4 | K40: 0.3 | L40: =SUM(D40:K40) -> 1.2 | M40: =SUM(D40:J40)*1000000+K40*1400000 -> 1320000 | P40: =SUM(L40:L40)+N40 -> 1.2 | Q40: =SUM(M40:M40)+O35 -> 1320000
B41: 計 | D41: =SUM(D35:D40) -> 8.1 | E41: =SUM(E35:E40) -> 4.9 | F41: =SUM(F35:F40) -> 0 | G41: =SUM(G35:G40) -> 0 | H41: =SUM(H35:H40) -> 0 | I41: =SUM(I35:I40) -> 0 | J41: =SUM(J35:J40) -> 0 | K41: =SUM(K36:K40) -> 2.6 | L41: =SUM(D41:K41) -> 15.6 | M41: =SUM(M35:M40) -> 18320000 | N41: =SUM(N35:N40) -> 0 | O41: =SUM(O35:O40) -> 0 | P41: =SUM(P35:P40) -> 16.8 | Q41: =SUM(Q35:Q40) -> 18320000
B42: 単価 | D42: 1000000 | E42: 1000000 | F42: 1000000 | G42: 1000000 | H42: 1000000 | I42: 1000000 | J42: 1000000 | K42: 1400000
...

Sheet スケジュール案
A2: システム | B2: 担当 | C2: 2024年 | O2: 2025年 | S2: 202６年
C3: 1月 | D3: 2月 | E3: 3月 | F3: 4月 | G3: 5月 | H3: 6月 | I3: 7月 | J3: 8月 | K3: 9月 | L3: 10月 | M3: 11月 | N3: 12月 | O3: 9月 | P3: 10月 | Q3: 11月 | R3: 12月 | S3: １月 | T3: ２月 | U3: ３月 | V3: ４月 | W3: ５月 | X3: ６月
A4: マイルストン | K4: ★縮小共通基盤構築 | P4: ★新共通基盤構築 | U4: ★館林DC廃止
A5: 数量確定システム（千葉・徳山）
A6: 用役管理システム（千葉・徳山）
A7: 千葉化学品質管理システム
A8: ＬＭＰＰ包装システム
A9: 工場DB
A13: 想定要員数
A14: 管理 | O14: 2 | P14: 2 | Q14: 2 | R14: 2 | S14: 2 | T14: 1.5
A15: 数量確定 | O15: 2 | P15: 2 | Q15: 3 | R15: 3 | S15: 2 | T15: 1
A16: 用役管理 | O16: 1 | P16: 2 | Q16: 3 | R16: 2 | S16: 2 | T16: 1
A17: 千葉化学 | O17: 1 | P17: 2 | Q17: 3 | R17: 3 | S17: 2 | T17: 0.5
A18: 包装 | O18: 1 | P18: 1 | Q18: 1 | R18: 1 | S18: 0.5 | T18: 0.5
A19: ヤード操業 | F19: 2 | G19: 2 | H19: 5 | I19: 5 | J19: 5 | K19: 5 | L19: 5 | M19: 5 | N19: 5 | O19: 1 | P19: 1 | Q19: 1 | R19: 1 | S19: 1 | T19: 0.5
A20: 合計 | C20: =SUM(C15:C19) -> 0 | D20: =SUM(D15:D19) -> 0 | E20: =SUM(E15:E19) -> 0 | F20: =SUM(F15:F19) -> 2 | G20: =SUM(G15:G19) -> 2 | H20: =SUM(H15:H19) -> 5 | I20: =SUM(I15:I19) -> 5 | J20: =SUM(J15:J19) -> 5 | ... N20: =SUM(N15:N19) -> 5 | O20: =SUM(O14:O19) -> 8 | P20: =SUM(P14:P19) -> 10 | Q20: =SUM(Q14:Q19) -> 13 | R20: =SUM(R14:R19) -> 12 | S20: =SUM(S14:S19) -> 9.5 | T20: =SUM(T14:T19) -> 5 | U20: =SUM(U14:U19) -> 0 | V20: =SUM(V14:V19) -> 0 | ... X20: =SUM(X14:X19) -> 0
A23: 要員

Sheet 見積（数量確定システム）_明細（社内用）
B2: 前提条件
B3: 1 | C3: クラウドアーキ環境への移行を想定した作業見積をしています
B4: 2 | C4: 事前調査で一部検証をしておりますが、未確認および検討事項があるため、要件定義工程にて調査後に改めて開発フェーズ移行のお見積りをいたします。
B5: 3 | C5: 事前調査にて数量確定システムで検証したところ、エラー発生率が高い結果であったため、全画面のテスト(縮小共通基盤での結合テストと同等)の確認が必要
B6: 4 | C6: インフラ環境の構築作業は含まれていません。出光様にてご準備をいただくきます
B7: 5 | C7: データ移行の作業は含まれていません。出光様にてご準備をいただくきます
B10: 作業パターン： | C10: 作業パターン： | D10: クラウドアーキ基盤への移行 | F10: 端数処理のため、I列値を少数2桁目をROUNDUPしている | G10: 提示する場合は値のみ | L10: 作業用 | M10: 計算用 | Q10: レビュー工数 | T10: テスト用
B11: フェーズ | C11: 工程 | D11: タスク | E11: 区分 | F11: 作業詳細 | G11: 工数 | H11: 備考 | I11: 計算 | J11: 計 | K11: レビュー工数+バッファ （×1.2） | L11: 根拠補足 | M11: 機能数 | N11: 環境数 | O11: 生産性(１人当たりの作業時間) | P11: 人月換算 | Q11: レビュー工数係数 | T11: 画面数 | U11: 生産性 | V11: 帳票数 | W11: 生産性 | X11: バッチ数 | Y11: 生産性 | Z11: I/F数 | AA11: 生産性
B12: 要件定義フェーズ | C12: 要件定義 | D12: AP基盤 Oracle WebLogic ⇒ Azure App Service (PaaS) Apache Tomcat | E12: AP基盤 | F12: =ROUNDUP(K12,1) -> 1.1 | G12: =SUM(F12:F16) -> 3.2 | H12: 事前調査結果： ローカル環境にてWeblogicからTomcatへ変更して検証をした影響調査結果より正式な対応内容を精査する。 ※千葉・徳山でソースは共通 数量確定（千葉） 19/41機能でエラーが発生 数量確定（徳山） 3/25機能でエラーが発生 １．エラー事項の対応 ・NoClassDefFound ⇒不足ライブラリの追加および暫定（Weblogic）ライブラリ追加箇所の正式なライブラリ調査およびプログラム改修箇所を調査する ・計算処理でエラー(PimsYard) ⇒計算処理でエラーが発生する。 ローカル環境ではFWの問題で確認ができず。 ローカル環境からPIMSサーバへFW設定をして動作確認。 FW以外の問題が起因をしていないか検証する。 ・各種設定値の追加、修正 ⇒server.xml、web.xml、Context.xmlの定義を修正する | I12: =M12*N12*O12/P12 -> 0.825 | J12: 0.85 | K12: =J12*Q12 -> 1.02 | L12: エラー事項の対応 0.85人月 | M12: 22 | N12: 1 | O12: 6 | P12: 160 | Q12: 1.2
C13: 要件定義 | E13: AP基盤 | F13: =ROUNDUP(K13,1) -> 1 | H13: ２．ear⇒warファイルへのビルド手順変更 ・build.xmlの定義修正 ⇒earに関するビルド定義修正およびwar形式に伴う定義修正をおこなう。 ⇒ライブラリの依存関係に影響がある場合は設定の見直しをする。 ⇒warでビルドしたファイルをPoC環境Azure App Serviceに配備して動作検証をおこなう。 ３．EJBの対応 ⇒ライブラリ追加、設定値変更 ４．クラウドアーキ環境の情報収集 ・サーバ情報の確認（申請準備、システム構成の確認、確定） ⇒アドレスIP、ホスト名、通信要件(FW)、サーバスペックの確認 ⇒縮小共通基盤との環境構成に違いがあるか確認 | J13: 0.8 | K13: =J13*Q13 -> 0.96 | L13: ear⇒warファイルへのビルド手順変更 0.5人月 EJBの対応 0.1人月 クラウドアーキ環境の情報収集 0.2人月 | Q13: 1.2
C14: 要件定義 | D14: 認証基盤 認証AP：Oracle WebLogic ⇒Azure Entra ID | E14: 認証基盤 | F14: =ROUNDUP(K14,1) -> 0.6 | H14: 事前調査対応： ローカル環境にて認証用の共通ファイル（com0-lib2_4_0.jar）へ差し替え、ライブラリ内のクラス実行ができることまで確認済み。Azure Entra ID認証について検証をする。 工場系システム ・共通ログイン廃止対応 ⇒SSOからリンク呼び出しに変更になるため、呼び出しURL、パラメータの設定値を調査する。また、URL直入力により工場系システムの呼び出しができることを確認する。 ・ログインユーザ切り替え方法の検討 ⇒権限による機能違いを確認するためのログイン手順を検討する ※SSOからのログインではPCログイン時のアカウントで認証がされるため、ユーザや権限の切り替えができない。 ・SSOからの遷移時にエラーが発生した場合の画面制御 ⇒エラー画面の表示検討、要件を整理する ・EntraID利用申請 ⇒申請に必要な情報の整理まで対応 | J14: 0.5 | K14: =J14*Q14 -> 0.6 | L14: 工場系システム 0.3人月 EntraID利用申請 0.2人月 | Q14: 1.2
C15: 要件定義 | D15: バッチ基盤 System Walker Operation Manager ⇒A-AUTO | E15: バッチ基盤 | F15: =ROUNDUP(K15,1) -> 0.2 | H15: 事前調査対応： 実施なし A-AUTO登録する為の情報提供、作業分担とスケジュールの認識合わせ ⇒DP課ご担当者とのA-AUTO移行に伴う課題や担当、スケジュールを確認する ※オペマネ⇒A-AUTOへのジョブ登録はDP課にて準備いただく ※A-AUTOから起動するスクリプトはDP課にて準備いただく ※実行ユーザに変更がある場合は設定ファイル、設定内容修正作業が追加で必要 | J15: 0.1 | K15: =J15*Q15 -> 0.12 | L15: DP課調整 0.1人月 | Q15: 1.2
C16: 要件定義 | D16: 次工程以降正式見積 | E16: 共通 | F16: =ROUNDUP(K16,1) -> 0.3 | H16: 調査結果資料作成、要件定義一覧作成、承認 開発フェーズ以降の見積書作成 | J16: 0.2 | K16: =J16*Q16 -> 0.24 | L16: 見積書作成（概算見積根拠を精査）：0.2人月 ※縮小共通基盤の時は概算見積から変更がなかったが、今回はプログラム修正方法や本数未確定があるため、0.1⇒0.2で算出 | Q16: 1.2
B17: 開発フェーズ | C17: 設計 | D17: 移行方式設計 | E17: 共通 | F17: =ROUNDUP(K17,1) -> 0.3 | G17: =SUM(F17:F19) -> 1.6 | H17: アプリ移行方式設計 その他連携基盤移行設計 移行計画書 テスト計画書（全体、結合、システムテスト） ※縮小共通基盤対応で作成したものを更新 | J17: 0.2 | K17: =J17*Q17 -> 0.24 | L17: 設計 0.2人月 ※縮小共通基盤通盛流用するため0.4⇒0.2で算出 | Q17: 1.2
C18: 設計 | D18: アプリケーション関連 （FW関連） | E18: AP基盤 | F18: =ROUNDUP(K18,1) -> 0.3 | H18: アプリケーション関連設計書修正 ・通信要件 ⇒通信要件FW申請書の作成、設定を依頼 (AP基盤、DB基盤、バッチ基盤 × 2環境(検証・本番環境)) ※帳票基盤は利用していないため含めない | I18: =M18*N18*O18/P18 -> 0 | J18: 0.2 | K18: =J18*Q18 -> 0.24 | L18: 共通 0.2人月 | P18: 160 | Q18: 1.2
C19: 設計 | D19: アプリケーション関連 （AP基盤、バッチ基盤、認証基盤関連） | E19: 共通 | F19: =ROUNDUP(K19,1) -> 1 | H19: アプリケーション関連設計書修正 ・AP基盤 ⇒AppServise、EntraIDの利用申請（検証環境・本番環境） ⇒事前調査エラーの22機能について画面、機能設計書の修正を想定 ・認証基盤 ⇒認証機能に関する設計書を新規1本作成（工場系システム共通） ・バッチ基盤 ⇒A-AUTO用ジョブネット一覧、ジョブ構成図の2本修正 テスト仕様書作成 ⇒画面・機能一覧よりチェックシートを作成 | I19: =M19*N19*O19/P19 -> 0.625 | J19: 0.8 | K19: =J19*Q19 -> 0.96 | L19: AP基盤、認証基盤、バッチ基盤 0.6人月 ※25本対象。計算式参照 テスト仕様書 0.2人月 | M19: 25 | N19: 1 | O19: 4 | P19: 160 | Q19: 1.2
C20: 製造 | D20: アプリケーション構築 | E20: AP基盤 | F20: =ROUNDUP(K20,1) -> 0.9 | G20: =SUM(F20:F23) -> 2.7 | H20: ・修正ファイルを配備、疎通確認（検証）※結合テストまでに準備 ・修正ファイルを配備、疎通確認（本番）※システムテストまでに準備 ※デプロイ手順の修正を含む | J20: 0.75 | K20: =J20*Q20 -> 0.9 | L20: 検証 0.5人月 検証 0.25人月 ※縮小共通基盤時は0.6。デプロイ手順書対応工数 を追加 | Q20: 1.2
C21: 製造 | D21: AP基盤 | E21: AP基盤 | F21: =ROUNDUP(K21,1) -> 1.7 | H21: ・プログラム改修、ビルドファイル作成 １．エラー事項の対応 ２．ear⇒warファイルへのビルド手順変更 ３．EJBの対応 ４．IP、ホスト名、DB接続先(必要があれば)の変更 | J21: 1.4 | K21: =J21*Q21 -> 1.68 | L21: プログラム改修、ビルドファイル作成 1.4人月 内訳 １．エラー事項の対応 1.0人月 ２．ear⇒warファイルへのビルド手順変更 0.3人月 ３．EJBの対応 0.05人月 ４．IP、ホスト名、DB接続先(必要があれば)の変更 0.05人月 | Q21: 1.2
C22: 製造 | D22: 認証基盤 | E22: 認証基盤 | F22: =ROUNDUP(K22,1) -> 0.1 | H22: ・プログラム改修、ビルドファイル作成 ５，com0-lib2_4_0.jarファイル対応 | J22: 0.05 | K22: =J22*Q22 -> 0.06 | L22: プログラム改修、ビルドファイル作成 0.05人月 内訳 ５，com0-lib2_4_0.jarファイル対応 0.05人月 | Q22: 1.2
C23: 製造 | D23: バッチ基盤 | E23: バッチ基盤 | F23: 0 | H23: 特になし | K23: =J23*Q23 -> 0 | Q23: 1.2
C24: 結合テスト | D24: 結合テスト | E24: AP基盤 | F24: =ROUNDUP(K24,1) -> 4.2 | G24: =SUM(F24:F24) -> 4.2 | H24: システム内の全画面を確認し、初期画面の描画や正常系の動作に問題がないことを確認。 ・データベースの参照・登録 ・画面遷移 ・ボタン押下 等 機能数（画面＋帳票＋IF）=113 ※IFは疎通確認まで ※テスト工数削減案として、チェックリストによる動作確認までとし、エビデンスは異常が発生したパターンのみ採取する。品質担保としてユーザ様に協力をいただき、ユーザテストにて動作検証を手厚く実施をお願いする（作業工数50%削減を想定） | I24: =(T24*U24+V24*W24+X24*Y24+Z24*AA24)/P24 -> 3.45 | J24: 3.45 | K24: =J24*Q24 -> 4.14 | L24: 結合テスト3.45人月 113機能 画面：6H 帳票：3H IF:3H ※縮小共通基盤から変更なし | P24: 160 | Q24: 1.2 | T24: 71 | U24: 6 | V24: 30 | W24: 3 | Z24: 12 | AA24: 3
C25: 結合テスト | D25: 結合テスト | E25: バッチ基盤 | F25: =ROUNDUP(K25,1) -> 0.4 | G25: =SUM(F25:F25) -> 0.4 | H25: A-AUTOバスクリプトのテスト 機能数（バッチ）=15 | I25: =(T25*U25+V25*W25+X25*Y25+Z25*AA25)/P25 -> 0.28125 | J25: 0.28 | K25: =J25*Q25 -> 0.336 | L25: 結合テスト0.28人月 15機能 バッチ：3H | P25: 160 | Q25: 1.2 | X25: 15 | Y25: 3
C26: 結合テスト | D26: 結合テスト | E26: 認証基盤 | F26: =ROUNDUP(K26,1) -> 0.6 | G26: =SUM(F26:F26) -> 0.6 | H26: EntraID認証でログインができることを確認。 ・工場系システム（数量確定） Https通信へ変更したことによる影響確認 ・ドメインは共通のため1環境を対象に影響確認 | J26: 0.5 | K26: =J26*Q26 -> 0.6 | L26: 工場系システム：0.1人月 Https通信へ変更：0.4人月 | P26: 160 | Q26: 1.2 | T26: 71 | U26: 6 | V26: 30 | W26: 3 | X26: 15 | Y26: 3 | Z26: 12 | AA26: 3
B27: 移行フェーズ | C27: システムテスト | D27: システムテスト | E27: バッチ基盤 | F27: =ROUNDUP(K27,1) -> 0.3 | G27: =SUM(F27:F27) -> 0.3 | H27: A-AUTO実行テスト DP課ご担当者による手動実行、作業立会い。エラー発生時の調査。 ※スケジュール実行対象ジョブ全量の確認を想定 12ジョブ | J27: 0.2 | K27: =J27*Q27 -> 0.24 | L27: A-AUTO実行 0.2人月 | P27: 160 | Q27: 1.2
C28: システムテスト | D28: システムテスト 本番切り替えテスト | E28: 共通 | F28: =ROUNDUP(K28,1) -> 1.1 | G28: =SUM(F28:F28) -> 1.1 | H28: 他システムとの連携テスト(本番環境⇔他システム(本番)) SAP、PIMS（ヤード操業千葉・徳山）、オフラス（千葉） 他シスとのテスト調整 ※全確認ではなく代表1本 | J28: 0.9 | K28: =J28*Q28 -> 1.08 | L28: 他システムとの連携テスト 0.9人月 ※縮小共通基盤から変更なし | P28: 160 | Q28: 1.2
C29: ユーザテスト | D29: ユーザテスト | E29: 共通 | F29: =ROUNDUP(K29,1) -> 0.8 | G29: =SUM(F29:F29) -> 0.8 | H29: ユーザテスト支援、問い合わせ対応、不具合指摘修正 ※ユーザテスト仕様書、計画書は含めない | J29: 0.75 | K29: =J29*Q29 -> 0.75 | L29: ユーザテスト支援、問い合わせ対応、不具合指摘修正：0.75 縮小共通基盤から変更なし | Q29: 1
C30: 本番稼働 | D30: アプリ移行 | E30: 共通 | F30: =ROUNDUP(K30,1) -> 1 | G30: =SUM(F30:F31) -> 2 | H30: 移行手順書作成＋出光内の移行方式レビュー支援 移行作業 ※ユーザテスト段階で環境構築は完了済み想定 ※オペマネジョブ停止 ※A-AUTOスケジュール実行 ※現行環境の停止作業を実施 | J30: 1 | K30: =J30*Q30 -> 1 | L30: アプリ移行：1.0人月 縮小共通基盤から変更なし | Q30: 1
C31: 本番稼働 | D31: 初期流動 | E31: 共通 | F31: =ROUNDUP(K31,1) -> 1 | H31: 月末月初挟む0.5ヶ月×2名 | J31: 1 | K31: =J31*Q31 -> 1 | L31: 初期流動：1.0人月 縮小共通基盤から変更なし | Q31: 1
B32: 管理 | D32: 全体工数（各フェーズ合計） | F32: =ROUNDUP(SUM(G12:G31)*0.15,1) -> 2.6 | G32: =SUM(F32:F34) -> 3.8 | H32: 全体工数＊15%
C33: 管理 | D33: 定例会関連 | E33: 管理 | F33: =ROUNDUP(K33,1) -> 0.4 | H33: 定例会：(準備+実施＋議事録) | I33: =M33*N33*O33/P33 -> 0.375 | J33: =ROUNDUP(I33,1) -> 0.4 | K33: =J33*Q33 -> 0.4 | L33: 定例会：(準備+実施＋議事録)：3H 期間：4回/月・5ヵ月 | M33: 3 | N33: 4 | O33: 5 | P33: 160 | Q33: 1
C34: 管理 | D34: 工程完了レビュー関連 | E34: 管理 | F34: =ROUNDUP(K34,1) -> 0.8 | H34: 各工程完了レビュー：(準備+実施＋議事録)（要件定義～試験、PJ総括） | I34: =M34*N34*O34/P34 -> 0.75 | J34: 0.75 | K34: =J34*Q34 -> 0.75 | L34: 各工程完了レビュー：(準備+実施＋議事録)6H*5回 （要件定義～試験、PJ総括） 縮小共通基盤から変更なし | M34: 6 | N34: 5 | O34: 4 | P34: 160 | Q34: 1
C35: 合計 | G35: =SUM(G12:G34) -> 20.7 | L35: 縮小共通基盤：13.5人月
C38: 区分別 | D38: 工程別 | E38: 工数 | F38: 管理工数(小数第2で繰り上げ) | G38: 小計 | H38: 調整工数
C39: 要件定義 | D39: 共通
D40: AP基盤
D41: 認証基盤
D42: バッチ基盤
D43: 管理
C44: 設計 | D44: 共通
D45: AP基盤
...

Sheet 再見積もり(要件定義結果反映定システム）_明細（社内用） 
B2: 前提条件
B3: 1 | C3: クラウドアーキ環境への移行を想定した作業見積をしています
B4: 2 | C4: 事前調査で一部検証をしておりますが、未確認および検討事項があるため、要件定義工程にて調査後に改めて開発フェーズ移行のお見積りをいたします。
B5: 3 | C5: 事前調査にて数量確定システムで検証したところ、エラー発生率が高い結果であったため、全画面のテスト(縮小共通基盤での結合テストと同等)の確認が必要
B6: 4 | C6: インフラ環境の構築作業は含まれていません。出光様にてご準備をいただくきます
B7: 5 | C7: データ移行の作業は含まれていません。出光様にてご準備をいただくきます
B10: 作業パターン： | C10: 作業パターン： | D10: クラウドアーキ基盤への移行 | F10: 端数処理のため、I列値を少数2桁目をROUNDUPしている | G10: 提示する場合は値のみ | L10: 作業用 | M10: 計算用 | Q10: レビュー工数 | T10: テスト用
B11: フェーズ | C11: 工程 | D11: タスク | E11: 区分 | F11: 作業詳細 | G11: 工数 | H11: 備考 | I11: 計算 | J11: 計 | K11: レビュー工数+バッファ （×1.2） | L11: 根拠補足 | M11: 機能数 | N11: 環境数 | O11: 生産性(１人当たりの作業時間) | P11: 人月換算 | Q11: レビュー工数係数 | T11: 画面数 | U11: 生産性 | V11: 帳票数 | W11: 生産性 | X11: バッチ数 | Y11: 生産性 | Z11: I/F数 | AA11: 生産性
B12: 要件定義フェーズ | C12: 要件定義 | D12: AP基盤 Oracle WebLogic ⇒ Azure App Service (PaaS) Apache Tomcat | E12: AP基盤 | F12: =ROUNDUP(K12,1) -> 1.1 | G12: =SUM(F12:F16) -> 3.2 | H12: 事前調査結果： ローカル環境にてWeblogicからTomcatへ変更して検証をした影響調査結果より正式な対応内容を精査する。 ※千葉・徳山でソースは共通 数量確定（千葉） 19/41機能でエラーが発生 数量確定（徳山） 3/25機能でエラーが発生 １．エラー事項の対応 ・NoClassDefFound ⇒不足ライブラリの追加および暫定（Weblogic）ライブラリ追加箇所の正式なライブラリ調査およびプログラム改修箇所を調査する ・計算処理でエラー(PimsYard) ⇒計算処理でエラーが発生する。 ローカル環境ではFWの問題で確認ができず。 ローカル環境からPIMSサーバへFW設定をして動作確認。 FW以外の問題が起因をしていないか検証する。 ・各種設定値の追加、修正 ⇒server.xml、web.xml、Context.xmlの定義を修正する | I12: =M12*N12*O12/P12 -> 0.825 | J12: 0.85 | K12: =J12*Q12 -> 1.02 | L12: エラー事項の対応 0.85人月 | M12: 22 | N12: 1 | O12: 6 | P12: 160 | Q12: 1.2
C13: 要件定義 | E13: AP基盤 | F13: =ROUNDUP(K13,1) -> 1 | H13: ２．ear⇒warファイルへのビルド手順変更 ・build.xmlの定義修正 ⇒earに関するビルド定義修正およびwar形式に伴う定義修正をおこなう。 ⇒ライブラリの依存関係に影響がある場合は設定の見直しをする。 ⇒warでビルドしたファイルをPoC環境Azure App Serviceに配備して動作検証をおこなう。 ３．EJBの対応 ⇒ライブラリ追加、設定値変更 ４．クラウドアーキ環境の情報収集 ・サーバ情報の確認（申請準備、システム構成の確認、確定） ⇒アドレスIP、ホスト名、通信要件(FW)、サーバスペックの確認 ⇒縮小共通基盤との環境構成に違いがあるか確認 | J13: 0.8 | K13: =J13*Q13 -> 0.96 | L13: ear⇒warファイルへのビルド手順変更 0.5人月 EJBの対応 0.1人月 クラウドアーキ環境の情報収集 0.2人月 | Q13: 1.2
C14: 要件定義 | D14: 認証基盤 認証AP：Oracle WebLogic ⇒Azure Entra ID | E14: 認証基盤 | F14: =ROUNDUP(K14,1) -> 0.6 | H14: 事前調査対応： ローカル環境にて認証用の共通ファイル（com0-lib2_4_0.jar）へ差し替え、ライブラリ内のクラス実行ができることまで確認済み。Azure Entra ID認証について検証をする。 工場系システム ・共通ログイン廃止対応 ⇒SSOからリンク呼び出しに変更になるため、呼び出しURL、パラメータの設定値を調査する。また、URL直入力により工場系システムの呼び出しができることを確認する。 ・ログインユーザ切り替え方法の検討 ⇒権限による機能違いを確認するためのログイン手順を検討する ※SSOからのログインではPCログイン時のアカウントで認証がされるため、ユーザや権限の切り替えができない。 ・SSOからの遷移時にエラーが発生した場合の画面制御 ⇒エラー画面の表示検討、要件を整理する ・EntraID利用申請 ⇒申請に必要な情報の整理まで対応 | J14: 0.5 | K14: =J14*Q14 -> 0.6 | L14: 工場系システム 0.3人月 EntraID利用申請 0.2人月 | Q14: 1.2
C15: 要件定義 | D15: バッチ基盤 System Walker Operation Manager ⇒A-AUTO | E15: バッチ基盤 | F15: =ROUNDUP(K15,1) -> 0.2 | H15: 事前調査対応： 実施なし A-AUTO登録する為の情報提供、作業分担とスケジュールの認識合わせ ⇒DP課ご担当者とのA-AUTO移行に伴う課題や担当、スケジュールを確認する ※オペマネ⇒A-AUTOへのジョブ登録はDP課にて準備いただく ※A-AUTOから起動するスクリプトはDP課にて準備いただく ※実行ユーザに変更がある場合は設定ファイル、設定内容修正作業が追加で必要 | J15: 0.1 | K15: =J15*Q15 -> 0.12 | L15: DP課調整 0.1人月 | Q15: 1.2
C16: 要件定義 | D16: 次工程以降正式見積 | E16: 共通 | F16: =ROUNDUP(K16,1) -> 0.3 | H16: 調査結果資料作成、要件定義一覧作成、承認 開発フェーズ以降の見積書作成 | J16: 0.2 | K16: =J16*Q16 -> 0.24 | L16: 見積書作成（概算見積根拠を精査）：0.2人月 ※縮小共通基盤の時は概算見積から変更がなかったが、今回はプログラム修正方法や本数未確定があるため、0.1⇒0.2で算出 | Q16: 1.2
B17: 開発フェーズ | C17: 設計 | D17: 移行方式設計 | E17: 共通 | F17: =ROUNDUP(K17,1) -> 0.3 | G17: =SUM(F17:F19) -> 1.6 | H17: アプリ移行方式設計 その他連携基盤移行設計 移行計画書 テスト計画書（全体、結合、システムテスト） ※縮小共通基盤対応で作成したものを更新 | J17: 0.2 | K17: =J17*Q17 -> 0.24 | L17: 設計 0.2人月 ※縮小共通基盤通盛流用するため0.4⇒0.2で算出 | Q17: 1.2
C18: 設計 | D18: アプリケーション関連 （FW関連） | E18: AP基盤 | F18: =ROUNDUP(K18,1) -> 0.3 | H18: アプリケーション関連設計書修正 ・通信要件 ⇒通信要件FW申請書の作成、設定を依頼 (AP基盤、DB基盤、バッチ基盤 × 2環境(検証・本番環境)) ※帳票基盤は利用していないため含めない | I18: =M18*N18*O18/P18 -> 0 | J18: 0.2 | K18: =J18*Q18 -> 0.24 | L18: 共通 0.2人月 | P18: 160 | Q18: 1.2
C19: 設計 | D19: アプリケーション関連 （AP基盤、バッチ基盤、認証基盤関連） | E19: 共通 | F19: =ROUNDUP(K19,1) -> 1 | H19: アプリケーション関連設計書修正 ・AP基盤 ⇒AppServise、EntraIDの利用申請（検証環境・本番環境） ⇒事前調査エラーの22機能について画面、機能設計書の修正を想定 ・認証基盤 ⇒認証機能に関する設計書を新規1本作成（工場系システム共通） ・バッチ基盤 ⇒A-AUTO用ジョブネット一覧、ジョブ構成図の2本修正 テスト仕様書作成 ⇒画面・機能一覧よりチェックシートを作成 | I19: =M19*N19*O19/P19 -> 0.625 | J19: 0.8 | K19: =J19*Q19 -> 0.96 | L19: AP基盤、認証基盤、バッチ基盤 0.6人月 ※25本対象。計算式参照 テスト仕様書 0.2人月 | M19: 25 | N19: 1 | O19: 4 | P19: 160 | Q19: 1.2
C20: 製造 | D20: アプリケーション構築 | E20: AP基盤 | F20: =ROUNDUP(K20,1) -> 0.9 | G20: =SUM(F20:F23) -> 2.7 | H20: ・修正ファイルを配備、疎通確認（検証）※結合テストまでに準備 ・修正ファイルを配備、疎通確認（本番）※システムテストまでに準備 ※デプロイ手順の修正を含む | J20: 0.75 | K20: =J20*Q20 -> 0.9 | L20: 検証 0.5人月 検証 0.25人月 ※縮小共通基盤時は0.6。デプロイ手順書対応工数 を追加 | Q20: 1.2
C21: 製造 | D21: AP基盤 | E21: AP基盤 | F21: =ROUNDUP(K21,1) -> 1.7 | H21: ・プログラム改修、ビルドファイル作成 １．エラー事項の対応 ２．ear⇒warファイルへのビルド手順変更 ３．EJBの対応 ４．IP、ホスト名、DB接続先(必要があれば)の変更 | J21: 1.4 | K21: =J21*Q21 -> 1.68 | L21: プログラム改修、ビルドファイル作成 1.4人月 内訳 １．エラー事項の対応 1.0人月 ２．ear⇒warファイルへのビルド手順変更 0.3人月 ３．EJBの対応 0.05人月 ４．IP、ホスト名、DB接続先(必要があれば)の変更 0.05人月 | Q21: 1.2
C22: 製造 | D22: 認証基盤 | E22: 認証基盤 | F22: =ROUNDUP(K22,1) -> 0.1 | H22: ・プログラム改修、ビルドファイル作成 ５，com0-lib2_4_0.jarファイル対応 | J22: 0.05 | K22: =J22*Q22 -> 0.06 | L22: プログラム改修、ビルドファイル作成 0.05人月 内訳 ５，com0-lib2_4_0.jarファイル対応 0.05人月 | Q22: 1.2
C23: 製造 | D23: バッチ基盤 | E23: バッチ基盤 | F23: 0 | H23: 特になし | K23: =J23*Q23 -> 0 | Q23: 1.2
C24: 結合テスト | D24: 結合テスト | E24: AP基盤 | F24: =ROUNDUP(K24,1) -> 4.2 | G24: =SUM(F24:F24) -> 4.2 | H24: システム内の全画面を確認し、初期画面の描画や正常系の動作に問題がないことを確認。 ・データベースの参照・登録 ・画面遷移 ・ボタン押下 等 機能数（画面＋帳票＋IF）=113 ※IFは疎通確認まで ※テスト工数削減案として、チェックリストによる動作確認までとし、エビデンスは異常が発生したパターンのみ採取する。品質担保としてユーザ様に協力をいただき、ユーザテストにて動作検証を手厚く実施をお願いする（作業工数50%削減を想定） | I24: =(T24*U24+V24*W24+X24*Y24+Z24*AA24)/P24 -> 3.45 | J24: 3.45 | K24: =J24*Q24 -> 4.14 | L24: 結合テスト3.45人月 113機能 画面：6H 帳票：3H IF:3H ※縮小共通基盤から変更なし | P24: 160 | Q24: 1.2 | T24: 71 | U24: 6 | V24: 30 | W24: 3 | Z24: 12 | AA24: 3
C25: 結合テスト | D25: 結合テスト | E25: バッチ基盤 | F25: =ROUNDUP(K25,1) -> 0.4 | G25: =SUM(F25:F25) -> 0.4 | H25: A-AUTOバスクリプトのテスト 機能数（バッチ）=15 | I25: =(T25*U25+V25*W25+X25*Y25+Z25*AA25)/P25 -> 0.28125 | J25: 0.28 | K25: =J25*Q25 -> 0.336 | L25: 結合テスト0.28人月 15機能 バッチ：3H | P25: 160 | Q25: 1.2 | X25: 15 | Y25: 3
C26: 結合テスト | D26: 結合テスト | E26: 認証基盤 | F26: =ROUNDUP(K26,1) -> 0.6 | G26: =SUM(F26:F26) -> 0.6 | H26: EntraID認証でログインができることを確認。 ・工場系システム（数量確定） Https通信へ変更したことによる影響確認 ・ドメインは共通のため1環境を対象に影響確認 | J26: 0.5 | K26: =J26*Q26 -> 0.6 | L26: 工場系システム：0.1人月 Https通信へ変更：0.4人月 | P26: 160 | Q26: 1.2 | T26: 71 | U26: 6 | V26: 30 | W26: 3 | X26: 15 | Y26: 3 | Z26: 12 | AA26: 3
B27: 移行フェーズ | C27: システムテスト | D27: システムテスト | E27: バッチ基盤 | F27: =ROUNDUP(K27,1) -> 0.3 | G27: =SUM(F27:F27) -> 0.3 | H27: A-AUTO実行テスト DP課ご担当者による手動実行、作業立会い。エラー発生時の調査。 ※スケジュール実行対象ジョブ全量の確認を想定 12ジョブ | J27: 0.2 | K27: =J27*Q27 -> 0.24 | L27: A-AUTO実行 0.2人月 | P27: 160 | Q27: 1.2
C28: システムテスト | D28: システムテスト 本番切り替えテスト | E28: 共通 | F28: =ROUNDUP(K28,1) -> 1.1 | G28: =SUM(F28:F28) -> 1.1 | H28: 他システムとの連携テスト(本番環境⇔他システム(本番)) SAP、PIMS（ヤード操業千葉・徳山）、オフラス（千葉） 他シスとのテスト調整 ※全確認ではなく代表1本 | J28: 0.9 | K28: =J28*Q28 -> 1.08 | L28: 他システムとの連携テスト 0.9人月 ※縮小共通基盤から変更なし | P28: 160 | Q28: 1.2
C29: ユーザテスト | D29: ユーザテスト | E29: 共通 | F29: =ROUNDUP(K29,1) -> 0.8 | G29: =SUM(F29:F29) -> 0.8 | H29: ユーザテスト支援、問い合わせ対応、不具合指摘修正 ※ユーザテスト仕様書、計画書は含めない | J29: 0.75 | K29: =J29*Q29 -> 0.75 | L29: ユーザテスト支援、問い合わせ対応、不具合指摘修正：0.75 縮小共通基盤から変更なし | Q29: 1
C30: 本番稼働 | D30: アプリ移行 | E30: 共通 | F30: =ROUNDUP(K30,1) -> 1 | G30: =SUM(F30:F31) -> 2 | H30: 移行手順書作成＋出光内の移行方式レビュー支援 移行作業 ※ユーザテスト段階で環境構築は完了済み想定 ※オペマネジョブ停止 ※A-AUTOスケジュール実行 ※現行環境の停止作業を実施 | J30: 1 | K30: =J30*Q30 -> 1 | L30: アプリ移行：1.0人月 縮小共通基盤から変更なし | Q30: 1
C31: 本番稼働 | D31: 初期流動 | E31: 共通 | F31: =ROUNDUP(K31,1) -> 1 | H31: 月末月初挟む0.5ヶ月×2名 | J31: 1 | K31: =J31*Q31 -> 1 | L31: 初期流動：1.0人月 縮小共通基盤から変更なし | Q31: 1
B32: 管理 | D32: 全体工数（各フェーズ合計） | F32: =ROUNDUP(SUM(G12:G31)*0.15,1) -> 2.6 | G32: =SUM(F32:F34) -> 3.8 | H32: 全体工数＊15%
C33: 管理 | D33: 定例会関連 | E33: 管理 | F33: =ROUNDUP(K33,1) -> 0.4 | H33: 定例会：(準備+実施＋議事録) | I33: =M33*N33*O33/P33 -> 0.375 | J33: =ROUNDUP(I33,1) -> 0.4 | K33: =J33*Q33 -> 0.4 | L33: 定例会：(準備+実施＋議事録)：3H 期間：4回/月・5ヵ月 | M33: 3 | N33: 4 | O33: 5 | P33: 160 | Q33: 1
C34: 管理 | D34: 工程完了レビュー関連 | E34: 管理 | F34: =ROUNDUP(K34,1) -> 0.8 | H34: 各工程完了レビュー：(準備+実施＋議事録)（要件定義～試験、PJ総括） | I34: =M34*N34*O34/P34 -> 0.75 | J34: 0.75 | K34: =J34*Q34 -> 0.75 | L34: 各工程完了レビュー：(準備+実施＋議事録)6H*5回 （要件定義～試験、PJ総括） 縮小共通基盤から変更なし | M34: 6 | N34: 5 | O34: 4 | P34: 160 | Q34: 1
C35: 合計 | G35: =SUM(G12:G34) -> 20.7 | L35: 縮小共通基盤：13.5人月
C38: 区分別 | D38: 工程別 | E38: 工数 | F38: 管理工数(小数第2で繰り上げ) | G38: 小計 | H38: 調整工数
C39: 要件定義 | D39: 共通
D40: AP基盤
D41: 認証基盤
D42: バッチ基盤
D43: 管理
C44: 設計 | D44: 共通
D45: AP基盤
...

Sheet 見積（用役管理システム）_明細（社内用）
B2: 前提条件
B3: 1 | C3: クラウドアーキ環境への移行を想定した作業見積をしています
B4: 2 | C4: 事前調査で一部検証をしておりますが、未確認および検討事項があるため、要件定義工程にて調査後に改めて開発フェーズ移行のお見積りをいたします。
B5: 3 | C5: 事前調査にて数量確定システムで検証したところ、エラー発生率が高い結果であったため、全画面のテスト(縮小共通基盤での結合テストと同等)の確認が必要
B6: 4 | C6: インフラ環境の構築作業は含まれていません。出光様にてご準備をいただくきます
B7: 5 | C7: データ移行の作業は含まれていません。出光様にてご準備をいただくきます
B10: 作業パターン： | C10: 作業パターン： | D10: クラウドアーキ基盤への移行 | F10: 端数処理のため、I列値を少数2桁目をROUNDUPしている | G10: 提示する場合は値のみ | L10: 作業用 | M10: 計算用 | Q10: レビュー工数 | T10: テスト用
B11: フェーズ | C11: 工程 | D11: タスク | E11: 区分 | F11: 作業詳細 | G11: 工数 | H11: 備考 | I11: 計算 | J11: 計 | K11: レビュー工数+バッファ （×1.2） | L11: 根拠補足 | M11: 機能数 | N11: 環境数 | O11: 生産性(１人当たりの作業時間) | P11: 人月換算 | Q11: レビュー工数係数 | T11: 画面数 | U11: 生産性 | V11: 帳票数 | W11: 生産性 | X11: バッチ数 | Y11: 生産性 | Z11: I/F数 | AA11: 生産性
B12: 要件定義フェーズ | C12: 要件定義 | D12: AP基盤 Oracle WebLogic ⇒ Azure App Service (PaaS) Apache Tomcat | E12: AP基盤 | F12: =ROUNDUP(K12,1) -> 0.5 | G12: =SUM(F12:F16) -> 1.4 | H12: 事前調査対応・ ローカル環境にてWeblogicからTomcatへ変更して検証をした影響調査結果より正式な対応内容を精査する。 ※千葉・徳山でソースは共通 用役管理（千葉） 44機能 用役管理（徳山） 26機能 ※事前調査の数量確定(千葉、徳山)にて、機能一覧の内40%程度のエラーが発生したため、同程度のエラー（28機能）が発生することを想定 １．エラー事項の対応 既知の数量確定で発生したエラーについて同様の対応で問題無いか確認する。 ※数量確定で検知しているエラーについては含めない ※本システムのみ発生する不具合を想定し、調査工数として計上する | I12: =M12*N12*O12/P12 -> 0.35 | J12: 0.35 | K12: =J12*Q12 -> 0.42 | L12: エラー事項の対応 0.35人月 | M12: 28 | N12: 1 | O12: 2 | P12: 160 | Q12: 1.2
C13: 要件定義 | E13: AP基盤 | F13: =ROUNDUP(K13,1) -> 0.5 | H13: ２．ear⇒warファイルへのビルド手順変更 ・build.xmlの定義修正 ３．EJBの対応 ⇒ライブラリ追加、設定値変更 ４．クラウドアーキ環境の情報収集 ・サーバ情報の確認 ※本システムとしても同様対応が必要となるため、数量確定システムの50%工数で見積 | J13: 0.4 | K13: =J13*Q13 -> 0.48 | L13: ear⇒warファイルへのビルド手順変更 0.25人月 EJBの対応 0.05人月 クラウドアーキ環境の情報収集 0.1人月 | Q13: 1.2
C14: 要件定義 | D14: 認証基盤 認証AP：Oracle WebLogic ⇒Azure Entra ID | E14: 認証基盤 | F14: =ROUNDUP(K14,1) -> 0.2 | H14: 事前調査対応・ ローカル環境にて認証用の共通ファイル（com0-lib2_4_0.jar）へ差し替え、ライブラリ内のクラス実行ができることまで確認済み。Azure Entra ID認証について検証をする。 工場系システム ・SSOからリンク呼び出し対応 以下については数量確定で検討するため工数に含めない ・ログインユーザ切り替え方法の検討。 ・SSOからの遷移時にエラーが発生した場合の画面制御 | J14: 0.1 | K14: =J14*Q14 -> 0.12 | L14: SSOからリンク呼び出し対応 0.1人月 | Q14: 1.2
C15: 要件定義 | D15: バッチ基盤 System Walker Operation Manager ⇒A-AUTO | E15: バッチ基盤 | F15: =ROUNDUP(K15,1) -> 0 | H15: 事前調査対応： 実施なし A-AUTO登録する為の情報提供、作業分担とスケジュールの認識合わせ ⇒DP課ご担当者とのA-AUTO移行に伴う課題や担当、スケジュールを確認する ※用役管理はオペマネジョブが存在しないため対象外 | K15: =J15*Q15 -> 0 | Q15: 1.2
C16: 要件定義 | D16: 次工程以降正式見積 | E16: 共通 | F16: =ROUNDUP(K16,1) -> 0.2 | H16: 調査結果資料作成、要件定義一覧作成、承認 開発フェーズ以降の見積書作成 | J16: 0.1 | K16: =J16*Q16 -> 0.12 | L16: 見積書作成（概算見積根拠を精査）：0.1 | Q16: 1.2
B17: 開発フェーズ | C17: 設計 | D17: 移行方式設計 | E17: 共通 | F17: =ROUNDUP(K17,1) -> 0 | G17: =SUM(F17:F19) -> 1.1 | H17: アプリ移行方式設計 その他連携基盤移行設計 移行計画書 テスト計画書（全体、結合、システムテスト） ※縮小共通基盤対応で作成したものを更新 ※数量確定と併せて作成する為対象外とする | K17: =J17*Q17 -> 0 | Q17: 1.2
C18: 設計 | D18: アプリケーション関連 （FW関連） | E18: AP基盤 | F18: =ROUNDUP(K18,1) -> 0 | H18: アプリケーション関連設計書修正 ・共通 ⇒通信要件FW申請書の作成、設定を依頼 (AP基盤、DB基盤、バッチ基盤 × 2環境(検証・本番環境)) ※帳票基盤は利用していないため含めない ※縮小共通基盤対応で作成したものを更新 ※数量確定と併せて作成する為対象外とする | K18: =J18*Q18 -> 0 | P18: 160 | Q18: 1.2
C19: 設計 | D19: アプリケーション関連 （AP基盤、DB基盤、認証基盤関連） | E19: 共通 | F19: =ROUNDUP(K19,1) -> 1.1 | H19: アプリケーション関連設計書修正 ・AP基盤 ⇒AppServise、EntraIDの利用申請（検証環境・本番環境） ⇒エラー発生想定の28機能について画面、機能設計書の修正を想定 テスト仕様書作成 ⇒画面・機能一覧よりチェックシートを作成 以下については数量確定で対応するため工数に含めない ・認証基盤 ⇒認証機能に関する設計書を新規1本作成（工場系システム共通） ・DB基盤 ⇒A-AUTO用ジョブネット一覧、ジョブ構成図の2本修正 ※用役管理はオペマネジョブが存在しないため対象外 | I19: =M19*N19*O19/P19 -> 0.090625 | J19: 0.9 | K19: =J19*Q19 -> 1.08 | L19: AP基盤、認証基盤 0.75人月 ※29本対象。計算式参照 テスト仕様書 0.2人月 | M19: 29 | N19: 1 | O19: 0.5 | P19: 160 | Q19: 1.2
C20: 製造 | D20: アプリケーション構築 | E20: AP基盤 | F20: =ROUNDUP(K20,1) -> 0.5 | G20: =SUM(F20:F23) -> 1.5 | H20: ・修正ファイルに配備、疎通確認（検証）※リグレッションテストまでに準備 ・修正ファイルに配備、疎通確認（本番）※システムテストまでに準備 ※デプロイ手順の修正を含む ※本システムとしてリリース作業は必要になるため、数量確定工数の50%を作業想定工数とする | J20: 0.375 | K20: =J20*Q20 -> 0.45 | L20: 検証 0.25人月 検証 0.125人月 | Q20: 1.2
C21: 製造 | D21: AP基盤 | E21: AP基盤 | F21: =ROUNDUP(K21,1) -> 0.9 | H21: ・プログラム改修、ビルドファイル作成 １．エラー事項の対応 ２．ear⇒warファイルへのビルド手順変更 ３．EJBの対応 ４．IP、ホスト名、DB接続先(必要があれば)の変更 ※本システムとして修正は必要になるため、数量確定工数の50%を作業想定工数とする | J21: 0.7 | K21: =J21*Q21 -> 0.84 | L21: プログラム改修、ビルドファイル作成 0.7人月 内訳 １．エラー事項の対応 0.5人月 ２．ear⇒warファイルへのビルド手順変更 0.15人月 ３．EJBの対応 0.025人月 ４．IP、ホスト名、DB接続先(必要があれば)の変更 0.025人月 | Q21: 1.2
C22: 製造 | D22: 認証基盤 | E22: 認証基盤 | F22: =ROUNDUP(K22,1) -> 0.1 | H22: ・プログラム改修、ビルドファイル作成 ５，com0-lib2_4_0.jarファイル対応 | J22: 0.05 | K22: =J22*Q22 -> 0.06 | L22: プログラム改修、ビルドファイル作成 0.05人月 ５，com0-lib2_4_0.jarファイル対応 0.05人月 | Q22: 1.2
C23: 製造 | D23: バッチ基盤 | E23: バッチ基盤 | F23: 0 | H23: 特になし | K23: =J23*Q23 -> 0 | Q23: 1.2
C24: 結合テスト | D24: 結合テスト | E24: AP基盤 | F24: =ROUNDUP(K24,1) -> 2.9 | G24: =SUM(F24:F24) -> 2.9 | H24: システム内の全画面を確認し、初期画面の描画や正常系の動作に問題がないことを確認。 ・データベースの参照・登録 ・画面遷移 ・ボタン押下 等 機能数（画面＋帳票＋IF）=94 ※IFは疎通確認まで ※テスト工数削減案として、チェックリストによる動作確認までとし、エビデンスは異常が発生したパターンのみ採取する。品質担保としてユーザ様に協力をいただき、ユーザテストにて動作検証を手厚く実施をお願いする（作業工数50%削減を想定） | I24: =(T24*U24+V24*W24+X24*Y24+Z24*AA24)/P24 -> 2.4 | J24: 2.4 | K24: =J24*Q24 -> 2.88 | L24: 94機能 画面：6H 帳票：3H | M24: 94 | N24: 1 | O24: 4.5 | P24: 160 | Q24: 1.2 | S24: 45 | T24: 6 | U24: 49 | V24: 3 | W24: 3 | X24: 15 | Y24: 3 | Z24: 12 | AA24: 3
C25: 結合テスト | D25: 結合テスト | E25: 認証基盤 | F25: =ROUNDUP(K25,1) -> 0.2 | G25: =SUM(F25:F25) -> 0.2 | H25: EntraID認証でログインができることを確認。 ・工場系システム（用役管理） | J25: 0.1 | K25: =J25*Q25 -> 0.12 | L25: 工場系システム：0.1人月 | P25: 160 | Q25: 1.2
B26: 移行フェーズ | C26: システムテスト | D26: システムテスト | E26: バッチ基盤 | F26: =ROUNDUP(K26,1) -> 0 | G26: =SUM(F26:F26) -> 0 | H26: A-AUTO実行テスト DP課ご担当者による手動実行、作業立会い。エラー発生時の調査。 ※スケジュール実行対象ジョブ全量の確認を想定 ※用役管理はオペマネジョブが存在しないため対象外 | K26: =J26*Q26 -> 0 | L26: A-AUTO実行 0.2人月 | P26: 160 | Q26: 1.2
C27: システムテスト | D27: システムテスト 本番切り替えテスト | E27: 共通 | F27: =ROUNDUP(K27,1) -> 1.1 | G27: =SUM(F27:F27) -> 1.1 | H27: 他システムとの連携テスト(本番環境⇔他システム(本番)) SAP、PIMS（ヤード操業千葉・徳山）、オフラス（千葉） 他シスとのテスト調整 ※全確認ではなく代表1本 | J27: 0.9 | K27: =J27*Q27 -> 1.08 | L27: 他システムとの連携テスト 0.9人月 | P27: 160 | Q27: 1.2
C28: ユーザテスト | D28: ユーザテスト | E28: 共通 | F28: =ROUNDUP(K28,1) -> 0.8 | G28: =SUM(F28:F28) -> 0.8 | H28: ユーザテスト支援、問い合わせ対応、不具合指摘修正 ※ユーザテスト仕様書、計画書は含めない | J28: 0.75 | K28: =J28*Q28 -> 0.75 | L28: ユーザテスト支援、問い合わせ対応、不具合指摘修正：0.75 縮小共通基盤から変更なし | Q28: 1
C29: 本番稼働 | D29: アプリ移行 | E29: 共通 | F29: =ROUNDUP(K29,1) -> 1 | G29: =SUM(F29:F30) -> 2 | H29: 移行手順書作成＋出光内の移行方式レビュー支援 移行作業 ※ユーザテスト段階で環境構築は完了済み想定 ※現行環境の停止作業を実施 | J29: 1 | K29: =J29*Q29 -> 1 | L29: アプリ移行：1.0人月 縮小共通基盤から変更なし | Q29: 1
C30: 本番稼働 | D30: 初期流動 | E30: 共通 | F30: =ROUNDUP(K30,1) -> 1 | H30: 月末月初挟む0.5ヶ月×2名 | J30: 1 | K30: =J30*Q30 -> 1 | L30: 初期流動：1.0人月 縮小共通基盤から変更なし | Q30: 1
B31: 管理 | D31: 全体工数（各フェーズ合計） | F31: =ROUNDUP(SUM(G12:G30)*0.15,1) -> 1.7 | G31: =SUM(F31:F33) -> 2.6 | H31: 全体工数＊15%
C32: 管理 | D32: 定例会関連 | E32: 管理 | F32: =ROUNDUP(K32,1) -> 0.4 | H32: 定例会：(準備+実施＋議事録) | I32: =M32*N32*O32/P32 -> 0.375 | J32: =ROUNDUP(I32,1) -> 0.4 | K32: =J32*Q32 -> 0.4 | L32: 定例会：(準備+実施＋議事録)：3H 期間：4回/月・5ヵ月 | M32: 3 | N32: 4 | O32: 5 | P32: 160 | Q32: 1
C33: 管理 | D33: 工程完了レビュー関連 | E33: 管理 | F33: =ROUNDUP(K33,1) -> 0.5 | H33: 各工程完了レビュー：(準備+実施＋議事録)（要件定義～試験、PJ総括） | I33: =M33*N33*O33/P33 -> 0.5 | J33: 0.5 | K33: =J33*Q33 -> 0.5 | L33: 各工程完了レビュー：(準備+実施＋議事録)4H*5回 （要件定義～試験、PJ総括） | M33: 4 | N33: 5 | O33: 4 | P33: 160 | Q33: 1
C34: 合計 | G34: =SUM(G12:G33) -> 13.6 | L34: 縮小共通基盤：11.6人月
D37: 区分別 | E37: 工数 | F37: 管理工数(小数第2で繰り上げ) | G37: 小計 | H37: 調整工数
D38: 共通 | E38: =SUMIF($E$12:E33, D38, $F$12:F33) -> 5.2 | F38: =ROUNDUP(E38*0.15,1) -> 0.8 | G38: =SUM(E38:F38) -> 6
D39: AP基盤 | E39: =SUMIF($E$12:E34, D39, $F$12:F34) -> 5.3 | F39: =ROUNDUP(E39*0.15,1) -> 0.8 | G39: =SUM(E39:F39) -> 6.1
D40: 認証基盤 | E40: =SUMIF($E$12:E35, D40, $F$12:F35) -> 0.5 | F40: =ROUNDUP(E40*0.15,1) -> 0.1 | G40: =SUM(E40:F40) -> 0.6
D41: バッチ基盤 | E41: =SUMIF($E$12:E36, D41, $F$12:F36) -> 0 | F41: =ROUNDUP(E41*0.15,1) -> 0 | G41: =SUM(E41:F41) -> 0
D42: 管理 | F42: =SUMIF($E$12:F37, D42, $F$12:F37)+H42 -> 0.8 | G42: =SUM(E42:F42) -> 0.8 | H42: -0.1
F44: 合計 | G44: =SUM(G38:G42) -> 13.5
D47: 工程別 | E47: 工数 | F47: 管理工数(小数第2で繰り上げ) | G47: 小計 | H47: 調整工数
D48: 要件定義 | E48: =SUMIF($C$12:C43, D48, $F$12:F43) -> 1.4 | F48: =ROUNDUP(E48*0.15,1) -> 0.3 | G48: =SUM(E48:F48) -> 1.7
...

Sheet 見積（千葉化学品質管理システム）_明細（社内用）
B2: 前提条件
B3: 1 | C3: クラウドアーキ環境への移行を想定した作業見積をしています
B4: 2 | C4: 事前調査で一部検証をしておりますが、未確認および検討事項があるため、要件定義工程にて調査後に改めて開発フェーズ移行のお見積りをいたします。
B5: 3 | C5: 事前調査にて数量確定システムで検証したところ、エラー発生率が高い結果であったため、全画面のテスト(縮小共通基盤での結合テストと同等)の確認が必要
B6: 4 | C6: インフラ環境の構築作業は含まれていません。出光様にてご準備をいただくきます
B7: 5 | C7: データ移行の作業は含まれていません。出光様にてご準備をいただくきます
B10: 作業パターン： | C10: 作業パターン： | D10: クラウドアーキ基盤への移行 | F10: 端数処理のため、I列値を少数2桁目をROUNDUPしている | G10: 提示する場合は値のみ | L10: 作業用 | M10: 計算用 | Q10: レビュー工数 | T10: テスト用
B11: フェーズ | C11: 工程 | D11: タスク | E11: 区分 | F11: 作業詳細 | G11: 工数 | H11: 備考 | I11: 計算 | J11: 計 | K11: レビュー工数+バッファ （×1.2） | L11: 根拠補足 | M11: 機能数 | N11: 環境数 | O11: 生産性(１人当たりの作業時間) | P11: 人月換算 | Q11: レビュー工数係数 | T11: 画面数 | U11: 生産性 | V11: 帳票数 | W11: 生産性 | X11: バッチ数 | Y11: 生産性 | Z11: I/F数 | AA11: 生産性
B12: 要件定義フェーズ | C12: 要件定義 | D12: AP基盤 Oracle WebLogic ⇒ Azure App Service (PaaS) Apache Tomcat | E12: AP基盤 | F12: =ROUNDUP(K12,1) -> 0.6 | G12: =SUM(F12:F16) -> 1.7 | H12: 事前調査対応： ローカル環境にてWeblogicからTomcatへ変更して検証をした影響調査結果より正式な対応内容を精査する。 千葉化学品質管理 86機能 （物性LANは使用しなくなるため除外） ※事前調査の数量確定(千葉、徳山)にて、機能一覧の内40%程度のエラーが発生したため、同程度のエラー（35機能）が発生することを想定 １．エラー事項の対応 既知の数量確定で発生したエラーについて同様の対応で問題無いか確認する。 ※数量確定で検知しているエラーについては含めない ※本システムのみ発生する不具合を想定し、調査工数として計上する | I12: =M12*N12*O12/P12 -> 0.4375 | J12: 0.44 | K12: =J12*Q12 -> 0.528 | L12: エラー事項の対応 0.35人月 | M12: 35 | N12: 1 | O12: 2 | P12: 160 | Q12: 1.2
C13: 要件定義 | E13: AP基盤 | F13: =ROUNDUP(K13,1) -> 0.5 | H13: ２．ear⇒warファイルへのビルド手順変更 ・build.xmlの定義修正 ３．EJBの対応 ⇒ライブラリ追加、設定値変更 ４．クラウドアーキ環境の情報収集 ・サーバ情報の確認 ※本システムとしても同様対応が必要となるため、数量確定システムの50%工数で見積 | J13: 0.4 | K13: =J13*Q13 -> 0.48 | L13: ear⇒warファイルへのビルド手順変更 0.25人月 EJBの対応 0.05人月 クラウドアーキ環境の情報収集 0.1人月 | Q13: 1.2
C14: 要件定義 | D14: 認証基盤 認証AP：Oracle WebLogic ⇒Azure Entra ID | E14: 認証基盤 | F14: =ROUNDUP(K14,1) -> 0.2 | H14: 事前調査対応： ローカル環境にて認証用の共通ファイル（com0-lib2_4_0.jar）へ差し替え、ライブラリ内のクラス実行ができることまで確認済み。Azure Entra ID認証について検証をする。 工場系システム ・SSOからリンク呼び出し対応 以下については数量確定で検討するため工数に含めない ・ログインユーザ切り替え方法の検討。 ・SSOからの遷移時にエラーが発生した場合の画面制御 | J14: 0.1 | K14: =J14*Q14 -> 0.12 | L14: SSOからリンク呼び出し対応 0.1人月 | Q14: 1.2
C15: 要件定義 | D15: バッチ基盤 System Walker Operation Manager ⇒A-AUTO | E15: バッチ基盤 | F15: =ROUNDUP(K15,1) -> 0.2 | H15: 事前調査対応： 実施なし A-AUTO登録する為の情報提供、作業分担とスケジュールの認識合わせ ⇒DP課ご担当者とのA-AUTO移行に伴う課題や担当、スケジュールを確認する ※オペマネ⇒A-AUTOへのジョブ登録はDP課にて準備いただく ※A-AUTOから起動するスクリプトはDP課にて準備いただく ※実行ユーザ変更がある場合は設定ファイル、設定内容修正作業が追加で必要 | J15: 0.1 | K15: =J15*Q15 -> 0.12 | L15: DP課調整 0.1人月 | Q15: 1.2
C16: 要件定義 | D16: 次工程以降正式見積 | E16: 共通 | F16: =ROUNDUP(K16,1) -> 0.2 | H16: 調査結果資料作成、要件定義一覧作成、承認 開発フェーズ以降の見積書作成 | J16: 0.1 | K16: =J16*Q16 -> 0.12 | L16: 見積書作成（概算見積根拠を精査）：0.1 | Q16: 1.2
B17: 開発フェーズ | C17: 設計 | D17: 移行方式設計 | E17: 共通 | F17: =ROUNDUP(K17,1) -> 0 | G17: =SUM(F17:F19) -> 1.4 | H17: アプリ移行方式設計 その他連携基盤移行設計 移行計画書 テスト計画書（全体、結合、システムテスト） ※縮小共通基盤対応で作成したものを更新 ※数量確定と併せて作成する為対象外とする | K17: =J17*Q17 -> 0 | Q17: 1.2
C18: 設計 | D18: アプリケーション関連 （FW関連） | E18: AP基盤 | F18: =ROUNDUP(K18,1) -> 0 | H18: アプリケーション関連設計書修正 ・共通 ⇒通信要件FW申請書の作成、設定を依頼 (AP基盤、DB基盤、バッチ基盤 × 2環境(検証・本番環境)) ※帳票基盤は利用していないため含めない ※縮小共通基盤対応で作成したものを更新 ※数量確定と併せて作成する為対象外とする | K18: =J18*Q18 -> 0 | P18: 160 | Q18: 1.2
