Workbook
Name PJ番号: #REF!
Name PJ番号: #REF!
Name PJ番号: #REF!
Name ＰＪ表紙名: #REF!
Name ＰＪ表紙名: #REF!
Name ＰＪ表紙名: #REF!
Name ＰＭ名: [1]プロジェクト実施計画書!$G$7
Name プロジェクトコード: [2]!プロジェクト情報[見積番号]
Name プロジェクトコード: [2]!プロジェクト情報[見積番号]
Name プロジェクトコード: '[3]プロジェクト報告書（3.3版）'!$L$9
Name プロジェクト名: [2]!プロジェクト情報[プロジェクト名]
Name プロジェクト名: [2]!プロジェクト情報[プロジェクト名]
Name プロジェクト名: '[3]プロジェクト報告書（3.3版）'!$L$10
Name プロジェクト名称: #REF!
Name プロジェクト名称: #REF!
Name プロジェクト名称: #REF!
Name 月: #REF!
Name 月: #REF!
Name 月: #REF!
Name 検収完了日: '[3]プロジェクト報告書（3.3版）'!$AI$21
Name 顧客コード: #REF!
Name 顧客コード: #REF!
Name 顧客コード: #REF!
Name 顧客満足度調査の依頼先担当者メールアドレス: '[3]プロジェクト報告書（3.3版）'!$AI$48
Name 顧客満足度調査の依頼先担当者名: '[3]プロジェクト報告書（3.3版）'!$L$48
Name 顧客名: '[3]プロジェクト報告書（3.3版）'!$L$13
Name 顧客名称: #REF!
Name 顧客名称: #REF!
Name 顧客名称: #REF!
Name 作成者: #REF!
Name 作成者: #REF!
Name 作成者: #REF!
Name 主管部門: #REF!
Name 主管部門: #REF!
Name 主管部門: #REF!
Name 受注額: [2]!プロジェクト情報[受注額]
Name 所属: [2]!担当者情報[所属]
Name 担当者名: [2]!担当者情報[担当者]
Name 日: #REF!
Name 日: #REF!
Name 日: #REF!
Name 年: #REF!
Name 年: #REF!
Name 年: #REF!
Name 部門名: #REF!
Name 部門名: #REF!
Name 部門名: #REF!

Sheet 運転管理(パターン１)
A1: 要員配置計画（運転管理制御システム通信サーバ更新：パターン１）
B2: TOPへ
B3: 受注金額 | C3: 10850000
B4: 売上計上額 | C4: =E13 -> 10150000
B5: 原価金額 | C5: =E14 -> 5220000
B6: 粗利額 | C6: =C3-C5 -> 5630000
B7: 粗利率 | C7: =IF(C3=0,0,C6/C3) -> 0.51889401
F9: 2026年 | BB9: 2027年 | CX9: 2028年
F10: 1Q | R10: 2Q | AD10: 3Q | AP10: 4Q | BB10: 1Q | BN10: 2Q | BZ10: 3Q | CL10: 4Q | CX10: 1Q | DJ10: 2Q | DV10: 3Q | EH10: 4Q
F11: 45017 | J11: 45047 | N11: 45078 | R11: 45108 | V11: 45139 | Z11: 45170 | AD11: 45200 | AH11: 45231 | AL11: 45261 | AP11: 45292 | AT11: 45323 | AX11: 45352 | BB11: 45383 | BF11: 45413 | BJ11: 45444 | BN11: 45474 | BR11: 45505 | BV11: 45536 | BZ11: 45566 | CD11: 45597 | CH11: 45627 | CL11: 45658 | CP11: 45689 | CT11: 45717 | CX11: 45383 | DB11: 45413 | DF11: 45444 | DJ11: 45474 | DN11: 45505 | DR11: 45536 | DV11: 45566 | DZ11: 45597 | ED11: 45627 | EH11: 45658 | EL11: 45689 | EP11: 45717
B12: 総合計 | D12: 工数 | E12: =SUM(F12:ES12) -> 9 | F12: =F57+F116 -> 0 | J12: =J57+J116 -> 0 | N12: =N57+N116 -> 0 | R12: =R57+R116 -> 0 | V12: =V57+V116 -> 0 | Z12: =Z57+Z116 -> 0 | AD12: =AD57+AD116 -> 0 | AH12: =AH57+AH116 -> 0 | AL12: =AL57+AL116 -> 0 | AP12: =AP57+AP116 -> 0 | AT12: =AT57+AT116 -> 0 | AX12: =AX57+AX116 -> 0 | BB12: =BB57+BB116 -> 0 | BF12: =BF57+BF116 -> 0 | BJ12: =BJ57+BJ116 -> 0 | BN12: =BN57+BN116 -> 0 | BR12: =BR57+BR116 -> 0 | BV12: =BV57+BV116 -> 1.25 | BZ12: =BZ57+BZ116 -> 3.25 | CD12: =CD57+CD116 -> 3.25 | CH12: =CH57+CH116 -> 1.25 | CL12: =CL57+CL116 -> 0 | CP12: =CP57+CP116 -> 0 | CT12: =CT57+CT116 -> 0 | CX12: =CX57+CX116 -> 0 | DB12: =DB57+DB116 -> 0 | DF12: =DF57+DF116 -> 0 | DJ12: =DJ57+DJ116 -> 0 | DN12: =DN57+DN116 -> 0 | DR12: =DR57+DR116 -> 0 | DV12: =DV57+DV116 -> 0 | DZ12: =DZ57+DZ116 -> 0 | ED12: =ED57+ED116 -> 0 | EH12: =EH57+EH116 -> 0 | EL12: =EL57+EL116 -> 0 | EP12: =EP57+EP116 -> 0
D13: 売上金額 | E13: =SUM(F13:ES13) -> 10150000 | F13: =F58+F117 -> 0 | J13: =J58+J117 -> 0 | N13: =N58+N117 -> 0 | R13: =R58+R117 -> 0 | V13: =V58+V117 -> 0 | Z13: =Z58+Z117 -> 0 | AD13: =AD58+AD117 -> 0 | AH13: =AH58+AH117 -> 0 | AL13: =AL58+AL117 -> 0 | AP13: =AP58+AP117 -> 0 | AT13: =AT58+AT117 -> 0 | AX13: =AX58+AX117 -> 0 | BB13: =BB58+BB117 -> 0 | BF13: =BF58+BF117 -> 0 | BJ13: =BJ58+BJ117 -> 0 | BN13: =BN58+BN117 -> 0 | BR13: =BR58+BR117 -> 0 | BV13: =BV58+BV117 -> 1487500 | BZ13: =BZ58+BZ117 -> 3587500 | CD13: =CD58+CD117 -> 3587500 | CH13: =CH58+CH117 -> 1487500 | CL13: =CL58+CL117 -> 0 | CP13: =CP58+CP117 -> 0 | CT13: =CT58+CT117 -> 0 | CX13: =CX58+CX117 -> 0 | DB13: =DB58+DB117 -> 0 | DF13: =DF58+DF117 -> 0 | DJ13: =DJ58+DJ117 -> 0 | DN13: =DN58+DN117 -> 0 | DR13: =DR58+DR117 -> 0 | DV13: =DV58+DV117 -> 0 | DZ13: =DZ58+DZ117 -> 0 | ED13: =ED58+ED117 -> 0 | EH13: =EH58+EH117 -> 0 | EL13: =EL58+EL117 -> 0 | EP13: =EP58+EP117 -> 0
D14: 原価金額 | E14: =SUM(F14:ES14) -> 5220000 | F14: =F59+F118 -> 0 | J14: =J59+J118 -> 0 | N14: =N59+N118 -> 0 | R14: =R59+R118 -> 0 | V14: =V59+V118 -> 0 | Z14: =Z59+Z118 -> 0 | AD14: =AD59+AD118 -> 0 | AH14: =AH59+AH118 -> 0 | AL14: =AL59+AL118 -> 0 | AP14: =AP59+AP118 -> 0 | AT14: =AT59+AT118 -> 0 | AX14: =AX59+AX118 -> 0 | BB14: =BB59+BB118 -> 0 | BF14: =BF59+BF118 -> 0 | BJ14: =BJ59+BJ118 -> 0 | BN14: =BN59+BN118 -> 0 | BR14: =BR59+BR118 -> 0 | BV14: =BV59+BV118 -> 805000 | BZ14: =BZ59+BZ118 -> 1805000 | CD14: =CD59+CD118 -> 1805000 | CH14: =CH59+CH118 -> 805000 | CL14: =CL59+CL118 -> 0 | CP14: =CP59+CP118 -> 0 | CT14: =CT59+CT118 -> 0 | CX14: =CX59+CX118 -> 0 | DB14: =DB59+DB118 -> 0 | DF14: =DF59+DF118 -> 0 | DJ14: =DJ59+DJ118 -> 0 | DN14: =DN59+DN118 -> 0 | DR14: =DR59+DR118 -> 0 | DV14: =DV59+DV118 -> 0 | DZ14: =DZ59+DZ118 -> 0 | ED14: =ED59+ED118 -> 0 | EH14: =EH59+EH118 -> 0 | EL14: =EL59+EL118 -> 0 | EP14: =EP59+EP118 -> 0
D15: 粗利額 | E15: =SUM(F15:ES15) -> 4930000 | F15: =F13-F14 -> 0 | J15: =J13-J14 -> 0 | N15: =N13-N14 -> 0 | R15: =R13-R14 -> 0 | V15: =V13-V14 -> 0 | Z15: =Z13-Z14 -> 0 | AD15: =AD13-AD14 -> 0 | AH15: =AH13-AH14 -> 0 | AL15: =AL13-AL14 -> 0 | AP15: =AP13-AP14 -> 0 | AT15: =AT13-AT14 -> 0 | AX15: =AX13-AX14 -> 0 | BB15: =BB13-BB14 -> 0 | BF15: =BF13-BF14 -> 0 | BJ15: =BJ13-BJ14 -> 0 | BN15: =BN13-BN14 -> 0 | BR15: =BR13-BR14 -> 0 | BV15: =BV13-BV14 -> 682500 | BZ15: =BZ13-BZ14 -> 1782500 | CD15: =CD13-CD14 -> 1782500 | CH15: =CH13-CH14 -> 682500 | CL15: =CL13-CL14 -> 0 | CP15: =CP13-CP14 -> 0 | CT15: =CT13-CT14 -> 0 | CX15: =CX13-CX14 -> 0 | DB15: =DB13-DB14 -> 0 | DF15: =DF13-DF14 -> 0 | DJ15: =DJ13-DJ14 -> 0 | DN15: =DN13-DN14 -> 0 | DR15: =DR13-DR14 -> 0 | DV15: =DV13-DV14 -> 0 | DZ15: =DZ13-DZ14 -> 0 | ED15: =ED13-ED14 -> 0 | EH15: =EH13-EH14 -> 0 | EL15: =EL13-EL14 -> 0 | EP15: =EP13-EP14 -> 0
A17: 【社員・契約社員】 | C17: ※必要に応じて修正すること。
B18: 要員名 | C18: 月額単価 | D18: 内訳 | E18: 合計 | F18: 2026年 | BB18: 2027年 | CX18: 2028年
F19: 1Q | R19: 2Q | AD19: 3Q | AP19: 4Q | BB19: 1Q | BN19: 2Q | BZ19: 3Q | CL19: 4Q | CX19: 1Q | DJ19: 2Q | DV19: 3Q | EH19: 4Q
C20: (上段:売上、下段:原価) | F20: 45017 | J20: 45047 | N20: 45078 | R20: 45108 | V20: 45139 | Z20: 45170 | AD20: 45200 | AH20: 45231 | AL20: 45261 | AP20: 45292 | AT20: 45323 | AX20: 45352 | BB20: 45383 | BF20: 45413 | BJ20: 45444 | BN20: 45474 | BR20: 45505 | BV20: 45536 | BZ20: 45566 | CD20: 45597 | CH20: 45627 | CL20: 45658 | CP20: 45689 | CT20: 45717 | CX20: 45383 | DB20: 45413 | DF20: 45444 | DJ20: 45474 | DN20: 45505 | DR20: 45536 | DV20: 45566 | DZ20: 45597 | ED20: 45627 | EH20: 45658 | EL20: 45689 | EP20: 45717
B21: 福田 | D21: 工数 | E21: =SUM(F21:ES21) -> 2 | BV21: 0.5 | BZ21: 0.5 | CD21: 0.5 | CH21: 0.5
C22: 1400000 | D22: 売上金額 | E22: =SUM(F22:CW22) -> 2800000 | F22: =IFERROR($C22*F21,"") -> 0 | J22: =IFERROR($C22*J21,"") -> 0 | N22: =IFERROR($C22*N21,"") -> 0 | R22: =IFERROR($C22*R21,"") -> 0 | V22: =IFERROR($C22*V21,"") -> 0 | Z22: =IFERROR($C22*Z21,"") -> 0 | AD22: =IFERROR($C22*AD21,"") -> 0 | AH22: =IFERROR($C22*AH21,"") -> 0 | AL22: =IFERROR($C22*AL21,"") -> 0 | AP22: =IFERROR($C22*AP21,"") -> 0 | AT22: =IFERROR($C22*AT21,"") -> 0 | AX22: =IFERROR($C22*AX21,"") -> 0 | BB22: =IFERROR($C22*BB21,"") -> 0 | BF22: =IFERROR($C22*BF21,"") -> 0 | BJ22: =IFERROR($C22*BJ21,"") -> 0 | BN22: =IFERROR($C22*BN21,"") -> 0 | BR22: =IFERROR($C22*BR21,"") -> 0 | BV22: =IFERROR($C22*BV21,"") -> 700000 | BZ22: =IFERROR($C22*BZ21,"") -> 700000 | CD22: =IFERROR($C22*CD21,"") -> 700000 | CH22: =IFERROR($C22*CH21,"") -> 700000 | CL22: =IFERROR($C22*CL21,"") -> 0 | CP22: =IFERROR($C22*CP21,"") -> 0 | CT22: =IFERROR($C22*CT21,"") -> 0 | CX22: =IFERROR($C22*CX21,"") -> 0 | DB22: =IFERROR($C22*DB21,"") -> 0 | DF22: =IFERROR($C22*DF21,"") -> 0 | DJ22: =IFERROR($C22*DJ21,"") -> 0 | DN22: =IFERROR($C22*DN21,"") -> 0 | DR22: =IFERROR($C22*DR21,"") -> 0 | DV22: =IFERROR($C22*DV21,"") -> 0 | DZ22: =IFERROR($C22*DZ21,"") -> 0 | ED22: =IFERROR($C22*ED21,"") -> 0 | EH22: =IFERROR($C22*EH21,"") -> 0 | EL22: =IFERROR($C22*EL21,"") -> 0 | EP22: =IFERROR($C22*EP21,"") -> 0
C23: 600000 | D23: 原価金額 | E23: =SUM(F23:CW23) -> 1200000 | F23: =IFERROR($C23*F21,"") -> 0 | J23: =IFERROR($C23*J21,"") -> 0 | N23: =IFERROR($C23*N21,"") -> 0 | R23: =IFERROR($C23*R21,"") -> 0 | V23: =IFERROR($C23*V21,"") -> 0 | Z23: =IFERROR($C23*Z21,"") -> 0 | AD23: =IFERROR($C23*AD21,"") -> 0 | AH23: =IFERROR($C23*AH21,"") -> 0 | AL23: =IFERROR($C23*AL21,"") -> 0 | AP23: =IFERROR($C23*AP21,"") -> 0 | AT23: =IFERROR($C23*AT21,"") -> 0 | AX23: =IFERROR($C23*AX21,"") -> 0 | BB23: =IFERROR($C23*BB21,"") -> 0 | BF23: =IFERROR($C23*BF21,"") -> 0 | BJ23: =IFERROR($C23*BJ21,"") -> 0 | BN23: =IFERROR($C23*BN21,"") -> 0 | BR23: =IFERROR($C23*BR21,"") -> 0 | BV23: =IFERROR($C23*BV21,"") -> 300000 | BZ23: =IFERROR($C23*BZ21,"") -> 300000 | CD23: =IFERROR($C23*CD21,"") -> 300000 | CH23: =IFERROR($C23*CH21,"") -> 300000 | CL23: =IFERROR($C23*CL21,"") -> 0 | CP23: =IFERROR($C23*CP21,"") -> 0 | CT23: =IFERROR($C23*CT21,"") -> 0 | CX23: =IFERROR($C23*CX21,"") -> 0 | DB23: =IFERROR($C23*DB21,"") -> 0 | DF23: =IFERROR($C23*DF21,"") -> 0 | DJ23: =IFERROR($C23*DJ21,"") -> 0 | DN23: =IFERROR($C23*DN21,"") -> 0 | DR23: =IFERROR($C23*DR21,"") -> 0 | DV23: =IFERROR($C23*DV21,"") -> 0 | DZ23: =IFERROR($C23*DZ21,"") -> 0 | ED23: =IFERROR($C23*ED21,"") -> 0 | EH23: =IFERROR($C23*EH21,"") -> 0 | EL23: =IFERROR($C23*EL21,"") -> 0 | EP23: =IFERROR($C23*EP21,"") -> 0
B24: A | D24: 工数 | E24: =SUM(F24:ES24) -> 2 | BZ24: 1 | CD24: 1
C25: 1050000 | D25: 売上金額 | E25: =SUM(F25:CW25) -> 2100000 | F25: =IFERROR($C25*F24,"") -> 0 | J25: =IFERROR($C25*J24,"") -> 0 | N25: =IFERROR($C25*N24,"") -> 0 | R25: =IFERROR($C25*R24,"") -> 0 | V25: =IFERROR($C25*V24,"") -> 0 | Z25: =IFERROR($C25*Z24,"") -> 0 | AD25: =IFERROR($C25*AD24,"") -> 0 | AH25: =IFERROR($C25*AH24,"") -> 0 | AL25: =IFERROR($C25*AL24,"") -> 0 | AP25: =IFERROR($C25*AP24,"") -> 0 | AT25: =IFERROR($C25*AT24,"") -> 0 | AX25: =IFERROR($C25*AX24,"") -> 0 | BB25: =IFERROR($C25*BB24,"") -> 0 | BF25: =IFERROR($C25*BF24,"") -> 0 | BJ25: =IFERROR($C25*BJ24,"") -> 0 | BN25: =IFERROR($C25*BN24,"") -> 0 | BR25: =IFERROR($C25*BR24,"") -> 0 | BV25: =IFERROR($C25*BV24,"") -> 0 | BZ25: =IFERROR($C25*BZ24,"") -> 1050000 | CD25: =IFERROR($C25*CD24,"") -> 1050000 | CH25: =IFERROR($C25*CH24,"") -> 0 | CL25: =IFERROR($C25*CL24,"") -> 0 | CP25: =IFERROR($C25*CP24,"") -> 0 | CT25: =IFERROR($C25*CT24,"") -> 0 | CX25: =IFERROR($C25*CX24,"") -> 0 | DB25: =IFERROR($C25*DB24,"") -> 0 | DF25: =IFERROR($C25*DF24,"") -> 0 | DJ25: =IFERROR($C25*DJ24,"") -> 0 | DN25: =IFERROR($C25*DN24,"") -> 0 | DR25: =IFERROR($C25*DR24,"") -> 0 | DV25: =IFERROR($C25*DV24,"") -> 0 | DZ25: =IFERROR($C25*DZ24,"") -> 0 | ED25: =IFERROR($C25*ED24,"") -> 0 | EH25: =IFERROR($C25*EH24,"") -> 0 | EL25: =IFERROR($C25*EL24,"") -> 0 | EP25: =IFERROR($C25*EP24,"") -> 0
C26: 500000 | D26: 原価金額 | E26: =SUM(F26:CW26) -> 1000000 | F26: =IFERROR($C26*F24,"") -> 0 | J26: =IFERROR($C26*J24,"") -> 0 | N26: =IFERROR($C26*N24,"") -> 0 | R26: =IFERROR($C26*R24,"") -> 0 | V26: =IFERROR($C26*V24,"") -> 0 | Z26: =IFERROR($C26*Z24,"") -> 0 | AD26: =IFERROR($C26*AD24,"") -> 0 | AH26: =IFERROR($C26*AH24,"") -> 0 | AL26: =IFERROR($C26*AL24,"") -> 0 | AP26: =IFERROR($C26*AP24,"") -> 0 | AT26: =IFERROR($C26*AT24,"") -> 0 | AX26: =IFERROR($C26*AX24,"") -> 0 | BB26: =IFERROR($C26*BB24,"") -> 0 | BF26: =IFERROR($C26*BF24,"") -> 0 | BJ26: =IFERROR($C26*BJ24,"") -> 0 | BN26: =IFERROR($C26*BN24,"") -> 0 | BR26: =IFERROR($C26*BR24,"") -> 0 | BV26: =IFERROR($C26*BV24,"") -> 0 | BZ26: =IFERROR($C26*BZ24,"") -> 500000 | CD26: =IFERROR($C26*CD24,"") -> 500000 | CH26: =IFERROR($C26*CH24,"") -> 0 | CL26: =IFERROR($C26*CL24,"") -> 0 | CP26: =IFERROR($C26*CP24,"") -> 0 | CT26: =IFERROR($C26*CT24,"") -> 0 | CX26: =IFERROR($C26*CX24,"") -> 0 | DB26: =IFERROR($C26*DB24,"") -> 0 | DF26: =IFERROR($C26*DF24,"") -> 0 | DJ26: =IFERROR($C26*DJ24,"") -> 0 | DN26: =IFERROR($C26*DN24,"") -> 0 | DR26: =IFERROR($C26*DR24,"") -> 0 | DV26: =IFERROR($C26*DV24,"") -> 0 | DZ26: =IFERROR($C26*DZ24,"") -> 0 | ED26: =IFERROR($C26*ED24,"") -> 0 | EH26: =IFERROR($C26*EH24,"") -> 0 | EL26: =IFERROR($C26*EL24,"") -> 0 | EP26: =IFERROR($C26*EP24,"") -> 0
B27: B | D27: 工数 | E27: =SUM(F27:ES27) -> 2 | BZ27: 1 | CD27: 1
C28: 1050000 | D28: 売上金額 | E28: =SUM(F28:CW28) -> 2100000 | F28: =IFERROR($C28*F27,"") -> 0 | J28: =IFERROR($C28*J27,"") -> 0 | N28: =IFERROR($C28*N27,"") -> 0 | R28: =IFERROR($C28*R27,"") -> 0 | V28: =IFERROR($C28*V27,"") -> 0 | Z28: =IFERROR($C28*Z27,"") -> 0 | AD28: =IFERROR($C28*AD27,"") -> 0 | AH28: =IFERROR($C28*AH27,"") -> 0 | AL28: =IFERROR($C28*AL27,"") -> 0 | AP28: =IFERROR($C28*AP27,"") -> 0 | AT28: =IFERROR($C28*AT27,"") -> 0 | AX28: =IFERROR($C28*AX27,"") -> 0 | BB28: =IFERROR($C28*BB27,"") -> 0 | BF28: =IFERROR($C28*BF27,"") -> 0 | BJ28: =IFERROR($C28*BJ27,"") -> 0 | BN28: =IFERROR($C28*BN27,"") -> 0 | BR28: =IFERROR($C28*BR27,"") -> 0 | BV28: =IFERROR($C28*BV27,"") -> 0 | BZ28: =IFERROR($C28*BZ27,"") -> 1050000 | CD28: =IFERROR($C28*CD27,"") -> 1050000 | CH28: =IFERROR($C28*CH27,"") -> 0 | CL28: =IFERROR($C28*CL27,"") -> 0 | CP28: =IFERROR($C28*CP27,"") -> 0 | CT28: =IFERROR($C28*CT27,"") -> 0 | CX28: =IFERROR($C28*CX27,"") -> 0 | DB28: =IFERROR($C28*DB27,"") -> 0 | DF28: =IFERROR($C28*DF27,"") -> 0 | DJ28: =IFERROR($C28*DJ27,"") -> 0 | DN28: =IFERROR($C28*DN27,"") -> 0 | DR28: =IFERROR($C28*DR27,"") -> 0 | DV28: =IFERROR($C28*DV27,"") -> 0 | DZ28: =IFERROR($C28*DZ27,"") -> 0 | ED28: =IFERROR($C28*ED27,"") -> 0 | EH28: =IFERROR($C28*EH27,"") -> 0 | EL28: =IFERROR($C28*EL27,"") -> 0 | EP28: =IFERROR($C28*EP27,"") -> 0
C29: 500000 | D29: 原価金額 | E29: =SUM(F29:CW29) -> 1000000 | F29: =IFERROR($C29*F27,"") -> 0 | J29: =IFERROR($C29*J27,"") -> 0 | N29: =IFERROR($C29*N27,"") -> 0 | R29: =IFERROR($C29*R27,"") -> 0 | V29: =IFERROR($C29*V27,"") -> 0 | Z29: =IFERROR($C29*Z27,"") -> 0 | AD29: =IFERROR($C29*AD27,"") -> 0 | AH29: =IFERROR($C29*AH27,"") -> 0 | AL29: =IFERROR($C29*AL27,"") -> 0 | AP29: =IFERROR($C29*AP27,"") -> 0 | AT29: =IFERROR($C29*AT27,"") -> 0 | AX29: =IFERROR($C29*AX27,"") -> 0 | BB29: =IFERROR($C29*BB27,"") -> 0 | BF29: =IFERROR($C29*BF27,"") -> 0 | BJ29: =IFERROR($C29*BJ27,"") -> 0 | BN29: =IFERROR($C29*BN27,"") -> 0 | BR29: =IFERROR($C29*BR27,"") -> 0 | BV29: =IFERROR($C29*BV27,"") -> 0 | BZ29: =IFERROR($C29*BZ27,"") -> 500000 | CD29: =IFERROR($C29*CD27,"") -> 500000 | CH29: =IFERROR($C29*CH27,"") -> 0 | CL29: =IFERROR($C29*CL27,"") -> 0 | CP29: =IFERROR($C29*CP27,"") -> 0 | CT29: =IFERROR($C29*CT27,"") -> 0 | CX29: =IFERROR($C29*CX27,"") -> 0 | DB29: =IFERROR($C29*DB27,"") -> 0 | DF29: =IFERROR($C29*DF27,"") -> 0 | DJ29: =IFERROR($C29*DJ27,"") -> 0 | DN29: =IFERROR($C29*DN27,"") -> 0 | DR29: =IFERROR($C29*DR27,"") -> 0 | DV29: =IFERROR($C29*DV27,"") -> 0 | DZ29: =IFERROR($C29*DZ27,"") -> 0 | ED29: =IFERROR($C29*ED27,"") -> 0 | EH29: =IFERROR($C29*EH27,"") -> 0 | EL29: =IFERROR($C29*EL27,"") -> 0 | EP29: =IFERROR($C29*EP27,"") -> 0
B30: ブリッジ | D30: 工数 | E30: =SUM(F30:ES30) -> 0
C31: 1000000 | D31: 売上金額 | E31: =SUM(F31:CW31) -> 0 | F31: =IFERROR($C31*F30,"") -> 0 | J31: =IFERROR($C31*J30,"") -> 0 | N31: =IFERROR($C31*N30,"") -> 0 | R31: =IFERROR($C31*R30,"") -> 0 | V31: =IFERROR($C31*V30,"") -> 0 | Z31: =IFERROR($C31*Z30,"") -> 0 | AD31: =IFERROR($C31*AD30,"") -> 0 | AH31: =IFERROR($C31*AH30,"") -> 0 | AL31: =IFERROR($C31*AL30,"") -> 0 | AP31: =IFERROR($C31*AP30,"") -> 0 | AT31: =IFERROR($C31*AT30,"") -> 0 | AX31: =IFERROR($C31*AX30,"") -> 0 | BB31: =IFERROR($C31*BB30,"") -> 0 | BF31: =IFERROR($C31*BF30,"") -> 0 | BJ31: =IFERROR($C31*BJ30,"") -> 0 | BN31: =IFERROR($C31*BN30,"") -> 0 | BR31: =IFERROR($C31*BR30,"") -> 0 | BV31: =IFERROR($C31*BV30,"") -> 0 | BZ31: =IFERROR($C31*BZ30,"") -> 0 | CD31: =IFERROR($C31*CD30,"") -> 0 | CH31: =IFERROR($C31*CH30,"") -> 0 | CL31: =IFERROR($C31*CL30,"") -> 0 | CP31: =IFERROR($C31*CP30,"") -> 0 | CT31: =IFERROR($C31*CT30,"") -> 0 | CX31: =IFERROR($C31*CX30,"") -> 0 | DB31: =IFERROR($C31*DB30,"") -> 0 | DF31: =IFERROR($C31*DF30,"") -> 0 | DJ31: =IFERROR($C31*DJ30,"") -> 0 | DN31: =IFERROR($C31*DN30,"") -> 0 | DR31: =IFERROR($C31*DR30,"") -> 0 | DV31: =IFERROR($C31*DV30,"") -> 0 | DZ31: =IFERROR($C31*DZ30,"") -> 0 | ED31: =IFERROR($C31*ED30,"") -> 0 | EH31: =IFERROR($C31*EH30,"") -> 0 | EL31: =IFERROR($C31*EL30,"") -> 0 | EP31: =IFERROR($C31*EP30,"") -> 0
C32: 420000 | D32: 原価金額 | E32: =SUM(F32:CW32) -> 0 | F32: =IFERROR($C32*F30,"") -> 0 | J32: =IFERROR($C32*J30,"") -> 0 | N32: =IFERROR($C32*N30,"") -> 0 | R32: =IFERROR($C32*R30,"") -> 0 | V32: =IFERROR($C32*V30,"") -> 0 | Z32: =IFERROR($C32*Z30,"") -> 0 | AD32: =IFERROR($C32*AD30,"") -> 0 | AH32: =IFERROR($C32*AH30,"") -> 0 | AL32: =IFERROR($C32*AL30,"") -> 0 | AP32: =IFERROR($C32*AP30,"") -> 0 | AT32: =IFERROR($C32*AT30,"") -> 0 | AX32: =IFERROR($C32*AX30,"") -> 0 | BB32: =IFERROR($C32*BB30,"") -> 0 | BF32: =IFERROR($C32*BF30,"") -> 0 | BJ32: =IFERROR($C32*BJ30,"") -> 0 | BN32: =IFERROR($C32*BN30,"") -> 0 | BR32: =IFERROR($C32*BR30,"") -> 0 | BV32: =IFERROR($C32*BV30,"") -> 0 | BZ32: =IFERROR($C32*BZ30,"") -> 0 | CD32: =IFERROR($C32*CD30,"") -> 0 | CH32: =IFERROR($C32*CH30,"") -> 0 | CL32: =IFERROR($C32*CL30,"") -> 0 | CP32: =IFERROR($C32*CP30,"") -> 0 | CT32: =IFERROR($C32*CT30,"") -> 0 | CX32: =IFERROR($C32*CX30,"") -> 0 | DB32: =IFERROR($C32*DB30,"") -> 0 | DF32: =IFERROR($C32*DF30,"") -> 0 | DJ32: =IFERROR($C32*DJ30,"") -> 0 | DN32: =IFERROR($C32*DN30,"") -> 0 | DR32: =IFERROR($C32*DR30,"") -> 0 | DV32: =IFERROR($C32*DV30,"") -> 0 | DZ32: =IFERROR($C32*DZ30,"") -> 0 | ED32: =IFERROR($C32*ED30,"") -> 0 | EH32: =IFERROR($C32*EH30,"") -> 0 | EL32: =IFERROR($C32*EL30,"") -> 0 | EP32: =IFERROR($C32*EP30,"") -> 0
B33: B | D33: 工数 | E33: =SUM(F33:ES33) -> 0
C34: 1000000 | D34: 売上金額 | E34: =SUM(F34:CW34) -> 0 | F34: =IFERROR($C34*F33,"") -> 0 | J34: =IFERROR($C34*J33,"") -> 0 | N34: =IFERROR($C34*N33,"") -> 0 | R34: =IFERROR($C34*R33,"") -> 0 | V34: =IFERROR($C34*V33,"") -> 0 | Z34: =IFERROR($C34*Z33,"") -> 0 | AD34: =IFERROR($C34*AD33,"") -> 0 | DR34: =IFERROR($C34*DR33,"") -> 0 | DV34: =IFERROR($C34*DV33,"") -> 0 | DZ34: =IFERROR($C34*DZ33,"") -> 0 | ED34: =IFERROR($C34*ED33,"") -> 0 | EH34: =IFERROR($C34*EH33,"") -> 0 | EL34: =IFERROR($C34*EL33,"") -> 0 | EP34: =IFERROR($C34*EP33,"") -> 0
C35: 420000 | D35: 原価金額 | E35: =SUM(F35:CW35) -> 0 | F35: =IFERROR($C35*F33,"") -> 0 | J35: =IFERROR($C35*J33,"") -> 0 | N35: =IFERROR($C35*N33,"") -> 0 | R35: =IFERROR($C35*R33,"") -> 0 | V35: =IFERROR($C35*V33,"") -> 0 | Z35: =IFERROR($C35*Z33,"") -> 0 | AD35: =IFERROR($C35*AD33,"") -> 0 | DR35: =IFERROR($C35*DR33,"") -> 0 | DV35: =IFERROR($C35*DV33,"") -> 0 | DZ35: =IFERROR($C35*DZ33,"") -> 0 | ED35: =IFERROR($C35*ED33,"") -> 0 | EH35: =IFERROR($C35*EH33,"") -> 0 | EL35: =IFERROR($C35*EL33,"") -> 0 | EP35: =IFERROR($C35*EP33,"") -> 0
B36: C | D36: 工数 | E36: =SUM(F36:ES36) -> 0
C37: 1000000 | D37: 売上金額 | E37: =SUM(F37:CW37) -> 0 | F37: =IFERROR($C37*F36,"") -> 0 | J37: =IFERROR($C37*J36,"") -> 0 | N37: =IFERROR($C37*N36,"") -> 0 | R37: =IFERROR($C37*R36,"") -> 0 | V37: =IFERROR($C37*V36,"") -> 0 | Z37: =IFERROR($C37*Z36,"") -> 0 | AD37: =IFERROR($C37*AD36,"") -> 0 | DR37: =IFERROR($C37*DR36,"") -> 0 | DV37: =IFERROR($C37*DV36,"") -> 0 | DZ37: =IFERROR($C37*DZ36,"") -> 0 | ED37: =IFERROR($C37*ED36,"") -> 0 | EH37: =IFERROR($C37*EH36,"") -> 0 | EL37: =IFERROR($C37*EL36,"") -> 0 | EP37: =IFERROR($C37*EP36,"") -> 0
C38: 420000 | D38: 原価金額 | E38: =SUM(F38:CW38) -> 0 | F38: =IFERROR($C38*F36,"") -> 0 | J38: =IFERROR($C38*J36,"") -> 0 | N38: =IFERROR($C38*N36,"") -> 0 | R38: =IFERROR($C38*R36,"") -> 0 | V38: =IFERROR($C38*V36,"") -> 0 | Z38: =IFERROR($C38*Z36,"") -> 0 | AD38: =IFERROR($C38*AD36,"") -> 0 | DR38: =IFERROR($C38*DR36,"") -> 0 | DV38: =IFERROR($C38*DV36,"") -> 0 | DZ38: =IFERROR($C38*DZ36,"") -> 0 | ED38: =IFERROR($C38*ED36,"") -> 0 | EH38: =IFERROR($C38*EH36,"") -> 0 | EL38: =IFERROR($C38*EL36,"") -> 0 | EP38: =IFERROR($C38*EP36,"") -> 0
B39: D | D39: 工数 | E39: =SUM(F39:ES39) -> 0
C40: 1000000 | D40: 売上金額 | E40: =SUM(F40:CW40) -> 0 | F40: =IFERROR($C40*F39,"") -> 0 | J40: =IFERROR($C40*J39,"") -> 0 | N40: =IFERROR($C40*N39,"") -> 0 | R40: =IFERROR($C40*R39,"") -> 0 | V40: =IFERROR($C40*V39,"") -> 0 | Z40: =IFERROR($C40*Z39,"") -> 0 | AD40: =IFERROR($C40*AD39,"") -> 0 | DR40: =IFERROR($C40*DR39,"") -> 0 | DV40: =IFERROR($C40*DV39,"") -> 0 | DZ40: =IFERROR($C40*DZ39,"") -> 0 | ED40: =IFERROR($C40*ED39,"") -> 0 | EH40: =IFERROR($C40*EH39,"") -> 0 | EL40: =IFERROR($C40*EL39,"") -> 0 | EP40: =IFERROR($C40*EP39,"") -> 0
C41: 420000 | D41: 原価金額 | E41: =SUM(F41:CW41) -> 0 | F41: =IFERROR($C41*F39,"") -> 0 | J41: =IFERROR($C41*J39,"") -> 0 | N41: =IFERROR($C41*N39,"") -> 0 | R41: =IFERROR($C41*R39,"") -> 0 | V41: =IFERROR($C41*V39,"") -> 0 | Z41: =IFERROR($C41*Z39,"") -> 0 | AD41: =IFERROR($C41*AD39,"") -> 0 | DR41: =IFERROR($C41*DR39,"") -> 0 | DV41: =IFERROR($C41*DV39,"") -> 0 | DZ41: =IFERROR($C41*DZ39,"") -> 0 | ED41: =IFERROR($C41*ED39,"") -> 0 | EH41: =IFERROR($C41*EH39,"") -> 0 | EL41: =IFERROR($C41*EL39,"") -> 0 | EP41: =IFERROR($C41*EP39,"") -> 0
D42: 工数 | E42: =SUM(F42:CW42) -> 0
...

Sheet 運転管理(パターン2)
A1: 要員配置計画（運転管理制御システム通信サーバ更新：パターン２）
B2: TOPへ
B3: 受注金額 | C3: 320250000
B4: 売上計上額 | C4: =E13 -> 339412500
B5: 原価金額 | C5: =E14 -> 160455000
B6: 粗利額 | C6: =C3-C5 -> 159795000
B7: 粗利率 | C7: =IF(C3=0,0,C6/C3) -> 0.49896956
F9: 2026年 | BB9: 2027年 | CX9: 2028年
F10: 1Q | R10: 2Q | AD10: 3Q | AP10: 4Q | BB10: 1Q | BN10: 2Q | BZ10: 3Q | CL10: 4Q | CX10: 1Q | DJ10: 2Q | DV10: 3Q | EH10: 4Q
F11: 45017 | J11: 45047 | N11: 45078 | R11: 45108 | V11: 45139 | Z11: 45170 | AD11: 45200 | AH11: 45231 | AL11: 45261 | AP11: 45292 | AT11: 45323 | AX11: 45352 | BB11: 45383 | BF11: 45413 | BJ11: 45444 | BN11: 45474 | BR11: 45505 | BV11: 45536 | BZ11: 45566 | CD11: 45597 | CH11: 45627 | CL11: 45658 | CP11: 45689 | CT11: 45717 | CX11: 45383 | DB11: 45413 | DF11: 45444 | DJ11: 45474 | DN11: 45505 | DR11: 45536 | DV11: 45566 | DZ11: 45597 | ED11: 45627 | EH11: 45658 | EL11: 45689 | EP11: 45717
B12: 総合計 | D12: 工数 | E12: =SUM(F12:ES12) -> 315.75 | F12: =F57+F155 -> 5 | J12: =J57+J155 -> 5 | N12: =N57+N155 -> 9.5 | R12: =R57+R155 -> 9.5 | V12: =V57+V155 -> 10.5 | Z12: =Z57+Z155 -> 19.5 | AD12: =AD57+AD155 -> 24.25 | AH12: =AH57+AH155 -> 22.5 | AL12: =AL57+AL155 -> 22.5 | AP12: =AP57+AP155 -> 22.5 | AT12: =AT57+AT155 -> 22.5 | AX12: =AX57+AX155 -> 22.5 | BB12: =BB57+BB155 -> 24.5 | BF12: =BF57+BF155 -> 24.5 | BJ12: =BJ57+BJ155 -> 19.5 | BN12: =BN57+BN155 -> 19 | BR12: =BR57+BR155 -> 7 | BV12: =BV57+BV155 -> 7 | BZ12: =BZ57+BZ155 -> 7 | CD12: =CD57+CD155 -> 7 | CH12: =CH57+CH155 -> 4.5 | CL12: =CL57+CL155 -> 0 | CP12: =CP57+CP155 -> 0 | CT12: =CT57+CT155 -> 0 | CX12: =CX57+CX155 -> 0 | DB12: =DB57+DB155 -> 0 | DF12: =DF57+DF155 -> 0 | DJ12: =DJ57+DJ155 -> 0 | DN12: =DN57+DN155 -> 0 | DR12: =DR57+DR155 -> 0 | DV12: =DV57+DV155 -> 0 | DZ12: =DZ57+DZ155 -> 0 | ED12: =ED57+ED155 -> 0 | EH12: =EH57+EH155 -> 0 | EL12: =EL57+EL155 -> 0 | EP12: =EP57+EP155 -> 0
D13: 売上金額 | E13: =SUM(F13:ES13) -> 339412500 | F13: =F58+F156 -> 5425000 | J13: =J58+J156 -> 5425000 | N13: =N58+N156 -> 10150000 | R13: =R58+R156 -> 10150000 | V13: =V58+V156 -> 11550000 | Z13: =Z58+Z156 -> 21000000 | AD13: =AD58+AD156 -> 25987500 | AH13: =AH58+AH156 -> 24150000 | AL13: =AL58+AL156 -> 24150000 | AP13: =AP58+AP156 -> 24150000 | AT13: =AT58+AT156 -> 24150000 | AX13: =AX58+AX156 -> 24150000 | BB13: =BB58+BB156 -> 26250000 | BF13: =BF58+BF156 -> 26250000 | BJ13: =BJ58+BJ156 -> 21000000 | BN13: =BN58+BN156 -> 20475000 | BR13: =BR58+BR156 -> 7525000 | BV13: =BV58+BV156 -> 7525000 | BZ13: =BZ58+BZ156 -> 7525000 | CD13: =CD58+CD156 -> 7525000 | CH13: =CH58+CH156 -> 4900000 | CL13: =CL58+CL156 -> 0 | CP13: =CP58+CP156 -> 0 | CT13: =CT58+CT156 -> 0 | CX13: =CX58+CX156 -> 0 | DB13: =DB58+DB156 -> 0 | DF13: =DF58+DF156 -> 0 | DJ13: =DJ58+DJ156 -> 0 | DN13: =DN58+DN156 -> 0 | DR13: =DR58+DR156 -> 0 | DV13: =DV58+DV156 -> 0 | DZ13: =DZ58+DZ156 -> 0 | ED13: =ED58+ED156 -> 0 | EH13: =EH58+EH156 -> 0 | EL13: =EL58+EL156 -> 0 | EP13: =EP58+EP156 -> 0
D14: 原価金額 | E14: =SUM(F14:ES14) -> 160455000 | F14: =F59+F157 -> 2580000 | J14: =J59+J157 -> 2580000 | N14: =N59+N157 -> 5430000 | R14: =R59+R157 -> 5430000 | V14: =V59+V157 -> 6630000 | Z14: =Z59+Z157 -> 9980000 | AD14: =AD59+AD157 -> 11605000 | AH14: =AH59+AH157 -> 10730000 | AL14: =AL59+AL157 -> 10730000 | AP14: =AP59+AP157 -> 10730000 | AT14: =AT59+AT157 -> 10730000 | AX14: =AX59+AX157 -> 10730000 | BB14: =BB59+BB157 -> 11730000 | BF14: =BF59+BF157 -> 11730000 | BJ14: =BJ59+BJ157 -> 9980000 | BN14: =BN59+BN157 -> 9730000 | BR14: =BR59+BR157 -> 4180000 | BV14: =BV59+BV157 -> 4180000 | BZ14: =BZ59+BZ157 -> 4180000 | CD14: =CD59+CD157 -> 4180000 | CH14: =CH59+CH157 -> 2680000 | CL14: =CL59+CL157 -> 0 | CP14: =CP59+CP157 -> 0 | CT14: =CT59+CT157 -> 0 | CX14: =CX59+CX157 -> 0 | DB14: =DB59+DB157 -> 0 | DF14: =DF59+DF157 -> 0 | DJ14: =DJ59+DJ157 -> 0 | DN14: =DN59+DN157 -> 0 | DR14: =DR59+DR157 -> 0 | DV14: =DV59+DV157 -> 0 | DZ14: =DZ59+DZ157 -> 0 | ED14: =ED59+ED157 -> 0 | EH14: =EH59+EH157 -> 0 | EL14: =EL59+EL157 -> 0 | EP14: =EP59+EP157 -> 0
D15: 粗利額 | E15: =SUM(F15:ES15) -> 178957500 | F15: =F13-F14 -> 2845000 | J15: =J13-J14 -> 2845000 | N15: =N13-N14 -> 4720000 | R15: =R13-R14 -> 4720000 | V15: =V13-V14 -> 4920000 | Z15: =Z13-Z14 -> 11020000 | AD15: =AD13-AD14 -> 14382500 | AH15: =AH13-AH14 -> 13420000 | AL15: =AL13-AL14 -> 13420000 | AP15: =AP13-AP14 -> 13420000 | AT15: =AT13-AT14 -> 13420000 | AX15: =AX13-AX14 -> 13420000 | BB15: =BB13-BB14 -> 14520000 | BF15: =BF13-BF14 -> 14520000 | BJ15: =BJ13-BJ14 -> 11020000 | BN15: =BN13-BN14 -> 10745000 | BR15: =BR13-BR14 -> 3345000 | BV15: =BV13-BV14 -> 3345000 | BZ15: =BZ13-BZ14 -> 3345000 | CD15: =CD13-CD14 -> 3345000 | CH15: =CH13-CH14 -> 2220000 | CL15: =CL13-CL14 -> 0 | CP15: =CP13-CP14 -> 0 | CT15: =CT13-CT14 -> 0 | CX15: =CX13-CX14 -> 0 | DB15: =DB13-DB14 -> 0 | DF15: =DF13-DF14 -> 0 | DJ15: =DJ13-DJ14 -> 0 | DN15: =DN13-DN14 -> 0 | DR15: =DR13-DR14 -> 0 | DV15: =DV13-DV14 -> 0 | DZ15: =DZ13-DZ14 -> 0 | ED15: =ED13-ED14 -> 0 | EH15: =EH13-EH14 -> 0 | EL15: =EL13-EL14 -> 0 | EP15: =EP13-EP14 -> 0
A17: 【社員・契約社員】 | C17: ※必要に応じて修正すること。
B18: 要員名 | C18: 月額単価 | D18: 内訳 | E18: 合計 | F18: 2026年 | BB18: 2027年 | CX18: 2028年
F19: 1Q | R19: 2Q | AD19: 3Q | AP19: 4Q | BB19: 1Q | BN19: 2Q | BZ19: 3Q | CL19: 4Q | CX19: 1Q | DJ19: 2Q | DV19: 3Q | EH19: 4Q
C20: (上段:売上、下段:原価) | F20: 45017 | J20: 45047 | N20: 45078 | R20: 45108 | V20: 45139 | Z20: 45170 | AD20: 45200 | AH20: 45231 | AL20: 45261 | AP20: 45292 | AT20: 45323 | AX20: 45352 | BB20: 45383 | BF20: 45413 | BJ20: 45444 | BN20: 45474 | BR20: 45505 | BV20: 45536 | BZ20: 45566 | CD20: 45597 | CH20: 45627 | CL20: 45658 | CP20: 45689 | CT20: 45717 | CX20: 45383 | DB20: 45413 | DF20: 45444 | DJ20: 45474 | DN20: 45505 | DR20: 45536 | DV20: 45566 | DZ20: 45597 | ED20: 45627 | EH20: 45658 | EL20: 45689 | EP20: 45717
B21: 福田 | D21: 工数 | E21: =SUM(F21:ES21) -> 10.5 | F21: 0.5 | J21: 0.5 | N21: 0.5 | R21: 0.5 | V21: 0.5 | Z21: 0.5 | AD21: 0.5 | AH21: 0.5 | AL21: 0.5 | AP21: 0.5 | AT21: 0.5 | AX21: 0.5 | BB21: 0.5 | BF21: 0.5 | BJ21: 0.5 | BN21: 0.5 | BR21: 0.5 | BV21: 0.5 | BZ21: 0.5 | CD21: 0.5 | CH21: 0.5
C22: 1400000 | D22: 売上金額 | E22: =SUM(F22:CW22) -> 14700000 | F22: =IFERROR($C22*F21,"") -> 700000 | J22: =IFERROR($C22*J21,"") -> 700000 | N22: =IFERROR($C22*N21,"") -> 700000 | R22: =IFERROR($C22*R21,"") -> 700000 | V22: =IFERROR($C22*V21,"") -> 700000 | Z22: =IFERROR($C22*Z21,"") -> 700000 | AD22: =IFERROR($C22*AD21,"") -> 700000 | AH22: =IFERROR($C22*AH21,"") -> 700000 | AL22: =IFERROR($C22*AL21,"") -> 700000 | AP22: =IFERROR($C22*AP21,"") -> 700000 | AT22: =IFERROR($C22*AT21,"") -> 700000 | AX22: =IFERROR($C22*AX21,"") -> 700000 | BB22: =IFERROR($C22*BB21,"") -> 700000 | BF22: =IFERROR($C22*BF21,"") -> 700000 | BJ22: =IFERROR($C22*BJ21,"") -> 700000 | BN22: =IFERROR($C22*BN21,"") -> 700000 | BR22: =IFERROR($C22*BR21,"") -> 700000 | BV22: =IFERROR($C22*BV21,"") -> 700000 | BZ22: =IFERROR($C22*BZ21,"") -> 700000 | CD22: =IFERROR($C22*CD21,"") -> 700000 | CH22: =IFERROR($C22*CH21,"") -> 700000 | CL22: =IFERROR($C22*CL21,"") -> 0 | CP22: =IFERROR($C22*CP21,"") -> 0 | CT22: =IFERROR($C22*CT21,"") -> 0 | CX22: =IFERROR($C22*CX21,"") -> 0 | DB22: =IFERROR($C22*DB21,"") -> 0 | DF22: =IFERROR($C22*DF21,"") -> 0 | DJ22: =IFERROR($C22*DJ21,"") -> 0 | DN22: =IFERROR($C22*DN21,"") -> 0 | DR22: =IFERROR($C22*DR21,"") -> 0 | DV22: =IFERROR($C22*DV21,"") -> 0 | DZ22: =IFERROR($C22*DZ21,"") -> 0 | ED22: =IFERROR($C22*ED21,"") -> 0 | EH22: =IFERROR($C22*EH21,"") -> 0 | EL22: =IFERROR($C22*EL21,"") -> 0 | EP22: =IFERROR($C22*EP21,"") -> 0
C23: 600000 | D23: 原価金額 | E23: =SUM(F23:CW23) -> 6300000 | F23: =IFERROR($C23*F21,"") -> 300000 | J23: =IFERROR($C23*J21,"") -> 300000 | N23: =IFERROR($C23*N21,"") -> 300000 | R23: =IFERROR($C23*R21,"") -> 300000 | V23: =IFERROR($C23*V21,"") -> 300000 | Z23: =IFERROR($C23*Z21,"") -> 300000 | AD23: =IFERROR($C23*AD21,"") -> 300000 | AH23: =IFERROR($C23*AH21,"") -> 300000 | AL23: =IFERROR($C23*AL21,"") -> 300000 | AP23: =IFERROR($C23*AP21,"") -> 300000 | AT23: =IFERROR($C23*AT21,"") -> 300000 | AX23: =IFERROR($C23*AX21,"") -> 300000 | BB23: =IFERROR($C23*BB21,"") -> 300000 | BF23: =IFERROR($C23*BF21,"") -> 300000 | BJ23: =IFERROR($C23*BJ21,"") -> 300000 | BN23: =IFERROR($C23*BN21,"") -> 300000 | BR23: =IFERROR($C23*BR21,"") -> 300000 | BV23: =IFERROR($C23*BV21,"") -> 300000 | BZ23: =IFERROR($C23*BZ21,"") -> 300000 | CD23: =IFERROR($C23*CD21,"") -> 300000 | CH23: =IFERROR($C23*CH21,"") -> 300000 | CL23: =IFERROR($C23*CL21,"") -> 0 | CP23: =IFERROR($C23*CP21,"") -> 0 | CT23: =IFERROR($C23*CT21,"") -> 0 | CX23: =IFERROR($C23*CX21,"") -> 0 | DB23: =IFERROR($C23*DB21,"") -> 0 | DF23: =IFERROR($C23*DF21,"") -> 0 | DJ23: =IFERROR($C23*DJ21,"") -> 0 | DN23: =IFERROR($C23*DN21,"") -> 0 | DR23: =IFERROR($C23*DR21,"") -> 0 | DV23: =IFERROR($C23*DV21,"") -> 0 | DZ23: =IFERROR($C23*DZ21,"") -> 0 | ED23: =IFERROR($C23*ED21,"") -> 0 | EH23: =IFERROR($C23*EH21,"") -> 0 | EL23: =IFERROR($C23*EL21,"") -> 0 | EP23: =IFERROR($C23*EP21,"") -> 0
B24: PL | D24: 工数 | E24: =SUM(F24:ES24) -> 20.5 | F24: 1 | J24: 1 | N24: 1 | R24: 1 | V24: 1 | Z24: 1 | AD24: 1 | AH24: 1 | AL24: 1 | AP24: 1 | AT24: 1 | AX24: 1 | BB24: 1 | BF24: 1 | BJ24: 1 | BN24: 1 | BR24: 1 | BV24: 1 | BZ24: 1 | CD24: 1 | CH24: 0.5
C25: 1200000 | D25: 売上金額 | E25: =SUM(F25:CW25) -> 24600000 | F25: =IFERROR($C25*F24,"") -> 1200000 | J25: =IFERROR($C25*J24,"") -> 1200000 | N25: =IFERROR($C25*N24,"") -> 1200000 | R25: =IFERROR($C25*R24,"") -> 1200000 | V25: =IFERROR($C25*V24,"") -> 1200000 | Z25: =IFERROR($C25*Z24,"") -> 1200000 | AD25: =IFERROR($C25*AD24,"") -> 1200000 | AH25: =IFERROR($C25*AH24,"") -> 1200000 | AL25: =IFERROR($C25*AL24,"") -> 1200000 | AP25: =IFERROR($C25*AP24,"") -> 1200000 | AT25: =IFERROR($C25*AT24,"") -> 1200000 | AX25: =IFERROR($C25*AX24,"") -> 1200000 | BB25: =IFERROR($C25*BB24,"") -> 1200000 | BF25: =IFERROR($C25*BF24,"") -> 1200000 | BJ25: =IFERROR($C25*BJ24,"") -> 1200000 | BN25: =IFERROR($C25*BN24,"") -> 1200000 | BR25: =IFERROR($C25*BR24,"") -> 1200000 | BV25: =IFERROR($C25*BV24,"") -> 1200000 | BZ25: =IFERROR($C25*BZ24,"") -> 1200000 | CD25: =IFERROR($C25*CD24,"") -> 1200000 | CH25: =IFERROR($C25*CH24,"") -> 600000 | CL25: =IFERROR($C25*CL24,"") -> 0 | CP25: =IFERROR($C25*CP24,"") -> 0 | CT25: =IFERROR($C25*CT24,"") -> 0 | CX25: =IFERROR($C25*CX24,"") -> 0 | DB25: =IFERROR($C25*DB24,"") -> 0 | DF25: =IFERROR($C25*DF24,"") -> 0 | DJ25: =IFERROR($C25*DJ24,"") -> 0 | DN25: =IFERROR($C25*DN24,"") -> 0 | DR25: =IFERROR($C25*DR24,"") -> 0 | DV25: =IFERROR($C25*DV24,"") -> 0 | DZ25: =IFERROR($C25*DZ24,"") -> 0 | ED25: =IFERROR($C25*ED24,"") -> 0 | EH25: =IFERROR($C25*EH24,"") -> 0 | EL25: =IFERROR($C25*EL24,"") -> 0 | EP25: =IFERROR($C25*EP24,"") -> 0
C26: 600000 | D26: 原価金額 | E26: =SUM(F26:CW26) -> 12300000 | F26: =IFERROR($C26*F24,"") -> 600000 | J26: =IFERROR($C26*J24,"") -> 600000 | N26: =IFERROR($C26*N24,"") -> 600000 | R26: =IFERROR($C26*R24,"") -> 600000 | V26: =IFERROR($C26*V24,"") -> 600000 | Z26: =IFERROR($C26*Z24,"") -> 600000 | AD26: =IFERROR($C26*AD24,"") -> 600000 | AH26: =IFERROR($C26*AH24,"") -> 600000 | AL26: =IFERROR($C26*AL24,"") -> 600000 | AP26: =IFERROR($C26*AP24,"") -> 600000 | AT26: =IFERROR($C26*AT24,"") -> 600000 | AX26: =IFERROR($C26*AX24,"") -> 600000 | BB26: =IFERROR($C26*BB24,"") -> 600000 | BF26: =IFERROR($C26*BF24,"") -> 600000 | BJ26: =IFERROR($C26*BJ24,"") -> 600000 | BN26: =IFERROR($C26*BN24,"") -> 600000 | BR26: =IFERROR($C26*BR24,"") -> 600000 | BV26: =IFERROR($C26*BV24,"") -> 600000 | BZ26: =IFERROR($C26*BZ24,"") -> 600000 | CD26: =IFERROR($C26*CD24,"") -> 600000 | CH26: =IFERROR($C26*CH24,"") -> 300000 | CL26: =IFERROR($C26*CL24,"") -> 0 | CP26: =IFERROR($C26*CP24,"") -> 0 | CT26: =IFERROR($C26*CT24,"") -> 0 | CX26: =IFERROR($C26*CX24,"") -> 0 | DB26: =IFERROR($C26*DB24,"") -> 0 | DF26: =IFERROR($C26*DF24,"") -> 0 | DJ26: =IFERROR($C26*DJ24,"") -> 0 | DN26: =IFERROR($C26*DN24,"") -> 0 | DR26: =IFERROR($C26*DR24,"") -> 0 | DV26: =IFERROR($C26*DV24,"") -> 0 | DZ26: =IFERROR($C26*DZ24,"") -> 0 | ED26: =IFERROR($C26*ED24,"") -> 0 | EH26: =IFERROR($C26*EH24,"") -> 0 | EL26: =IFERROR($C26*EL24,"") -> 0 | EP26: =IFERROR($C26*EP24,"") -> 0
B27: ブリッジ | D27: 工数 | E27: =SUM(F27:ES27) -> 12 | V27: 1 | Z27: 1 | AD27: 1 | AH27: 1 | AL27: 1 | AP27: 1 | AT27: 1 | AX27: 1 | BB27: 1 | BF27: 1 | BJ27: 1 | BN27: 1
C28: 1400000 | D28: 売上金額 | E28: =SUM(F28:CW28) -> 16800000 | F28: =IFERROR($C28*F27,"") -> 0 | J28: =IFERROR($C28*J27,"") -> 0 | N28: =IFERROR($C28*N27,"") -> 0 | R28: =IFERROR($C28*R27,"") -> 0 | V28: =IFERROR($C28*V27,"") -> 1400000 | Z28: =IFERROR($C28*Z27,"") -> 1400000 | AD28: =IFERROR($C28*AD27,"") -> 1400000 | AH28: =IFERROR($C28*AH27,"") -> 1400000 | AL28: =IFERROR($C28*AL27,"") -> 1400000 | AP28: =IFERROR($C28*AP27,"") -> 1400000 | AT28: =IFERROR($C28*AT27,"") -> 1400000 | AX28: =IFERROR($C28*AX27,"") -> 1400000 | BB28: =IFERROR($C28*BB27,"") -> 1400000 | BF28: =IFERROR($C28*BF27,"") -> 1400000 | BJ28: =IFERROR($C28*BJ27,"") -> 1400000 | BN28: =IFERROR($C28*BN27,"") -> 1400000 | BR28: =IFERROR($C28*BR27,"") -> 0 | BV28: =IFERROR($C28*BV27,"") -> 0 | BZ28: =IFERROR($C28*BZ27,"") -> 0 | CD28: =IFERROR($C28*CD27,"") -> 0 | CH28: =IFERROR($C28*CH27,"") -> 0 | CL28: =IFERROR($C28*CL27,"") -> 0 | CP28: =IFERROR($C28*CP27,"") -> 0 | CT28: =IFERROR($C28*CT27,"") -> 0 | CX28: =IFERROR($C28*CX27,"") -> 0 | DB28: =IFERROR($C28*DB27,"") -> 0 | DF28: =IFERROR($C28*DF27,"") -> 0 | DJ28: =IFERROR($C28*DJ27,"") -> 0 | DN28: =IFERROR($C28*DN27,"") -> 0 | DR28: =IFERROR($C28*DR27,"") -> 0 | DV28: =IFERROR($C28*DV27,"") -> 0 | DZ28: =IFERROR($C28*DZ27,"") -> 0 | ED28: =IFERROR($C28*ED27,"") -> 0 | EH28: =IFERROR($C28*EH27,"") -> 0 | EL28: =IFERROR($C28*EL27,"") -> 0 | EP28: =IFERROR($C28*EP27,"") -> 0
C29: 1200000 | D29: 原価金額 | E29: =SUM(F29:CW29) -> 14400000 | F29: =IFERROR($C29*F27,"") -> 0 | J29: =IFERROR($C29*J27,"") -> 0 | N29: =IFERROR($C29*N27,"") -> 0 | R29: =IFERROR($C29*R27,"") -> 0 | V29: =IFERROR($C29*V27,"") -> 1200000 | Z29: =IFERROR($C29*Z27,"") -> 1200000 | AD29: =IFERROR($C29*AD27,"") -> 1200000 | AH29: =IFERROR($C29*AH27,"") -> 1200000 | AL29: =IFERROR($C29*AL27,"") -> 1200000 | AP29: =IFERROR($C29*AP27,"") -> 1200000 | AT29: =IFERROR($C29*AT27,"") -> 1200000 | AX29: =IFERROR($C29*AX27,"") -> 1200000 | BB29: =IFERROR($C29*BB27,"") -> 1200000 | BF29: =IFERROR($C29*BF27,"") -> 1200000 | BJ29: =IFERROR($C29*BJ27,"") -> 1200000 | BN29: =IFERROR($C29*BN27,"") -> 1200000 | BR29: =IFERROR($C29*BR27,"") -> 0 | BV29: =IFERROR($C29*BV27,"") -> 0 | BZ29: =IFERROR($C29*BZ27,"") -> 0 | CD29: =IFERROR($C29*CD27,"") -> 0 | CH29: =IFERROR($C29*CH27,"") -> 0 | CL29: =IFERROR($C29*CL27,"") -> 0 | CP29: =IFERROR($C29*CP27,"") -> 0 | CT29: =IFERROR($C29*CT27,"") -> 0 | CX29: =IFERROR($C29*CX27,"") -> 0 | DB29: =IFERROR($C29*DB27,"") -> 0 | DF29: =IFERROR($C29*DF27,"") -> 0 | DJ29: =IFERROR($C29*DJ27,"") -> 0 | DN29: =IFERROR($C29*DN27,"") -> 0 | DR29: =IFERROR($C29*DR27,"") -> 0 | DV29: =IFERROR($C29*DV27,"") -> 0 | DZ29: =IFERROR($C29*DZ27,"") -> 0 | ED29: =IFERROR($C29*ED27,"") -> 0 | EH29: =IFERROR($C29*EH27,"") -> 0 | EL29: =IFERROR($C29*EL27,"") -> 0 | EP29: =IFERROR($C29*EP27,"") -> 0
B30: PMO | D30: 工数 | E30: =SUM(F30:ES30) -> 20.5 | F30: 1 | J30: 1 | N30: 1 | R30: 1 | V30: 1 | Z30: 1 | AD30: 1 | AH30: 1 | AL30: 1 | AP30: 1 | AT30: 1 | AX30: 1 | BB30: 1 | BF30: 1 | BJ30: 1 | BN30: 1 | BR30: 1 | BV30: 1 | BZ30: 1 | CD30: 1 | CH30: 0.5
C31: 900000 | D31: 売上金額 | E31: =SUM(F31:CW31) -> 18450000 | F31: =IFERROR($C31*F30,"") -> 900000 | J31: =IFERROR($C31*J30,"") -> 900000 | N31: =IFERROR($C31*N30,"") -> 900000 | R31: =IFERROR($C31*R30,"") -> 900000 | V31: =IFERROR($C31*V30,"") -> 900000 | Z31: =IFERROR($C31*Z30,"") -> 900000 | AD31: =IFERROR($C31*AD30,"") -> 900000 | AH31: =IFERROR($C31*AH30,"") -> 900000 | AL31: =IFERROR($C31*AL30,"") -> 900000 | AP31: =IFERROR($C31*AP30,"") -> 900000 | AT31: =IFERROR($C31*AT30,"") -> 900000 | AX31: =IFERROR($C31*AX30,"") -> 900000 | BB31: =IFERROR($C31*BB30,"") -> 900000 | BF31: =IFERROR($C31*BF30,"") -> 900000 | BJ31: =IFERROR($C31*BJ30,"") -> 900000 | BN31: =IFERROR($C31*BN30,"") -> 900000 | BR31: =IFERROR($C31*BR30,"") -> 900000 | BV31: =IFERROR($C31*BV30,"") -> 900000 | BZ31: =IFERROR($C31*BZ30,"") -> 900000 | CD31: =IFERROR($C31*CD30,"") -> 900000 | CH31: =IFERROR($C31*CH30,"") -> 450000 | CL31: =IFERROR($C31*CL30,"") -> 0 | CP31: =IFERROR($C31*CP30,"") -> 0 | CT31: =IFERROR($C31*CT30,"") -> 0 | CX31: =IFERROR($C31*CX30,"") -> 0 | DB31: =IFERROR($C31*DB30,"") -> 0 | DF31: =IFERROR($C31*DF30,"") -> 0 | DJ31: =IFERROR($C31*DJ30,"") -> 0 | DN31: =IFERROR($C31*DN30,"") -> 0 | DR31: =IFERROR($C31*DR30,"") -> 0 | DV31: =IFERROR($C31*DV30,"") -> 0 | DZ31: =IFERROR($C31*DZ30,"") -> 0 | ED31: =IFERROR($C31*ED30,"") -> 0 | EH31: =IFERROR($C31*EH30,"") -> 0 | EL31: =IFERROR($C31*EL30,"") -> 0 | EP31: =IFERROR($C31*EP30,"") -> 0
C32: 300000 | D32: 原価金額 | E32: =SUM(F32:CW32) -> 6150000 | F32: =IFERROR($C32*F30,"") -> 300000 | J32: =IFERROR($C32*J30,"") -> 300000 | N32: =IFERROR($C32*N30,"") -> 300000 | R32: =IFERROR($C32*R30,"") -> 300000 | V32: =IFERROR($C32*V30,"") -> 300000 | Z32: =IFERROR($C32*Z30,"") -> 300000 | AD32: =IFERROR($C32*AD30,"") -> 300000 | AH32: =IFERROR($C32*AH30,"") -> 300000 | AL32: =IFERROR($C32*AL30,"") -> 300000 | AP32: =IFERROR($C32*AP30,"") -> 300000 | AT32: =IFERROR($C32*AT30,"") -> 300000 | AX32: =IFERROR($C32*AX30,"") -> 300000 | BB32: =IFERROR($C32*BB30,"") -> 300000 | BF32: =IFERROR($C32*BF30,"") -> 300000 | BJ32: =IFERROR($C32*BJ30,"") -> 300000 | BN32: =IFERROR($C32*BN30,"") -> 300000 | BR32: =IFERROR($C32*BR30,"") -> 300000 | BV32: =IFERROR($C32*BV30,"") -> 300000 | BZ32: =IFERROR($C32*BZ30,"") -> 300000 | CD32: =IFERROR($C32*CD30,"") -> 300000 | CH32: =IFERROR($C32*CH30,"") -> 150000 | CL32: =IFERROR($C32*CL30,"") -> 0 | CP32: =IFERROR($C32*CP30,"") -> 0 | CT32: =IFERROR($C32*CT30,"") -> 0 | CX32: =IFERROR($C32*CX30,"") -> 0 | DB32: =IFERROR($C32*DB30,"") -> 0 | DF32: =IFERROR($C32*DF30,"") -> 0 | DJ32: =IFERROR($C32*DJ30,"") -> 0 | DN32: =IFERROR($C32*DN30,"") -> 0 | DR32: =IFERROR($C32*DR30,"") -> 0 | DV32: =IFERROR($C32*DV30,"") -> 0 | DZ32: =IFERROR($C32*DZ30,"") -> 0 | ED32: =IFERROR($C32*ED30,"") -> 0 | EH32: =IFERROR($C32*EH30,"") -> 0 | EL32: =IFERROR($C32*EL30,"") -> 0 | EP32: =IFERROR($C32*EP30,"") -> 0
B33: SE1 | D33: 工数 | E33: =SUM(F33:ES33) -> 20.5 | F33: 1 | J33: 1 | N33: 1 | R33: 1 | V33: 1 | Z33: 1 | AD33: 1 | AH33: 1 | AL33: 1 | AP33: 1 | AT33: 1 | AX33: 1 | BB33: 1 | BF33: 1 | BJ33: 1 | BN33: 1 | BR33: 1 | BV33: 1 | BZ33: 1 | CD33: 1 | CH33: 0.5
C34: 1050000 | D34: 売上金額 | E34: =SUM(F34:CW34) -> 21525000 | F34: =IFERROR($C34*F33,"") -> 1050000 | J34: =IFERROR($C34*J33,"") -> 1050000 | N34: =IFERROR($C34*N33,"") -> 1050000 | R34: =IFERROR($C34*R33,"") -> 1050000 | V34: =IFERROR($C34*V33,"") -> 1050000 | Z34: =IFERROR($C34*Z33,"") -> 1050000 | AD34: =IFERROR($C34*AD33,"") -> 1050000 | AH34: =IFERROR($C34*AH33,"") -> 1050000 | AL34: =IFERROR($C34*AL33,"") -> 1050000 | AP34: =IFERROR($C34*AP33,"") -> 1050000 | AT34: =IFERROR($C34*AT33,"") -> 1050000 | AX34: =IFERROR($C34*AX33,"") -> 1050000 | BB34: =IFERROR($C34*BB33,"") -> 1050000 | BF34: =IFERROR($C34*BF33,"") -> 1050000 | BJ34: =IFERROR($C34*BJ33,"") -> 1050000 | BN34: =IFERROR($C34*BN33,"") -> 1050000 | BR34: =IFERROR($C34*BR33,"") -> 1050000 | BV34: =IFERROR($C34*BV33,"") -> 1050000 | BZ34: =IFERROR($C34*BZ33,"") -> 1050000 | CD34: =IFERROR($C34*CD33,"") -> 1050000 | CH34: =IFERROR($C34*CH33,"") -> 525000 | CL34: =IFERROR($C34*CL33,"") -> 0 | CP34: =IFERROR($C34*CP33,"") -> 0 | CT34: =IFERROR($C34*CT33,"") -> 0 | CX34: =IFERROR($C34*CX33,"") -> 0 | DB34: =IFERROR($C34*DB33,"") -> 0 | DF34: =IFERROR($C34*DF33,"") -> 0 | DJ34: =IFERROR($C34*DJ33,"") -> 0 | DN34: =IFERROR($C34*DN33,"") -> 0 | DR34: =IFERROR($C34*DR33,"") -> 0 | DV34: =IFERROR($C34*DV33,"") -> 0 | DZ34: =IFERROR($C34*DZ33,"") -> 0 | ED34: =IFERROR($C34*ED33,"") -> 0 | EH34: =IFERROR($C34*EH33,"") -> 0 | EL34: =IFERROR($C34*EL33,"") -> 0 | EP34: =IFERROR($C34*EP33,"") -> 0
C35: 500000 | D35: 原価金額 | E35: =SUM(F35:CW35) -> 10250000 | F35: =IFERROR($C35*F33,"") -> 500000 | J35: =IFERROR($C35*J33,"") -> 500000 | N35: =IFERROR($C35*N33,"") -> 500000 | R35: =IFERROR($C35*R33,"") -> 500000 | V35: =IFERROR($C35*V33,"") -> 500000 | Z35: =IFERROR($C35*Z33,"") -> 500000 | AD35: =IFERROR($C35*AD33,"") -> 500000 | AH35: =IFERROR($C35*AH33,"") -> 500000 | AL35: =IFERROR($C35*AL33,"") -> 500000 | AP35: =IFERROR($C35*AP33,"") -> 500000 | AT35: =IFERROR($C35*AT33,"") -> 500000 | AX35: =IFERROR($C35*AX33,"") -> 500000 | BB35: =IFERROR($C35*BB33,"") -> 500000 | BF35: =IFERROR($C35*BF33,"") -> 500000 | BJ35: =IFERROR($C35*BJ33,"") -> 500000 | BN35: =IFERROR($C35*BN33,"") -> 500000 | BR35: =IFERROR($C35*BR33,"") -> 500000 | BV35: =IFERROR($C35*BV33,"") -> 500000 | BZ35: =IFERROR($C35*BZ33,"") -> 500000 | CD35: =IFERROR($C35*CD33,"") -> 500000 | CH35: =IFERROR($C35*CH33,"") -> 250000 | CL35: =IFERROR($C35*CL33,"") -> 0 | CP35: =IFERROR($C35*CP33,"") -> 0 | CT35: =IFERROR($C35*CT33,"") -> 0 | CX35: =IFERROR($C35*CX33,"") -> 0 | DB35: =IFERROR($C35*DB33,"") -> 0 | DF35: =IFERROR($C35*DF33,"") -> 0 | DJ35: =IFERROR($C35*DJ33,"") -> 0 | DN35: =IFERROR($C35*DN33,"") -> 0 | DR35: =IFERROR($C35*DR33,"") -> 0 | DV35: =IFERROR($C35*DV33,"") -> 0 | DZ35: =IFERROR($C35*DZ33,"") -> 0 | ED35: =IFERROR($C35*ED33,"") -> 0 | EH35: =IFERROR($C35*EH33,"") -> 0 | EL35: =IFERROR($C35*EL33,"") -> 0 | EP35: =IFERROR($C35*EP33,"") -> 0
B36: SE2 | D36: 工数 | E36: =SUM(F36:ES36) -> 17 | F36: 0.5 | J36: 0.5 | N36: 1 | R36: 1 | V36: 1 | Z36: 1 | AD36: 1 | AH36: 1 | AL36: 1 | AP36: 1 | AT36: 1 | AX36: 1 | BB36: 1 | BF36: 1 | BJ36: 1 | BN36: 0.5 | BR36: 0.5 | BV36: 0.5 | BZ36: 0.5 | CD36: 0.5 | CH36: 0.5
C37: 1050000 | D37: 売上金額 | E37: =SUM(F37:CW37) -> 17850000 | F37: =IFERROR($C37*F36,"") -> 525000 | J37: =IFERROR($C37*J36,"") -> 525000 | N37: =IFERROR($C37*N36,"") -> 1050000 | R37: =IFERROR($C37*R36,"") -> 1050000 | V37: =IFERROR($C37*V36,"") -> 1050000 | Z37: =IFERROR($C37*Z36,"") -> 1050000 | AD37: =IFERROR($C37*AD36,"") -> 1050000 | AH37: =IFERROR($C37*AH36,"") -> 1050000 | AL37: =IFERROR($C37*AL36,"") -> 1050000 | AP37: =IFERROR($C37*AP36,"") -> 1050000 | AT37: =IFERROR($C37*AT36,"") -> 1050000 | AX37: =IFERROR($C37*AX36,"") -> 1050000 | BB37: =IFERROR($C37*BB36,"") -> 1050000 | BF37: =IFERROR($C37*BF36,"") -> 1050000 | BJ37: =IFERROR($C37*BJ36,"") -> 1050000 | BN37: =IFERROR($C37*BN36,"") -> 525000 | BR37: =IFERROR($C37*BR36,"") -> 525000 | BV37: =IFERROR($C37*BV36,"") -> 525000 | BZ37: =IFERROR($C37*BZ36,"") -> 525000 | CD37: =IFERROR($C37*CD36,"") -> 525000 | CH37: =IFERROR($C37*CH36,"") -> 525000 | CL37: =IFERROR($C37*CL36,"") -> 0 | CP37: =IFERROR($C37*CP36,"") -> 0 | CT37: =IFERROR($C37*CT36,"") -> 0 | CX37: =IFERROR($C37*CX36,"") -> 0 | DB37: =IFERROR($C37*DB36,"") -> 0 | DF37: =IFERROR($C37*DF36,"") -> 0 | DJ37: =IFERROR($C37*DJ36,"") -> 0 | DN37: =IFERROR($C37*DN36,"") -> 0 | DR37: =IFERROR($C37*DR36,"") -> 0 | DV37: =IFERROR($C37*DV36,"") -> 0 | DZ37: =IFERROR($C37*DZ36,"") -> 0 | ED37: =IFERROR($C37*ED36,"") -> 0 | EH37: =IFERROR($C37*EH36,"") -> 0 | EL37: =IFERROR($C37*EL36,"") -> 0 | EP37: =IFERROR($C37*EP36,"") -> 0
C38: 500000 | D38: 原価金額 | E38: =SUM(F38:CW38) -> 8500000 | F38: =IFERROR($C38*F36,"") -> 250000 | J38: =IFERROR($C38*J36,"") -> 250000 | N38: =IFERROR($C38*N36,"") -> 500000 | R38: =IFERROR($C38*R36,"") -> 500000 | V38: =IFERROR($C38*V36,"") -> 500000 | Z38: =IFERROR($C38*Z36,"") -> 500000 | AD38: =IFERROR($C38*AD36,"") -> 500000 | AH38: =IFERROR($C38*AH36,"") -> 500000 | AL38: =IFERROR($C38*AL36,"") -> 500000 | AP38: =IFERROR($C38*AP36,"") -> 500000 | AT38: =IFERROR($C38*AT36,"") -> 500000 | AX38: =IFERROR($C38*AX36,"") -> 500000 | BB38: =IFERROR($C38*BB36,"") -> 500000 | BF38: =IFERROR($C38*BF36,"") -> 500000 | BJ38: =IFERROR($C38*BJ36,"") -> 500000 | BN38: =IFERROR($C38*BN36,"") -> 250000 | BR38: =IFERROR($C38*BR36,"") -> 250000 | BV38: =IFERROR($C38*BV36,"") -> 250000 | BZ38: =IFERROR($C38*BZ36,"") -> 250000 | CD38: =IFERROR($C38*CD36,"") -> 250000 | CH38: =IFERROR($C38*CH36,"") -> 250000 | CL38: =IFERROR($C38*CL36,"") -> 0 | CP38: =IFERROR($C38*CP36,"") -> 0 | CT38: =IFERROR($C38*CT36,"") -> 0 | CX38: =IFERROR($C38*CX36,"") -> 0 | DB38: =IFERROR($C38*DB36,"") -> 0 | DF38: =IFERROR($C38*DF36,"") -> 0 | DJ38: =IFERROR($C38*DJ36,"") -> 0 | DN38: =IFERROR($C38*DN36,"") -> 0 | DR38: =IFERROR($C38*DR36,"") -> 0 | DV38: =IFERROR($C38*DV36,"") -> 0 | DZ38: =IFERROR($C38*DZ36,"") -> 0 | ED38: =IFERROR($C38*ED36,"") -> 0 | EH38: =IFERROR($C38*EH36,"") -> 0 | EL38: =IFERROR($C38*EL36,"") -> 0 | EP38: =IFERROR($C38*EP36,"") -> 0
B39: SE3 | D39: 工数 | E39: =SUM(F39:ES39) -> 9 | N39: 1 | R39: 1 | V39: 1 | Z39: 1 | AD39: 1 | BB39: 1 | BF39: 1 | BJ39: 1 | BN39: 1
C40: 1050000 | D40: 売上金額 | E40: =SUM(F40:CW40) -> 9450000 | F40: =IFERROR($C40*F39,"") -> 0 | J40: =IFERROR($C40*J39,"") -> 0 | N40: =IFERROR($C40*N39,"") -> 1050000 | R40: =IFERROR($C40*R39,"") -> 1050000 | V40: =IFERROR($C40*V39,"") -> 1050000 | Z40: =IFERROR($C40*Z39,"") -> 1050000 | AD40: =IFERROR($C40*AD39,"") -> 1050000 | AH40: =IFERROR($C40*AH39,"") -> 0 | AL40: =IFERROR($C40*AL39,"") -> 0 | AP40: =IFERROR($C40*AP39,"") -> 0 | AT40: =IFERROR($C40*AT39,"") -> 0 | AX40: =IFERROR($C40*AX39,"") -> 0 | BB40: =IFERROR($C40*BB39,"") -> 1050000 | BF40: =IFERROR($C40*BF39,"") -> 1050000 | BJ40: =IFERROR($C40*BJ39,"") -> 1050000 | BN40: =IFERROR($C40*BN39,"") -> 1050000 | BR40: =IFERROR($C40*BR39,"") -> 0 | BV40: =IFERROR($C40*BV39,"") -> 0 | BZ40: =IFERROR($C40*BZ39,"") -> 0 | CD40: =IFERROR($C40*CD39,"") -> 0 | CH40: =IFERROR($C40*CH39,"") -> 0 | CL40: =IFERROR($C40*CL39,"") -> 0 | CP40: =IFERROR($C40*CP39,"") -> 0 | CT40: =IFERROR($C40*CT39,"") -> 0 | CX40: =IFERROR($C40*CX39,"") -> 0 | DB40: =IFERROR($C40*DB39,"") -> 0 | DF40: =IFERROR($C40*DF39,"") -> 0 | DJ40: =IFERROR($C40*DJ39,"") -> 0 | DN40: =IFERROR($C40*DN39,"") -> 0 | DR40: =IFERROR($C40*DR39,"") -> 0 | DV40: =IFERROR($C40*DV39,"") -> 0 | DZ40: =IFERROR($C40*DZ39,"") -> 0 | ED40: =IFERROR($C40*ED39,"") -> 0 | EH40: =IFERROR($C40*EH39,"") -> 0 | EL40: =IFERROR($C40*EL39,"") -> 0 | EP40: =IFERROR($C40*EP39,"") -> 0
C41: 500000 | D41: 原価金額 | E41: =SUM(F41:CW41) -> 4500000 | F41: =IFERROR($C41*F39,"") -> 0 | J41: =IFERROR($C41*J39,"") -> 0 | N41: =IFERROR($C41*N39,"") -> 500000 | R41: =IFERROR($C41*R39,"") -> 500000 | V41: =IFERROR($C41*V39,"") -> 500000 | Z41: =IFERROR($C41*Z39,"") -> 500000 | AD41: =IFERROR($C41*AD39,"") -> 500000 | AH41: =IFERROR($C41*AH39,"") -> 0 | AL41: =IFERROR($C41*AL39,"") -> 0 | AP41: =IFERROR($C41*AP39,"") -> 0 | AT41: =IFERROR($C41*AT39,"") -> 0 | AX41: =IFERROR($C41*AX39,"") -> 0 | BB41: =IFERROR($C41*BB39,"") -> 500000 | BF41: =IFERROR($C41*BF39,"") -> 500000 | BJ41: =IFERROR($C41*BJ39,"") -> 500000 | BN41: =IFERROR($C41*BN39,"") -> 500000 | BR41: =IFERROR($C41*BR39,"") -> 0 | BV41: =IFERROR($C41*BV39,"") -> 0 | BZ41: =IFERROR($C41*BZ39,"") -> 0 | CD41: =IFERROR($C41*CD39,"") -> 0 | CH41: =IFERROR($C41*CH39,"") -> 0 | CL41: =IFERROR($C41*CL39,"") -> 0 | CP41: =IFERROR($C41*CP39,"") -> 0 | CT41: =IFERROR($C41*CT39,"") -> 0 | CX41: =IFERROR($C41*CX39,"") -> 0 | DB41: =IFERROR($C41*DB39,"") -> 0 | DF41: =IFERROR($C41*DF39,"") -> 0 | DJ41: =IFERROR($C41*DJ39,"") -> 0 | DN41: =IFERROR($C41*DN39,"") -> 0 | DR41: =IFERROR($C41*DR39,"") -> 0 | DV41: =IFERROR($C41*DV39,"") -> 0 | DZ41: =IFERROR($C41*DZ39,"") -> 0 | ED41: =IFERROR($C41*ED39,"") -> 0 | EH41: =IFERROR($C41*EH39,"") -> 0 | EL41: =IFERROR($C41*EL39,"") -> 0 | EP41: =IFERROR($C41*EP39,"") -> 0
B42: SE4 | D42: 工数 | E42: =SUM(F42:ES42) -> 9 | N42: 1 | R42: 1 | V42: 1 | Z42: 1 | AD42: 1 | BB42: 1 | BF42: 1 | BJ42: 1 | BN42: 1
...
