Workbook

Sheet 依頼概要
B3: 1. 経緯
B4: 館林DCセンターの廃止に伴い、現在のサーバ郡を移転する必要がある。
B5: 期日までに以下のいずれかの対応をとる必要がある。
B6: （２）Azureに構築される縮小版の共通基盤に移行
B7: ※現状よりスペックは低下、Oracleは19C
B8: 加えて、館林DC以外（現地）のサーバに関してWindows2016サーバはサポート期限切れに伴い、再構築を行う必要がある。
B11: 2. 依頼事項
B12: 各システム毎に概算見積を行ってほしい。
B13: （２）Azureに構築される縮小版の共通基盤に移行
C14: 対象：現行共通基盤を利用しているシステム
C15: 時期：2025年度1Q以降見込
C16: 出光側で構築した縮小版共通基盤へアプリ、帳票、バッチを移行
C17: 縮小版共通基盤の構成は現行共通基盤を踏襲した形となるが、OS,MWのバージョンは変更となる見込み
B20: 3. 希望期日
B21: 2024/12中に概算見積提示
B24: 顧客受領資料より

Sheet 想定作業
A1: 前提
B2: 業務・機能変更は行わない。
B3: サーバ構成は現行踏襲とする。
B4: DBは現行踏襲（Oracle、SQLSever継続）
B5: JavaフレームワークはStruts継続
B6: テストは新規構築した本番環境（次期本番機）にて行う。
B7: 開始時期を2025/4月以降
B8: ※検証、予備環境は最低限の動作確認（アプリ起動、ログイン確認程度）を想定
A11: 想定作業
A12: 全パターン共通
B13: IP,ホスト名変更に伴う各種（IF、DB等）向け先変更、検証
B14: アプリ動作検証（全画面、帳票、バッチ、IF打鍵 ※初期画面の描画や正常系の動作に問題がないことを確認）
B15: アプリケーション構築、ミドルウェアのセットアップ ※デプロイ作業のみ想定
B16: ※関連基盤の切り替えは完了しており、アプリケーションのAzure移行の切り替え作業は1回の未実施を想定（基盤切り替えが複数回発生する場合は別途工数が必要となります）
A18: （２）Azureに構築される縮小版の共通基盤に移行
B19: 全パターン共通の作業のみ

Sheet 概要図(千葉)
C1: ファイル連携 | F1: 工場系保守対象 | I1: 館林管理
C2: DBデータ連携 | F2: 工場系保守対象外 | I2: 現地管理
K63: Azure環境
K121: Azure環境

Sheet 概要図(徳山)
C1: ファイル連携 | F1: 工場系保守対象 | I1: 館林管理
C2: DBデータ連携 | F2: 工場系保守対象外 | I2: 現地管理
C60: Azure環境
C114: Azure環境

Sheet システム概要
E1: システム概要 | M1: システム規模 | S1: 共通基盤利用状況（現状）
A2: サービス: サービス番号 | B2: サービス名 | C2: 保守領域 | D2: 移行状況 | E2: 業務概要 | F2: OS | G2: アプリ | H2: DB | I2: ミドルウェア | J2: フレームワーク | K2: その他 | L2: サーバ構成 | M2: 画面 | N2: 帳票 | O2: バッチ | P2: IF | Q2: テーブル | R2: その他 | S2: 共通AP | T2: 共通DB | U2: 連携 | V2: レポート | W2: 認証 | X2: バッチ
A3: SVC-00000710 | B3: 数量確定システム(千葉) | C3: 工場系 | D3: 縮小共通基盤移行中 ⇒クラウドアーキ環境へ移行へ方針変更 | E3: 千葉事業所及び徳山事業所の石油化学装置の生産、在庫、PL(パイプライン)出荷、品目転換数量の管理を行うシステム。またタンクヤードの日報作成(ヤード日報)機能も持つ。 | F3: Red Hat Enterprise Linux7.3 | G3: java 1.8.0_202 Tomcat 9.0 | H3: Oracle19C | I3: A-AUTO | J3: struts 1.2.9 | L3: 本番 共通基盤（館林） 検証 共通基盤（館林） | M3: 千葉：41 徳山：30 | N3: 千葉：23 徳山：7 | O3: 共通：2 千葉：9 徳山：4 | P3: 千葉：8 徳山：4 | Q3: 共通：58 千葉：16 徳山：9 | S3: 〇 | T3: 〇 | U3: 〇 | V3: × | W3: 〇 | X3: 〇 | Y3: e
A4: SVC-00000857 | B4: 数量確定システム(徳山) | Y4: e
A5: - | B5: 用役管理システム(千葉工場) | C5: 工場系 | D5: 縮小共通基盤移行中 ⇒クラウドアーキ環境へ移行へ方針変更 | E5: 石油化学装置の生産数量、用役数量の管理を行うシステム。 | F5: Red Hat Enterprise Linux7.3 | G5: java 1.8.0_202 Tomcat 9.0 | H5: Oracle19C | I5: A-AUTO | J5: struts 1.2.9 | L5: 本番 共通基盤（館林） 検証 共通基盤（館林） | M5: 千葉：28 徳山：17 | N5: 千葉：43 徳山：6 | O5: 共通：0 千葉：0 徳山：0 | P5: 千葉：0 徳山：0 | Q5: 共通：11 千葉：1 徳山：11 | S5: 〇 | T5: 〇 | U5: 〇 | V5: × | W5: 〇 | X5: 〇 | Y5: e
A6: SVC-00000858 | B6: 用役管理システム(徳山工場) | Y6: e
A7: SVC-00001700 | B7: 千葉化学品質管理システム | C7: 工場系 | D7: 縮小共通基盤移行中 ⇒クラウドアーキ環境へ移行へ方針変更 | E7: 千葉事業所(工場)の品質管理課にて行う各種試験(工程、製品、物性)、及びそれに付随する業務(ロット管理、試験料金計算)を行うシステム。 | F7: Red Hat Enterprise Linux7.3 | G7: java 1.8.0_202 Tomcat 9.0 | H7: Oracle19C | I7: A-AUTO | J7: struts 1.2.9 | K7: List Creatorでの帳票作成 | L7: 本番 共通基盤（館林） 検証 共通基盤（館林） | M7: 83 | N7: 25 | O7: 5 | P7: 4 | Q7: 67 | S7: 〇 | T7: 〇 | U7: 〇 | V7: 〇 | W7: 〇 | X7: 〇 | Y7: e
A8: SVC-00000854 | B8: ＬＭＰＰ包装システム | C8: 工場系 | D8: 縮小共通基盤移行中 ⇒クラウドアーキ環境へ移行へ方針変更 | E8: 千葉事業所(工場)のSPS、LMPP装置で生産される製品の包装管理を行うシステム。 | F8: Red Hat Enterprise Linux7.3 | G8: java 1.8.0_202 Tomcat 9.0 | H8: Oracle19C | I8: A-AUTO | J8: struts 1.2.9 | K8: List Creatorでの帳票作成 | L8: 本番 共通基盤（館林） 検証 共通基盤（館林） | M8: 17 | N8: 3 | O8: 1 | P8: 3 | Q8: 12 | S8: 〇 | T8: 〇 | U8: 〇 | V8: 〇 | W8: 〇 | X8: 〇 | Y8: e
A9: SVC-00000877 | B9: 工場DB | C9: 工場系 | D9: 縮小共通基盤移行中 ⇒クラウドアーキ環境へ移行へ方針変更 ※アプリはXenApp | E9: 徳山事業所の石油化学装置の生産、在庫の計画値及び実績値を管理するDB及びエクセルマクロ群。 | F9: - | G9: Excel | H9: Oracle19C | I9: - | J9: - | L9: 本番 共通基盤（館林） 検証 共通基盤（館林） | M9: 0 | N9: 0 | O9: 0 | P9: 0 | Q9: 211 | S9: × | T9: 〇 | U9: × | V9: × | W9: × | X9: × | Y9: e
A10: SVC-00000705 | B10: 千葉ヤ－ド操業システム | C10: 工場系 | D10: OS更新対応にて現地サーバ構築済み | E10: 千葉事業所及び徳山事業所の石油化学品の入出荷を管理するシステム。 | F10: WindowsServer2022 | G10: java 1.8.0_152 WebLogic 12.2.1.2.0 | H10: SQLServer2022 | I10: A-AUTO | J10: struts 1.2.9 | L10: 本番 AP/DBサーバ×2（現地） AP/DB予備×2（館林） 検証 AP/DBサーバ×2（館林） | M10: 80 | N10: 20 | O10: 千葉：20 徳山：19 | P10: 千葉：16 徳山：15 | Q10: 75 | S10: × | T10: 〇 | U10: 〇 | V10: × | W10: 〇 | X10: × | Y10: e
A11: SVC-00000707 | B11: 徳山ヤ－ド操業システム | S11: × | T11: 〇 | U11: 〇 | V11: × | W11: 〇 | X11: × | Y11: e
A12: SVC-00000704 | B12: 千葉製品倉庫システム | C12: 工場系 | D12: 未実施（現地サーバ） | E12: 千葉事業所(工場)で生産されているポリマー製品の包装、入出荷、在庫管理を行うシステム。 | F12: WindowsServer2016 | G12: VB.NET | H12: Oracle12C | I12: Systemwalker Operation Manager OWFT | L12: 本番 AP/DBサーバ（現地） 検証 APサーバ（館林） | M12: 68 | N12: 43 | O12: 9 | P12: 45 | Q12: 205 | S12: × | T12: × | U12: 〇 | V12: × | W12: × | X12: × | Y12: e
A13: SVC-00000901 | B13: 千葉工場数量確定システム（ポリマ－） | C13: 工場系 | D13: 未実施（現地サーバ） | E13: 千葉事業所(工場)で生産されているポリマー製品の生産、在庫、PL(パイプライン)出荷、品目転換数量の管理を行うシステム。 | F13: WindowsServer2016 | G13: ASP.NET | H13: Oracle12C | I13: Systemwalker Operation Manager OWFT | M13: 20 | N13: 4 | O13: 2 | P13: 2 | Q13: 30 | S13: × | T13: × | U13: × | V13: × | W13: × | X13: × | Y13: e
A14: SVC-00000711 | B14: ＡＢＣ数量確定システム | C14: 工場系 | D14: 未実施（現地サーバ） | E14: 千葉事業所(工場)のABC装置で生産される製品の生産管理を行うシステム。 | F14: WindowsServer2016 | G14: C# | H14: Oracle12C | I14: Systemwalker Operation Manager OWFT | M14: 15 | N14: 0 | O14: 12 | P14: 5 | Q14: 24 | S14: × | T14: × | U14: × | V14: × | W14: × | X14: × | Y14: e
A15: - | B15: 千葉L3.5 | C15: 工場系 | D15: 未実施（現地サーバ） | E15: L3層に存在するシステムとL4層に存在するシステムの中継となるサーバ | F15: WindowsServer2016 | G15: - | H15: - | I15: Systemwalker Operation Manager OWFT | J15: - | L15: 本番 APサーバ（現地） 検証 APサーバ（館林） | M15: 0 | N15: 0 | O15: 2 | P15: 千葉：52 徳山：14 | Q15: 0 | S15: × | T15: × | U15: × | V15: × | W15: × | X15: ×
A16: - | B16: 徳山L3.5 | S16: × | T16: × | U16: × | V16: × | W16: × | X16: ×
A17: SVC-00001969 | B17: 用役集計 | C17: 工場系 | D17: excelファイルでの構築の為不要 | E17: 用役管理システムで出力した帳票のデータをOneSAPへ連携する為のシステム。 | G17: Excel | S17: - | T17: 不明 | U17: - | V17: - | W17: - | X17: - | Y17: e
A18: SVC-00001975 | B18: PRM HULFT | C18: 工場系 | D18: 2023年Azure移行済み | E18: PRMSAP⇔製品倉庫等PRMシステムの連携中継サーバ | S18: × | T18: × | U18: × | V18: × | W18: × | X18: × | Y18: e
A19: SVC-00000702 | B19: ロット管理明細表システム（PRM） | C19: 工場系 | D19: XenAppにて稼働 | G19: Excel | S19: × | T19: × | U19: × | V19: × | W19: × | X19: × | Y19: e
A20: SVC-00000706 | B20: 工場ロ－カルＥｘｃｅｌシステム | C20: 工場系 | S20: × | T20: 不明 | U20: × | V20: × | W20: × | X20: × | Y20: e
A21: SVC-00000876 | B21: スクラップ管理システム | C21: 工場系 | S21: × | T21: × | U21: × | V21: × | W21: × | X21: × | Y21: e

Sheet パターン別お見積り
B3: No | C3: パターン | D3: 説明 | E3: 金額
B4: 1 | C4: 次期アーキへ移行 | D4: 次期アーキへ移行のため概算総額 | E4: ='見積 (システム別・基盤対応別サマリ) '!K13 -> 68960000
B5: 1-1 | D5: 上記の内、次期アーキ要件定義フェーズ金額 | E5: =SUM('見積 (システム別・契約変更)_内部'!M6:M11) -> 12020000
B6: 1-2 | D6: 次期アーキ要件定義を現契約で実施するにあたり、現契約から追加で必要な金額 | E6: ='見積 (システム別・契約変更)_内部'!Q13 -> 5213000
B7: 2 | C7: 縮小共通基盤へ移行 | D7: 中断中の移行フェーズを再開するにあたり、現契約から追加で必要な金額 | E7: ='見積 (縮小共通基盤継続） '!D22 -> 6549000
B8: 3 | C8: 縮小共通基盤へ移行後、次期アーキへ移行 | D8: No1+No2 | E8: ='見積 (システム別・縮小共通基盤⇒クラウドアーキサマリ) '!M14 -> 75509000

Sheet 見積 (縮小共通基盤継続） 
C1: 工数直入力のため注意！！
C2: 移行フェーズ作業実績
G3: 備考
B4: No. | C4: 月 | D4: 作業内容 | E4: 工数 | F4: 金額
B5: 1 | C5: 7月（当初予定作業） | D5: 縮小共通基盤移行作業 ・環境構築 ・システムテスト準備 | E5: 2.335 | F5: 2444000
B6: 2 | C6: 8月（当初予定外作業） | D6: 次期アーキに向けた調査・検証作業 | E6: 4.38 | F6: 4366000
B7: 3 | C7: 9月（当初予定外作業） | D7: 次期アーキに向けた調査・検証作業 | E7: 2.2 | F7: 2183000 | G7: 9月中旬に方針確定と想定し、8月の0.5人月分で算出
B8: 計 | E8: =SUM(E5:E7) -> 8.915 | F8: =SUM(F5:F7) -> 8993000
C11: 案件名 | D11: 見積金額
C12: LMPP包装システム Azure移行（移行フェーズ） | D12: 2160000
C13: 千葉化学品質管理システム Azure移行（移行フェーズ） | D13: 2160000
C14: 数量確定システム Azure移行（移行フェーズ） | D14: 5440000
C15: 用役管理システム Azure移行（移行フェーズ） | D15: 5300000
C16: 工場DB Azure移行（移行フェーズ） | D16: 740000
B17: ① | C17: 現契約合計 | D17: =SUM(D12:D16) -> 15800000
B18: ② | C18: 縮小共通基盤作業実績（7月作業実績） | D18: =F5 -> 2444000
B19: ③ | C19: 縮小共通基盤残作業分費用 （①-②） | D19: =D17-F5 -> 13356000
B20: ④ | C20: 次期アーキ調査・検証分費用 （8月、9月作業実績） | D20: =SUM(F6:F7) -> 6549000
B21: ⑤ | C21: 現契約残額（①-②-④） | D21: =D17-D18-D20 -> 6807000
B22: ⑥ | C22: 追加発注分（③-⑤） | D22: =D19-D21 -> 6549000
D23: ※ヤード認証基盤対応分は除く

Sheet 見積 (システム別・契約変更)_内部
C2: 調査・要件定義（次期アーキ要件定義を現契約で実施）
C3: パターン | D3: クラウドアーキ基盤に移行 | R3: 備考
D4: アプリ | N4: DB | P4: 全体
B5: No. | C5: システム | D5: 調査・要件定義 | E5: 設計 | F5: 製造 | G5: 結合テスト | H5: システムテスト | I5: ユーザテスト | J5: 本番稼働 | K5: 管理 | L5: 工数計 | M5: 金額 | N5: 工数計 | O5: 金額 | P5: 工数計 | Q5: 金額
B6: 1 | C6: 数量確定システム（千葉・徳山） | D6: 3.2 | K6: 0.9 | L6: =SUM(D6:K6) -> 4.1 | M6: =SUM(D6:J6)*1000000+K6*1400000 -> 4460000 | N6: 0 | O6: 0 | P6: =SUM(L6:L10)+N6 -> 10.2 | Q6: =SUM(M6:M10)+O6 -> 11240000
B7: 2 | C7: 用役管理システム（千葉・徳山） | D7: 1.4 | K7: 0.6 | L7: =SUM(D7:K7) -> 2 | M7: =SUM(D7:J7)*1000000+K7*1400000 -> 2240000
B8: 3 | C8: 千葉化学品質管理システム | D8: 1.7 | K8: 0.6 | L8: =SUM(D8:K8) -> 2.3 | M8: =SUM(D8:J8)*1000000+K8*1400000 -> 2540000
B9: 4 | C9: ＬＭＰＰ包装システム | D9: 1.3 | K9: 0.5 | L9: =SUM(D9:K9) -> 1.8 | M9: =SUM(D9:J9)*1000000+K9*1400000 -> 2000000
B10: 5 | C10: 工場DB | L10: =SUM(D10:K10) -> 0 | M10: =SUM(D10:J10)*1000000+K10*1400000 -> 0
B11: 6 | C11: ヤ－ド操業システム（千葉・徳山） | D11: 0.5 | K11: 0.2 | L11: =SUM(D11:K11) -> 0.7 | M11: =SUM(D11:J11)*1000000+K11*1400000 -> 780000 | P11: =SUM(L11:L11)+N11 -> 0.7 | Q11: =SUM(M11:M11)+O11 -> 780000
B12: 7 | C12: 縮小共通基盤（移行フェーズ） | L12: =SUM(D12:K12) -> 0 | M12: -6807000 | P12: =SUM(L12:L12)+N12 -> 0 | Q12: =SUM(M12:M12)+O6 -> -6807000 | R12: 現契約残額を差し引き
B13: 計 | D13: =SUM(D6:D12) -> 8.1 | E13: =SUM(E6:E12) -> 0 | F13: =SUM(F6:F12) -> 0 | G13: =SUM(G6:G12) -> 0 | H13: =SUM(H6:H12) -> 0 | I13: =SUM(I6:I12) -> 0 | J13: =SUM(J6:J12) -> 0 | K13: =SUM(K7:K12) -> 1.9 | L13: =SUM(D13:K13) -> 10 | M13: =SUM(M6:M12) -> 5213000 | N13: =SUM(N6:N12) -> 0 | O13: =SUM(O6:O12) -> 0 | P13: =SUM(P6:P12) -> 10.9 | Q13: =SUM(Q6:Q12) -> 5213000
B14: 単価 | D14: 1000000 | E14: 1000000 | F14: 1000000 | G14: 1000000 | H14: 1000000 | I14: 1000000 | J14: 1000000 | K14: 1400000
B15: 金額 | D15: =D13*D14 -> 8100000 | E15: =E13*E14 -> 0 | F15: =F13*F14 -> 0 | G15: =G13*G14 -> 0 | H15: =H13*H14 -> 0 | I15: =I13*I14 -> 0 | J15: =J13*J14 -> 0 | K15: =K13*K14 -> 2660000
C17: （参考）次期アーキへ移行のため概算総額
C18: パターン | D18: クラウドアーキ基盤に移行 | R18: 備考
D19: アプリ | N19: DB | P19: 全体
B20: No. | C20: システム | D20: 調査・要件定義 | E20: 設計 | F20: 製造 | G20: 結合テスト | H20: システムテスト | I20: ユーザテスト | J20: 本番稼働 | K20: 管理 | L20: 工数計 | M20: 金額 | N20: 工数計 | O20: 金額 | P20: 工数計 | Q20: 金額
B21: 1 | C21: 数量確定システム（千葉・徳山） | D21: 3.2 | E21: 1.6 | F21: 2.7 | G21: 5.2 | H21: 1.4 | I21: 0.8 | J21: 2 | K21: 3.8 | L21: =SUM(D21:K21) -> 20.7 | M21: =SUM(D21:J21)*1000000+K21*1400000 -> 22220000 | N21: 0 | O21: 0 | P21: =SUM(L21:L25)+N21 -> 58.3 | Q21: =SUM(M21:M25)+O21 -> 62900000
B22: 2 | C22: 用役管理システム（千葉・徳山） | D22: 1.4 | E22: 1.1 | F22: 1.5 | G22: 3.1 | H22: 1.1 | I22: 0.8 | J22: 2 | K22: 2.6 | L22: =SUM(D22:K22) -> 13.6 | M22: =SUM(D22:J22)*1000000+K22*1400000 -> 14640000
B23: 3 | C23: 千葉化学品質管理システム | D23: 1.7 | E23: 1.4 | F23: 1.6 | G23: 5.5 | H23: 0.8 | I23: 0.5 | J23: 0.6 | K23: 2.7 | L23: =SUM(D23:K23) -> 14.8 | M23: =SUM(D23:J23)*1000000+K23*1400000 -> 15880000
B24: 4 | C24: ＬＭＰＰ包装システム | D24: 1.3 | E24: 0.4 | F24: 1.6 | G24: 1.2 | H24: 0.8 | I24: 0.5 | J24: 0.6 | K24: 1.9 | L24: =SUM(D24:K24) -> 8.3 | M24: =SUM(D24:J24)*1000000+K24*1400000 -> 9060000
B25: 5 | C25: 工場DB | J25: 0.4 | K25: 0.5 | L25: =SUM(D25:K25) -> 0.9 | M25: =SUM(D25:J25)*1000000+K25*1400000 -> 1100000
B26: 6 | C26: ヤ－ド操業システム（千葉・徳山） | D26: 0.5 | E26: 0.4 | F26: 0.7 | G26: 1.4 | H26: 0.2 | I26: 0.1 | J26: 1.5 | K26: 0.9 | L26: =SUM(D26:K26) -> 5.7 | M26: =SUM(D26:J26)*1000000+K26*1400000 -> 6060000 | N26: 0 | O26: =SUM(O20:O25) -> 0 | P26: =SUM(L26:L26)+N26 -> 5.7 | Q26: =SUM(M26:M26)+O21 -> 6060000
B27: 計 | D27: =SUM(D21:D26) -> 8.1 | E27: =SUM(E21:E26) -> 4.9 | F27: =SUM(F21:F26) -> 8.1 | G27: =SUM(G21:G26) -> 16.4 | H27: =SUM(H21:H26) -> 4.3 | I27: =SUM(I21:I26) -> 2.7 | J27: =SUM(J21:J26) -> 7.1 | K27: =SUM(K21:K26) -> 12.4 | L27: =SUM(D27:K27) -> 64 | M27: =SUM(M21:M26) -> 68960000 | N27: =SUM(N21:N26) -> 0 | O27: =SUM(O21:O26) -> 0 | P27: =SUM(P21:P26) -> 64 | Q27: =SUM(Q21:Q26) -> 68960000
B28: 単価 | D28: 1000000 | E28: 1000000 | F28: 1000000 | G28: 1000000 | H28: 1000000 | I28: 1000000 | J28: 1000000 | K28: 1400000
B29: 金額 | D29: =D27*D28 -> 8100000 | E29: =E27*E28 -> 4900000 | F29: =F27*F28 -> 8100000 | G29: =G27*G28 -> 16400000 | H29: =H27*H28 -> 4300000 | I29: =I27*I28 -> 2700000 | J29: =J27*J28 -> 7100000 | K29: =K27*K28 -> 17360000
C31: （参考）調査・要件定義(クラウドアーキから開始)
C32: パターン | D32: クラウドアーキ基盤に移行 | R32: 備考
D33: アプリ | N33: DB | P33: 全体
B34: No. | C34: システム | D34: 調査・要件定義 | E34: 設計 | F34: 製造 | G34: 結合テスト | H34: システムテスト | I34: ユーザテスト | J34: 本番稼働 | K34: 管理 | L34: 工数計 | M34: 金額 | N34: 工数計 | O34: 金額 | P34: 工数計 | Q34: 金額
B35: 1 | C35: 数量確定システム（千葉・徳山） | D35: 3.2 | K35: 0.9 | L35: =SUM(D35:K35) -> 4.1 | M35: =SUM(D35:J35)*1000000+K35*1400000 -> 4460000 | N35: 0 | O35: 0 | P35: =SUM(L35:L39)+N35 -> 10.2 | Q35: =SUM(M35:M39)+O35 -> 11240000
B36: 2 | C36: 用役管理システム（千葉・徳山） | D36: 1.4 | K36: 0.6 | L36: =SUM(D36:K36) -> 2 | M36: =SUM(D36:J36)*1000000+K36*1400000 -> 2240000
B37: 3 | C37: 千葉化学品質管理システム | D37: 1.7 | K37: 0.6 | L37: =SUM(D37:K37) -> 2.3 | M37: =SUM(D37:J37)*1000000+K37*1400000 -> 2540000
B38: 4 | C38: ＬＭＰＰ包装システム | D38: 1.3 | K38: 0.5 | L38: =SUM(D38:K38) -> 1.8 | M38: =SUM(D38:J38)*1000000+K38*1400000 -> 2000000
B39: 5 | C39: 工場DB | L39: =SUM(D39:K39) -> 0 | M39: =SUM(D39:J39)*1000000+K39*1400000 -> 0
B40: 6 | C40: ヤ－ド操業システム（千葉・徳山） | D40: 0.5 | K40: 0.2 | L40: =SUM(D40:K40) -> 0.7 | M40: =SUM(D40:J40)*1000000+K40*1400000 -> 780000 | P40: =SUM(L40:L40)+N40 -> 0.7 | Q40: =SUM(M40:M40)+O35 -> 780000
B41: 計 | D41: =SUM(D35:D40) -> 8.1 | E41: =SUM(E35:E40) -> 0 | F41: =SUM(F35:F40) -> 0 | G41: =SUM(G35:G40) -> 0 | H41: =SUM(H35:H40) -> 0 | I41: =SUM(I35:I40) -> 0 | J41: =SUM(J35:J40) -> 0 | K41: =SUM(K36:K40) -> 1.9 | L41: =SUM(D41:K41) -> 10 | M41: =SUM(M35:M40) -> 12020000 | N41: =SUM(N35:N40) -> 0 | O41: =SUM(O35:O40) -> 0 | P41: =SUM(P35:P40) -> 10.9 | Q41: =SUM(Q35:Q40) -> 12020000
B42: 単価 | D42: 1000000 | E42: 1000000 | F42: 1000000 | G42: 1000000 | H42: 1000000 | I42: 1000000 | J42: 1000000 | K42: 1400000
B43: 金額 | D43: =D41*D42 -> 8100000 | E43: =E41*E42 -> 0 | F43: =F41*F42 -> 0 | G43: =G41*G42 -> 0 | H43: =H41*H42 -> 0 | I43: =I41*I42 -> 0 | J43: =J41*J42 -> 0 | K43: =K41*K42 -> 2660000

Sheet 見積 (システム別・契約変更) _顧客提示
C2: 顧客予算都合により、品管システム分の一部（\4,880,000）を包装システムに回す
C3: パターン | D3: クラウドアーキ基盤に移行 | R3: 備考
D4: アプリ | N4: DB | P4: 全体
B5: No. | C5: システム | D5: 調査・要件定義 | E5: 設計 | F5: 製造 | G5: 結合テスト | H5: システムテスト | I5: ユーザテスト | J5: 本番稼働 | K5: 管理 | L5: 工数計 | M5: 金額 | N5: 工数計 | O5: 金額 | P5: 工数計 | Q5: 金額
B6: 1 | C6: 数量確定システム（千葉・徳山） | D6: 3.2 | E6: 1.6 | F6: 2.7 | G6: 5.2 | H6: 1.4 | I6: 0.8 | J6: 2 | K6: 3.8 | L6: =SUM(D6:K6) -> 20.7 | M6: =SUM(D6:J6)*1000000+K6*1400000 -> 22220000 | N6: 0 | O6: 0 | P6: =SUM(L6:L10)+N6 -> 58.3 | Q6: =SUM(M6:M10)+O6 -> 62900000
B7: 2 | C7: 用役管理システム（千葉・徳山） | D7: 1.4 | E7: 1.1 | F7: 1.5 | G7: 3.1 | H7: 1.1 | I7: 0.8 | J7: 2 | K7: 2.6 | L7: =SUM(D7:K7) -> 13.6 | M7: =SUM(D7:J7)*1000000+K7*1400000 -> 14640000
B8: 3 | C8: 千葉化学品質管理システム | D8: 1.5 | E8: 0.9 | F8: 1.2 | G8: 3.1 | H8: 0.6 | I8: 0.3 | J8: 0.3 | K8: 2.2 | L8: =SUM(D8:K8) -> 10.1 | M8: =SUM(D8:J8)*1000000+K8*1400000 -> 10980000
B9: 4 | C9: ＬＭＰＰ包装システム | D9: 1.5 | E9: 0.9 | F9: 2 | G9: 3.6 | H9: 1 | I9: 0.7 | J9: 0.9 | K9: 2.4 | L9: =SUM(D9:K9) -> 13 | M9: =SUM(D9:J9)*1000000+K9*1400000 -> 13960000
B10: 5 | C10: 工場DB | J10: 0.4 | K10: 0.5 | L10: =SUM(D10:K10) -> 0.9 | M10: =SUM(D10:J10)*1000000+K10*1400000 -> 1100000
B11: 6 | C11: ヤ－ド操業システム（千葉・徳山） | D11: 0.5 | E11: 0.4 | F11: 0.7 | G11: 1.4 | H11: 0.2 | I11: 0.1 | J11: 1.5 | K11: 0.9 | L11: =SUM(D11:K11) -> 5.7 | M11: =SUM(D11:J11)*1000000+K11*1400000 -> 6060000 | N11: 0 | O11: =SUM(O5:O10) -> 0 | P11: =SUM(L11:L11)+N11 -> 5.7 | Q11: =SUM(M11:M11)+O6 -> 6060000
B12: 計 | D12: =SUM(D6:D11) -> 8.1 | E12: =SUM(E6:E11) -> 4.9 | F12: =SUM(F6:F11) -> 8.1 | G12: =SUM(G6:G11) -> 16.4 | H12: =SUM(H6:H11) -> 4.3 | I12: =SUM(I6:I11) -> 2.7 | J12: =SUM(J6:J11) -> 7.1 | K12: =SUM(K6:K11) -> 12.4 | L12: =SUM(D12:K12) -> 64 | M12: =SUM(M6:M11) -> 68960000 | N12: =SUM(N6:N11) -> 0 | O12: =SUM(O6:O11) -> 0 | P12: =SUM(P6:P11) -> 64 | Q12: =SUM(Q6:Q11) -> 68960000
B13: 単価 | D13: 1000000 | E13: 1000000 | F13: 1000000 | G13: 1000000 | H13: 1000000 | I13: 1000000 | J13: 1000000 | K13: 1400000
B14: 金額 | D14: =D12*D13 -> 8100000 | E14: =E12*E13 -> 4900000 | F14: =F12*F13 -> 8100000 | G14: =G12*G13 -> 16400000 | H14: =H12*H13 -> 4300000 | I14: =I12*I13 -> 2700000 | J14: =J12*J13 -> 7100000 | K14: =K12*K13 -> 17360000
L15: 品管差額 | M15: =M22-M8 -> 4900000
C16: 変更前 | L16: 包装差額 | M16: =M23-M9 -> -4900000
C17: パターン | D17: クラウドアーキ基盤に移行 | R17: 備考
D18: アプリ | N18: DB | P18: 全体
B19: No. | C19: システム | D19: 調査・要件定義 | E19: 設計 | F19: 製造 | G19: 結合テスト | H19: システムテスト | I19: ユーザテスト | J19: 本番稼働 | K19: 管理 | L19: 工数計 | M19: 金額 | N19: 工数計 | O19: 金額 | P19: 工数計 | Q19: 金額
B20: 1 | C20: 数量確定システム（千葉・徳山） | D20: 3.2 | E20: 1.6 | F20: 2.7 | G20: 5.2 | H20: 1.4 | I20: 0.8 | J20: 2 | K20: 3.8 | L20: =SUM(D20:K20) -> 20.7 | M20: =SUM(D20:J20)*1000000+K20*1400000 -> 22220000 | N20: 0 | O20: 0 | P20: =SUM(L20:L24)+N20 -> 58.3 | Q20: =SUM(M20:M24)+O20 -> 62900000
B21: 2 | C21: 用役管理システム（千葉・徳山） | D21: 1.4 | E21: 1.1 | F21: 1.5 | G21: 3.1 | H21: 1.1 | I21: 0.8 | J21: 2 | K21: 2.6 | L21: =SUM(D21:K21) -> 13.6 | M21: =SUM(D21:J21)*1000000+K21*1400000 -> 14640000
B22: 3 | C22: 千葉化学品質管理システム | D22: 1.7 | E22: 1.4 | F22: 1.6 | G22: 5.5 | H22: 0.8 | I22: 0.5 | J22: 0.6 | K22: 2.7 | L22: =SUM(D22:K22) -> 14.8 | M22: =SUM(D22:J22)*1000000+K22*1400000 -> 15880000
B23: 4 | C23: ＬＭＰＰ包装システム | D23: 1.3 | E23: 0.4 | F23: 1.6 | G23: 1.2 | H23: 0.8 | I23: 0.5 | J23: 0.6 | K23: 1.9 | L23: =SUM(D23:K23) -> 8.3 | M23: =SUM(D23:J23)*1000000+K23*1400000 -> 9060000
B24: 5 | C24: 工場DB | J24: 0.4 | K24: 0.5 | L24: =SUM(D24:K24) -> 0.9 | M24: =SUM(D24:J24)*1000000+K24*1400000 -> 1100000
B25: 6 | C25: ヤ－ド操業システム（千葉・徳山） | D25: 0.5 | E25: 0.4 | F25: 0.7 | G25: 1.4 | H25: 0.2 | I25: 0.1 | J25: 1.5 | K25: 0.9 | L25: =SUM(D25:K25) -> 5.7 | M25: =SUM(D25:J25)*1000000+K25*1400000 -> 6060000 | N25: 0 | O25: =SUM(O19:O24) -> 0 | P25: =SUM(L25:L25)+N25 -> 5.7 | Q25: =SUM(M25:M25)+O20 -> 6060000
B26: 計 | D26: =SUM(D20:D25) -> 8.1 | E26: =SUM(E20:E25) -> 4.9 | F26: =SUM(F20:F25) -> 8.1 | G26: =SUM(G20:G25) -> 16.4 | H26: =SUM(H20:H25) -> 4.3 | I26: =SUM(I20:I25) -> 2.7 | J26: =SUM(J20:J25) -> 7.1 | K26: =SUM(K20:K25) -> 12.4 | L26: =SUM(D26:K26) -> 64 | M26: =SUM(M20:M25) -> 68960000 | N26: =SUM(N20:N25) -> 0 | O26: =SUM(O20:O25) -> 0 | P26: =SUM(P20:P25) -> 64 | Q26: =SUM(Q20:Q25) -> 68960000
B27: 単価 | D27: 1000000 | E27: 1000000 | F27: 1000000 | G27: 1000000 | H27: 1000000 | I27: 1000000 | J27: 1000000 | K27: 1400000
B28: 金額 | D28: =D26*D27 -> 8100000 | E28: =E26*E27 -> 4900000 | F28: =F26*F27 -> 8100000 | G28: =G26*G27 -> 16400000 | H28: =H26*H27 -> 4300000 | I28: =I26*I27 -> 2700000 | J28: =J26*J27 -> 7100000 | K28: =K26*K27 -> 17360000
C30: 要件定義＿顧客予算都合により、品管システム分の一部（\4,880,000）を包装システムに回す
C31: パターン | D31: クラウドアーキ基盤に移行 | R31: 備考
D32: アプリ | N32: DB | P32: 全体
B33: No. | C33: システム | D33: 調査・要件定義 | E33: 設計 | F33: 製造 | G33: 結合テスト | H33: システムテスト | I33: ユーザテスト | J33: 本番稼働 | K33: 管理 | L33: 工数計 | M33: 金額 | N33: 工数計 | O33: 金額 | P33: 工数計 | Q33: 金額
B34: 1 | C34: 数量確定システム（千葉・徳山） | D34: 3.2 | K34: 0.9 | L34: =SUM(D34:K34) -> 4.1 | M34: =SUM(D34:J34)*1000000+K34*1400000 -> 4460000 | N34: 0 | O34: 0 | P34: =SUM(L34:L38)+N34 -> 10.2 | Q34: =SUM(M34:M38)+O34 -> 11240000
B35: 2 | C35: 用役管理システム（千葉・徳山） | D35: 1.4 | K35: 0.6 | L35: =SUM(D35:K35) -> 2 | M35: =SUM(D35:J35)*1000000+K35*1400000 -> 2240000
B36: 3 | C36: 千葉化学品質管理システム | D36: 1.5 | K36: 0.6 | L36: =SUM(D36:K36) -> 2.1 | M36: =SUM(D36:J36)*1000000+K36*1400000 -> 2340000
B37: 4 | C37: ＬＭＰＰ包装システム | D37: 1.5 | K37: 0.5 | L37: =SUM(D37:K37) -> 2 | M37: =SUM(D37:J37)*1000000+K37*1400000 -> 2200000
B38: 5 | C38: 工場DB | L38: =SUM(D38:K38) -> 0 | M38: =SUM(D38:J38)*1000000+K38*1400000 -> 0
B39: 6 | C39: ヤ－ド操業システム（千葉・徳山） | D39: 0.5 | K39: 0.2 | L39: =SUM(D39:K39) -> 0.7 | M39: =SUM(D39:J39)*1000000+K39*1400000 -> 780000 | P39: =SUM(L39:L39)+N39 -> 0.7 | Q39: =SUM(M39:M39)+O34 -> 780000
B40: 計 | D40: =SUM(D34:D39) -> 8.1 | E40: =SUM(E34:E39) -> 0 | F40: =SUM(F34:F39) -> 0 | G40: =SUM(G34:G39) -> 0 | H40: =SUM(H34:H39) -> 0 | I40: =SUM(I34:I39) -> 0 | J40: =SUM(J34:J39) -> 0 | K40: =SUM(K34:K39) -> 2.8 | L40: =SUM(D40:K40) -> 10.9 | M40: =SUM(M34:M39) -> 12020000 | N40: =SUM(N34:N39) -> 0 | O40: =SUM(O34:O39) -> 0 | P40: =SUM(P34:P39) -> 10.9 | Q40: =SUM(Q34:Q39) -> 12020000
B41: 単価 | D41: 1000000 | E41: 1000000 | F41: 1000000 | G41: 1000000 | H41: 1000000 | I41: 1000000 | J41: 1000000 | K41: 1400000
B42: 金額 | D42: =D40*D41 -> 8100000 | E42: =E40*E41 -> 0 | F42: =F40*F41 -> 0 | G42: =G40*G41 -> 0 | H42: =H40*H41 -> 0 | I42: =I40*I41 -> 0 | J42: =J40*J41 -> 0 | K42: =K40*K41 -> 3920000
...

Sheet 見積 (システム別・基盤対応別サマリ) 
C1: 工数直入力のため注意！！
C3: 見積 (基盤対応別サマリ)
C4: パターン | D4: クラウドアーキ基盤に移行 | P4: 備考
D5: アプリ | L5: DB | N5: 全体
B6: No. | C6: システム | D6: 共通 (基盤に関わらず共通して必要な作業) | E6: AP基盤 | F6: 認証基盤 | G6: バッチ基盤 | H6: DB基盤 | I6: 管理 | J6: 工数計 | K6: 金額 | L6: 工数計 | M6: 金額 | N6: 工数計 | O6: 金額
B7: 1 | C7: 数量確定システム（千葉・徳山） | D7: 5.5 | E7: 9.2 | F7: 1.3 | G7: 0.9 | H7: 0 | I7: 3.8 | J7: =SUM(D7:I7) -> 20.7 | K7: =SUM(D7:H7)*1000000+I7*1400000 -> 22220000 | L7: 0 | M7: 0 | N7: =SUM(J7:J11)+L7 -> 58.3 | O7: =SUM(K7:K11)+M7 -> 62900000
B8: 2 | C8: 用役管理システム（千葉・徳山） | D8: 5.2 | E8: 5.3 | F8: 0.5 | G8: 0 | H8: 0 | I8: 2.6 | J8: =SUM(D8:I8) -> 13.6 | K8: =SUM(D8:H8)*1000000+I8*1400000 -> 14640000
B9: 3 | C9: 千葉化学品質管理システム | D9: 3.2 | E9: 7 | F9: 1.2 | G9: 0.7 | H9: 0 | I9: 2.7 | J9: =SUM(D9:I9) -> 14.8 | K9: =SUM(D9:H9)*1000000+I9*1400000 -> 15880000
B10: 4 | C10: ＬＭＰＰ包装システム | D10: 2.2 | E10: 3 | F10: 0.6 | G10: 0.6 | H10: 0 | I10: 1.9 | J10: =SUM(D10:I10) -> 8.3 | K10: =SUM(D10:H10)*1000000+I10*1400000 -> 9060000
B11: 5 | C11: 工場DB | D11: 0.4 | I11: 0.5 | J11: =SUM(D11:I11) -> 0.9 | K11: =SUM(D11:H11)*1000000+I11*1400000 -> 1100000
B12: 6 | C12: ヤ－ド操業システム（千葉・徳山） | D12: 2.4 | E12: 0 | F12: 2.4 | G12: 0 | H12: 0 | I12: 0.9 | J12: =SUM(D12:I12) -> 5.7 | K12: =SUM(D12:H12)*1000000+I12*1400000 -> 6060000 | L12: 0 | M12: =SUM(M6:M11) -> 0 | N12: =SUM(J12:J12)+L12 -> 5.7 | O12: =SUM(K12:K12)+M7 -> 6060000
B13: 計 | D13: =SUM(D7:D12) -> 18.9 | E13: =SUM(E7:E12) -> 24.5 | F13: =SUM(F7:F12) -> 6 | G13: =SUM(G7:G12) -> 2.2 | H13: =SUM(H7:H12) -> 0 | I13: =SUM(I7:I12) -> 12.4 | J13: =SUM(D13:I13) -> 64 | K13: =SUM(K7:K12) -> 68960000 | L13: =SUM(L7:L12) -> 0 | M13: =SUM(M7:M12) -> 0 | N13: =SUM(N7:N12) -> 64 | O13: =SUM(O7:O12) -> 68960000
B14: 単価 | D14: 1000000 | E14: 1000000 | F14: 1000000 | G14: 1000000 | H14: 1000000 | I14: 1400000
B15: 金額 | D15: =D13*D14 -> 18900000 | E15: =E13*E14 -> 24500000 | F15: =F13*F14 -> 6000000 | G15: =G13*G14 -> 2200000 | H15: =H13*H14 -> 0 | I15: =I13*I14 -> 17360000

Sheet 見積 (システム別・縮小共通基盤⇒クラウドアーキサマリ) 
C1: 工数直入力のため注意！！
C3: 見積（縮小共通基盤⇒クラウドアーキサマリ）
C4: パターン | D4: クラウドアーキ基盤に移行 | R4: 備考
D5: アプリ | N5: DB | P5: 全体
B6: No. | C6: システム | D6: 調査・要件定義 | E6: 設計 | F6: 製造 | G6: 結合テスト | H6: システムテスト | I6: ユーザテスト | J6: 本番稼働 | K6: 管理 | L6: 工数計 | M6: 金額 | N6: 工数計 | O6: 金額 | P6: 工数計 | Q6: 金額
B7: 1 | C7: 数量確定システム（千葉・徳山） | D7: 3.2 | E7: 1.6 | F7: 2.7 | G7: 5.2 | H7: 1.4 | I7: 0.8 | J7: 2 | K7: 3.8 | L7: =SUM(D7:K7) -> 20.7 | M7: =SUM(D7:J7)*1000000+K7*1400000 -> 22220000 | N7: 0 | O7: 0 | P7: =SUM(L7:L11)+N7 -> 58.3 | Q7: =SUM(M7:M11)+O7 -> 62900000
B8: 2 | C8: 用役管理システム（千葉・徳山） | D8: 1.4 | E8: 1.1 | F8: 1.5 | G8: 3.1 | H8: 1.1 | I8: 0.8 | J8: 2 | K8: 2.6 | L8: =SUM(D8:K8) -> 13.6 | M8: =SUM(D8:J8)*1000000+K8*1400000 -> 14640000
B9: 3 | C9: 千葉化学品質管理システム | D9: 1.7 | E9: 1.4 | F9: 1.6 | G9: 5.5 | H9: 0.8 | I9: 0.5 | J9: 0.6 | K9: 2.7 | L9: =SUM(D9:K9) -> 14.8 | M9: =SUM(D9:J9)*1000000+K9*1400000 -> 15880000
B10: 4 | C10: ＬＭＰＰ包装システム | D10: 1.3 | E10: 0.4 | F10: 1.6 | G10: 1.2 | H10: 0.8 | I10: 0.5 | J10: 0.6 | K10: 1.9 | L10: =SUM(D10:K10) -> 8.3 | M10: =SUM(D10:J10)*1000000+K10*1400000 -> 9060000
B11: 5 | C11: 工場DB | J11: 0.4 | K11: 0.5 | L11: =SUM(D11:K11) -> 0.9 | M11: =SUM(D11:J11)*1000000+K11*1400000 -> 1100000
B12: 6 | C12: ヤ－ド操業システム（千葉・徳山） | D12: 0.5 | E12: 0.4 | F12: 0.7 | G12: 1.4 | H12: 0.2 | I12: 0.1 | J12: 1.5 | K12: 0.9 | L12: =SUM(D12:K12) -> 5.7 | M12: =SUM(D12:J12)*1000000+K12*1400000 -> 6060000 | N12: 0 | O12: =SUM(O5:O10) -> 0 | P12: =SUM(L12:L12)+N12 -> 5.7 | Q12: =SUM(M12)+O12 -> 6060000
B13: 7 | C13: 縮小共通基盤対応 | M13: ='見積 (縮小共通基盤継続） '!D22 -> 6549000 | N13: 0 | O13: =SUM(O6:O11) -> 0 | P13: =SUM(L13:L13)+N13 -> 0 | Q13: =SUM(M13:M13)+O7 -> 6549000 | R13: 残作業工数が追加
B14: 計 | D14: =SUM(D7:D13) -> 8.1 | E14: =SUM(E7:E13) -> 4.9 | F14: =SUM(F7:F13) -> 8.1 | G14: =SUM(G7:G13) -> 16.4 | H14: =SUM(H7:H13) -> 4.3 | I14: =SUM(I7:I13) -> 2.7 | J14: =SUM(J7:J13) -> 7.1 | K14: =SUM(K7:K13) -> 12.4 | L14: =SUM(D14:K14) -> 64 | M14: =SUM(M7:M13) -> 75509000 | N14: =SUM(N7:N13) -> 0 | O14: =SUM(O7:O13) -> 0 | P14: =SUM(P7:P13) -> 64 | Q14: =SUM(Q7:Q13) -> 75509000
B15: 単価 | D15: 1000000 | E15: 1000000 | F15: 1000000 | G15: 1000000 | H15: 1000000 | I15: 1000000 | J15: 1000000 | K15: 1400000
B16: 金額 | D16: =D14*D15 -> 8100000 | E16: =E14*E15 -> 4900000 | F16: =F14*F15 -> 8100000 | G16: =G14*G15 -> 16400000 | H16: =H14*H15 -> 4300000 | I16: =I14*I15 -> 2700000 | J16: =J14*J15 -> 7100000 | K16: =K14*K15 -> 17360000
