Workbook
Name 部門名: #REF!
Name 部門名: '御見積詳細書 (顧客用) (2)'!#REF!
Name 部門名: #REF!

Sheet 御見積詳細書 (顧客用) (2)
A1: 御 見 積 書 | Y1: 見積番号 | AJ1: -
Y2: 見積年月日 | AF2: 45873
A5: 出光興産株式会社 御中
A9: 見積金額 | F9: =AE44 -> 5010000
A13: 件名
B15: MESシステム 千葉工場製造一課開発対応
A19: 作業形態
B21: 請負契約
A24: 作業場所
B26: 弊社内（在宅勤務を含む） ※ お打合せ等、必要に応じて貴社へお伺いします。
A29: 作業期間
B31: 2025年9月1日 ～ 2026年1月9日
A34: 見積金額内訳
B36: No | D36: 項目 | AE36: 金額
B37: 1 | D37: 要件定義 | AE37: 250000
B38: 2 | D38: 設計 | AE38: 750000
B39: 3 | D39: 開発 | AE39: 1500000
B40: 4 | D40: 結合テスト | AE40: 1200000
B41: 5 | D41: ユーザテスト | AE41: 300000
B42: 6 | D42: 本稼働 | AE42: 100000
B43: 7 | D43: プロジェクト管理 | AE43: 910000
B44: 合計 | AE44: =SUM(AE37:AJ43) -> 5010000
A47: 納品物
B49: ・ | C49: 設計書 | K49: ・ | L49: 結合テスト仕様書兼結果報告書
B50: ・ | C50: プログラム | K50: ・ | L50: 本番リリース作業手順書
A53: 対象機能
B54: 1.画面機能
C55: 1) | D55: 製造一課カルテメンテナンス
C56: 2) | D56: 実績入力（原料使用量）
C57: 3) | D57: 一次スリット指示書備考マスタ修正
B59: 2.帳票機能
C60: 1) | D60: 製造指示書
C61: 2) | D61: 一次スリット指示書
A64: 作業内容
B65: 1.画面機能
C66: 1) | D66: 製造一課カルテメンテナンス
D67: ①画面フォームの改修
E68: ・原料項目の表示を6項目追加して17品目にする。
E69: ・注意事項項目を5項目追加して6項目にする。
D70: ②プログラム改修
...

Sheet 御見積詳細書 (顧客用)
A1: 御 見 積 書 | Y1: 見積番号 | AJ1: -
Y2: 見積年月日 | AF2: 45901
A5: 出光興産株式会社 御中
A9: 見積金額 | F9: =AE43 -> 3752000
A13: 件名
B15: MESシステム 千葉工場製造一課開発対応
A19: 作業形態
B21: 請負契約
A24: 作業場所
B26: 弊社内（在宅勤務を含む） ※ お打合せ等、必要に応じて貴社へお伺いします
A29: 作業期間
B31: 2025年9月15日 ～ 2026年1月15日
A34: 見積金額内訳
B36: No | D36: 項目 | AE36: 金額
B37: 1 | D37: 要件定義・ 設計 | AE37: ='御見積詳細書（社内用）'!AE37 -> 500000
B38: 2 | D38: 開発 | AE38: ='御見積詳細書（社内用）'!AE38 -> 1350000
B39: 3 | D39: 結合テスト・システムテスト | AE39: ='御見積詳細書（社内用）'!AE39 -> 850000
B40: 4 | D40: ユーザテスト | AE40: ='御見積詳細書（社内用）'!AE40 -> 300000
B41: 5 | D41: 本稼働 | AE41: ='御見積詳細書（社内用）'!AE41 -> 100000
B42: 6 | D42: プロジェクト管理 | AE42: 651000
B43: 合計 | AE43: ='御見積詳細書（社内用）'!AE43 -> 3752000
A46: 納品物
B48: ・ | C48: 設計書 | K48: ・ | L48: 結合テスト仕様書兼結果報告書
B49: ・ | C49: プログラム | K49: ・ | L49: 本番リリース作業手順書
A52: 対象機能
B53: 1.画面機能
C54: 1) | D54: 製造一課カルテメンテナンス
C55: 2) | D55: 実績入力（原料使用量）
C56: 3) | D56: 一次スリット指示書備考マスタ修正
C57: 4) | D57: 一時スリット指示書作成備考マスタ一覧
B59: 2.帳票機能
C60: 1) | D60: 製造指示書
C61: 2) | D61: 一次スリット指示書
A63: 作業内容
B65: MES_概算御見積（顧客提出用）を参照
B67: 表.工程ごとの作業内容一覧
B68: No | D68: 工程 | I68: 作業内容
B69: 1 | D69: 要件定義・ 設計 | I69: 修正方針の確定、不明瞭箇所の特定、資料作成方針の決定等細かい仕様について、ユーザ様と決定します 本改修についての改修仕様書を作成します
B72: 2 | D72: 開発 | I72: コーディングを実施します
B74: 3 | D74: 結合・システムテスト | I74: 貴社環境にて結合・システムテスト実施、実施結果の分析、不具合の対応を実施し、結合・システムテスト仕様書および結合・システムテスト結果報告書を作成します
...

Sheet 御見積詳細書（社内用）
A1: 御 見 積 書 | Y1: 見積番号 | AJ1: -
Y2: 見積年月日 | AF2: 45901
A5: 出光興産株式会社 御中
A9: 見積金額 | F9: =AE43 -> 3752000
A13: 件名
B15: ='御見積詳細書 (顧客用)'!B15 -> MESシステム 千葉工場製造一課開発対応
A19: 作業形態
B21: 請負契約
A24: 作業場所
B26: 弊社内（在宅勤務を含む） ※ お打合せ等、必要に応じて貴社へお伺いします。
A29: 作業期間
B31: ='御見積詳細書 (顧客用)'!B31 -> 2025年9月15日 ～ 2026年1月15日
A34: 見積金額内訳
B36: No | D36: 項目 | S36: 単価 | Y36: 数量 | AE36: 金額
B37: 1 | D37: 要件定義・ 設計 | S37: 1000000 | Y37: 10 | AC37: 人日 | AE37: =S37/20*Y37 -> 500000
B38: 2 | D38: 開発 | S38: 1000000 | Y38: 27 | AC38: 人日 | AE38: =S38/20*Y38 -> 1350000
B39: 3 | D39: 結合テスト・システムテスト | S39: 1000000 | Y39: 17 | AC39: 人日 | AE39: =S39/20*Y39 -> 850000
B40: 4 | D40: ユーザテスト | S40: 1000000 | Y40: 6 | AC40: 人日 | AE40: =S40/20*Y40 -> 300000
B41: 5 | D41: 本稼働 | S41: 1000000 | Y41: 2 | AC41: 人日 | AE41: =S41/20*Y41 -> 100000
B42: 6 | D42: プロジェクト管理 | S42: 1400000 | Y42: 9.3 | AC42: 人日 | AE42: 652000
B43: 合計 | Y43: =SUM(Y37:AB42) -> 71.3 | AC43: 人日 | AE43: =SUM(AE37:AJ42) -> 3752000

Sheet MES_概算御見積（内部用）
A1: 2025年度 MESシステム改修 御見積 | AA1: 人日 | AG1: 人月 | AM1: 工程別作業工数合算
A2: ※リリース作業は2人対応とする | K2: 人日 | S2: 人月 | AA2: 開発 | AB2: 50000 | AC2: 管理 | AD2: 70000 | AG2: 開発 | AH2: 1000000 | AI2: 管理 | AJ2: 1400000 | AM2: 人日 | AU2: 人月
A3: No. | B3: 工場 | C3: 案件名 | D3: 完成希望日 | E3: 開発目的 | F3: 内容 | G3: 改修内容 | H3: 概算工数 開発工数内訳（人日） | I3: 概算工数 開発工数（人日） | J3: 管理工数込み（人日） | K3: 調査・設計 | L3: PG | M3: IT | N3: ST | O3: OT | P3: リリース | Q3: 合計 | S3: 調査・設計 | T3: PGPT | U3: IT | V3: ST | W3: OT | X3: リリース | Y3: 合計 | Z3: 備考 | AA3: 人日 | AB3: 金額 | AC3: 人日 | AD3: 金額 | AE3: 合計金額 | AG3: 人月 | AH3: 金額 | AI3: 人月 | AJ3: 金額 | AK3: 合計金額 | AM3: 調査・設計 | AN3: PGPT | AO3: IT | AP3: ST | AQ3: OT | AR3: リリース | AS3: 合計 | AU3: 調査・設計 | AV3: PGPT | AW3: IT | AX3: ST | AY3: OT | AZ3: リリース | BA3: 合計
A4: 1 | B4: 千葉工場 製造一課 | C4: カルテ、製造指示書、生産実績における原料品目数拡大 | D4: 46031 | E4: 現状の原料品目数（11品目）では原料品目数が足りず、試作品開発が出来ない。 試作品開発を行えるよう原料品目数を増やす改修を行う。 | F4: 原料品目数を6品目追加し、合計17品目として多種多様な原料配合に対応できるようにする。 | G4: ■PG改修 カルテメンテナンス画面 実績入力（原料使用料）画面 ・原料項目6品目追加、合計17品目表示対応 | H4: =Q4 -> 25 | I4: =SUM(H4:H6) -> 62 | J4: =AA4+AC4 -> 28.75 | K4: 4 | L4: 12 | M4: 4 | N4: 3 | O4: 2 | P4: 0 | Q4: =SUM(K4:P4) -> 25 | S4: =ROUNDUP(K4/20,3) -> 0.2 | T4: =ROUNDUP(L4/20,3) -> 0.6 | U4: =ROUNDUP(N4/20,3) -> 0.15 | V4: =ROUNDUP(N4/20,3) -> 0.15 | W4: =ROUNDUP(O4/20,3) -> 0.1 | X4: =ROUNDUP(P4/20,3) -> 0 | Y4: =ROUNDUP(Q4/20,3) -> 1.25 | AA4: =SUM(Q4) -> 25 | AB4: =AA4*$AB$2 -> 1250000 | AC4: =ROUNDUP(AA4*0.15,2) -> 3.75 | AD4: =AC4*$AD$2 -> 262500 | AE4: =ROUNDUP(SUM(AB4,AD4),-3) -> 1513000 | AG4: =SUM(Y4) -> 1.25 | AH4: =AG4*$AH$2 -> 1250000 | AI4: =ROUNDUP(AG4*0.15,3) -> 0.188 | AJ4: =AI4*$AJ$2 -> 263200 | AK4: =ROUNDUP(SUM(AH4,AJ4),-3) -> 1514000 | AM4: =SUM(K4:K6) -> 10 | AN4: =SUM(L4:L6) -> 27 | AO4: =SUM(M4:M6) -> 10 | AP4: =SUM(N4:N6) -> 7 | AQ4: =SUM(O4:O6) -> 6 | AR4: =SUM(P4:P6) -> 2 | AS4: =SUM(Q4:Q6) -> 62 | AU4: =SUM(S4:S6) -> 0.5 | AV4: =SUM(T4:T6) -> 1.35 | AW4: =SUM(U4:U6) -> 0.45 | AX4: =SUM(V4:V6) -> 0.35 | AY4: =SUM(W4:W6) -> 0.3 | AZ4: =SUM(X4:X6) -> 0.1 | BA4: =SUM(Y4:Y6) -> 3.1
A5: 2 | C5: 製造指示書の印刷フォーマット改修と入力項目追加 | D5: 46031 | E5: 製造指示書のフォーマットを原料品目数増加に伴い、改修をする。 一部の手書き箇所も入力、マスタ化にする。 | F5: ・原料品目数増加により、他項目の印刷位置等を見直す。 ・備考欄が1項目のみで文字数制限がある。欄を3～4項目に増やして、手書きをなくす。 ・工程№の上に課内で使用しているFAの工程№を自動反映で印字させる。 ※起案資料には3～4項目に増やしてとあるが、6項目として対応する | G5: ■フォーマット改修 製造指示書 ・工程Noの上にFAの行程Noを自動表示する（工程Noが32411060の場合→FA工程No3411-06） ・原料項目を追加し、合計17品目表示可能とする ・フォーマット中段の課長押印欄削除 ・改訂理由項目の幅を狭める ・注意事項項目の幅を広げる ・注意事項項目の入力項目を3項目6項目に増やす ■PG改修 カルテメンテナンス画面（注意事項タブ） ・FA工程No出力対応 ・原料項目合計17品目表示対応 ・注意事項項目の入力項目を3項目6項目に増やす（マスタからの選択項目を増やす） | H5: =Q5 -> 25 | J5: =AA5+AC5 -> 28.75 | K5: 4 | L5: 12 | M5: 4 | N5: 3 | O5: 2 | P5: 0 | Q5: =SUM(K5:P5) -> 25 | S5: =ROUNDUP(K5/20,3) -> 0.2 | T5: =ROUNDUP(L5/20,3) -> 0.6 | U5: =ROUNDUP(M5/20,3) -> 0.2 | V5: =ROUNDUP(N5/20,3) -> 0.15 | W5: =ROUNDUP(O5/20,3) -> 0.1 | X5: =ROUNDUP(P5/20,3) -> 0 | Y5: =ROUNDUP(Q5/20,3) -> 1.25 | AA5: =SUM(Q5) -> 25 | AB5: =AA5*$AB$2 -> 1250000 | AC5: =ROUNDUP(AA5*0.15,2) -> 3.75 | AD5: =AC5*$AD$2 -> 262500 | AE5: =ROUNDUP(SUM(AB5,AD5),-3) -> 1513000 | AG5: =SUM(Y5) -> 1.25 | AH5: =AG5*$AH$2 -> 1250000 | AI5: =ROUNDUP(AG5*0.15,3) -> 0.188 | AJ5: =AI5*$AJ$2 -> 263200 | AK5: =ROUNDUP(SUM(AH5,AJ5),-3) -> 1514000
A6: 3 | C6: 一次指示書の印刷フォーマット改修と入力項目追加 | D6: 46031 | E6: 一次スリット指示書のフォーマットを改修をする。 一部の手書き箇所も入力、マスタ化にする。 | F6: ・備考欄が1項目のみで文字数制限がある。欄を8項目に増やして、手書きをなくす。 ・工程№の上に課内で使用しているFAの工程№を自動反映で印字させる。 ※起案資料には8項目とあるが、10項目として対応する | G6: ■フォーマット改修 一次スリット指示書 ・工程Noの右にFAの行程Noを自動表示する（工程Noが32411060の場合→FA工程No3411-06） ・備考項目の入力項目を8項目10項目に増やす ・サイズ項目の罫線を1行目以降削除する ■PG改修 一次スリット指示書備考マスタ修正画面 ・FA工程No出力対応 ・備考項目の入力項目を8項目10項目に増やす（マスタからの選択項目を増やす） ・製造備考マスタテーブルの項目追加（備考項目9件追加 合計10項目） | H6: =Q6 -> 12 | J6: =AA6+AC6 -> 13.8 | K6: 2 | L6: 3 | M6: 2 | N6: 1 | O6: 2 | P6: 2 | Q6: =SUM(K6:P6) -> 12 | S6: =ROUNDUP(K6/20,3) -> 0.1 | T6: =ROUNDUP(L6/20,3) -> 0.15 | U6: =ROUNDUP(M6/20,3) -> 0.1 | V6: =ROUNDUP(N6/20,3) -> 0.05 | W6: =ROUNDUP(O6/20,3) -> 0.1 | X6: =ROUNDUP(P6/20,3) -> 0.1 | Y6: =ROUNDUP(Q6/20,3) -> 0.6 | AA6: =SUM(Q6) -> 12 | AB6: =AA6*$AB$2 -> 600000 | AC6: =ROUNDUP(AA6*0.15,2) -> 1.8 | AD6: =AC6*$AD$2 -> 126000 | AE6: =ROUNDUP(SUM(AB6,AD6),-3) -> 726000 | AG6: =SUM(Y6) -> 0.6 | AH6: =AG6*$AH$2 -> 600000 | AI6: =ROUNDUP(AG6*0.15,3) -> 0.09 | AJ6: =AI6*$AJ$2 -> 126000 | AK6: =ROUNDUP(SUM(AH6,AJ6),-3) -> 726000
A9: 御見積の前提条件
B11: リリース工数、初期流動工数を含んでおります。
B12: No.1～3のリリース工数はNo.3に集約しております。
B13: 費用は開発業務と管理業務で算出しております。
B14: 弊社千葉事業所（在宅勤務を含む）での作業を前提としております。現地等遠隔地での作業が発生する場合は、工数を変更する場合があります。
B15: 現地等遠隔地での作業が発生した場合は、交通費・宿泊費等の必要経費を別途ご請求させて頂きます。
B16: 御見積の工数には、ハードウェア・ミドルウェア等にかかる費用は含まれておりません。
B17: 納品物：設計書、結合テスト仕様書兼結果報告書、ソースコード、システムテスト仕様書兼結果報告書
B18: （納品物が追加となる場合、工数が変動する場合がございます。）

Sheet MES_概算御見積（顧客提出用）
A1: 2025年度 MESシステム改修 御見積
A2: ※リリース作業は2人対応とする
A3: No. | B3: 工場 | C3: 案件名 | D3: 開発目的 | E3: 内容 | F3: 改修内容 | G3: 開発概算工数 （人日） | H3: 管理工数込み （人日） | I3: 合計金額
A4: 1 | B4: ='MES_概算御見積（内部用）'!B4 -> 千葉工場 製造一課 | C4: ='MES_概算御見積（内部用）'!C4 -> カルテ、製造指示書、生産実績における原料品目数拡大 | D4: ='MES_概算御見積（内部用）'!E4 -> 現状の原料品目数（11品目）では原料品目数が足りず、試作品開発が出来ない。 試作品開発を行えるよう原料品目数を増やす改修を行う。 | E4: 原料品目数を6品目追加し、合計17品目として多種多様な原料配合に対応できるようにする。 | F4: ■PG改修 カルテメンテナンス画面 実績入力（原料使用料）画面 ・原料項目6品目追加、合計17品目表示対応 | G4: ='MES_概算御見積（内部用）'!AA4 -> 25 | H4: ='MES_概算御見積（内部用）'!AA4+'MES_概算御見積（内部用）'!AC4 -> 28.75 | I4: ='MES_概算御見積（内部用）'!AE4 -> 1513000
A5: 2 | C5: ='MES_概算御見積（内部用）'!C5 -> 製造指示書の印刷フォーマット改修と入力項目追加 | D5: ='MES_概算御見積（内部用）'!E5 -> 製造指示書のフォーマットを原料品目数増加に伴い、改修をする。 一部の手書き箇所も入力、マスタ化にする。 | E5: ・原料品目数増加により、他項目の印刷位置等を見直す。 ・備考欄が1項目のみで文字数制限がある。欄を3～4項目に増やして、手書きをなくす。 ・工程№の上に課内で使用しているFAの工程№を自動反映で印字させる。 ※起案資料には3～4項目に増やしてとあるが、6項目として対応する | F5: ■フォーマット改修 製造指示書 ・工程Noの上にFAの行程Noを自動表示する（工程Noが32411060の場合→FA工程No3411-06） ・原料項目を追加し、合計17品目表示可能とする ・フォーマット中段の課長押印欄削除 ・改訂理由項目の幅を狭める ・注意事項項目の幅を広げる ・注意事項項目の入力項目を3項目6項目に増やす ■PG改修 カルテメンテナンス画面（注意事項タブ） ・FA工程No出力対応 ・原料項目合計17品目表示対応 ・注意事項項目の入力項目を3項目6項目に増やす（マスタからの選択項目を増やす） | G5: ='MES_概算御見積（内部用）'!AA5 -> 25 | H5: ='MES_概算御見積（内部用）'!AA5+'MES_概算御見積（内部用）'!AC5 -> 28.75 | I5: ='MES_概算御見積（内部用）'!AE5 -> 1513000
A6: 3 | C6: ='MES_概算御見積（内部用）'!C6 -> 一次指示書の印刷フォーマット改修と入力項目追加 | D6: ='MES_概算御見積（内部用）'!E6 -> 一次スリット指示書のフォーマットを改修をする。 一部の手書き箇所も入力、マスタ化にする。 | E6: ・備考欄が1項目のみで文字数制限がある。欄を8項目に増やして、手書きをなくす。 ・工程№の上に課内で使用しているFAの工程№を自動反映で印字させる。 ※起案資料には8項目とあるが、10項目として対応する | F6: ■フォーマット改修 一次スリット指示書 ・工程Noの右にFAの行程Noを自動表示する（工程Noが32411060の場合→FA工程No3411-06） ・備考項目の入力項目を8項目10項目に増やす ・サイズ項目の罫線を1行目以降削除する ■PG改修 一次スリット指示書備考マスタ修正画面 ・FA工程No出力対応 ・備考項目の入力項目を8項目10項目に増やす（マスタからの選択項目を増やす） ・製造備考マスタテーブルの項目追加（備考項目9件追加 合計10項目） | G6: ='MES_概算御見積（内部用）'!AA6 -> 12 | H6: ='MES_概算御見積（内部用）'!AA6+'MES_概算御見積（内部用）'!AC6 -> 13.8 | I6: ='MES_概算御見積（内部用）'!AE6 -> 726000
A10: 御見積の前提条件
B12: リリース工数、初期流動工数を含んでおります。
B13: No.1～3のリリース工数はNo.3に集約しております。
B14: 費用は開発業務と管理業務で算出しております。
B15: 弊社千葉事業所（在宅勤務を含む）での作業を前提としております。現地等遠隔地での作業が発生する場合は、工数を変更する場合があります。
B16: 現地等遠隔地での作業が発生した場合は、交通費・宿泊費等の必要経費を別途ご請求させて頂きます。
B17: 御見積の工数には、ハードウェア・ミドルウェア等にかかる費用は含まれておりません。
B18: 納品物：設計書、結合テスト仕様書兼結果報告書、ソースコード、システムテスト仕様書兼結果報告書
B19: （納品物が追加となる場合、工数が変動する場合がございます。）

Sheet スケジュール概算
N1: (人日) | R1: 2025
A2: No. | B2: 工場 | C2: 案件名 | D2: 内容 | E2: 完成希望日 | F2: 調査 設計 | G2: PG | H2: IT | I2: ST | J2: OT | K2: リリ ース | L2: 小計 | M2: 合計 | N2: 管理工数込み | P2: 着手 | Q2: リリース | R2: =DATE(R1,9,15) -> 45915 | S2: =R2+7 -> 45922 | T2: =S2+7 -> 45929 | U2: =T2+7 -> 45936 | V2: =U2+7 -> 45943 | W2: =V2+7 -> 45950 | X2: =W2+7 -> 45957 | Y2: =X2+7 -> 45964 | Z2: =Y2+7 -> 45971 | ... BE2: =BD2+7 -> 46188
A3: 1 | B3: ='MES_概算御見積（内部用）'!B4 -> 千葉工場 製造一課 | C3: ='MES_概算御見積（内部用）'!C4 -> カルテ、製造指示書、生産実績における原料品目数拡大 | D3: ='MES_概算御見積（内部用）'!F4 -> 原料品目数を6品目追加し、合計17品目として多種多様な原料配合に対応できるようにする。 | E3: ='MES_概算御見積（内部用）'!D4 -> 46031 | F3: ='MES_概算御見積（内部用）'!K4 -> 4 | G3: ='MES_概算御見積（内部用）'!L4 -> 12 | H3: ='MES_概算御見積（内部用）'!M4 -> 4 | I3: ='MES_概算御見積（内部用）'!N4 -> 3 | J3: ='MES_概算御見積（内部用）'!O4 -> 2 | K3: ='MES_概算御見積（内部用）'!P4 -> 0 | L3: ='MES_概算御見積（内部用）'!Q4 -> 25 | M3: =L3 -> 25 | N3: =M3+'MES_概算御見積（内部用）'!AC4 -> 28.75 | P3: =R2 -> 45915 | Q3: 46031
A4: 2 | C4: ='MES_概算御見積（内部用）'!C5 -> 製造指示書の印刷フォーマット改修と入力項目追加 | D4: ='MES_概算御見積（内部用）'!F5 -> ・原料品目数増加により、他項目の印刷位置等を見直す。 ・備考欄が1項目のみで文字数制限がある。欄を3～4項目に増やして、手書きをなくす。 ・工程№の上に課内で使用しているFAの工程№を自動反映で印字させる。 ※起案資料には3～4項目に増やしてとあるが、6項目として対応する | E4: ='MES_概算御見積（内部用）'!D5 -> 46031 | F4: ='MES_概算御見積（内部用）'!K5 -> 4 | G4: ='MES_概算御見積（内部用）'!L5 -> 12 | H4: ='MES_概算御見積（内部用）'!M5 -> 4 | I4: ='MES_概算御見積（内部用）'!N5 -> 3 | J4: ='MES_概算御見積（内部用）'!O5 -> 2 | K4: ='MES_概算御見積（内部用）'!P5 -> 0 | L4: ='MES_概算御見積（内部用）'!Q5 -> 25 | M4: =L4 -> 25 | N4: =M4+'MES_概算御見積（内部用）'!AC5 -> 28.75 | P4: =U2 -> 45936 | Q4: 46031
A5: 3 | C5: ='MES_概算御見積（内部用）'!C6 -> 一次指示書の印刷フォーマット改修と入力項目追加 | D5: ='MES_概算御見積（内部用）'!F6 -> ・備考欄が1項目のみで文字数制限がある。欄を8項目に増やして、手書きをなくす。 ・工程№の上に課内で使用しているFAの工程№を自動反映で印字させる。 ※起案資料には8項目とあるが、10項目として対応する | E5: ='MES_概算御見積（内部用）'!D6 -> 46031 | F5: ='MES_概算御見積（内部用）'!K6 -> 2 | G5: ='MES_概算御見積（内部用）'!L6 -> 3 | H5: ='MES_概算御見積（内部用）'!M6 -> 2 | I5: ='MES_概算御見積（内部用）'!N6 -> 1 | J5: ='MES_概算御見積（内部用）'!O6 -> 2 | K5: ='MES_概算御見積（内部用）'!P6 -> 2 | L5: ='MES_概算御見積（内部用）'!Q6 -> 12 | M5: =L5 -> 12 | N5: =M5+'MES_概算御見積（内部用）'!AC6 -> 13.8 | P5: =X2 -> 45957 | Q5: 46031
A7: 体制
B8: PM | C8: 桝井雄太
B9: PL | C9: 髙橋裕輔
B10: PG | C10: 1名＋エグゼベトナム
