Workbook
Name 作業ステータス: [1]コード内訳!$A$125:$A$132
Name 発生場所: [1]コード内訳!$A$115:$A$120

Sheet 概算見積③12月～1月
A1: 概 算 御 見 積 書 | X1: 見積番号 | AF1: -
X2: 見積年月日 | AF2: 45971
A5: 出光興産株式会社 御中
X8: 株式会社システムエグゼ
X9: 東京都中央区日本橋室町三丁目4番4号
X10: OVOL日本橋ビル7階
A11: 見積金額 | F11: =AE47 -> 684000 | X11: 担当: 髙橋 裕輔
X12: MAIL: yusuke.takahashi@system-exe.jp
A16: 件名
B17: 【設計～結合テスト】
B18: IFC生産委託ポータル 2次開発対応
B19: 訂正区分4・5対応、表示除外機能実装、レイアウト調整対応御見積
A21: 作業形態
B23: 請負契約
A26: 作業場所
B28: 弊社内（在宅勤務を含む）
A31: 作業期間
B33: 2025年12月1日 ～ 2026年1月16日
A35: 検収期間
B37: 2026年1月19日 ～ 2026年1月31日
A40: 見積金額内訳
B42: No | D42: 項目 | Y42: 数量 | AE42: 金額 | AM42: 単価
B43: 1 | D43: ='工数明細③12月～1月'!D4 -> 訂正区分4、5対応 | Y43: ='工数明細③12月～1月'!AC4 -> 0.18 | AC43: 人月 | AE43: =AM43*Y43 -> 180000 | AM43: 1000000
B44: 2 | D44: ='工数明細③12月～1月'!D5 -> 表示除外機能実装 | Y44: ='工数明細③12月～1月'!AC5 -> 0.2 | AC44: 人月 | AE44: =AM44*Y44 -> 200000 | AM44: 1000000
B45: 3 | D45: ='工数明細③12月～1月'!D6 -> レイアウト調整対応 | Y45: ='工数明細③12月～1月'!AC6 -> 0.15 | AC45: 人月 | AE45: =AM45*Y45 -> 150000 | AM45: 1000000
B46: 4 | D46: プロジェクト管理 | Y46: =SUM('工数明細③12月～1月'!AE4:AE8) -> 0.11 | AC46: 人月 | AE46: =AM46*Y46 -> 154000 | AM46: 1400000
D47: 合計 | Y47: =SUM(Y43:AB46) -> 0.64 | AC47: 人月 | AE47: =SUM(AE43:AJ46) -> 684000 | AM47: -
A49: 納品物
B51: ・ | C51: 設計書 | T51: ・ | U51: 結合テスト仕様書兼結果報告書
B52: ・ | C52: ソースコード
A55: 作業内容
B57: No | D57: 工程 | I57: 作業内容 | U57: 成果物
B58: 1 | D58: 調査・設計 | I58: ・ | J58: 対象箇所及び影響調査 | U58: ・ | V58: 基本設計書
I59: ・ | J59: 基本設計作成（新規作成・既存更新） | U59: ・ | V59: 詳細設計書
I60: ・ | J60: 詳細設計作成（新規作成・既存更新）
B61: 2 | D61: 開発・単体テスト | I61: 「改修対象」を参照 | U61: ・ | V61: プログラム一式
B63: 3 | D63: 結合テスト | I63: ・ | J63: 結合テスト実施 | U63: ・ | V63: 結合テスト仕様書
B65: 4 | D65: プロジェクト管理 | I65: ・ | J65: スケジュール管理 | U65: ・ | V65: 進捗報告書
I66: ・ | J66: レビュー、進捗管理・報告 | U66: ・ | V66: 課題管理表
I67: ・ | J67: 打ち合わせ等
...

Sheet 工数明細③12月～1月
A1: IFC生産委託システム追加開発対応 | W1: 人日 | AC1: 人月 | AI1: 工程別作業工数合算
I2: 人日 | P2: 人月 | W2: 開発 | X2: 50000 | Y2: 管理 | Z2: 70000 | AC2: 開発 | AD2: 1000000 | AE2: 管理 | AF2: 1400000 | AI2: 人日 | AQ2: 人月
A3: No. | B3: 案件名 | C3: 完成希望日 | D3: 内容 | E3: 改修内容 | F3: 概算工数 開発工数内訳（人日） | G3: 概算工数 開発工数（人日） | H3: 管理工数込み（人日） | I3: 調査・設計 | J3: PG | K3: IT | L3: ST | M3: UAT | N3: 合計 | P3: 調査・設計 | Q3: PG | R3: IT | S3: ST | T3: UAT | U3: 合計 | V3: 備考 | W3: 人日 | X3: 金額 | Y3: 人日 | Z3: 金額 | AA3: 合計金額 | AC3: 人月 | AD3: 金額 | AE3: 人月 | AF3: 金額 | AG3: 合計金額 | AI3: 調査・設計 | AJ3: PG | AK3: IT | AL3: ST | AM3: UAT | AN3: リリース | AO3: 合計 | AQ3: 調査・設計 | AR3: PG | AS3: IT | AT3: ST | AU3: UAT | AV3: リリース | AW3: 合計
A4: =ROW()-3 -> 1 | B4: IFC生産委託システム追加開発対応 | C4: 2026/1月末頃 | D4: 訂正区分4、5対応 | E4: 生産状況連携 ・OneSAPから訂正区分4で連携された場合 中間テーブルにはそのまま登録する 生産状況テーブルには納期以外を更新対象とする ・OneSAPから訂正区分5で連携された場合 中間テーブルにはそのまま登録する 生産状況テーブルには反映しない | F4: =N4 -> 3.5 | G4: =SUM(F4:F4) -> 3.5 | H4: =SUM(W4:W4)+SUM(Y4:Y4) -> 4.2 | I4: 0.5 | J4: 1 | K4: 2 | N4: =SUM(I4:M4) -> 3.5 | P4: =ROUNDUP(I4/20,3) -> 0.025 | Q4: =ROUNDUP(J4/20,3) -> 0.05 | R4: =ROUNDUP(K4/20,3) -> 0.1 | S4: =ROUNDUP(L4/20,3) -> 0 | T4: =ROUNDUP(M4/20,3) -> 0 | U4: =SUM(P4:T4) -> 0.175 | W4: =N4 -> 3.5 | X4: =W4*$X$2 -> 175000 | Y4: =ROUNDUP(W4*0.2,2) -> 0.7 | Z4: =ROUNDUP(Y4*$Z$2,-3) -> 49000 | AA4: =SUM(X4,Z4) -> 224000 | AC4: =ROUNDUP(U4,2) -> 0.18 | AD4: =AC4*$AD$2 -> 180000 | AE4: =ROUNDUP(AC4*0.2,2) -> 0.04 | AF4: =AE4*$AF$2 -> 56000 | AG4: =SUM(AD4,AF4) -> 236000 | AI4: =SUM(I4:I4) -> 0.5 | AJ4: =SUM(J4:J4) -> 1 | AK4: =SUM(K4:K4) -> 2 | AL4: =SUM(L4:L4) -> 0 | AM4: =SUM(M4:M4) -> 0 | AN4: =SUM(#REF!) -> #REF! | AO4: =SUM(N4:N4) -> 3.5 | AQ4: =SUM(P4:P4) -> 0.025 | AR4: =SUM(Q4:Q4) -> 0.05 | AS4: =SUM(R4:R4) -> 0.1 | AT4: =SUM(S4:S4) -> 0 | AU4: =SUM(T4:T4) -> 0 | AV4: =SUM(#REF!) -> #REF! | AW4: =SUM(U4:U4) -> 0.175
A5: =ROW()-3 -> 2 | D5: 表示除外機能実装 | E5: OneSAPからの連携データにおいて、IFC生産委託ポータル表示除外機能を実装する。 ・依頼Noが「x」として連携されてきた場合 生産委託ポータルの各画面に表示しない 生産委託ポータルの各出力ファイルに表示しない 連携は従来通り実施すること（生産状況テーブルに登録すること） ・依頼Noに入力する除外文字については仮とする | F5: =N5 -> 4 | I5: 0.5 | J5: 2 | K5: 1.5 | N5: =SUM(I5:M5) -> 4 | P5: =ROUNDUP(I5/20,3) -> 0.025 | Q5: =ROUNDUP(J5/20,3) -> 0.1 | R5: =ROUNDUP(K5/20,3) -> 0.075 | S5: =ROUNDUP(L5/20,3) -> 0 | T5: =ROUNDUP(M5/20,3) -> 0 | U5: =SUM(P5:T5) -> 0.2 | W5: =N5 -> 4 | X5: =W5*$X$2 -> 200000 | Y5: =ROUNDUP(W5*0.2,2) -> 0.8 | Z5: =ROUNDUP(Y5*$Z$2,-3) -> 56000 | AA5: =SUM(X5,Z5) -> 256000 | AC5: =U5 -> 0.2 | AD5: =AC5*$AD$2 -> 200000 | AE5: =ROUNDUP(AC5*0.2,2) -> 0.04 | AF5: =AE5*$AF$2 -> 56000 | AG5: =ROUNDUP(SUM(AD5,AF5),-3) -> 256000
A6: =ROW()-3 -> 3 | D6: レイアウト調整対応 | E6: 一部表示項目名の変更及び、列幅の調整を実施する。 ・表示項目名称変更 （現）希望納期→（新）（未定） （現）回答納期→（新）生産完了予定 各画面及び、各出力ファイルの表示項目名を変更する（5画面3ファイル） DBの定義については変更しないものとする 利用マニュアル修正（IFC読取ユーザ用を除く3ファイル） ・列幅調整 グレード、荷姿の列幅を現状想定される最大文字数が表示される幅に調整する DBの定義については変更しないものとする 想定桁数を超えた場合、折り返して表示する グレード、荷姿の想定桁数はそれぞれ半角英数15文字、17文字とする | F6: =N6 -> 3 | I6: 0.5 | J6: 2 | K6: 0.5 | N6: =SUM(I6:M6) -> 3 | P6: =ROUNDUP(I6/20,3) -> 0.025 | Q6: =ROUNDUP(J6/20,3) -> 0.1 | R6: =ROUNDUP(K6/20,3) -> 0.025 | S6: =ROUNDUP(L6/20,3) -> 0 | T6: =ROUNDUP(M6/20,3) -> 0 | U6: =SUM(P6:T6) -> 0.15 | W6: =N6 -> 3 | X6: =W6*$X$2 -> 150000 | Y6: =ROUNDUP(W6*0.2,2) -> 0.6 | Z6: =ROUNDUP(Y6*$Z$2,-3) -> 42000 | AA6: =SUM(X6,Z6) -> 192000 | AC6: =U6 -> 0.15 | AD6: =AC6*$AD$2 -> 150000 | AE6: =ROUNDUP(AC6*0.2,2) -> 0.03 | AF6: =AE6*$AF$2 -> 42000 | AG6: =ROUNDUP(SUM(AD6,AF6),-3) -> 192000
A7: 御見積の前提条件 | V7: リリース | W7: 0 | X7: =W7*$X$2 -> 0 | Y7: =ROUNDUP(W7*0.2,2) -> 0 | Z7: =ROUNDUP(Y7*$Z$2,-3) -> 0 | AA7: =SUM(X7,Z7) -> 0 | AC7: =ROUNDUP(W7/20,3) -> 0 | AD7: =AC7*$AD$2 -> 0 | AE7: =ROUNDUP(AC7*0.2,2) -> 0 | AF7: =AE7*$AF$2 -> 0 | AG7: =SUM(AD7,AF7) -> 0
V8: 初期流動 | W8: 0 | X8: =W8*$X$2 -> 0 | Y8: =ROUNDUP(W8*0.2,2) -> 0 | Z8: =ROUNDUP(Y8*$Z$2,-3) -> 0 | AA8: =SUM(X8,Z8) -> 0 | AC8: =ROUNDUP(W8/20,3) -> 0 | AD8: =AC8*$AD$2 -> 0 | AE8: =ROUNDUP(AC8*0.2,2) -> 0 | AF8: =AE8*$AF$2 -> 0 | AG8: =SUM(AD8,AF8) -> 0
B9: リリース工数、初期流動工数を含んでおります。 | AA9: 合計 | AC9: =SUM(AC4:AC8) -> 0.53 | AD9: =SUM(AD4:AD8) -> 530000 | AE9: =ROUNDUP(SUM(AE4:AE8),2) -> 0.11 | AF9: =SUM(AF4:AF8) -> 154000 | AG9: =SUM(AG4:AG8) -> 684000
B10: 費用は開発業務と管理業務で算出しております。 | AD10: 開発＋管理 | AE10: =SUM(AC9,AE9) -> 0.64
B11: 弊社千葉事業所（在宅勤務を含む）での作業を前提としております。現地等遠隔地での作業が発生する場合は、工数を変更する場合があります。
B12: 現地等遠隔地での作業が発生した場合は、交通費・宿泊費等の必要経費を別途ご請求させて頂きます。
B13: 御見積の工数には、ハードウェア・ミドルウェア等にかかる費用は含まれておりません。
B14: リリース作業は2人対応といたします。

Sheet 工数明細③12月～1月_bk
A1: IFC生産委託システム追加開発対応 | W1: 人日 | AC1: 人月 | AI1: 工程別作業工数合算
I2: 人日 | P2: 人月 | W2: 開発 | X2: 50000 | Y2: 管理 | Z2: 70000 | AC2: 開発 | AD2: 1000000 | AE2: 管理 | AF2: 1400000 | AI2: 人日 | AQ2: 人月
A3: No. | B3: 案件名 | C3: 完成希望日 | D3: 内容 | E3: 改修内容 | F3: 概算工数 開発工数内訳（人日） | G3: 概算工数 開発工数（人日） | H3: 管理工数込み（人日） | I3: 調査・設計 | J3: PG | K3: IT | L3: ST | M3: UAT | N3: 合計 | P3: 調査・設計 | Q3: PG | R3: IT | S3: ST | T3: UAT | U3: 合計 | V3: 備考 | W3: 人日 | X3: 金額 | Y3: 人日 | Z3: 金額 | AA3: 合計金額 | AC3: 人月 | AD3: 金額 | AE3: 人月 | AF3: 金額 | AG3: 合計金額 | AI3: 調査・設計 | AJ3: PG | AK3: IT | AL3: ST | AM3: UAT | AN3: リリース | AO3: 合計 | AQ3: 調査・設計 | AR3: PG | AS3: IT | AT3: ST | AU3: UAT | AV3: リリース | AW3: 合計
A4: =ROW()-3 -> 1 | B4: IFC生産委託システム追加開発対応 | C4: 2026/1月末頃 | D4: 訂正区分4、5対応 | E4: 生産状況連携 ・OneSAPから訂正区分4で連携された場合 中間テーブルにはそのまま登録する 生産状況テーブルには納期以外を更新対象とする ・OneSAPから訂正区分5で連携された場合 中間テーブルにはそのまま登録する 生産状況テーブルには反映しない | F4: =N4 -> 5 | G4: =SUM(F4:F4) -> 5 | H4: =SUM(W4:W4)+SUM(Y4:Y4) -> 6 | I4: 0.5 | J4: 1 | K4: 2 | L4: 1 | M4: 0.5 | N4: =SUM(I4:M4) -> 5 | P4: =ROUNDUP(I4/20,3) -> 0.025 | Q4: =ROUNDUP(J4/20,3) -> 0.05 | R4: =ROUNDUP(K4/20,3) -> 0.1 | S4: =ROUNDUP(L4/20,3) -> 0.05 | T4: =ROUNDUP(M4/20,3) -> 0.025 | U4: =SUM(P4:T4) -> 0.25 | W4: =N4 -> 5 | X4: =W4*$X$2 -> 250000 | Y4: =ROUNDUP(W4*0.2,2) -> 1 | Z4: =ROUNDUP(Y4*$Z$2,-3) -> 70000 | AA4: =SUM(X4,Z4) -> 320000 | AC4: =ROUNDUP(U4,2) -> 0.25 | AD4: =AC4*$AD$2 -> 250000 | AE4: =ROUNDUP(AC4*0.2,2) -> 0.05 | AF4: =AE4*$AF$2 -> 70000 | AG4: =SUM(AD4,AF4) -> 320000 | AI4: =SUM(I4:I4) -> 0.5 | AJ4: =SUM(J4:J4) -> 1 | AK4: =SUM(K4:K4) -> 2 | AL4: =SUM(L4:L4) -> 1 | AM4: =SUM(M4:M4) -> 0.5 | AN4: =SUM(#REF!) -> #REF! | AO4: =SUM(N4:N4) -> 5 | AQ4: =SUM(P4:P4) -> 0.025 | AR4: =SUM(Q4:Q4) -> 0.05 | AS4: =SUM(R4:R4) -> 0.1 | AT4: =SUM(S4:S4) -> 0.05 | AU4: =SUM(T4:T4) -> 0.025 | AV4: =SUM(#REF!) -> #REF! | AW4: =SUM(U4:U4) -> 0.25
A5: =ROW()-3 -> 2 | D5: 表示除外機能実装 | E5: OneSAPからの連携データにおいて、IFC生産委託ポータル表示除外機能を実装する。 ・依頼Noが「x」として連携されてきた場合 生産委託ポータルの各画面に表示しない 生産委託ポータルの各出力ファイルに表示しない 連携は従来通り実施すること（生産状況テーブルに登録すること） ・依頼Noに入力する除外文字については仮とする | F5: =N5 -> 5 | I5: 0.5 | J5: 2 | K5: 1.5 | L5: 0.5 | M5: 0.5 | N5: =SUM(I5:M5) -> 5 | P5: =ROUNDUP(I5/20,3) -> 0.025 | Q5: =ROUNDUP(J5/20,3) -> 0.1 | R5: =ROUNDUP(K5/20,3) -> 0.075 | S5: =ROUNDUP(L5/20,3) -> 0.025 | T5: =ROUNDUP(M5/20,3) -> 0.025 | U5: =SUM(P5:T5) -> 0.25 | W5: =N5 -> 5 | X5: =W5*$X$2 -> 250000 | Y5: =ROUNDUP(W5*0.2,2) -> 1 | Z5: =ROUNDUP(Y5*$Z$2,-3) -> 70000 | AA5: =SUM(X5,Z5) -> 320000 | AC5: =U5 -> 0.25 | AD5: =AC5*$AD$2 -> 250000 | AE5: =ROUNDUP(AC5*0.2,2) -> 0.05 | AF5: =AE5*$AF$2 -> 70000 | AG5: =ROUNDUP(SUM(AD5,AF5),-3) -> 320000
A6: =ROW()-3 -> 3 | D6: レイアウト調整対応 | E6: 一部表示項目名の変更及び、列幅の調整を実施する。 ・表示項目名称変更 （現）希望納期→（新）（未定） （現）回答納期→（新）生産完了予定 各画面及び、各出力ファイルの表示項目名を変更する（5画面3ファイル） DBの定義については変更しないものとする 利用マニュアル修正（IFC読取ユーザ用を除く3ファイル） ・列幅調整 グレード、荷姿の列幅を現状想定される最大文字数が表示される幅に調整する DBの定義については変更しないものとする 想定桁数を超えた場合、折り返して表示する グレード、荷姿の想定桁数はそれぞれ半角英数15文字、17文字とする | F6: =N6 -> 4 | I6: 0.5 | J6: 2 | K6: 0.5 | L6: 0.5 | M6: 0.5 | N6: =SUM(I6:M6) -> 4 | P6: =ROUNDUP(I6/20,3) -> 0.025 | Q6: =ROUNDUP(J6/20,3) -> 0.1 | R6: =ROUNDUP(K6/20,3) -> 0.025 | S6: =ROUNDUP(L6/20,3) -> 0.025 | T6: =ROUNDUP(M6/20,3) -> 0.025 | U6: =SUM(P6:T6) -> 0.2 | W6: =N6 -> 4 | X6: =W6*$X$2 -> 200000 | Y6: =ROUNDUP(W6*0.2,2) -> 0.8 | Z6: =ROUNDUP(Y6*$Z$2,-3) -> 56000 | AA6: =SUM(X6,Z6) -> 256000 | AC6: =U6 -> 0.2 | AD6: =AC6*$AD$2 -> 200000 | AE6: =ROUNDUP(AC6*0.2,2) -> 0.04 | AF6: =AE6*$AF$2 -> 56000 | AG6: =ROUNDUP(SUM(AD6,AF6),-3) -> 256000
A7: 御見積の前提条件 | V7: リリース | W7: 0 | X7: =W7*$X$2 -> 0 | Y7: =ROUNDUP(W7*0.2,2) -> 0 | Z7: =ROUNDUP(Y7*$Z$2,-3) -> 0 | AA7: =SUM(X7,Z7) -> 0 | AC7: =ROUNDUP(W7/20,3) -> 0 | AD7: =AC7*$AD$2 -> 0 | AE7: =ROUNDUP(AC7*0.2,2) -> 0 | AF7: =AE7*$AF$2 -> 0 | AG7: =SUM(AD7,AF7) -> 0
V8: 初期流動 | W8: 0 | X8: =W8*$X$2 -> 0 | Y8: =ROUNDUP(W8*0.2,2) -> 0 | Z8: =ROUNDUP(Y8*$Z$2,-3) -> 0 | AA8: =SUM(X8,Z8) -> 0 | AC8: =ROUNDUP(W8/20,3) -> 0 | AD8: =AC8*$AD$2 -> 0 | AE8: =ROUNDUP(AC8*0.2,2) -> 0 | AF8: =AE8*$AF$2 -> 0 | AG8: =SUM(AD8,AF8) -> 0
B9: リリース工数、初期流動工数を含んでおります。 | AA9: 合計 | AC9: =SUM(AC4:AC8) -> 0.7 | AD9: =SUM(AD4:AD8) -> 700000 | AE9: =ROUNDUP(SUM(AE4:AE8),2) -> 0.14 | AF9: =SUM(AF4:AF8) -> 196000 | AG9: =SUM(AG4:AG8) -> 896000
B10: 費用は開発業務と管理業務で算出しております。 | AD10: 開発＋管理 | AE10: =SUM(AC9,AE9) -> 0.84
B11: 弊社千葉事業所（在宅勤務を含む）での作業を前提としております。現地等遠隔地での作業が発生する場合は、工数を変更する場合があります。
B12: 現地等遠隔地での作業が発生した場合は、交通費・宿泊費等の必要経費を別途ご請求させて頂きます。
B13: 御見積の工数には、ハードウェア・ミドルウェア等にかかる費用は含まれておりません。
B14: リリース作業は2人対応といたします。

Sheet 概算見積③2月
A1: 概 算 御 見 積 書 | X1: 見積番号 | AF1: -
X2: 見積年月日 | AF2: 45971
A5: 出光興産株式会社 御中
X8: 株式会社システムエグゼ
X9: 東京都中央区日本橋室町三丁目4番4号
X10: OVOL日本橋ビル7階
A11: 見積金額 | F11: =AE47 -> 660000 | X11: 担当: 髙橋 裕輔
X12: MAIL: yusuke.takahashi@system-exe.jp
A16: 件名
B17: 【システムテスト～初期流動】
B18: IFC生産委託ポータル 2次開発対応
B19: 訂正区分4・5対応、表示除外機能実装、レイアウト調整対応御見積
A21: 作業形態
B23: 準委任契約
A26: 作業場所
B28: 弊社内（在宅勤務を含む）
A31: 作業期間
B33: 2026年1月19日 ～ 2026年2月28日
A35: 検収日
B37: 2026/2/28
A39: 見積金額内訳
B41: No | D41: 項目 | Y41: 数量 | AE41: 金額 | AM41: 単価
B42: 1 | D42: システムテスト | Y42: =工数明細③2月!AC7 -> 0.1 | AC42: 人月 | AE42: =AM42*Y42 -> 100000 | AM42: 1000000
B43: 2 | D43: 受入テスト | Y43: 0.09 | AC43: 人月 | AE43: =AM43*Y43 -> 90000 | AM43: 1000000
B44: 3 | D44: リリース | Y44: =工数明細③2月!AC9 -> 0.1 | AC44: 人月 | AE44: =AM44*Y44 -> 100000 | AM44: 1000000
B45: 4 | D45: 初期流動 | Y45: 0.23 | AC45: 人月 | AE45: =AM45*Y45 -> 230000 | AM45: 1000000
B46: 5 | D46: プロジェクト管理 | Y46: 0.1 | AC46: 人月 | AE46: =AM46*Y46 -> 140000 | AM46: 1400000
D47: 合計 | Y47: =SUM(Y42:AB46) -> 0.62 | AC47: 人月 | AE47: =SUM(AE42:AJ46) -> 660000 | AM47: -
A49: 納品物
B51: ・ | C51: ソースコード | T51: ・ | U51: システムテスト仕様書兼結果報告書
B52: ・ | C52: 本番作業手順書
A54: 作業内容
B56: No | D56: 工程 | I56: 作業内容 | U56: 成果物
B57: 1 | D57: システムテスト | I57: ・ | J57: システムテスト実施 | U57: ・ | V57: システムテスト仕様書
B59: 2 | D59: 受入テスト | I59: ・ | J59: 受入テスト対応
B61: 3 | D61: リリース | I61: ・ | J61: 作業手順書作成 | U61: ・ | V61: 本番作業手順書
I62: ・ | J62: リリース作業実施
B63: 4 | D63: プロジェクト管理 | I63: ・ | J63: スケジュール管理 | U63: ・ | V63: 進捗報告書
I64: ・ | J64: レビュー、進捗管理・報告 | U64: ・ | V64: 課題管理表
I65: ・ | J65: 打ち合わせ等
...

Sheet 工数明細③2月
A1: IFC生産委託システム追加開発対応 | W1: 人日 | AC1: 人月 | AI1: 工程別作業工数合算
I2: 人日 | P2: 人月 | W2: 開発 | X2: 50000 | Y2: 管理 | Z2: 70000 | AC2: 開発 | AD2: 1000000 | AE2: 管理 | AF2: 1400000 | AI2: 人日 | AQ2: 人月
A3: No. | B3: 案件名 | C3: 完成希望日 | D3: 内容 | E3: 改修内容 | F3: 概算工数 開発工数内訳（人日） | G3: 概算工数 開発工数（人日） | H3: 管理工数込み（人日） | I3: 調査・設計 | J3: PG | K3: IT | L3: ST | M3: UAT | N3: 合計 | P3: 調査・設計 | Q3: PG | R3: IT | S3: ST | T3: UAT | U3: 合計 | V3: 備考 | W3: 人日 | X3: 金額 | Y3: 人日 | Z3: 金額 | AA3: 合計金額 | AC3: 人月 | AD3: 金額 | AE3: 人月 | AF3: 金額 | AG3: 合計金額 | AI3: 調査・設計 | AJ3: PG | AK3: IT | AL3: ST | AM3: UAT | AN3: リリース | AO3: 合計 | AQ3: 調査・設計 | AR3: PG | AS3: IT | AT3: ST | AU3: UAT | AV3: リリース | AW3: 合計
A4: =ROW()-3 -> 1 | B4: IFC生産委託システム追加開発対応 | C4: 2026/1月末頃 | D4: 訂正区分4、5対応 | E4: 生産状況連携 ・OneSAPから訂正区分4で連携された場合 中間テーブルにはそのまま登録する 生産状況テーブルには納期以外を更新対象とする ・OneSAPから訂正区分5で連携された場合 中間テーブルにはそのまま登録する 生産状況テーブルには反映しない | F4: =N4 -> 1.5 | G4: =SUM(F4:F4) -> 1.5 | H4: =SUM(W4:W4)+SUM(Y4:Y4) -> 1.8 | L4: 1 | M4: 0.5 | N4: =SUM(I4:M4) -> 1.5 | P4: =ROUNDUP(I4/20,3) -> 0 | Q4: =ROUNDUP(J4/20,3) -> 0 | R4: =ROUNDUP(K4/20,3) -> 0 | S4: =ROUNDUP(L4/20,3) -> 0.05 | T4: =ROUNDUP(M4/20,3) -> 0.025 | U4: =SUM(P4:T4) -> 0.075 | W4: =N4 -> 1.5 | X4: =W4*$X$2 -> 75000 | Y4: =ROUNDUP(W4*0.2,2) -> 0.3 | Z4: =ROUNDUP(Y4*$Z$2,-3) -> 21000 | AA4: =SUM(X4,Z4) -> 96000 | AC4: =ROUNDUP(U4,2) -> 0.08 | AD4: =AC4*$AD$2 -> 80000 | AE4: =ROUNDUP(AC4*0.2,2) -> 0.02 | AF4: =AE4*$AF$2 -> 28000 | AG4: =SUM(AD4,AF4) -> 108000 | AI4: =SUM(I4:I4) -> 0 | AJ4: =SUM(J4:J4) -> 0 | AK4: =SUM(K4:K4) -> 0 | AL4: =SUM(L4:L4) -> 1 | AM4: =SUM(M4:M4) -> 0.5 | AN4: =SUM(#REF!) -> #REF! | AO4: =SUM(N4:N4) -> 1.5 | AQ4: =SUM(P4:P4) -> 0 | AR4: =SUM(Q4:Q4) -> 0 | AS4: =SUM(R4:R4) -> 0 | AT4: =SUM(S4:S4) -> 0.05 | AU4: =SUM(T4:T4) -> 0.025 | AV4: =SUM(#REF!) -> #REF! | AW4: =SUM(U4:U4) -> 0.075
A5: =ROW()-3 -> 2 | D5: 表示除外機能実装 | E5: OneSAPからの連携データにおいて、IFC生産委託ポータル表示除外機能を実装する。 ・依頼Noが「x」として連携されてきた場合 生産委託ポータルの各画面に表示しない 生産委託ポータルの各出力ファイルに表示しない 連携は従来通り実施すること（生産状況テーブルに登録すること） ・依頼Noに入力する除外文字については仮とする | F5: =N5 -> 1 | L5: 0.5 | M5: 0.5 | N5: =SUM(I5:M5) -> 1 | P5: =ROUNDUP(I5/20,3) -> 0 | Q5: =ROUNDUP(J5/20,3) -> 0 | R5: =ROUNDUP(K5/20,3) -> 0 | S5: =ROUNDUP(L5/20,3) -> 0.025 | T5: =ROUNDUP(M5/20,3) -> 0.025 | U5: =SUM(P5:T5) -> 0.05 | W5: =N5 -> 1 | X5: =W5*$X$2 -> 50000 | Y5: =ROUNDUP(W5*0.2,2) -> 0.2 | Z5: =ROUNDUP(Y5*$Z$2,-3) -> 14000 | AA5: =SUM(X5,Z5) -> 64000 | AC5: =U5 -> 0.05 | AD5: =AC5*$AD$2 -> 50000 | AE5: =ROUNDUP(AC5*0.2,2) -> 0.01 | AF5: =AE5*$AF$2 -> 14000 | AG5: =ROUNDUP(SUM(AD5,AF5),-3) -> 64000
A6: =ROW()-3 -> 3 | D6: レイアウト調整対応 | E6: 一部表示項目名の変更及び、列幅の調整を実施する。 ・表示項目名称変更 （現）希望納期→（新）（未定） （現）回答納期→（新）生産完了予定 各画面及び、各出力ファイルの表示項目名を変更する（5画面3ファイル） DBの定義については変更しないものとする 利用マニュアル修正（IFC読取ユーザ用を除く3ファイル） ・列幅調整 グレード、荷姿の列幅を現状想定される最大文字数が表示される幅に調整する DBの定義については変更しないものとする 想定桁数を超えた場合、折り返して表示する グレード、荷姿の想定桁数はそれぞれ半角英数15文字、17文字とする | F6: =N6 -> 1 | L6: 0.5 | M6: 0.5 | N6: =SUM(I6:M6) -> 1 | P6: =ROUNDUP(I6/20,3) -> 0 | Q6: =ROUNDUP(J6/20,3) -> 0 | R6: =ROUNDUP(K6/20,3) -> 0 | S6: =ROUNDUP(L6/20,3) -> 0.025 | T6: =ROUNDUP(M6/20,3) -> 0.025 | U6: =SUM(P6:T6) -> 0.05 | W6: =N6 -> 1 | X6: =W6*$X$2 -> 50000 | Y6: =ROUNDUP(W6*0.2,2) -> 0.2 | Z6: =ROUNDUP(Y6*$Z$2,-3) -> 14000 | AA6: =SUM(X6,Z6) -> 64000 | AC6: =U6 -> 0.05 | AD6: =AC6*$AD$2 -> 50000 | AE6: =ROUNDUP(AC6*0.2,2) -> 0.01 | AF6: =AE6*$AF$2 -> 14000 | AG6: =ROUNDUP(SUM(AD6,AF6),-3) -> 64000
A7: 御見積の前提条件 | V7: システムテスト | W7: 2 | X7: =W7*$X$2 -> 100000 | Y7: =ROUNDUP(W7*0.2,2) -> 0.4 | Z7: =ROUNDUP(Y7*$Z$2,-3) -> 28000 | AA7: =SUM(X7,Z7) -> 128000 | AC7: =ROUNDUP(W7/20,3) -> 0.1 | AD7: =AC7*$AD$2 -> 100000 | AE7: =ROUNDUP(AC7*0.2,2) -> 0.02 | AF7: =AE7*$AF$2 -> 28000 | AG7: =SUM(AD7,AF7) -> 128000
A8: 御見積の前提条件 | V8: 受入テスト | W8: 1.5 | X8: =W8*$X$2 -> 75000 | Y8: =ROUNDUP(W8*0.2,2) -> 0.3 | Z8: =ROUNDUP(Y8*$Z$2,-3) -> 21000 | AA8: =SUM(X8,Z8) -> 96000 | AC8: =ROUNDUP(W8/20,3) -> 0.075 | AD8: =AC8*$AD$2 -> 75000 | AE8: =ROUNDUP(AC8*0.2,2) -> 0.02 | AF8: =AE8*$AF$2 -> 28000 | AG8: =SUM(AD8,AF8) -> 103000
A9: 御見積の前提条件 | V9: リリース | W9: 2 | X9: =W9*$X$2 -> 100000 | Y9: =ROUNDUP(W9*0.2,2) -> 0.4 | Z9: =ROUNDUP(Y9*$Z$2,-3) -> 28000 | AA9: =SUM(X9,Z9) -> 128000 | AC9: =ROUNDUP(W9/20,3) -> 0.1 | AD9: =AC9*$AD$2 -> 100000 | AE9: =ROUNDUP(AC9*0.2,2) -> 0.02 | AF9: =AE9*$AF$2 -> 28000 | AG9: =SUM(AD9,AF9) -> 128000
V10: 初期流動 | W10: 5 | X10: =W10*$X$2 -> 250000 | Y10: =ROUNDUP(W10*0.2,2) -> 1 | Z10: =ROUNDUP(Y10*$Z$2,-3) -> 70000 | AA10: =SUM(X10,Z10) -> 320000 | AC10: =ROUNDUP(W10/20,3) -> 0.25 | AD10: =AC10*$AD$2 -> 250000 | AE10: =ROUNDUP(AC10*0.2,2) -> 0.05 | AF10: =AE10*$AF$2 -> 70000 | AG10: =SUM(AD10,AF10) -> 320000
B11: リリース工数、初期流動工数を含んでおります。 | AA11: 合計 | AC11: =SUM(AC4:AC10) -> 0.705 | AD11: =SUM(AD4:AD10) -> 705000 | AE11: =ROUNDUP(SUM(AE4:AE10),2) -> 0.15 | AF11: =SUM(AF4:AF10) -> 210000 | AG11: =SUM(AG4:AG10) -> 915000
B12: 費用は開発業務と管理業務で算出しております。 | AD12: 開発＋管理 | AE12: =SUM(AC11,AE11) -> 0.855
B13: 弊社千葉事業所（在宅勤務を含む）での作業を前提としております。現地等遠隔地での作業が発生する場合は、工数を変更する場合があります。
B14: 現地等遠隔地での作業が発生した場合は、交通費・宿泊費等の必要経費を別途ご請求させて頂きます。
B15: 御見積の工数には、ハードウェア・ミドルウェア等にかかる費用は含まれておりません。
B16: リリース作業は2人対応といたします。

Sheet 工数明細 (2)
A1: IFC生産委託システム追加開発対応 | Y1: 人日 | AE1: 人月 | AL1: 工程別作業工数合算
I2: 人日 | Q2: 人月 | Y2: 開発 | Z2: 50000 | AA2: 管理 | AB2: 70000 | AE2: 開発 | AF2: 1000000 | AG2: 管理 | AI2: 1400000 | AL2: 人日 | AT2: 人月
A3: No. | B3: 案件名 | C3: 完成希望日 | D3: 内容 | E3: 改修内容 | F3: 概算工数 開発工数内訳（人日） | G3: 概算工数 開発工数（人日） | H3: 管理工数込み（人日） | I3: 調査・設計 | J3: PG | K3: IT | L3: ST | M3: UAT | N3: リリース | O3: 合計 | Q3: 調査・設計 | R3: PG | S3: IT | T3: ST | U3: UAT | V3: リリース | W3: 合計 | X3: 備考 | Y3: 人日 | Z3: 金額 | AA3: 人日 | AB3: 金額 | AC3: 合計金額 | AE3: 人月 | AF3: 金額 | AG3: 人月 | AI3: 金額 | AJ3: 合計金額 | AL3: 調査・設計 | AM3: PG | AN3: IT | AO3: ST | AP3: UAT | AQ3: リリース | AR3: 合計 | AT3: 調査・設計 | AU3: PG | AV3: IT | AW3: ST | AX3: UAT | AY3: リリース | AZ3: 合計
A4: =ROW()-3 -> 1 | B4: IFC生産委託システム追加開発対応 | C4: 2025/12月頃 | D4: 訂正区分4対応 | E4: 生産状況連携 ・OneSAPから訂正区分4で連携された場合、生産状況テーブルの納期を更新対象外とする。 ・中間テーブルにはそのまま登録し、生産状況テーブルに登録する際に条件を追加する。 | F4: =O4 -> 7 | G4: =SUM(F4:F8) -> 26.5 | H4: =SUM(Y4:Y7)+SUM(AA4:AA7) -> 19.8 | I4: 0.5 | J4: 1 | K4: 2 | L4: 1 | M4: 0.5 | N4: 2 | O4: =SUM(I4:N4) -> 7 | Q4: =ROUNDUP(I4/20,3) -> 0.025 | R4: =ROUNDUP(J4/20,3) -> 0.05 | S4: =ROUNDUP(K4/20,3) -> 0.1 | T4: =ROUNDUP(L4/20,3) -> 0.05 | U4: =ROUNDUP(M4/20,3) -> 0.025 | V4: =ROUNDUP(N4/20,3) -> 0.1 | W4: =SUM(Q4:V4) -> 0.35 | Y4: =O4 -> 7 | Z4: =Y4*$Z$2 -> 350000 | AA4: =ROUNDUP(Y4*0.2,2) -> 1.4 | AB4: =ROUNDUP(AA4*$AB$2,-3) -> 98000 | AC4: =SUM(Z4,AB4) -> 448000 | AE4: =ROUNDUP(W4,2) -> 0.35 | AF4: =AE4*$AF$2 -> 350000 | AG4: =ROUNDUP(AE4*0.2,3) -> 0.07 | AH4: =SUM(AE4,AG4) -> 0.42 | AI4: =AG4*$AI$2 -> 98000 | AJ4: =ROUNDUP(SUM(AF4,AI4),-3) -> 448000 | AL4: =SUM(I4:I7) -> 2 | AM4: =SUM(J4:J7) -> 3.5 | AN4: =SUM(K4:K7) -> 4.5 | AO4: =SUM(L4:L7) -> 2.5 | AP4: =SUM(M4:M7) -> 2 | AQ4: =SUM(N4:N7) -> 2 | AR4: =SUM(O4:O7) -> 16.5 | AT4: =SUM(Q4:Q7) -> 0.1 | AU4: =SUM(R4:R7) -> 0.175 | AV4: =SUM(S4:S7) -> 0.225 | AW4: =SUM(T4:T7) -> 0.125 | AX4: =SUM(U4:U7) -> 0.1 | AY4: =SUM(V4:V7) -> 0.1 | AZ4: =SUM(W4:W7) -> 0.825
A5: =ROW()-3 -> 2 | D5: お知らせ対応 | E5: トップページ ・トップページ内に子画面を表示し、お知らせ情報を表示する。 ・お知らせ権限が無い場合、子画面を表示しない。 | F5: =O5 -> 3.5 | I5: 0.5 | J5: 1 | K5: 1 | L5: 0.5 | M5: 0.5 | N5: 0 | O5: =SUM(I5:N5) -> 3.5 | Q5: =ROUNDUP(I5/20,3) -> 0.025 | R5: =ROUNDUP(J5/20,3) -> 0.05 | S5: =ROUNDUP(K5/20,3) -> 0.05 | T5: =ROUNDUP(L5/20,3) -> 0.025 | U5: =ROUNDUP(M5/20,3) -> 0.025 | V5: =ROUNDUP(N5/20,3) -> 0 | W5: =SUM(Q5:V5) -> 0.175 | Y5: =O5 -> 3.5 | Z5: =Y5*$Z$2 -> 175000 | AA5: =ROUNDUP(Y5*0.2,2) -> 0.7 | AB5: =ROUNDUP(AA5*$AB$2,-3) -> 49000 | AC5: =SUM(Z5,AB5) -> 224000 | AE5: =ROUNDUP(W5,2) -> 0.18 | AF5: =AE5*$AF$2 -> 180000 | AG5: =ROUNDUP(AE5*0.2,3) -> 0.036 | AH5: =SUM(AE5,AG5) -> 0.216 | AI5: =AG5*$AI$2 -> 50400 | AJ5: =ROUNDUP(SUM(AF5,AI5),-3) -> 231000
A6: =ROW()-3 -> 3 | D6: ニュースリリース対応 | E6: トップページ ・HTMLタグ使用可能対応（太字、色付け、URLリンク等使用可能とする。） ・ユーザ自身（IFC品証権限）で登録、更新、削除可能とする | F6: =O6 -> 3.5 | I6: 0.5 | J6: 1 | K6: 1 | L6: 0.5 | M6: 0.5 | N6: 0 | O6: =SUM(I6:N6) -> 3.5 | Q6: =ROUNDUP(I6/20,3) -> 0.025 | R6: =ROUNDUP(J6/20,3) -> 0.05 | S6: =ROUNDUP(K6/20,3) -> 0.05 | T6: =ROUNDUP(L6/20,3) -> 0.025 | U6: =ROUNDUP(M6/20,3) -> 0.025 | V6: =ROUNDUP(N6/20,3) -> 0 | W6: =SUM(Q6:V6) -> 0.175 | Y6: =O6 -> 3.5 | Z6: =Y6*$Z$2 -> 175000 | AA6: =ROUNDUP(Y6*0.2,2) -> 0.7 | AB6: =ROUNDUP(AA6*$AB$2,-3) -> 49000 | AC6: =SUM(Z6,AB6) -> 224000 | AE6: =ROUNDUP(W6,2) -> 0.18 | AF6: =AE6*$AF$2 -> 180000 | AG6: =ROUNDUP(AE6*0.2,3) -> 0.036 | AH6: =SUM(AE6,AG6) -> 0.216 | AI6: =AG6*$AI$2 -> 50400 | AJ6: =ROUNDUP(SUM(AF6,AI6),-3) -> 231000
A7: =ROW()-3 -> 4 | D7: キャンセル明細対応 | E7: 試験結果通知 ・キャンセル明細（訂正区分3）の場合、試験結果を登録、更新しない。 | F7: =O7 -> 2.5 | I7: 0.5 | J7: 0.5 | K7: 0.5 | L7: 0.5 | M7: 0.5 | N7: 0 | O7: =SUM(I7:N7) -> 2.5 | Q7: =ROUNDUP(I7/20,3) -> 0.025 | R7: =ROUNDUP(J7/20,3) -> 0.025 | S7: =ROUNDUP(K7/20,3) -> 0.025 | T7: =ROUNDUP(L7/20,3) -> 0.025 | U7: =ROUNDUP(M7/20,3) -> 0.025 | V7: =ROUNDUP(N7/20,3) -> 0 | W7: =SUM(Q7:V7) -> 0.125 | Y7: =O7 -> 2.5 | Z7: =Y7*$Z$2 -> 125000 | AA7: =ROUNDUP(Y7*0.2,2) -> 0.5 | AB7: =ROUNDUP(AA7*$AB$2,-3) -> 35000 | AC7: =SUM(Z7,AB7) -> 160000 | AE7: =ROUNDUP(W7,2) -> 0.13 | AF7: =AE7*$AF$2 -> 130000 | AG7: =ROUNDUP(AE7*0.2,3) -> 0.026 | AH7: =SUM(AE7,AG7) -> 0.156 | AI7: =AG7*$AI$2 -> 36400 | AJ7: =ROUNDUP(SUM(AF7,AI7),-3) -> 167000
A8: =ROW()-3 -> 5 | D8: ファイル添付機能実装 | E8: 生産状況確認、納期回答、生産完了、試験結果報告（横持情報入力以外の画面）の各明細にファイル添付機能を実装する。 ・生産状況確認画面はアップロード、ダウンロード、削除機能実装 他画面はダウンロード機能のみ実装 ・添付ファイルはPDFのみ ・Azure Blob Storageを使用する想定（Azure Blob Storage契約等の準備は出光DI部様対応） ・権限によるアップロード、ダウンロード機能の表示、非表示の制御を行う ・添付ファイル数については1明細につき1ファイルまでとする ・添付ファイルのファイルサイズ制限を設ける（外部ファイルで設定） ・各画面の出力ファイル（CSV）には添付ファイルのファイル名を表示する | F8: =O8 -> 10 | I8: 3 | J8: 5 | K8: 1 | L8: 0.5 | M8: 0.5 | N8: 0 | O8: =SUM(I8:N8) -> 10 | Q8: =ROUNDUP(I8/20,3) -> 0.15 | R8: =ROUNDUP(J8/20,3) -> 0.25 | S8: =ROUNDUP(K8/20,3) -> 0.05 | T8: =ROUNDUP(L8/20,3) -> 0.025 | U8: =ROUNDUP(M8/20,3) -> 0.025 | V8: =ROUNDUP(N8/20,3) -> 0 | W8: =SUM(Q8:V8) -> 0.5 | Y8: =O8 -> 10 | Z8: =Y8*$Z$2 -> 500000 | AA8: =ROUNDUP(Y8*0.2,2) -> 2 | AB8: =ROUNDUP(AA8*$AB$2,-3) -> 140000 | AC8: =SUM(Z8,AB8) -> 640000 | AE8: =ROUNDUP(W8,2) -> 0.5 | AF8: =AE8*$AF$2 -> 500000 | AG8: =ROUNDUP(AE8*0.2,3) -> 0.1 | AH8: =SUM(AE8,AG8) -> 0.6 | AI8: =AG8*$AI$2 -> 140000 | AJ8: =ROUNDUP(SUM(AF8,AI8),-3) -> 640000
A9: 御見積の前提条件 | N9: ※リリース工数は一番上の項目に集約 | X9: 初期流動 | Y9: 5 | Z9: =Y9*$Z$2 -> 250000 | AA9: =ROUNDUP(Y9*0.2,2) -> 1 | AB9: =ROUNDUP(AA9*$AB$2,-3) -> 70000 | AC9: =SUM(Z9,AB9) -> 320000 | AE9: =ROUNDUP(Y9/20,3) -> 0.25 | AF9: =AE9*$AF$2 -> 250000 | AG9: =ROUNDUP(AE9*0.2,3) -> 0.05 | AH9: =SUM(AE9,AG9) -> 0.3 | AI9: =AG9*$AI$2 -> 70000 | AJ9: =ROUNDUP(SUM(AF9,AI9),-3) -> 320000
AH10: =SUM(AH4:AH9) -> 1.908 | AI10: 合計 | AJ10: =SUM(AJ4:AJ9) -> 2037000
B11: リリース工数、初期流動工数を含んでおります。
B12: 費用は開発業務と管理業務で算出しております。
B13: 弊社千葉事業所（在宅勤務を含む）での作業を前提としております。現地等遠隔地での作業が発生する場合は、工数を変更する場合があります。
B14: 現地等遠隔地での作業が発生した場合は、交通費・宿泊費等の必要経費を別途ご請求させて頂きます。
B15: 御見積の工数には、ハードウェア・ミドルウェア等にかかる費用は含まれておりません。
B16: リリース作業は2人対応といたします。

Sheet 社員工数
A1: 社員工数入力（単位：人月）
A3: 見積番号 | D3: 案件名
A4: 受注番号 | B4: - | D4: 契約金額 | G4: 社員工数 | H4: =AF59 -> 0 | J4: 外注費金額 | K4: =外注費・経費!K4 -> 0 | M4: 経費金額 | N4: 0
A6: 区分 | B6: 社員番号 | C6: 氏名 | D6: 見積工数 | AF6: 合計
D7: 2021年度4Q | G7: 2022年度1Q | J7: 2022年度2Q | M7: 2022年度3Q | P7: 2022年度4Q | S7: 2023年度1Q | V7: 2023年度2Q | Y7: 2023年度3Q | AB7: 2023年度4Q | AE7: それ以降
D8: 44197 | E8: 44228 | F8: 44256 | G8: 44287 | H8: 44317 | I8: 44348 | J8: 44378 | K8: 44409 | L8: 44440 | M8: 44470 | N8: 44501 | O8: 44531 | P8: 44562 | Q8: 44593 | R8: 44621 | S8: 44652 | T8: 44682 | U8: 44713 | V8: 44743 | W8: 44774 | X8: 44805 | Y8: 44835 | Z8: 44866 | AA8: 44896 | AB8: 44927 | AC8: 44958 | AD8: 44986
AF9: =SUM(D9:AE9) -> 0
AF10: =SUM(D10:AE10) -> 0
AF11: =SUM(D11:AE11) -> 0
AF12: =SUM(D12:AE12) -> 0
AF13: =SUM(D13:AE13) -> 0
AF14: =SUM(D14:AE14) -> 0
AF15: =SUM(D15:AE15) -> 0
AF16: =SUM(D16:AE16) -> 0
AF17: =SUM(D17:AE17) -> 0
AF18: =SUM(D18:AE18) -> 0
AF19: =SUM(D19:AE19) -> 0
AF20: =SUM(D20:AE20) -> 0
... AF58: =SUM(D58:AE58) -> 0
A59: 合計 | D59: =SUM(D9:D58) -> 0 | E59: =SUM(E9:E58) -> 0 | F59: =SUM(F9:F58) -> 0 | G59: =SUM(G9:G58) -> 0 | H59: =SUM(H9:H58) -> 0 | I59: =SUM(I9:I58) -> 0 | J59: =SUM(J9:J58) -> 0 | K59: =SUM(K9:K58) -> 0 | ... AF59: =SUM(AF9:AF58) -> 0

Sheet 外注費・経費
A1: 外注費・経費（単位：円）
A3: 見積番号 | D3: 案件名 | E3: =社員工数!E3 -> 0
A4: 受注番号 | B4: - | D4: 契約金額 | E4: =社員工数!E4 -> 0 | G4: 社員工数 | H4: =社員工数!H4 -> 0 | J4: 外注費金額 | K4: =AF59 -> 0 | M4: 経費金額 | N4: =SUMIF(A:A,"経費",AF:AF) -> 0
A6: 区分 | B6: BPID | C6: 氏名 | D6: 見積金額 | AF6: 合計
D7: 2021年度4Q | G7: 2022年度1Q | J7: 2022年度2Q | M7: 2022年度3Q | P7: 2022年度4Q | S7: 2023年度1Q | V7: 2023年度2Q | Y7: 2023年度3Q | AB7: 2023年度4Q | AE7: それ以降
D8: 44197 | E8: 44228 | F8: 44256 | G8: 44287 | H8: 44317 | I8: 44348 | J8: 44378 | K8: 44409 | L8: 44440 | M8: 44470 | N8: 44501 | O8: 44531 | P8: 44562 | Q8: 44593 | R8: 44621 | S8: 44652 | T8: 44682 | U8: 44713 | V8: 44743 | W8: 44774 | X8: 44805 | Y8: 44835 | Z8: 44866 | AA8: 44896 | AB8: 44927 | AC8: 44958 | AD8: 44986
AF9: =SUM(D9:AE9) -> 0
AF10: =SUM(D10:AE10) -> 0
AF11: =SUM(D11:AE11) -> 0
AF12: =SUM(D12:AE12) -> 0
AF13: =SUM(D13:AE13) -> 0
AF14: =SUM(D14:AE14) -> 0
AF15: =SUM(D15:AE15) -> 0
AF16: =SUM(D16:AE16) -> 0
AF17: =SUM(D17:AE17) -> 0
AF18: =SUM(D18:AE18) -> 0
AF19: =SUM(D19:AE19) -> 0
AF20: =SUM(D20:AE20) -> 0
... AF58: =SUM(D58:AE58) -> 0
A59: 合計 | D59: =SUM(D9:D58) -> 0 | E59: =SUM(E9:E58) -> 0 | F59: =SUM(F9:F58) -> 0 | G59: =SUM(G9:G58) -> 0 | H59: =SUM(H9:H58) -> 0 | I59: =SUM(I9:I58) -> 0 | J59: =SUM(J9:J58) -> 0 | K59: =SUM(K9:K58) -> 0 | ... AF59: =SUM(AF9:AF58) -> 0

Sheet リストマスタ
A1: No | B1: 消費税 | C1: 見積有効期限 | D1: 作業形態 | E1: 作業場所 | F1: 支払条件 | G1: 摘要 | H1: 契約区分 | J1: 単位 | K1: 社員区分 | L1: 経費区分
B2: 税率 | H2: No | I2: 契約名
A3: 1 | B3: 0.1 | C3: 見積年月日より一ヶ月後 | D3: 準委任契約 | E3: 貴社内 | F3: 検収後翌月15日払い（但し、金融機関休業日の場合はその前営業日） | G3: ﾌﾟﾛｸﾞﾗﾏ | H3: 1 | I3: 固定契約 | J3: 人月 | K3: 入社済社員 | L3: BP
A4: 2 | E4: 弊社内 | F4: 検収後翌月末日払い（但し、金融機関休業日の場合はその翌営業日） | G4: ｼｽﾃﾑｴﾝｼﾞﾆｱ | H4: 2 | I4: 変動契約 | J4: 人日 | K4: 計画要員（等級1） | L4: 経費
A5: 3 | F5: 検収後翌々月10日払い（但し、金融機関休業日の場合はその翌営業日） | G5: ｵﾍﾟﾚｰﾀ | H5: 3 | I5: 時間契約 | J5: 時給 | K5: 計画要員（等級2）
A6: 4 | K6: 計画要員（等級3）
A7: 5 | K7: 計画要員（等級4）
A8: 6 | K8: 計画要員（等級5）
A9: 7 | K9: 計画要員（等級6）
A10: 8 | K10: 計画要員（等級7）
A11: 9 | K11: 計画要員（等級8）
A12: 10 | K12: 計画要員（等級9）
A13: 11
