Workbook
Name 作業ステータス: [1]コード内訳!$A$125:$A$132
Name 発生場所: [1]コード内訳!$A$115:$A$120

Sheet 概算見積
A1: 概 算 御 見 積 書 | X1: 見積番号 | AF1: -
X2: 見積年月日 | AF2: 45924
A5: 出光興産株式会社 御中
X8: 株式会社システムエグゼ
X9: 東京都中央区日本橋室町三丁目4番4号
X10: OVOL日本橋ビル7階
A11: 見積金額 | F11: =AE47 -> 2035200 | X11: 担当: 髙橋 裕輔
X12: MAIL: yusuke.takahashi@system-exe.jp
A16: 件名
B18: IFC生産委託ポータル 2次開発対応
A21: 作業形態
B23: 請負契約
A26: 作業場所
B28: 弊社内（在宅勤務を含む）
A31: 作業期間
B33: （仮）2025年10月20日 ～ 2025年12月31日
A36: 見積金額内訳
B38: No | D38: 項目 | Y38: 数量 | AE38: 金額 | AM38: 単価
B39: 1 | D39: =工数明細!D4 -> 訂正区分4対応 | Y39: =工数明細!AE4 -> 0.25 | AC39: 人月 | AE39: =AM39*Y39 -> 250000 | AM39: 1000000
B40: 2 | D40: =工数明細!D5 -> お知らせ対応 | Y40: =工数明細!AE5 -> 0.18 | AC40: 人月 | AE40: =AM40*Y40 -> 180000 | AM40: 1000000
B41: 3 | D41: =工数明細!D6 -> ニュースリリース対応 | Y41: =工数明細!AE6 -> 0.18 | AC41: 人月 | AE41: =AM41*Y41 -> 180000 | AM41: 1000000
B42: 4 | D42: =工数明細!D7 -> キャンセル明細対応 | Y42: =工数明細!AE7 -> 0.13 | AC42: 人月 | AE42: =AM42*Y42 -> 130000 | AM42: 1000000
B43: 5 | D43: =工数明細!D8 -> ファイル添付機能実装 | Y43: =工数明細!AE8 -> 0.5 | AC43: 人月 | AE43: =AM43*Y43 -> 500000 | AM43: 1000000
B44: 6 | D44: リリース | Y44: 0.1 | AC44: 人月 | AE44: =AM44*Y44 -> 100000 | AM44: 1000000
B45: 7 | D45: 初期流動 | Y45: =工数明細!AE10 -> 0.25 | AC45: 人月 | AE45: =AM45*Y45 -> 250000 | AM45: 1000000
B46: 8 | D46: プロジェクト管理 | Y46: =SUM(工数明細!AG4:AG10) -> 0.318 | AC46: 人月 | AE46: =AM46*Y46 -> 445200 | AM46: 1400000
D47: 合計 | Y47: =SUM(Y39:AB46) -> 1.908 | AC47: 人月 | AE47: =SUM(AE39:AJ46) -> 2035200 | AM47: -
A49: 納品物
B51: ・ | C51: 設計書 | T51: ・ | U51: 結合テスト仕様書兼結果報告書
B52: ・ | C52: ソースコード | T52: ・ | U52: システムテスト仕様書兼結果報告書
B53: ・ | C53: 本番作業手順書
A55: 作業内容
B57: No | D57: 工程 | I57: 作業内容 | U57: 成果物
B58: 1 | D58: 調査・設計 | I58: ・ | J58: 対象箇所及び影響調査 | U58: ・ | V58: 基本設計書
I59: ・ | J59: 基本設計作成（新規作成・既存更新） | U59: ・ | V59: 詳細設計書
I60: ・ | J60: 詳細設計作成（新規作成・既存更新）
B61: 2 | D61: 開発・単体テスト | I61: 「改修対象」を参照 | U61: ・ | V61: プログラム一式
B63: 3 | D63: 結合テスト | I63: ・ | J63: 結合テスト実施 | U63: ・ | V63: 結合テスト仕様書
B65: 4 | D65: システムテスト | I65: ・ | J65: システムテスト実施 | U65: ・ | V65: システムテスト仕様書
B67: 5 | D67: 受入テスト | I67: ・ | J67: 受入テスト対応
...

Sheet 工数明細
A1: IFC生産委託システム追加開発対応 | Y1: 人日 | AE1: 人月 | AK1: 工程別作業工数合算
I2: 人日 | Q2: 人月 | Y2: 開発 | Z2: 50000 | AA2: 管理 | AB2: 70000 | AE2: 開発 | AF2: 1000000 | AG2: 管理 | AH2: 1400000 | AK2: 人日 | AS2: 人月
A3: No. | B3: 案件名 | C3: 完成希望日 | D3: 内容 | E3: 改修内容 | F3: 概算工数 開発工数内訳（人日） | G3: 概算工数 開発工数（人日） | H3: 管理工数込み（人日） | I3: 調査・設計 | J3: PG | K3: IT | L3: ST | M3: UAT | N3: リリース | O3: 合計 | Q3: 調査・設計 | R3: PG | S3: IT | T3: ST | U3: UAT | V3: リリース | W3: 合計 | X3: 備考 | Y3: 人日 | Z3: 金額 | AA3: 人日 | AB3: 金額 | AC3: 合計金額 | AE3: 人月 | AF3: 金額 | AG3: 人月 | AH3: 金額 | AI3: 合計金額 | AK3: 調査・設計 | AL3: PG | AM3: IT | AN3: ST | AO3: UAT | AP3: リリース | AQ3: 合計 | AS3: 調査・設計 | AT3: PG | AU3: IT | AV3: ST | AW3: UAT | AX3: リリース | AY3: 合計
A4: =ROW()-3 -> 1 | B4: IFC生産委託システム追加開発対応 | C4: 2025/12月頃 | D4: 訂正区分4対応 | E4: 生産状況連携 ・OneSAPから訂正区分4で連携された場合、生産状況テーブルの納期を更新対象外とする。 ・中間テーブルにはそのまま登録し、生産状況テーブルに登録する際に条件を追加する。 | F4: =O4 -> 5 | G4: =SUM(F4:F8) -> 24.5 | H4: =SUM(Y4:Y7)+SUM(AA4:AA7) -> 17.4 | I4: 0.5 | J4: 1 | K4: 2 | L4: 1 | M4: 0.5 | N4: 0 | O4: =SUM(I4:N4) -> 5 | Q4: =ROUNDUP(I4/20,3) -> 0.025 | R4: =ROUNDUP(J4/20,3) -> 0.05 | S4: =ROUNDUP(K4/20,3) -> 0.1 | T4: =ROUNDUP(L4/20,3) -> 0.05 | U4: =ROUNDUP(M4/20,3) -> 0.025 | V4: =ROUNDUP(N4/20,3) -> 0 | W4: =SUM(Q4:V4) -> 0.25 | Y4: =O4 -> 5 | Z4: =Y4*$Z$2 -> 250000 | AA4: =ROUNDUP(Y4*0.2,2) -> 1 | AB4: =ROUNDUP(AA4*$AB$2,-3) -> 70000 | AC4: =SUM(Z4,AB4) -> 320000 | AE4: =ROUNDUP(W4,2) -> 0.25 | AF4: =AE4*$AF$2 -> 250000 | AG4: =ROUNDUP(AE4*0.2,3) -> 0.05 | AH4: =AG4*$AH$2 -> 70000 | AI4: =SUM(AF4,AH4) -> 320000 | AK4: =SUM(I4:I7) -> 2 | AL4: =SUM(J4:J7) -> 3.5 | AM4: =SUM(K4:K7) -> 4.5 | AN4: =SUM(L4:L7) -> 2.5 | AO4: =SUM(M4:M7) -> 2 | AP4: =SUM(N4:N7) -> 0 | AQ4: =SUM(O4:O7) -> 14.5 | AS4: =SUM(Q4:Q7) -> 0.1 | AT4: =SUM(R4:R7) -> 0.175 | AU4: =SUM(S4:S7) -> 0.225 | AV4: =SUM(T4:T7) -> 0.125 | AW4: =SUM(U4:U7) -> 0.1 | AX4: =SUM(V4:V7) -> 0 | AY4: =SUM(W4:W7) -> 0.725
A5: =ROW()-3 -> 2 | D5: お知らせ対応 | E5: トップページ ・トップページ内に子画面を表示し、お知らせ情報を表示する。 ・お知らせ権限が無い場合、子画面を表示しない。 | F5: =O5 -> 3.5 | I5: 0.5 | J5: 1 | K5: 1 | L5: 0.5 | M5: 0.5 | N5: 0 | O5: =SUM(I5:N5) -> 3.5 | Q5: =ROUNDUP(I5/20,3) -> 0.025 | R5: =ROUNDUP(J5/20,3) -> 0.05 | S5: =ROUNDUP(K5/20,3) -> 0.05 | T5: =ROUNDUP(L5/20,3) -> 0.025 | U5: =ROUNDUP(M5/20,3) -> 0.025 | V5: =ROUNDUP(N5/20,3) -> 0 | W5: =SUM(Q5:V5) -> 0.175 | Y5: =O5 -> 3.5 | Z5: =Y5*$Z$2 -> 175000 | AA5: =ROUNDUP(Y5*0.2,2) -> 0.7 | AB5: =ROUNDUP(AA5*$AB$2,-3) -> 49000 | AC5: =SUM(Z5,AB5) -> 224000 | AE5: =ROUNDUP(W5,2) -> 0.18 | AF5: =AE5*$AF$2 -> 180000 | AG5: =ROUNDUP(AE5*0.2,3) -> 0.036 | AH5: =AG5*$AH$2 -> 50400 | AI5: =SUM(AF5,AH5) -> 230400
A6: =ROW()-3 -> 3 | D6: ニュースリリース対応 | E6: トップページ ・HTMLタグ使用可能対応（太字、色付け、URLリンク等使用可能とする。） ・ユーザ自身（IFC品証権限）で登録、更新、削除可能とする | F6: =O6 -> 3.5 | I6: 0.5 | J6: 1 | K6: 1 | L6: 0.5 | M6: 0.5 | N6: 0 | O6: =SUM(I6:N6) -> 3.5 | Q6: =ROUNDUP(I6/20,3) -> 0.025 | R6: =ROUNDUP(J6/20,3) -> 0.05 | S6: =ROUNDUP(K6/20,3) -> 0.05 | T6: =ROUNDUP(L6/20,3) -> 0.025 | U6: =ROUNDUP(M6/20,3) -> 0.025 | V6: =ROUNDUP(N6/20,3) -> 0 | W6: =SUM(Q6:V6) -> 0.175 | Y6: =O6 -> 3.5 | Z6: =Y6*$Z$2 -> 175000 | AA6: =ROUNDUP(Y6*0.2,2) -> 0.7 | AB6: =ROUNDUP(AA6*$AB$2,-3) -> 49000 | AC6: =SUM(Z6,AB6) -> 224000 | AE6: =ROUNDUP(W6,2) -> 0.18 | AF6: =AE6*$AF$2 -> 180000 | AG6: =ROUNDUP(AE6*0.2,3) -> 0.036 | AH6: =AG6*$AH$2 -> 50400 | AI6: =SUM(AF6,AH6) -> 230400
A7: =ROW()-3 -> 4 | D7: キャンセル明細対応 | E7: 試験結果通知 ・キャンセル明細（訂正区分3）の場合、試験結果を登録、更新しない。 | F7: =O7 -> 2.5 | I7: 0.5 | J7: 0.5 | K7: 0.5 | L7: 0.5 | M7: 0.5 | N7: 0 | O7: =SUM(I7:N7) -> 2.5 | Q7: =ROUNDUP(I7/20,3) -> 0.025 | R7: =ROUNDUP(J7/20,3) -> 0.025 | S7: =ROUNDUP(K7/20,3) -> 0.025 | T7: =ROUNDUP(L7/20,3) -> 0.025 | U7: =ROUNDUP(M7/20,3) -> 0.025 | V7: =ROUNDUP(N7/20,3) -> 0 | W7: =SUM(Q7:V7) -> 0.125 | Y7: =O7 -> 2.5 | Z7: =Y7*$Z$2 -> 125000 | AA7: =ROUNDUP(Y7*0.2,2) -> 0.5 | AB7: =ROUNDUP(AA7*$AB$2,-3) -> 35000 | AC7: =SUM(Z7,AB7) -> 160000 | AE7: =ROUNDUP(W7,2) -> 0.13 | AF7: =AE7*$AF$2 -> 130000 | AG7: =ROUNDUP(AE7*0.2,3) -> 0.026 | AH7: =AG7*$AH$2 -> 36400 | AI7: =SUM(AF7,AH7) -> 166400
A8: =ROW()-3 -> 5 | D8: ファイル添付機能実装 | E8: 生産状況確認、納期回答、生産完了、試験結果報告（横持情報入力以外の画面）の各明細にファイル添付機能を実装する。 ・生産状況確認画面はアップロード、ダウンロード、削除機能実装 他画面はダウンロード機能のみ実装 ・添付ファイルはPDFのみ ・Azure Blob Storageを使用する想定（Azure Blob Storage契約等の準備は出光DI部様対応） ・権限によるアップロード、ダウンロード機能の表示、非表示の制御を行う ・添付ファイル数については1明細につき1ファイルまでとする ・添付ファイルのファイルサイズ制限を設ける（外部ファイルで設定） ・各画面の出力ファイル（CSV）には添付ファイルのファイル名を表示する | F8: =O8 -> 10 | I8: 3 | J8: 5 | K8: 1 | L8: 0.5 | M8: 0.5 | N8: 0 | O8: =SUM(I8:N8) -> 10 | Q8: =ROUNDUP(I8/20,3) -> 0.15 | R8: =ROUNDUP(J8/20,3) -> 0.25 | S8: =ROUNDUP(K8/20,3) -> 0.05 | T8: =ROUNDUP(L8/20,3) -> 0.025 | U8: =ROUNDUP(M8/20,3) -> 0.025 | V8: =ROUNDUP(N8/20,3) -> 0 | W8: =SUM(Q8:V8) -> 0.5 | Y8: =O8 -> 10 | Z8: =Y8*$Z$2 -> 500000 | AA8: =ROUNDUP(Y8*0.2,2) -> 2 | AB8: =ROUNDUP(AA8*$AB$2,-3) -> 140000 | AC8: =SUM(Z8,AB8) -> 640000 | AE8: =ROUNDUP(W8,2) -> 0.5 | AF8: =AE8*$AF$2 -> 500000 | AG8: =ROUNDUP(AE8*0.2,3) -> 0.1 | AH8: =AG8*$AH$2 -> 140000 | AI8: =SUM(AF8,AH8) -> 640000
A9: 御見積の前提条件 | N9: ※リリース工数は一番上の項目に集約 | X9: リリース | AE9: 0.1 | AF9: =AE9*$AF$2 -> 100000 | AG9: =ROUNDUP(AE9*0.2,3) -> 0.02 | AH9: =AG9*$AH$2 -> 28000 | AI9: =SUM(AF9,AH9) -> 128000
X10: 初期流動 | Y10: 5 | Z10: =Y10*$Z$2 -> 250000 | AA10: =ROUNDUP(Y10*0.2,2) -> 1 | AB10: =ROUNDUP(AA10*$AB$2,-3) -> 70000 | AC10: =SUM(Z10,AB10) -> 320000 | AE10: =ROUNDUP(Y10/20,3) -> 0.25 | AF10: =AE10*$AF$2 -> 250000 | AG10: =ROUNDUP(AE10*0.2,3) -> 0.05 | AH10: =AG10*$AH$2 -> 70000 | AI10: =SUM(AF10,AH10) -> 320000
B11: リリース工数、初期流動工数を含んでおります。 | AH11: 合計 | AI11: =SUM(AI4:AI10) -> 2035200
B12: 費用は開発業務と管理業務で算出しております。
B13: 弊社千葉事業所（在宅勤務を含む）での作業を前提としております。現地等遠隔地での作業が発生する場合は、工数を変更する場合があります。
B14: 現地等遠隔地での作業が発生した場合は、交通費・宿泊費等の必要経費を別途ご請求させて頂きます。
B15: 御見積の工数には、ハードウェア・ミドルウェア等にかかる費用は含まれておりません。
B16: リリース作業は2人対応といたします。

Sheet 工数明細 (2)
A1: IFC生産委託システム追加開発対応 | Y1: 人日 | AE1: 人月 | AL1: 工程別作業工数合算
I2: 人日 | Q2: 人月 | Y2: 開発 | Z2: 50000 | AA2: 管理 | AB2: 70000 | AE2: 開発 | AF2: 1000000 | AG2: 管理 | AI2: 1400000 | AL2: 人日 | AT2: 人月
A3: No. | B3: 案件名 | C3: 完成希望日 | D3: 内容 | E3: 改修内容 | F3: 概算工数 開発工数内訳（人日） | G3: 概算工数 開発工数（人日） | H3: 管理工数込み（人日） | I3: 調査・設計 | J3: PG | K3: IT | L3: ST | M3: UAT | N3: リリース | O3: 合計 | Q3: 調査・設計 | R3: PG | S3: IT | T3: ST | U3: UAT | V3: リリース | W3: 合計 | X3: 備考 | Y3: 人日 | Z3: 金額 | AA3: 人日 | AB3: 金額 | AC3: 合計金額 | AE3: 人月 | AF3: 金額 | AG3: 人月 | AI3: 金額 | AJ3: 合計金額 | AL3: 調査・設計 | AM3: PG | AN3: IT | AO3: ST | AP3: UAT | AQ3: リリース | AR3: 合計 | AT3: 調査・設計 | AU3: PG | AV3: IT | AW3: ST | AX3: UAT | AY3: リリース | AZ3: 合計
A4: =ROW()-3 -> 1 | B4: IFC生産委託システム追加開発対応 | C4: 2025/12月頃 | D4: 訂正区分4対応 | E4: 生産状況連携 ・OneSAPから訂正区分4で連携された場合、生産状況テーブルの納期を更新対象外とする。 ・中間テーブルにはそのまま登録し、生産状況テーブルに登録する際に条件を追加する。 | F4: =O4 -> 7 | G4: =SUM(F4:F8) -> 26.5 | H4: =SUM(Y4:Y7)+SUM(AA4:AA7) -> 19.8 | I4: 0.5 | J4: 1 | K4: 2 | L4: 1 | M4: 0.5 | N4: 2 | O4: =SUM(I4:N4) -> 7 | Q4: =ROUNDUP(I4/20,3) -> 0.025 | R4: =ROUNDUP(J4/20,3) -> 0.05 | S4: =ROUNDUP(K4/20,3) -> 0.1 | T4: =ROUNDUP(L4/20,3) -> 0.05 | U4: =ROUNDUP(M4/20,3) -> 0.025 | V4: =ROUNDUP(N4/20,3) -> 0.1 | W4: =SUM(Q4:V4) -> 0.35 | Y4: =O4 -> 7 | Z4: =Y4*$Z$2 -> 350000 | AA4: =ROUNDUP(Y4*0.2,2) -> 1.4 | AB4: =ROUNDUP(AA4*$AB$2,-3) -> 98000 | AC4: =SUM(Z4,AB4) -> 448000 | AE4: =ROUNDUP(W4,2) -> 0.35 | AF4: =AE4*$AF$2 -> 350000 | AG4: =ROUNDUP(AE4*0.2,3) -> 0.07 | AH4: =SUM(AE4,AG4) -> 0.42 | AI4: =AG4*$AI$2 -> 98000 | AJ4: =ROUNDUP(SUM(AF4,AI4),-3) -> 448000 | AL4: =SUM(I4:I7) -> 2 | AM4: =SUM(J4:J7) -> 3.5 | AN4: =SUM(K4:K7) -> 4.5 | AO4: =SUM(L4:L7) -> 2.5 | AP4: =SUM(M4:M7) -> 2 | AQ4: =SUM(N4:N7) -> 2 | AR4: =SUM(O4:O7) -> 16.5 | AT4: =SUM(Q4:Q7) -> 0.1 | AU4: =SUM(R4:R7) -> 0.175 | AV4: =SUM(S4:S7) -> 0.225 | AW4: =SUM(T4:T7) -> 0.125 | AX4: =SUM(U4:U7) -> 0.1 | AY4: =SUM(V4:V7) -> 0.1 | AZ4: =SUM(W4:W7) -> 0.825
A5: =ROW()-3 -> 2 | D5: お知らせ対応 | E5: トップページ ・トップページ内に子画面を表示し、お知らせ情報を表示する。 ・お知らせ権限が無い場合、子画面を表示しない。 | F5: =O5 -> 3.5 | I5: 0.5 | J5: 1 | K5: 1 | L5: 0.5 | M5: 0.5 | N5: 0 | O5: =SUM(I5:N5) -> 3.5 | Q5: =ROUNDUP(I5/20,3) -> 0.025 | R5: =ROUNDUP(J5/20,3) -> 0.05 | S5: =ROUNDUP(K5/20,3) -> 0.05 | T5: =ROUNDUP(L5/20,3) -> 0.025 | U5: =ROUNDUP(M5/20,3) -> 0.025 | V5: =ROUNDUP(N5/20,3) -> 0 | W5: =SUM(Q5:V5) -> 0.175 | Y5: =O5 -> 3.5 | Z5: =Y5*$Z$2 -> 175000 | AA5: =ROUNDUP(Y5*0.2,2) -> 0.7 | AB5: =ROUNDUP(AA5*$AB$2,-3) -> 49000 | AC5: =SUM(Z5,AB5) -> 224000 | AE5: =ROUNDUP(W5,2) -> 0.18 | AF5: =AE5*$AF$2 -> 180000 | AG5: =ROUNDUP(AE5*0.2,3) -> 0.036 | AH5: =SUM(AE5,AG5) -> 0.216 | AI5: =AG5*$AI$2 -> 50400 | AJ5: =ROUNDUP(SUM(AF5,AI5),-3) -> 231000
A6: =ROW()-3 -> 3 | D6: ニュースリリース対応 | E6: トップページ ・HTMLタグ使用可能対応（太字、色付け、URLリンク等使用可能とする。） ・ユーザ自身（IFC品証権限）で登録、更新、削除可能とする | F6: =O6 -> 3.5 | I6: 0.5 | J6: 1 | K6: 1 | L6: 0.5 | M6: 0.5 | N6: 0 | O6: =SUM(I6:N6) -> 3.5 | Q6: =ROUNDUP(I6/20,3) -> 0.025 | R6: =ROUNDUP(J6/20,3) -> 0.05 | S6: =ROUNDUP(K6/20,3) -> 0.05 | T6: =ROUNDUP(L6/20,3) -> 0.025 | U6: =ROUNDUP(M6/20,3) -> 0.025 | V6: =ROUNDUP(N6/20,3) -> 0 | W6: =SUM(Q6:V6) -> 0.175 | Y6: =O6 -> 3.5 | Z6: =Y6*$Z$2 -> 175000 | AA6: =ROUNDUP(Y6*0.2,2) -> 0.7 | AB6: =ROUNDUP(AA6*$AB$2,-3) -> 49000 | AC6: =SUM(Z6,AB6) -> 224000 | AE6: =ROUNDUP(W6,2) -> 0.18 | AF6: =AE6*$AF$2 -> 180000 | AG6: =ROUNDUP(AE6*0.2,3) -> 0.036 | AH6: =SUM(AE6,AG6) -> 0.216 | AI6: =AG6*$AI$2 -> 50400 | AJ6: =ROUNDUP(SUM(AF6,AI6),-3) -> 231000
A7: =ROW()-3 -> 4 | D7: キャンセル明細対応 | E7: 試験結果通知 ・キャンセル明細（訂正区分3）の場合、試験結果を登録、更新しない。 | F7: =O7 -> 2.5 | I7: 0.5 | J7: 0.5 | K7: 0.5 | L7: 0.5 | M7: 0.5 | N7: 0 | O7: =SUM(I7:N7) -> 2.5 | Q7: =ROUNDUP(I7/20,3) -> 0.025 | R7: =ROUNDUP(J7/20,3) -> 0.025 | S7: =ROUNDUP(K7/20,3) -> 0.025 | T7: =ROUNDUP(L7/20,3) -> 0.025 | U7: =ROUNDUP(M7/20,3) -> 0.025 | V7: =ROUNDUP(N7/20,3) -> 0 | W7: =SUM(Q7:V7) -> 0.125 | Y7: =O7 -> 2.5 | Z7: =Y7*$Z$2 -> 125000 | AA7: =ROUNDUP(Y7*0.2,2) -> 0.5 | AB7: =ROUNDUP(AA7*$AB$2,-3) -> 35000 | AC7: =SUM(Z7,AB7) -> 160000 | AE7: =ROUNDUP(W7,2) -> 0.13 | AF7: =AE7*$AF$2 -> 130000 | AG7: =ROUNDUP(AE7*0.2,3) -> 0.026 | AH7: =SUM(AE7,AG7) -> 0.156 | AI7: =AG7*$AI$2 -> 36400 | AJ7: =ROUNDUP(SUM(AF7,AI7),-3) -> 167000
A8: =ROW()-3 -> 5 | D8: ファイル添付機能実装 | E8: 生産状況確認、納期回答、生産完了、試験結果報告（横持情報入力以外の画面）の各明細にファイル添付機能を実装する。 ・生産状況確認画面はアップロード、ダウンロード、削除機能実装 他画面はダウンロード機能のみ実装 ・添付ファイルはPDFのみ ・Azure Blob Storageを使用する想定（Azure Blob Storage契約等の準備は出光DI部様対応） ・権限によるアップロード、ダウンロード機能の表示、非表示の制御を行う ・添付ファイル数については1明細につき1ファイルまでとする ・添付ファイルのファイルサイズ制限を設ける（外部ファイルで設定） ・各画面の出力ファイル（CSV）には添付ファイルのファイル名を表示する | F8: =O8 -> 10 | I8: 3 | J8: 5 | K8: 1 | L8: 0.5 | M8: 0.5 | N8: 0 | O8: =SUM(I8:N8) -> 10 | Q8: =ROUNDUP(I8/20,3) -> 0.15 | R8: =ROUNDUP(J8/20,3) -> 0.25 | S8: =ROUNDUP(K8/20,3) -> 0.05 | T8: =ROUNDUP(L8/20,3) -> 0.025 | U8: =ROUNDUP(M8/20,3) -> 0.025 | V8: =ROUNDUP(N8/20,3) -> 0 | W8: =SUM(Q8:V8) -> 0.5 | Y8: =O8 -> 10 | Z8: =Y8*$Z$2 -> 500000 | AA8: =ROUNDUP(Y8*0.2,2) -> 2 | AB8: =ROUNDUP(AA8*$AB$2,-3) -> 140000 | AC8: =SUM(Z8,AB8) -> 640000 | AE8: =ROUNDUP(W8,2) -> 0.5 | AF8: =AE8*$AF$2 -> 500000 | AG8: =ROUNDUP(AE8*0.2,3) -> 0.1 | AH8: =SUM(AE8,AG8) -> 0.6 | AI8: =AG8*$AI$2 -> 140000 | AJ8: =ROUNDUP(SUM(AF8,AI8),-3) -> 640000
A9: 御見積の前提条件 | N9: ※リリース工数は一番上の項目に集約 | X9: 初期流動 | Y9: 5 | Z9: =Y9*$Z$2 -> 250000 | AA9: =ROUNDUP(Y9*0.2,2) -> 1 | AB9: =ROUNDUP(AA9*$AB$2,-3) -> 70000 | AC9: =SUM(Z9,AB9) -> 320000 | AE9: =ROUNDUP(Y9/20,3) -> 0.25 | AF9: =AE9*$AF$2 -> 250000 | AG9: =ROUNDUP(AE9*0.2,3) -> 0.05 | AH9: =SUM(AE9,AG9) -> 0.3 | AI9: =AG9*$AI$2 -> 70000 | AJ9: =ROUNDUP(SUM(AF9,AI9),-3) -> 320000
AH10: =SUM(AH4:AH9) -> 1.908 | AI10: 合計 | AJ10: =SUM(AJ4:AJ9) -> 2037000
B11: リリース工数、初期流動工数を含んでおります。
B12: 費用は開発業務と管理業務で算出しております。
B13: 弊社千葉事業所（在宅勤務を含む）での作業を前提としております。現地等遠隔地での作業が発生する場合は、工数を変更する場合があります。
B14: 現地等遠隔地での作業が発生した場合は、交通費・宿泊費等の必要経費を別途ご請求させて頂きます。
B15: 御見積の工数には、ハードウェア・ミドルウェア等にかかる費用は含まれておりません。
B16: リリース作業は2人対応といたします。

Sheet 社員工数
A1: 社員工数入力（単位：人月）
A3: 見積番号 | D3: 案件名
A4: 受注番号 | B4: - | D4: 契約金額 | G4: 社員工数 | H4: =AF59 -> 0 | J4: 外注費金額 | K4: =外注費・経費!K4 -> 0 | M4: 経費金額 | N4: 0
A6: 区分 | B6: 社員番号 | C6: 氏名 | D6: 見積工数 | AF6: 合計
D7: 2021年度4Q | G7: 2022年度1Q | J7: 2022年度2Q | M7: 2022年度3Q | P7: 2022年度4Q | S7: 2023年度1Q | V7: 2023年度2Q | Y7: 2023年度3Q | AB7: 2023年度4Q | AE7: それ以降
D8: 44197 | E8: 44228 | F8: 44256 | G8: 44287 | H8: 44317 | I8: 44348 | J8: 44378 | K8: 44409 | L8: 44440 | M8: 44470 | N8: 44501 | O8: 44531 | P8: 44562 | Q8: 44593 | R8: 44621 | S8: 44652 | T8: 44682 | U8: 44713 | V8: 44743 | W8: 44774 | X8: 44805 | Y8: 44835 | Z8: 44866 | AA8: 44896 | AB8: 44927 | AC8: 44958 | AD8: 44986
AF9: =SUM(D9:AE9) -> 0
AF10: =SUM(D10:AE10) -> 0
AF11: =SUM(D11:AE11) -> 0
AF12: =SUM(D12:AE12) -> 0
AF13: =SUM(D13:AE13) -> 0
AF14: =SUM(D14:AE14) -> 0
AF15: =SUM(D15:AE15) -> 0
AF16: =SUM(D16:AE16) -> 0
AF17: =SUM(D17:AE17) -> 0
AF18: =SUM(D18:AE18) -> 0
AF19: =SUM(D19:AE19) -> 0
AF20: =SUM(D20:AE20) -> 0
... AF58: =SUM(D58:AE58) -> 0
A59: 合計 | D59: =SUM(D9:D58) -> 0 | E59: =SUM(E9:E58) -> 0 | F59: =SUM(F9:F58) -> 0 | G59: =SUM(G9:G58) -> 0 | H59: =SUM(H9:H58) -> 0 | I59: =SUM(I9:I58) -> 0 | J59: =SUM(J9:J58) -> 0 | K59: =SUM(K9:K58) -> 0 | ... AF59: =SUM(AF9:AF58) -> 0

Sheet 外注費・経費
A1: 外注費・経費（単位：円）
A3: 見積番号 | D3: 案件名 | E3: =社員工数!E3 -> 0
A4: 受注番号 | B4: - | D4: 契約金額 | E4: =社員工数!E4 -> 0 | G4: 社員工数 | H4: =社員工数!H4 -> 0 | J4: 外注費金額 | K4: =AF59 -> 0 | M4: 経費金額 | N4: =SUMIF(A:A,"経費",AF:AF) -> 0
A6: 区分 | B6: BPID | C6: 氏名 | D6: 見積金額 | AF6: 合計
D7: 2021年度4Q | G7: 2022年度1Q | J7: 2022年度2Q | M7: 2022年度3Q | P7: 2022年度4Q | S7: 2023年度1Q | V7: 2023年度2Q | Y7: 2023年度3Q | AB7: 2023年度4Q | AE7: それ以降
D8: 44197 | E8: 44228 | F8: 44256 | G8: 44287 | H8: 44317 | I8: 44348 | J8: 44378 | K8: 44409 | L8: 44440 | M8: 44470 | N8: 44501 | O8: 44531 | P8: 44562 | Q8: 44593 | R8: 44621 | S8: 44652 | T8: 44682 | U8: 44713 | V8: 44743 | W8: 44774 | X8: 44805 | Y8: 44835 | Z8: 44866 | AA8: 44896 | AB8: 44927 | AC8: 44958 | AD8: 44986
AF9: =SUM(D9:AE9) -> 0
AF10: =SUM(D10:AE10) -> 0
AF11: =SUM(D11:AE11) -> 0
AF12: =SUM(D12:AE12) -> 0
AF13: =SUM(D13:AE13) -> 0
AF14: =SUM(D14:AE14) -> 0
AF15: =SUM(D15:AE15) -> 0
AF16: =SUM(D16:AE16) -> 0
AF17: =SUM(D17:AE17) -> 0
AF18: =SUM(D18:AE18) -> 0
AF19: =SUM(D19:AE19) -> 0
AF20: =SUM(D20:AE20) -> 0
... AF58: =SUM(D58:AE58) -> 0
A59: 合計 | D59: =SUM(D9:D58) -> 0 | E59: =SUM(E9:E58) -> 0 | F59: =SUM(F9:F58) -> 0 | G59: =SUM(G9:G58) -> 0 | H59: =SUM(H9:H58) -> 0 | I59: =SUM(I9:I58) -> 0 | J59: =SUM(J9:J58) -> 0 | K59: =SUM(K9:K58) -> 0 | ... AF59: =SUM(AF9:AF58) -> 0

Sheet リストマスタ
A1: No | B1: 消費税 | C1: 見積有効期限 | D1: 作業形態 | E1: 作業場所 | F1: 支払条件 | G1: 摘要 | H1: 契約区分 | J1: 単位 | K1: 社員区分 | L1: 経費区分
B2: 税率 | H2: No | I2: 契約名
A3: 1 | B3: 0.1 | C3: 見積年月日より一ヶ月後 | D3: 準委任契約 | E3: 貴社内 | F3: 検収後翌月15日払い（但し、金融機関休業日の場合はその前営業日） | G3: ﾌﾟﾛｸﾞﾗﾏ | H3: 1 | I3: 固定契約 | J3: 人月 | K3: 入社済社員 | L3: BP
A4: 2 | E4: 弊社内 | F4: 検収後翌月末日払い（但し、金融機関休業日の場合はその翌営業日） | G4: ｼｽﾃﾑｴﾝｼﾞﾆｱ | H4: 2 | I4: 変動契約 | J4: 人日 | K4: 計画要員（等級1） | L4: 経費
A5: 3 | F5: 検収後翌々月10日払い（但し、金融機関休業日の場合はその翌営業日） | G5: ｵﾍﾟﾚｰﾀ | H5: 3 | I5: 時間契約 | J5: 時給 | K5: 計画要員（等級2）
A6: 4 | K6: 計画要員（等級3）
A7: 5 | K7: 計画要員（等級4）
A8: 6 | K8: 計画要員（等級5）
A9: 7 | K9: 計画要員（等級6）
A10: 8 | K10: 計画要員（等級7）
A11: 9 | K11: 計画要員（等級8）
A12: 10 | K12: 計画要員（等級9）
A13: 11
