Workbook
Name ステータス: 選択肢!$G$2:$G$21
Name セキュリティに配慮した開発計画: プロジェクト計画書!$L$41
Name セキュリティ目標: プロジェクト計画書!$L$39
Name プロジェクトコード: プロジェクト計画書!$L$11
Name プロジェクト概要: プロジェクト計画書!$L$13
Name プロジェクト区分: プロジェクト計画書!$AI$18
Name プロジェクト名: プロジェクト計画書!$L$12
Name プロジェクト目的: プロジェクト計画書!$L$33
Name ヘッダプロジェクト名: マスタ!$B$10
Name ヘッダ文書名: マスタ!$B$11
Name ヘッダ文書名‐改訂履歴: マスタ!$B$15
Name ヘッダ文書名‐補足１: マスタ!$B$12
Name ヘッダ文書名‐補足２: マスタ!$B$13
Name ヘッダ文書名‐補足３: マスタ!$B$14
Name ヘッダ様式名称: マスタ!$B$16
Name 改定ステータス: 選択肢!$C$2:$C$21
Name 改定承認形式: 選択肢!$B$2:$B$21
Name 改定担当者: 選択肢!$A$2:$A$21
Name 区分: 選択肢!$D$2:$D$21
Name 計画_AWS: プロジェクト計画書!$AI$26
Name 計画_Azure: プロジェクト計画書!$AI$27
Name 計画_CJA: プロジェクト計画書!$AI$25
Name 計画_EXECloud: プロジェクト計画書!$AI$29
Name 計画_Java: プロジェクト計画書!$L$26
Name 計画_NET: プロジェクト計画書!$L$27
Name 計画_OCI: プロジェクト計画書!$AI$28
Name 計画_Python: プロジェクト計画書!$L$28
Name 計画_VBA: プロジェクト計画書!$L$29
Name 計画_アライアンス: プロジェクト計画書!$AI$23
Name 計画_オフショア: プロジェクト計画書!$L$24
Name 計画_クラウドその他: プロジェクト計画書!$AI$30
Name 計画_クラウドネイティブ: プロジェクト計画書!$AI$24
Name 計画_テーブル数: プロジェクト計画書!$L$77
Name 計画_バッチ数: プロジェクト計画書!$L$76
Name 計画_プロジェクトマネージャ: プロジェクト計画書!$AI$16
Name 計画_プロジェクトメンバー: プロジェクト計画書!$L$19
Name 計画_プロジェクト責任者: プロジェクト計画書!$L$16
Name 計画_営業担当者: プロジェクト計画書!$AI$17
Name 計画_画面数: プロジェクト計画書!$L$75
Name 計画_開始日: プロジェクト計画書!$L$124
Name 計画_開発規模その他: プロジェクト計画書!$L$78
Name 計画_開発言語その他: プロジェクト計画書!$L$30
Name 計画_開発言語その他詳細: プロジェクト計画書!#REF!
Name 計画_外部IF数: プロジェクト計画書!$AI$76
Name 計画_概算FP: プロジェクト計画書!$AI$77
Name 計画_原価: プロジェクト計画書!$AJ$124
Name 計画_顧客担当部署: プロジェクト計画書!$AI$14
Name 計画_公共: プロジェクト計画書!$L$25
Name 計画_工期: プロジェクト計画書!$T$124
Name 計画_工数: プロジェクト計画書!$X$124
Name 計画_受注額: プロジェクト計画書!$L$18
Name 計画_終了日: プロジェクト計画書!$P$124
Name 計画_粗利: プロジェクト計画書!$AN$124
Name 計画_粗利率: プロジェクト計画書!$AR$124
Name 計画_他本部連携: プロジェクト計画書!$L$23
Name 計画_単価: プロジェクト計画書!$AF$124
Name 計画_担当部門: プロジェクト計画書!$AI$15
Name 計画_担当本部: プロジェクト計画書!$L$15
Name 計画_帳票数: プロジェクト計画書!$AI$75
Name 計画_売上: プロジェクト計画書!$AB$124

Sheet プロジェクト計画書
AL4: 作成(PM) | AQ4: =IF(計画_受注額>=10000000,"承認(品質保証責任者)","承認(部長)") -> 承認(部長)
AL5: 関谷 亮 | AQ5: 福井 将敏
AL8: 45810 | AQ8: 45812
B10: ＜基本情報＞
B11: プロジェクトコード | L11: PJ2025052974 | Y11: プロジェクト期間 | AI11: =計画_開始日 -> 45817 | AO11: ～ | AP11: =計画_終了日 -> 45856
B12: プロジェクト名 | L12: MES嵌合工程検査のオンライン化対応
B13: プロジェクト概要 | L13: 嵌合実績入力画面における工程検査表取込機能追加対応
B14: 顧客名 | L14: 出光興産株式会社 | Y14: 顧客担当部署 | AI14: ﾃﾞｼﾞﾀﾙ･ICT推進部
B15: 担当本部 | L15: システムソリューション１部 | Y15: 担当部門 | AI15: システムソリューション本部
B16: プロジェクト責任者 | L16: 福井将敏 | Y16: プロジェクトマネージャ | AI16: 関谷亮
B17: 品質管理担当者 | L17: 福井将敏 | Y17: 営業担当者 | AI17: 髙浦祐朗
B18: 受注額（プロジェクト全体） | L18: =IF(計画_売上="",0,計画_売上)+IF(計画_物販売上="",0,計画_物販売上) -> 1000000 | Y18: プロジェクト区分 | AI18: 改良開発
B19: プロジェクトメンバー | L19: 関谷亮、森田泰博
B22: ＜プロジェクト属性＞
B23: 他本部連携 | L23: - | Y23: アライアンス | AI23: オラクル
B24: オフショア | L24: - | Y24: クラウドネイティブ | AI24: -
B25: 公共 | L25: - | Y25: CloudJetAdvisory | AI25: -
B26: 開発言語 | C26: Java | L26: - | Y26: クラウド | Z26: AWS | AI26: -
C27: .NET | L27: ○ | Z27: Azure | AI27: ○
C28: Python | L28: - | Z28: OCI | AI28: -
C29: VBA | L29: - | Z29: EXE-Cloud | AI29: -
C30: その他 | L30: - | Z30: その他 | AI30: -
B32: ＜プロジェクト目的及び品質目標＞
B33: プロジェクト目的 | L33: 嵌合工程検査表は紙ベースでの記録となっており、重大クレーム発生時に設備が停止した記録をトレースする際に、スタッフが紙を１枚１枚確認する必要がある。MFB-906Z1フランジ折れクレーム発生時はトレース作業時のヒューマンエラーによる範囲の特定ミスが発生し、お客様からの信頼を失墜するリスクがあるため、オンライン化することでトレース作業を確実に短時間で出来るようにする。
B35: 成功要因 | L35: 関係者（利用部門含む）との連携を密に行い、要件定義にて仕様を明確にし、完成イメージの認識合わせを実施する。また、設計工程後、および結合テスト工程後に打ち合わせを実施し、認識齟齬がないかを確認する。
B37: 品質目標 | L37: 成果物すべてで内部レビュー及び外部レビューを100%実施し、出光興産様とシステムエグゼ双方で内容を合意する。 また、開発期間中から本稼働までを含め、障害発生をゼロとする。
B39: セキュリティ目標 | L39: セキュリティ事故０件（メール誤送信や添付ファイルのPW漏れ 等）
B41: セキュリティに配慮した開発計画 | L41: 既存画面改修の為、対象外
B44: ＜インプット＞
B45: インプット項目 | L45: あり／なし | Q45: 備考
B46: 提案依頼書 | L46: なし
B47: 提案書 | L47: なし
B48: 見積書 | L48: あり（右記に文書名記入） | Q48: 見積詳細_三重MES 嵌合工程検査のオンライン化対応.xlsx
B49: 注文書 | L49: あり（右記に文書名記入） | Q49: 注文書_伊東様_三重MES 嵌合工程検査のオンライン化対応.xlsx
B50: 個別契約書 | L50: なし
B51: 仕様書 | L51: なし
B52: 要件定義書 | L52: なし
B53: 影響度調査結果（改修の場合） | L53: なし
B54: その他 | L54: なし
B56: ＜アウトプット＞
...

Sheet プロジェクト完了報告書
AL4: 作成(PM) | AQ4: =IF(実績_受注額>=10000000,"承認(品質保証責任者)","承認(部長)") -> 承認(部長)
AL5: 関谷 亮 | AQ5: 福井 将敏
B8: ※ ★の項目は顧客満足度調査の依頼メールの本文に記載されますので間違いがないよう記載してください。
B10: ＜基本情報＞ ※プロジェクト終了時点の情報を記載
B11: プロジェクトコード ★ | L11: =プロジェクトコード&"" -> PJ2025052974 | Y11: プロジェクト期間 | AI11: =実績_開始日 | AO11: ～ | AP11: =実績_終了日
B12: プロジェクト名 ★ | L12: =プロジェクト名&"" -> MES嵌合工程検査のオンライン化対応
B13: プロジェクト概要 | L13: =プロジェクト概要&"" -> 嵌合実績入力画面における工程検査表取込機能追加対応
B14: 顧客名 ★ | L14: =顧客名&"" -> 出光興産株式会社 | Y14: 顧客担当部署 | AI14: =計画_顧客担当部署&"" -> ﾃﾞｼﾞﾀﾙ･ICT推進部
B15: 担当本部 | L15: =計画_担当本部&"" -> システムソリューション１部 | Y15: 担当部門 | AI15: =計画_担当部門&"" -> システムソリューション本部
B16: プロジェクト責任者 | L16: =計画_プロジェクト責任者&"" -> 福井将敏 | Y16: プロジェクトマネージャ | AI16: =計画_プロジェクトマネージャ&"" -> 関谷亮
B17: 品質管理担当者 | L17: =計画_品質管理担当者&"" -> 福井将敏 | Y17: 営業担当者 | AI17: =計画_営業担当者&"" -> 髙浦祐朗
B18: 受注額（プロジェクト全体） | L18: =IF(実績_売上="",0,実績_売上)+IF(実績_物販売上="",0,実績_物販売上) -> 0 | Y18: プロジェクト区分 | AI18: =プロジェクト区分&"" -> 改良開発
B19: プロジェクトメンバー
B22: ＜プロジェクト属性＞
B23: 他本部連携 | Y23: アライアンス | AI23: =計画_アライアンス&"" -> オラクル
B24: オフショア | Y24: クラウドネイティブ
B25: 公共 | L25: =計画_公共&"" -> - | Y25: CloudJetAdvisory
B26: 開発言語 | C26: Java | Y26: クラウド | Z26: AWS
C27: .NET | Z27: Azure
C28: Python | Z28: OCI
C29: VBA | Z29: EXE-Cloud
C30: その他 | Z30: その他
B32: ＜プロジェクトの状況＞
B33: 納品完了日 | Y33: 検収完了日
B35: ＜プロジェクト目的及び品質目標＞
B36: プロジェクト目的 | L36: =プロジェクト目的&"" -> 嵌合工程検査表は紙ベースでの記録となっており、重大クレーム発生時に設備が停止した記録をトレースする際に、スタッフが紙を１枚１枚確認する必要がある。MFB-906Z1フランジ折れクレーム発生時はトレース作業時のヒューマンエラーによる範囲の特定ミスが発生し、お客様からの信頼を失墜するリスクがあるため、オンライン化することでトレース作業を確実に短時間で出来るようにする。
B38: 成功要因 | L38: =成功要因&"" -> 関係者（利用部門含む）との連携を密に行い、要件定義にて仕様を明確にし、完成イメージの認識合わせを実施する。また、設計工程後、および結合テスト工程後に打ち合わせを実施し、認識齟齬がないかを確認する。
B40: 品質目標 | L40: =品質目標&"" -> 成果物すべてで内部レビュー及び外部レビューを100%実施し、出光興産様とシステムエグゼ双方で内容を合意する。 また、開発期間中から本稼働までを含め、障害発生をゼロとする。
B42: セキュリティ目標 | L42: =セキュリティ目標&"" -> セキュリティ事故０件（メール誤送信や添付ファイルのPW漏れ 等）
B44: セキュリティに配慮した開発計画 | L44: =セキュリティに配慮した開発計画&"" -> 既存画面改修の為、対象外
B47: ＜プロジェクト目的及び品質目標に対する評価＞
B48: プロジェクト目的の達成状況
B50: 品質目標に対する評価
B52: セキュリティ目標に対する評価
B54: セキュリティに配慮した開発計画に対する評価
B57: ＜顧客満足度調査＞
B58: 顧客満足度調査の依頼予定 | Y58: 顧客満足度調査の依頼予定がなしの理由
B60: 顧客満足度調査の依頼先 担当者名 ★ | Y60: 顧客満足度調査の依頼先 担当者メールアドレス ★
B63: ＜開発規模（結果）＞
B64: 画面数 | Y64: 帳票数
...

Sheet 品質データ分析報告書
AL4: 作成(PM) | AQ4: 承認(部長)
AL5: 関谷 亮 | AQ5: 福井 将敏
B10: ＜基本情報＞
B11: プロジェクトコード | L11: =プロジェクトコード&"" -> PJ2025052974 | Y11: プロジェクト期間 | AI11: =実績_開始日 | AO11: ～ | AP11: =実績_終了日
B12: プロジェクト名 | L12: =プロジェクト名&"" -> MES嵌合工程検査のオンライン化対応
B13: プロジェクト概要 | L13: =プロジェクト概要&"" -> 嵌合実績入力画面における工程検査表取込機能追加対応
B14: 顧客名 | L14: =顧客名&"" -> 出光興産株式会社 | Y14: 顧客担当部署 | AI14: =計画_顧客担当部署&"" -> ﾃﾞｼﾞﾀﾙ･ICT推進部
B15: 担当本部 | L15: =計画_担当本部&"" -> システムソリューション１部 | Y15: 担当部門 | AI15: =計画_担当部門&"" -> システムソリューション本部
B16: プロジェクト責任者 | L16: =計画_プロジェクト責任者&"" -> 福井将敏 | Y16: プロジェクトマネージャ | AI16: =計画_プロジェクトマネージャ&"" -> 関谷亮
B17: 品質管理担当者 | L17: =計画_品質管理担当者&"" -> 福井将敏 | Y17: 営業担当者 | AI17: =計画_営業担当者&"" -> 髙浦祐朗
B18: 受注額（プロジェクト全体） | L18: =計画_受注額 -> 1000000 | Y18: プロジェクト区分 | AI18: =プロジェクト区分&"" -> 改良開発
B20: ＜開発規模（想定）＞
B21: 画面数 | L21: =IF(プロジェクト計画書!L75="","",プロジェクト計画書!L75) -> 1 | Y21: 帳票数 | AI21: =IF(プロジェクト計画書!AI75="","",プロジェクト計画書!AI75) -> 0
B22: バッチ数 | L22: =IF(プロジェクト計画書!L76="","",プロジェクト計画書!L76) -> 0 | Y22: 外部IF数 | AI22: =IF(プロジェクト計画書!AI76="","",プロジェクト計画書!AI76) -> 4
B23: テーブル数 | L23: =IF(プロジェクト計画書!L77="","",プロジェクト計画書!L77) -> 0 | Y23: 概算FP | AI23: =IF(プロジェクト計画書!AI77="","",プロジェクト計画書!AI77) -> 36
B24: その他 | L24: =IF(プロジェクト計画書!L78="","",プロジェクト計画書!L78)
B26: ＜開発規模（結果）＞
B27: 画面数 | L27: =IF(プロジェクト完了報告書!L64="","",プロジェクト完了報告書!L64) | Y27: 帳票数 | AI27: =IF(プロジェクト完了報告書!AI64="","",プロジェクト完了報告書!AI64)
B28: バッチ数 | L28: =IF(プロジェクト完了報告書!L65="","",プロジェクト完了報告書!L65) | Y28: 外部IF数 | AI28: =IF(プロジェクト完了報告書!AI65="","",プロジェクト完了報告書!AI65)
B29: テーブル数 | L29: =IF(プロジェクト完了報告書!L66="","",プロジェクト完了報告書!L66) | Y29: 概算FP | AI29: =IF(プロジェクト完了報告書!AI66="","",プロジェクト完了報告書!AI66) -> 0
B30: その他 | L30: =IF(プロジェクト完了報告書!L67="","",プロジェクト完了報告書!L67)
B32: ＜テスト実績＞
B33: 結合テストケース数 | L33: =IF(プロジェクト完了報告書!L70="","",プロジェクト完了報告書!L70) | Y33: システムテストケース数 | AI33: =IF(プロジェクト完了報告書!AI70="","",プロジェクト完了報告書!AI70)
B34: 結合テスト不具合摘出数 | L34: =IF(プロジェクト完了報告書!L71="","",プロジェクト完了報告書!L71) | Y34: システムテスト不具合摘出数 | AI34: =IF(プロジェクト完了報告書!AI71="","",プロジェクト完了報告書!AI71)
B35: 結合テストケース密度 | L35: =IF(プロジェクト完了報告書!L72="","",プロジェクト完了報告書!L72) | Y35: システムテストケース密度 | AI35: =IF(プロジェクト完了報告書!AI72="","",プロジェクト完了報告書!AI72)
B36: 結合テストバグ密度 | L36: =IF(プロジェクト完了報告書!L73="","",プロジェクト完了報告書!L73) | Y36: システムテストバグ密度 | AI36: =IF(プロジェクト完了報告書!AI73="","",プロジェクト完了報告書!AI73)
B37: ユーザーテスト時障害発生件数 | L37: =IF(プロジェクト完了報告書!L74="","",プロジェクト完了報告書!L74)
B39: ＜本稼働実績＞
B40: 本稼働後障害発生件数 | L40: =IF(プロジェクト完了報告書!L77="","",プロジェクト完了報告書!L77) | Y40: 内）本稼働後の重大障害件数 | AI40: =IF(プロジェクト完了報告書!AI77="","",プロジェクト完了報告書!AI77)
B42: （参考）IPA指標 P25～P75
B43: 結合テスト | Y43: システムテスト
B44: テスト密度 | G44: 新規開発 | L44: 539.1 | R44: ～ | S44: 2393.7 | Y44: テスト密度 | AD44: 新規開発 | AI44: 107.9 | AO44: ～ | AP44: 659.1
G45: 改良開発 | L45: 950.1 | R45: ～ | S45: 8914.1 | AD45: 改良開発 | AI45: 511.1 | AO45: ～ | AP45: 2058.1
B46: バグ密度 | G46: 新規開発 | L46: 36.6 | R46: ～ | S46: 159.7 | Y46: バグ密度 | AD46: 新規開発 | AI46: 14.8 | AO46: ～ | AP46: 104.7
G47: 改良開発 | L47: 36.6 | R47: ～ | S47: 137.8 | AD47: 改良開発 | AI47: 14.7 | AO47: ～ | AP47: 45.2
B49: ＜不具合混入工程別不具合検出一覧＞
B50: 不具合混入工程 不具合検出工程 | G50: 要件定義 | K50: 基本設計 | O50: 詳細設計 | S50: 製造・単体ﾃｽﾄ | W50: 結合ﾃｽﾄ | AA50: ｼｽﾃﾑﾃｽﾄ | AE50: ﾕｰｻﾞｰﾃｽﾄ | AI50: 本稼働以降 | AM50: 計 | AQ50: 不具合検出率
B52: 要件定義 | AM52: =SUM(G52:AL52) -> 0 | AQ52: =AM52/G60 -> #DIV/0!
B53: 基本設計 | AM53: =SUM(G53:AL53) -> 0 | AQ53: =AM53/SUM(G53:N59) -> #DIV/0!
B54: 詳細設計 | AM54: =SUM(G54:AL54) -> 0 | AQ54: =AM54/SUM(G54:R59) -> #DIV/0!
...

Sheet 開発及びサポートプロセスにおけるセキュリティ
A1: 以下、ISMS手順書（第 13 章 システム導入・開発・変更のセキュリティ基準）より抜粋
B3: 4 | C3: 開発及びサポートプロセスにおけるセキュリティ
C5: (1) | D5: セキュリティに配慮した開発のための方針
D6: ア | E6: セキュリティに配慮したサービス、アーキテクチャ、ソフトウェア及びシステムを構築する。
D7: イ | E7: 前号を達成するため、セキュリティに配慮した開発のための方針には、次の側面を考慮する。
E8: a) | F8: 開発環境のセキュリティ
E9: b) | F9: ソフトウェア開発のライフサイクルにおける、次に関わるセキュリティに関する手引
F10:  | G10: ソフトウェア開発の方法論におけるセキュリティ
F11:  | G11: 用いる各プログラミング言語について定めた、セキュリティに配慮したコーディングに関する指針
E12: c) | F12: 設計段階におけるセキュリティ要求事項
E13: d) | F13: プロジェクトの開発の節目ごとにおけるセキュリティの確認項目
E14: e) | F14: セキュリティが保たれたリポジトリ
E15: f) | F15: 版の管理におけるセキュリティ
E16: g) | F16: アプリケーションのセキュリティに関して必要な知識
E17: h) | F17: ぜい弱性を回避、発見及び修正するに当たっての開発者の能力
C19: (4) | D19: セキュリティに配慮したシステム構築の原則
D20: ア | E20: 次の事項を考慮して、セキュリティに配慮したシステムの構築を原則とする。
E21: a) | F21: セキュリティは、情報セキュリティの必要性とアクセス性の必要性との均衡を保ちながら、全てのアーキテクチャ層（業務、データ、アプリケーション及び技術）において設計する。
E22: b) | F22: 新技術は、セキュリティ上のリスクについて分析し、その設計を既知の攻撃パターンに照らしてレビューする。
D23: イ | E23: QMS手順書に従い、システムを開発、変更する場合は、顧客との合意に基づき、前項を考慮して、セキュリティに配慮したシステムを構築する。
C25: (5) | D25: セキュリティに配慮した開発環境
D26: ア | E26: システム開発業務（全てのシステム開発ライフサイクルを含む）に伴うリスクに応じて、次の事項を考慮して、セキュリティに配慮した開発環境を整備する。
E27: a) | F27: システムによって処理、保管及び伝送されるデータの取扱いに慎重を要する度合い。
E28: b) | F28: 適用される外部及び内部の要求事項。例えば、規制又は方針によるもの。
E29: c) | F29: 組織によって既に実施されており、システム開発を支えるようなセキュリティ管理策。
E30: d) | F30: その環境で作業する要員の信頼性。
E31: e) | F31: システム開発に関連した外部委託の程度。
E32: f) | F32: 異なる開発環境の分離の必要性。
E33: g) | F33: 開発環境へのアクセスの制御。
E34: h) | F34: 開発環境の変更及びそこに保管されたコードに対する変更の監視。
E35: i) | F35: セキュリティに配慮した遠隔地でのバックアップの保管。
E36: j) | F36: 開発環境からの、及び開発環境への、データの移動の管理。
D37: イ | E37: 前項は、QMS手順書に従い、システムを開発、変更する場合においても適用する。
C39: (6) | D39: システムセキュリティの試験
D40: ア | E40: セキュリティ機能（functionality）の試験は、システムが期待どおりに、かつ、期待した形でだけ動作することを確実にするため、開発期間中に実施する。なお、試験の程度は、そのシステムの重要性及び性質に見合ったものとする。
D41: イ | E41: システムを開発、変更する場合は、一連の条件の下での試験活動、試験への入力及び予想される出力について、計画を作成し、開発プロセスにおいて試験及び検証を行う。
D42: ウ | E42: 前２項は、QMS手順書に従い、システムを開発、変更する場合においても適用する。なお、作成する計画には、プロジェクト計画にて決定したセキュリティ要求事項を含める。
C44: (7) | D44: システムの受入れ試験
D45: ア | E45: 新しい情報システム及びその改訂版・更新版のために行う、システムの受入れ試験は、情報セキュリティ要求事項の試験及びセキュリティに配慮したシステム開発のための方針の順守を含み、受け入れた構成部品及びシステムに対して、試験を実施する。
D46: イ | E46: 前項において、コード分析ツール又は脆弱性スキャナーのような自動化ツールを利用して、セキュリティに関連する欠陥を修正した場合は、この修正を検証する。
...

Sheet 改定履歴
A4: 番号 | B4: 版数 | C4: 発行日 | D4: 改定内容 | E4: 更新者 | F4: 更新日 | G4: 承認者 | H4: 承認日 | I4: 備考 | J4: ステータス
A5: 1 | B5: 1 | D5: 初版発行 | J5: =IF(B5="","",IF(F5="","更新中",IF(H5="","更新済み",IF(C5="","承認済み",IF(C5>TODAY(),"発行待ち","発行済み"))))) -> 更新中
A6: 2 | J6: =IF(B6="","",IF(F6="","更新中",IF(H6="","更新済み",IF(C6="","承認済み",IF(C6>TODAY(),"発行待ち","発行済み")))))
A7: 3 | J7: =IF(B7="","",IF(F7="","更新中",IF(H7="","更新済み",IF(C7="","承認済み",IF(C7>TODAY(),"発行待ち","発行済み")))))
A8: 4 | J8: =IF(B8="","",IF(F8="","更新中",IF(H8="","更新済み",IF(C8="","承認済み",IF(C8>TODAY(),"発行待ち","発行済み")))))
A9: 5 | J9: =IF(B9="","",IF(F9="","更新中",IF(H9="","更新済み",IF(C9="","承認済み",IF(C9>TODAY(),"発行待ち","発行済み")))))
A10: 6 | J10: =IF(B10="","",IF(F10="","更新中",IF(H10="","更新済み",IF(C10="","承認済み",IF(C10>TODAY(),"発行待ち","発行済み")))))
A11: 7 | J11: =IF(B11="","",IF(F11="","更新中",IF(H11="","更新済み",IF(C11="","承認済み",IF(C11>TODAY(),"発行待ち","発行済み")))))
A12: 8 | J12: =IF(B12="","",IF(F12="","更新中",IF(H12="","更新済み",IF(C12="","承認済み",IF(C12>TODAY(),"発行待ち","発行済み")))))
A13: 9 | J13: =IF(B13="","",IF(F13="","更新中",IF(H13="","更新済み",IF(C13="","承認済み",IF(C13>TODAY(),"発行待ち","発行済み")))))
A14: 10 | J14: =IF(B14="","",IF(F14="","更新中",IF(H14="","更新済み",IF(C14="","承認済み",IF(C14>TODAY(),"発行待ち","発行済み")))))
A15: 11 | J15: =IF(B15="","",IF(F15="","更新中",IF(H15="","更新済み",IF(C15="","承認済み",IF(C15>TODAY(),"発行待ち","発行済み")))))
A16: 12 | J16: =IF(B16="","",IF(F16="","更新中",IF(H16="","更新済み",IF(C16="","承認済み",IF(C16>TODAY(),"発行待ち","発行済み")))))
A17: 13 | J17: =IF(B17="","",IF(F17="","更新中",IF(H17="","更新済み",IF(C17="","承認済み",IF(C17>TODAY(),"発行待ち","発行済み")))))
... A24: 20 | J24: =IF(B24="","",IF(F24="","更新中",IF(H24="","更新済み",IF(C24="","承認済み",IF(C24>TODAY(),"発行待ち","発行済み")))))

Sheet 【事務局用】顧客満足度調査依頼 メール文面
A1: From | B1: qms-isms-office@system-exe.jp
A2: To | B2: =顧客満足度調査の依頼先担当者メールアドレス & ""
A3: CC | B3: =プロジェクト完了報告書!AI16 & " " & プロジェクト完了報告書!AI17 -> 関谷亮 髙浦祐朗
A4: BCC | B4: qms-isms-office@system-exe.jp
A5: タイトル | B5: 【株式会社システムエグゼ】お客様満足度調査へのご協力依頼
A6: 本文 | B6: =SUBSTITUTE(SUBSTITUTE(SUBSTITUTE(SUBSTITUTE(SUBSTITUTE(B25, "[顧客名]", 顧客名),"[顧客担当者名]",顧客満足度調査の依頼先担当者名),"[プロジェクト名]",プロジェクト名),"[プロジェクトコード]",プロジェクトコード),"[期日]",TEXT(EOMONTH(検収完了日,1),"yyyy/MM/dd")) -> 出光興産株式会社 様 平素は格別のご高配を賜り、厚く御礼申し上げます。 株式会社システムエグゼ 千葉オフィスQMS・ISMS事務局からご連絡となります。 さて、弊社では、お客様が期待する高品質で信頼性の高いシステムを提供するべく、 品質マネジメントシステムの規格「JIS Q 9001」および 情報セキュリティマネジメントシステムの規格「JIS Q 27001」の認証を取得しております。 その取り組みの一環として、弊社の活動が適切なものであったか否かについて、 このたびの以下のプロジェクトに対するお客様の率直なご意見を賜りたく存じます。 ・MES嵌合工程検査のオンライン化対応 ご多用中誠に恐縮ではございますが、趣旨ご理解の上、 下記アンケートサイトにアクセスいただきご回答を賜りますようお願い申し上げます。 アンケートサイト ： https://smilesurvey.co/start.php?s=8435515e&id=PJ2025052974 所要時間は、3分～5分程度です。1900/02/28までにご回答いただけますと幸いです。 ご質問やご不明点等がございましたら、下記のメールアドレスまでお問い合わせください。 お問い合わせ先のメールアドレス： qms-isms-office@system-exe.jp 尚、アンケートにてご記入いただいた内容につきましては、 お客様満足度調査とその分析を利用目的とし、他の目的に利用することは一切ありません。 弊社の情報セキュリティ基本方針につきましては、下記の弊社WEBサイトよりご確認下さい。 http://www.system-exe.co.jp —————————————————————————————— 株式会社システムエグゼ 千葉オフィス QMS・ISMS事務局 MAIL：qms-isms-office@system-exe.jp ——————————————————————————————
B24: ↓本文テンプレート ★編集注意
B25: [顧客名] [顧客担当者名] 様 平素は格別のご高配を賜り、厚く御礼申し上げます。 株式会社システムエグゼ 千葉オフィスQMS・ISMS事務局からご連絡となります。 さて、弊社では、お客様が期待する高品質で信頼性の高いシステムを提供するべく、 品質マネジメントシステムの規格「JIS Q 9001」および 情報セキュリティマネジメントシステムの規格「JIS Q 27001」の認証を取得しております。 その取り組みの一環として、弊社の活動が適切なものであったか否かについて、 このたびの以下のプロジェクトに対するお客様の率直なご意見を賜りたく存じます。 ・[プロジェクト名] ご多用中誠に恐縮ではございますが、趣旨ご理解の上、 下記アンケートサイトにアクセスいただきご回答を賜りますようお願い申し上げます。 アンケートサイト ： https://smilesurvey.co/start.php?s=8435515e&id=[プロジェクトコード] 所要時間は、3分～5分程度です。[期日]までにご回答いただけますと幸いです。 ご質問やご不明点等がございましたら、下記のメールアドレスまでお問い合わせください。 お問い合わせ先のメールアドレス： qms-isms-office@system-exe.jp 尚、アンケートにてご記入いただいた内容につきましては、 お客様満足度調査とその分析を利用目的とし、他の目的に利用することは一切ありません。 弊社の情報セキュリティ基本方針につきましては、下記の弊社WEBサイトよりご確認下さい。 http://www.system-exe.co.jp —————————————————————————————— 株式会社システムエグゼ 千葉オフィス QMS・ISMS事務局 MAIL：qms-isms-office@system-exe.jp ——————————————————————————————

Sheet マスタ
A1: プロジェクトコード | B1: =プロジェクトコード&"" -> PJ2025052974
A2: プロジェクト名 | B2: =プロジェクト名&"" -> MES嵌合工程検査のオンライン化対応
A3: 顧客名 | B3: =顧客名&"" -> 出光興産株式会社
A4: 文書番号 | B4: 53-01
A5: 文書名 | B5: プロジェクト計画書・完了報告書
A6: 発行者 | B6: 株式会社システムエグゼ
A7: 文書管理責任者 | B7: [PM]
A8: 発行日 | B8: =IF(VLOOKUP(版数,改定履歴!B:C,2,FALSE)=0,"未定",VLOOKUP(版数,改定履歴!B:C,2,FALSE)) -> 未定
A9: 版数 | B9: =IF(COUNTA(改定履歴!B5:B24)>0,MAX(改定履歴!B5:B24),"-") -> 1
A10: ヘッダプロジェクト名 | B10: =顧客名 & " " & プロジェクト名 -> 出光興産株式会社 MES嵌合工程検査のオンライン化対応
A11: ヘッダ文書名 | B11: =文書番号 & " プロジェクト計画書" -> 53-01 プロジェクト計画書
A12: ヘッダ文書名‐補足１ | B12: =文書番号 & " プロジェクト完了報告書" -> 53-01 プロジェクト完了報告書
A13: ヘッダ文書名‐補足２ | B13: =文書番号 & " 品質データ分析報告書" -> 53-01 品質データ分析報告書
A14: ヘッダ文書名‐補足３ | B14: =文書番号 & " " & 文書名 & "‐" -> 53-01 プロジェクト計画書・完了報告書‐
A15: ヘッダ文書名‐改訂履歴 | B15: =文書番号 & " " & 文書名 & "‐改訂履歴" -> 53-01 プロジェクト計画書・完了報告書‐改訂履歴
A16: ヘッダ様式名称 | B16: ="様式：" & 文書番号 & " " & 文書名 & " " & TEXT(様式版数, "（第 0.0 版）") -> 様式：53-01 プロジェクト計画書・完了報告書 (第 4.7 版)
A17: 様式版数 | B17: 4.7

Sheet 選択肢
A1: 改訂担当者 | B1: 改定承認形式 | C1: 改定ステータス | D1: 区分 | E1: 担当 | F1: 分類３ | G1: ステータス
A2: QMS・ISMS委員会 | B2: メール | C2: 更新中 | D2: QMS・ISMS | E2: 経営者 | G2: 未着手
A3: QMS・ISMS事務局 | B3: Teams（チャット） | C3: 更新済み | D3: QMS | E3: 品質管理責任者・情報セキュリティ管理責任者 | G3: 対応中
A4: 佐藤輝雄 | B4: 会議体 | C4: 承認済み | D4: ISMS | E4: 品質管理責任者 | G4: 完了
A5: 福田慎 | B5: 口頭 | C5: 発行済み | D5: その他 | E5: 情報セキュリティ管理責任者 | G5: 保留
A6: 安部ゆかり | E6: 内部監査責任者 | G6: 取消
A7: 矢野幸代 | E7: システム管理責任者
A8: 福井将敏 | E8: 鍵管理者
A9: 川名翔太 | E9: 委員会
A10: 鈴木邦彦 | E10: 事務局
A11: 本吉史明 | E11: 部長
A12: 松下智一
A13: 遠矢成洋
A14: 野村康二
A15: 郡司剛
A16: 山本真輔
A17: 菊池北斗
A18: 石井徹
A19: 青井圭介
A20: 村上輝暁（認証科学） | E20: JICQA
E21: -
