Workbook
Name PJ番号: #REF!
Name ＰＪ表紙名: #REF!
Name ＰＭ名: [1]プロジェクト実施計画書!$G$7
Name プロジェクトコード: '[2]プロジェクト報告書（3.3版）'!$L$9
Name プロジェクトコード: '[2]プロジェクト報告書（3.3版）'!$L$9
Name プロジェクトコード: プロジェクト完了報告書!$L$9
Name プロジェクト名: '[2]プロジェクト報告書（3.3版）'!$L$10
Name プロジェクト名: '[2]プロジェクト報告書（3.3版）'!$L$10
Name プロジェクト名: プロジェクト完了報告書!$L$10
Name プロジェクト名称: #REF!
Name 月: #REF!
Name 検収完了日: '[2]プロジェクト報告書（3.3版）'!$AI$21
Name 検収完了日: '[2]プロジェクト報告書（3.3版）'!$AI$21
Name 検収完了日: プロジェクト完了報告書!$AI$21
Name 顧客コード: #REF!
Name 顧客満足度調査の依頼先担当者メールアドレス: '[2]プロジェクト報告書（3.3版）'!$AI$48
Name 顧客満足度調査の依頼先担当者メールアドレス: '[2]プロジェクト報告書（3.3版）'!$AI$48
Name 顧客満足度調査の依頼先担当者メールアドレス: プロジェクト完了報告書!$AI$48
Name 顧客満足度調査の依頼先担当者名: '[2]プロジェクト報告書（3.3版）'!$L$48
Name 顧客満足度調査の依頼先担当者名: '[2]プロジェクト報告書（3.3版）'!$L$48
Name 顧客満足度調査の依頼先担当者名: プロジェクト完了報告書!$L$48
Name 顧客名: '[2]プロジェクト報告書（3.3版）'!$L$13
Name 顧客名: '[2]プロジェクト報告書（3.3版）'!$L$13
Name 顧客名: プロジェクト完了報告書!$L$12
Name 顧客名称: #REF!
Name 作成者: #REF!
Name 主管部門: #REF!
Name 日: #REF!
Name 年: #REF!

Sheet プロジェクト計画書
B2: プロジェクト計画書 | AL2: 作成(PM) | AQ2: 承認(責任者)
AL3: ○○ 太郎 | AQ3: ○○ 花子
AL6: 20XX/XX/XX | AQ6: 20XX/XX/XX
B8: ＜基本情報＞
B9: プロジェクトコード | Y9: プロジェクト期間 | AO9: ～
B10: プロジェクト名
B11: プロジェクト概要
B12: 顧客名 | Y12: 顧客担当部署
B13: 担当本部 | Y13: 担当部門
B14: プロジェクト責任者 | Y14: プロジェクトマネージャ
B15: 品質管理担当者 | Y15: 営業担当者
B16: 受注額（プロジェクト全体） | Y16: プロジェクト区分
B18: ＜プロジェクト目的及び品質目標＞
B19: プロジェクト目的
B21: 成功要因
B23: 品質目標
B25: セキュリティ目標
B27: セキュリティに配慮した開発計画
B30: ＜インプット＞
B31: インプット項目 | L31: あり／なし | Q31: 備考
B32: 提案依頼書
B33: 提案書
B34: 見積書
B35: 注文書
B36: 個別契約書
B37: 仕様書
B38: 要件定義書
B39: 影響度調査結果（改修の場合）
B40: その他
B42: ＜アウトプット＞
B43: アウトプット項目 | L43: 納品 | Q43: 作成 | V43: 備考
B44: プロジェクト計画書
B45: 要件定義書
B46: 影響度調査結果（改修の場合）
B47: 基本設計書
B48: 詳細設計書
B49: プログラム
B50: 単体テスト仕様書・結果報告書
B51: 結合テスト仕様書・結果報告書
B52: システムテスト仕様書・結果報告書
...

Sheet プロジェクト完了報告書
B2: プロジェクト完了報告書 | AL2: 作成(PM) | AQ2: 承認(責任者)
AL3: ○○ 太郎 | AQ3: ○○ 花子
B6: ※ ★の項目は顧客満足度調査の依頼メールの本文に記載されますので間違いがないよう記載してください。 | AL6: 20XX/XX/XX | AQ6: 20XX/XX/XX
B8: ＜基本情報＞
B9: プロジェクトコード ★ | L9: =プロジェクト計画書!L9 & "" | Y9: プロジェクト期間 | AI9: =IF(プロジェクト計画書!AI9="","",プロジェクト計画書!AI9) | AO9: ～ | AP9: =IF(プロジェクト計画書!AP9="","",プロジェクト計画書!AP9)
B10: プロジェクト名 ★ | L10: =プロジェクト計画書!L10 & ""
B11: プロジェクト概要 | L11: =プロジェクト計画書!L11 & ""
B12: 顧客名 ★ | L12: =プロジェクト計画書!L12 & "" | Y12: 顧客担当部署 | AI12: =プロジェクト計画書!AI12 & ""
B13: 担当本部 | L13: =プロジェクト計画書!L13 & "" | Y13: 担当部門 | AI13: =プロジェクト計画書!AI13 & ""
B14: プロジェクト責任者 | L14: =プロジェクト計画書!L14 & "" | Y14: プロジェクトマネージャ | AI14: =プロジェクト計画書!AI14 & ""
B15: 品質管理担当者 | L15: =プロジェクト計画書!L15 & "" | Y15: 営業担当者 | AI15: =プロジェクト計画書!AI15 & ""
B16: 受注額（プロジェクト全体） | L16: =IF(プロジェクト計画書!L16="","",プロジェクト計画書!L16) | Y16: プロジェクト区分 | AI16: =プロジェクト計画書!AI16 & ""
B17: プロジェクトメンバー
B20: ＜プロジェクトの状況＞
B21: 納品完了日 | Y21: 検収完了日
B23: ＜プロジェクト目的及び品質目標＞
B24: プロジェクト目的 | L24: =プロジェクト計画書!L19 & ""
B26: 成功要因 | L26: =プロジェクト計画書!L21 & ""
B28: 品質目標 | L28: =プロジェクト計画書!L23 & ""
B30: セキュリティ目標 | L30: =プロジェクト計画書!L25 & ""
B32: セキュリティに配慮した開発計画 | L32: =プロジェクト計画書!L27 & ""
B35: ＜プロジェクト目的及び品質目標に対する評価＞
B36: プロジェクト目的の達成状況
B38: 品質目標に対する評価
B40: セキュリティ目標に対する評価
B42: セキュリティに配慮した開発計画に対する評価
B45: ＜顧客満足度調査＞
B46: 顧客満足度調査の依頼予定 | Y46: 顧客満足度調査の依頼予定がなしの理由
B48: 顧客満足度調査の依頼先 担当者名 ★ | Y48: 顧客満足度調査の依頼先 担当者メールアドレス ★
B51: ＜開発規模（結果）＞
B52: 画面数 | Y52: 帳票数
B53: バッチ数 | Y53: 外部IF数
B54: テーブル数 | Y54: 概算FP | AI54: =(L52*4*4)+(AI52*4)+(L53*5)+(AI53*5)+(L54*7) -> 0
B55: その他
B57: ＜テスト実績＞
B58: 結合テストケース数 | Y58: システムテストケース数
B59: 結合テスト不具合摘出数 | Y59: システムテスト不具合摘出数
B60: 結合テストケース密度 | L60: =IF(AI54=0,"",L58/(AI54/1000)) | Y60: システムテストケース密度 | AI60: =IF(AI54=0,"",AI58/(AI54/1000))
B61: 結合テストバグ密度 | L61: =IF(AI54=0,"",L59/(AI54/1000)) | Y61: システムテストバグ密度 | AI61: =IF(AI54=0,"",AI59/(AI54/1000))
B62: ユーザーテスト不具合摘出数
...

Sheet 品質データ分析報告書
B2: 品質データ分析報告書 | AL2: 作成(PM) | AQ2: 承認(責任者)
AL3: ○○ 太郎 | AQ3: ○○ 花子
AL6: 20XX/XX/XX | AQ6: 20XX/XX/XX
B8: ＜基本情報＞
B9: プロジェクトコード | L9: =プロジェクト計画書!L9 & "" | Y9: プロジェクト期間 | AI9: =IF(プロジェクト計画書!AI9="","",プロジェクト計画書!AI9) | AO9: ～ | AP9: =IF(プロジェクト計画書!AP9="","",プロジェクト計画書!AP9)
B10: プロジェクト名 | L10: =プロジェクト計画書!L10 & ""
B11: プロジェクト概要 | L11: =プロジェクト計画書!L11 & ""
B12: 顧客名 | L12: =プロジェクト計画書!L12 & "" | Y12: 顧客担当部署 | AI12: =プロジェクト計画書!AI12 & ""
B13: 担当本部 | L13: =プロジェクト計画書!L13 & "" | Y13: 担当部門 | AI13: =プロジェクト計画書!AI13 & ""
B14: プロジェクト責任者 | L14: =プロジェクト計画書!L14 & "" | Y14: プロジェクトマネージャ | AI14: =プロジェクト計画書!AI14 & ""
B15: 品質管理担当者 | L15: =プロジェクト計画書!L15 & "" | Y15: 営業担当者 | AI15: =プロジェクト計画書!AI15 & ""
B16: 受注額（プロジェクト全体） | L16: =IF(プロジェクト計画書!L16="","",プロジェクト計画書!L16) | Y16: プロジェクト区分 | AI16: =プロジェクト計画書!AI16 & ""
B18: ＜開発規模（想定）＞
B19: 画面数 | L19: =IF(プロジェクト計画書!L61="","",プロジェクト計画書!L61) | Y19: 帳票数 | AI19: =IF(プロジェクト計画書!AI61="","",プロジェクト計画書!AI61)
B20: バッチ数 | L20: =IF(プロジェクト計画書!L62="","",プロジェクト計画書!L62) | Y20: 外部IF数 | AI20: =IF(プロジェクト計画書!AI62="","",プロジェクト計画書!AI62)
B21: テーブル数 | L21: =IF(プロジェクト計画書!L63="","",プロジェクト計画書!L63) | Y21: 概算FP | AI21: =IF(プロジェクト計画書!AI63="","",プロジェクト計画書!AI63) -> 0
B22: その他 | L22: =IF(プロジェクト計画書!L64="","",プロジェクト計画書!L64)
B24: ＜開発規模（結果）＞
B25: 画面数 | L25: =IF(プロジェクト完了報告書!L52="","",プロジェクト完了報告書!L52) | Y25: 帳票数 | AI25: =IF(プロジェクト完了報告書!AI52="","",プロジェクト完了報告書!AI52)
B26: バッチ数 | L26: =IF(プロジェクト完了報告書!L53="","",プロジェクト完了報告書!L53) | Y26: 外部IF数 | AI26: =IF(プロジェクト完了報告書!AI53="","",プロジェクト完了報告書!AI53)
B27: テーブル数 | L27: =IF(プロジェクト完了報告書!L54="","",プロジェクト完了報告書!L54) | Y27: 概算FP | AI27: =IF(プロジェクト完了報告書!AI54="","",プロジェクト完了報告書!AI54) -> 0
B28: その他 | L28: =IF(プロジェクト完了報告書!L55="","",プロジェクト完了報告書!L55)
B30: ＜テスト実績＞
B31: 結合テストケース数 | L31: =IF(プロジェクト完了報告書!L58="","",プロジェクト完了報告書!L58) | Y31: システムテストケース数 | AI31: =IF(プロジェクト完了報告書!AI58="","",プロジェクト完了報告書!AI58)
B32: 結合テスト不具合摘出数 | L32: =IF(プロジェクト完了報告書!L59="","",プロジェクト完了報告書!L59) | Y32: システムテスト不具合摘出数 | AI32: =IF(プロジェクト完了報告書!AI59="","",プロジェクト完了報告書!AI59)
B33: 結合テストケース密度 | L33: =IF(プロジェクト完了報告書!L60="","",プロジェクト完了報告書!L60) | Y33: システムテストケース密度 | AI33: =IF(プロジェクト完了報告書!AI60="","",プロジェクト完了報告書!AI60)
B34: 結合テストバグ密度 | L34: =IF(プロジェクト完了報告書!L61="","",プロジェクト完了報告書!L61) | Y34: システムテストバグ密度 | AI34: =IF(プロジェクト完了報告書!AI61="","",プロジェクト完了報告書!AI61)
B36: （参考）IPA指標 P25～P75
B37: 結合テスト | Y37: システムテスト
B38: テスト密度 | G38: 新規開発 | L38: 539.1 | R38: ～ | S38: 2393.7 | Y38: テスト密度 | AD38: 新規開発 | AI38: 107.9 | AO38: ～ | AP38: 659.1
G39: 改良開発 | L39: 950.1 | R39: ～ | S39: 8914.1 | AD39: 改良開発 | AI39: 511.1 | AO39: ～ | AP39: 2058.1
B40: バグ密度 | G40: 新規開発 | L40: 36.6 | R40: ～ | S40: 159.7 | Y40: バグ密度 | AD40: 新規開発 | AI40: 14.8 | AO40: ～ | AP40: 104.7
G41: 改良開発 | L41: 36.6 | R41: ～ | S41: 137.8 | AD41: 改良開発 | AI41: 14.7 | AO41: ～ | AP41: 45.2
B43: ＜不具合混入工程別不具合検出一覧＞
B44: 不具合混入工程 不具合検出工程 | G44: 要件定義 | K44: 基本設計 | O44: 詳細設計 | S44: 製造・単体ﾃｽﾄ | W44: 結合ﾃｽﾄ | AA44: ｼｽﾃﾑﾃｽﾄ | AE44: ﾕｰｻﾞｰﾃｽﾄ | AI44: 本稼働以降 | AM44: 計 | AQ44: 不具合検出率
B46: 要件定義 | AM46: =SUM(G46:AL46) -> 0 | AQ46: =AM46/G54 -> #DIV/0!
B47: 基本設計 | AM47: =SUM(G47:AL47) -> 0 | AQ47: =AM47/SUM(G47:N53) -> #DIV/0!
B48: 詳細設計 | AM48: =SUM(G48:AL48) -> 0 | AQ48: =AM48/SUM(G48:R53) -> #DIV/0!
B49: 製造・単体ﾃｽﾄ | AM49: =SUM(G49:AL49) -> 0 | AQ49: =AM49/SUM(G49:V53) -> #DIV/0!
B50: 結合ﾃｽﾄ | AM50: =SUM(G50:AL50) -> 0 | AQ50: =AM50/SUM(G50:Z53) -> #DIV/0!
...

Sheet 開発及びサポートプロセスにおけるセキュリティ
A1: 以下、ISMS手順書（第 13 章 システム導入・開発・変更のセキュリティ基準）より抜粋
B3: 4 | C3: 開発及びサポートプロセスにおけるセキュリティ
C5: (1) | D5: セキュリティに配慮した開発のための方針
D6: ア | E6: セキュリティに配慮したサービス、アーキテクチャ、ソフトウェア及びシステムを構築する。
D7: イ | E7: 前号を達成するため、セキュリティに配慮した開発のための方針には、次の側面を考慮する。
E8: a) | F8: 開発環境のセキュリティ
E9: b) | F9: ソフトウェア開発のライフサイクルにおける、次に関わるセキュリティに関する手引
F10:  | G10: ソフトウェア開発の方法論におけるセキュリティ
F11:  | G11: 用いる各プログラミング言語について定めた、セキュリティに配慮したコーディングに関する指針
E12: c) | F12: 設計段階におけるセキュリティ要求事項
E13: d) | F13: プロジェクトの開発の節目ごとにおけるセキュリティの確認項目
E14: e) | F14: セキュリティが保たれたリポジトリ
E15: f) | F15: 版の管理におけるセキュリティ
E16: g) | F16: アプリケーションのセキュリティに関して必要な知識
E17: h) | F17: ぜい弱性を回避、発見及び修正するに当たっての開発者の能力
C19: (4) | D19: セキュリティに配慮したシステム構築の原則
D20: ア | E20: 次の事項を考慮して、セキュリティに配慮したシステムの構築を原則とする。
E21: a) | F21: セキュリティは、情報セキュリティの必要性とアクセス性の必要性との均衡を保ちながら、全てのアーキテクチャ層（業務、データ、アプリケーション及び技術）において設計する。
E22: b) | F22: 新技術は、セキュリティ上のリスクについて分析し、その設計を既知の攻撃パターンに照らしてレビューする。
D23: イ | E23: QMS手順書に従い、システムを開発、変更する場合は、顧客との合意に基づき、前項を考慮して、セキュリティに配慮したシステムを構築する。
C25: (5) | D25: セキュリティに配慮した開発環境
D26: ア | E26: システム開発業務（全てのシステム開発ライフサイクルを含む）に伴うリスクに応じて、次の事項を考慮して、セキュリティに配慮した開発環境を整備する。
E27: a) | F27: システムによって処理、保管及び伝送されるデータの取扱いに慎重を要する度合い。
E28: b) | F28: 適用される外部及び内部の要求事項。例えば、規制又は方針によるもの。
E29: c) | F29: 組織によって既に実施されており、システム開発を支えるようなセキュリティ管理策。
E30: d) | F30: その環境で作業する要員の信頼性。
E31: e) | F31: システム開発に関連した外部委託の程度。
E32: f) | F32: 異なる開発環境の分離の必要性。
E33: g) | F33: 開発環境へのアクセスの制御。
E34: h) | F34: 開発環境の変更及びそこに保管されたコードに対する変更の監視。
E35: i) | F35: セキュリティに配慮した遠隔地でのバックアップの保管。
E36: j) | F36: 開発環境からの、及び開発環境への、データの移動の管理。
D37: イ | E37: 前項は、QMS手順書に従い、システムを開発、変更する場合においても適用する。
C39: (6) | D39: システムセキュリティの試験
D40: ア | E40: セキュリティ機能（functionality）の試験は、システムが期待どおりに、かつ、期待した形でだけ動作することを確実にするため、開発期間中に実施する。なお、試験の程度は、そのシステムの重要性及び性質に見合ったものとする。
D41: イ | E41: システムを開発、変更する場合は、一連の条件の下での試験活動、試験への入力及び予想される出力について、計画を作成し、開発プロセスにおいて試験及び検証を行う。
D42: ウ | E42: 前２項は、QMS手順書に従い、システムを開発、変更する場合においても適用する。なお、作成する計画には、プロジェクト計画にて決定したセキュリティ要求事項を含める。
C44: (7) | D44: システムの受入れ試験
D45: ア | E45: 新しい情報システム及びその改訂版・更新版のために行う、システムの受入れ試験は、情報セキュリティ要求事項の試験及びセキュリティに配慮したシステム開発のための方針の順守を含み、受け入れた構成部品及びシステムに対して、試験を実施する。
D46: イ | E46: 前項において、コード分析ツール又は脆弱性スキャナーのような自動化ツールを利用して、セキュリティに関連する欠陥を修正した場合は、この修正を検証する。
...

Sheet 更新履歴
A1: 版数 | B1: 更新内容 | C1: 更新者 | D1: 更新日
A3: 3.1 | B3: 更新履歴（当シート）を追加 プロジェクトの成功要因欄を追加 セキュリティ目標を追加 改ページ調整 備考欄のサイズ調整 | C3: 福田慎 | D3: 44579
A4: 3.3 | B4: プロジェクトメンバーを追加 セキュリティに配慮した開発計画を追加 開発及びサポートプロセスにおけるセキュリティシートを追加 セキュリティに配慮した開発計画に対する評価項目を追加 顧客満足度調査の依頼予定項目を追加 顧客満足度調査の依頼予定がなしの理由項目を追加 顧客満足度調査の依頼先担当者名項目を追加 顧客満足度調査の依頼先担当者メールアドレス項目を追加 発生した作業ミスやヒヤリハット項目を追加 顧客満足度調査の回収状況項目を追加 顧客満足度調査の結果に対する施策および実施状況項目を追加 | C4: 福田慎 | D4: 45209
A5: 3.4 | B5: 回答期限：検収日の３ヶ月⇒１か月 後までに変更 『プロジェクト名』について記述場所変更 文言変更 ”ご協力を” ⇒ ”ご回答を” 以下文を追加 『株式会社システムエグゼ千葉オフィスQMS・ISMS事務局からのご連絡となります。』 署名欄 ・MAILを追加 （qms-isms-office@system-exe.jp） ・電話番号 削除 CC:PMのほか、営業担当を追加 BCC:qms-isms-office@system-exe.jp を追加 タイトル：【株式会社システムエグゼ】 文言追加 | C5: 福田慎 | D5: 45356
A6: 3.5 | B6: 顧客満足度調査依頼 メール文面におけるURLを2024年度版に変更 | C6: 福田慎 | D6: 45405
A7: 4 | B7: プロジェクト計画書・プロジェクト完了報告書・品質分析報告書を１つのファイルに統合 プロジェクト計画書に成功要因を追加 プロジェクト完了報告書にテストケース密度・バグ密度を追加 外部IF数・FPを追加 担当チームを削除、品質管理担当者を追加 | C7: 福田慎 | D7: 45440
A8: 4.1 | B8: 品質分析報告書の名称を品質データ分析報告書に変更 | C8: 福田慎 | D8: 45566
A9: 4.2 | B9: プロジェクト計画書のスケジュールを削除 プロジェクト計画書の収支計画を削除 プロジェクト計画書のアウトプット 移行作業手順書・移行結果報告書を削除 プロジェクト計画書のアウトプット WBS・課題管理表・リスク管理表・議事録を削除 プロジェクト計画書にアウトプット プロジェクト管理資料を追加 プロジェクト計画書にスケジュールおよび工程別収支計画を追加 プロジェクト完了報告書の外注実績を削除 プロジェクト完了報告書にスケジュールおよび工程別収支実績を追加 プロジェクト完了報告書にユーザーテスト不具合摘出数を追加 | C9: 福田慎

Sheet 【事務局用】顧客満足度調査依頼 メール文面
A1: From | B1: qms-isms-office@system-exe.jp
A2: To | B2: =顧客満足度調査の依頼先担当者メールアドレス -> 0
A3: CC | B3: 営業担当,PM
A4: BCC | B4: qms-isms-office@system-exe.jp
A5: タイトル | B5: 【株式会社システムエグゼ】お客様満足度調査へのご協力依頼
A6: 本文 | B6: =SUBSTITUTE(SUBSTITUTE(SUBSTITUTE(SUBSTITUTE(SUBSTITUTE(B25, "[顧客名]", 顧客名),"[顧客担当者名]",顧客満足度調査の依頼先担当者名),"[プロジェクト名]",プロジェクト名),"[プロジェクトコード]",プロジェクトコード),"[期日]",TEXT(EOMONTH(検収完了日,1),"yyyy/MM/dd")) -> 様 平素は格別のご高配を賜り、厚く御礼申し上げます。 株式会社システムエグゼ 千葉オフィスQMS・ISMS事務局からご連絡となります。 さて、弊社では、お客様が期待する高品質で信頼性の高いシステムを提供するべく、 品質マネジメントシステムの規格「JIS Q 9001」および 情報セキュリティマネジメントシステムの規格「JIS Q 27001」の認証を取得しております。 その取り組みの一環として、弊社の活動が適切なものであったか否かについて、 このたびの以下のプロジェクトに対するお客様の率直なご意見を賜りたく存じます。 ・ ご多用中誠に恐縮ではございますが、趣旨ご理解の上、 下記アンケートサイトにアクセスいただきご回答を賜りますようお願い申し上げます。 アンケートサイト ： https://smilesurvey.co/start.php?s=c32e6cb2&id= 所要時間は、3分～5分程度です。1900/02/28までにご回答いただけますと幸いです。 ご質問やご不明点等がございましたら、下記のメールアドレスまでお問い合わせください。 お問い合わせ先のメールアドレス： qms-isms-office@system-exe.jp 尚、アンケートにてご記入いただいた内容につきましては、 お客様満足度調査とその分析を利用目的とし、他の目的に利用することは一切ありません。 弊社の情報セキュリティ基本方針につきましては、下記の弊社WEBサイトよりご確認下さい。 http://www.system-exe.co.jp —————————————————————————————— 株式会社システムエグゼ 千葉オフィス QMS・ISMS事務局 MAIL：qms-isms-office@system-exe.jp ——————————————————————————————
B24: ↓本文テンプレート ★編集注意
B25: [顧客名] [顧客担当者名] 様 平素は格別のご高配を賜り、厚く御礼申し上げます。 株式会社システムエグゼ 千葉オフィスQMS・ISMS事務局からご連絡となります。 さて、弊社では、お客様が期待する高品質で信頼性の高いシステムを提供するべく、 品質マネジメントシステムの規格「JIS Q 9001」および 情報セキュリティマネジメントシステムの規格「JIS Q 27001」の認証を取得しております。 その取り組みの一環として、弊社の活動が適切なものであったか否かについて、 このたびの以下のプロジェクトに対するお客様の率直なご意見を賜りたく存じます。 ・[プロジェクト名] ご多用中誠に恐縮ではございますが、趣旨ご理解の上、 下記アンケートサイトにアクセスいただきご回答を賜りますようお願い申し上げます。 アンケートサイト ： https://smilesurvey.co/start.php?s=c32e6cb2&id=[プロジェクトコード] 所要時間は、3分～5分程度です。[期日]までにご回答いただけますと幸いです。 ご質問やご不明点等がございましたら、下記のメールアドレスまでお問い合わせください。 お問い合わせ先のメールアドレス： qms-isms-office@system-exe.jp 尚、アンケートにてご記入いただいた内容につきましては、 お客様満足度調査とその分析を利用目的とし、他の目的に利用することは一切ありません。 弊社の情報セキュリティ基本方針につきましては、下記の弊社WEBサイトよりご確認下さい。 http://www.system-exe.co.jp —————————————————————————————— 株式会社システムエグゼ 千葉オフィス QMS・ISMS事務局 MAIL：qms-isms-office@system-exe.jp ——————————————————————————————
